ts_recv,ts_event,rtype,publisher_id,instrument_id,action,side,price,size,channel_id,order_id,flags,ts_in_delta,sequence,symbol
2025-09-24T19:32:00.409340860Z,2025-09-24T19:32:00.408665355Z,160,1,432669,C,A,64.830000000,2,26,8058566324260,128,19601,94252165,CLX5
2025-09-24T19:32:00.409368153Z,2025-09-24T19:32:00.408666413Z,160,1,432669,A,A,64.830000000,2,26,8058566324263,128,15056,94252166,CLX5
2025-09-24T19:32:00.409570656Z,2025-09-24T19:32:00.408921973Z,160,1,432669,T,B,64.830000000,12,26,8058566324264,0,15636,94252176,CLX5
2025-09-24T19:32:00.409570656Z,2025-09-24T19:32:00.408921973Z,160,1,432669,F,A,64.830000000,3,26,8058566322092,0,15636,94252176,CLX5
2025-09-24T19:32:00.409570656Z,2025-09-24T19:32:00.408921973Z,160,1,432669,F,A,64.830000000,1,26,8058566322115,0,15636,94252176,CLX5
2025-09-24T19:32:00.409570656Z,2025-09-24T19:32:00.408921973Z,160,1,432669,F,A,64.830000000,2,26,8058566322124,0,15636,94252176,CLX5
2025-09-24T19:32:00.409570656Z,2025-09-24T19:32:00.408921973Z,160,1,432669,F,A,64.830000000,3,26,8058566322156,0,15636,94252176,CLX5
2025-09-24T19:32:00.409570656Z,2025-09-24T19:32:00.408921973Z,160,1,432669,F,A,64.830000000,1,26,8058566322062,0,15636,94252176,CLX5
2025-09-24T19:32:00.409570656Z,2025-09-24T19:32:00.408921973Z,160,1,432669,F,A,64.830000000,2,26,8058566324263,0,15636,94252176,CLX5
2025-09-24T19:32:00.409628184Z,2025-09-24T19:32:00.408921973Z,160,1,432669,C,A,64.830000000,3,26,8058566322092,0,15458,94252177,CLX5
2025-09-24T19:32:00.409628184Z,2025-09-24T19:32:00.408921973Z,160,1,432669,C,A,64.830000000,1,26,8058566322115,0,15458,94252177,CLX5
2025-09-24T19:32:00.409628184Z,2025-09-24T19:32:00.408921973Z,160,1,432669,C,A,64.830000000,2,26,8058566322124,0,15458,94252177,CLX5
2025-09-24T19:32:00.409628184Z,2025-09-24T19:32:00.408921973Z,160,1,432669,C,A,64.830000000,3,26,8058566322156,0,15458,94252177,CLX5
2025-09-24T19:32:00.409628184Z,2025-09-24T19:32:00.408921973Z,160,1,432669,C,A,64.830000000,1,26,8058566322062,0,15458,94252177,CLX5
2025-09-24T19:32:00.409628184Z,2025-09-24T19:32:00.408921973Z,160,1,432669,C,A,64.830000000,2,26,8058566324263,0,15458,94252177,CLX5
2025-09-24T19:32:00.409628184Z,2025-09-24T19:32:00.408921973Z,160,1,432669,C,A,64.830000000,1,26,8058566322118,128,15458,94252177,CLX5
2025-09-24T19:32:00.409696348Z,2025-09-24T19:32:00.408933799Z,160,1,432669,A,B,64.830000000,2,26,8058566324265,128,17494,94252181,CLX5
2025-09-24T19:32:00.409945890Z,2025-09-24T19:32:00.409268971Z,160,1,432669,A,B,64.820000000,2,26,8058566324266,128,14693,94252192,CLX5
2025-09-24T19:32:00.409997251Z,2025-09-24T19:32:00.409341703Z,160,1,432669,A,B,64.820000000,2,26,8058566324267,128,14291,94252194,CLX5
2025-09-24T19:32:00.410027209Z,2025-09-24T19:32:00.409345735Z,160,1,432669,A,B,64.820000000,2,26,8058566324268,128,15132,94252195,CLX5
2025-09-24T19:32:00.411198109Z,2025-09-24T19:32:00.409656129Z,160,1,432669,C,B,64.790000000,2,26,8058566323256,128,18619,94252246,CLX5
2025-09-24T19:32:00.411356916Z,2025-09-24T19:32:00.409698981Z,160,1,432669,C,B,64.830000000,2,26,8058566324265,128,14274,94252250,CLX5
2025-09-24T19:32:00.411451735Z,2025-09-24T19:32:00.409709215Z,160,1,432669,A,A,64.840000000,1,26,8058566324290,128,15489,94252257,CLX5
2025-09-24T19:32:00.411633404Z,2025-09-24T19:32:00.409761781Z,160,1,432669,A,B,64.830000000,1,26,8058566324294,128,17992,94252264,CLX5
2025-09-24T19:32:00.411656857Z,2025-09-24T19:32:00.409844183Z,160,1,432669,A,A,64.850000000,1,26,8058566324295,128,17232,94252266,CLX5
2025-09-24T19:32:00.411817399Z,2025-09-24T19:32:00.409947341Z,160,1,432669,C,A,64.860000000,1,26,8058566323560,128,14836,94252276,CLX5
2025-09-24T19:32:00.412465972Z,2025-09-24T19:32:00.410219201Z,160,1,432669,M,B,64.820000000,1,26,8058566311303,128,16274,94252296,CLX5
2025-09-24T19:32:00.413265787Z,2025-09-24T19:32:00.410326235Z,160,1,432669,A,B,64.830000000,1,26,8058566324312,128,17312,94252326,CLX5
2025-09-24T19:32:00.414150891Z,2025-09-24T19:32:00.411018269Z,160,1,432669,A,B,64.800000000,1,26,8058566324324,128,13984,94252374,CLX5
2025-09-24T19:32:00.414546298Z,2025-09-24T19:32:00.411205787Z,160,1,432669,T,A,64.830000000,2,26,8058566324327,0,15107,94252399,CLX5
2025-09-24T19:32:00.414546298Z,2025-09-24T19:32:00.411205787Z,160,1,432669,F,B,64.830000000,1,26,8058566324294,0,15107,94252399,CLX5
2025-09-24T19:32:00.414546298Z,2025-09-24T19:32:00.411205787Z,160,1,432669,F,B,64.830000000,1,26,8058566324312,0,15107,94252399,CLX5
2025-09-24T19:32:00.414604955Z,2025-09-24T19:32:00.411205787Z,160,1,432669,C,B,64.830000000,1,26,8058566324294,0,15604,94252400,CLX5
2025-09-24T19:32:00.414604955Z,2025-09-24T19:32:00.411205787Z,160,1,432669,C,B,64.830000000,1,26,8058566324312,128,15604,94252400,CLX5
2025-09-24T19:32:00.414876497Z,2025-09-24T19:32:00.411366043Z,160,1,432669,C,A,64.840000000,1,26,8058566324290,128,16860,94252414,CLX5
2025-09-24T19:32:00.415458603Z,2025-09-24T19:32:00.412012363Z,160,1,432669,M,A,64.850000000,1,26,8058566173085,128,15292,94252440,CLX5
2025-09-24T19:32:00.415522551Z,2025-09-24T19:32:00.412089871Z,160,1,432669,A,A,64.840000000,1,26,8058566324336,128,18093,94252442,CLX5
2025-09-24T19:32:00.416364911Z,2025-09-24T19:32:00.413956835Z,160,1,432669,A,B,64.830000000,1,26,8058566324343,128,18967,94252485,CLX5
2025-09-24T19:32:00.417191503Z,2025-09-24T19:32:00.414565083Z,160,1,432669,C,B,64.810000000,1,26,8058566323766,128,16898,94252535,CLX5
2025-09-24T19:32:00.417222122Z,2025-09-24T19:32:00.414568481Z,160,1,432669,C,A,64.840000000,1,26,8058566324336,128,15344,94252536,CLX5
2025-09-24T19:32:00.417465964Z,2025-09-24T19:32:00.415467809Z,160,1,432669,A,A,64.840000000,1,26,8058566324359,128,15213,94252551,CLX5
2025-09-24T19:32:00.417520728Z,2025-09-24T19:32:00.415882663Z,160,1,432669,C,A,64.840000000,1,26,8058566324359,128,17866,94252554,CLX5
2025-09-24T19:32:00.418036689Z,2025-09-24T19:32:00.416372029Z,160,1,432669,T,A,64.830000000,1,26,8058566324369,0,14781,94252588,CLX5
2025-09-24T19:32:00.418036689Z,2025-09-24T19:32:00.416372029Z,160,1,432669,F,B,64.830000000,1,26,8058566324343,0,14781,94252588,CLX5
2025-09-24T19:32:00.418103110Z,2025-09-24T19:32:00.416372029Z,160,1,432669,C,B,64.830000000,1,26,8058566324343,128,18354,94252589,CLX5
2025-09-24T19:32:00.418139965Z,2025-09-24T19:32:00.416373029Z,160,1,432669,A,A,64.840000000,1,26,8058566324370,128,14779,94252593,CLX5
2025-09-24T19:32:00.418371535Z,2025-09-24T19:32:00.416594011Z,160,1,432669,A,A,64.830000000,1,26,8058566324375,128,14779,94252603,CLX5
2025-09-24T19:32:00.420108445Z,2025-09-24T19:32:00.418379783Z,160,1,432669,A,A,64.830000000,1,26,8058566324402,128,18991,94252700,CLX5
2025-09-24T19:32:00.420159522Z,2025-09-24T19:32:00.418409407Z,160,1,432669,C,A,64.840000000,1,26,8058566324370,128,15102,94252704,CLX5
2025-09-24T19:32:00.420576992Z,2025-09-24T19:32:00.419200277Z,160,1,432669,A,B,64.820000000,1,26,8058566324408,128,14384,94252730,CLX5
2025-09-24T19:32:00.421059586Z,2025-09-24T19:32:00.420192739Z,160,1,432669,A,A,64.840000000,1,26,8058566324420,128,14258,94252757,CLX5
2025-09-24T19:32:00.433641736Z,2025-09-24T19:32:00.433505393Z,160,1,432669,C,A,64.840000000,1,26,8058566324420,128,19187,94252844,CLX5
2025-09-24T19:32:00.447150906Z,2025-09-24T19:32:00.447001419Z,160,1,432669,A,B,64.810000000,2,26,8058566324443,128,15336,94252858,CLX5
2025-09-24T19:32:00.591568042Z,2025-09-24T19:32:00.591435193Z,160,1,432669,C,B,64.800000000,1,26,8058566324324,128,18291,94252972,CLX5
2025-09-24T19:32:00.862978751Z,2025-09-24T19:32:00.862851517Z,160,1,432669,A,B,64.560000000,1,26,8058566324512,128,18286,94253013,CLX5
2025-09-24T19:32:01.730066462Z,2025-09-24T19:32:01.729889307Z,160,1,432669,M,B,64.740000000,2,26,8058566262123,128,19036,94253082,CLX5
2025-09-24T19:32:02.502657166Z,2025-09-24T19:32:02.502334537Z,160,1,432669,T,B,64.830000000,1,26,8058566324545,0,19085,94253154,CLX5
2025-09-24T19:32:02.502657166Z,2025-09-24T19:32:02.502334537Z,160,1,432669,F,A,64.830000000,1,26,8058566324375,0,19085,94253154,CLX5
2025-09-24T19:32:02.502666435Z,2025-09-24T19:32:02.502334537Z,160,1,432669,C,A,64.830000000,1,26,8058566324375,128,15240,94253155,CLX5
2025-09-24T19:32:02.502744928Z,2025-09-24T19:32:02.502355293Z,160,1,432669,T,B,64.830000000,1,26,8058566324547,0,15219,94253158,CLX5
2025-09-24T19:32:02.502744928Z,2025-09-24T19:32:02.502355293Z,160,1,432669,F,A,64.830000000,1,26,8058566324402,0,15219,94253158,CLX5
2025-09-24T19:32:02.502757215Z,2025-09-24T19:32:02.502355293Z,160,1,432669,C,A,64.830000000,1,26,8058566324402,128,18445,94253159,CLX5
2025-09-24T19:32:02.502882009Z,2025-09-24T19:32:02.502624541Z,160,1,432669,A,B,64.830000000,2,26,8058566324549,128,16778,94253165,CLX5
2025-09-24T19:32:02.502905501Z,2025-09-24T19:32:02.502624721Z,160,1,432669,A,B,64.830000000,1,26,8058566324550,128,15633,94253167,CLX5
2025-09-24T19:32:02.503007540Z,2025-09-24T19:32:02.502666607Z,160,1,432669,A,B,64.790000000,1,26,8058566324553,128,14942,94253171,CLX5
2025-09-24T19:32:02.503076119Z,2025-09-24T19:32:02.502717715Z,160,1,432669,C,A,64.840000000,1,26,8058566322055,128,17064,94253174,CLX5
2025-09-24T19:32:02.503103827Z,2025-09-24T19:32:02.502717863Z,160,1,432669,C,A,64.840000000,1,26,8058566322056,128,15452,94253175,CLX5
2025-09-24T19:32:02.503303573Z,2025-09-24T19:32:02.502889087Z,160,1,432669,T,A,64.830000000,1,26,8058566324558,0,14311,94253185,CLX5
2025-09-24T19:32:02.503303573Z,2025-09-24T19:32:02.502889087Z,160,1,432669,F,B,64.830000000,1,26,8058566324549,0,14311,94253185,CLX5
2025-09-24T19:32:02.503303573Z,2025-09-24T19:32:02.502889087Z,160,1,432669,M,B,64.830000000,1,26,8058566324549,128,14311,94253185,CLX5
2025-09-24T19:32:02.503403999Z,2025-09-24T19:32:02.502930443Z,160,1,432669,T,A,64.830000000,1,26,8058566324559,0,15177,94253190,CLX5
2025-09-24T19:32:02.503403999Z,2025-09-24T19:32:02.502930443Z,160,1,432669,F,B,64.830000000,1,26,8058566324549,0,15177,94253190,CLX5
2025-09-24T19:32:02.503442989Z,2025-09-24T19:32:02.502930443Z,160,1,432669,C,B,64.830000000,1,26,8058566324549,128,15374,94253191,CLX5
2025-09-24T19:32:02.503588294Z,2025-09-24T19:32:02.503140001Z,160,1,432669,A,A,64.840000000,1,26,8058566324561,128,18545,94253199,CLX5
2025-09-24T19:32:02.503598255Z,2025-09-24T19:32:02.503189111Z,160,1,432669,T,A,64.830000000,1,26,8058566324562,0,14973,94253200,CLX5
2025-09-24T19:32:02.503598255Z,2025-09-24T19:32:02.503189111Z,160,1,432669,F,B,64.830000000,1,26,8058566324550,0,14973,94253200,CLX5
2025-09-24T19:32:02.503641383Z,2025-09-24T19:32:02.503189111Z,160,1,432669,C,B,64.830000000,1,26,8058566324550,128,15378,94253201,CLX5
2025-09-24T19:32:02.503851075Z,2025-09-24T19:32:02.503250837Z,160,1,432669,A,B,64.830000000,1,26,8058566324565,128,13905,94253209,CLX5
2025-09-24T19:32:02.503985629Z,2025-09-24T19:32:02.503303501Z,160,1,432669,T,A,64.830000000,1,26,8058566324568,0,15003,94253215,CLX5
2025-09-24T19:32:02.503985629Z,2025-09-24T19:32:02.503303501Z,160,1,432669,F,B,64.830000000,1,26,8058566324565,0,15003,94253215,CLX5
2025-09-24T19:32:02.504032897Z,2025-09-24T19:32:02.503303501Z,160,1,432669,C,B,64.830000000,1,26,8058566324565,128,17584,94253216,CLX5
2025-09-24T19:32:02.504075865Z,2025-09-24T19:32:02.503401261Z,160,1,432669,A,B,64.800000000,1,26,8058566324570,128,16441,94253220,CLX5
2025-09-24T19:32:02.504132624Z,2025-09-24T19:32:02.503412169Z,160,1,432669,C,A,64.840000000,1,26,8058566324561,128,17473,94253222,CLX5
2025-09-24T19:32:02.504462002Z,2025-09-24T19:32:02.503726075Z,160,1,432669,A,B,64.820000000,1,26,8058566324577,128,17921,94253237,CLX5
2025-09-24T19:32:02.504600749Z,2025-09-24T19:32:02.503982939Z,160,1,432669,A,A,64.840000000,2,26,8058566324579,128,15151,94253242,CLX5
2025-09-24T19:32:02.504676324Z,2025-09-24T19:32:02.503986875Z,160,1,432669,A,A,64.830000000,2,26,8058566324580,128,18089,94253244,CLX5
2025-09-24T19:32:02.504756645Z,2025-09-24T19:32:02.504100169Z,160,1,432669,A,B,64.820000000,1,26,8058566324583,128,15216,94253250,CLX5
2025-09-24T19:32:02.505001909Z,2025-09-24T19:32:02.504486571Z,160,1,432669,A,B,64.820000000,1,26,8058566324586,128,18891,94253264,CLX5
2025-09-24T19:32:02.505170675Z,2025-09-24T19:32:02.504697109Z,160,1,432669,C,B,64.820000000,1,26,8058566324586,128,15127,94253271,CLX5
2025-09-24T19:32:02.505220746Z,2025-09-24T19:32:02.504707745Z,160,1,432669,C,B,64.820000000,1,26,8058566324583,128,18905,94253273,CLX5
2025-09-24T19:32:02.509831554Z,2025-09-24T19:32:02.509677445Z,160,1,432669,A,A,64.840000000,1,26,8058566324594,128,18457,94253301,CLX5
2025-09-24T19:32:02.514348816Z,2025-09-24T19:32:02.514193491Z,160,1,432669,M,A,64.830000000,1,26,8058566324594,128,18389,94253304,CLX5
2025-09-24T19:32:02.514505119Z,2025-09-24T19:32:02.514377151Z,160,1,432669,C,B,64.820000000,1,26,8058566324577,128,18337,94253307,CLX5
2025-09-24T19:32:02.565508360Z,2025-09-24T19:32:02.565367375Z,160,1,432669,C,B,64.790000000,1,26,8058566324553,128,19059,94253361,CLX5
2025-09-24T19:32:02.681581636Z,2025-09-24T19:32:02.681445975Z,160,1,432669,C,B,64.800000000,1,26,8058566324570,128,18619,94253427,CLX5
2025-09-24T19:32:04.315316789Z,2025-09-24T19:32:04.315202061Z,160,1,432669,C,A,65.040000000,1,26,8058566320427,128,18183,94253672,CLX5
2025-09-24T19:32:04.341403636Z,2025-09-24T19:32:04.341239953Z,160,1,432669,A,A,64.830000000,1,26,8058566324722,128,18447,94253674,CLX5
2025-09-24T19:32:04.341637403Z,2025-09-24T19:32:04.341413647Z,160,1,432669,A,A,64.830000000,2,26,8058566324724,128,16580,94253678,CLX5
2025-09-24T19:32:04.377854953Z,2025-09-24T19:32:04.377742957Z,160,1,432669,A,A,65.030000000,1,26,8058566324730,128,18033,94253690,CLX5
2025-09-24T19:32:06.750795964Z,2025-09-24T19:32:06.750651941Z,160,1,432669,C,A,66.000000000,1,26,8058564175332,128,24519,94253916,CLX5
2025-09-24T19:32:08.203803797Z,2025-09-24T19:32:08.203647011Z,160,1,432669,A,A,64.830000000,1,26,8058566324837,128,20077,94254128,CLX5
2025-09-24T19:32:09.016713448Z,2025-09-24T19:32:09.016589697Z,160,1,432669,C,A,66.000000000,1,26,8058564180198,128,18954,94254192,CLX5
2025-09-24T19:32:09.321845686Z,2025-09-24T19:32:09.318804471Z,160,1,432669,C,B,64.820000000,2,26,8058566324268,128,21557,94254317,CLX5
2025-09-24T19:32:09.321895135Z,2025-09-24T19:32:09.318826993Z,160,1,432669,C,B,64.820000000,1,26,8058566323724,128,18041,94254321,CLX5
2025-09-24T19:32:09.321895135Z,2025-09-24T19:32:09.318841411Z,160,1,432669,A,B,64.810000000,1,26,8058566324948,128,18041,94254321,CLX5
2025-09-24T19:32:09.322804146Z,2025-09-24T19:32:09.319451463Z,160,1,432669,C,A,64.830000000,1,26,8058566324837,128,18823,94254350,CLX5
2025-09-24T19:32:14.528904966Z,2025-09-24T19:32:14.528557307Z,160,1,432669,T,A,64.820000000,1,26,8058566325441,0,18409,94255296,CLX5
2025-09-24T19:32:14.528904966Z,2025-09-24T19:32:14.528557307Z,160,1,432669,F,B,64.820000000,1,26,8058566321823,0,18409,94255296,CLX5
2025-09-24T19:32:14.528915533Z,2025-09-24T19:32:14.528557307Z,160,1,432669,C,B,64.820000000,1,26,8058566321823,128,15395,94255297,CLX5
2025-09-24T19:32:14.529127282Z,2025-09-24T19:32:14.528883657Z,160,1,432669,A,A,64.830000000,1,26,8058566325444,128,16536,94255301,CLX5
2025-09-24T19:32:14.529164521Z,2025-09-24T19:32:14.528908729Z,160,1,432669,A,A,64.830000000,1,26,8058566325445,128,17612,94255302,CLX5
2025-09-24T19:32:15.045504787Z,2025-09-24T19:32:15.045290367Z,160,1,432669,C,B,64.810000000,2,26,8058566324443,128,15222,94255346,CLX5
2025-09-24T19:32:15.045747209Z,2025-09-24T19:32:15.045432193Z,160,1,432669,A,A,64.830000000,1,26,8058566325454,128,16217,94255357,CLX5
2025-09-24T19:32:15.045869038Z,2025-09-24T19:32:15.045463065Z,160,1,432669,A,B,64.820000000,1,26,8058566325455,128,15053,94255363,CLX5
2025-09-24T19:32:15.109862127Z,2025-09-24T19:32:15.109720445Z,160,1,432669,A,B,64.810000000,2,26,8058566325459,128,18453,94255380,CLX5
2025-09-24T19:32:15.136636511Z,2025-09-24T19:32:15.136510097Z,160,1,432669,C,B,64.810000000,2,26,8058566325459,128,18882,94255382,CLX5
2025-09-24T19:32:15.136746314Z,2025-09-24T19:32:15.136541067Z,160,1,432669,C,B,64.820000000,1,26,8058566325455,128,16422,94255388,CLX5
2025-09-24T19:32:15.137345130Z,2025-09-24T19:32:15.137203093Z,160,1,432669,A,A,64.830000000,2,26,8058566325461,128,19894,94255401,CLX5
2025-09-24T19:32:15.138087893Z,2025-09-24T19:32:15.137379685Z,160,1,432669,A,A,64.830000000,1,26,8058566325472,128,18463,94255436,CLX5
2025-09-24T19:32:15.138494873Z,2025-09-24T19:32:15.138217575Z,160,1,432669,A,B,64.810000000,2,26,8058566325476,128,18541,94255455,CLX5
2025-09-24T19:32:15.138655139Z,2025-09-24T19:32:15.138228403Z,160,1,432669,A,B,64.820000000,1,26,8058566325481,128,14954,94255460,CLX5
2025-09-24T19:32:15.138789909Z,2025-09-24T19:32:15.138256089Z,160,1,432669,C,B,64.820000000,1,26,8058566325481,128,15280,94255463,CLX5
2025-09-24T19:32:15.139026302Z,2025-09-24T19:32:15.138640185Z,160,1,432669,A,B,64.820000000,1,26,8058566325485,128,18563,94255476,CLX5
2025-09-24T19:32:15.139081595Z,2025-09-24T19:32:15.138798137Z,160,1,432669,C,B,64.820000000,1,26,8058566325485,128,15169,94255479,CLX5
2025-09-24T19:32:15.141174515Z,2025-09-24T19:32:15.141054807Z,160,1,432669,C,B,64.810000000,2,26,8058566325476,128,18530,94255495,CLX5
2025-09-24T19:32:15.141250451Z,2025-09-24T19:32:15.141059185Z,160,1,432669,A,A,64.830000000,1,26,8058566325492,128,14841,94255497,CLX5
2025-09-24T19:32:15.142822088Z,2025-09-24T19:32:15.142496969Z,160,1,432669,A,B,64.810000000,2,26,8058566325510,128,18495,94255559,CLX5
2025-09-24T19:32:15.286930460Z,2025-09-24T19:32:15.286790953Z,160,1,432669,C,B,64.810000000,2,26,8058566325510,128,19080,94255600,CLX5
2025-09-24T19:32:15.287159834Z,2025-09-24T19:32:15.286974305Z,160,1,432669,C,A,64.830000000,1,26,8058566325472,128,17907,94255609,CLX5
2025-09-24T19:32:15.287536119Z,2025-09-24T19:32:15.287173055Z,160,1,432669,A,B,64.820000000,1,26,8058566325529,128,18433,94255623,CLX5
2025-09-24T19:32:15.288134505Z,2025-09-24T19:32:15.287438405Z,160,1,432669,C,B,64.820000000,1,26,8058566325529,128,18608,94255630,CLX5
2025-09-24T19:32:15.289415608Z,2025-09-24T19:32:15.288280655Z,160,1,432669,A,B,64.810000000,2,26,8058566325556,128,14200,94255728,CLX5
2025-09-24T19:32:15.290301288Z,2025-09-24T19:32:15.289410945Z,160,1,432669,C,B,64.810000000,2,26,8058566325556,128,15127,94255788,CLX5
2025-09-24T19:32:15.310183818Z,2025-09-24T19:32:15.310057083Z,160,1,432669,A,B,64.790000000,2,26,8058566325603,128,17251,94255865,CLX5
2025-09-24T19:32:15.387476595Z,2025-09-24T19:32:15.387346961Z,160,1,432669,C,A,64.830000000,1,26,8058566325492,128,19632,94255909,CLX5
2025-09-24T19:32:15.387503489Z,2025-09-24T19:32:15.387350225Z,160,1,432669,C,A,64.830000000,1,26,8058566325444,128,14736,94255910,CLX5
2025-09-24T19:32:15.387614267Z,2025-09-24T19:32:15.387490781Z,160,1,432669,C,A,64.830000000,2,26,8058566325461,128,19204,94255912,CLX5
2025-09-24T19:32:15.409869985Z,2025-09-24T19:32:15.409734615Z,160,1,432669,A,B,64.780000000,2,26,8058566325641,128,18116,94255937,CLX5
2025-09-24T19:32:16.014146531Z,2025-09-24T19:32:16.013989259Z,160,1,432669,C,A,64.900000000,1,26,8058566303277,128,19138,94256057,CLX5
2025-09-24T19:32:16.086492186Z,2025-09-24T19:32:16.086347621Z,160,1,432669,A,A,64.870000000,1,26,8058566325711,128,19092,94256059,CLX5
2025-09-24T19:32:18.177978643Z,2025-09-24T19:32:18.177730247Z,160,1,432669,C,A,64.830000000,1,26,8058566325445,128,15143,94256162,CLX5
2025-09-24T19:32:18.178018186Z,2025-09-24T19:32:18.177739195Z,160,1,432669,A,B,64.820000000,1,26,8058566325750,128,15317,94256163,CLX5
2025-09-24T19:32:18.178364858Z,2025-09-24T19:32:18.177994945Z,160,1,432669,C,A,64.830000000,1,26,8058566325454,128,22223,94256177,CLX5
2025-09-24T19:32:25.289864990Z,2025-09-24T19:32:25.289679789Z,160,1,432669,A,A,64.830000000,1,26,8058566325778,128,27296,94256235,CLX5
2025-09-24T19:32:25.290014619Z,2025-09-24T19:32:25.289877597Z,160,1,432669,A,A,64.830000000,1,26,8058566325779,128,23149,94256236,CLX5
2025-09-24T19:32:25.290065266Z,2025-09-24T19:32:25.289923387Z,160,1,432669,A,A,64.830000000,1,26,8058566325780,128,17762,94256240,CLX5
2025-09-24T19:32:25.290146033Z,2025-09-24T19:32:25.290020651Z,160,1,432669,A,A,64.830000000,1,26,8058566325781,128,21608,94256242,CLX5
2025-09-24T19:32:25.290671417Z,2025-09-24T19:32:25.290437713Z,160,1,432669,C,B,64.820000000,2,26,8058566324266,128,17702,94256253,CLX5
2025-09-24T19:32:25.290768518Z,2025-09-24T19:32:25.290513723Z,160,1,432669,A,A,64.830000000,2,26,8058566325785,128,20038,94256256,CLX5
2025-09-24T19:32:28.785361980Z,2025-09-24T19:32:28.785223269Z,160,1,432669,A,A,64.830000000,1,26,8058566325806,128,24765,94256311,CLX5
2025-09-24T19:32:28.785394910Z,2025-09-24T19:32:28.785236863Z,160,1,432669,C,B,64.820000000,2,26,8058566324267,128,18643,94256312,CLX5
2025-09-24T19:32:28.785430090Z,2025-09-24T19:32:28.785242469Z,160,1,432669,C,B,64.820000000,1,26,8058566325750,128,19365,94256313,CLX5
2025-09-24T19:32:28.785506510Z,2025-09-24T19:32:28.785377305Z,160,1,432669,C,B,64.820000000,1,26,8058566323760,128,21955,94256314,CLX5
2025-09-24T19:32:28.785841348Z,2025-09-24T19:32:28.785710601Z,160,1,432669,C,B,64.820000000,1,26,8058566323603,128,21337,94256321,CLX5
2025-09-24T19:32:28.786303751Z,2025-09-24T19:32:28.786166177Z,160,1,432669,A,A,64.860000000,1,26,8058566325809,128,18763,94256323,CLX5
2025-09-24T19:32:29.325524564Z,2025-09-24T19:32:29.325389295Z,160,1,432669,A,B,64.820000000,2,26,8058566325822,128,22107,94256343,CLX5
2025-09-24T19:32:29.325562701Z,2025-09-24T19:32:29.325417345Z,160,1,432669,A,B,64.820000000,1,26,8058566325823,128,25645,94256344,CLX5
2025-09-24T19:32:29.325672949Z,2025-09-24T19:32:29.325543117Z,160,1,432669,C,A,64.830000000,1,26,8058566325806,128,21960,94256345,CLX5
2025-09-24T19:32:31.120183611Z,2025-09-24T19:32:31.120025143Z,160,1,432669,A,A,64.830000000,1,26,8058566325831,128,22443,94256377,CLX5
2025-09-24T19:32:31.835307480Z,2025-09-24T19:32:31.835148175Z,160,1,432669,C,A,64.830000000,2,26,8058566325785,128,21298,94256453,CLX5
2025-09-24T19:32:31.835489878Z,2025-09-24T19:32:31.835364511Z,160,1,432669,C,A,64.830000000,1,26,8058566325780,128,19978,94256454,CLX5
2025-09-24T19:32:31.835618957Z,2025-09-24T19:32:31.835497717Z,160,1,432669,C,A,64.830000000,1,26,8058566325779,128,19443,94256455,CLX5
2025-09-24T19:32:35.910180121Z,2025-09-24T19:32:35.910031297Z,160,1,432669,M,B,64.540000000,1,26,8058566324512,128,29735,94256750,CLX5
2025-09-24T19:32:39.957981136Z,2025-09-24T19:32:39.957829595Z,160,1,432669,A,A,64.830000000,1,26,8058566325939,128,21657,94256767,CLX5
2025-09-24T19:32:39.958013390Z,2025-09-24T19:32:39.957856473Z,160,1,432669,A,A,64.830000000,2,26,8058566325940,128,22577,94256768,CLX5
2025-09-24T19:32:39.958038187Z,2025-09-24T19:32:39.957863635Z,160,1,432669,A,A,64.830000000,1,26,8058566325941,128,18715,94256769,CLX5
2025-09-24T19:32:39.958104009Z,2025-09-24T19:32:39.957980883Z,160,1,432669,A,A,64.830000000,1,26,8058566325942,128,21965,94256772,CLX5
2025-09-24T19:32:39.958312526Z,2025-09-24T19:32:39.958182379Z,160,1,432669,A,A,64.840000000,1,26,8058566325943,128,18371,94256775,CLX5
2025-09-24T19:32:39.958348052Z,2025-09-24T19:32:39.958216687Z,160,1,432669,C,B,64.820000000,2,26,8058566325822,128,15563,94256776,CLX5
2025-09-24T19:32:40.058803986Z,2025-09-24T19:32:40.058664257Z,160,1,432669,M,A,64.830000000,1,26,8058566325943,128,19841,94256795,CLX5
2025-09-24T19:32:40.058949438Z,2025-09-24T19:32:40.058824071Z,160,1,432669,C,B,64.820000000,1,26,8058566325823,128,18883,94256796,CLX5
2025-09-24T19:32:40.059104865Z,2025-09-24T19:32:40.058966643Z,160,1,432669,C,B,64.820000000,1,26,8058566323763,128,18765,94256797,CLX5
2025-09-24T19:32:40.059133165Z,2025-09-24T19:32:40.058967795Z,160,1,432669,A,B,64.820000000,1,26,8058566325949,128,15503,94256798,CLX5
2025-09-24T19:32:40.059231963Z,2025-09-24T19:32:40.059113403Z,160,1,432669,C,B,64.820000000,1,26,8058566325949,128,18505,94256799,CLX5
2025-09-24T19:32:40.059274470Z,2025-09-24T19:32:40.059149035Z,160,1,432669,A,B,64.820000000,1,26,8058566325950,128,15297,94256800,CLX5
2025-09-24T19:32:40.059402926Z,2025-09-24T19:32:40.059281931Z,160,1,432669,A,B,64.820000000,1,26,8058566325951,128,18279,94256801,CLX5
2025-09-24T19:32:40.059533280Z,2025-09-24T19:32:40.059414867Z,160,1,432669,C,A,64.830000000,1,26,8058566325942,128,18895,94256802,CLX5
2025-09-24T19:32:40.699567740Z,2025-09-24T19:32:40.699428297Z,160,1,432669,A,B,64.720000000,1,26,8058566325952,128,20364,94256804,CLX5
2025-09-24T19:32:40.699721494Z,2025-09-24T19:32:40.699585865Z,160,1,432669,C,B,64.810000000,1,26,8058566324948,128,18879,94256805,CLX5
2025-09-24T19:32:42.919765204Z,2025-09-24T19:32:42.919615081Z,160,1,432669,A,A,64.830000000,1,26,8058566325955,128,21381,94256829,CLX5
2025-09-24T19:32:42.919907500Z,2025-09-24T19:32:42.919641747Z,160,1,432669,C,B,64.820000000,1,26,8058566325950,128,17941,94256835,CLX5
2025-09-24T19:32:42.919970649Z,2025-09-24T19:32:42.919652421Z,160,1,432669,A,B,64.810000000,1,26,8058566325959,128,20472,94256837,CLX5
2025-09-24T19:32:42.920010268Z,2025-09-24T19:32:42.919801619Z,160,1,432669,C,B,64.820000000,1,26,8058566325951,128,20828,94256839,CLX5
2025-09-24T19:32:42.920346281Z,2025-09-24T19:32:42.920019913Z,160,1,432669,A,B,64.820000000,1,26,8058566325962,128,21443,94256847,CLX5
2025-09-24T19:32:42.920485850Z,2025-09-24T19:32:42.920358413Z,160,1,432669,C,A,64.830000000,1,26,8058566325955,128,22108,94256849,CLX5
2025-09-24T19:32:42.921073600Z,2025-09-24T19:32:42.920932237Z,160,1,432669,A,B,64.820000000,2,26,8058566325963,128,21519,94256853,CLX5
2025-09-24T19:32:47.945238625Z,2025-09-24T19:32:47.945027047Z,160,1,432669,C,A,64.830000000,1,26,8058566325939,128,15647,94256963,CLX5
2025-09-24T19:32:47.945306266Z,2025-09-24T19:32:47.945049931Z,160,1,432669,C,A,64.830000000,1,26,8058566325941,128,16019,94256967,CLX5
2025-09-24T19:32:47.945444146Z,2025-09-24T19:32:47.945183441Z,160,1,432669,C,A,64.830000000,1,26,8058566325781,128,16100,94256973,CLX5
2025-09-24T19:32:47.945576342Z,2025-09-24T19:32:47.945325037Z,160,1,432669,A,B,64.820000000,1,26,8058566326005,128,18839,94256982,CLX5
2025-09-24T19:32:47.945634692Z,2025-09-24T19:32:47.945382039Z,160,1,432669,M,A,64.840000000,1,26,8058566325943,128,15444,94256985,CLX5
2025-09-24T19:32:50.953829301Z,2025-09-24T19:32:50.953661689Z,160,1,432669,A,A,64.830000000,1,26,8058566326135,128,19167,94257249,CLX5
2025-09-24T19:32:50.954199988Z,2025-09-24T19:32:50.953866889Z,160,1,432669,T,A,64.820000000,1,26,8058566326136,0,18171,94257251,CLX5
2025-09-24T19:32:50.954199988Z,2025-09-24T19:32:50.953866889Z,160,1,432669,F,B,64.820000000,1,26,8058566323002,0,18171,94257251,CLX5
2025-09-24T19:32:50.954217682Z,2025-09-24T19:32:50.953866889Z,160,1,432669,C,B,64.820000000,1,26,8058566323002,128,16685,94257252,CLX5
2025-09-24T19:32:50.954441388Z,2025-09-24T19:32:50.954172865Z,160,1,432669,A,A,64.830000000,1,26,8058566326138,128,16087,94257257,CLX5
2025-09-24T19:32:50.954492934Z,2025-09-24T19:32:50.954176013Z,160,1,432669,A,A,64.830000000,1,26,8058566326139,128,15648,94257259,CLX5
2025-09-24T19:32:50.954520834Z,2025-09-24T19:32:50.954180563Z,160,1,432669,A,A,64.830000000,1,26,8058566326140,128,15857,94257260,CLX5
2025-09-24T19:32:50.954547697Z,2025-09-24T19:32:50.954183501Z,160,1,432669,A,A,64.830000000,1,26,8058566326141,128,16059,94257261,CLX5
2025-09-24T19:32:50.954624739Z,2025-09-24T19:32:50.954373247Z,160,1,432669,A,A,64.830000000,1,26,8058566326143,128,15339,94257264,CLX5
2025-09-24T19:32:50.954790426Z,2025-09-24T19:32:50.954564259Z,160,1,432669,M,A,64.830000000,1,26,8058566325943,128,14692,94257275,CLX5
2025-09-24T19:32:50.954938104Z,2025-09-24T19:32:50.954806263Z,160,1,432669,C,B,64.820000000,1,26,8058566326005,128,18931,94257283,CLX5
2025-09-24T19:32:51.199158510Z,2025-09-24T19:32:51.199022547Z,160,1,432669,C,B,64.820000000,1,26,8058566325962,128,15258,94257335,CLX5
2025-09-24T19:32:51.199293210Z,2025-09-24T19:32:51.199168097Z,160,1,432669,C,B,64.820000000,2,26,8058566325963,128,18582,94257344,CLX5
2025-09-24T19:32:51.199927461Z,2025-09-24T19:32:51.199803243Z,160,1,432669,A,B,64.820000000,1,26,8058566326161,128,17987,94257345,CLX5
2025-09-24T19:32:51.200065432Z,2025-09-24T19:32:51.199942265Z,160,1,432669,C,A,64.830000000,1,26,8058566326143,128,18796,94257349,CLX5
2025-09-24T19:32:51.200166012Z,2025-09-24T19:32:51.200042061Z,160,1,432669,C,B,64.820000000,1,26,8058566326161,128,18356,94257353,CLX5
2025-09-24T19:32:51.200706233Z,2025-09-24T19:32:51.200313709Z,160,1,432669,A,B,64.820000000,2,26,8058566326167,128,15231,94257368,CLX5
2025-09-24T19:32:51.200744884Z,2025-09-24T19:32:51.200415695Z,160,1,432669,M,A,64.940000000,1,26,8058565075241,128,15013,94257370,CLX5
2025-09-24T19:32:51.200980080Z,2025-09-24T19:32:51.200609011Z,160,1,432669,C,B,64.820000000,2,26,8058566326167,128,14377,94257381,CLX5
2025-09-24T19:32:51.201602081Z,2025-09-24T19:32:51.201342419Z,160,1,432669,A,B,64.820000000,2,26,8058566326174,128,16328,94257403,CLX5
2025-09-24T19:32:51.202567898Z,2025-09-24T19:32:51.202303779Z,160,1,432669,A,B,64.820000000,1,26,8058566326177,128,19113,94257416,CLX5
2025-09-24T19:32:51.202601335Z,2025-09-24T19:32:51.202308023Z,160,1,432669,C,A,64.830000000,1,26,8058566326141,128,15419,94257417,CLX5
2025-09-24T19:32:51.202723210Z,2025-09-24T19:32:51.202332865Z,160,1,432669,C,B,64.820000000,1,26,8058566326177,128,14829,94257421,CLX5
2025-09-24T19:32:51.202746149Z,2025-09-24T19:32:51.202408223Z,160,1,432669,M,A,64.950000000,1,26,8058565075241,128,14958,94257423,CLX5
2025-09-24T19:32:51.202806073Z,2025-09-24T19:32:51.202532305Z,160,1,432669,A,A,64.830000000,1,26,8058566326180,128,20524,94257425,CLX5
2025-09-24T19:32:51.202833574Z,2025-09-24T19:32:51.202576521Z,160,1,432669,A,B,64.820000000,1,26,8058566326181,128,14476,94257426,CLX5
2025-09-24T19:32:51.252232709Z,2025-09-24T19:32:51.252108935Z,160,1,432669,C,A,64.830000000,1,26,8058566326180,128,15333,94257467,CLX5
2025-09-24T19:32:51.252356642Z,2025-09-24T19:32:51.252240489Z,160,1,432669,C,A,64.830000000,1,26,8058566326139,128,15499,94257470,CLX5
2025-09-24T19:32:51.252387621Z,2025-09-24T19:32:51.252242487Z,160,1,432669,A,A,64.830000000,1,26,8058566326195,128,17703,94257471,CLX5
2025-09-24T19:32:51.252412534Z,2025-09-24T19:32:51.252242965Z,160,1,432669,C,A,64.830000000,1,26,8058566326140,128,15410,94257472,CLX5
2025-09-24T19:32:51.252511601Z,2025-09-24T19:32:51.252395465Z,160,1,432669,A,A,64.830000000,1,26,8058566326196,128,18457,94257476,CLX5
2025-09-24T19:32:51.252880399Z,2025-09-24T19:32:51.252759883Z,160,1,432669,C,A,64.830000000,1,26,8058566326195,128,15517,94257489,CLX5
2025-09-24T19:32:51.954857822Z,2025-09-24T19:32:51.954729425Z,160,1,432669,C,B,64.820000000,1,26,8058566326181,128,18560,94257581,CLX5
2025-09-24T19:32:51.954890046Z,2025-09-24T19:32:51.954733363Z,160,1,432669,A,A,64.830000000,1,26,8058566326246,128,14657,94257582,CLX5
2025-09-24T19:32:53.935594141Z,2025-09-24T19:32:53.934727825Z,160,1,432669,T,N,64.830000000,2,26,0,0,18491,94257796,CLX5
2025-09-24T19:32:53.935594141Z,2025-09-24T19:32:53.934727825Z,160,1,432669,F,N,64.830000000,2,26,8058566324580,0,18491,94257796,CLX5
2025-09-24T19:32:53.935605399Z,2025-09-24T19:32:53.934727825Z,160,1,432669,C,A,64.830000000,2,26,8058566324580,128,15197,94257797,CLX5
2025-09-24T19:32:53.935989333Z,2025-09-24T19:32:53.935567079Z,160,1,432669,A,B,64.820000000,1,26,8058566326342,128,18320,94257821,CLX5
2025-09-24T19:32:53.936112974Z,2025-09-24T19:32:53.935575659Z,160,1,432669,C,A,64.830000000,1,26,8058566326196,128,18555,94257826,CLX5
2025-09-24T19:32:53.936292370Z,2025-09-24T19:32:53.935597989Z,160,1,432669,C,A,64.830000000,1,26,8058566326246,128,15412,94257834,CLX5
2025-09-24T19:32:53.936371408Z,2025-09-24T19:32:53.935603671Z,160,1,432669,A,B,64.820000000,1,26,8058566326351,128,15503,94257837,CLX5
2025-09-24T19:32:53.936422424Z,2025-09-24T19:32:53.935610351Z,160,1,432669,C,B,64.820000000,2,26,8058566326174,128,18458,94257839,CLX5
2025-09-24T19:32:53.936852927Z,2025-09-24T19:32:53.935997815Z,160,1,432669,A,A,64.830000000,1,26,8058566326357,128,18491,94257863,CLX5
2025-09-24T19:32:53.936925837Z,2025-09-24T19:32:53.936001939Z,160,1,432669,A,A,64.830000000,1,26,8058566326358,128,14363,94257865,CLX5
2025-09-24T19:32:53.936979072Z,2025-09-24T19:32:53.936123391Z,160,1,432669,C,A,64.830000000,1,26,8058566326358,128,15677,94257867,CLX5
2025-09-24T19:32:53.937138930Z,2025-09-24T19:32:53.936380199Z,160,1,432669,A,A,64.830000000,1,26,8058566326364,128,15130,94257875,CLX5
2025-09-24T19:32:53.937223398Z,2025-09-24T19:32:53.936414105Z,160,1,432669,A,A,64.830000000,1,26,8058566326365,128,14600,94257878,CLX5
2025-09-24T19:32:53.940002444Z,2025-09-24T19:32:53.939868609Z,160,1,432669,A,A,64.830000000,1,26,8058566326389,128,19418,94257979,CLX5
2025-09-24T19:32:53.946871843Z,2025-09-24T19:32:53.946562681Z,160,1,432669,C,B,64.820000000,1,26,8058566326342,128,15232,94258027,CLX5
2025-09-24T19:32:53.946928026Z,2025-09-24T19:32:53.946571053Z,160,1,432669,C,B,64.820000000,1,26,8058566326351,128,17406,94258029,CLX5
2025-09-24T19:32:53.947006089Z,2025-09-24T19:32:53.946835445Z,160,1,432669,C,A,64.830000000,1,26,8058566326365,128,15209,94258033,CLX5
2025-09-24T19:32:53.947118142Z,2025-09-24T19:32:53.946997351Z,160,1,432669,A,B,64.820000000,1,26,8058566326402,128,16217,94258035,CLX5
2025-09-24T19:32:53.987211177Z,2025-09-24T19:32:53.987042945Z,160,1,432669,C,A,64.830000000,1,26,8058566326357,128,15389,94258058,CLX5
2025-09-24T19:32:53.987259152Z,2025-09-24T19:32:53.987046267Z,160,1,432669,C,A,64.830000000,1,26,8058566326364,128,15735,94258060,CLX5
2025-09-24T19:32:53.987370844Z,2025-09-24T19:32:53.987219539Z,160,1,432669,A,A,64.830000000,1,26,8058566326412,128,15322,94258063,CLX5
2025-09-24T19:32:53.987468898Z,2025-09-24T19:32:53.987266923Z,160,1,432669,C,A,64.830000000,1,26,8058566326412,128,15343,94258071,CLX5
2025-09-24T19:32:53.987559694Z,2025-09-24T19:32:53.987378259Z,160,1,432669,A,A,64.830000000,1,26,8058566326413,128,15188,94258077,CLX5
2025-09-24T19:32:53.987796102Z,2025-09-24T19:32:53.987476347Z,160,1,432669,C,A,64.830000000,1,26,8058566326413,128,18662,94258092,CLX5
2025-09-24T19:32:53.987895944Z,2025-09-24T19:32:53.987567101Z,160,1,432669,A,A,64.830000000,1,26,8058566326414,128,19384,94258101,CLX5
2025-09-24T19:32:53.988019939Z,2025-09-24T19:32:53.987902971Z,160,1,432669,A,A,64.830000000,1,26,8058566326415,128,18414,94258105,CLX5
2025-09-24T19:32:54.316201145Z,2025-09-24T19:32:54.316035913Z,160,1,432669,A,B,64.820000000,3,26,8058566326500,128,18693,94258253,CLX5
2025-09-24T19:32:54.316335031Z,2025-09-24T19:32:54.316209513Z,160,1,432669,C,A,64.830000000,1,26,8058566326414,128,18772,94258254,CLX5
2025-09-24T19:32:54.316363338Z,2025-09-24T19:32:54.316237217Z,160,1,432669,C,A,64.830000000,1,26,8058566326415,128,15324,94258255,CLX5
2025-09-24T19:32:54.316497723Z,2025-09-24T19:32:54.316377177Z,160,1,432669,C,A,64.830000000,1,26,8058566326389,128,15819,94258257,CLX5
2025-09-24T19:32:55.354667639Z,2025-09-24T19:32:55.354514435Z,160,1,432669,A,B,64.820000000,2,26,8058566326607,128,19313,94258480,CLX5
2025-09-24T19:32:55.356612044Z,2025-09-24T19:32:55.354724513Z,160,1,432669,C,A,64.860000000,1,26,8058566325809,128,14693,94258490,CLX5
2025-09-24T19:32:55.356649635Z,2025-09-24T19:32:55.354777139Z,160,1,432669,M,A,64.840000000,1,26,8058566325943,128,19853,94258491,CLX5
2025-09-24T19:32:55.356717431Z,2025-09-24T19:32:55.356346841Z,160,1,432669,A,A,64.830000000,1,26,8058566326610,128,14701,94258493,CLX5
2025-09-24T19:32:55.356751436Z,2025-09-24T19:32:55.356350353Z,160,1,432669,A,A,64.830000000,1,26,8058566326611,128,20037,94258494,CLX5
2025-09-24T19:32:55.356773768Z,2025-09-24T19:32:55.356361547Z,160,1,432669,A,A,64.830000000,1,26,8058566326612,128,15824,94258495,CLX5
2025-09-24T19:32:55.356861815Z,2025-09-24T19:32:55.356448021Z,160,1,432669,A,A,64.830000000,1,26,8058566326614,128,18887,94258499,CLX5
2025-09-24T19:32:55.356932359Z,2025-09-24T19:32:55.356460309Z,160,1,432669,C,B,64.820000000,2,26,8058566326607,128,14500,94258502,CLX5
2025-09-24T19:32:55.357228093Z,2025-09-24T19:32:55.356759103Z,160,1,432669,C,A,64.830000000,1,26,8058566326612,128,15384,94258517,CLX5
2025-09-24T19:32:55.357378551Z,2025-09-24T19:32:55.356947697Z,160,1,432669,A,A,64.830000000,1,26,8058566326624,128,18608,94258523,CLX5
2025-09-24T19:32:55.357507515Z,2025-09-24T19:32:55.357034631Z,160,1,432669,A,A,64.860000000,1,26,8058566326626,128,14772,94258530,CLX5
2025-09-24T19:32:55.357803003Z,2025-09-24T19:32:55.357297467Z,160,1,432669,C,A,64.830000000,1,26,8058566326611,128,18215,94258545,CLX5
2025-09-24T19:32:55.357830212Z,2025-09-24T19:32:55.357297639Z,160,1,432669,C,A,64.830000000,1,26,8058566326610,128,15105,94258546,CLX5
2025-09-24T19:32:55.358065953Z,2025-09-24T19:32:55.357810641Z,160,1,432669,A,A,64.830000000,1,26,8058566326635,128,15625,94258561,CLX5
2025-09-24T19:32:55.358239258Z,2025-09-24T19:32:55.358073573Z,160,1,432669,A,A,64.830000000,1,26,8058566326638,128,19055,94258569,CLX5
2025-09-24T19:32:55.358299013Z,2025-09-24T19:32:55.358146147Z,160,1,432669,C,A,64.830000000,1,26,8058566326638,128,15826,94258571,CLX5
2025-09-24T19:32:55.358375793Z,2025-09-24T19:32:55.358164137Z,160,1,432669,C,A,64.830000000,1,26,8058566326624,128,14499,94258573,CLX5
2025-09-24T19:32:55.381347804Z,2025-09-24T19:32:55.381209687Z,160,1,432669,C,A,64.830000000,1,26,8058566326614,128,19519,94258587,CLX5
2025-09-24T19:32:55.381471269Z,2025-09-24T19:32:55.381355925Z,160,1,432669,C,A,64.830000000,1,26,8058566326635,128,18889,94258588,CLX5
2025-09-24T19:32:55.410949143Z,2025-09-24T19:32:55.410815703Z,160,1,432669,A,A,64.830000000,1,26,8058566326647,128,19564,94258602,CLX5
2025-09-24T19:32:55.411075841Z,2025-09-24T19:32:55.410956835Z,160,1,432669,A,A,64.830000000,1,26,8058566326648,128,18854,94258604,CLX5
2025-09-24T19:32:55.456836036Z,2025-09-24T19:32:55.456699931Z,160,1,432669,M,A,64.830000000,1,26,8058566325943,128,19669,94258624,CLX5
2025-09-24T19:32:55.661856067Z,2025-09-24T19:32:55.661722643Z,160,1,432669,C,A,64.860000000,1,26,8058566326626,128,18805,94258656,CLX5
2025-09-24T19:32:56.885357680Z,2025-09-24T19:32:56.885196949Z,160,1,432669,C,A,64.830000000,1,26,8058566326135,128,20710,94258742,CLX5
2025-09-24T19:32:56.885532713Z,2025-09-24T19:32:56.885415359Z,160,1,432669,C,A,64.830000000,1,26,8058566326648,128,15326,94258746,CLX5
2025-09-24T19:32:56.885669932Z,2025-09-24T19:32:56.885540191Z,160,1,432669,C,A,64.830000000,1,26,8058566326647,128,19091,94258747,CLX5
2025-09-24T19:32:56.885800240Z,2025-09-24T19:32:56.885677349Z,160,1,432669,A,A,64.830000000,1,26,8058566326714,128,19242,94258748,CLX5
2025-09-24T19:32:57.031734668Z,2025-09-24T19:32:57.031414073Z,160,1,432669,T,A,64.820000000,1,26,8058566326716,0,18319,94258791,CLX5
2025-09-24T19:32:57.031734668Z,2025-09-24T19:32:57.031414073Z,160,1,432669,F,B,64.820000000,1,26,8058566323034,0,18319,94258791,CLX5
2025-09-24T19:32:57.031745243Z,2025-09-24T19:32:57.031414073Z,160,1,432669,M,B,64.820000000,1,26,8058566323034,128,15910,94258792,CLX5
2025-09-24T19:32:57.031891601Z,2025-09-24T19:32:57.031725405Z,160,1,432669,A,A,64.830000000,1,26,8058566326719,128,14906,94258795,CLX5
2025-09-24T19:32:57.031922703Z,2025-09-24T19:32:57.031727709Z,160,1,432669,A,A,64.830000000,1,26,8058566326720,128,15457,94258796,CLX5
2025-09-24T19:32:57.032253326Z,2025-09-24T19:32:57.031810457Z,160,1,432669,C,A,64.830000000,1,26,8058566326719,128,18488,94258806,CLX5
2025-09-24T19:32:57.032811770Z,2025-09-24T19:32:57.032557325Z,160,1,432669,C,B,64.820000000,1,26,8058566326402,128,15452,94258838,CLX5
2025-09-24T19:32:57.033074919Z,2025-09-24T19:32:57.032856753Z,160,1,432669,A,A,64.860000000,1,26,8058566326733,128,15118,94258843,CLX5
2025-09-24T19:32:57.033700277Z,2025-09-24T19:32:57.033560711Z,160,1,432669,A,B,64.820000000,1,26,8058566326740,128,15796,94258868,CLX5
2025-09-24T19:32:57.033832074Z,2025-09-24T19:32:57.033708333Z,160,1,432669,C,B,64.820000000,1,26,8058566326740,128,18921,94258871,CLX5
2025-09-24T19:32:57.071384136Z,2025-09-24T19:32:57.071234959Z,160,1,432669,A,B,64.820000000,1,26,8058566326745,128,18798,94258880,CLX5
2025-09-24T19:32:57.071411591Z,2025-09-24T19:32:57.071251721Z,160,1,432669,C,B,64.810000000,1,26,8058566325959,128,14887,94258881,CLX5
2025-09-24T19:32:57.071515864Z,2025-09-24T19:32:57.071395637Z,160,1,432669,A,B,64.820000000,1,26,8058566326746,128,18610,94258882,CLX5
2025-09-24T19:33:00.593755548Z,2025-09-24T19:33:00.593586879Z,160,1,432669,A,B,64.820000000,1,26,8058566326782,128,20111,94259059,CLX5
2025-09-24T19:33:00.593901407Z,2025-09-24T19:33:00.593767371Z,160,1,432669,C,A,64.830000000,1,26,8058566326714,128,19114,94259060,CLX5
2025-09-24T19:33:00.594044417Z,2025-09-24T19:33:00.593918987Z,160,1,432669,C,A,64.830000000,1,26,8058566326720,128,18918,94259063,CLX5
2025-09-24T19:33:00.594361623Z,2025-09-24T19:33:00.594237981Z,160,1,432669,A,A,64.830000000,1,26,8058566326784,128,19926,94259068,CLX5
2025-09-24T19:33:00.594484435Z,2025-09-24T19:33:00.594370703Z,160,1,432669,A,A,64.830000000,1,26,8058566326785,128,14162,94259072,CLX5
2025-09-24T19:33:01.081188258Z,2025-09-24T19:33:01.080708849Z,160,1,432669,A,A,64.830000000,1,26,8058566326787,128,16626,94259089,CLX5
2025-09-24T19:33:01.081220413Z,2025-09-24T19:33:01.080720505Z,160,1,432669,A,A,64.830000000,1,26,8058566326788,128,18575,94259090,CLX5
2025-09-24T19:33:01.081379726Z,2025-09-24T19:33:01.080727299Z,160,1,432669,C,B,64.820000000,1,26,8058566326746,128,15425,94259096,CLX5
2025-09-24T19:33:01.082242867Z,2025-09-24T19:33:01.081053437Z,160,1,432669,A,B,64.820000000,1,26,8058566326798,128,15475,94259132,CLX5
2025-09-24T19:33:01.082333639Z,2025-09-24T19:33:01.081087457Z,160,1,432669,M,A,64.940000000,1,26,8058565075241,128,16059,94259135,CLX5
2025-09-24T19:33:01.082352117Z,2025-09-24T19:33:01.081088301Z,160,1,432669,A,A,64.830000000,1,26,8058566326799,128,15701,94259136,CLX5
2025-09-24T19:33:01.082386606Z,2025-09-24T19:33:01.081271117Z,160,1,432669,A,A,64.860000000,2,26,8058566326800,128,15269,94259138,CLX5
2025-09-24T19:33:01.082515200Z,2025-09-24T19:33:01.081283135Z,160,1,432669,C,B,64.820000000,1,26,8058566326798,128,18534,94259143,CLX5
2025-09-24T19:33:01.083126373Z,2025-09-24T19:33:01.082207863Z,160,1,432669,A,B,64.820000000,1,26,8058566326816,128,18360,94259182,CLX5
2025-09-24T19:33:01.083432451Z,2025-09-24T19:33:01.082598257Z,160,1,432669,M,A,64.840000000,3,26,8058566288785,128,18291,94259201,CLX5
2025-09-24T19:33:01.088588740Z,2025-09-24T19:33:01.088265847Z,160,1,432669,C,A,64.860000000,2,26,8058566326800,128,14899,94259272,CLX5
2025-09-24T19:33:01.088763458Z,2025-09-24T19:33:01.088396267Z,160,1,432669,M,A,64.950000000,1,26,8058565075241,128,19619,94259279,CLX5
2025-09-24T19:33:01.089071870Z,2025-09-24T19:33:01.088709347Z,160,1,432669,C,A,64.830000000,1,26,8058566326787,128,20080,94259291,CLX5
2025-09-24T19:33:01.089327063Z,2025-09-24T19:33:01.089086035Z,160,1,432669,C,A,64.830000000,1,26,8058566326799,128,15593,94259300,CLX5
2025-09-24T19:33:01.096255495Z,2025-09-24T19:33:01.096130587Z,160,1,432669,C,A,64.830000000,1,26,8058566326788,128,18991,94259326,CLX5
2025-09-24T19:33:01.096391224Z,2025-09-24T19:33:01.096269379Z,160,1,432669,A,A,64.830000000,1,26,8058566326849,128,19046,94259327,CLX5
2025-09-24T19:33:01.096438269Z,2025-09-24T19:33:01.096322041Z,160,1,432669,M,A,64.840000000,1,26,8058566325943,128,16600,94259329,CLX5
2025-09-24T19:33:01.196744125Z,2025-09-24T19:33:01.196592155Z,160,1,432669,M,A,64.830000000,1,26,8058566325943,128,19487,94259363,CLX5
2025-09-24T19:33:01.196890498Z,2025-09-24T19:33:01.196758149Z,160,1,432669,C,B,64.820000000,1,26,8058566326816,128,18674,94259364,CLX5
2025-09-24T19:33:01.197024008Z,2025-09-24T19:33:01.196899839Z,160,1,432669,A,B,64.820000000,1,26,8058566326860,128,18341,94259365,CLX5
2025-09-24T19:33:03.068151036Z,2025-09-24T19:33:03.067669185Z,160,1,432669,T,N,64.830000000,1,26,0,0,18340,94259435,CLX5
2025-09-24T19:33:03.068151036Z,2025-09-24T19:33:03.067669185Z,160,1,432669,F,N,64.830000000,1,26,8058566324594,0,18340,94259435,CLX5
2025-09-24T19:33:03.068168046Z,2025-09-24T19:33:03.067669185Z,160,1,432669,C,A,64.830000000,1,26,8058566324594,128,17181,94259436,CLX5
2025-09-24T19:33:03.069144131Z,2025-09-24T19:33:03.068928285Z,160,1,432669,A,B,64.820000000,2,26,8058566326897,128,19183,94259471,CLX5
2025-09-24T19:33:03.069445194Z,2025-09-24T19:33:03.069152511Z,160,1,432669,C,A,64.830000000,1,26,8058566326784,128,14913,94259481,CLX5
2025-09-24T19:33:03.069499151Z,2025-09-24T19:33:03.069157217Z,160,1,432669,C,A,64.830000000,1,26,8058566326785,128,19241,94259483,CLX5
2025-09-24T19:33:03.069712966Z,2025-09-24T19:33:03.069215657Z,160,1,432669,M,A,64.840000000,1,26,8058566325943,128,16593,94259493,CLX5
2025-09-24T19:33:03.069896946Z,2025-09-24T19:33:03.069453631Z,160,1,432669,A,A,64.830000000,1,26,8058566326904,128,15950,94259504,CLX5
2025-09-24T19:33:03.069931059Z,2025-09-24T19:33:03.069457913Z,160,1,432669,A,A,64.830000000,1,26,8058566326905,128,19140,94259505,CLX5
2025-09-24T19:33:03.069965141Z,2025-09-24T19:33:03.069467609Z,160,1,432669,C,B,64.820000000,2,26,8058566326897,128,15188,94259506,CLX5
2025-09-24T19:33:03.070114041Z,2025-09-24T19:33:03.069569787Z,160,1,432669,C,B,64.820000000,1,26,8058566326860,128,15156,94259514,CLX5
2025-09-24T19:33:03.070375907Z,2025-09-24T19:33:03.069730119Z,160,1,432669,A,B,64.820000000,1,26,8058566326913,128,18796,94259528,CLX5
2025-09-24T19:33:03.070497022Z,2025-09-24T19:33:03.069939427Z,160,1,432669,A,B,64.820000000,1,26,8058566326915,128,18220,94259534,CLX5
2025-09-24T19:33:03.075220482Z,2025-09-24T19:33:03.075066215Z,160,1,432669,A,A,64.830000000,1,26,8058566326935,128,18871,94259585,CLX5
2025-09-24T19:33:03.169794546Z,2025-09-24T19:33:03.169677857Z,160,1,432669,M,A,64.830000000,1,26,8058566325943,128,15751,94259642,CLX5
2025-09-24T19:33:03.169986144Z,2025-09-24T19:33:03.169810159Z,160,1,432669,C,B,64.820000000,1,26,8058566326913,128,14640,94259647,CLX5
2025-09-24T19:33:03.170047228Z,2025-09-24T19:33:03.169817973Z,160,1,432669,C,B,64.820000000,1,26,8058566326915,128,18673,94259649,CLX5
2025-09-24T19:33:03.170226945Z,2025-09-24T19:33:03.170056081Z,160,1,432669,A,B,64.820000000,1,26,8058566326956,128,15431,94259654,CLX5
2025-09-24T19:33:03.488589017Z,2025-09-24T19:33:03.488465935Z,160,1,432669,C,A,65.220000000,1,26,8058566273414,128,18884,94259705,CLX5
2025-09-24T19:33:03.519756632Z,2025-09-24T19:33:03.519642307Z,160,1,432669,A,A,65.140000000,1,26,8058566326983,128,17852,94259716,CLX5
2025-09-24T19:33:05.017542557Z,2025-09-24T19:33:05.017084449Z,160,1,432669,C,B,64.820000000,1,26,8058566326956,128,15452,94259918,CLX5
2025-09-24T19:33:12.739944217Z,2025-09-24T19:33:12.739763309Z,160,1,432669,A,B,64.820000000,1,26,8058566327162,128,20059,94260161,CLX5
2025-09-24T19:33:12.740309005Z,2025-09-24T19:33:12.740179315Z,160,1,432669,A,B,64.820000000,1,26,8058566327164,128,18533,94260166,CLX5
2025-09-24T19:33:15.597278785Z,2025-09-24T19:33:15.597140181Z,160,1,432669,M,A,64.960000000,1,26,8058566157942,128,20184,94260224,CLX5
2025-09-24T19:33:15.855817280Z,2025-09-24T19:33:15.855446051Z,160,1,432669,T,B,64.830000000,1,26,8058566327177,0,19391,94260234,CLX5
2025-09-24T19:33:15.855817280Z,2025-09-24T19:33:15.855446051Z,160,1,432669,F,A,64.830000000,1,26,8058566324722,0,19391,94260234,CLX5
2025-09-24T19:33:15.855829015Z,2025-09-24T19:33:15.855446051Z,160,1,432669,C,A,64.830000000,1,26,8058566324722,128,16902,94260235,CLX5
2025-09-24T19:33:15.855933711Z,2025-09-24T19:33:15.855784841Z,160,1,432669,A,B,64.820000000,1,26,8058566327178,128,18945,94260236,CLX5
2025-09-24T19:33:15.856010199Z,2025-09-24T19:33:15.855792443Z,160,1,432669,C,A,64.830000000,1,26,8058566326904,128,15363,94260239,CLX5
2025-09-24T19:33:15.856173084Z,2025-09-24T19:33:15.856018801Z,160,1,432669,A,A,64.830000000,1,26,8058566327182,128,15707,94260241,CLX5
2025-09-24T19:33:15.856207887Z,2025-09-24T19:33:15.856021393Z,160,1,432669,C,B,64.820000000,1,26,8058566327164,128,15667,94260242,CLX5
2025-09-24T19:33:15.856260316Z,2025-09-24T19:33:15.856083771Z,160,1,432669,M,A,64.840000000,1,26,8058566325943,128,20095,94260244,CLX5
2025-09-24T19:33:15.856344024Z,2025-09-24T19:33:15.856221007Z,160,1,432669,A,B,64.820000000,1,26,8058566327184,128,15522,94260247,CLX5
2025-09-24T19:33:16.388975919Z,2025-09-24T19:33:16.388754317Z,160,1,432669,C,B,64.820000000,1,26,8058566327184,128,18365,94260275,CLX5
2025-09-24T19:33:16.389217359Z,2025-09-24T19:33:16.389056243Z,160,1,432669,A,B,64.820000000,1,26,8058566327196,128,15414,94260286,CLX5
2025-09-24T19:33:16.389390787Z,2025-09-24T19:33:16.389103703Z,160,1,432669,M,A,64.830000000,1,26,8058566325943,128,16769,94260293,CLX5
2025-09-24T19:33:16.389564130Z,2025-09-24T19:33:16.389400157Z,160,1,432669,C,B,64.820000000,1,26,8058566327196,128,15867,94260297,CLX5
2025-09-24T19:33:16.389698646Z,2025-09-24T19:33:16.389572393Z,160,1,432669,A,B,64.820000000,1,26,8058566327202,128,19148,94260298,CLX5
2025-09-24T19:33:16.389730471Z,2025-09-24T19:33:16.389604569Z,160,1,432669,C,A,64.860000000,1,26,8058566326733,128,15265,94260299,CLX5
2025-09-24T19:33:16.695923955Z,2025-09-24T19:33:16.695796431Z,160,1,432669,C,A,64.830000000,1,26,8058566327182,128,18817,94260323,CLX5
2025-09-24T19:33:16.696055837Z,2025-09-24T19:33:16.695932207Z,160,1,432669,A,A,64.830000000,1,26,8058566327209,128,18629,94260324,CLX5
2025-09-24T19:33:16.696082086Z,2025-09-24T19:33:16.695944785Z,160,1,432669,M,A,64.840000000,1,26,8058566325943,128,16144,94260325,CLX5
2025-09-24T19:33:16.696113257Z,2025-09-24T19:33:16.695945109Z,160,1,432669,C,A,64.830000000,1,26,8058566326905,128,15858,94260326,CLX5
2025-09-24T19:33:17.220987254Z,2025-09-24T19:33:17.218873717Z,160,1,432669,C,A,64.830000000,1,26,8058566326849,128,15821,94260562,CLX5
2025-09-24T19:33:17.222861391Z,2025-09-24T19:33:17.220996049Z,160,1,432669,C,A,64.830000000,1,26,8058566327209,128,16551,94260692,CLX5
2025-09-24T19:33:17.224302913Z,2025-09-24T19:33:17.222704871Z,160,1,432669,A,B,64.820000000,1,26,8058566327347,128,18616,94260798,CLX5
2025-09-24T19:33:17.224481801Z,2025-09-24T19:33:17.222870211Z,160,1,432669,A,B,64.820000000,2,26,8058566327349,128,15272,94260811,CLX5
2025-09-24T19:33:17.225715536Z,2025-09-24T19:33:17.223479959Z,160,1,432669,A,B,64.810000000,2,26,8058566327364,128,19204,94260861,CLX5
2025-09-24T19:33:17.225877445Z,2025-09-24T19:33:17.223484661Z,160,1,432669,C,A,64.830000000,2,26,8058566325940,128,16552,94260865,CLX5
2025-09-24T19:33:17.225954963Z,2025-09-24T19:33:17.223489635Z,160,1,432669,C,B,64.780000000,2,26,8058566325641,128,18644,94260867,CLX5
2025-09-24T19:33:17.226728107Z,2025-09-24T19:33:17.224172203Z,160,1,432669,A,A,64.830000000,1,26,8058566327387,128,20778,94260920,CLX5
2025-09-24T19:33:17.226789282Z,2025-09-24T19:33:17.224182763Z,160,1,432669,A,A,64.830000000,1,26,8058566327389,128,16159,94260923,CLX5
2025-09-24T19:33:17.226826597Z,2025-09-24T19:33:17.224195971Z,160,1,432669,A,A,64.830000000,1,26,8058566327390,128,18152,94260924,CLX5
2025-09-24T19:33:17.226908032Z,2025-09-24T19:33:17.224244835Z,160,1,432669,C,B,64.820000000,2,26,8058566327349,128,15750,94260926,CLX5
2025-09-24T19:33:17.226998313Z,2025-09-24T19:33:17.224311915Z,160,1,432669,C,A,64.830000000,1,26,8058566327389,128,16489,94260929,CLX5
2025-09-24T19:33:17.227036127Z,2025-09-24T19:33:17.224315257Z,160,1,432669,C,A,64.830000000,1,26,8058566327390,128,19433,94260930,CLX5
2025-09-24T19:33:17.227215523Z,2025-09-24T19:33:17.224719571Z,160,1,432669,C,B,64.810000000,2,26,8058566327364,128,15714,94260940,CLX5
2025-09-24T19:33:17.227947304Z,2025-09-24T19:33:17.225886841Z,160,1,432669,T,B,64.830000000,1,26,8058566327403,0,15138,94260979,CLX5
2025-09-24T19:33:17.227947304Z,2025-09-24T19:33:17.225886841Z,160,1,432669,F,A,64.830000000,1,26,8058566324724,0,15138,94260979,CLX5
2025-09-24T19:33:17.227989695Z,2025-09-24T19:33:17.225886841Z,160,1,432669,M,A,64.830000000,1,26,8058566324724,128,16896,94260980,CLX5
2025-09-24T19:33:17.228032125Z,2025-09-24T19:33:17.225887457Z,160,1,432669,A,A,64.830000000,1,26,8058566327404,128,19434,94260981,CLX5
2025-09-24T19:33:17.228559275Z,2025-09-24T19:33:17.226285455Z,160,1,432669,C,B,64.820000000,1,26,8058566327162,128,22543,94261020,CLX5
2025-09-24T19:33:17.228795032Z,2025-09-24T19:33:17.226330725Z,160,1,432669,A,B,64.820000000,2,26,8058566327423,128,19386,94261032,CLX5
2025-09-24T19:33:17.229048351Z,2025-09-24T19:33:17.226735847Z,160,1,432669,A,A,64.830000000,1,26,8058566327430,128,14820,94261051,CLX5
2025-09-24T19:33:17.229123957Z,2025-09-24T19:33:17.226736153Z,160,1,432669,A,A,64.830000000,1,26,8058566327431,128,18834,94261053,CLX5
2025-09-24T19:33:17.229205276Z,2025-09-24T19:33:17.226797821Z,160,1,432669,C,A,64.830000000,1,26,8058566327404,128,15957,94261057,CLX5
2025-09-24T19:33:17.229261060Z,2025-09-24T19:33:17.226834185Z,160,1,432669,C,A,64.830000000,1,26,8058566327431,128,16318,94261060,CLX5
2025-09-24T19:33:17.229364996Z,2025-09-24T19:33:17.227044013Z,160,1,432669,C,B,64.820000000,1,26,8058566327202,128,16407,94261065,CLX5
2025-09-24T19:33:17.229450247Z,2025-09-24T19:33:17.227477107Z,160,1,432669,A,A,64.830000000,1,26,8058566327439,128,20298,94261069,CLX5
2025-09-24T19:33:17.229479199Z,2025-09-24T19:33:17.227478393Z,160,1,432669,A,A,64.830000000,1,26,8058566327440,128,16046,94261070,CLX5
2025-09-24T19:33:17.229515792Z,2025-09-24T19:33:17.227480103Z,160,1,432669,A,B,64.820000000,1,26,8058566327441,128,15727,94261071,CLX5
2025-09-24T19:33:17.229989655Z,2025-09-24T19:33:17.227965131Z,160,1,432669,C,A,64.830000000,1,26,8058566327439,128,15268,94261100,CLX5
2025-09-24T19:33:17.230126574Z,2025-09-24T19:33:17.227999477Z,160,1,432669,C,A,64.830000000,1,26,8058566327440,128,16457,94261107,CLX5
2025-09-24T19:33:17.230515691Z,2025-09-24T19:33:17.228683947Z,160,1,432669,C,A,64.830000000,1,26,8058566327430,128,15437,94261137,CLX5
2025-09-24T19:33:17.231095440Z,2025-09-24T19:33:17.229473397Z,160,1,432669,A,A,64.830000000,1,26,8058566327476,128,20148,94261171,CLX5
2025-09-24T19:33:17.231127609Z,2025-09-24T19:33:17.229486913Z,160,1,432669,A,A,64.830000000,1,26,8058566327477,128,16382,94261172,CLX5
2025-09-24T19:33:17.231183217Z,2025-09-24T19:33:17.229523277Z,160,1,432669,C,A,64.830000000,1,26,8058566327477,128,16339,94261174,CLX5
2025-09-24T19:33:17.231220832Z,2025-09-24T19:33:17.229523487Z,160,1,432669,C,A,64.830000000,1,26,8058566327476,128,19829,94261175,CLX5
2025-09-24T19:33:17.231344166Z,2025-09-24T19:33:17.229829465Z,160,1,432669,A,A,64.830000000,1,26,8058566327480,128,20679,94261182,CLX5
2025-09-24T19:33:17.231800941Z,2025-09-24T19:33:17.231102713Z,160,1,432669,A,A,64.830000000,1,26,8058566327491,128,16590,94261213,CLX5
2025-09-24T19:33:17.231837465Z,2025-09-24T19:33:17.231103231Z,160,1,432669,A,A,64.830000000,1,26,8058566327492,128,19630,94261214,CLX5
2025-09-24T19:33:17.232454736Z,2025-09-24T19:33:17.231880069Z,160,1,432669,C,A,64.830000000,1,26,8058566327492,128,19920,94261253,CLX5
2025-09-24T19:33:17.232487543Z,2025-09-24T19:33:17.231892701Z,160,1,432669,C,A,64.830000000,1,26,8058566327491,128,15169,94261254,CLX5
2025-09-24T19:33:17.233015915Z,2025-09-24T19:33:17.232438341Z,160,1,432669,A,A,64.830000000,1,26,8058566327517,128,14826,94261286,CLX5
2025-09-24T19:33:17.234087933Z,2025-09-24T19:33:17.233922341Z,160,1,432669,C,A,64.830000000,1,26,8058566327517,128,16360,94261330,CLX5
2025-09-24T19:33:17.234188036Z,2025-09-24T19:33:17.234023193Z,160,1,432669,C,A,64.830000000,1,26,8058566327480,128,14820,94261334,CLX5
2025-09-24T19:33:17.234247284Z,2025-09-24T19:33:17.234075261Z,160,1,432669,C,B,64.820000000,1,26,8058566326745,128,14502,94261336,CLX5
2025-09-24T19:33:17.235281135Z,2025-09-24T19:33:17.235142561Z,160,1,432669,C,A,64.830000000,1,26,8058566327387,128,21165,94261359,CLX5
2025-09-24T19:33:17.238129413Z,2025-09-24T19:33:17.237989067Z,160,1,432669,A,A,64.830000000,1,26,8058566327547,128,17432,94261371,CLX5
2025-09-24T19:33:17.238169424Z,2025-09-24T19:33:17.237990469Z,160,1,432669,A,A,64.830000000,1,26,8058566327548,128,20255,94261372,CLX5
2025-09-24T19:33:17.238385727Z,2025-09-24T19:33:17.238138877Z,160,1,432669,C,A,64.830000000,1,26,8058566327548,128,20336,94261386,CLX5
2025-09-24T19:33:17.240806544Z,2025-09-24T19:33:17.240658881Z,160,1,432669,A,A,64.830000000,1,26,8058566327570,128,19670,94261458,CLX5
2025-09-24T19:33:17.240943263Z,2025-09-24T19:33:17.240815085Z,160,1,432669,C,A,64.830000000,1,26,8058566327570,128,20914,94261460,CLX5
2025-09-24T19:33:17.240978367Z,2025-09-24T19:33:17.240834995Z,160,1,432669,A,B,64.810000000,1,26,8058566327572,128,15273,94261461,CLX5
2025-09-24T19:33:17.256508754Z,2025-09-24T19:33:17.256401437Z,160,1,432669,M,A,64.940000000,1,26,8058565075241,128,18525,94261518,CLX5
2025-09-24T19:33:17.258262491Z,2025-09-24T19:33:17.258097185Z,160,1,432669,M,A,64.950000000,1,26,8058565075241,128,14878,94261568,CLX5
2025-09-24T19:33:17.259224276Z,2025-09-24T19:33:17.259091739Z,160,1,432669,A,B,64.810000000,2,26,8058566327626,128,18549,94261589,CLX5
2025-09-24T19:33:17.259471098Z,2025-09-24T19:33:17.259348777Z,160,1,432669,A,B,64.820000000,2,26,8058566327630,128,15415,94261595,CLX5
2025-09-24T19:33:17.296778381Z,2025-09-24T19:33:17.296622031Z,160,1,432669,A,A,64.830000000,1,26,8058566327688,128,20241,94261723,CLX5
2025-09-24T19:33:17.296815850Z,2025-09-24T19:33:17.296622665Z,160,1,432669,C,B,64.810000000,2,26,8058566327626,128,15942,94261724,CLX5
2025-09-24T19:33:17.297008116Z,2025-09-24T19:33:17.296632207Z,160,1,432669,A,A,64.830000000,1,26,8058566327689,128,15972,94261731,CLX5
2025-09-24T19:33:17.297043657Z,2025-09-24T19:33:17.296636163Z,160,1,432669,C,B,64.820000000,1,26,8058566327441,128,14201,94261732,CLX5
2025-09-24T19:33:17.297333961Z,2025-09-24T19:33:17.296990847Z,160,1,432669,A,B,64.820000000,1,26,8058566327691,128,15906,94261744,CLX5
2025-09-24T19:33:17.297431400Z,2025-09-24T19:33:17.297228993Z,160,1,432669,A,A,64.830000000,2,26,8058566327692,128,16372,94261748,CLX5
2025-09-24T19:33:17.300317946Z,2025-09-24T19:33:17.300191481Z,160,1,432669,M,A,64.940000000,1,26,8058565075241,128,14644,94261807,CLX5
2025-09-24T19:33:17.303061696Z,2025-09-24T19:33:17.302814335Z,160,1,432669,M,A,64.950000000,1,26,8058565075241,128,15525,94261862,CLX5
2025-09-24T19:33:17.309090164Z,2025-09-24T19:33:17.308955665Z,160,1,432669,C,A,64.830000000,2,26,8058566327692,128,16693,94261883,CLX5
2025-09-24T19:33:17.309222261Z,2025-09-24T19:33:17.309098373Z,160,1,432669,C,A,64.830000000,1,26,8058566327689,128,20085,94261885,CLX5
2025-09-24T19:33:17.309256190Z,2025-09-24T19:33:17.309102845Z,160,1,432669,C,A,64.830000000,1,26,8058566327688,128,16537,94261886,CLX5
2025-09-24T19:33:17.309362874Z,2025-09-24T19:33:17.309230233Z,160,1,432669,A,A,64.830000000,1,26,8058566327725,128,18925,94261887,CLX5
2025-09-24T19:33:17.309399690Z,2025-09-24T19:33:17.309232325Z,160,1,432669,C,B,64.820000000,1,26,8058566327691,128,15387,94261888,CLX5
2025-09-24T19:33:17.309494142Z,2025-09-24T19:33:17.309371021Z,160,1,432669,A,A,64.830000000,1,26,8058566327727,128,14949,94261891,CLX5
2025-09-24T19:33:17.310285509Z,2025-09-24T19:33:17.310163771Z,160,1,432669,C,A,64.830000000,1,26,8058566327727,128,19976,94261894,CLX5
2025-09-24T19:33:17.310392240Z,2025-09-24T19:33:17.310284861Z,160,1,432669,M,A,64.940000000,1,26,8058565075241,128,16045,94261896,CLX5
2025-09-24T19:33:17.310635991Z,2025-09-24T19:33:17.310473723Z,160,1,432669,A,A,64.830000000,1,26,8058566327728,128,17812,94261899,CLX5
2025-09-24T19:33:17.310913186Z,2025-09-24T19:33:17.310636109Z,160,1,432669,A,A,64.830000000,1,26,8058566327730,128,15596,94261905,CLX5
2025-09-24T19:33:17.310922478Z,2025-09-24T19:33:17.310643173Z,160,1,432669,C,A,64.830000000,1,26,8058566327728,128,15978,94261906,CLX5
2025-09-24T19:33:17.312822625Z,2025-09-24T19:33:17.312688403Z,160,1,432669,M,A,64.950000000,1,26,8058565075241,128,14461,94261919,CLX5
2025-09-24T19:33:17.314340045Z,2025-09-24T19:33:17.314193903Z,160,1,432669,A,B,64.820000000,1,26,8058566327740,128,15305,94261941,CLX5
2025-09-24T19:33:17.314470168Z,2025-09-24T19:33:17.314348189Z,160,1,432669,C,B,64.820000000,1,26,8058566327740,128,17468,94261942,CLX5
2025-09-24T19:33:17.314601819Z,2025-09-24T19:33:17.314477705Z,160,1,432669,A,B,64.820000000,1,26,8058566327741,128,19376,94261943,CLX5
2025-09-24T19:33:17.314726498Z,2025-09-24T19:33:17.314609431Z,160,1,432669,C,B,64.820000000,1,26,8058566327741,128,18856,94261944,CLX5
2025-09-24T19:33:17.314861651Z,2025-09-24T19:33:17.314734225Z,160,1,432669,A,B,64.820000000,1,26,8058566327742,128,18577,94261945,CLX5
2025-09-24T19:33:17.314988694Z,2025-09-24T19:33:17.314869081Z,160,1,432669,C,B,64.820000000,1,26,8058566327742,128,18982,94261946,CLX5
2025-09-24T19:33:17.315471395Z,2025-09-24T19:33:17.315322181Z,160,1,432669,C,A,64.830000000,1,26,8058566327730,128,15369,94261957,CLX5
2025-09-24T19:33:17.315574632Z,2025-09-24T19:33:17.315442521Z,160,1,432669,C,A,64.830000000,1,26,8058566327547,128,22156,94261958,CLX5
2025-09-24T19:33:17.316173602Z,2025-09-24T19:33:17.316002233Z,160,1,432669,A,A,64.830000000,1,26,8058566327747,128,16350,94261965,CLX5
2025-09-24T19:33:17.316270542Z,2025-09-24T19:33:17.316151507Z,160,1,432669,C,A,64.830000000,1,26,8058566327747,128,19666,94261966,CLX5
2025-09-24T19:33:17.316399436Z,2025-09-24T19:33:17.316278163Z,160,1,432669,A,A,64.830000000,1,26,8058566327748,128,18252,94261967,CLX5
2025-09-24T19:33:17.319966947Z,2025-09-24T19:33:17.319823499Z,160,1,432669,A,A,64.830000000,2,26,8058566327755,128,20047,94261984,CLX5
2025-09-24T19:33:17.319995661Z,2025-09-24T19:33:17.319828663Z,160,1,432669,A,A,64.830000000,1,26,8058566327756,128,15987,94261985,CLX5
2025-09-24T19:33:17.320097055Z,2025-09-24T19:33:17.319975019Z,160,1,432669,C,A,64.830000000,1,26,8058566327756,128,19494,94261986,CLX5
2025-09-24T19:33:17.320227209Z,2025-09-24T19:33:17.320104727Z,160,1,432669,C,A,64.830000000,1,26,8058566327748,128,19459,94261990,CLX5
2025-09-24T19:33:17.320260100Z,2025-09-24T19:33:17.320104997Z,160,1,432669,A,B,64.820000000,1,26,8058566327757,128,14471,94261991,CLX5
2025-09-24T19:33:17.320312806Z,2025-09-24T19:33:17.320151803Z,160,1,432669,A,A,64.830000000,1,26,8058566327758,128,16179,94261993,CLX5
2025-09-24T19:33:17.320454786Z,2025-09-24T19:33:17.320320123Z,160,1,432669,A,A,64.830000000,1,26,8058566327759,128,16635,94261997,CLX5
2025-09-24T19:33:17.320482325Z,2025-09-24T19:33:17.320320737Z,160,1,432669,C,A,64.830000000,1,26,8058566327758,128,14579,94261998,CLX5
2025-09-24T19:33:17.341654490Z,2025-09-24T19:33:17.341513741Z,160,1,432669,C,B,64.820000000,1,26,8058566327757,128,19695,94262035,CLX5
2025-09-24T19:33:17.341688442Z,2025-09-24T19:33:17.341514357Z,160,1,432669,A,A,64.830000000,1,26,8058566327775,128,15955,94262036,CLX5
2025-09-24T19:33:17.341719590Z,2025-09-24T19:33:17.341632737Z,160,1,432669,M,A,64.940000000,1,26,8058565075241,128,14575,94262037,CLX5
2025-09-24T19:33:17.343376693Z,2025-09-24T19:33:17.343243951Z,160,1,432669,C,A,64.830000000,1,26,8058566327759,128,19455,94262075,CLX5
2025-09-24T19:33:17.343413141Z,2025-09-24T19:33:17.343244393Z,160,1,432669,A,B,64.820000000,1,26,8058566327787,128,15074,94262076,CLX5
2025-09-24T19:33:17.343449734Z,2025-09-24T19:33:17.343245717Z,160,1,432669,C,A,64.830000000,1,26,8058566327775,128,15044,94262077,CLX5
2025-09-24T19:33:17.343457421Z,2025-09-24T19:33:17.343360085Z,160,1,432669,M,A,64.950000000,1,26,8058565075241,128,16362,94262078,CLX5
2025-09-24T19:33:17.343579819Z,2025-09-24T19:33:17.343384681Z,160,1,432669,A,A,64.830000000,1,26,8058566327789,128,18666,94262079,CLX5
2025-09-24T19:33:17.343609593Z,2025-09-24T19:33:17.343420911Z,160,1,432669,C,A,64.830000000,1,26,8058566327789,128,16079,94262080,CLX5
2025-09-24T19:33:17.343695581Z,2025-09-24T19:33:17.343461093Z,160,1,432669,C,A,64.830000000,2,26,8058566327755,128,14638,94262083,CLX5
2025-09-24T19:33:17.343786692Z,2025-09-24T19:33:17.343587519Z,160,1,432669,C,B,64.820000000,1,26,8058566327787,128,17685,94262086,CLX5
2025-09-24T19:33:17.343938525Z,2025-09-24T19:33:17.343794275Z,160,1,432669,A,A,64.830000000,1,26,8058566327793,128,15264,94262089,CLX5
2025-09-24T19:33:17.488919150Z,2025-09-24T19:33:17.488763779Z,160,1,432669,A,A,64.830000000,1,26,8058566327931,128,19954,94262307,CLX5
2025-09-24T19:33:17.610141552Z,2025-09-24T19:33:17.610000327Z,160,1,432669,A,B,64.780000000,2,26,8058566327965,128,18166,94262362,CLX5
2025-09-24T19:33:17.745780547Z,2025-09-24T19:33:17.745474221Z,160,1,432669,A,B,64.820000000,1,26,8058566327996,128,14978,94262432,CLX5
2025-09-24T19:33:17.745829950Z,2025-09-24T19:33:17.745497085Z,160,1,432669,C,A,64.830000000,1,26,8058566327793,128,19921,94262433,CLX5
2025-09-24T19:33:17.745865537Z,2025-09-24T19:33:17.745498007Z,160,1,432669,C,A,64.830000000,1,26,8058566327931,128,17080,94262434,CLX5
2025-09-24T19:33:17.745929623Z,2025-09-24T19:33:17.745501425Z,160,1,432669,C,B,64.820000000,1,26,8058566327996,128,17316,94262436,CLX5
2025-09-24T19:33:17.746045578Z,2025-09-24T19:33:17.745790621Z,160,1,432669,A,B,64.820000000,1,26,8058566328000,128,18715,94262442,CLX5
2025-09-24T19:33:18.080987128Z,2025-09-24T19:33:18.080363305Z,160,1,432669,C,B,64.820000000,1,26,8058566328000,128,14654,94262671,CLX5
2025-09-24T19:33:18.081848418Z,2025-09-24T19:33:18.080994055Z,160,1,432669,A,A,64.830000000,1,26,8058566328129,128,17468,94262708,CLX5
2025-09-24T19:33:18.082883665Z,2025-09-24T19:33:18.081765093Z,160,1,432669,C,A,64.830000000,1,26,8058566328129,128,16727,94262782,CLX5
2025-09-24T19:33:18.082950102Z,2025-09-24T19:33:18.081879961Z,160,1,432669,A,A,64.830000000,2,26,8058566328147,128,19349,94262785,CLX5
2025-09-24T19:33:18.083781480Z,2025-09-24T19:33:18.082957861Z,160,1,432669,A,A,64.830000000,1,26,8058566328167,128,14174,94262846,CLX5
2025-09-24T19:33:18.083843162Z,2025-09-24T19:33:18.082958667Z,160,1,432669,A,B,64.820000000,1,26,8058566328168,128,15295,94262848,CLX5
2025-09-24T19:33:18.083904307Z,2025-09-24T19:33:18.083158183Z,160,1,432669,A,B,64.810000000,2,26,8058566328169,128,14679,94262852,CLX5
2025-09-24T19:33:18.083952120Z,2025-09-24T19:33:18.083164193Z,160,1,432669,C,A,64.830000000,1,26,8058566328167,128,19788,94262854,CLX5
2025-09-24T19:33:18.084022865Z,2025-09-24T19:33:18.083168705Z,160,1,432669,C,B,64.780000000,2,26,8058566327965,128,13776,94262856,CLX5
2025-09-24T19:33:18.084061846Z,2025-09-24T19:33:18.083173621Z,160,1,432669,C,A,64.830000000,1,26,8058566327725,128,18077,94262857,CLX5
2025-09-24T19:33:18.084321862Z,2025-09-24T19:33:18.083634169Z,160,1,432669,C,B,64.810000000,2,26,8058566328169,128,15091,94262874,CLX5
2025-09-24T19:33:18.084444429Z,2025-09-24T19:33:18.083639889Z,160,1,432669,A,A,64.830000000,1,26,8058566328179,128,16731,94262878,CLX5
2025-09-24T19:33:18.084509559Z,2025-09-24T19:33:18.083647243Z,160,1,432669,A,A,64.830000000,1,26,8058566328181,128,19087,94262879,CLX5
2025-09-24T19:33:18.084768707Z,2025-09-24T19:33:18.083959845Z,160,1,432669,C,A,64.830000000,1,26,8058566328179,128,16461,94262895,CLX5
2025-09-24T19:33:18.084839928Z,2025-09-24T19:33:18.084069413Z,160,1,432669,C,B,64.820000000,1,26,8058566328168,128,19220,94262899,CLX5
2025-09-24T19:33:18.085133211Z,2025-09-24T19:33:18.084774579Z,160,1,432669,C,A,64.830000000,1,26,8058566328181,128,15249,94262916,CLX5
2025-09-24T19:33:18.085199494Z,2025-09-24T19:33:18.084847671Z,160,1,432669,A,B,64.820000000,1,26,8058566328188,128,19200,94262920,CLX5
2025-09-24T19:33:18.085449211Z,2025-09-24T19:33:18.085139479Z,160,1,432669,A,A,64.830000000,1,26,8058566328193,128,14117,94262934,CLX5
2025-09-24T19:33:18.085519779Z,2025-09-24T19:33:18.085141879Z,160,1,432669,C,B,64.820000000,1,26,8058566328188,128,18867,94262937,CLX5
2025-09-24T19:33:18.085656821Z,2025-09-24T19:33:18.085207021Z,160,1,432669,C,A,64.830000000,1,26,8058566328193,128,16307,94262945,CLX5
2025-09-24T19:33:18.086286349Z,2025-09-24T19:33:18.085455361Z,160,1,432669,A,A,64.830000000,1,26,8058566328205,128,14428,94262977,CLX5
2025-09-24T19:33:18.086375701Z,2025-09-24T19:33:18.085526919Z,160,1,432669,C,A,64.830000000,1,26,8058566328205,128,19611,94262981,CLX5
2025-09-24T19:33:18.086564826Z,2025-09-24T19:33:18.085826253Z,160,1,432669,A,A,64.830000000,1,26,8058566328211,128,16719,94262991,CLX5
2025-09-24T19:33:18.087109018Z,2025-09-24T19:33:18.086382989Z,160,1,432669,A,B,64.820000000,1,26,8058566328227,128,18151,94263020,CLX5
2025-09-24T19:33:18.087147570Z,2025-09-24T19:33:18.086383181Z,160,1,432669,C,A,64.830000000,1,26,8058566328211,128,16289,94263021,CLX5
2025-09-24T19:33:18.087320038Z,2025-09-24T19:33:18.086572197Z,160,1,432669,C,B,64.820000000,1,26,8058566328227,128,18938,94263029,CLX5
2025-09-24T19:33:18.088290255Z,2025-09-24T19:33:18.087116627Z,160,1,432669,A,B,64.820000000,1,26,8058566328243,128,15196,94263092,CLX5
2025-09-24T19:33:18.088329237Z,2025-09-24T19:33:18.087155525Z,160,1,432669,C,B,64.820000000,1,26,8058566328243,128,18982,94263093,CLX5
2025-09-24T19:33:18.088739442Z,2025-09-24T19:33:18.088297815Z,160,1,432669,A,A,64.830000000,1,26,8058566328251,128,15514,94263126,CLX5
2025-09-24T19:33:18.210141780Z,2025-09-24T19:33:18.210002325Z,160,1,432669,A,B,64.780000000,2,26,8058566328312,128,18069,94263238,CLX5
2025-09-24T19:33:18.561348312Z,2025-09-24T19:33:18.561205947Z,160,1,432669,A,A,64.830000000,1,26,8058566328399,128,16077,94263371,CLX5
2025-09-24T19:33:18.945510805Z,2025-09-24T19:33:18.945355781Z,160,1,432669,A,B,64.800000000,1,26,8058566328479,128,18526,94263578,CLX5
2025-09-24T19:33:19.145771945Z,2025-09-24T19:33:19.145376553Z,160,1,432669,C,A,64.830000000,1,26,8058566328251,128,15952,94263657,CLX5
2025-09-24T19:33:19.146209060Z,2025-09-24T19:33:19.145789297Z,160,1,432669,A,B,64.820000000,1,26,8058566328518,128,15877,94263680,CLX5
2025-09-24T19:33:19.147034878Z,2025-09-24T19:33:19.146885913Z,160,1,432669,C,A,64.830000000,2,26,8058566328147,128,20021,94263693,CLX5
2025-09-24T19:33:19.241998403Z,2025-09-24T19:33:19.241831987Z,160,1,432669,A,A,64.830000000,1,26,8058566328537,128,20097,94263727,CLX5
2025-09-24T19:33:19.242031487Z,2025-09-24T19:33:19.241841009Z,160,1,432669,A,A,64.830000000,1,26,8058566328538,128,16252,94263728,CLX5
2025-09-24T19:33:19.242081780Z,2025-09-24T19:33:19.241854123Z,160,1,432669,C,B,64.820000000,1,26,8058566328518,128,15222,94263730,CLX5
2025-09-24T19:33:19.242213739Z,2025-09-24T19:33:19.242089869Z,160,1,432669,C,A,64.830000000,1,26,8058566328538,128,16554,94263732,CLX5
2025-09-24T19:33:19.242248289Z,2025-09-24T19:33:19.242091405Z,160,1,432669,A,B,64.820000000,1,26,8058566328540,128,15284,94263733,CLX5
2025-09-24T19:33:19.252386604Z,2025-09-24T19:33:19.252250965Z,160,1,432669,C,A,64.830000000,1,26,8058566328537,128,20016,94263745,CLX5
2025-09-24T19:33:19.252644154Z,2025-09-24T19:33:19.252395647Z,160,1,432669,C,A,64.830000000,1,26,8058566328399,128,15939,94263748,CLX5
2025-09-24T19:33:19.252703694Z,2025-09-24T19:33:19.252397011Z,160,1,432669,C,B,64.820000000,1,26,8058566328540,128,15956,94263750,CLX5
2025-09-24T19:33:19.252845666Z,2025-09-24T19:33:19.252708307Z,160,1,432669,C,A,64.830000000,1,26,8058566326138,128,20643,94263752,CLX5
2025-09-24T19:33:20.216086910Z,2025-09-24T19:33:20.215928735Z,160,1,432669,A,A,64.830000000,1,26,8058566328620,128,21150,94263898,CLX5
2025-09-24T19:33:20.216263486Z,2025-09-24T19:33:20.216126889Z,160,1,432669,A,A,64.830000000,1,26,8058566328621,128,20678,94263899,CLX5
2025-09-24T19:33:21.480437465Z,2025-09-24T19:33:21.480268585Z,160,1,432669,A,B,64.810000000,2,26,8058566328625,128,20031,94263925,CLX5
2025-09-24T19:33:21.481000940Z,2025-09-24T19:33:21.480277647Z,160,1,432669,C,B,64.780000000,2,26,8058566328312,128,17078,94263943,CLX5
2025-09-24T19:33:21.481116533Z,2025-09-24T19:33:21.480283023Z,160,1,432669,C,A,64.830000000,1,26,8058566328620,128,19991,94263946,CLX5
2025-09-24T19:33:21.481176004Z,2025-09-24T19:33:21.480297057Z,160,1,432669,A,B,64.820000000,1,26,8058566328636,128,15005,94263948,CLX5
2025-09-24T19:33:21.481227289Z,2025-09-24T19:33:21.480301781Z,160,1,432669,C,A,64.830000000,1,26,8058566328621,128,21520,94263949,CLX5
2025-09-24T19:33:21.481253645Z,2025-09-24T19:33:21.480308903Z,160,1,432669,A,B,64.820000000,1,26,8058566328637,128,15145,94263950,CLX5
2025-09-24T19:33:21.481283265Z,2025-09-24T19:33:21.480313127Z,160,1,432669,C,B,64.810000000,1,26,8058566327572,128,14819,94263951,CLX5
2025-09-24T19:33:21.482064249Z,2025-09-24T19:33:21.481352241Z,160,1,432669,C,B,64.820000000,1,26,8058566328637,128,18382,94263987,CLX5
2025-09-24T19:33:21.510156085Z,2025-09-24T19:33:21.510014755Z,160,1,432669,C,B,64.790000000,2,26,8058566325603,128,18584,94264113,CLX5
2025-09-24T19:33:21.546757237Z,2025-09-24T19:33:21.546609491Z,160,1,432669,A,B,64.820000000,1,26,8058566328682,128,18756,94264146,CLX5
2025-09-24T19:33:22.400710823Z,2025-09-24T19:33:22.400537799Z,160,1,432669,A,B,64.820000000,1,26,8058566328730,128,15341,94264237,CLX5
2025-09-24T19:33:22.400819612Z,2025-09-24T19:33:22.400692791Z,160,1,432669,C,B,64.820000000,1,26,8058566328730,128,15713,94264241,CLX5
2025-09-24T19:33:22.401327256Z,2025-09-24T19:33:22.400896611Z,160,1,432669,A,B,64.820000000,1,26,8058566328734,128,18301,94264262,CLX5
2025-09-24T19:33:22.508670118Z,2025-09-24T19:33:22.508515141Z,160,1,432669,C,A,64.830000000,1,26,8058566324724,128,14782,94264279,CLX5
2025-09-24T19:33:22.508711765Z,2025-09-24T19:33:22.508520459Z,160,1,432669,C,B,64.820000000,1,26,8058566328734,128,18604,94264281,CLX5
2025-09-24T19:33:22.510237348Z,2025-09-24T19:33:22.510110207Z,160,1,432669,A,B,64.820000000,1,26,8058566328742,128,18605,94264296,CLX5
2025-09-24T19:33:22.895907010Z,2025-09-24T19:33:22.895461345Z,160,1,432669,T,B,64.830000000,3,26,8058566328745,0,20249,94264311,CLX5
2025-09-24T19:33:22.895907010Z,2025-09-24T19:33:22.895461345Z,160,1,432669,F,A,64.830000000,1,26,8058566325778,0,20249,94264311,CLX5
2025-09-24T19:33:22.895907010Z,2025-09-24T19:33:22.895461345Z,160,1,432669,F,A,64.830000000,1,26,8058566325831,0,20249,94264311,CLX5
2025-09-24T19:33:22.895907010Z,2025-09-24T19:33:22.895461345Z,160,1,432669,F,A,64.830000000,1,26,8058566326935,0,20249,94264311,CLX5
2025-09-24T19:33:22.895916917Z,2025-09-24T19:33:22.895461345Z,160,1,432669,C,A,64.830000000,1,26,8058566325778,0,14989,94264312,CLX5
2025-09-24T19:33:22.895916917Z,2025-09-24T19:33:22.895461345Z,160,1,432669,C,A,64.830000000,1,26,8058566325831,0,14989,94264312,CLX5
2025-09-24T19:33:22.895916917Z,2025-09-24T19:33:22.895461345Z,160,1,432669,C,A,64.830000000,1,26,8058566326935,128,14989,94264312,CLX5
2025-09-24T19:33:22.895946671Z,2025-09-24T19:33:22.895462459Z,160,1,432669,A,B,64.830000000,1,26,8058566328746,128,17680,94264315,CLX5
2025-09-24T19:33:22.896128829Z,2025-09-24T19:33:22.895463317Z,160,1,432669,A,B,64.820000000,2,26,8058566328750,128,15568,94264324,CLX5
2025-09-24T19:33:22.896208397Z,2025-09-24T19:33:22.895463853Z,160,1,432669,A,B,64.830000000,2,26,8058566328753,128,17436,94264326,CLX5
2025-09-24T19:33:22.896230383Z,2025-09-24T19:33:22.895464027Z,160,1,432669,A,B,64.830000000,3,26,8058566328754,128,15518,94264328,CLX5
2025-09-24T19:33:22.896292181Z,2025-09-24T19:33:22.895464207Z,160,1,432669,A,B,64.830000000,1,26,8058566328755,128,17335,94264330,CLX5
2025-09-24T19:33:22.896327085Z,2025-09-24T19:33:22.895464383Z,160,1,432669,C,A,64.840000000,2,26,8058566322040,128,19345,94264331,CLX5
2025-09-24T19:33:22.896359738Z,2025-09-24T19:33:22.895467893Z,160,1,432669,A,B,64.820000000,1,26,8058566328758,128,14958,94264332,CLX5
2025-09-24T19:33:22.896813257Z,2025-09-24T19:33:22.895473539Z,160,1,432669,C,A,64.870000000,2,26,8058566314496,128,14713,94264347,CLX5
2025-09-24T19:33:22.896973230Z,2025-09-24T19:33:22.895476283Z,160,1,432669,A,B,64.830000000,1,26,8058566328765,128,19652,94264355,CLX5
2025-09-24T19:33:22.897219838Z,2025-09-24T19:33:22.895478767Z,160,1,432669,A,B,64.830000000,1,26,8058566328769,128,16669,94264366,CLX5
2025-09-24T19:33:22.897851569Z,2025-09-24T19:33:22.895497977Z,160,1,432669,C,A,64.840000000,1,26,8058566319377,128,19076,94264395,CLX5
2025-09-24T19:33:22.897914288Z,2025-09-24T19:33:22.895498331Z,160,1,432669,T,A,64.830000000,2,26,8058566328779,0,15174,94264399,CLX5
2025-09-24T19:33:22.897914288Z,2025-09-24T19:33:22.895498331Z,160,1,432669,F,B,64.830000000,1,26,8058566328746,0,15174,94264399,CLX5
2025-09-24T19:33:22.897914288Z,2025-09-24T19:33:22.895498331Z,160,1,432669,F,B,64.830000000,1,26,8058566328753,0,15174,94264399,CLX5
2025-09-24T19:33:22.897914288Z,2025-09-24T19:33:22.895498331Z,160,1,432669,C,B,64.830000000,1,26,8058566328746,0,15174,94264399,CLX5
2025-09-24T19:33:22.897914288Z,2025-09-24T19:33:22.895498331Z,160,1,432669,M,B,64.830000000,1,26,8058566328753,128,15174,94264399,CLX5
2025-09-24T19:33:22.898035288Z,2025-09-24T19:33:22.895514393Z,160,1,432669,C,B,64.820000000,1,26,8058566328636,128,15199,94264404,CLX5
2025-09-24T19:33:22.898062965Z,2025-09-24T19:33:22.895524531Z,160,1,432669,A,B,64.810000000,1,26,8058566328781,128,14996,94264405,CLX5
2025-09-24T19:33:22.898106992Z,2025-09-24T19:33:22.895529139Z,160,1,432669,A,B,64.830000000,1,26,8058566328782,128,17349,94264407,CLX5
2025-09-24T19:33:22.898125078Z,2025-09-24T19:33:22.895560933Z,160,1,432669,A,B,64.830000000,2,26,8058566328784,128,14184,94264408,CLX5
2025-09-24T19:33:22.898245286Z,2025-09-24T19:33:22.895633525Z,160,1,432669,C,B,64.830000000,1,26,8058566328753,128,16058,94264412,CLX5
2025-09-24T19:33:22.898280497Z,2025-09-24T19:33:22.895633677Z,160,1,432669,C,B,64.830000000,1,26,8058566328755,128,18459,94264413,CLX5
2025-09-24T19:33:22.898596437Z,2025-09-24T19:33:22.895964173Z,160,1,432669,C,B,64.830000000,1,26,8058566328782,128,15112,94264428,CLX5
2025-09-24T19:33:22.898638659Z,2025-09-24T19:33:22.895990071Z,160,1,432669,T,A,64.830000000,1,26,8058566328792,0,14861,94264431,CLX5
2025-09-24T19:33:22.898638659Z,2025-09-24T19:33:22.895990071Z,160,1,432669,F,B,64.830000000,1,26,8058566328754,0,14861,94264431,CLX5
2025-09-24T19:33:22.898674400Z,2025-09-24T19:33:22.895990071Z,160,1,432669,M,B,64.830000000,2,26,8058566328754,128,17731,94264432,CLX5
2025-09-24T19:33:22.898687632Z,2025-09-24T19:33:22.895997923Z,160,1,432669,T,A,64.830000000,1,26,8058566328793,0,14475,94264433,CLX5
2025-09-24T19:33:22.898687632Z,2025-09-24T19:33:22.895997923Z,160,1,432669,F,B,64.830000000,1,26,8058566328754,0,14475,94264433,CLX5
2025-09-24T19:33:22.898687632Z,2025-09-24T19:33:22.895997923Z,160,1,432669,M,B,64.830000000,1,26,8058566328754,128,14475,94264433,CLX5
2025-09-24T19:33:22.898883553Z,2025-09-24T19:33:22.896026107Z,160,1,432669,A,A,64.840000000,1,26,8058566328796,128,15230,94264439,CLX5
2025-09-24T19:33:22.899306238Z,2025-09-24T19:33:22.896065007Z,160,1,432669,C,B,64.830000000,1,26,8058566328754,128,14841,94264458,CLX5
2025-09-24T19:33:22.899521927Z,2025-09-24T19:33:22.896150807Z,160,1,432669,A,B,64.830000000,1,26,8058566328807,128,15185,94264470,CLX5
2025-09-24T19:33:22.899718218Z,2025-09-24T19:33:22.896191317Z,160,1,432669,C,A,64.840000000,3,26,8058566288785,128,14307,94264478,CLX5
2025-09-24T19:33:22.899726881Z,2025-09-24T19:33:22.896214759Z,160,1,432669,T,A,64.830000000,2,26,8058566328808,0,14663,94264479,CLX5
2025-09-24T19:33:22.899726881Z,2025-09-24T19:33:22.896214759Z,160,1,432669,F,B,64.830000000,1,26,8058566328765,0,14663,94264479,CLX5
2025-09-24T19:33:22.899726881Z,2025-09-24T19:33:22.896214759Z,160,1,432669,F,B,64.830000000,1,26,8058566328769,0,14663,94264479,CLX5
2025-09-24T19:33:22.899778572Z,2025-09-24T19:33:22.896214759Z,160,1,432669,C,B,64.830000000,1,26,8058566328765,0,18624,94264480,CLX5
2025-09-24T19:33:22.899778572Z,2025-09-24T19:33:22.896214759Z,160,1,432669,C,B,64.830000000,1,26,8058566328769,128,18624,94264480,CLX5
2025-09-24T19:33:22.899915430Z,2025-09-24T19:33:22.896383039Z,160,1,432669,C,B,64.820000000,1,26,8058566326782,128,15030,94264487,CLX5
2025-09-24T19:33:22.899997986Z,2025-09-24T19:33:22.896457495Z,160,1,432669,A,B,64.800000000,1,26,8058566328813,128,17178,94264489,CLX5
2025-09-24T19:33:22.900582096Z,2025-09-24T19:33:22.896872753Z,160,1,432669,A,A,64.840000000,1,26,8058566328816,128,16067,94264519,CLX5
2025-09-24T19:33:22.900635116Z,2025-09-24T19:33:22.897001177Z,160,1,432669,T,A,64.830000000,2,26,8058566328817,0,14744,94264523,CLX5
2025-09-24T19:33:22.900635116Z,2025-09-24T19:33:22.897001177Z,160,1,432669,F,B,64.830000000,2,26,8058566328784,0,14744,94264523,CLX5
2025-09-24T19:33:22.900686945Z,2025-09-24T19:33:22.897001177Z,160,1,432669,C,B,64.830000000,2,26,8058566328784,128,17459,94264524,CLX5
2025-09-24T19:33:22.901420262Z,2025-09-24T19:33:22.897463395Z,160,1,432669,T,A,64.830000000,1,26,8058566328830,0,18186,94264560,CLX5
2025-09-24T19:33:22.901420262Z,2025-09-24T19:33:22.897463395Z,160,1,432669,F,B,64.830000000,1,26,8058566328807,0,18186,94264560,CLX5
2025-09-24T19:33:22.901420262Z,2025-09-24T19:33:22.897463395Z,160,1,432669,C,B,64.830000000,1,26,8058566328807,0,18186,94264560,CLX5
2025-09-24T19:33:22.901420262Z,2025-09-24T19:33:22.897463395Z,160,1,432669,A,A,64.830000000,1,26,8058566328830,128,18186,94264560,CLX5
2025-09-24T19:33:22.901916196Z,2025-09-24T19:33:22.897856921Z,160,1,432669,A,A,64.840000000,2,26,8058566328837,128,17180,94264582,CLX5
2025-09-24T19:33:22.902264273Z,2025-09-24T19:33:22.898068765Z,160,1,432669,A,B,64.820000000,1,26,8058566328846,128,15067,94264596,CLX5
2025-09-24T19:33:22.902466661Z,2025-09-24T19:33:22.898583955Z,160,1,432669,A,A,64.830000000,1,26,8058566328848,128,17099,94264604,CLX5
2025-09-24T19:33:22.902497618Z,2025-09-24T19:33:22.898647023Z,160,1,432669,C,A,64.830000000,1,26,8058566328848,128,14750,94264607,CLX5
2025-09-24T19:33:22.902630229Z,2025-09-24T19:33:22.898729101Z,160,1,432669,C,A,64.840000000,1,26,8058566319360,128,14987,94264613,CLX5
2025-09-24T19:33:22.902710112Z,2025-09-24T19:33:22.898734917Z,160,1,432669,A,B,64.820000000,2,26,8058566328851,128,16107,94264617,CLX5
2025-09-24T19:33:22.902973829Z,2025-09-24T19:33:22.898765425Z,160,1,432669,T,B,64.830000000,1,26,8058566328855,0,18610,94264628,CLX5
2025-09-24T19:33:22.902973829Z,2025-09-24T19:33:22.898765425Z,160,1,432669,F,A,64.830000000,1,26,8058566328830,0,18610,94264628,CLX5
2025-09-24T19:33:22.902973829Z,2025-09-24T19:33:22.898765425Z,160,1,432669,C,A,64.830000000,1,26,8058566328830,128,18610,94264628,CLX5
2025-09-24T19:33:22.903148164Z,2025-09-24T19:33:22.898904811Z,160,1,432669,A,B,64.830000000,1,26,8058566328858,128,15187,94264635,CLX5
2025-09-24T19:33:22.903562279Z,2025-09-24T19:33:22.899333067Z,160,1,432669,C,A,64.840000000,1,26,8058566328796,128,14406,94264654,CLX5
2025-09-24T19:33:22.903571794Z,2025-09-24T19:33:22.899335179Z,160,1,432669,T,A,64.830000000,1,26,8058566328862,0,15360,94264655,CLX5
2025-09-24T19:33:22.903571794Z,2025-09-24T19:33:22.899335179Z,160,1,432669,F,B,64.830000000,1,26,8058566328858,0,15360,94264655,CLX5
2025-09-24T19:33:22.903625374Z,2025-09-24T19:33:22.899335179Z,160,1,432669,C,B,64.830000000,1,26,8058566328858,128,18649,94264656,CLX5
2025-09-24T19:33:22.903965020Z,2025-09-24T19:33:22.899665271Z,160,1,432669,C,B,64.820000000,2,26,8058566328851,128,19559,94264678,CLX5
2025-09-24T19:33:22.904058096Z,2025-09-24T19:33:22.899947247Z,160,1,432669,A,B,64.820000000,1,26,8058566328867,128,16788,94264681,CLX5
2025-09-24T19:33:22.904088339Z,2025-09-24T19:33:22.900169131Z,160,1,432669,A,A,64.840000000,1,26,8058566328868,128,15126,94264682,CLX5
2025-09-24T19:33:22.904626602Z,2025-09-24T19:33:22.900796485Z,160,1,432669,A,B,64.830000000,1,26,8058566328877,128,17255,94264704,CLX5
2025-09-24T19:33:22.904797411Z,2025-09-24T19:33:22.900874395Z,160,1,432669,A,B,64.830000000,2,26,8058566328880,128,17818,94264711,CLX5
2025-09-24T19:33:22.904828475Z,2025-09-24T19:33:22.900889523Z,160,1,432669,C,A,64.840000000,2,26,8058566319357,128,17103,94264714,CLX5
2025-09-24T19:33:22.904877033Z,2025-09-24T19:33:22.900903461Z,160,1,432669,C,A,64.840000000,1,26,8058566328868,128,15667,94264716,CLX5
2025-09-24T19:33:22.904924647Z,2025-09-24T19:33:22.900950653Z,160,1,432669,M,A,64.960000000,1,26,8058565075241,128,14863,94264719,CLX5
2025-09-24T19:33:22.905059270Z,2025-09-24T19:33:22.901153089Z,160,1,432669,A,A,64.840000000,1,26,8058566328883,128,15617,94264726,CLX5
2025-09-24T19:33:22.905203278Z,2025-09-24T19:33:22.901420669Z,160,1,432669,T,A,64.830000000,1,26,8058566328887,0,15622,94264734,CLX5
2025-09-24T19:33:22.905203278Z,2025-09-24T19:33:22.901420669Z,160,1,432669,F,B,64.830000000,1,26,8058566328877,0,15622,94264734,CLX5
2025-09-24T19:33:22.905203278Z,2025-09-24T19:33:22.901420669Z,160,1,432669,C,B,64.830000000,1,26,8058566328877,128,15622,94264734,CLX5
2025-09-24T19:33:22.905605218Z,2025-09-24T19:33:22.901515377Z,160,1,432669,A,B,64.830000000,1,26,8058566328898,128,17405,94264752,CLX5
2025-09-24T19:33:22.905624143Z,2025-09-24T19:33:22.901515553Z,160,1,432669,A,B,64.830000000,1,26,8058566328899,128,16574,94264754,CLX5
2025-09-24T19:33:22.905753529Z,2025-09-24T19:33:22.901569423Z,160,1,432669,C,A,64.840000000,1,26,8058566328816,128,15470,94264759,CLX5
2025-09-24T19:33:22.905782819Z,2025-09-24T19:33:22.901569711Z,160,1,432669,C,A,64.840000000,1,26,8058566328883,128,15092,94264760,CLX5
2025-09-24T19:33:22.905977151Z,2025-09-24T19:33:22.901824005Z,160,1,432669,A,B,64.830000000,2,26,8058566328901,128,18665,94264765,CLX5
2025-09-24T19:33:22.906802155Z,2025-09-24T19:33:22.902973687Z,160,1,432669,A,B,64.830000000,1,26,8058566328911,128,19132,94264811,CLX5
2025-09-24T19:33:22.906961414Z,2025-09-24T19:33:22.903006479Z,160,1,432669,M,A,64.950000000,1,26,8058565075241,128,14448,94264821,CLX5
2025-09-24T19:33:22.906989990Z,2025-09-24T19:33:22.903011143Z,160,1,432669,A,B,64.820000000,3,26,8058566328914,128,15375,94264822,CLX5
2025-09-24T19:33:22.907066440Z,2025-09-24T19:33:22.903155637Z,160,1,432669,A,A,64.840000000,1,26,8058566328916,128,15022,94264825,CLX5
2025-09-24T19:33:22.907137538Z,2025-09-24T19:33:22.903191597Z,160,1,432669,A,A,64.840000000,1,26,8058566328917,128,15185,94264828,CLX5
2025-09-24T19:33:22.907661148Z,2025-09-24T19:33:22.903789785Z,160,1,432669,A,B,64.820000000,1,26,8058566328926,128,18216,94264854,CLX5
2025-09-24T19:33:22.907712010Z,2025-09-24T19:33:22.903978627Z,160,1,432669,A,A,64.840000000,2,26,8058566328931,128,14726,94264859,CLX5
2025-09-24T19:33:22.908294754Z,2025-09-24T19:33:22.904645759Z,160,1,432669,C,A,64.840000000,2,26,8058566328931,128,15373,94264898,CLX5
2025-09-24T19:33:22.908585104Z,2025-09-24T19:33:22.905063879Z,160,1,432669,C,B,64.830000000,2,26,8058566328901,128,18268,94264913,CLX5
2025-09-24T19:33:22.908707171Z,2025-09-24T19:33:22.905203169Z,160,1,432669,C,B,64.830000000,1,26,8058566328911,128,14114,94264919,CLX5
2025-09-24T19:33:22.908773200Z,2025-09-24T19:33:22.905220025Z,160,1,432669,A,A,64.840000000,2,26,8058566328949,128,18650,94264921,CLX5
2025-09-24T19:33:22.908816098Z,2025-09-24T19:33:22.905226093Z,160,1,432669,C,B,64.830000000,2,26,8058566328880,128,14988,94264922,CLX5
2025-09-24T19:33:22.909660562Z,2025-09-24T19:33:22.907104767Z,160,1,432669,C,A,64.840000000,2,26,8058566328949,128,15154,94264963,CLX5
2025-09-24T19:33:22.909795969Z,2025-09-24T19:33:22.907748651Z,160,1,432669,A,A,64.840000000,1,26,8058566328962,128,15573,94264969,CLX5
2025-09-24T19:33:22.910080275Z,2025-09-24T19:33:22.908826357Z,160,1,432669,A,B,64.830000000,2,26,8058566328966,128,14754,94264987,CLX5
2025-09-24T19:33:22.911167023Z,2025-09-24T19:33:22.909997985Z,160,1,432669,A,B,64.830000000,1,26,8058566328977,128,14405,94265044,CLX5
2025-09-24T19:33:22.911215058Z,2025-09-24T19:33:22.909998773Z,160,1,432669,A,B,64.830000000,1,26,8058566328978,128,20147,94265046,CLX5
2025-09-24T19:33:22.918762857Z,2025-09-24T19:33:22.918626085Z,160,1,432669,M,B,64.820000000,4,26,8058566319851,128,17678,94265141,CLX5
2025-09-24T19:33:22.918790143Z,2025-09-24T19:33:22.918630077Z,160,1,432669,C,B,64.820000000,1,26,8058566328926,128,15039,94265142,CLX5
2025-09-24T19:33:22.933083200Z,2025-09-24T19:33:22.932795541Z,160,1,432669,T,A,64.830000000,1,26,8058566328997,0,18045,94265160,CLX5
2025-09-24T19:33:22.933083200Z,2025-09-24T19:33:22.932795541Z,160,1,432669,F,B,64.830000000,1,26,8058566328898,0,18045,94265160,CLX5
2025-09-24T19:33:22.933096393Z,2025-09-24T19:33:22.932795541Z,160,1,432669,C,B,64.830000000,1,26,8058566328898,128,18997,94265161,CLX5
2025-09-24T19:33:22.933194331Z,2025-09-24T19:33:22.933061603Z,160,1,432669,C,B,64.830000000,1,26,8058566328978,128,17376,94265162,CLX5
2025-09-24T19:33:22.933375424Z,2025-09-24T19:33:22.933083087Z,160,1,432669,T,A,64.830000000,4,26,8058566328998,0,19944,94265164,CLX5
2025-09-24T19:33:22.933375424Z,2025-09-24T19:33:22.933083087Z,160,1,432669,F,B,64.830000000,1,26,8058566328899,0,19944,94265164,CLX5
2025-09-24T19:33:22.933375424Z,2025-09-24T19:33:22.933083087Z,160,1,432669,F,B,64.830000000,2,26,8058566328966,0,19944,94265164,CLX5
2025-09-24T19:33:22.933375424Z,2025-09-24T19:33:22.933083087Z,160,1,432669,F,B,64.830000000,1,26,8058566328977,0,19944,94265164,CLX5
2025-09-24T19:33:22.933385599Z,2025-09-24T19:33:22.933083087Z,160,1,432669,C,B,64.830000000,1,26,8058566328899,0,15042,94265165,CLX5
2025-09-24T19:33:22.933385599Z,2025-09-24T19:33:22.933083087Z,160,1,432669,C,B,64.830000000,2,26,8058566328966,0,15042,94265165,CLX5
2025-09-24T19:33:22.933385599Z,2025-09-24T19:33:22.933083087Z,160,1,432669,C,B,64.830000000,1,26,8058566328977,128,15042,94265165,CLX5
2025-09-24T19:33:22.933413146Z,2025-09-24T19:33:22.933085409Z,160,1,432669,A,B,64.830000000,1,26,8058566328999,128,16144,94265168,CLX5
2025-09-24T19:33:22.933560602Z,2025-09-24T19:33:22.933365947Z,160,1,432669,A,A,64.840000000,2,26,8058566329004,128,15319,94265174,CLX5
2025-09-24T19:33:22.933771844Z,2025-09-24T19:33:22.933392863Z,160,1,432669,C,B,64.830000000,1,26,8058566328999,128,16010,94265184,CLX5
2025-09-24T19:33:22.933925014Z,2025-09-24T19:33:22.933407627Z,160,1,432669,A,A,64.830000000,1,26,8058566329010,128,14805,94265190,CLX5
2025-09-24T19:33:22.934109808Z,2025-09-24T19:33:22.933565253Z,160,1,432669,A,A,64.830000000,1,26,8058566329013,128,17571,94265201,CLX5
2025-09-24T19:33:22.934189899Z,2025-09-24T19:33:22.933583127Z,160,1,432669,M,B,63.670000000,4,26,8058566319851,128,15236,94265206,CLX5
2025-09-24T19:33:22.934490877Z,2025-09-24T19:33:22.934219657Z,160,1,432669,C,B,64.820000000,1,26,8058566328867,128,16212,94265220,CLX5
2025-09-24T19:33:22.934577810Z,2025-09-24T19:33:22.934409383Z,160,1,432669,A,A,64.870000000,2,26,8058566329019,128,14927,94265224,CLX5
2025-09-24T19:33:22.934772926Z,2025-09-24T19:33:22.934513595Z,160,1,432669,C,B,64.820000000,1,26,8058566328846,128,14261,94265234,CLX5
2025-09-24T19:33:22.935248300Z,2025-09-24T19:33:22.934998433Z,160,1,432669,A,A,64.830000000,1,26,8058566329031,128,14902,94265253,CLX5
2025-09-24T19:33:22.938964803Z,2025-09-24T19:33:22.938863931Z,160,1,432669,A,B,63.680000000,4,26,8058566329044,128,18571,94265321,CLX5
2025-09-24T19:33:22.940959547Z,2025-09-24T19:33:22.940795981Z,160,1,432669,M,A,64.830000000,1,26,8058566328962,128,19133,94265324,CLX5
2025-09-24T19:33:23.071988487Z,2025-09-24T19:33:23.071859863Z,160,1,432669,C,B,64.800000000,1,26,8058566328813,128,18923,94265472,CLX5
2025-09-24T19:33:23.110189294Z,2025-09-24T19:33:23.110058059Z,160,1,432669,A,B,64.780000000,2,26,8058566329100,128,18424,94265485,CLX5
2025-09-24T19:33:23.382732024Z,2025-09-24T19:33:23.382581593Z,160,1,432669,A,A,64.830000000,2,26,8058566329144,128,21404,94265581,CLX5
2025-09-24T19:33:23.391984863Z,2025-09-24T19:33:23.391835737Z,160,1,432669,A,A,64.830000000,1,26,8058566329148,128,20575,94265596,CLX5
2025-09-24T19:33:23.392129024Z,2025-09-24T19:33:23.391998237Z,160,1,432669,C,B,64.820000000,1,26,8058566328682,128,18751,94265597,CLX5
2025-09-24T19:33:23.392626700Z,2025-09-24T19:33:23.392498089Z,160,1,432669,A,B,64.820000000,1,26,8058566329149,128,14283,94265600,CLX5
2025-09-24T19:33:24.173231587Z,2025-09-24T19:33:24.173081785Z,160,1,432669,C,A,64.830000000,1,26,8058566329148,128,20074,94265639,CLX5
2025-09-24T19:33:24.173375141Z,2025-09-24T19:33:24.173246457Z,160,1,432669,C,B,64.810000000,1,26,8058566328781,128,18097,94265640,CLX5
2025-09-24T19:33:24.173431333Z,2025-09-24T19:33:24.173250815Z,160,1,432669,C,A,64.830000000,2,26,8058566329144,128,18035,94265642,CLX5
2025-09-24T19:33:29.488207995Z,2025-09-24T19:33:29.488036293Z,160,1,432669,C,A,64.830000000,1,26,8058566329010,128,22967,94265705,CLX5
2025-09-24T19:33:29.488241087Z,2025-09-24T19:33:29.488036447Z,160,1,432669,C,A,64.830000000,1,26,8058566329013,128,20774,94265707,CLX5
2025-09-24T19:33:29.488746597Z,2025-09-24T19:33:29.488571931Z,160,1,432669,C,B,64.820000000,1,26,8058566329149,128,18316,94265723,CLX5
2025-09-24T19:33:29.539367582Z,2025-09-24T19:33:29.539026595Z,160,1,432669,T,B,64.830000000,1,26,8058566329192,0,18967,94265745,CLX5
2025-09-24T19:33:29.539367582Z,2025-09-24T19:33:29.539026595Z,160,1,432669,F,A,64.830000000,1,26,8058566329031,0,18967,94265745,CLX5
2025-09-24T19:33:29.539377412Z,2025-09-24T19:33:29.539026595Z,160,1,432669,C,A,64.830000000,1,26,8058566329031,128,16152,94265746,CLX5
2025-09-24T19:33:29.539686301Z,2025-09-24T19:33:29.539379879Z,160,1,432669,T,B,64.830000000,1,26,8058566329195,0,14108,94265758,CLX5
2025-09-24T19:33:29.539686301Z,2025-09-24T19:33:29.539379879Z,160,1,432669,F,A,64.830000000,1,26,8058566328962,0,14108,94265758,CLX5
2025-09-24T19:33:29.539686301Z,2025-09-24T19:33:29.539379879Z,160,1,432669,C,A,64.830000000,1,26,8058566328962,128,14108,94265758,CLX5
2025-09-24T19:33:29.541242871Z,2025-09-24T19:33:29.540400679Z,160,1,432669,M,B,64.830000000,1,26,8058566324408,128,18675,94265848,CLX5
2025-09-24T19:33:29.541849137Z,2025-09-24T19:33:29.541291749Z,160,1,432669,A,B,64.830000000,1,26,8058566329219,128,14686,94265881,CLX5
2025-09-24T19:33:29.542301458Z,2025-09-24T19:33:29.542016843Z,160,1,432669,A,B,64.800000000,1,26,8058566329225,128,14726,94265908,CLX5
2025-09-24T19:33:29.548134058Z,2025-09-24T19:33:29.547889019Z,160,1,432669,T,A,64.830000000,1,26,8058566329239,0,17983,94265945,CLX5
2025-09-24T19:33:29.548134058Z,2025-09-24T19:33:29.547889019Z,160,1,432669,F,B,64.830000000,1,26,8058566324408,0,17983,94265945,CLX5
2025-09-24T19:33:29.548143719Z,2025-09-24T19:33:29.547889019Z,160,1,432669,C,B,64.830000000,1,26,8058566324408,128,15052,94265946,CLX5
2025-09-24T19:33:29.548366903Z,2025-09-24T19:33:29.548134019Z,160,1,432669,T,A,64.830000000,1,26,8058566329240,0,16865,94265949,CLX5
2025-09-24T19:33:29.548366903Z,2025-09-24T19:33:29.548134019Z,160,1,432669,F,B,64.830000000,1,26,8058566329219,0,16865,94265949,CLX5
2025-09-24T19:33:29.548376733Z,2025-09-24T19:33:29.548134019Z,160,1,432669,C,B,64.830000000,1,26,8058566329219,128,17279,94265950,CLX5
2025-09-24T19:33:29.548674448Z,2025-09-24T19:33:29.548368211Z,160,1,432669,A,A,64.830000000,1,26,8058566329246,128,17206,94265962,CLX5
2025-09-24T19:33:29.548724780Z,2025-09-24T19:33:29.548368441Z,160,1,432669,A,A,64.830000000,2,26,8058566329247,128,14730,94265966,CLX5
2025-09-24T19:33:29.555187222Z,2025-09-24T19:33:29.555042125Z,160,1,432669,A,A,64.840000000,1,26,8058566329260,128,18458,94266033,CLX5
2025-09-24T19:33:29.581687976Z,2025-09-24T19:33:29.581525129Z,160,1,432669,A,A,64.830000000,1,26,8058566329264,128,17903,94266046,CLX5
2025-09-24T19:33:29.640536199Z,2025-09-24T19:33:29.640388699Z,160,1,432669,M,A,64.830000000,1,26,8058566329260,128,18299,94266099,CLX5
2025-09-24T19:33:29.674023512Z,2025-09-24T19:33:29.673868507Z,160,1,432669,A,A,64.830000000,1,26,8058566329288,128,21291,94266114,CLX5
2025-09-24T19:33:29.674164425Z,2025-09-24T19:33:29.674032565Z,160,1,432669,A,A,64.830000000,1,26,8058566329289,128,18822,94266116,CLX5
2025-09-24T19:33:29.674199375Z,2025-09-24T19:33:29.674035023Z,160,1,432669,A,A,64.830000000,1,26,8058566329290,128,16683,94266117,CLX5
2025-09-24T19:33:29.722029580Z,2025-09-24T19:33:29.721897187Z,160,1,432669,C,B,64.800000000,1,26,8058566329225,128,18520,94266135,CLX5
2025-09-24T19:33:29.819642597Z,2025-09-24T19:33:29.819486637Z,160,1,432669,C,A,64.830000000,1,26,8058566329288,128,19968,94266143,CLX5
2025-09-24T19:33:29.819809429Z,2025-09-24T19:33:29.819652671Z,160,1,432669,C,A,64.830000000,1,26,8058566329289,128,16994,94266146,CLX5
2025-09-24T19:33:29.819852358Z,2025-09-24T19:33:29.819670391Z,160,1,432669,C,A,64.830000000,1,26,8058566329290,128,20424,94266147,CLX5
2025-09-24T19:33:33.842557418Z,2025-09-24T19:33:33.842432475Z,160,1,432669,C,A,65.320000000,1,26,8058562216742,128,20671,94266397,CLX5
2025-09-24T19:33:34.716448302Z,2025-09-24T19:33:34.716325459Z,160,1,432669,C,B,64.720000000,1,26,8058566325952,128,18354,94266429,CLX5
2025-09-24T19:33:37.933906938Z,2025-09-24T19:33:37.933717771Z,160,1,432669,A,A,64.830000000,1,26,8058566329398,128,25180,94266456,CLX5
2025-09-24T19:33:37.957451439Z,2025-09-24T19:33:37.957199835Z,160,1,432669,A,A,64.830000000,1,26,8058566329401,128,22821,94266463,CLX5
2025-09-24T19:33:37.958095719Z,2025-09-24T19:33:37.957435079Z,160,1,432669,C,B,64.820000000,2,26,8058566327630,128,14584,94266481,CLX5
2025-09-24T19:33:37.960191857Z,2025-09-24T19:33:37.960024509Z,160,1,432669,M,A,64.840000000,1,26,8058566329260,128,16586,94266509,CLX5
2025-09-24T19:33:37.964066851Z,2025-09-24T19:33:37.963924837Z,160,1,432669,M,A,64.830000000,1,26,8058566329260,128,19599,94266515,CLX5
2025-09-24T19:33:38.039289997Z,2025-09-24T19:33:38.039036167Z,160,1,432669,A,A,64.830000000,1,26,8058566329421,128,19768,94266536,CLX5
2025-09-24T19:33:38.039417570Z,2025-09-24T19:33:38.039049759Z,160,1,432669,A,A,64.830000000,1,26,8058566329423,128,14876,94266540,CLX5
2025-09-24T19:33:38.039492531Z,2025-09-24T19:33:38.039064101Z,160,1,432669,C,B,64.820000000,1,26,8058566328742,128,18284,94266544,CLX5
2025-09-24T19:33:38.039559036Z,2025-09-24T19:33:38.039090463Z,160,1,432669,C,A,64.830000000,1,26,8058566329423,128,20070,94266547,CLX5
2025-09-24T19:33:38.039838058Z,2025-09-24T19:33:38.039246609Z,160,1,432669,A,A,64.830000000,1,26,8058566329426,128,19837,94266562,CLX5
2025-09-24T19:33:38.039866673Z,2025-09-24T19:33:38.039259241Z,160,1,432669,C,B,64.820000000,1,26,8058566328758,128,14119,94266563,CLX5
2025-09-24T19:33:38.039950649Z,2025-09-24T19:33:38.039428347Z,160,1,432669,C,B,64.820000000,2,26,8058566327423,128,17985,94266568,CLX5
2025-09-24T19:33:38.039992426Z,2025-09-24T19:33:38.039503417Z,160,1,432669,A,B,64.820000000,1,26,8058566329427,128,15427,94266570,CLX5
2025-09-24T19:33:38.041944273Z,2025-09-24T19:33:38.041775041Z,160,1,432669,C,A,64.830000000,1,26,8058566329426,128,16931,94266597,CLX5
2025-09-24T19:33:38.138574539Z,2025-09-24T19:33:38.138395183Z,160,1,432669,C,A,64.830000000,1,26,8058566329421,128,16285,94266644,CLX5
2025-09-24T19:33:38.138752744Z,2025-09-24T19:33:38.138582799Z,160,1,432669,C,A,64.830000000,1,26,8058566329401,128,15315,94266649,CLX5
2025-09-24T19:33:38.138817967Z,2025-09-24T19:33:38.138677547Z,160,1,432669,C,B,64.780000000,2,26,8058566329100,128,17752,94266651,CLX5
2025-09-24T19:33:38.139173425Z,2025-09-24T19:33:38.138994467Z,160,1,432669,A,A,64.830000000,2,26,8058566329446,128,15181,94266658,CLX5
2025-09-24T19:33:38.142212709Z,2025-09-24T19:33:38.142076679Z,160,1,432669,A,A,64.830000000,2,26,8058566329470,128,17464,94266709,CLX5
2025-09-24T19:33:38.142341151Z,2025-09-24T19:33:38.142220943Z,160,1,432669,A,A,64.830000000,1,26,8058566329471,128,15740,94266714,CLX5
2025-09-24T19:33:38.142650131Z,2025-09-24T19:33:38.142529165Z,160,1,432669,C,A,64.830000000,1,26,8058566329471,128,19507,94266720,CLX5
2025-09-24T19:33:38.188268901Z,2025-09-24T19:33:38.187804369Z,160,1,432669,A,B,64.820000000,1,26,8058566329521,128,18828,94266852,CLX5
2025-09-24T19:33:38.188679936Z,2025-09-24T19:33:38.187807459Z,160,1,432669,C,A,64.870000000,1,26,8058566307943,128,14600,94266874,CLX5
2025-09-24T19:33:38.188763290Z,2025-09-24T19:33:38.187807785Z,160,1,432669,C,A,64.880000000,1,26,8058566302457,128,13802,94266876,CLX5
2025-09-24T19:33:38.188893052Z,2025-09-24T19:33:38.187808921Z,160,1,432669,A,B,64.820000000,1,26,8058566329527,128,14445,94266880,CLX5
2025-09-24T19:33:38.188907459Z,2025-09-24T19:33:38.187809157Z,160,1,432669,T,B,64.830000000,8,26,8058566329528,0,14822,94266881,CLX5
2025-09-24T19:33:38.188907459Z,2025-09-24T19:33:38.187809157Z,160,1,432669,F,A,64.830000000,1,26,8058566329246,0,14822,94266881,CLX5
2025-09-24T19:33:38.188907459Z,2025-09-24T19:33:38.187809157Z,160,1,432669,F,A,64.830000000,2,26,8058566329247,0,14822,94266881,CLX5
2025-09-24T19:33:38.188907459Z,2025-09-24T19:33:38.187809157Z,160,1,432669,F,A,64.830000000,1,26,8058566329264,0,14822,94266881,CLX5
2025-09-24T19:33:38.188907459Z,2025-09-24T19:33:38.187809157Z,160,1,432669,F,A,64.830000000,1,26,8058566329398,0,14822,94266881,CLX5
2025-09-24T19:33:38.188907459Z,2025-09-24T19:33:38.187809157Z,160,1,432669,F,A,64.830000000,1,26,8058566329260,0,14822,94266881,CLX5
2025-09-24T19:33:38.188907459Z,2025-09-24T19:33:38.187809157Z,160,1,432669,F,A,64.830000000,2,26,8058566329446,0,14822,94266881,CLX5
2025-09-24T19:33:38.188958237Z,2025-09-24T19:33:38.187809157Z,160,1,432669,C,A,64.830000000,1,26,8058566329246,0,18382,94266882,CLX5
2025-09-24T19:33:38.188958237Z,2025-09-24T19:33:38.187809157Z,160,1,432669,C,A,64.830000000,2,26,8058566329247,0,18382,94266882,CLX5
2025-09-24T19:33:38.188958237Z,2025-09-24T19:33:38.187809157Z,160,1,432669,C,A,64.830000000,1,26,8058566329264,0,18382,94266882,CLX5
2025-09-24T19:33:38.188958237Z,2025-09-24T19:33:38.187809157Z,160,1,432669,C,A,64.830000000,1,26,8058566329398,0,18382,94266882,CLX5
2025-09-24T19:33:38.188958237Z,2025-09-24T19:33:38.187809157Z,160,1,432669,C,A,64.830000000,1,26,8058566329260,0,18382,94266882,CLX5
2025-09-24T19:33:38.188958237Z,2025-09-24T19:33:38.187809157Z,160,1,432669,C,A,64.830000000,2,26,8058566329446,128,18382,94266882,CLX5
2025-09-24T19:33:38.188989301Z,2025-09-24T19:33:38.187809791Z,160,1,432669,C,A,64.830000000,2,26,8058566329470,128,16993,94266885,CLX5
2025-09-24T19:33:38.189128178Z,2025-09-24T19:33:38.187811923Z,160,1,432669,A,B,64.820000000,2,26,8058566329531,128,15505,94266891,CLX5
2025-09-24T19:33:38.189227368Z,2025-09-24T19:33:38.187817279Z,160,1,432669,C,A,64.840000000,1,26,8058566328917,128,15649,94266894,CLX5
2025-09-24T19:33:38.189695539Z,2025-09-24T19:33:38.187863835Z,160,1,432669,A,B,64.830000000,2,26,8058566329540,128,18555,94266919,CLX5
2025-09-24T19:33:38.189730397Z,2025-09-24T19:33:38.188117651Z,160,1,432669,A,B,64.820000000,1,26,8058566329541,128,15051,94266922,CLX5
2025-09-24T19:33:38.190313125Z,2025-09-24T19:33:38.188375167Z,160,1,432669,A,B,64.830000000,1,26,8058566329553,128,18332,94266961,CLX5
2025-09-24T19:33:38.191049183Z,2025-09-24T19:33:38.188927757Z,160,1,432669,C,B,64.820000000,1,26,8058566329541,128,15379,94266993,CLX5
2025-09-24T19:33:38.191156014Z,2025-09-24T19:33:38.188948877Z,160,1,432669,C,B,64.820000000,1,26,8058566329521,128,15203,94266998,CLX5
2025-09-24T19:33:38.191220407Z,2025-09-24T19:33:38.189005687Z,160,1,432669,C,B,64.820000000,1,26,8058566329427,128,19883,94267001,CLX5
2025-09-24T19:33:38.191259727Z,2025-09-24T19:33:38.189007743Z,160,1,432669,A,A,64.840000000,1,26,8058566329566,128,15239,94267003,CLX5
2025-09-24T19:33:38.191508938Z,2025-09-24T19:33:38.189159933Z,160,1,432669,T,A,64.830000000,2,26,8058566329568,0,15117,94267018,CLX5
2025-09-24T19:33:38.191508938Z,2025-09-24T19:33:38.189159933Z,160,1,432669,F,B,64.830000000,2,26,8058566329540,0,15117,94267018,CLX5
2025-09-24T19:33:38.191562964Z,2025-09-24T19:33:38.189159933Z,160,1,432669,C,B,64.830000000,2,26,8058566329540,128,18819,94267019,CLX5
2025-09-24T19:33:38.191940954Z,2025-09-24T19:33:38.189257369Z,160,1,432669,A,B,64.820000000,1,26,8058566329572,128,16184,94267042,CLX5
2025-09-24T19:33:38.192160168Z,2025-09-24T19:33:38.189376501Z,160,1,432669,T,A,64.830000000,1,26,8058566329577,0,15010,94267056,CLX5
2025-09-24T19:33:38.192160168Z,2025-09-24T19:33:38.189376501Z,160,1,432669,F,B,64.830000000,1,26,8058566329553,0,15010,94267056,CLX5
2025-09-24T19:33:38.192238730Z,2025-09-24T19:33:38.189376501Z,160,1,432669,C,B,64.830000000,1,26,8058566329553,0,18905,94267057,CLX5
2025-09-24T19:33:38.192238730Z,2025-09-24T19:33:38.189376501Z,160,1,432669,A,A,64.830000000,1,26,8058566329577,128,18905,94267057,CLX5
2025-09-24T19:33:38.192997336Z,2025-09-24T19:33:38.189687891Z,160,1,432669,A,B,64.820000000,1,26,8058566329584,128,15036,94267100,CLX5
2025-09-24T19:33:38.193089591Z,2025-09-24T19:33:38.189777571Z,160,1,432669,T,B,64.830000000,1,26,8058566329588,0,15106,94267106,CLX5
2025-09-24T19:33:38.193089591Z,2025-09-24T19:33:38.189777571Z,160,1,432669,F,A,64.830000000,1,26,8058566329577,0,15106,94267106,CLX5
2025-09-24T19:33:38.193089591Z,2025-09-24T19:33:38.189777571Z,160,1,432669,C,A,64.830000000,1,26,8058566329577,128,15106,94267106,CLX5
2025-09-24T19:33:38.193835563Z,2025-09-24T19:33:38.190803055Z,160,1,432669,A,A,64.830000000,1,26,8058566329597,128,14759,94267153,CLX5
2025-09-24T19:33:38.194121475Z,2025-09-24T19:33:38.191016971Z,160,1,432669,A,A,64.830000000,2,26,8058566329604,128,14909,94267169,CLX5
2025-09-24T19:33:38.194309795Z,2025-09-24T19:33:38.191078159Z,160,1,432669,A,B,64.820000000,1,26,8058566329607,128,18148,94267177,CLX5
2025-09-24T19:33:38.194421079Z,2025-09-24T19:33:38.191116019Z,160,1,432669,C,B,64.820000000,1,26,8058566329527,128,19719,94267182,CLX5
2025-09-24T19:33:38.194858947Z,2025-09-24T19:33:38.191419175Z,160,1,432669,A,A,64.830000000,2,26,8058566329617,128,22625,94267198,CLX5
2025-09-24T19:33:38.195118804Z,2025-09-24T19:33:38.191517053Z,160,1,432669,A,A,64.870000000,1,26,8058566329627,128,14679,94267212,CLX5
2025-09-24T19:33:38.195184400Z,2025-09-24T19:33:38.191523675Z,160,1,432669,A,A,64.830000000,1,26,8058566329630,128,19017,94267214,CLX5
2025-09-24T19:33:38.195233580Z,2025-09-24T19:33:38.191540705Z,160,1,432669,C,B,64.820000000,2,26,8058566329531,128,15097,94267216,CLX5
2025-09-24T19:33:38.195390191Z,2025-09-24T19:33:38.191714421Z,160,1,432669,A,B,64.800000000,1,26,8058566329635,128,17987,94267226,CLX5
2025-09-24T19:33:38.195689856Z,2025-09-24T19:33:38.192160147Z,160,1,432669,A,A,64.830000000,1,26,8058566329642,128,16471,94267242,CLX5
2025-09-24T19:33:38.195738476Z,2025-09-24T19:33:38.192166349Z,160,1,432669,A,A,64.880000000,1,26,8058566329644,128,15737,94267245,CLX5
2025-09-24T19:33:38.195773318Z,2025-09-24T19:33:38.192167961Z,160,1,432669,A,A,64.870000000,1,26,8058566329645,128,14604,94267247,CLX5
2025-09-24T19:33:38.195811278Z,2025-09-24T19:33:38.192169997Z,160,1,432669,A,A,64.830000000,1,26,8058566329646,128,19822,94267248,CLX5
2025-09-24T19:33:38.195841198Z,2025-09-24T19:33:38.192181419Z,160,1,432669,A,B,64.820000000,1,26,8058566329647,128,14469,94267249,CLX5
2025-09-24T19:33:38.195949470Z,2025-09-24T19:33:38.192269697Z,160,1,432669,C,B,64.820000000,1,26,8058566329607,128,15427,94267253,CLX5
2025-09-24T19:33:38.196021976Z,2025-09-24T19:33:38.192282215Z,160,1,432669,C,B,64.820000000,1,26,8058566329584,128,18084,94267255,CLX5
2025-09-24T19:33:38.196048463Z,2025-09-24T19:33:38.192286767Z,160,1,432669,C,B,64.820000000,1,26,8058566329572,128,15372,94267256,CLX5
2025-09-24T19:33:38.196592078Z,2025-09-24T19:33:38.193100581Z,160,1,432669,C,B,64.820000000,1,26,8058566329647,128,15563,94267277,CLX5
2025-09-24T19:33:38.196786818Z,2025-09-24T19:33:38.193323501Z,160,1,432669,C,A,64.830000000,1,26,8058566329642,128,19771,94267286,CLX5
2025-09-24T19:33:38.197227695Z,2025-09-24T19:33:38.193843067Z,160,1,432669,A,B,64.820000000,1,26,8058566329666,128,15785,94267301,CLX5
2025-09-24T19:33:38.197279195Z,2025-09-24T19:33:38.193870697Z,160,1,432669,A,B,64.820000000,1,26,8058566329667,128,15747,94267304,CLX5
2025-09-24T19:33:38.197429515Z,2025-09-24T19:33:38.193944267Z,160,1,432669,C,B,64.820000000,1,26,8058566329666,128,18935,94267310,CLX5
2025-09-24T19:33:38.197507186Z,2025-09-24T19:33:38.194128789Z,160,1,432669,A,B,64.820000000,1,26,8058566329671,128,17343,94267314,CLX5
2025-09-24T19:33:38.197574160Z,2025-09-24T19:33:38.194254141Z,160,1,432669,C,A,64.830000000,1,26,8058566329646,128,16959,94267316,CLX5
2025-09-24T19:33:38.197617389Z,2025-09-24T19:33:38.194317497Z,160,1,432669,C,B,64.820000000,1,26,8058566329671,128,15375,94267318,CLX5
2025-09-24T19:33:38.197774690Z,2025-09-24T19:33:38.194496799Z,160,1,432669,A,B,64.820000000,1,26,8058566329673,128,16568,94267324,CLX5
2025-09-24T19:33:38.197812873Z,2025-09-24T19:33:38.194554031Z,160,1,432669,C,B,64.820000000,1,26,8058566329673,128,14911,94267326,CLX5
2025-09-24T19:33:38.198491073Z,2025-09-24T19:33:38.195242093Z,160,1,432669,A,B,64.820000000,1,26,8058566329685,128,18853,94267363,CLX5
2025-09-24T19:33:38.198674769Z,2025-09-24T19:33:38.195535819Z,160,1,432669,A,A,64.830000000,1,26,8058566329687,128,16868,94267368,CLX5
2025-09-24T19:33:38.198728811Z,2025-09-24T19:33:38.195697937Z,160,1,432669,A,B,64.820000000,1,26,8058566329688,128,18799,94267370,CLX5
2025-09-24T19:33:38.198885751Z,2025-09-24T19:33:38.195957817Z,160,1,432669,C,B,64.820000000,1,26,8058566329688,128,15194,94267376,CLX5
2025-09-24T19:33:38.198970710Z,2025-09-24T19:33:38.196504821Z,160,1,432669,A,B,64.820000000,1,26,8058566329691,128,16240,94267380,CLX5
2025-09-24T19:33:38.199061951Z,2025-09-24T19:33:38.196893179Z,160,1,432669,A,B,64.820000000,2,26,8058566329693,128,14764,94267386,CLX5
2025-09-24T19:33:38.199205859Z,2025-09-24T19:33:38.197520089Z,160,1,432669,C,A,64.830000000,2,26,8058566329617,128,17364,94267393,CLX5
2025-09-24T19:33:38.199403494Z,2025-09-24T19:33:38.198652859Z,160,1,432669,C,B,64.820000000,1,26,8058566329691,128,15061,94267403,CLX5
2025-09-24T19:33:38.200236638Z,2025-09-24T19:33:38.200093793Z,160,1,432669,C,B,64.820000000,1,26,8058566329685,128,15693,94267438,CLX5
2025-09-24T19:33:38.200442436Z,2025-09-24T19:33:38.200245871Z,160,1,432669,A,B,64.820000000,1,26,8058566329709,128,15210,94267452,CLX5
2025-09-24T19:33:38.265496038Z,2025-09-24T19:33:38.265367191Z,160,1,432669,C,A,64.870000000,1,26,8058566329627,128,18356,94267516,CLX5
2025-09-24T19:33:38.372073628Z,2025-09-24T19:33:38.371945511Z,160,1,432669,C,B,64.800000000,1,26,8058566329635,128,18384,94267614,CLX5
2025-09-24T19:33:38.750060792Z,2025-09-24T19:33:38.749934215Z,160,1,432669,C,B,64.820000000,1,26,8058566329709,128,18332,94267681,CLX5
2025-09-24T19:33:39.028125155Z,2025-09-24T19:33:39.027774145Z,160,1,432669,T,B,64.830000000,3,26,8058566326500,0,19100,94267730,CLX5
2025-09-24T19:33:39.028125155Z,2025-09-24T19:33:39.027774145Z,160,1,432669,F,B,64.830000000,3,26,8058566326500,0,19100,94267730,CLX5
2025-09-24T19:33:39.028125155Z,2025-09-24T19:33:39.027774145Z,160,1,432669,F,A,64.830000000,1,26,8058566329597,0,19100,94267730,CLX5
2025-09-24T19:33:39.028125155Z,2025-09-24T19:33:39.027774145Z,160,1,432669,F,A,64.830000000,2,26,8058566329604,0,19100,94267730,CLX5
2025-09-24T19:33:39.028135269Z,2025-09-24T19:33:39.027774145Z,160,1,432669,C,B,64.820000000,3,26,8058566326500,0,15123,94267731,CLX5
2025-09-24T19:33:39.028135269Z,2025-09-24T19:33:39.027774145Z,160,1,432669,C,A,64.830000000,1,26,8058566329597,0,15123,94267731,CLX5
2025-09-24T19:33:39.028135269Z,2025-09-24T19:33:39.027774145Z,160,1,432669,C,A,64.830000000,2,26,8058566329604,128,15123,94267731,CLX5
2025-09-24T19:33:39.028324640Z,2025-09-24T19:33:39.028119749Z,160,1,432669,C,A,64.840000000,1,26,8058566328916,128,15736,94267737,CLX5
2025-09-24T19:33:39.028352785Z,2025-09-24T19:33:39.028121459Z,160,1,432669,C,A,64.840000000,1,26,8058566329566,128,14936,94267738,CLX5
2025-09-24T19:33:39.028389087Z,2025-09-24T19:33:39.028123225Z,160,1,432669,A,B,64.820000000,1,26,8058566329823,128,15286,94267739,CLX5
2025-09-24T19:33:39.028424666Z,2025-09-24T19:33:39.028125125Z,160,1,432669,A,B,64.820000000,1,26,8058566329824,128,19148,94267740,CLX5
2025-09-24T19:33:39.028496785Z,2025-09-24T19:33:39.028126967Z,160,1,432669,A,B,64.820000000,1,26,8058566329826,128,14350,94267742,CLX5
2025-09-24T19:33:39.028504949Z,2025-09-24T19:33:39.028138143Z,160,1,432669,T,B,64.830000000,1,26,8058566329827,0,14657,94267743,CLX5
2025-09-24T19:33:39.028504949Z,2025-09-24T19:33:39.028138143Z,160,1,432669,F,A,64.830000000,1,26,8058566329630,0,14657,94267743,CLX5
2025-09-24T19:33:39.028558967Z,2025-09-24T19:33:39.028138143Z,160,1,432669,C,A,64.830000000,1,26,8058566329630,128,22033,94267744,CLX5
2025-09-24T19:33:39.028774227Z,2025-09-24T19:33:39.028175197Z,160,1,432669,C,B,64.820000000,1,26,8058566329823,128,19276,94267755,CLX5
2025-09-24T19:33:39.028853526Z,2025-09-24T19:33:39.028514195Z,160,1,432669,T,B,64.830000000,1,26,8058566329832,0,14154,94267759,CLX5
2025-09-24T19:33:39.028853526Z,2025-09-24T19:33:39.028514195Z,160,1,432669,F,A,64.830000000,1,26,8058566329687,0,14154,94267759,CLX5
2025-09-24T19:33:39.028853526Z,2025-09-24T19:33:39.028514195Z,160,1,432669,C,A,64.830000000,1,26,8058566329687,128,14154,94267759,CLX5
2025-09-24T19:33:39.029110739Z,2025-09-24T19:33:39.028784827Z,160,1,432669,A,B,64.820000000,1,26,8058566329835,128,15776,94267771,CLX5
2025-09-24T19:33:39.029146500Z,2025-09-24T19:33:39.028834879Z,160,1,432669,C,B,64.820000000,1,26,8058566329835,128,20105,94267772,CLX5
2025-09-24T19:33:39.029323003Z,2025-09-24T19:33:39.028874237Z,160,1,432669,A,A,64.840000000,1,26,8058566329839,128,15424,94267782,CLX5
2025-09-24T19:33:39.029605051Z,2025-09-24T19:33:39.028974975Z,160,1,432669,A,B,64.820000000,1,26,8058566329844,128,14894,94267794,CLX5
2025-09-24T19:33:39.029824225Z,2025-09-24T19:33:39.029133233Z,160,1,432669,A,B,64.820000000,1,26,8058566329848,128,16463,94267806,CLX5
2025-09-24T19:33:39.029881348Z,2025-09-24T19:33:39.029170249Z,160,1,432669,A,B,64.820000000,1,26,8058566329849,128,15230,94267808,CLX5
2025-09-24T19:33:39.029933408Z,2025-09-24T19:33:39.029331215Z,160,1,432669,A,B,64.820000000,1,26,8058566329852,128,17326,94267811,CLX5
2025-09-24T19:33:39.029984823Z,2025-09-24T19:33:39.029541177Z,160,1,432669,C,B,64.820000000,1,26,8058566329852,128,15031,94267813,CLX5
2025-09-24T19:33:39.030357012Z,2025-09-24T19:33:39.029889335Z,160,1,432669,A,A,64.840000000,1,26,8058566329855,128,18802,94267831,CLX5
2025-09-24T19:33:39.030504063Z,2025-09-24T19:33:39.030270785Z,160,1,432669,A,B,64.820000000,1,26,8058566329857,128,15021,94267839,CLX5
2025-09-24T19:33:39.037423566Z,2025-09-24T19:33:39.037208839Z,160,1,432669,A,A,64.830000000,1,26,8058566329869,128,18259,94267892,CLX5
2025-09-24T19:33:39.040613985Z,2025-09-24T19:33:39.040462577Z,160,1,432669,M,A,64.840000000,1,26,8058566329869,128,19661,94267899,CLX5
2025-09-24T19:33:39.140418704Z,2025-09-24T19:33:39.140220071Z,160,1,432669,M,A,64.830000000,1,26,8058566329869,128,18651,94267943,CLX5
2025-09-24T19:33:39.140600457Z,2025-09-24T19:33:39.140453841Z,160,1,432669,C,B,64.820000000,1,26,8058566329849,128,15193,94267950,CLX5
2025-09-24T19:33:39.140755001Z,2025-09-24T19:33:39.140631105Z,160,1,432669,C,B,64.820000000,1,26,8058566329848,128,18742,94267952,CLX5
2025-09-24T19:33:39.140898694Z,2025-09-24T19:33:39.140778287Z,160,1,432669,C,B,64.820000000,1,26,8058566329844,128,17286,94267953,CLX5
2025-09-24T19:33:39.210230524Z,2025-09-24T19:33:39.210097963Z,160,1,432669,A,B,64.780000000,2,26,8058566329888,128,18006,94267957,CLX5
2025-09-24T19:33:43.533313088Z,2025-09-24T19:33:43.533133043Z,160,1,432669,A,B,64.820000000,1,26,8058566330172,128,18253,94268725,CLX5
2025-09-24T19:33:44.397473096Z,2025-09-24T19:33:44.397165875Z,160,1,432669,C,B,64.820000000,1,26,8058566329857,128,15185,94268768,CLX5
2025-09-24T19:33:44.397707378Z,2025-09-24T19:33:44.397492625Z,160,1,432669,A,B,64.820000000,1,26,8058566330188,128,14922,94268777,CLX5
2025-09-24T19:33:48.335221875Z,2025-09-24T19:33:48.334870041Z,160,1,432669,T,A,64.820000000,2,26,8058566330210,0,17735,94268839,CLX5
2025-09-24T19:33:48.335221875Z,2025-09-24T19:33:48.334870041Z,160,1,432669,F,B,64.820000000,1,26,8058566323034,0,17735,94268839,CLX5
2025-09-24T19:33:48.335221875Z,2025-09-24T19:33:48.334870041Z,160,1,432669,F,B,64.820000000,1,26,8058566323035,0,17735,94268839,CLX5
2025-09-24T19:33:48.335233710Z,2025-09-24T19:33:48.334870041Z,160,1,432669,C,B,64.820000000,1,26,8058566323034,0,16889,94268840,CLX5
2025-09-24T19:33:48.335233710Z,2025-09-24T19:33:48.334870041Z,160,1,432669,C,B,64.820000000,1,26,8058566323035,128,16889,94268840,CLX5
2025-09-24T19:33:48.335492473Z,2025-09-24T19:33:48.335198865Z,160,1,432669,A,A,64.830000000,1,26,8058566330213,128,16991,94268844,CLX5
2025-09-24T19:33:48.335978016Z,2025-09-24T19:33:48.335565357Z,160,1,432669,C,A,64.830000000,1,26,8058566330213,128,18513,94268870,CLX5
2025-09-24T19:33:56.766671849Z,2025-09-24T19:33:56.766140039Z,160,1,432669,C,B,64.820000000,1,26,8058566329826,128,19458,94269012,CLX5
2025-09-24T19:33:56.766889934Z,2025-09-24T19:33:56.766140693Z,160,1,432669,A,A,64.830000000,1,26,8058566330278,128,23594,94269017,CLX5
2025-09-24T19:33:56.767234464Z,2025-09-24T19:33:56.766141881Z,160,1,432669,A,A,64.830000000,1,26,8058566330283,128,18162,94269026,CLX5
2025-09-24T19:33:56.767322387Z,2025-09-24T19:33:56.766142207Z,160,1,432669,A,A,64.830000000,1,26,8058566330284,128,20673,94269030,CLX5
2025-09-24T19:33:56.767355525Z,2025-09-24T19:33:56.766144251Z,160,1,432669,A,A,64.830000000,1,26,8058566330285,128,19946,94269032,CLX5
2025-09-24T19:33:56.767611463Z,2025-09-24T19:33:56.766153735Z,160,1,432669,A,A,64.830000000,2,26,8058566330291,128,22184,94269040,CLX5
2025-09-24T19:33:56.768235016Z,2025-09-24T19:33:56.766157705Z,160,1,432669,C,B,64.810000000,2,26,8058566328625,128,25502,94269063,CLX5
2025-09-24T19:33:56.768322456Z,2025-09-24T19:33:56.766158181Z,160,1,432669,C,B,64.800000000,2,26,8058566323254,128,18368,94269066,CLX5
2025-09-24T19:33:56.769142222Z,2025-09-24T19:33:56.766164313Z,160,1,432669,A,A,64.830000000,2,26,8058566330305,128,23870,94269095,CLX5
2025-09-24T19:33:56.769261271Z,2025-09-24T19:33:56.766168231Z,160,1,432669,C,B,64.820000000,1,26,8058566330188,128,22358,94269101,CLX5
2025-09-24T19:33:56.769346522Z,2025-09-24T19:33:56.766176275Z,160,1,432669,A,A,64.830000000,1,26,8058566330307,128,19657,94269105,CLX5
2025-09-24T19:33:56.769392531Z,2025-09-24T19:33:56.766216497Z,160,1,432669,A,A,64.830000000,1,26,8058566330308,128,20056,94269108,CLX5
2025-09-24T19:33:56.769482182Z,2025-09-24T19:33:56.766242971Z,160,1,432669,T,A,64.820000000,1,26,8058566330310,0,16780,94269113,CLX5
2025-09-24T19:33:56.769482182Z,2025-09-24T19:33:56.766242971Z,160,1,432669,F,B,64.820000000,1,26,8058566323716,0,16780,94269113,CLX5
2025-09-24T19:33:56.769482182Z,2025-09-24T19:33:56.766242971Z,160,1,432669,C,B,64.820000000,1,26,8058566323061,0,16780,94269113,CLX5
2025-09-24T19:33:56.769482182Z,2025-09-24T19:33:56.766242971Z,160,1,432669,M,B,64.820000000,1,26,8058566323716,128,16780,94269113,CLX5
2025-09-24T19:33:56.769534672Z,2025-09-24T19:33:56.766283175Z,160,1,432669,T,A,64.820000000,1,26,8058566330311,0,18133,94269116,CLX5
2025-09-24T19:33:56.769534672Z,2025-09-24T19:33:56.766283175Z,160,1,432669,F,B,64.820000000,1,26,8058566323716,0,18133,94269116,CLX5
2025-09-24T19:33:56.769534672Z,2025-09-24T19:33:56.766283175Z,160,1,432669,C,B,64.820000000,1,26,8058566323716,128,18133,94269116,CLX5
2025-09-24T19:33:56.769687680Z,2025-09-24T19:33:56.766338257Z,160,1,432669,T,A,64.820000000,17,26,8058566330313,0,27425,94269122,CLX5
2025-09-24T19:33:56.769687680Z,2025-09-24T19:33:56.766338257Z,160,1,432669,F,B,64.820000000,1,26,8058566323717,0,27425,94269122,CLX5
2025-09-24T19:33:56.769687680Z,2025-09-24T19:33:56.766338257Z,160,1,432669,F,B,64.820000000,1,26,8058566321508,0,27425,94269122,CLX5
2025-09-24T19:33:56.769687680Z,2025-09-24T19:33:56.766338257Z,160,1,432669,F,B,64.820000000,1,26,8058566311303,0,27425,94269122,CLX5
2025-09-24T19:33:56.769687680Z,2025-09-24T19:33:56.766338257Z,160,1,432669,F,B,64.820000000,1,26,8058566327178,0,27425,94269122,CLX5
2025-09-24T19:33:56.769687680Z,2025-09-24T19:33:56.766338257Z,160,1,432669,F,B,64.820000000,1,26,8058566327347,0,27425,94269122,CLX5
2025-09-24T19:33:56.769687680Z,2025-09-24T19:33:56.766338257Z,160,1,432669,F,B,64.820000000,2,26,8058566328750,0,27425,94269122,CLX5
2025-09-24T19:33:56.769687680Z,2025-09-24T19:33:56.766338257Z,160,1,432669,F,B,64.820000000,3,26,8058566328914,0,27425,94269122,CLX5
2025-09-24T19:33:56.769687680Z,2025-09-24T19:33:56.766338257Z,160,1,432669,F,B,64.820000000,1,26,8058566329667,0,27425,94269122,CLX5
2025-09-24T19:33:56.769687680Z,2025-09-24T19:33:56.766338257Z,160,1,432669,F,B,64.820000000,2,26,8058566329693,0,27425,94269122,CLX5
2025-09-24T19:33:56.769687680Z,2025-09-24T19:33:56.766338257Z,160,1,432669,F,B,64.820000000,1,26,8058566330172,0,27425,94269122,CLX5
2025-09-24T19:33:56.769687680Z,2025-09-24T19:33:56.766338257Z,160,1,432669,C,B,64.820000000,1,26,8058566323717,0,27425,94269122,CLX5
2025-09-24T19:33:56.769687680Z,2025-09-24T19:33:56.766338257Z,160,1,432669,C,B,64.820000000,1,26,8058566321508,0,27425,94269122,CLX5
2025-09-24T19:33:56.769687680Z,2025-09-24T19:33:56.766338257Z,160,1,432669,C,B,64.820000000,1,26,8058566311303,0,27425,94269122,CLX5
2025-09-24T19:33:56.769687680Z,2025-09-24T19:33:56.766338257Z,160,1,432669,C,B,64.820000000,1,26,8058566327178,0,27425,94269122,CLX5
2025-09-24T19:33:56.769687680Z,2025-09-24T19:33:56.766338257Z,160,1,432669,C,B,64.820000000,1,26,8058566327347,0,27425,94269122,CLX5
2025-09-24T19:33:56.769687680Z,2025-09-24T19:33:56.766338257Z,160,1,432669,C,B,64.820000000,2,26,8058566328750,0,27425,94269122,CLX5
2025-09-24T19:33:56.769687680Z,2025-09-24T19:33:56.766338257Z,160,1,432669,C,B,64.820000000,3,26,8058566328914,0,27425,94269122,CLX5
2025-09-24T19:33:56.769687680Z,2025-09-24T19:33:56.766338257Z,160,1,432669,C,B,64.820000000,1,26,8058566329667,0,27425,94269122,CLX5
2025-09-24T19:33:56.769687680Z,2025-09-24T19:33:56.766338257Z,160,1,432669,C,B,64.820000000,2,26,8058566329693,0,27425,94269122,CLX5
2025-09-24T19:33:56.769687680Z,2025-09-24T19:33:56.766338257Z,160,1,432669,C,B,64.820000000,1,26,8058566330172,0,27425,94269122,CLX5
2025-09-24T19:33:56.769687680Z,2025-09-24T19:33:56.766338257Z,160,1,432669,C,B,64.820000000,1,26,8058566329824,128,27425,94269122,CLX5
2025-09-24T19:33:56.770024285Z,2025-09-24T19:33:56.766345505Z,160,1,432669,A,A,64.820000000,1,26,8058566330319,128,20283,94269135,CLX5
2025-09-24T19:33:56.770461300Z,2025-09-24T19:33:56.766359741Z,160,1,432669,C,B,64.780000000,2,26,8058566329888,128,18717,94269158,CLX5
2025-09-24T19:33:56.770608287Z,2025-09-24T19:33:56.766364831Z,160,1,432669,A,A,64.830000000,1,26,8058566330339,128,20044,94269165,CLX5
2025-09-24T19:33:56.770714565Z,2025-09-24T19:33:56.766366385Z,160,1,432669,A,A,64.820000000,1,26,8058566330341,128,17898,94269169,CLX5
2025-09-24T19:33:56.771199939Z,2025-09-24T19:33:56.766416393Z,160,1,432669,A,A,64.820000000,1,26,8058566330348,128,17981,94269196,CLX5
2025-09-24T19:33:56.771342480Z,2025-09-24T19:33:56.766416927Z,160,1,432669,A,A,64.820000000,1,26,8058566330351,128,15909,94269203,CLX5
2025-09-24T19:33:56.771931497Z,2025-09-24T19:33:56.766425767Z,160,1,432669,C,B,64.810000000,1,26,8058566312880,128,14808,94269239,CLX5
2025-09-24T19:33:56.772828329Z,2025-09-24T19:33:56.766437451Z,160,1,432669,A,A,64.820000000,2,26,8058566330387,128,20726,94269301,CLX5
2025-09-24T19:33:56.772857219Z,2025-09-24T19:33:56.766437629Z,160,1,432669,C,B,64.810000000,2,26,8058566312876,128,14240,94269302,CLX5
2025-09-24T19:33:56.773144160Z,2025-09-24T19:33:56.766446271Z,160,1,432669,C,B,64.810000000,2,26,8058566312883,128,17026,94269317,CLX5
2025-09-24T19:33:56.773173941Z,2025-09-24T19:33:56.766446427Z,160,1,432669,C,B,64.810000000,1,26,8058566312885,128,14867,94269318,CLX5
2025-09-24T19:33:56.773666956Z,2025-09-24T19:33:56.766476089Z,160,1,432669,A,A,64.820000000,2,26,8058566330422,128,16608,94269337,CLX5
2025-09-24T19:33:56.775374031Z,2025-09-24T19:33:56.766525257Z,160,1,432669,A,A,64.830000000,2,26,8058566330477,128,19158,94269408,CLX5
2025-09-24T19:33:56.777192667Z,2025-09-24T19:33:56.766649343Z,160,1,432669,A,A,64.820000000,1,26,8058566330533,128,18210,94269509,CLX5
2025-09-24T19:33:56.777247653Z,2025-09-24T19:33:56.766653797Z,160,1,432669,C,B,64.810000000,1,26,8058566320736,128,14290,94269511,CLX5
2025-09-24T19:33:56.777295773Z,2025-09-24T19:33:56.766660095Z,160,1,432669,A,A,64.820000000,3,26,8058566330536,128,19449,94269513,CLX5
2025-09-24T19:33:56.778495695Z,2025-09-24T19:33:56.766720245Z,160,1,432669,C,B,64.810000000,2,26,8058566320855,128,15031,94269573,CLX5
2025-09-24T19:33:56.779056282Z,2025-09-24T19:33:56.766795467Z,160,1,432669,A,A,64.830000000,1,26,8058566330575,128,18320,94269599,CLX5
2025-09-24T19:33:56.779161393Z,2025-09-24T19:33:56.766842467Z,160,1,432669,A,A,64.830000000,2,26,8058566330578,128,18804,94269604,CLX5
2025-09-24T19:33:56.779192287Z,2025-09-24T19:33:56.766842773Z,160,1,432669,C,B,64.810000000,2,26,8058566298574,128,15309,94269605,CLX5
2025-09-24T19:33:56.779240055Z,2025-09-24T19:33:56.766861475Z,160,1,432669,A,A,64.860000000,1,26,8058566330580,128,14900,94269608,CLX5
2025-09-24T19:33:56.779270912Z,2025-09-24T19:33:56.766864891Z,160,1,432669,T,A,64.810000000,3,26,8058566330581,0,14769,94269610,CLX5
2025-09-24T19:33:56.779270912Z,2025-09-24T19:33:56.766864891Z,160,1,432669,F,B,64.810000000,3,26,8058566288724,0,14769,94269610,CLX5
2025-09-24T19:33:56.779302291Z,2025-09-24T19:33:56.766864891Z,160,1,432669,C,B,64.810000000,3,26,8058566288724,0,17457,94269611,CLX5
2025-09-24T19:33:56.779302291Z,2025-09-24T19:33:56.766864891Z,160,1,432669,C,B,64.810000000,1,26,8058566288514,0,17457,94269611,CLX5
2025-09-24T19:33:56.779302291Z,2025-09-24T19:33:56.766864891Z,160,1,432669,C,B,64.810000000,1,26,8058566288515,128,17457,94269611,CLX5
2025-09-24T19:33:56.779598516Z,2025-09-24T19:33:56.766901965Z,160,1,432669,C,B,64.810000000,2,26,8058566321424,128,18685,94269620,CLX5
2025-09-24T19:33:56.780231836Z,2025-09-24T19:33:56.767015875Z,160,1,432669,A,A,64.850000000,1,26,8058566330617,128,14960,94269646,CLX5
2025-09-24T19:33:56.781035667Z,2025-09-24T19:33:56.767244669Z,160,1,432669,A,A,64.820000000,2,26,8058566330633,128,15510,94269683,CLX5
2025-09-24T19:33:56.781975244Z,2025-09-24T19:33:56.767797509Z,160,1,432669,A,A,64.820000000,1,26,8058566330658,128,15152,94269736,CLX5
2025-09-24T19:33:56.782000924Z,2025-09-24T19:33:56.767805093Z,160,1,432669,C,A,64.840000000,1,26,8058566329839,128,14859,94269737,CLX5
2025-09-24T19:33:56.782176019Z,2025-09-24T19:33:56.767859579Z,160,1,432669,A,A,64.820000000,1,26,8058566330662,128,15436,94269746,CLX5
2025-09-24T19:33:56.782516977Z,2025-09-24T19:33:56.768110357Z,160,1,432669,C,B,64.810000000,1,26,8058566321434,128,21837,94269764,CLX5
2025-09-24T19:33:56.782767870Z,2025-09-24T19:33:56.768226381Z,160,1,432669,A,B,64.810000000,1,26,8058566330679,128,18567,94269774,CLX5
2025-09-24T19:33:56.783134371Z,2025-09-24T19:33:56.768308687Z,160,1,432669,A,A,64.830000000,3,26,8058566330683,128,15324,94269794,CLX5
2025-09-24T19:33:56.784495618Z,2025-09-24T19:33:56.769687389Z,160,1,432669,A,A,64.820000000,1,26,8058566330715,128,16965,94269877,CLX5
2025-09-24T19:33:56.784607840Z,2025-09-24T19:33:56.769698071Z,160,1,432669,C,B,64.790000000,1,26,8058566323125,128,17059,94269882,CLX5
2025-09-24T19:33:56.784636968Z,2025-09-24T19:33:56.769728099Z,160,1,432669,A,A,64.830000000,1,26,8058566330721,128,15375,94269883,CLX5
2025-09-24T19:33:56.784769787Z,2025-09-24T19:33:56.769781819Z,160,1,432669,M,A,64.830000000,1,26,8058566325943,128,14102,94269890,CLX5
2025-09-24T19:33:56.784948699Z,2025-09-24T19:33:56.769906017Z,160,1,432669,A,A,64.830000000,1,26,8058566330731,128,15001,94269896,CLX5
2025-09-24T19:33:56.785253064Z,2025-09-24T19:33:56.770027337Z,160,1,432669,A,A,64.820000000,1,26,8058566330743,128,14338,94269910,CLX5
2025-09-24T19:33:56.785417001Z,2025-09-24T19:33:56.770033981Z,160,1,432669,A,B,64.810000000,1,26,8058566330745,128,18554,94269918,CLX5
2025-09-24T19:33:56.785634210Z,2025-09-24T19:33:56.770109085Z,160,1,432669,M,B,63.660000000,4,26,8058566319508,128,16968,94269927,CLX5
2025-09-24T19:33:56.786346992Z,2025-09-24T19:33:56.770314709Z,160,1,432669,M,A,64.840000000,3,26,8058566275421,128,14942,94269981,CLX5
2025-09-24T19:33:56.786706628Z,2025-09-24T19:33:56.770426467Z,160,1,432669,C,B,64.780000000,1,26,8058566323114,128,14669,94269997,CLX5
2025-09-24T19:33:56.786737484Z,2025-09-24T19:33:56.770426615Z,160,1,432669,C,B,64.770000000,1,26,8058566320901,128,18657,94269998,CLX5
2025-09-24T19:33:56.786793031Z,2025-09-24T19:33:56.770427273Z,160,1,432669,C,B,64.720000000,2,26,8058566321275,128,14927,94270000,CLX5
2025-09-24T19:33:56.787396655Z,2025-09-24T19:33:56.770758977Z,160,1,432669,C,A,64.840000000,3,26,8058566275421,128,16333,94270036,CLX5
2025-09-24T19:33:56.787746460Z,2025-09-24T19:33:56.771321513Z,160,1,432669,M,A,64.840000000,3,26,8058566321460,128,13805,94270058,CLX5
2025-09-24T19:33:56.788259796Z,2025-09-24T19:33:56.771704519Z,160,1,432669,M,A,64.830000000,1,26,8058566173085,128,15605,94270090,CLX5
2025-09-24T19:33:56.788430805Z,2025-09-24T19:33:56.771994117Z,160,1,432669,A,A,64.860000000,2,26,8058566330777,128,15022,94270096,CLX5
2025-09-24T19:33:56.788541284Z,2025-09-24T19:33:56.772128013Z,160,1,432669,M,A,64.940000000,1,26,8058565075241,128,14641,94270102,CLX5
2025-09-24T19:33:56.789542842Z,2025-09-24T19:33:56.773027377Z,160,1,432669,M,A,64.840000000,1,26,8058566329869,128,15307,94270165,CLX5
2025-09-24T19:33:56.790531613Z,2025-09-24T19:33:56.774404187Z,160,1,432669,C,A,64.820000000,2,26,8058566330422,128,15445,94270221,CLX5
2025-09-24T19:33:56.791688260Z,2025-09-24T19:33:56.775591541Z,160,1,432669,M,A,64.840000000,1,26,8058566282798,128,15119,94270301,CLX5
2025-09-24T19:33:56.792414749Z,2025-09-24T19:33:56.776245711Z,160,1,432669,C,A,64.820000000,1,26,8058566330658,128,18782,94270342,CLX5
2025-09-24T19:33:56.793456694Z,2025-09-24T19:33:56.777204153Z,160,1,432669,A,B,64.810000000,1,26,8058566330853,128,18985,94270406,CLX5
2025-09-24T19:33:56.794343411Z,2025-09-24T19:33:56.778043253Z,160,1,432669,C,B,64.810000000,1,26,8058566330745,128,14761,94270459,CLX5
2025-09-24T19:33:56.794909059Z,2025-09-24T19:33:56.778418461Z,160,1,432669,T,A,64.810000000,1,26,8058566330875,0,15019,94270489,CLX5
2025-09-24T19:33:56.794909059Z,2025-09-24T19:33:56.778418461Z,160,1,432669,F,B,64.810000000,1,26,8058566304545,0,15019,94270489,CLX5
2025-09-24T19:33:56.794961573Z,2025-09-24T19:33:56.778418461Z,160,1,432669,C,B,64.810000000,1,26,8058566304545,128,17966,94270490,CLX5
2025-09-24T19:33:56.795399364Z,2025-09-24T19:33:56.779197141Z,160,1,432669,A,B,64.810000000,1,26,8058566330880,128,18931,94270512,CLX5
2025-09-24T19:33:56.795417181Z,2025-09-24T19:33:56.779200751Z,160,1,432669,A,B,64.810000000,1,26,8058566330881,128,15186,94270514,CLX5
2025-09-24T19:33:56.795577477Z,2025-09-24T19:33:56.779277681Z,160,1,432669,A,B,64.810000000,1,26,8058566330884,128,19373,94270521,CLX5
2025-09-24T19:33:56.796008164Z,2025-09-24T19:33:56.779508627Z,160,1,432669,A,B,64.810000000,1,26,8058566330886,128,16504,94270544,CLX5
2025-09-24T19:33:56.796078386Z,2025-09-24T19:33:56.779535947Z,160,1,432669,A,B,64.810000000,2,26,8058566330888,128,16384,94270547,CLX5
2025-09-24T19:33:56.796162386Z,2025-09-24T19:33:56.779607867Z,160,1,432669,T,A,64.810000000,2,26,8058566330890,0,15224,94270552,CLX5
2025-09-24T19:33:56.796162386Z,2025-09-24T19:33:56.779607867Z,160,1,432669,F,B,64.810000000,1,26,8058566330679,0,15224,94270552,CLX5
2025-09-24T19:33:56.796162386Z,2025-09-24T19:33:56.779607867Z,160,1,432669,F,B,64.810000000,1,26,8058566330853,0,15224,94270552,CLX5
2025-09-24T19:33:56.796189264Z,2025-09-24T19:33:56.779607867Z,160,1,432669,C,B,64.810000000,1,26,8058566330679,0,16282,94270553,CLX5
2025-09-24T19:33:56.796189264Z,2025-09-24T19:33:56.779607867Z,160,1,432669,C,B,64.810000000,1,26,8058566330853,128,16282,94270553,CLX5
2025-09-24T19:33:56.797097330Z,2025-09-24T19:33:56.780387391Z,160,1,432669,A,A,64.840000000,1,26,8058566330904,128,14716,94270602,CLX5
2025-09-24T19:33:56.797127488Z,2025-09-24T19:33:56.780390443Z,160,1,432669,C,A,64.900000000,1,26,8058566307915,128,18280,94270603,CLX5
2025-09-24T19:33:56.798752322Z,2025-09-24T19:33:56.781061705Z,160,1,432669,A,B,64.810000000,1,26,8058566330941,128,16991,94270678,CLX5
2025-09-24T19:33:56.800324965Z,2025-09-24T19:33:56.782024447Z,160,1,432669,A,B,64.810000000,1,26,8058566330949,128,19768,94270784,CLX5
2025-09-24T19:33:56.800661063Z,2025-09-24T19:33:56.782184125Z,160,1,432669,C,A,64.820000000,1,26,8058566330715,128,19373,94270805,CLX5
2025-09-24T19:33:56.801603433Z,2025-09-24T19:33:56.783146119Z,160,1,432669,C,B,64.810000000,2,26,8058566330888,128,16332,94270861,CLX5
2025-09-24T19:33:56.801649151Z,2025-09-24T19:33:56.783158099Z,160,1,432669,M,A,64.820000000,1,26,8058566239191,128,15255,94270863,CLX5
2025-09-24T19:33:56.802209976Z,2025-09-24T19:33:56.784502021Z,160,1,432669,A,B,64.770000000,1,26,8058566330971,128,15263,94270902,CLX5
2025-09-24T19:33:56.802598356Z,2025-09-24T19:33:56.784631019Z,160,1,432669,A,B,64.790000000,1,26,8058566330981,128,14900,94270922,CLX5
2025-09-24T19:33:56.803549144Z,2025-09-24T19:33:56.786939603Z,160,1,432669,C,A,64.850000000,1,26,8058566324295,128,18218,94270975,CLX5
2025-09-24T19:33:56.803840746Z,2025-09-24T19:33:56.787736003Z,160,1,432669,M,A,64.820000000,1,26,8058566329869,128,19287,94270988,CLX5
2025-09-24T19:33:56.803942340Z,2025-09-24T19:33:56.787988759Z,160,1,432669,A,A,64.820000000,1,26,8058566330998,128,19203,94270994,CLX5
2025-09-24T19:33:56.804526488Z,2025-09-24T19:33:56.789574417Z,160,1,432669,C,A,64.830000000,1,26,8058566330731,128,14877,94271025,CLX5
2025-09-24T19:33:56.804886415Z,2025-09-24T19:33:56.789877897Z,160,1,432669,C,B,64.810000000,1,26,8058566330884,128,16197,94271047,CLX5
2025-09-24T19:33:56.805331495Z,2025-09-24T19:33:56.790570085Z,160,1,432669,A,B,64.800000000,1,26,8058566331010,128,13874,94271073,CLX5
2025-09-24T19:33:56.806027588Z,2025-09-24T19:33:56.792424493Z,160,1,432669,A,B,64.810000000,1,26,8058566331027,128,19304,94271113,CLX5
2025-09-24T19:33:56.807636218Z,2025-09-24T19:33:56.793455871Z,160,1,432669,A,B,64.810000000,1,26,8058566331052,128,16063,94271232,CLX5
2025-09-24T19:33:56.807781555Z,2025-09-24T19:33:56.793675951Z,160,1,432669,M,A,65.140000000,1,26,8058566239191,128,15685,94271241,CLX5
2025-09-24T19:33:56.808034159Z,2025-09-24T19:33:56.793890545Z,160,1,432669,C,B,64.810000000,1,26,8058566331052,128,16164,94271258,CLX5
2025-09-24T19:33:56.808268740Z,2025-09-24T19:33:56.793893363Z,160,1,432669,C,B,64.770000000,1,26,8058566330971,128,14837,94271270,CLX5
2025-09-24T19:33:56.809969825Z,2025-09-24T19:33:56.794206213Z,160,1,432669,C,B,64.810000000,1,26,8058566330886,128,16813,94271393,CLX5
2025-09-24T19:33:56.810515606Z,2025-09-24T19:33:56.794909959Z,160,1,432669,A,A,65.960000000,4,26,8058566331102,128,14724,94271427,CLX5
2025-09-24T19:33:56.810756055Z,2025-09-24T19:33:56.795426703Z,160,1,432669,A,B,64.810000000,2,26,8058566331113,128,17052,94271443,CLX5
2025-09-24T19:33:56.810972443Z,2025-09-24T19:33:56.795472051Z,160,1,432669,C,A,64.820000000,1,26,8058566330998,128,15465,94271451,CLX5
2025-09-24T19:33:56.811003077Z,2025-09-24T19:33:56.795486605Z,160,1,432669,C,A,64.820000000,1,26,8058566330319,128,15792,94271452,CLX5
2025-09-24T19:33:56.811046505Z,2025-09-24T19:33:56.795492345Z,160,1,432669,A,B,64.810000000,1,26,8058566331115,128,19697,94271453,CLX5
2025-09-24T19:33:56.811259590Z,2025-09-24T19:33:56.795517919Z,160,1,432669,A,B,64.810000000,2,26,8058566331118,128,19581,94271460,CLX5
2025-09-24T19:33:56.813214432Z,2025-09-24T19:33:56.798752035Z,160,1,432669,A,B,64.810000000,1,26,8058566331152,128,14270,94271578,CLX5
2025-09-24T19:33:56.813505711Z,2025-09-24T19:33:56.799105989Z,160,1,432669,T,B,64.820000000,1,26,8058566331161,0,14781,94271595,CLX5
2025-09-24T19:33:56.813505711Z,2025-09-24T19:33:56.799105989Z,160,1,432669,F,A,64.820000000,1,26,8058566330341,0,14781,94271595,CLX5
2025-09-24T19:33:56.813538557Z,2025-09-24T19:33:56.799105989Z,160,1,432669,C,A,64.820000000,1,26,8058566330341,128,16041,94271596,CLX5
2025-09-24T19:33:56.813981608Z,2025-09-24T19:33:56.799117107Z,160,1,432669,A,B,64.810000000,1,26,8058566331163,128,18882,94271630,CLX5
2025-09-24T19:33:56.814608501Z,2025-09-24T19:33:56.799702335Z,160,1,432669,C,B,64.810000000,2,26,8058566331118,128,19255,94271664,CLX5
2025-09-24T19:33:56.814624920Z,2025-09-24T19:33:56.799864241Z,160,1,432669,A,A,65.000000000,1,26,8058566331179,128,14777,94271666,CLX5
2025-09-24T19:33:56.815145114Z,2025-09-24T19:33:56.801067799Z,160,1,432669,C,A,64.820000000,1,26,8058566330533,128,19364,94271692,CLX5
2025-09-24T19:33:56.815178351Z,2025-09-24T19:33:56.801069161Z,160,1,432669,A,B,64.810000000,2,26,8058566331188,128,15321,94271693,CLX5
2025-09-24T19:33:56.815212771Z,2025-09-24T19:33:56.801071543Z,160,1,432669,C,A,64.820000000,1,26,8058566330743,128,15729,94271694,CLX5
2025-09-24T19:33:56.815363306Z,2025-09-24T19:33:56.801385641Z,160,1,432669,A,B,64.810000000,2,26,8058566331191,128,18610,94271700,CLX5
2025-09-24T19:33:56.816947039Z,2025-09-24T19:33:56.803845511Z,160,1,432669,A,B,64.810000000,1,26,8058566331211,128,18353,94271795,CLX5
2025-09-24T19:33:56.817370799Z,2025-09-24T19:33:56.804375141Z,160,1,432669,C,B,64.810000000,1,26,8058566330949,128,15031,94271822,CLX5
2025-09-24T19:33:56.817427797Z,2025-09-24T19:33:56.804381439Z,160,1,432669,C,B,64.810000000,1,26,8058566330941,128,15253,94271824,CLX5
2025-09-24T19:33:56.817827520Z,2025-09-24T19:33:56.805337729Z,160,1,432669,A,B,64.770000000,1,26,8058566331225,128,15307,94271855,CLX5
2025-09-24T19:33:56.819199457Z,2025-09-24T19:33:56.807449711Z,160,1,432669,C,B,64.810000000,1,26,8058566331115,128,15459,94271954,CLX5
2025-09-24T19:33:56.819235059Z,2025-09-24T19:33:56.807464303Z,160,1,432669,A,A,64.820000000,1,26,8058566331242,128,15934,94271955,CLX5
2025-09-24T19:33:56.819437793Z,2025-09-24T19:33:56.807713681Z,160,1,432669,A,B,64.810000000,1,26,8058566331247,128,15486,94271967,CLX5
2025-09-24T19:33:56.820024492Z,2025-09-24T19:33:56.808239027Z,160,1,432669,C,A,64.820000000,1,26,8058566331242,128,20337,94272007,CLX5
2025-09-24T19:33:56.821214245Z,2025-09-24T19:33:56.809985037Z,160,1,432669,A,A,64.820000000,1,26,8058566331280,128,19483,94272084,CLX5
2025-09-24T19:33:56.821701254Z,2025-09-24T19:33:56.810604037Z,160,1,432669,C,A,64.870000000,2,26,8058566329019,128,14770,94272108,CLX5
2025-09-24T19:33:56.821726082Z,2025-09-24T19:33:56.810604555Z,160,1,432669,C,A,64.880000000,2,26,8058566323777,128,14826,94272109,CLX5
2025-09-24T19:33:56.822416218Z,2025-09-24T19:33:56.811272935Z,160,1,432669,C,A,64.820000000,1,26,8058566331280,128,15431,94272136,CLX5
2025-09-24T19:33:56.822972927Z,2025-09-24T19:33:56.812445871Z,160,1,432669,C,A,64.820000000,2,26,8058566330387,128,16155,94272163,CLX5
2025-09-24T19:33:56.823180038Z,2025-09-24T19:33:56.812478393Z,160,1,432669,C,A,64.820000000,1,26,8058566330348,128,16198,94272169,CLX5
2025-09-24T19:33:56.823212477Z,2025-09-24T19:33:56.812478545Z,160,1,432669,C,A,64.820000000,1,26,8058566330351,128,16138,94272170,CLX5
2025-09-24T19:33:56.823251366Z,2025-09-24T19:33:56.812490949Z,160,1,432669,C,A,64.820000000,2,26,8058566330633,128,20635,94272171,CLX5
2025-09-24T19:33:56.823295155Z,2025-09-24T19:33:56.812495095Z,160,1,432669,A,B,64.810000000,2,26,8058566331315,128,15350,94272173,CLX5
2025-09-24T19:33:56.824142499Z,2025-09-24T19:33:56.813025051Z,160,1,432669,C,A,64.820000000,1,26,8058566330662,128,17089,94272211,CLX5
2025-09-24T19:33:56.824356560Z,2025-09-24T19:33:56.813222225Z,160,1,432669,T,B,64.820000000,4,26,8058566331329,0,15112,94272227,CLX5
2025-09-24T19:33:56.824356560Z,2025-09-24T19:33:56.813222225Z,160,1,432669,F,A,64.820000000,3,26,8058566330536,0,15112,94272227,CLX5
2025-09-24T19:33:56.824356560Z,2025-09-24T19:33:56.813222225Z,160,1,432669,F,A,64.820000000,1,26,8058566329869,0,15112,94272227,CLX5
2025-09-24T19:33:56.824410763Z,2025-09-24T19:33:56.813222225Z,160,1,432669,C,A,64.820000000,3,26,8058566330536,0,19529,94272228,CLX5
2025-09-24T19:33:56.824410763Z,2025-09-24T19:33:56.813222225Z,160,1,432669,C,A,64.820000000,1,26,8058566329869,128,19529,94272228,CLX5
2025-09-24T19:33:56.824474718Z,2025-09-24T19:33:56.813223147Z,160,1,432669,A,B,64.820000000,1,26,8058566331330,128,15025,94272231,CLX5
2025-09-24T19:33:56.824518192Z,2025-09-24T19:33:56.813249199Z,160,1,432669,T,A,64.820000000,1,26,8058566331331,0,15225,94272235,CLX5
2025-09-24T19:33:56.824518192Z,2025-09-24T19:33:56.813249199Z,160,1,432669,F,B,64.820000000,1,26,8058566331330,0,15225,94272235,CLX5
2025-09-24T19:33:56.824518192Z,2025-09-24T19:33:56.813249199Z,160,1,432669,C,B,64.820000000,1,26,8058566331330,128,15225,94272235,CLX5
2025-09-24T19:33:56.825051740Z,2025-09-24T19:33:56.813568239Z,160,1,432669,A,A,64.820000000,1,26,8058566331341,128,18630,94272261,CLX5
2025-09-24T19:33:56.825734625Z,2025-09-24T19:33:56.813613485Z,160,1,432669,A,B,64.810000000,2,26,8058566331351,128,17058,94272290,CLX5
2025-09-24T19:33:56.825945361Z,2025-09-24T19:33:56.813988789Z,160,1,432669,T,B,64.820000000,1,26,8058566331354,0,14776,94272306,CLX5
2025-09-24T19:33:56.825945361Z,2025-09-24T19:33:56.813988789Z,160,1,432669,F,A,64.820000000,1,26,8058566331341,0,14776,94272306,CLX5
2025-09-24T19:33:56.825991746Z,2025-09-24T19:33:56.813988789Z,160,1,432669,C,A,64.820000000,1,26,8058566331341,128,14738,94272307,CLX5
2025-09-24T19:33:56.826633008Z,2025-09-24T19:33:56.814616085Z,160,1,432669,A,B,64.820000000,1,26,8058566331363,128,15168,94272347,CLX5
2025-09-24T19:33:56.826906194Z,2025-09-24T19:33:56.814881933Z,160,1,432669,T,N,64.820000000,1,26,0,0,15128,94272367,CLX5
2025-09-24T19:33:56.826906194Z,2025-09-24T19:33:56.814881933Z,160,1,432669,F,N,64.820000000,1,26,8058566331363,0,15128,94272367,CLX5
2025-09-24T19:33:56.826968084Z,2025-09-24T19:33:56.814881933Z,160,1,432669,C,B,64.820000000,1,26,8058566331363,128,18156,94272368,CLX5
2025-09-24T19:33:56.827331820Z,2025-09-24T19:33:56.815371071Z,160,1,432669,A,B,64.820000000,1,26,8058566331378,128,14968,94272392,CLX5
2025-09-24T19:33:56.828013085Z,2025-09-24T19:33:56.815991857Z,160,1,432669,M,A,64.830000000,3,26,8058566282770,128,15477,94272436,CLX5
2025-09-24T19:33:56.828083000Z,2025-09-24T19:33:56.816084283Z,160,1,432669,C,A,65.900000000,1,26,8058566302406,128,17860,94272440,CLX5
2025-09-24T19:33:56.828394845Z,2025-09-24T19:33:56.816161731Z,160,1,432669,A,B,64.780000000,1,26,8058566331393,128,18363,94272459,CLX5
2025-09-24T19:33:56.833436778Z,2025-09-24T19:33:56.822863483Z,160,1,432669,A,B,64.810000000,1,26,8058566331492,128,15136,94272764,CLX5
2025-09-24T19:33:56.834051061Z,2025-09-24T19:33:56.824339417Z,160,1,432669,M,A,65.970000000,4,26,8058566282770,128,19141,94272794,CLX5
2025-09-24T19:33:56.834154705Z,2025-09-24T19:33:56.824356525Z,160,1,432669,A,B,64.820000000,1,26,8058566331498,128,18200,94272796,CLX5
2025-09-24T19:33:56.834173197Z,2025-09-24T19:33:56.824356701Z,160,1,432669,C,A,64.830000000,1,26,8058566330575,128,16348,94272798,CLX5
2025-09-24T19:33:56.834375678Z,2025-09-24T19:33:56.824366143Z,160,1,432669,C,A,64.840000000,1,26,8058566330904,128,18027,94272807,CLX5
2025-09-24T19:33:56.834462803Z,2025-09-24T19:33:56.824419441Z,160,1,432669,A,B,64.820000000,1,26,8058566331502,128,14861,94272811,CLX5
2025-09-24T19:33:56.834713449Z,2025-09-24T19:33:56.824530009Z,160,1,432669,C,B,64.820000000,1,26,8058566331502,128,18294,94272824,CLX5
2025-09-24T19:33:56.834841637Z,2025-09-24T19:33:56.824550993Z,160,1,432669,A,B,64.810000000,3,26,8058566331508,128,14996,94272830,CLX5
2025-09-24T19:33:56.834906437Z,2025-09-24T19:33:56.824563415Z,160,1,432669,C,B,64.820000000,1,26,8058566331498,128,14765,94272832,CLX5
2025-09-24T19:33:56.835142569Z,2025-09-24T19:33:56.824876841Z,160,1,432669,A,B,64.820000000,1,26,8058566331511,128,17843,94272845,CLX5
2025-09-24T19:33:56.835373772Z,2025-09-24T19:33:56.825441737Z,160,1,432669,C,B,64.820000000,1,26,8058566331511,128,17927,94272860,CLX5
2025-09-24T19:33:56.835647788Z,2025-09-24T19:33:56.825757967Z,160,1,432669,A,B,64.810000000,1,26,8058566331521,128,14808,94272876,CLX5
2025-09-24T19:33:56.835720544Z,2025-09-24T19:33:56.825945313Z,160,1,432669,A,B,64.820000000,1,26,8058566331522,128,20119,94272878,CLX5
2025-09-24T19:33:56.835855559Z,2025-09-24T19:33:56.826012451Z,160,1,432669,A,B,64.820000000,1,26,8058566331524,128,14745,94272886,CLX5
2025-09-24T19:33:56.835974324Z,2025-09-24T19:33:56.826286923Z,160,1,432669,A,B,64.810000000,1,26,8058566331529,128,15054,94272894,CLX5
2025-09-24T19:33:56.836202323Z,2025-09-24T19:33:56.826514739Z,160,1,432669,C,B,64.820000000,1,26,8058566331522,128,14810,94272906,CLX5
2025-09-24T19:33:56.836232205Z,2025-09-24T19:33:56.826517639Z,160,1,432669,T,A,64.820000000,1,26,8058566331533,0,15332,94272909,CLX5
2025-09-24T19:33:56.836232205Z,2025-09-24T19:33:56.826517639Z,160,1,432669,F,B,64.820000000,1,26,8058566331378,0,15332,94272909,CLX5
2025-09-24T19:33:56.836232205Z,2025-09-24T19:33:56.826517639Z,160,1,432669,C,B,64.820000000,1,26,8058566331378,128,15332,94272909,CLX5
2025-09-24T19:33:56.836443187Z,2025-09-24T19:33:56.826885013Z,160,1,432669,C,B,64.820000000,1,26,8058566331524,128,18703,94272919,CLX5
2025-09-24T19:33:56.836472699Z,2025-09-24T19:33:56.826887049Z,160,1,432669,A,B,64.820000000,1,26,8058566331536,128,14310,94272922,CLX5
2025-09-24T19:33:56.836884533Z,2025-09-24T19:33:56.827331835Z,160,1,432669,A,B,64.820000000,1,26,8058566331545,128,17873,94272946,CLX5
2025-09-24T19:33:56.836903509Z,2025-09-24T19:33:56.827339229Z,160,1,432669,A,B,64.820000000,1,26,8058566331546,128,17025,94272948,CLX5
2025-09-24T19:33:56.837218803Z,2025-09-24T19:33:56.828028037Z,160,1,432669,C,B,64.820000000,1,26,8058566331545,128,15181,94272968,CLX5
2025-09-24T19:33:56.837881767Z,2025-09-24T19:33:56.829126573Z,160,1,432669,A,B,64.820000000,1,26,8058566331564,128,19109,94273007,CLX5
2025-09-24T19:33:56.837986110Z,2025-09-24T19:33:56.829405153Z,160,1,432669,A,B,64.820000000,1,26,8058566331565,128,22897,94273013,CLX5
2025-09-24T19:33:56.838019815Z,2025-09-24T19:33:56.829405537Z,160,1,432669,A,B,64.820000000,1,26,8058566331566,128,17376,94273014,CLX5
2025-09-24T19:33:56.838055971Z,2025-09-24T19:33:56.829405729Z,160,1,432669,A,B,64.820000000,1,26,8058566331567,128,16660,94273015,CLX5
2025-09-24T19:33:56.838137689Z,2025-09-24T19:33:56.829534997Z,160,1,432669,A,B,64.820000000,1,26,8058566331568,128,16129,94273019,CLX5
2025-09-24T19:33:56.838200317Z,2025-09-24T19:33:56.829548053Z,160,1,432669,A,B,64.820000000,2,26,8058566331569,128,19531,94273021,CLX5
2025-09-24T19:33:56.838833461Z,2025-09-24T19:33:56.829830625Z,160,1,432669,A,B,64.820000000,1,26,8058566331576,128,16194,94273051,CLX5
2025-09-24T19:33:56.839978328Z,2025-09-24T19:33:56.832326323Z,160,1,432669,A,B,64.720000000,2,26,8058566331591,128,15001,94273120,CLX5
2025-09-24T19:33:56.840995298Z,2025-09-24T19:33:56.833683799Z,160,1,432669,M,A,64.950000000,1,26,8058565075241,128,17107,94273179,CLX5
2025-09-24T19:33:56.841309824Z,2025-09-24T19:33:56.834489013Z,160,1,432669,M,B,64.810000000,1,26,8058566331010,128,18442,94273199,CLX5
2025-09-24T19:33:56.841460728Z,2025-09-24T19:33:56.834830449Z,160,1,432669,T,A,64.820000000,1,26,8058566331616,0,14669,94273212,CLX5
2025-09-24T19:33:56.841460728Z,2025-09-24T19:33:56.834830449Z,160,1,432669,F,B,64.820000000,1,26,8058566331536,0,14669,94273212,CLX5
2025-09-24T19:33:56.841492744Z,2025-09-24T19:33:56.834830449Z,160,1,432669,C,B,64.820000000,1,26,8058566331536,128,16519,94273213,CLX5
2025-09-24T19:33:56.841542216Z,2025-09-24T19:33:56.835380409Z,160,1,432669,A,B,64.820000000,1,26,8058566331617,128,19734,94273215,CLX5
2025-09-24T19:33:56.841845337Z,2025-09-24T19:33:56.835716683Z,160,1,432669,A,A,65.950000000,3,26,8058566331622,128,15567,94273230,CLX5
2025-09-24T19:33:56.842022144Z,2025-09-24T19:33:56.836305865Z,160,1,432669,T,A,64.820000000,1,26,8058566331628,0,14915,94273242,CLX5
2025-09-24T19:33:56.842022144Z,2025-09-24T19:33:56.836305865Z,160,1,432669,F,B,64.820000000,1,26,8058566331546,0,14915,94273242,CLX5
2025-09-24T19:33:56.842061933Z,2025-09-24T19:33:56.836305865Z,160,1,432669,C,B,64.820000000,1,26,8058566331546,128,20127,94273243,CLX5
2025-09-24T19:33:56.842113195Z,2025-09-24T19:33:56.836475433Z,160,1,432669,C,B,64.820000000,1,26,8058566331568,128,15847,94273246,CLX5
2025-09-24T19:33:56.842222759Z,2025-09-24T19:33:56.836550579Z,160,1,432669,C,B,64.820000000,1,26,8058566331576,128,16204,94273251,CLX5
2025-09-24T19:33:56.842376305Z,2025-09-24T19:33:56.836724139Z,160,1,432669,C,B,64.820000000,1,26,8058566331565,128,16299,94273259,CLX5
2025-09-24T19:33:56.842411478Z,2025-09-24T19:33:56.836909411Z,160,1,432669,A,B,64.820000000,1,26,8058566331631,128,19351,94273260,CLX5
2025-09-24T19:33:56.842510567Z,2025-09-24T19:33:56.837229807Z,160,1,432669,C,B,64.820000000,1,26,8058566331564,128,19554,94273266,CLX5
2025-09-24T19:33:56.842850658Z,2025-09-24T19:33:56.837881771Z,160,1,432669,A,B,64.820000000,1,26,8058566331650,128,16067,94273285,CLX5
2025-09-24T19:33:56.843151936Z,2025-09-24T19:33:56.838242831Z,160,1,432669,C,B,64.820000000,2,26,8058566331569,128,16899,94273301,CLX5
2025-09-24T19:33:56.843215109Z,2025-09-24T19:33:56.838369891Z,160,1,432669,C,B,64.820000000,1,26,8058566331617,128,20569,94273303,CLX5
2025-09-24T19:33:56.843440982Z,2025-09-24T19:33:56.838451123Z,160,1,432669,A,B,64.820000000,2,26,8058566331661,128,15853,94273314,CLX5
2025-09-24T19:33:56.843599565Z,2025-09-24T19:33:56.838462661Z,160,1,432669,C,B,64.820000000,1,26,8058566331631,128,19688,94273321,CLX5
2025-09-24T19:33:56.844537459Z,2025-09-24T19:33:56.839746413Z,160,1,432669,T,A,64.820000000,1,26,8058566331683,0,14787,94273379,CLX5
2025-09-24T19:33:56.844537459Z,2025-09-24T19:33:56.839746413Z,160,1,432669,F,B,64.820000000,1,26,8058566331566,0,14787,94273379,CLX5
2025-09-24T19:33:56.844537459Z,2025-09-24T19:33:56.839746413Z,160,1,432669,C,B,64.820000000,1,26,8058566331566,128,14787,94273379,CLX5
2025-09-24T19:33:56.844919181Z,2025-09-24T19:33:56.839980449Z,160,1,432669,C,B,64.820000000,1,26,8058566331567,128,17997,94273397,CLX5
2025-09-24T19:33:56.846044777Z,2025-09-24T19:33:56.841460685Z,160,1,432669,T,A,64.820000000,3,26,8058566331707,0,15852,94273466,CLX5
2025-09-24T19:33:56.846044777Z,2025-09-24T19:33:56.841460685Z,160,1,432669,F,B,64.820000000,1,26,8058566331650,0,15852,94273466,CLX5
2025-09-24T19:33:56.846044777Z,2025-09-24T19:33:56.841460685Z,160,1,432669,F,B,64.820000000,2,26,8058566331661,0,15852,94273466,CLX5
2025-09-24T19:33:56.846044777Z,2025-09-24T19:33:56.841460685Z,160,1,432669,C,B,64.820000000,1,26,8058566331650,0,15852,94273466,CLX5
2025-09-24T19:33:56.846044777Z,2025-09-24T19:33:56.841460685Z,160,1,432669,C,B,64.820000000,2,26,8058566331661,128,15852,94273466,CLX5
2025-09-24T19:33:56.847432805Z,2025-09-24T19:33:56.843412835Z,160,1,432669,M,A,64.840000000,1,26,8058566173085,128,17610,94273536,CLX5
2025-09-24T19:33:56.849306950Z,2025-09-24T19:33:56.846926723Z,160,1,432669,A,A,64.840000000,1,26,8058566331778,128,15223,94273642,CLX5
2025-09-24T19:33:56.849731408Z,2025-09-24T19:33:56.848093859Z,160,1,432669,C,A,64.840000000,1,26,8058566331778,128,15193,94273665,CLX5
2025-09-24T19:33:56.850633792Z,2025-09-24T19:33:56.849404911Z,160,1,432669,A,A,64.820000000,1,26,8058566331801,128,18728,94273713,CLX5
2025-09-24T19:33:56.851245272Z,2025-09-24T19:33:56.850655505Z,160,1,432669,C,B,64.810000000,2,26,8058566331315,128,14584,94273758,CLX5
2025-09-24T19:33:56.851512146Z,2025-09-24T19:33:56.850934527Z,160,1,432669,A,A,64.820000000,2,26,8058566331821,128,14842,94273771,CLX5
2025-09-24T19:33:56.858392696Z,2025-09-24T19:33:56.858152217Z,160,1,432669,T,B,64.820000000,1,26,8058566331861,0,17860,94273878,CLX5
2025-09-24T19:33:56.858392696Z,2025-09-24T19:33:56.858152217Z,160,1,432669,F,A,64.820000000,1,26,8058566331801,0,17860,94273878,CLX5
2025-09-24T19:33:56.858401559Z,2025-09-24T19:33:56.858152217Z,160,1,432669,C,A,64.820000000,1,26,8058566331801,128,15103,94273879,CLX5
2025-09-24T19:33:56.858734070Z,2025-09-24T19:33:56.858400579Z,160,1,432669,T,B,64.820000000,2,26,8058566331864,0,18226,94273888,CLX5
2025-09-24T19:33:56.858734070Z,2025-09-24T19:33:56.858400579Z,160,1,432669,F,A,64.820000000,2,26,8058566331821,0,18226,94273888,CLX5
2025-09-24T19:33:56.858742824Z,2025-09-24T19:33:56.858400579Z,160,1,432669,C,A,64.820000000,2,26,8058566331821,128,15112,94273889,CLX5
2025-09-24T19:33:56.858992926Z,2025-09-24T19:33:56.858735373Z,160,1,432669,A,B,64.820000000,1,26,8058566331867,128,17830,94273900,CLX5
2025-09-24T19:33:56.859342586Z,2025-09-24T19:33:56.858992947Z,160,1,432669,A,B,64.820000000,1,26,8058566331871,128,15053,94273916,CLX5
2025-09-24T19:33:56.859371323Z,2025-09-24T19:33:56.859001357Z,160,1,432669,T,A,64.820000000,1,26,8058566331872,0,14897,94273919,CLX5
2025-09-24T19:33:56.859371323Z,2025-09-24T19:33:56.859001357Z,160,1,432669,F,B,64.820000000,1,26,8058566331867,0,14897,94273919,CLX5
2025-09-24T19:33:56.859371323Z,2025-09-24T19:33:56.859001357Z,160,1,432669,C,B,64.820000000,1,26,8058566331867,128,14897,94273919,CLX5
2025-09-24T19:33:56.859426923Z,2025-09-24T19:33:56.859047857Z,160,1,432669,T,A,64.820000000,1,26,8058566331874,0,15539,94273922,CLX5
2025-09-24T19:33:56.859426923Z,2025-09-24T19:33:56.859047857Z,160,1,432669,F,B,64.820000000,1,26,8058566331871,0,15539,94273922,CLX5
2025-09-24T19:33:56.859467041Z,2025-09-24T19:33:56.859047857Z,160,1,432669,C,B,64.820000000,1,26,8058566331871,128,14713,94273923,CLX5
2025-09-24T19:33:56.865942163Z,2025-09-24T19:33:56.865748307Z,160,1,432669,A,A,64.820000000,1,26,8058566331891,128,18521,94273960,CLX5
2025-09-24T19:33:56.866483129Z,2025-09-24T19:33:56.866343825Z,160,1,432669,A,A,64.820000000,2,26,8058566331892,128,16716,94273966,CLX5
2025-09-24T19:33:56.868875623Z,2025-09-24T19:33:56.868741893Z,160,1,432669,A,B,64.790000000,1,26,8058566331895,128,17751,94273974,CLX5
2025-09-24T19:33:56.884360932Z,2025-09-24T19:33:56.884233537Z,160,1,432669,A,B,64.810000000,1,26,8058566331914,128,17579,94274024,CLX5
2025-09-24T19:33:56.884911160Z,2025-09-24T19:33:56.884765911Z,160,1,432669,M,A,64.830000000,1,26,8058566331891,128,18407,94274025,CLX5
2025-09-24T19:33:56.884973019Z,2025-09-24T19:33:56.884854841Z,160,1,432669,A,B,64.800000000,2,26,8058566331915,128,14184,94274028,CLX5
2025-09-24T19:33:56.885004590Z,2025-09-24T19:33:56.884858931Z,160,1,432669,A,B,64.790000000,2,26,8058566331916,128,17576,94274029,CLX5
2025-09-24T19:33:56.910378801Z,2025-09-24T19:33:56.910266323Z,160,1,432669,A,A,64.870000000,2,26,8058566331963,128,15027,94274091,CLX5
2025-09-24T19:33:56.915922195Z,2025-09-24T19:33:56.915828239Z,160,1,432669,A,A,65.900000000,1,26,8058566331990,128,18183,94274122,CLX5
2025-09-24T19:33:56.931302041Z,2025-09-24T19:33:56.931180689Z,160,1,432669,A,B,64.800000000,1,26,8058566332034,128,14805,94274176,CLX5
2025-09-24T19:33:57.010375422Z,2025-09-24T19:33:57.010247581Z,160,1,432669,A,B,64.770000000,2,26,8058566332230,128,18378,94274462,CLX5
2025-09-24T19:33:57.032875658Z,2025-09-24T19:33:57.032522881Z,160,1,432669,C,A,64.820000000,2,26,8058566331892,128,18269,94274529,CLX5
2025-09-24T19:33:57.033009713Z,2025-09-24T19:33:57.032881713Z,160,1,432669,C,A,64.850000000,1,26,8058566330617,128,14807,94274538,CLX5
2025-09-24T19:33:57.087730705Z,2025-09-24T19:33:57.087596841Z,160,1,432669,C,B,64.800000000,1,26,8058566332034,128,18048,94274709,CLX5
2025-09-24T19:33:57.166431056Z,2025-09-24T19:33:57.166289965Z,160,1,432669,A,A,64.830000000,1,26,8058566332416,128,17267,94274774,CLX5
2025-09-24T19:33:57.166590661Z,2025-09-24T19:33:57.166455597Z,160,1,432669,C,B,64.810000000,1,26,8058566331914,128,19178,94274775,CLX5
2025-09-24T19:33:57.991375136Z,2025-09-24T19:33:57.991134503Z,160,1,432669,A,B,64.820000000,1,26,8058566332654,128,18070,94275226,CLX5
2025-09-24T19:33:57.991405256Z,2025-09-24T19:33:57.991135329Z,160,1,432669,A,B,64.820000000,1,26,8058566332656,128,15349,94275229,CLX5
2025-09-24T19:33:57.991664673Z,2025-09-24T19:33:57.991159711Z,160,1,432669,A,B,64.820000000,1,26,8058566332658,128,15152,94275239,CLX5
2025-09-24T19:33:57.991685769Z,2025-09-24T19:33:57.991202065Z,160,1,432669,A,B,64.810000000,2,26,8058566332659,128,14620,94275241,CLX5
2025-09-24T19:33:57.991755999Z,2025-09-24T19:33:57.991394845Z,160,1,432669,C,B,64.810000000,1,26,8058566331492,128,17389,94275245,CLX5
2025-09-24T19:33:57.991818871Z,2025-09-24T19:33:57.991409127Z,160,1,432669,C,B,64.820000000,1,26,8058566332656,128,14844,94275247,CLX5
2025-09-24T19:33:57.991863897Z,2025-09-24T19:33:57.991440211Z,160,1,432669,A,B,64.820000000,1,26,8058566332662,128,14072,94275251,CLX5
2025-09-24T19:33:57.992241080Z,2025-09-24T19:33:57.991790941Z,160,1,432669,A,B,64.810000000,1,26,8058566332666,128,15361,94275266,CLX5
2025-09-24T19:33:57.992288118Z,2025-09-24T19:33:57.991829723Z,160,1,432669,A,B,64.820000000,2,26,8058566332667,128,18272,94275267,CLX5
2025-09-24T19:33:57.992400017Z,2025-09-24T19:33:57.992198443Z,160,1,432669,M,B,64.810000000,3,26,8058566319508,128,15450,94275274,CLX5
2025-09-24T19:33:57.993445602Z,2025-09-24T19:33:57.993114397Z,160,1,432669,T,A,64.820000000,5,26,8058566332669,0,18235,94275276,CLX5
2025-09-24T19:33:57.993445602Z,2025-09-24T19:33:57.993114397Z,160,1,432669,F,B,64.820000000,1,26,8058566332654,0,18235,94275276,CLX5
2025-09-24T19:33:57.993445602Z,2025-09-24T19:33:57.993114397Z,160,1,432669,F,B,64.820000000,1,26,8058566332658,0,18235,94275276,CLX5
2025-09-24T19:33:57.993445602Z,2025-09-24T19:33:57.993114397Z,160,1,432669,F,B,64.820000000,1,26,8058566332662,0,18235,94275276,CLX5
2025-09-24T19:33:57.993445602Z,2025-09-24T19:33:57.993114397Z,160,1,432669,F,B,64.820000000,2,26,8058566332667,0,18235,94275276,CLX5
2025-09-24T19:33:57.993456691Z,2025-09-24T19:33:57.993114397Z,160,1,432669,C,B,64.820000000,1,26,8058566332654,0,14831,94275277,CLX5
2025-09-24T19:33:57.993456691Z,2025-09-24T19:33:57.993114397Z,160,1,432669,C,B,64.820000000,1,26,8058566332658,0,14831,94275277,CLX5
2025-09-24T19:33:57.993456691Z,2025-09-24T19:33:57.993114397Z,160,1,432669,C,B,64.820000000,1,26,8058566332662,0,14831,94275277,CLX5
2025-09-24T19:33:57.993456691Z,2025-09-24T19:33:57.993114397Z,160,1,432669,C,B,64.820000000,2,26,8058566332667,128,14831,94275277,CLX5
2025-09-24T19:33:57.993694405Z,2025-09-24T19:33:57.993446925Z,160,1,432669,A,A,64.820000000,1,26,8058566332672,128,18016,94275287,CLX5
2025-09-24T19:33:57.993805299Z,2025-09-24T19:33:57.993468045Z,160,1,432669,C,B,64.810000000,2,26,8058566332659,128,19047,94275292,CLX5
2025-09-24T19:33:57.993993219Z,2025-09-24T19:33:57.993702023Z,160,1,432669,M,B,63.660000000,4,26,8058566319508,128,17653,94275298,CLX5
2025-09-24T19:33:58.002374724Z,2025-09-24T19:33:58.002230865Z,160,1,432669,M,B,64.810000000,3,26,8058566319851,128,18904,94275313,CLX5
2025-09-24T19:33:58.008437212Z,2025-09-24T19:33:58.008337885Z,160,1,432669,A,B,63.670000000,4,26,8058566332677,128,18387,94275314,CLX5
2025-09-24T19:33:58.037558727Z,2025-09-24T19:33:58.037421453Z,160,1,432669,A,B,64.800000000,1,26,8058566332682,128,20781,94275327,CLX5
2025-09-24T19:33:59.406928889Z,2025-09-24T19:33:59.406771827Z,160,1,432669,A,B,64.810000000,1,26,8058566332855,128,19084,94275674,CLX5
2025-09-24T19:33:59.407117616Z,2025-09-24T19:33:59.406953317Z,160,1,432669,C,A,64.820000000,1,26,8058566332672,128,16839,94275677,CLX5
2025-09-24T19:33:59.407449751Z,2025-09-24T19:33:59.407186837Z,160,1,432669,A,B,64.820000000,1,26,8058566332859,128,15868,94275689,CLX5
2025-09-24T19:33:59.407811920Z,2025-09-24T19:33:59.407674745Z,160,1,432669,M,A,65.980000000,4,26,8058566321460,128,15068,94275703,CLX5
2025-09-24T19:33:59.407854903Z,2025-09-24T19:33:59.407687013Z,160,1,432669,M,A,65.990000000,4,26,8058566282798,128,15061,94275705,CLX5
2025-09-24T19:33:59.448432856Z,2025-09-24T19:33:59.448159825Z,160,1,432669,T,A,64.820000000,1,26,8058566332870,0,18422,94275726,CLX5
2025-09-24T19:33:59.448432856Z,2025-09-24T19:33:59.448159825Z,160,1,432669,F,B,64.820000000,1,26,8058566332859,0,18422,94275726,CLX5
2025-09-24T19:33:59.448441143Z,2025-09-24T19:33:59.448159825Z,160,1,432669,C,B,64.820000000,1,26,8058566332859,128,14778,94275727,CLX5
2025-09-24T19:33:59.448665072Z,2025-09-24T19:33:59.448476305Z,160,1,432669,C,B,64.800000000,1,26,8058566332682,128,15074,94275738,CLX5
2025-09-24T19:33:59.448766089Z,2025-09-24T19:33:59.448585815Z,160,1,432669,A,A,64.830000000,1,26,8058566332875,128,15143,94275743,CLX5
2025-09-24T19:33:59.448823072Z,2025-09-24T19:33:59.448701799Z,160,1,432669,A,A,64.830000000,1,26,8058566332876,128,15542,94275745,CLX5
2025-09-24T19:33:59.448908530Z,2025-09-24T19:33:59.448796587Z,160,1,432669,A,A,64.830000000,1,26,8058566332877,128,14261,94275747,CLX5
2025-09-24T19:33:59.449433024Z,2025-09-24T19:33:59.449204029Z,160,1,432669,M,B,63.650000000,4,26,8058566319851,128,18446,94275761,CLX5
2025-09-24T19:33:59.461961129Z,2025-09-24T19:33:59.461808907Z,160,1,432669,A,A,64.830000000,1,26,8058566332889,128,18429,94275798,CLX5
2025-09-24T19:33:59.462136446Z,2025-09-24T19:33:59.461991433Z,160,1,432669,C,A,64.830000000,1,26,8058566332877,128,15381,94275801,CLX5
2025-09-24T19:33:59.462164223Z,2025-09-24T19:33:59.461996349Z,160,1,432669,C,A,64.830000000,1,26,8058566332876,128,14966,94275802,CLX5
2025-09-24T19:33:59.462195571Z,2025-09-24T19:33:59.462001301Z,160,1,432669,C,A,64.830000000,1,26,8058566332875,128,18387,94275803,CLX5
2025-09-24T19:33:59.507638587Z,2025-09-24T19:33:59.507368921Z,160,1,432669,A,B,64.820000000,2,26,8058566332898,128,14637,94275821,CLX5
2025-09-24T19:34:00.249819498Z,2025-09-24T19:34:00.249681311Z,160,1,432669,C,B,64.810000000,1,26,8058566332666,128,19092,94276162,CLX5
2025-09-24T19:34:00.249847276Z,2025-09-24T19:34:00.249692139Z,160,1,432669,C,B,64.810000000,1,26,8058566331529,128,14985,94276163,CLX5
2025-09-24T19:34:00.249976723Z,2025-09-24T19:34:00.249857253Z,160,1,432669,C,B,64.810000000,1,26,8058566331521,128,18400,94276164,CLX5
2025-09-24T19:34:01.475896738Z,2025-09-24T19:34:01.475591553Z,160,1,432669,T,A,64.820000000,1,26,8058566333069,0,18680,94276331,CLX5
2025-09-24T19:34:01.475896738Z,2025-09-24T19:34:01.475591553Z,160,1,432669,F,B,64.820000000,1,26,8058566332898,0,18680,94276331,CLX5
2025-09-24T19:34:01.475905531Z,2025-09-24T19:34:01.475591553Z,160,1,432669,M,B,64.820000000,1,26,8058566332898,128,15027,94276332,CLX5
2025-09-24T19:34:01.476118456Z,2025-09-24T19:34:01.475869133Z,160,1,432669,T,A,64.820000000,1,26,8058566333071,0,18288,94276336,CLX5
2025-09-24T19:34:01.476118456Z,2025-09-24T19:34:01.475869133Z,160,1,432669,F,B,64.820000000,1,26,8058566332898,0,18288,94276336,CLX5
2025-09-24T19:34:01.476127111Z,2025-09-24T19:34:01.475869133Z,160,1,432669,C,B,64.820000000,1,26,8058566332898,128,14648,94276337,CLX5
2025-09-24T19:34:01.476362367Z,2025-09-24T19:34:01.476145565Z,160,1,432669,A,B,64.810000000,2,26,8058566333074,128,16771,94276344,CLX5
2025-09-24T19:34:01.973236407Z,2025-09-24T19:34:01.972976929Z,160,1,432669,A,B,64.820000000,1,26,8058566333099,128,19025,94276413,CLX5
2025-09-24T19:34:01.973254256Z,2025-09-24T19:34:01.972995015Z,160,1,432669,A,B,64.820000000,2,26,8058566333100,128,17203,94276415,CLX5
2025-09-24T19:34:01.973336533Z,2025-09-24T19:34:01.973012773Z,160,1,432669,A,B,64.820000000,2,26,8058566333101,128,17536,94276418,CLX5
2025-09-24T19:34:01.973474328Z,2025-09-24T19:34:01.973245677Z,160,1,432669,A,B,64.820000000,1,26,8058566333103,128,16429,94276425,CLX5
2025-09-24T19:34:01.973534521Z,2025-09-24T19:34:01.973301855Z,160,1,432669,A,B,64.820000000,1,26,8058566333104,128,18527,94276427,CLX5
2025-09-24T19:34:02.095407195Z,2025-09-24T19:34:02.095254069Z,160,1,432669,C,B,64.820000000,2,26,8058566333101,128,21072,94276489,CLX5
2025-09-24T19:34:02.097086777Z,2025-09-24T19:34:02.096947973Z,160,1,432669,M,B,64.810000000,3,26,8058566319851,128,18486,94276492,CLX5
2025-09-24T19:34:02.677422847Z,2025-09-24T19:34:02.677267871Z,160,1,432669,A,B,64.820000000,2,26,8058566333154,128,21271,94276568,CLX5
2025-09-24T19:34:02.678064830Z,2025-09-24T19:34:02.677931913Z,160,1,432669,A,B,64.820000000,1,26,8058566333156,128,19539,94276574,CLX5
2025-09-24T19:34:02.678202456Z,2025-09-24T19:34:02.678064541Z,160,1,432669,A,B,64.820000000,1,26,8058566333157,128,19278,94276578,CLX5
2025-09-24T19:34:02.678232913Z,2025-09-24T19:34:02.678076311Z,160,1,432669,A,B,64.820000000,1,26,8058566333158,128,14873,94276579,CLX5
2025-09-24T19:34:02.678794170Z,2025-09-24T19:34:02.678538491Z,160,1,432669,A,B,64.820000000,1,26,8058566333166,128,15012,94276602,CLX5
2025-09-24T19:34:02.679153006Z,2025-09-24T19:34:02.678580999Z,160,1,432669,C,A,64.830000000,2,26,8058566330477,128,19057,94276617,CLX5
2025-09-24T19:34:02.679277009Z,2025-09-24T19:34:02.678696289Z,160,1,432669,A,B,64.820000000,1,26,8058566333171,128,19085,94276622,CLX5
2025-09-24T19:34:02.679622529Z,2025-09-24T19:34:02.678798179Z,160,1,432669,A,B,64.820000000,1,26,8058566333177,128,15397,94276636,CLX5
2025-09-24T19:34:02.679829456Z,2025-09-24T19:34:02.678957321Z,160,1,432669,C,B,64.820000000,1,26,8058566333171,128,15735,94276645,CLX5
2025-09-24T19:34:02.810666459Z,2025-09-24T19:34:02.810530251Z,160,1,432669,A,B,64.780000000,2,26,8058566333334,128,18175,94277223,CLX5
2025-09-24T19:34:03.002543620Z,2025-09-24T19:34:03.002396737Z,160,1,432669,C,B,64.820000000,1,26,8058566333104,128,18643,94277315,CLX5
2025-09-24T19:34:03.002690699Z,2025-09-24T19:34:03.002558491Z,160,1,432669,C,B,64.820000000,1,26,8058566333157,128,19173,94277316,CLX5
2025-09-24T19:34:03.002724559Z,2025-09-24T19:34:03.002565421Z,160,1,432669,C,B,64.820000000,1,26,8058566333166,128,16026,94277317,CLX5
2025-09-24T19:34:03.181963258Z,2025-09-24T19:34:03.181671057Z,160,1,432669,T,A,64.820000000,1,26,8058566333398,0,18772,94277369,CLX5
2025-09-24T19:34:03.181963258Z,2025-09-24T19:34:03.181671057Z,160,1,432669,F,B,64.820000000,1,26,8058566333099,0,18772,94277369,CLX5
2025-09-24T19:34:03.181973633Z,2025-09-24T19:34:03.181671057Z,160,1,432669,C,B,64.820000000,1,26,8058566333099,128,15962,94277370,CLX5
2025-09-24T19:34:04.104345729Z,2025-09-24T19:34:04.104065155Z,160,1,432669,T,A,64.820000000,1,26,8058566333465,0,18478,94277508,CLX5
2025-09-24T19:34:04.104345729Z,2025-09-24T19:34:04.104065155Z,160,1,432669,F,B,64.820000000,1,26,8058566333100,0,18478,94277508,CLX5
2025-09-24T19:34:04.104360649Z,2025-09-24T19:34:04.104065155Z,160,1,432669,M,B,64.820000000,1,26,8058566333100,128,20094,94277509,CLX5
2025-09-24T19:34:04.432463269Z,2025-09-24T19:34:04.432234133Z,160,1,432669,C,B,64.780000000,2,26,8058566333334,128,14960,94277773,CLX5
2025-09-24T19:34:04.435120387Z,2025-09-24T19:34:04.434982377Z,160,1,432669,A,B,64.820000000,1,26,8058566333549,128,19429,94277826,CLX5
2025-09-24T19:34:04.435415015Z,2025-09-24T19:34:04.435153039Z,160,1,432669,T,A,64.820000000,1,26,8058566333552,0,18141,94277829,CLX5
2025-09-24T19:34:04.435415015Z,2025-09-24T19:34:04.435153039Z,160,1,432669,F,B,64.820000000,1,26,8058566333100,0,18141,94277829,CLX5
2025-09-24T19:34:04.435426258Z,2025-09-24T19:34:04.435153039Z,160,1,432669,C,B,64.820000000,1,26,8058566333100,128,16306,94277830,CLX5
2025-09-24T19:34:04.438811317Z,2025-09-24T19:34:04.438670783Z,160,1,432669,A,B,64.820000000,1,26,8058566333563,128,18068,94277865,CLX5
2025-09-24T19:34:04.450514354Z,2025-09-24T19:34:04.450403367Z,160,1,432669,C,A,65.030000000,1,26,8058566324730,128,19236,94277898,CLX5
2025-09-24T19:34:04.452951429Z,2025-09-24T19:34:04.452795389Z,160,1,432669,C,B,64.820000000,1,26,8058566333549,128,19774,94277905,CLX5
2025-09-24T19:34:04.452984466Z,2025-09-24T19:34:04.452796061Z,160,1,432669,C,B,64.820000000,1,26,8058566333563,128,15171,94277906,CLX5
2025-09-24T19:34:04.544563826Z,2025-09-24T19:34:04.544457197Z,160,1,432669,A,A,65.010000000,1,26,8058566333574,128,18163,94277930,CLX5
2025-09-24T19:34:04.858610109Z,2025-09-24T19:34:04.858497097Z,160,1,432669,C,A,65.210000000,1,26,8058566277403,128,17782,94277946,CLX5
2025-09-24T19:34:04.968651840Z,2025-09-24T19:34:04.968541231Z,160,1,432669,A,A,65.130000000,1,26,8058566333583,128,18994,94277947,CLX5
2025-09-24T19:34:05.635198885Z,2025-09-24T19:34:05.634942641Z,160,1,432669,A,B,64.820000000,1,26,8058566333591,128,14939,94277995,CLX5
2025-09-24T19:34:05.635257726Z,2025-09-24T19:34:05.634947783Z,160,1,432669,A,B,64.820000000,2,26,8058566333592,128,16244,94277997,CLX5
2025-09-24T19:34:05.635513756Z,2025-09-24T19:34:05.635004209Z,160,1,432669,A,B,64.820000000,2,26,8058566333598,128,15007,94278007,CLX5
2025-09-24T19:34:05.635548076Z,2025-09-24T19:34:05.635192975Z,160,1,432669,A,B,64.820000000,2,26,8058566333599,128,15481,94278008,CLX5
2025-09-24T19:34:05.635593178Z,2025-09-24T19:34:05.635202097Z,160,1,432669,C,A,64.860000000,2,26,8058566330777,128,19086,94278010,CLX5
2025-09-24T19:34:05.635996618Z,2025-09-24T19:34:05.635288125Z,160,1,432669,C,B,64.820000000,2,26,8058566333598,128,20705,94278027,CLX5
2025-09-24T19:34:05.636739981Z,2025-09-24T19:34:05.636104763Z,160,1,432669,C,B,64.820000000,2,26,8058566333599,128,16087,94278062,CLX5
2025-09-24T19:34:05.668701524Z,2025-09-24T19:34:05.668565041Z,160,1,432669,A,A,64.860000000,2,26,8058566333636,128,18073,94278183,CLX5
2025-09-24T19:34:05.668857044Z,2025-09-24T19:34:05.668720669Z,160,1,432669,C,B,64.820000000,2,26,8058566333592,128,19671,94278184,CLX5
2025-09-24T19:34:05.694665013Z,2025-09-24T19:34:05.694538481Z,160,1,432669,C,A,64.860000000,2,26,8058566333636,128,19022,94278190,CLX5
2025-09-24T19:34:05.694858414Z,2025-09-24T19:34:05.694668477Z,160,1,432669,A,B,64.820000000,1,26,8058566333637,128,16355,94278195,CLX5
2025-09-24T19:34:05.694893440Z,2025-09-24T19:34:05.694668689Z,160,1,432669,A,B,64.820000000,1,26,8058566333638,128,16333,94278196,CLX5
2025-09-24T19:34:05.710367059Z,2025-09-24T19:34:05.710238357Z,160,1,432669,A,A,64.880000000,2,26,8058566333657,128,18032,94278268,CLX5
2025-09-24T19:34:05.780633293Z,2025-09-24T19:34:05.780507259Z,160,1,432669,C,B,64.790000000,1,26,8058566330981,128,18024,94278338,CLX5
2025-09-24T19:34:05.810691366Z,2025-09-24T19:34:05.810557217Z,160,1,432669,A,B,64.780000000,2,26,8058566333689,128,18301,94278360,CLX5
2025-09-24T19:34:06.087439774Z,2025-09-24T19:34:06.087234337Z,160,1,432669,C,B,64.780000000,2,26,8058566333689,128,14616,94278481,CLX5
2025-09-24T19:34:06.780148506Z,2025-09-24T19:34:06.779998239Z,160,1,432669,A,B,64.820000000,1,26,8058566333799,128,19518,94278728,CLX5
2025-09-24T19:34:06.875850249Z,2025-09-24T19:34:06.874358277Z,160,1,432669,C,B,64.820000000,1,26,8058566333799,128,16874,94278877,CLX5
2025-09-24T19:34:06.876512092Z,2025-09-24T19:34:06.874917527Z,160,1,432669,C,A,64.830000000,1,26,8058566330308,128,18652,94278933,CLX5
2025-09-24T19:34:06.878033005Z,2025-09-24T19:34:06.875775039Z,160,1,432669,A,B,64.820000000,1,26,8058566333874,128,16813,94279029,CLX5
2025-09-24T19:34:06.878725167Z,2025-09-24T19:34:06.876417001Z,160,1,432669,A,B,64.820000000,1,26,8058566333888,128,15820,94279073,CLX5
2025-09-24T19:34:06.878798738Z,2025-09-24T19:34:06.876517891Z,160,1,432669,A,B,64.820000000,1,26,8058566333889,128,18634,94279076,CLX5
2025-09-24T19:34:06.879101276Z,2025-09-24T19:34:06.876626097Z,160,1,432669,C,A,64.830000000,1,26,8058566330283,128,18478,94279088,CLX5
2025-09-24T19:34:06.879140234Z,2025-09-24T19:34:06.876626397Z,160,1,432669,C,A,64.830000000,1,26,8058566330284,128,15135,94279090,CLX5
2025-09-24T19:34:06.879224526Z,2025-09-24T19:34:06.876626723Z,160,1,432669,A,B,64.820000000,2,26,8058566333896,128,15028,94279093,CLX5
2025-09-24T19:34:06.879366844Z,2025-09-24T19:34:06.876653477Z,160,1,432669,A,B,64.820000000,2,26,8058566333900,128,15359,94279099,CLX5
2025-09-24T19:34:06.879480594Z,2025-09-24T19:34:06.876743693Z,160,1,432669,C,A,64.830000000,2,26,8058566330305,128,15147,94279105,CLX5
2025-09-24T19:34:06.879681254Z,2025-09-24T19:34:06.876807951Z,160,1,432669,A,B,64.810000000,2,26,8058566333906,128,15152,94279115,CLX5
2025-09-24T19:34:06.879872560Z,2025-09-24T19:34:06.876810851Z,160,1,432669,C,A,64.830000000,1,26,8058566330339,128,18495,94279121,CLX5
2025-09-24T19:34:06.879940655Z,2025-09-24T19:34:06.876816765Z,160,1,432669,C,A,64.830000000,1,26,8058566330307,128,15383,94279124,CLX5
2025-09-24T19:34:06.880261102Z,2025-09-24T19:34:06.876861115Z,160,1,432669,C,A,64.830000000,2,26,8058566330578,128,19413,94279137,CLX5
2025-09-24T19:34:06.881986646Z,2025-09-24T19:34:06.878671307Z,160,1,432669,C,A,64.830000000,1,26,8058566330721,128,19512,94279234,CLX5
2025-09-24T19:34:06.882109304Z,2025-09-24T19:34:06.878903579Z,160,1,432669,C,B,64.820000000,2,26,8058566333900,128,18484,94279238,CLX5
2025-09-24T19:34:06.882353532Z,2025-09-24T19:34:06.879203815Z,160,1,432669,A,B,64.820000000,1,26,8058566333949,128,17610,94279251,CLX5
2025-09-24T19:34:06.883009845Z,2025-09-24T19:34:06.879878973Z,160,1,432669,C,A,64.860000000,1,26,8058566330580,128,19336,94279281,CLX5
2025-09-24T19:34:06.883613162Z,2025-09-24T19:34:06.880345243Z,160,1,432669,M,A,64.840000000,1,26,8058566325943,128,16715,94279309,CLX5
2025-09-24T19:34:06.883962446Z,2025-09-24T19:34:06.880727537Z,160,1,432669,C,A,64.830000000,1,26,8058566330285,128,17256,94279322,CLX5
2025-09-24T19:34:06.885065266Z,2025-09-24T19:34:06.881345633Z,160,1,432669,C,A,64.830000000,1,26,8058566330278,128,16153,94279394,CLX5
2025-09-24T19:34:06.885681530Z,2025-09-24T19:34:06.882067349Z,160,1,432669,C,A,64.830000000,3,26,8058566330683,128,18205,94279438,CLX5
2025-09-24T19:34:06.889373851Z,2025-09-24T19:34:06.886495077Z,160,1,432669,A,B,64.820000000,2,26,8058566334061,128,14904,94279672,CLX5
2025-09-24T19:34:06.890404245Z,2025-09-24T19:34:06.889048259Z,160,1,432669,C,B,64.820000000,2,26,8058566334061,128,18496,94279745,CLX5
2025-09-24T19:34:06.891872354Z,2025-09-24T19:34:06.891075785Z,160,1,432669,A,A,64.830000000,2,26,8058566334104,128,16815,94279844,CLX5
2025-09-24T19:34:06.891915713Z,2025-09-24T19:34:06.891093199Z,160,1,432669,A,A,64.830000000,1,26,8058566334105,128,20632,94279845,CLX5
2025-09-24T19:34:06.891945540Z,2025-09-24T19:34:06.891093391Z,160,1,432669,A,A,64.830000000,1,26,8058566334106,128,15357,94279846,CLX5
2025-09-24T19:34:06.892524029Z,2025-09-24T19:34:06.891746737Z,160,1,432669,A,A,64.830000000,1,26,8058566334112,128,19637,94279891,CLX5
2025-09-24T19:34:06.892645911Z,2025-09-24T19:34:06.891871897Z,160,1,432669,C,B,64.820000000,2,26,8058566333896,128,18513,94279895,CLX5
2025-09-24T19:34:06.893006169Z,2025-09-24T19:34:06.892516259Z,160,1,432669,C,B,64.810000000,2,26,8058566333906,128,15651,94279919,CLX5
2025-09-24T19:34:06.893254504Z,2025-09-24T19:34:06.892522327Z,160,1,432669,A,A,64.830000000,1,26,8058566334123,128,19195,94279926,CLX5
2025-09-24T19:34:06.981664984Z,2025-09-24T19:34:06.981500803Z,160,1,432669,M,A,64.830000000,1,26,8058566325943,128,20021,94280425,CLX5
2025-09-24T19:34:06.981809329Z,2025-09-24T19:34:06.981683501Z,160,1,432669,C,A,64.830000000,1,26,8058566334123,128,15631,94280428,CLX5
2025-09-24T19:34:07.010417480Z,2025-09-24T19:34:07.010275495Z,160,1,432669,A,B,64.780000000,2,26,8058566334354,128,18469,94280598,CLX5
2025-09-24T19:34:07.188702366Z,2025-09-24T19:34:07.188513985Z,160,1,432669,C,A,64.830000000,1,26,8058566334112,128,19480,94281157,CLX5
2025-09-24T19:34:07.188737823Z,2025-09-24T19:34:07.188514253Z,160,1,432669,C,A,64.830000000,1,26,8058566334106,128,16264,94281158,CLX5
2025-09-24T19:34:07.188823427Z,2025-09-24T19:34:07.188550041Z,160,1,432669,C,A,64.830000000,1,26,8058566334105,128,20022,94281160,CLX5
2025-09-24T19:34:07.189041965Z,2025-09-24T19:34:07.188848071Z,160,1,432669,M,A,64.840000000,1,26,8058566325943,128,18903,94281170,CLX5
2025-09-24T19:34:07.521454425Z,2025-09-24T19:34:07.521004893Z,160,1,432669,A,B,64.820000000,2,26,8058566334745,128,19094,94281394,CLX5
2025-09-24T19:34:10.007761358Z,2025-09-24T19:34:10.006885953Z,160,1,432669,C,A,64.830000000,2,26,8058566334104,128,20771,94282037,CLX5
2025-09-24T19:34:10.007965942Z,2025-09-24T19:34:10.007413449Z,160,1,432669,A,B,64.810000000,2,26,8058566335033,128,14611,94282050,CLX5
2025-09-24T19:34:10.009216211Z,2025-09-24T19:34:10.007781055Z,160,1,432669,C,A,64.830000000,2,26,8058566330291,128,19091,94282096,CLX5
2025-09-24T19:34:10.009798955Z,2025-09-24T19:34:10.009137705Z,160,1,432669,A,A,64.830000000,1,26,8058566335056,128,18052,94282122,CLX5
2025-09-24T19:34:10.009821087Z,2025-09-24T19:34:10.009137887Z,160,1,432669,A,A,64.830000000,1,26,8058566335057,128,14137,94282124,CLX5
2025-09-24T19:34:10.009915777Z,2025-09-24T19:34:10.009218669Z,160,1,432669,A,A,64.830000000,2,26,8058566335059,128,15719,94282128,CLX5
2025-09-24T19:34:10.010025994Z,2025-09-24T19:34:10.009273157Z,160,1,432669,A,A,64.830000000,1,26,8058566335060,128,20692,94282134,CLX5
2025-09-24T19:34:10.012043793Z,2025-09-24T19:34:10.010237339Z,160,1,432669,C,B,64.790000000,2,26,8058566331916,128,18356,94282261,CLX5
2025-09-24T19:34:10.013446272Z,2025-09-24T19:34:10.012060989Z,160,1,432669,C,B,64.820000000,2,26,8058566334745,128,15651,94282355,CLX5
2025-09-24T19:34:10.013749777Z,2025-09-24T19:34:10.012396205Z,160,1,432669,A,A,64.830000000,1,26,8058566335100,128,16660,94282366,CLX5
2025-09-24T19:34:10.014946189Z,2025-09-24T19:34:10.013457075Z,160,1,432669,C,A,64.830000000,1,26,8058566335100,128,16274,94282430,CLX5
2025-09-24T19:34:10.075755910Z,2025-09-24T19:34:10.075618787Z,160,1,432669,C,B,64.820000000,1,26,8058566333889,128,18580,94282955,CLX5
2025-09-24T19:34:10.075783495Z,2025-09-24T19:34:10.075619229Z,160,1,432669,C,B,64.810000000,2,26,8058566335033,128,15194,94282956,CLX5
2025-09-24T19:34:10.075890210Z,2025-09-24T19:34:10.075628213Z,160,1,432669,A,A,64.830000000,1,26,8058566335292,128,15578,94282960,CLX5
2025-09-24T19:34:10.075948606Z,2025-09-24T19:34:10.075630423Z,160,1,432669,C,B,64.820000000,1,26,8058566333874,128,15112,94282962,CLX5
2025-09-24T19:34:10.076152545Z,2025-09-24T19:34:10.075633455Z,160,1,432669,A,A,64.830000000,2,26,8058566335294,128,17339,94282968,CLX5
2025-09-24T19:34:10.076181873Z,2025-09-24T19:34:10.075634357Z,160,1,432669,A,A,64.830000000,1,26,8058566335295,128,15546,94282969,CLX5
2025-09-24T19:34:10.076261687Z,2025-09-24T19:34:10.075639849Z,160,1,432669,A,A,64.830000000,1,26,8058566335296,128,14869,94282972,CLX5
2025-09-24T19:34:10.076378786Z,2025-09-24T19:34:10.075678937Z,160,1,432669,A,A,64.830000000,2,26,8058566335297,128,14380,94282977,CLX5
2025-09-24T19:34:10.076633049Z,2025-09-24T19:34:10.076022391Z,160,1,432669,M,A,64.830000000,1,26,8058566325943,128,15862,94282989,CLX5
2025-09-24T19:34:10.076686807Z,2025-09-24T19:34:10.076045277Z,160,1,432669,C,A,64.830000000,2,26,8058566335297,128,15358,94282991,CLX5
2025-09-24T19:34:10.076716127Z,2025-09-24T19:34:10.076067165Z,160,1,432669,C,A,64.830000000,1,26,8058566335296,128,15515,94282992,CLX5
2025-09-24T19:34:10.076851304Z,2025-09-24T19:34:10.076157873Z,160,1,432669,A,A,64.830000000,1,26,8058566335300,128,14447,94282996,CLX5
2025-09-24T19:34:10.076891607Z,2025-09-24T19:34:10.076440243Z,160,1,432669,C,A,64.830000000,1,26,8058566335300,128,18958,94282998,CLX5
2025-09-24T19:34:10.076927555Z,2025-09-24T19:34:10.076442661Z,160,1,432669,C,B,64.820000000,1,26,8058566333888,128,14735,94282999,CLX5
2025-09-24T19:34:10.076964056Z,2025-09-24T19:34:10.076451531Z,160,1,432669,C,B,64.820000000,1,26,8058566333949,128,15833,94283000,CLX5
2025-09-24T19:34:10.077236904Z,2025-09-24T19:34:10.076899563Z,160,1,432669,C,A,64.830000000,1,26,8058566335295,128,19009,94283012,CLX5
2025-09-24T19:34:10.077264343Z,2025-09-24T19:34:10.076931933Z,160,1,432669,A,A,64.830000000,1,26,8058566335303,128,15238,94283013,CLX5
2025-09-24T19:34:10.077613173Z,2025-09-24T19:34:10.077240903Z,160,1,432669,C,A,64.830000000,1,26,8058566335303,128,15190,94283029,CLX5
2025-09-24T19:34:10.077647401Z,2025-09-24T19:34:10.077244763Z,160,1,432669,A,A,64.830000000,1,26,8058566335312,128,18492,94283030,CLX5
2025-09-24T19:34:10.077673781Z,2025-09-24T19:34:10.077271989Z,160,1,432669,C,A,64.830000000,1,26,8058566335312,128,15414,94283031,CLX5
2025-09-24T19:34:10.077737168Z,2025-09-24T19:34:10.077620779Z,160,1,432669,A,A,64.830000000,1,26,8058566335313,128,15777,94283032,CLX5
2025-09-24T19:34:10.077769100Z,2025-09-24T19:34:10.077654993Z,160,1,432669,C,A,64.830000000,1,26,8058566335313,128,18212,94283033,CLX5
2025-09-24T19:34:10.101132293Z,2025-09-24T19:34:10.101000721Z,160,1,432669,A,A,64.830000000,1,26,8058566335319,128,18309,94283042,CLX5
2025-09-24T19:34:10.101158764Z,2025-09-24T19:34:10.101005213Z,160,1,432669,A,A,64.830000000,1,26,8058566335320,128,15344,94283043,CLX5
2025-09-24T19:34:10.110414674Z,2025-09-24T19:34:10.110289175Z,160,1,432669,A,B,64.790000000,2,26,8058566335327,128,18072,94283061,CLX5
2025-09-24T19:34:10.121151304Z,2025-09-24T19:34:10.121029873Z,160,1,432669,C,A,64.830000000,1,26,8058566335320,128,18675,94283102,CLX5
2025-09-24T19:34:10.121276005Z,2025-09-24T19:34:10.121155991Z,160,1,432669,C,A,64.830000000,1,26,8058566335319,128,18549,94283108,CLX5
2025-09-24T19:34:10.160699024Z,2025-09-24T19:34:10.160563961Z,160,1,432669,A,A,64.830000000,1,26,8058566335361,128,18995,94283139,CLX5
2025-09-24T19:34:10.161021644Z,2025-09-24T19:34:10.160905437Z,160,1,432669,A,A,64.830000000,1,26,8058566335362,128,15178,94283145,CLX5
2025-09-24T19:34:10.702622126Z,2025-09-24T19:34:10.702471621Z,160,1,432669,C,A,64.830000000,1,26,8058566335361,128,15449,94283251,CLX5
2025-09-24T19:34:10.702668619Z,2025-09-24T19:34:10.702478935Z,160,1,432669,A,B,64.820000000,2,26,8058566335423,128,19021,94283252,CLX5
2025-09-24T19:34:10.702698354Z,2025-09-24T19:34:10.702497539Z,160,1,432669,C,A,64.830000000,1,26,8058566335362,128,15325,94283253,CLX5
2025-09-24T19:34:10.861941496Z,2025-09-24T19:34:10.861780607Z,160,1,432669,A,A,64.830000000,1,26,8058566335436,128,19366,94283289,CLX5
2025-09-24T19:34:11.954779747Z,2025-09-24T19:34:11.954597043Z,160,1,432669,A,B,64.810000000,2,26,8058566335478,128,25969,94283381,CLX5
2025-09-24T19:34:11.954896062Z,2025-09-24T19:34:11.954602937Z,160,1,432669,A,B,64.820000000,1,26,8058566335479,128,19803,94283385,CLX5
2025-09-24T19:34:11.955148552Z,2025-09-24T19:34:11.954901465Z,160,1,432669,C,A,64.830000000,1,26,8058566335060,128,20773,94283390,CLX5
2025-09-24T19:34:11.955182135Z,2025-09-24T19:34:11.954911025Z,160,1,432669,A,B,64.820000000,1,26,8058566335482,128,18351,94283391,CLX5
2025-09-24T19:34:12.010370499Z,2025-09-24T19:34:12.010230007Z,160,1,432669,C,B,64.790000000,2,26,8058566335327,128,18942,94283403,CLX5
2025-09-24T19:34:12.518703092Z,2025-09-24T19:34:12.518568655Z,160,1,432669,C,B,64.820000000,1,26,8058566335482,128,18697,94283476,CLX5
2025-09-24T19:34:17.233582035Z,2025-09-24T19:34:17.233218373Z,160,1,432669,T,A,64.820000000,1,26,8058566335601,0,17816,94283686,CLX5
2025-09-24T19:34:17.233582035Z,2025-09-24T19:34:17.233218373Z,160,1,432669,F,B,64.820000000,1,26,8058566333103,0,17816,94283686,CLX5
2025-09-24T19:34:17.233592411Z,2025-09-24T19:34:17.233218373Z,160,1,432669,C,B,64.820000000,1,26,8058566333103,128,15520,94283687,CLX5
2025-09-24T19:34:17.677519428Z,2025-09-24T19:34:17.677176887Z,160,1,432669,T,A,64.820000000,1,26,8058566335628,0,18749,94283744,CLX5
2025-09-24T19:34:17.677519428Z,2025-09-24T19:34:17.677176887Z,160,1,432669,F,B,64.820000000,1,26,8058566333154,0,18749,94283744,CLX5
2025-09-24T19:34:17.677529558Z,2025-09-24T19:34:17.677176887Z,160,1,432669,M,B,64.820000000,1,26,8058566333154,128,15682,94283745,CLX5
2025-09-24T19:34:17.678145845Z,2025-09-24T19:34:17.678009439Z,160,1,432669,A,B,64.820000000,1,26,8058566335630,128,17958,94283751,CLX5
2025-09-24T19:34:17.678272575Z,2025-09-24T19:34:17.678127109Z,160,1,432669,A,A,64.830000000,1,26,8058566335631,128,17902,94283752,CLX5
2025-09-24T19:34:17.687759035Z,2025-09-24T19:34:17.687617541Z,160,1,432669,A,B,64.820000000,1,26,8058566335632,128,18728,94283753,CLX5
2025-09-24T19:34:18.121633879Z,2025-09-24T19:34:18.121323937Z,160,1,432669,T,A,64.820000000,1,26,8058566335649,0,17785,94283786,CLX5
2025-09-24T19:34:18.121633879Z,2025-09-24T19:34:18.121323937Z,160,1,432669,F,B,64.820000000,1,26,8058566333154,0,17785,94283786,CLX5
2025-09-24T19:34:18.121645276Z,2025-09-24T19:34:18.121323937Z,160,1,432669,C,B,64.820000000,1,26,8058566333154,128,17016,94283787,CLX5
2025-09-24T19:34:18.121850121Z,2025-09-24T19:34:18.121695231Z,160,1,432669,C,B,64.820000000,1,26,8058566335630,128,14788,94283792,CLX5
2025-09-24T19:34:18.224838649Z,2025-09-24T19:34:18.224676397Z,160,1,432669,A,B,64.820000000,1,26,8058566335656,128,18335,94283805,CLX5
2025-09-24T19:34:18.565775090Z,2025-09-24T19:34:18.565485731Z,160,1,432669,T,A,64.820000000,1,26,8058566335671,0,17898,94283836,CLX5
2025-09-24T19:34:18.565775090Z,2025-09-24T19:34:18.565485731Z,160,1,432669,F,B,64.820000000,1,26,8058566333156,0,17898,94283836,CLX5
2025-09-24T19:34:18.565786740Z,2025-09-24T19:34:18.565485731Z,160,1,432669,C,B,64.820000000,1,26,8058566333156,128,17045,94283837,CLX5
2025-09-24T19:34:18.576043394Z,2025-09-24T19:34:18.575905401Z,160,1,432669,A,B,64.820000000,1,26,8058566335674,128,19458,94283842,CLX5
2025-09-24T19:34:18.576295008Z,2025-09-24T19:34:18.576165393Z,160,1,432669,A,B,64.820000000,1,26,8058566335675,128,18692,94283844,CLX5
2025-09-24T19:34:18.576500407Z,2025-09-24T19:34:18.576307507Z,160,1,432669,C,B,64.820000000,1,26,8058566335675,128,15077,94283849,CLX5
2025-09-24T19:34:19.009937145Z,2025-09-24T19:34:19.009609755Z,160,1,432669,T,A,64.820000000,1,26,8058566335696,0,18039,94283888,CLX5
2025-09-24T19:34:19.009937145Z,2025-09-24T19:34:19.009609755Z,160,1,432669,F,B,64.820000000,1,26,8058566333158,0,18039,94283888,CLX5
2025-09-24T19:34:19.009949195Z,2025-09-24T19:34:19.009609755Z,160,1,432669,C,B,64.820000000,1,26,8058566333158,128,17685,94283889,CLX5
2025-09-24T19:34:19.010058521Z,2025-09-24T19:34:19.009914563Z,160,1,432669,A,A,64.830000000,1,26,8058566335697,128,19359,94283890,CLX5
2025-09-24T19:34:19.010110243Z,2025-09-24T19:34:19.009933473Z,160,1,432669,A,A,64.830000000,1,26,8058566335699,128,15325,94283892,CLX5
2025-09-24T19:34:19.010208089Z,2025-09-24T19:34:19.010030391Z,160,1,432669,A,B,64.820000000,1,26,8058566335701,128,16475,94283895,CLX5
2025-09-24T19:34:19.010335908Z,2025-09-24T19:34:19.010212187Z,160,1,432669,C,A,64.830000000,1,26,8058566335697,128,18387,94283897,CLX5
2025-09-24T19:34:19.454063143Z,2025-09-24T19:34:19.453759641Z,160,1,432669,T,A,64.820000000,1,26,8058566335719,0,18245,94283935,CLX5
2025-09-24T19:34:19.454063143Z,2025-09-24T19:34:19.453759641Z,160,1,432669,F,B,64.820000000,1,26,8058566333177,0,18245,94283935,CLX5
2025-09-24T19:34:19.454074724Z,2025-09-24T19:34:19.453759641Z,160,1,432669,C,B,64.820000000,1,26,8058566333177,128,16093,94283936,CLX5
2025-09-24T19:34:19.454164268Z,2025-09-24T19:34:19.454037261Z,160,1,432669,A,A,64.830000000,1,26,8058566335720,128,18635,94283937,CLX5
2025-09-24T19:34:19.454204017Z,2025-09-24T19:34:19.454055081Z,160,1,432669,C,B,64.820000000,1,26,8058566335701,128,17079,94283938,CLX5
2025-09-24T19:34:19.454344892Z,2025-09-24T19:34:19.454217831Z,160,1,432669,C,B,64.820000000,1,26,8058566335632,128,16341,94283943,CLX5
2025-09-24T19:34:19.454382599Z,2025-09-24T19:34:19.454218195Z,160,1,432669,C,B,64.820000000,1,26,8058566335656,128,19744,94283944,CLX5
2025-09-24T19:34:19.454413816Z,2025-09-24T19:34:19.454218521Z,160,1,432669,C,B,64.820000000,1,26,8058566335674,128,16252,94283945,CLX5
2025-09-24T19:34:19.454448528Z,2025-09-24T19:34:19.454281611Z,160,1,432669,A,B,64.820000000,1,26,8058566335723,128,16227,94283946,CLX5
2025-09-24T19:34:19.454612234Z,2025-09-24T19:34:19.454423089Z,160,1,432669,A,B,64.820000000,1,26,8058566335725,128,16649,94283951,CLX5
2025-09-24T19:34:19.454774258Z,2025-09-24T19:34:19.454651195Z,160,1,432669,C,B,64.820000000,1,26,8058566335725,128,20992,94283955,CLX5
2025-09-24T19:34:19.454805276Z,2025-09-24T19:34:19.454653325Z,160,1,432669,A,A,64.830000000,1,26,8058566335726,128,14183,94283956,CLX5
2025-09-24T19:34:19.455059287Z,2025-09-24T19:34:19.454934151Z,160,1,432669,A,B,64.820000000,1,26,8058566335727,128,19407,94283957,CLX5
2025-09-24T19:34:19.898260568Z,2025-09-24T19:34:19.897959311Z,160,1,432669,T,A,64.820000000,1,26,8058566335742,0,17601,94283994,CLX5
2025-09-24T19:34:19.898260568Z,2025-09-24T19:34:19.897959311Z,160,1,432669,F,B,64.820000000,1,26,8058566333591,0,17601,94283994,CLX5
2025-09-24T19:34:19.898272448Z,2025-09-24T19:34:19.897959311Z,160,1,432669,C,B,64.820000000,1,26,8058566333591,128,17621,94283995,CLX5
2025-09-24T19:34:19.898613276Z,2025-09-24T19:34:19.898281357Z,160,1,432669,C,B,64.820000000,1,26,8058566335727,128,16066,94284002,CLX5
2025-09-24T19:34:19.898774279Z,2025-09-24T19:34:19.898630629Z,160,1,432669,A,A,64.830000000,1,26,8058566335746,128,17566,94284003,CLX5
2025-09-24T19:34:20.342382251Z,2025-09-24T19:34:20.342085967Z,160,1,432669,T,A,64.820000000,1,26,8058566335762,0,17980,94284035,CLX5
2025-09-24T19:34:20.342382251Z,2025-09-24T19:34:20.342085967Z,160,1,432669,F,B,64.820000000,1,26,8058566333637,0,17980,94284035,CLX5
2025-09-24T19:34:20.342394070Z,2025-09-24T19:34:20.342085967Z,160,1,432669,C,B,64.820000000,1,26,8058566333637,128,16933,94284036,CLX5
2025-09-24T19:34:20.342735374Z,2025-09-24T19:34:20.342362607Z,160,1,432669,C,B,64.820000000,1,26,8058566335479,128,22525,94284044,CLX5
2025-09-24T19:34:20.342777182Z,2025-09-24T19:34:20.342373897Z,160,1,432669,C,B,64.820000000,1,26,8058566335723,128,17482,94284045,CLX5
2025-09-24T19:34:20.343016570Z,2025-09-24T19:34:20.342451383Z,160,1,432669,T,A,64.820000000,4,26,8058566335765,0,16376,94284057,CLX5
2025-09-24T19:34:20.343016570Z,2025-09-24T19:34:20.342451383Z,160,1,432669,F,B,64.820000000,1,26,8058566333638,0,16376,94284057,CLX5
2025-09-24T19:34:20.343016570Z,2025-09-24T19:34:20.342451383Z,160,1,432669,F,B,64.820000000,2,26,8058566335423,0,16376,94284057,CLX5
2025-09-24T19:34:20.343016570Z,2025-09-24T19:34:20.342451383Z,160,1,432669,C,B,64.820000000,1,26,8058566333638,0,16376,94284057,CLX5
2025-09-24T19:34:20.343016570Z,2025-09-24T19:34:20.342451383Z,160,1,432669,C,B,64.820000000,2,26,8058566335423,128,16376,94284057,CLX5
2025-09-24T19:34:20.343581788Z,2025-09-24T19:34:20.342882755Z,160,1,432669,A,A,64.830000000,1,26,8058566335771,128,17774,94284076,CLX5
2025-09-24T19:34:20.343917149Z,2025-09-24T19:34:20.343019795Z,160,1,432669,A,A,64.830000000,1,26,8058566335775,128,14642,94284088,CLX5
2025-09-24T19:34:20.343997708Z,2025-09-24T19:34:20.343025017Z,160,1,432669,A,A,64.860000000,1,26,8058566335777,128,16849,94284090,CLX5
2025-09-24T19:34:20.344189928Z,2025-09-24T19:34:20.343029951Z,160,1,432669,C,B,64.810000000,2,26,8058566333074,128,18737,94284099,CLX5
2025-09-24T19:34:20.344456041Z,2025-09-24T19:34:20.343099125Z,160,1,432669,A,A,64.830000000,3,26,8058566335783,128,15100,94284107,CLX5
2025-09-24T19:34:20.344527462Z,2025-09-24T19:34:20.343167973Z,160,1,432669,A,A,64.830000000,2,26,8058566335784,128,15069,94284109,CLX5
2025-09-24T19:34:20.344566405Z,2025-09-24T19:34:20.343181797Z,160,1,432669,A,B,64.810000000,5,26,8058566335785,128,14988,94284110,CLX5
2025-09-24T19:34:20.344677682Z,2025-09-24T19:34:20.343283897Z,160,1,432669,C,A,64.830000000,1,26,8058566335775,128,15197,94284115,CLX5
2025-09-24T19:34:20.344760361Z,2025-09-24T19:34:20.343313599Z,160,1,432669,A,A,64.830000000,1,26,8058566335786,128,15139,94284120,CLX5
2025-09-24T19:34:20.344836942Z,2025-09-24T19:34:20.343430771Z,160,1,432669,A,A,64.830000000,1,26,8058566335787,128,15258,94284126,CLX5
2025-09-24T19:34:20.345000171Z,2025-09-24T19:34:20.343612895Z,160,1,432669,A,A,64.830000000,1,26,8058566335789,128,18387,94284133,CLX5
2025-09-24T19:34:20.345687204Z,2025-09-24T19:34:20.343707239Z,160,1,432669,C,A,64.830000000,1,26,8058566335787,128,14968,94284157,CLX5
2025-09-24T19:34:20.345802705Z,2025-09-24T19:34:20.343719219Z,160,1,432669,A,A,64.830000000,1,26,8058566335799,128,14930,94284163,CLX5
2025-09-24T19:34:20.346000938Z,2025-09-24T19:34:20.343851423Z,160,1,432669,C,A,64.830000000,2,26,8058566335784,128,15611,94284173,CLX5
2025-09-24T19:34:20.346146252Z,2025-09-24T19:34:20.343928681Z,160,1,432669,M,B,63.650000000,4,26,8058566319851,128,15162,94284180,CLX5
2025-09-24T19:34:20.346803287Z,2025-09-24T19:34:20.344531919Z,160,1,432669,A,A,64.820000000,2,26,8058566335813,128,18459,94284207,CLX5
2025-09-24T19:34:20.347358330Z,2025-09-24T19:34:20.344754833Z,160,1,432669,A,A,64.820000000,1,26,8058566335826,128,15005,94284234,CLX5
2025-09-24T19:34:20.347704772Z,2025-09-24T19:34:20.344938825Z,160,1,432669,C,B,64.810000000,2,26,8058566335478,128,14945,94284251,CLX5
2025-09-24T19:34:20.347758998Z,2025-09-24T19:34:20.344940093Z,160,1,432669,A,A,64.820000000,2,26,8058566335833,128,21873,94284252,CLX5
2025-09-24T19:34:20.348143661Z,2025-09-24T19:34:20.344949079Z,160,1,432669,C,B,64.780000000,2,26,8058566334354,128,15932,94284264,CLX5
2025-09-24T19:34:20.348370547Z,2025-09-24T19:34:20.345178777Z,160,1,432669,A,A,64.860000000,2,26,8058566335838,128,14986,94284276,CLX5
2025-09-24T19:34:20.349667016Z,2025-09-24T19:34:20.345827651Z,160,1,432669,M,B,64.810000000,4,26,8058566335785,128,15094,94284339,CLX5
2025-09-24T19:34:20.351040513Z,2025-09-24T19:34:20.347098423Z,160,1,432669,M,A,64.840000000,4,26,8058566282798,128,15129,94284402,CLX5
2025-09-24T19:34:20.351164661Z,2025-09-24T19:34:20.347230553Z,160,1,432669,C,A,64.830000000,1,26,8058566335726,128,14965,94284409,CLX5
2025-09-24T19:34:20.351196493Z,2025-09-24T19:34:20.347231473Z,160,1,432669,C,A,64.830000000,1,26,8058566335631,128,18557,94284410,CLX5
2025-09-24T19:34:20.351953678Z,2025-09-24T19:34:20.347707805Z,160,1,432669,A,A,64.820000000,1,26,8058566335879,128,17669,94284440,CLX5
2025-09-24T19:34:20.352236726Z,2025-09-24T19:34:20.347764135Z,160,1,432669,A,A,64.820000000,1,26,8058566335881,128,17223,94284453,CLX5
2025-09-24T19:34:20.352401491Z,2025-09-24T19:34:20.347909127Z,160,1,432669,M,A,64.940000000,1,26,8058565075241,128,14751,94284464,CLX5
2025-09-24T19:34:20.353352702Z,2025-09-24T19:34:20.348732253Z,160,1,432669,M,B,64.800000000,4,26,8058566335785,128,18219,94284508,CLX5
2025-09-24T19:34:20.355675327Z,2025-09-24T19:34:20.353871635Z,160,1,432669,A,A,64.820000000,3,26,8058566335916,128,17143,94284627,CLX5
2025-09-24T19:34:20.356417244Z,2025-09-24T19:34:20.354998241Z,160,1,432669,C,A,64.820000000,1,26,8058566335879,128,15992,94284659,CLX5
2025-09-24T19:34:20.356707687Z,2025-09-24T19:34:20.356252349Z,160,1,432669,A,A,64.820000000,1,26,8058566335929,128,19674,94284672,CLX5
2025-09-24T19:34:20.372271796Z,2025-09-24T19:34:20.372136693Z,160,1,432669,C,A,64.830000000,1,26,8058566335799,128,18739,94284744,CLX5
2025-09-24T19:34:20.372297246Z,2025-09-24T19:34:20.372144659Z,160,1,432669,C,A,64.830000000,1,26,8058566335789,128,14879,94284745,CLX5
2025-09-24T19:34:20.372325561Z,2025-09-24T19:34:20.372153991Z,160,1,432669,C,A,64.830000000,1,26,8058566335786,128,15087,94284746,CLX5
2025-09-24T19:34:20.397597465Z,2025-09-24T19:34:20.397448837Z,160,1,432669,A,A,64.820000000,2,26,8058566335960,128,19555,94284772,CLX5
2025-09-24T19:34:20.410493260Z,2025-09-24T19:34:20.410356275Z,160,1,432669,C,A,64.880000000,2,26,8058566333657,128,17970,94284788,CLX5
2025-09-24T19:34:20.410524624Z,2025-09-24T19:34:20.410356925Z,160,1,432669,A,B,64.790000000,2,26,8058566335966,128,14539,94284789,CLX5
2025-09-24T19:34:20.662509098Z,2025-09-24T19:34:20.662352243Z,160,1,432669,C,A,64.830000000,1,26,8058566335436,128,18461,94284971,CLX5
2025-09-24T19:34:20.663046509Z,2025-09-24T19:34:20.662911397Z,160,1,432669,A,A,64.820000000,1,26,8058566336044,128,19246,94284972,CLX5
2025-09-24T19:34:20.786585492Z,2025-09-24T19:34:20.786244013Z,160,1,432669,T,A,64.810000000,1,26,8058566336045,0,17926,94284981,CLX5
2025-09-24T19:34:20.786585492Z,2025-09-24T19:34:20.786244013Z,160,1,432669,F,B,64.810000000,1,26,8058566330880,0,17926,94284981,CLX5
2025-09-24T19:34:20.786594608Z,2025-09-24T19:34:20.786244013Z,160,1,432669,C,B,64.810000000,1,26,8058566330880,128,14840,94284982,CLX5
2025-09-24T19:34:20.786786591Z,2025-09-24T19:34:20.786563045Z,160,1,432669,C,B,64.810000000,2,26,8058566331188,128,15116,94284985,CLX5
2025-09-24T19:34:20.786867273Z,2025-09-24T19:34:20.786563851Z,160,1,432669,C,B,64.810000000,1,26,8058566331211,128,16755,94284988,CLX5
2025-09-24T19:34:20.787559389Z,2025-09-24T19:34:20.787430521Z,160,1,432669,C,B,64.790000000,1,26,8058566331895,128,20728,94285003,CLX5
2025-09-24T19:34:20.787829457Z,2025-09-24T19:34:20.787667055Z,160,1,432669,A,A,64.850000000,1,26,8058566336056,128,15812,94285013,CLX5
2025-09-24T19:34:20.816275017Z,2025-09-24T19:34:20.816171595Z,160,1,432669,A,B,64.160000000,2,26,8058566336059,128,18187,94285021,CLX5
2025-09-24T19:34:24.736768793Z,2025-09-24T19:34:24.736508645Z,160,1,432669,A,B,64.810000000,1,26,8058566336108,128,18583,94285157,CLX5
2025-09-24T19:34:27.116020231Z,2025-09-24T19:34:27.115915389Z,160,1,432669,C,B,64.160000000,2,26,8058566336059,128,18260,94285263,CLX5
2025-09-24T19:34:28.463529534Z,2025-09-24T19:34:28.463360087Z,160,1,432669,M,A,64.830000000,1,26,8058566276097,128,19388,94285278,CLX5
2025-09-24T19:34:29.214928972Z,2025-09-24T19:34:29.214518393Z,160,1,432669,A,A,64.820000000,1,26,8058566336144,128,19432,94285307,CLX5
2025-09-24T19:34:29.215650700Z,2025-09-24T19:34:29.215015591Z,160,1,432669,M,A,64.820000000,1,26,8058566325943,128,16390,94285339,CLX5
2025-09-24T19:34:29.216158829Z,2025-09-24T19:34:29.215582581Z,160,1,432669,C,A,64.820000000,1,26,8058566336144,128,14433,94285365,CLX5
2025-09-24T19:34:29.216440793Z,2025-09-24T19:34:29.215875235Z,160,1,432669,A,B,64.160000000,2,26,8058566336172,128,17770,94285371,CLX5
2025-09-24T19:34:29.216527487Z,2025-09-24T19:34:29.216167617Z,160,1,432669,A,A,64.820000000,1,26,8058566336174,128,14717,94285375,CLX5
2025-09-24T19:34:29.221307623Z,2025-09-24T19:34:29.221164735Z,160,1,432669,A,A,64.820000000,1,26,8058566336248,128,18308,94285624,CLX5
2025-09-24T19:34:29.221604462Z,2025-09-24T19:34:29.221415571Z,160,1,432669,C,A,64.820000000,1,26,8058566336248,128,18875,94285632,CLX5
2025-09-24T19:34:29.221731030Z,2025-09-24T19:34:29.221605145Z,160,1,432669,A,A,64.820000000,1,26,8058566336253,128,19112,94285636,CLX5
2025-09-24T19:34:29.222199907Z,2025-09-24T19:34:29.221926557Z,160,1,432669,C,A,64.820000000,1,26,8058566336253,128,15109,94285671,CLX5
2025-09-24T19:34:29.224791994Z,2025-09-24T19:34:29.223849027Z,160,1,432669,M,A,64.820000000,1,26,8058566331891,128,19752,94285799,CLX5
2025-09-24T19:34:29.225335172Z,2025-09-24T19:34:29.224376101Z,160,1,432669,A,A,64.820000000,1,26,8058566336312,128,14616,94285837,CLX5
2025-09-24T19:34:29.226926085Z,2025-09-24T19:34:29.225406557Z,160,1,432669,C,B,64.810000000,2,26,8058566331191,128,18593,94285945,CLX5
2025-09-24T19:34:29.237352813Z,2025-09-24T19:34:29.237161431Z,160,1,432669,C,A,64.820000000,1,26,8058566336312,128,14343,94286205,CLX5
2025-09-24T19:34:29.353600672Z,2025-09-24T19:34:29.353446171Z,160,1,432669,C,A,64.820000000,1,26,8058566336174,128,19075,94286557,CLX5
2025-09-24T19:34:29.353738252Z,2025-09-24T19:34:29.353609671Z,160,1,432669,A,A,64.820000000,1,26,8058566336566,128,18516,94286558,CLX5
2025-09-24T19:34:29.361360199Z,2025-09-24T19:34:29.361178611Z,160,1,432669,C,A,64.820000000,1,26,8058566336566,128,15172,94286583,CLX5
2025-09-24T19:34:29.361502294Z,2025-09-24T19:34:29.361368431Z,160,1,432669,A,A,64.820000000,1,26,8058566336590,128,15544,94286588,CLX5
2025-09-24T19:34:29.565463693Z,2025-09-24T19:34:29.565315565Z,160,1,432669,A,A,64.820000000,1,26,8058566336693,128,18740,94286771,CLX5
2025-09-24T19:34:30.766991518Z,2025-09-24T19:34:30.766820167Z,160,1,432669,A,B,64.780000000,1,26,8058566336849,128,21178,94287050,CLX5
2025-09-24T19:34:32.274732516Z,2025-09-24T19:34:32.274591031Z,160,1,432669,C,B,64.810000000,2,26,8058566331351,128,22245,94287071,CLX5
2025-09-24T19:34:32.275577763Z,2025-09-24T19:34:32.275443127Z,160,1,432669,C,B,64.770000000,2,26,8058566332230,128,22031,94287077,CLX5
2025-09-24T19:34:32.901098303Z,2025-09-24T19:34:32.900840161Z,160,1,432669,C,B,64.810000000,1,26,8058566336108,128,21343,94287105,CLX5
2025-09-24T19:34:33.359222767Z,2025-09-24T19:34:33.358874625Z,160,1,432669,C,A,64.820000000,1,26,8058566336590,128,16926,94287182,CLX5
2025-09-24T19:34:33.359706382Z,2025-09-24T19:34:33.359230999Z,160,1,432669,A,A,64.820000000,1,26,8058566336891,128,17414,94287210,CLX5
2025-09-24T19:34:33.360163349Z,2025-09-24T19:34:33.359963217Z,160,1,432669,A,B,64.810000000,1,26,8058566336898,128,18885,94287233,CLX5
2025-09-24T19:34:33.510453555Z,2025-09-24T19:34:33.510310037Z,160,1,432669,A,B,64.770000000,2,26,8058566336922,128,18567,94287298,CLX5
2025-09-24T19:34:35.503858628Z,2025-09-24T19:34:35.503726417Z,160,1,432669,C,A,64.820000000,1,26,8058566336891,128,18525,94287337,CLX5
2025-09-24T19:34:35.504101680Z,2025-09-24T19:34:35.503900843Z,160,1,432669,C,A,64.820000000,1,26,8058566325943,128,15165,94287341,CLX5
2025-09-24T19:34:40.842944915Z,2025-09-24T19:34:40.842802501Z,160,1,432669,M,B,62.110000000,10,26,8058561691831,128,23342,94287894,CLX5
2025-09-24T19:34:46.945789299Z,2025-09-24T19:34:46.945564221Z,160,1,432669,A,B,64.810000000,1,26,8058566337228,128,15109,94288152,CLX5
2025-09-24T19:34:46.945834232Z,2025-09-24T19:34:46.945568253Z,160,1,432669,A,A,64.820000000,1,26,8058566337229,128,18408,94288153,CLX5
2025-09-24T19:34:46.945931095Z,2025-09-24T19:34:46.945798603Z,160,1,432669,C,A,64.820000000,1,26,8058566337229,128,18303,94288159,CLX5
2025-09-24T19:34:46.954074792Z,2025-09-24T19:34:46.953927791Z,160,1,432669,M,A,64.830000000,1,26,8058566331891,128,20139,94288161,CLX5
2025-09-24T19:34:50.047393611Z,2025-09-24T19:34:50.047105353Z,160,1,432669,C,B,64.810000000,1,26,8058566337228,128,15334,94288183,CLX5
2025-09-24T19:34:50.047574741Z,2025-09-24T19:34:50.047110171Z,160,1,432669,A,A,64.820000000,1,26,8058566337236,128,18618,94288189,CLX5
2025-09-24T19:34:50.048161769Z,2025-09-24T19:34:50.047496249Z,160,1,432669,C,B,64.770000000,2,26,8058566336922,128,13995,94288219,CLX5
2025-09-24T19:34:50.210537645Z,2025-09-24T19:34:50.210394037Z,160,1,432669,A,B,64.770000000,2,26,8058566337262,128,18914,94288267,CLX5
2025-09-24T19:34:50.577134576Z,2025-09-24T19:34:50.576966635Z,160,1,432669,A,A,64.820000000,1,26,8058566337265,128,19132,94288271,CLX5
2025-09-24T19:34:56.471840400Z,2025-09-24T19:34:56.471437373Z,160,1,432669,T,A,64.810000000,1,26,8058566337281,0,24242,94288314,CLX5
2025-09-24T19:34:56.471840400Z,2025-09-24T19:34:56.471437373Z,160,1,432669,F,B,64.810000000,1,26,8058566330881,0,24242,94288314,CLX5
2025-09-24T19:34:56.471855268Z,2025-09-24T19:34:56.471437373Z,160,1,432669,C,B,64.810000000,1,26,8058566330881,128,19623,94288315,CLX5
2025-09-24T19:34:56.471985330Z,2025-09-24T19:34:56.471804539Z,160,1,432669,C,B,64.810000000,1,26,8058566336898,128,19417,94288317,CLX5
