ts_recv,ts_event,rtype,publisher_id,instrument_id,action,side,price,size,channel_id,order_id,flags,ts_in_delta,sequence,symbol
2025-09-24T19:34:56.472064914Z,2025-09-24T19:34:56.471853995Z,160,1,432669,A,B,64.810000000,1,26,8058566337284,128,21405,94288320,CLX5
2025-09-24T19:34:56.472078799Z,2025-09-24T19:34:56.471875057Z,160,1,432669,C,B,64.810000000,1,26,8058566337284,128,18977,94288321,CLX5
2025-09-24T19:34:56.472204767Z,2025-09-24T19:34:56.472074401Z,160,1,432669,A,B,64.810000000,1,26,8058566337285,128,22438,94288323,CLX5
2025-09-24T19:34:56.472576536Z,2025-09-24T19:34:56.472447135Z,160,1,432669,C,B,64.770000000,2,26,8058566337262,128,22559,94288324,CLX5
2025-09-24T19:34:56.497449891Z,2025-09-24T19:34:56.497339143Z,160,1,432669,A,B,64.470000000,1,26,8058566337289,128,22412,94288329,CLX5
2025-09-24T19:34:56.610545544Z,2025-09-24T19:34:56.610404799Z,160,1,432669,A,B,64.770000000,2,26,8058566337292,128,20545,94288334,CLX5
2025-09-24T19:34:56.675752228Z,2025-09-24T19:34:56.675605411Z,160,1,432669,C,B,64.780000000,1,26,8058566336849,128,18369,94288336,CLX5
2025-09-24T19:34:59.614729922Z,2025-09-24T19:34:59.614050051Z,160,1,432669,T,A,64.810000000,17,26,8058566337308,0,18969,94288374,CLX5
2025-09-24T19:34:59.614729922Z,2025-09-24T19:34:59.614050051Z,160,1,432669,F,B,64.810000000,1,26,8058566331027,0,18969,94288374,CLX5
2025-09-24T19:34:59.614729922Z,2025-09-24T19:34:59.614050051Z,160,1,432669,F,B,64.810000000,2,26,8058566331113,0,18969,94288374,CLX5
2025-09-24T19:34:59.614729922Z,2025-09-24T19:34:59.614050051Z,160,1,432669,F,B,64.810000000,1,26,8058566331152,0,18969,94288374,CLX5
2025-09-24T19:34:59.614729922Z,2025-09-24T19:34:59.614050051Z,160,1,432669,F,B,64.810000000,1,26,8058566331247,0,18969,94288374,CLX5
2025-09-24T19:34:59.614729922Z,2025-09-24T19:34:59.614050051Z,160,1,432669,F,B,64.810000000,3,26,8058566331508,0,18969,94288374,CLX5
2025-09-24T19:34:59.614729922Z,2025-09-24T19:34:59.614050051Z,160,1,432669,F,B,64.810000000,1,26,8058566331010,0,18969,94288374,CLX5
2025-09-24T19:34:59.614729922Z,2025-09-24T19:34:59.614050051Z,160,1,432669,F,B,64.810000000,1,26,8058566332855,0,18969,94288374,CLX5
2025-09-24T19:34:59.614729922Z,2025-09-24T19:34:59.614050051Z,160,1,432669,F,B,64.810000000,1,26,8058566337285,0,18969,94288374,CLX5
2025-09-24T19:34:59.614729922Z,2025-09-24T19:34:59.614050051Z,160,1,432669,F,B,64.810000000,1,26,8058566331163,0,18969,94288374,CLX5
2025-09-24T19:34:59.614744743Z,2025-09-24T19:34:59.614050051Z,160,1,432669,C,B,64.810000000,1,26,8058566331027,0,16448,94288375,CLX5
2025-09-24T19:34:59.614744743Z,2025-09-24T19:34:59.614050051Z,160,1,432669,C,B,64.810000000,2,26,8058566331113,0,16448,94288375,CLX5
2025-09-24T19:34:59.614744743Z,2025-09-24T19:34:59.614050051Z,160,1,432669,C,B,64.810000000,1,26,8058566331152,0,16448,94288375,CLX5
2025-09-24T19:34:59.614744743Z,2025-09-24T19:34:59.614050051Z,160,1,432669,C,B,64.810000000,1,26,8058566331247,0,16448,94288375,CLX5
2025-09-24T19:34:59.614744743Z,2025-09-24T19:34:59.614050051Z,160,1,432669,C,B,64.810000000,3,26,8058566331508,0,16448,94288375,CLX5
2025-09-24T19:34:59.614744743Z,2025-09-24T19:34:59.614050051Z,160,1,432669,C,B,64.810000000,1,26,8058566331010,0,16448,94288375,CLX5
2025-09-24T19:34:59.614744743Z,2025-09-24T19:34:59.614050051Z,160,1,432669,C,B,64.810000000,1,26,8058566332855,0,16448,94288375,CLX5
2025-09-24T19:34:59.614744743Z,2025-09-24T19:34:59.614050051Z,160,1,432669,C,B,64.810000000,1,26,8058566337285,0,16448,94288375,CLX5
2025-09-24T19:34:59.614744743Z,2025-09-24T19:34:59.614050051Z,160,1,432669,C,B,64.810000000,1,26,8058566331163,128,16448,94288375,CLX5
2025-09-24T19:34:59.614950510Z,2025-09-24T19:34:59.614606347Z,160,1,432669,A,A,64.820000000,1,26,8058566337314,128,17175,94288386,CLX5
2025-09-24T19:34:59.615063500Z,2025-09-24T19:34:59.614685311Z,160,1,432669,A,A,64.820000000,1,26,8058566337315,128,15425,94288390,CLX5
2025-09-24T19:34:59.615127786Z,2025-09-24T19:34:59.614691803Z,160,1,432669,A,B,64.800000000,1,26,8058566337316,128,15228,94288392,CLX5
2025-09-24T19:34:59.615202693Z,2025-09-24T19:34:59.614729951Z,160,1,432669,A,A,64.820000000,2,26,8058566337318,128,14537,94288394,CLX5
2025-09-24T19:34:59.615364279Z,2025-09-24T19:34:59.614737169Z,160,1,432669,A,B,64.800000000,1,26,8058566337322,128,18006,94288400,CLX5
2025-09-24T19:34:59.615593054Z,2025-09-24T19:34:59.614748305Z,160,1,432669,A,B,64.800000000,1,26,8058566337327,128,15177,94288409,CLX5
2025-09-24T19:34:59.616372956Z,2025-09-24T19:34:59.614788893Z,160,1,432669,A,A,64.820000000,1,26,8058566337337,128,17002,94288440,CLX5
2025-09-24T19:34:59.616515696Z,2025-09-24T19:34:59.614828979Z,160,1,432669,M,A,64.820000000,1,26,8058566173085,128,15620,94288445,CLX5
2025-09-24T19:34:59.616577839Z,2025-09-24T19:34:59.614846777Z,160,1,432669,A,A,64.820000000,3,26,8058566337340,128,17343,94288447,CLX5
2025-09-24T19:34:59.617049068Z,2025-09-24T19:34:59.615142847Z,160,1,432669,C,B,64.770000000,2,26,8058566337292,128,18363,94288475,CLX5
2025-09-24T19:34:59.617276422Z,2025-09-24T19:34:59.615309841Z,160,1,432669,A,B,64.810000000,1,26,8058566337348,128,18263,94288485,CLX5
2025-09-24T19:34:59.618560067Z,2025-09-24T19:34:59.615674165Z,160,1,432669,C,B,64.800000000,2,26,8058566331915,128,23257,94288539,CLX5
2025-09-24T19:34:59.618607212Z,2025-09-24T19:34:59.615681807Z,160,1,432669,A,A,64.850000000,2,26,8058566337368,128,14700,94288541,CLX5
2025-09-24T19:34:59.619179818Z,2025-09-24T19:34:59.615979797Z,160,1,432669,M,B,64.460000000,10,26,8058566151203,128,14960,94288575,CLX5
2025-09-24T19:34:59.619260592Z,2025-09-24T19:34:59.616088805Z,160,1,432669,C,A,65.900000000,1,26,8058566331990,128,14706,94288583,CLX5
2025-09-24T19:34:59.619522535Z,2025-09-24T19:34:59.616171941Z,160,1,432669,C,A,64.820000000,1,26,8058566337315,128,18055,94288599,CLX5
2025-09-24T19:34:59.619705732Z,2025-09-24T19:34:59.616292019Z,160,1,432669,C,A,64.820000000,2,26,8058566337318,128,15780,94288611,CLX5
2025-09-24T19:34:59.619894842Z,2025-09-24T19:34:59.616354179Z,160,1,432669,C,B,64.810000000,1,26,8058566337348,128,15238,94288622,CLX5
2025-09-24T19:34:59.620644831Z,2025-09-24T19:34:59.617276545Z,160,1,432669,A,B,64.810000000,1,26,8058566337390,128,15205,94288669,CLX5
2025-09-24T19:34:59.620734184Z,2025-09-24T19:34:59.617279789Z,160,1,432669,C,B,64.800000000,1,26,8058566337322,128,14989,94288672,CLX5
2025-09-24T19:34:59.620820771Z,2025-09-24T19:34:59.617396887Z,160,1,432669,A,B,64.810000000,1,26,8058566337392,128,17010,94288676,CLX5
2025-09-24T19:34:59.621453378Z,2025-09-24T19:34:59.618107561Z,160,1,432669,C,A,64.850000000,2,26,8058566337368,128,14265,94288715,CLX5
2025-09-24T19:34:59.621578487Z,2025-09-24T19:34:59.618110345Z,160,1,432669,A,B,64.810000000,2,26,8058566337397,128,14576,94288719,CLX5
2025-09-24T19:34:59.621599828Z,2025-09-24T19:34:59.618110845Z,160,1,432669,A,B,64.810000000,2,26,8058566337398,128,14923,94288721,CLX5
2025-09-24T19:34:59.621761645Z,2025-09-24T19:34:59.618151507Z,160,1,432669,A,B,64.810000000,2,26,8058566337402,128,16886,94288727,CLX5
2025-09-24T19:34:59.621990190Z,2025-09-24T19:34:59.618310113Z,160,1,432669,A,B,64.810000000,1,26,8058566337404,128,18746,94288740,CLX5
2025-09-24T19:34:59.622631866Z,2025-09-24T19:34:59.618449231Z,160,1,432669,A,B,64.810000000,1,26,8058566337411,128,16503,94288767,CLX5
2025-09-24T19:34:59.623948364Z,2025-09-24T19:34:59.619468533Z,160,1,432669,M,A,64.830000000,1,26,8058566173085,128,15011,94288830,CLX5
2025-09-24T19:34:59.624128082Z,2025-09-24T19:34:59.619528223Z,160,1,432669,A,B,64.810000000,1,26,8058566337425,128,17452,94288839,CLX5
2025-09-24T19:34:59.624158601Z,2025-09-24T19:34:59.619533483Z,160,1,432669,A,B,64.810000000,1,26,8058566337426,128,15596,94288840,CLX5
2025-09-24T19:34:59.624570142Z,2025-09-24T19:34:59.619897671Z,160,1,432669,A,B,64.800000000,1,26,8058566337428,128,14922,94288865,CLX5
2025-09-24T19:34:59.624599578Z,2025-09-24T19:34:59.619899131Z,160,1,432669,A,B,64.800000000,2,26,8058566337429,128,14902,94288866,CLX5
2025-09-24T19:34:59.624631471Z,2025-09-24T19:34:59.619899309Z,160,1,432669,A,B,64.800000000,2,26,8058566337430,128,18303,94288867,CLX5
2025-09-24T19:34:59.625755281Z,2025-09-24T19:34:59.620647647Z,160,1,432669,A,B,64.810000000,3,26,8058566337434,128,19318,94288955,CLX5
2025-09-24T19:34:59.626673446Z,2025-09-24T19:34:59.621634427Z,160,1,432669,C,B,64.810000000,2,26,8058566337402,128,18522,94289009,CLX5
2025-09-24T19:34:59.627019171Z,2025-09-24T19:34:59.622067291Z,160,1,432669,A,B,64.810000000,1,26,8058566337448,128,15689,94289031,CLX5
2025-09-24T19:34:59.627484534Z,2025-09-24T19:34:59.622688959Z,160,1,432669,C,B,64.810000000,1,26,8058566337404,128,18043,94289055,CLX5
2025-09-24T19:34:59.627613982Z,2025-09-24T19:34:59.623408525Z,160,1,432669,M,A,64.820000000,1,26,8058566331891,128,18593,94289060,CLX5
2025-09-24T19:34:59.627643986Z,2025-09-24T19:34:59.623519515Z,160,1,432669,C,B,64.810000000,1,26,8058566337448,128,14975,94289061,CLX5
2025-09-24T19:34:59.627957159Z,2025-09-24T19:34:59.623826701Z,160,1,432669,A,B,64.810000000,1,26,8058566337458,128,15256,94289075,CLX5
2025-09-24T19:34:59.628022060Z,2025-09-24T19:34:59.624136403Z,160,1,432669,C,B,64.810000000,1,26,8058566337458,128,18764,94289077,CLX5
2025-09-24T19:34:59.629623317Z,2025-09-24T19:34:59.625768657Z,160,1,432669,C,A,64.820000000,1,26,8058566337337,128,19343,94289190,CLX5
2025-09-24T19:34:59.630876927Z,2025-09-24T19:34:59.627603481Z,160,1,432669,M,A,64.830000000,1,26,8058566331891,128,14282,94289270,CLX5
2025-09-24T19:34:59.631271290Z,2025-09-24T19:34:59.628087531Z,160,1,432669,C,B,64.810000000,1,26,8058566337426,128,17991,94289296,CLX5
2025-09-24T19:34:59.631303022Z,2025-09-24T19:34:59.628303443Z,160,1,432669,A,B,64.810000000,1,26,8058566337515,128,15121,94289297,CLX5
2025-09-24T19:34:59.632305063Z,2025-09-24T19:34:59.629632201Z,160,1,432669,C,B,64.810000000,1,26,8058566337515,128,18446,94289370,CLX5
2025-09-24T19:34:59.632404092Z,2025-09-24T19:34:59.630166549Z,160,1,432669,C,A,64.820000000,1,26,8058566337314,128,18009,94289376,CLX5
2025-09-24T19:34:59.632477071Z,2025-09-24T19:34:59.630289021Z,160,1,432669,A,B,64.810000000,1,26,8058566337533,128,15342,94289379,CLX5
2025-09-24T19:34:59.632798002Z,2025-09-24T19:34:59.630885097Z,160,1,432669,C,B,64.810000000,1,26,8058566337533,128,16481,94289396,CLX5
2025-09-24T19:34:59.647551806Z,2025-09-24T19:34:59.647409329Z,160,1,432669,A,B,64.800000000,2,26,8058566337562,128,15181,94289497,CLX5
2025-09-24T19:34:59.678808404Z,2025-09-24T19:34:59.678668813Z,160,1,432669,A,B,64.810000000,2,26,8058566337592,128,18828,94289553,CLX5
2025-09-24T19:34:59.716232386Z,2025-09-24T19:34:59.716128301Z,160,1,432669,A,A,65.900000000,1,26,8058566337606,128,18040,94289581,CLX5
2025-09-24T19:34:59.810950368Z,2025-09-24T19:34:59.810822401Z,160,1,432669,A,B,64.770000000,2,26,8058566337653,128,18519,94289675,CLX5
2025-09-24T19:35:00.525623280Z,2025-09-24T19:35:00.525468713Z,160,1,432669,C,A,64.830000000,1,26,8058566332889,128,18324,94289849,CLX5
2025-09-24T19:35:00.543618257Z,2025-09-24T19:35:00.543478401Z,160,1,432669,A,A,64.820000000,1,26,8058566337750,128,18897,94289856,CLX5
2025-09-24T19:35:00.700153260Z,2025-09-24T19:35:00.700008789Z,160,1,432669,C,B,64.810000000,1,26,8058566337392,128,19445,94289891,CLX5
2025-09-24T19:35:01.840742373Z,2025-09-24T19:35:01.840568197Z,160,1,432669,A,A,64.820000000,1,26,8058566337813,128,18151,94290018,CLX5
2025-09-24T19:35:02.649959506Z,2025-09-24T19:35:02.649784529Z,160,1,432669,A,B,64.810000000,1,26,8058566337821,128,26280,94290028,CLX5
2025-09-24T19:35:04.974321626Z,2025-09-24T19:35:04.974191647Z,160,1,432669,C,A,65.230000000,1,26,8058566285568,128,21796,94290039,CLX5
2025-09-24T19:35:05.017512216Z,2025-09-24T19:35:05.017238843Z,160,1,432669,A,B,64.810000000,1,26,8058566337834,128,19279,94290079,CLX5
2025-09-24T19:35:05.017650740Z,2025-09-24T19:35:05.017517683Z,160,1,432669,C,A,64.820000000,1,26,8058566335881,128,18392,94290084,CLX5
2025-09-24T19:35:05.068156846Z,2025-09-24T19:35:05.068045707Z,160,1,432669,A,A,65.150000000,1,26,8058566337859,128,19032,94290184,CLX5
2025-09-24T19:35:05.116164034Z,2025-09-24T19:35:05.116061293Z,160,1,432669,C,B,64.160000000,2,26,8058566336172,128,19108,94290198,CLX5
2025-09-24T19:35:08.011624996Z,2025-09-24T19:35:08.011474651Z,160,1,432669,C,B,64.810000000,1,26,8058566337834,128,18703,94290330,CLX5
2025-09-24T19:35:08.016149039Z,2025-09-24T19:35:08.016038099Z,160,1,432669,A,B,64.160000000,2,26,8058566337918,128,18003,94290331,CLX5
2025-09-24T19:35:08.207394897Z,2025-09-24T19:35:08.207162827Z,160,1,432669,A,A,64.820000000,1,26,8058566337921,128,14398,94290334,CLX5
2025-09-24T19:35:08.207481330Z,2025-09-24T19:35:08.207177535Z,160,1,432669,A,A,64.820000000,1,26,8058566337923,128,16545,94290337,CLX5
2025-09-24T19:35:08.207533175Z,2025-09-24T19:35:08.207177713Z,160,1,432669,C,B,64.810000000,2,26,8058566337592,128,15165,94290339,CLX5
2025-09-24T19:35:08.207568839Z,2025-09-24T19:35:08.207178285Z,160,1,432669,C,B,64.770000000,2,26,8058566337653,128,18708,94290340,CLX5
2025-09-24T19:35:08.207597146Z,2025-09-24T19:35:08.207178669Z,160,1,432669,C,B,64.810000000,1,26,8058566337411,128,15637,94290341,CLX5
2025-09-24T19:35:08.207890952Z,2025-09-24T19:35:08.207401051Z,160,1,432669,C,A,64.820000000,1,26,8058566337921,128,14164,94290352,CLX5
2025-09-24T19:35:08.208002998Z,2025-09-24T19:35:08.207442521Z,160,1,432669,C,A,64.820000000,1,26,8058566337923,128,15022,94290356,CLX5
2025-09-24T19:35:08.208256340Z,2025-09-24T19:35:08.207607519Z,160,1,432669,A,B,64.810000000,1,26,8058566337930,128,14311,94290362,CLX5
2025-09-24T19:35:08.275966610Z,2025-09-24T19:35:08.275749231Z,160,1,432669,C,B,64.800000000,2,26,8058566337562,128,14807,94290471,CLX5
2025-09-24T19:35:08.276003833Z,2025-09-24T19:35:08.275749557Z,160,1,432669,A,A,64.820000000,1,26,8058566337963,128,15205,94290472,CLX5
2025-09-24T19:35:08.276042246Z,2025-09-24T19:35:08.275754837Z,160,1,432669,A,A,64.820000000,1,26,8058566337964,128,19172,94290474,CLX5
2025-09-24T19:35:08.276072013Z,2025-09-24T19:35:08.275757641Z,160,1,432669,C,B,64.810000000,1,26,8058566337930,128,14860,94290475,CLX5
2025-09-24T19:35:08.276330354Z,2025-09-24T19:35:08.276059161Z,160,1,432669,A,A,64.820000000,1,26,8058566337966,128,16988,94290486,CLX5
2025-09-24T19:35:08.276428261Z,2025-09-24T19:35:08.276139127Z,160,1,432669,C,A,64.820000000,1,26,8058566337964,128,17843,94290489,CLX5
2025-09-24T19:35:08.276931283Z,2025-09-24T19:35:08.276401619Z,160,1,432669,C,A,64.820000000,1,26,8058566337963,128,15240,94290519,CLX5
2025-09-24T19:35:08.310959744Z,2025-09-24T19:35:08.310824221Z,160,1,432669,A,B,64.780000000,2,26,8058566337984,128,18401,94290548,CLX5
2025-09-24T19:35:08.321992852Z,2025-09-24T19:35:08.321893205Z,160,1,432669,C,B,64.540000000,8,26,8058566321866,128,18102,94290554,CLX5
2025-09-24T19:35:08.410629159Z,2025-09-24T19:35:08.410491557Z,160,1,432669,A,B,64.770000000,2,26,8058566337995,128,18891,94290582,CLX5
2025-09-24T19:35:08.496608004Z,2025-09-24T19:35:08.495841221Z,160,1,432669,T,A,64.810000000,15,26,8058566338000,0,20016,94290590,CLX5
2025-09-24T19:35:08.496608004Z,2025-09-24T19:35:08.495841221Z,160,1,432669,F,B,64.810000000,1,26,8058566337390,0,20016,94290590,CLX5
2025-09-24T19:35:08.496608004Z,2025-09-24T19:35:08.495841221Z,160,1,432669,F,B,64.810000000,2,26,8058566337397,0,20016,94290590,CLX5
2025-09-24T19:35:08.496608004Z,2025-09-24T19:35:08.495841221Z,160,1,432669,F,B,64.810000000,2,26,8058566337398,0,20016,94290590,CLX5
2025-09-24T19:35:08.496608004Z,2025-09-24T19:35:08.495841221Z,160,1,432669,F,B,64.810000000,1,26,8058566337425,0,20016,94290590,CLX5
2025-09-24T19:35:08.496608004Z,2025-09-24T19:35:08.495841221Z,160,1,432669,F,B,64.810000000,3,26,8058566337434,0,20016,94290590,CLX5
2025-09-24T19:35:08.496608004Z,2025-09-24T19:35:08.495841221Z,160,1,432669,F,B,64.810000000,1,26,8058566337821,0,20016,94290590,CLX5
2025-09-24T19:35:08.496746613Z,2025-09-24T19:35:08.495841221Z,160,1,432669,C,B,64.810000000,1,26,8058566337390,0,20318,94290591,CLX5
2025-09-24T19:35:08.496746613Z,2025-09-24T19:35:08.495841221Z,160,1,432669,C,B,64.810000000,2,26,8058566337397,0,20318,94290591,CLX5
2025-09-24T19:35:08.496746613Z,2025-09-24T19:35:08.495841221Z,160,1,432669,C,B,64.810000000,2,26,8058566337398,0,20318,94290591,CLX5
2025-09-24T19:35:08.496746613Z,2025-09-24T19:35:08.495841221Z,160,1,432669,C,B,64.810000000,1,26,8058566337425,0,20318,94290591,CLX5
2025-09-24T19:35:08.496746613Z,2025-09-24T19:35:08.495841221Z,160,1,432669,C,B,64.810000000,3,26,8058566337434,0,20318,94290591,CLX5
2025-09-24T19:35:08.496746613Z,2025-09-24T19:35:08.495841221Z,160,1,432669,C,B,64.810000000,1,26,8058566337821,0,20318,94290591,CLX5
2025-09-24T19:35:08.496746613Z,2025-09-24T19:35:08.495841221Z,160,1,432669,A,A,64.810000000,15,26,8058566338000,128,20318,94290591,CLX5
2025-09-24T19:35:08.496843468Z,2025-09-24T19:35:08.496367545Z,160,1,432669,A,A,64.820000000,1,26,8058566338002,128,18989,94290601,CLX5
2025-09-24T19:35:08.496875769Z,2025-09-24T19:35:08.496376089Z,160,1,432669,A,A,64.820000000,1,26,8058566338004,128,15574,94290603,CLX5
2025-09-24T19:35:08.497079754Z,2025-09-24T19:35:08.496454269Z,160,1,432669,C,B,64.800000000,1,26,8058566337327,128,16561,94290611,CLX5
2025-09-24T19:35:08.497398449Z,2025-09-24T19:35:08.496614427Z,160,1,432669,A,A,64.820000000,1,26,8058566338016,128,14316,94290629,CLX5
2025-09-24T19:35:08.497704274Z,2025-09-24T19:35:08.496629037Z,160,1,432669,C,B,64.800000000,1,26,8058566337428,128,18631,94290642,CLX5
2025-09-24T19:35:08.497812902Z,2025-09-24T19:35:08.496631611Z,160,1,432669,A,A,64.820000000,2,26,8058566338023,128,18826,94290646,CLX5
2025-09-24T19:35:08.497988166Z,2025-09-24T19:35:08.496709981Z,160,1,432669,A,A,64.810000000,2,26,8058566338026,128,15160,94290656,CLX5
2025-09-24T19:35:08.498043467Z,2025-09-24T19:35:08.496757807Z,160,1,432669,A,B,64.800000000,1,26,8058566338030,128,15007,94290660,CLX5
2025-09-24T19:35:08.498144123Z,2025-09-24T19:35:08.496772647Z,160,1,432669,A,A,64.810000000,1,26,8058566338032,128,15346,94290664,CLX5
2025-09-24T19:35:08.498249687Z,2025-09-24T19:35:08.496783437Z,160,1,432669,A,A,64.810000000,1,26,8058566338033,128,15335,94290667,CLX5
2025-09-24T19:35:08.498427362Z,2025-09-24T19:35:08.496812177Z,160,1,432669,A,A,64.810000000,1,26,8058566338036,128,18634,94290674,CLX5
2025-09-24T19:35:08.498827653Z,2025-09-24T19:35:08.496996049Z,160,1,432669,C,A,64.810000000,1,26,8058566338033,128,15468,94290691,CLX5
2025-09-24T19:35:08.499051975Z,2025-09-24T19:35:08.497034197Z,160,1,432669,M,A,64.830000000,3,26,8058566321460,128,14808,94290704,CLX5
2025-09-24T19:35:08.499229427Z,2025-09-24T19:35:08.497136433Z,160,1,432669,C,A,64.820000000,2,26,8058566335960,128,15037,94290710,CLX5
2025-09-24T19:35:08.499257288Z,2025-09-24T19:35:08.497138181Z,160,1,432669,C,A,64.820000000,1,26,8058566337265,128,15175,94290711,CLX5
2025-09-24T19:35:08.500063277Z,2025-09-24T19:35:08.497327389Z,160,1,432669,C,A,64.840000000,4,26,8058566282798,128,15098,94290756,CLX5
2025-09-24T19:35:08.500261511Z,2025-09-24T19:35:08.497436171Z,160,1,432669,C,B,64.800000000,2,26,8058566337430,128,18659,94290765,CLX5
2025-09-24T19:35:08.500570185Z,2025-09-24T19:35:08.497469061Z,160,1,432669,C,B,64.780000000,1,26,8058566331393,128,14888,94290779,CLX5
2025-09-24T19:35:08.501103778Z,2025-09-24T19:35:08.497778933Z,160,1,432669,C,B,64.770000000,2,26,8058566337995,128,19341,94290805,CLX5
2025-09-24T19:35:08.501330449Z,2025-09-24T19:35:08.497819983Z,160,1,432669,C,B,64.800000000,2,26,8058566337429,128,14197,94290818,CLX5
2025-09-24T19:35:08.501482605Z,2025-09-24T19:35:08.497845073Z,160,1,432669,A,A,64.850000000,2,26,8058566338063,128,14706,94290827,CLX5
2025-09-24T19:35:08.502473895Z,2025-09-24T19:35:08.498467011Z,160,1,432669,A,A,64.810000000,1,26,8058566338085,128,15219,94290882,CLX5
2025-09-24T19:35:08.503284776Z,2025-09-24T19:35:08.499266617Z,160,1,432669,A,A,64.820000000,1,26,8058566338093,128,13961,94290919,CLX5
2025-09-24T19:35:08.503329064Z,2025-09-24T19:35:08.499304459Z,160,1,432669,A,A,64.820000000,1,26,8058566338095,128,18355,94290921,CLX5
2025-09-24T19:35:08.503486734Z,2025-09-24T19:35:08.499559173Z,160,1,432669,M,A,64.930000000,1,26,8058565075241,128,14198,94290934,CLX5
2025-09-24T19:35:08.503755666Z,2025-09-24T19:35:08.499885559Z,160,1,432669,M,B,64.790000000,4,26,8058566335785,128,15097,94290947,CLX5
2025-09-24T19:35:08.503811704Z,2025-09-24T19:35:08.499955771Z,160,1,432669,T,B,64.810000000,1,26,8058566338099,0,14462,94290952,CLX5
2025-09-24T19:35:08.503811704Z,2025-09-24T19:35:08.499955771Z,160,1,432669,F,A,64.810000000,1,26,8058566338000,0,14462,94290952,CLX5
2025-09-24T19:35:08.503842430Z,2025-09-24T19:35:08.499955771Z,160,1,432669,M,A,64.810000000,14,26,8058566338000,128,15196,94290953,CLX5
2025-09-24T19:35:08.506392432Z,2025-09-24T19:35:08.502548309Z,160,1,432669,M,A,64.940000000,1,26,8058565075241,128,14709,94291095,CLX5
2025-09-24T19:35:08.507242087Z,2025-09-24T19:35:08.503459731Z,160,1,432669,M,A,64.930000000,1,26,8058565075241,128,14692,94291136,CLX5
2025-09-24T19:35:08.507765168Z,2025-09-24T19:35:08.504099639Z,160,1,432669,C,A,64.810000000,1,26,8058566338085,128,18782,94291167,CLX5
2025-09-24T19:35:08.507921133Z,2025-09-24T19:35:08.504293859Z,160,1,432669,A,A,64.810000000,1,26,8058566338157,128,15009,94291175,CLX5
2025-09-24T19:35:08.508158847Z,2025-09-24T19:35:08.504885539Z,160,1,432669,M,A,64.820000000,1,26,8058566331891,128,18209,94291191,CLX5
2025-09-24T19:35:08.508396907Z,2025-09-24T19:35:08.505224903Z,160,1,432669,C,A,64.810000000,1,26,8058566338157,128,17340,94291202,CLX5
2025-09-24T19:35:08.508712976Z,2025-09-24T19:35:08.505732719Z,160,1,432669,A,A,64.810000000,1,26,8058566338171,128,15076,94291224,CLX5
2025-09-24T19:35:08.509180065Z,2025-09-24T19:35:08.506408435Z,160,1,432669,C,A,64.810000000,1,26,8058566338171,128,18158,94291258,CLX5
2025-09-24T19:35:08.510240141Z,2025-09-24T19:35:08.509609413Z,160,1,432669,C,B,64.800000000,1,26,8058566338030,128,15686,94291326,CLX5
2025-09-24T19:35:08.510349506Z,2025-09-24T19:35:08.509648829Z,160,1,432669,C,A,64.820000000,1,26,8058566338095,128,15099,94291330,CLX5
2025-09-24T19:35:08.510402511Z,2025-09-24T19:35:08.509662671Z,160,1,432669,C,A,64.820000000,1,26,8058566338093,128,17314,94291332,CLX5
2025-09-24T19:35:08.510663156Z,2025-09-24T19:35:08.510550709Z,160,1,432669,C,A,64.870000000,2,26,8058566331963,128,14574,94291350,CLX5
2025-09-24T19:35:08.511630939Z,2025-09-24T19:35:08.511537699Z,160,1,432669,M,A,64.940000000,1,26,8058565075241,128,17597,94291357,CLX5
2025-09-24T19:35:08.516512367Z,2025-09-24T19:35:08.516113529Z,160,1,432669,C,A,65.900000000,1,26,8058566337606,128,14612,94291467,CLX5
2025-09-24T19:35:08.516526436Z,2025-09-24T19:35:08.516156323Z,160,1,432669,C,A,65.700000000,6,26,8058566287517,128,14630,94291468,CLX5
2025-09-24T19:35:08.547514814Z,2025-09-24T19:35:08.547368869Z,160,1,432669,A,A,64.810000000,2,26,8058566338260,128,18438,94291541,CLX5
2025-09-24T19:35:08.547541946Z,2025-09-24T19:35:08.547371863Z,160,1,432669,A,A,64.810000000,1,26,8058566338261,128,14917,94291542,CLX5
2025-09-24T19:35:08.579476198Z,2025-09-24T19:35:08.579332559Z,160,1,432669,C,A,64.820000000,1,26,8058566336044,128,18366,94291642,CLX5
2025-09-24T19:35:08.579995546Z,2025-09-24T19:35:08.579865661Z,160,1,432669,A,A,64.810000000,1,26,8058566338293,128,18334,94291643,CLX5
2025-09-24T19:35:08.581348184Z,2025-09-24T19:35:08.581212579Z,160,1,432669,M,A,64.930000000,1,26,8058565075241,128,13693,94291680,CLX5
2025-09-24T19:35:08.584303716Z,2025-09-24T19:35:08.584185529Z,160,1,432669,M,A,64.940000000,1,26,8058565075241,128,14553,94291772,CLX5
2025-09-24T19:35:08.609327121Z,2025-09-24T19:35:08.608984289Z,160,1,432669,T,B,64.810000000,3,26,8058566338375,0,18068,94291921,CLX5
2025-09-24T19:35:08.609327121Z,2025-09-24T19:35:08.608984289Z,160,1,432669,F,A,64.810000000,3,26,8058566338000,0,18068,94291921,CLX5
2025-09-24T19:35:08.609425220Z,2025-09-24T19:35:08.608984289Z,160,1,432669,M,A,64.810000000,11,26,8058566338000,128,19214,94291922,CLX5
2025-09-24T19:35:08.609478632Z,2025-09-24T19:35:08.609023741Z,160,1,432669,T,B,64.810000000,1,26,8058566338377,0,14385,94291925,CLX5
2025-09-24T19:35:08.609478632Z,2025-09-24T19:35:08.609023741Z,160,1,432669,F,A,64.810000000,1,26,8058566338000,0,14385,94291925,CLX5
2025-09-24T19:35:08.609478632Z,2025-09-24T19:35:08.609023741Z,160,1,432669,M,A,64.810000000,10,26,8058566338000,128,14385,94291925,CLX5
2025-09-24T19:35:08.609656284Z,2025-09-24T19:35:08.609338819Z,160,1,432669,M,A,64.930000000,1,26,8058565075241,128,14246,94291935,CLX5
2025-09-24T19:35:08.609976147Z,2025-09-24T19:35:08.609489685Z,160,1,432669,T,B,64.810000000,15,26,8058566338384,0,17378,94291947,CLX5
2025-09-24T19:35:08.609976147Z,2025-09-24T19:35:08.609489685Z,160,1,432669,F,A,64.810000000,10,26,8058566338000,0,17378,94291947,CLX5
2025-09-24T19:35:08.609976147Z,2025-09-24T19:35:08.609489685Z,160,1,432669,F,A,64.810000000,2,26,8058566338026,0,17378,94291947,CLX5
2025-09-24T19:35:08.609976147Z,2025-09-24T19:35:08.609489685Z,160,1,432669,F,A,64.810000000,1,26,8058566338032,0,17378,94291947,CLX5
2025-09-24T19:35:08.609976147Z,2025-09-24T19:35:08.609489685Z,160,1,432669,F,A,64.810000000,1,26,8058566338036,0,17378,94291947,CLX5
2025-09-24T19:35:08.609976147Z,2025-09-24T19:35:08.609489685Z,160,1,432669,F,A,64.810000000,1,26,8058566338260,0,17378,94291947,CLX5
2025-09-24T19:35:08.609985861Z,2025-09-24T19:35:08.609489685Z,160,1,432669,C,A,64.810000000,10,26,8058566338000,0,14553,94291948,CLX5
2025-09-24T19:35:08.609985861Z,2025-09-24T19:35:08.609489685Z,160,1,432669,C,A,64.810000000,2,26,8058566338026,0,14553,94291948,CLX5
2025-09-24T19:35:08.609985861Z,2025-09-24T19:35:08.609489685Z,160,1,432669,C,A,64.810000000,1,26,8058566338032,0,14553,94291948,CLX5
2025-09-24T19:35:08.609985861Z,2025-09-24T19:35:08.609489685Z,160,1,432669,C,A,64.810000000,1,26,8058566338036,0,14553,94291948,CLX5
2025-09-24T19:35:08.609985861Z,2025-09-24T19:35:08.609489685Z,160,1,432669,M,A,64.810000000,1,26,8058566338260,128,14553,94291948,CLX5
2025-09-24T19:35:08.610036025Z,2025-09-24T19:35:08.609494641Z,160,1,432669,T,B,64.810000000,3,26,8058566338385,0,18591,94291949,CLX5
2025-09-24T19:35:08.610036025Z,2025-09-24T19:35:08.609494641Z,160,1,432669,F,A,64.810000000,1,26,8058566338260,0,18591,94291949,CLX5
2025-09-24T19:35:08.610036025Z,2025-09-24T19:35:08.609494641Z,160,1,432669,F,A,64.810000000,1,26,8058566338261,0,18591,94291949,CLX5
2025-09-24T19:35:08.610036025Z,2025-09-24T19:35:08.609494641Z,160,1,432669,F,A,64.810000000,1,26,8058566338293,0,18591,94291949,CLX5
2025-09-24T19:35:08.610043597Z,2025-09-24T19:35:08.609494641Z,160,1,432669,C,A,64.810000000,1,26,8058566338260,0,14807,94291950,CLX5
2025-09-24T19:35:08.610043597Z,2025-09-24T19:35:08.609494641Z,160,1,432669,C,A,64.810000000,1,26,8058566338261,0,14807,94291950,CLX5
2025-09-24T19:35:08.610043597Z,2025-09-24T19:35:08.609494641Z,160,1,432669,C,A,64.810000000,1,26,8058566338293,128,14807,94291950,CLX5
2025-09-24T19:35:08.610364327Z,2025-09-24T19:35:08.609922077Z,160,1,432669,A,B,64.800000000,1,26,8058566338390,128,15058,94291965,CLX5
2025-09-24T19:35:08.610589816Z,2025-09-24T19:35:08.609926907Z,160,1,432669,A,B,64.800000000,1,26,8058566338394,128,14775,94291973,CLX5
2025-09-24T19:35:08.610712490Z,2025-09-24T19:35:08.609976175Z,160,1,432669,A,B,64.800000000,1,26,8058566338398,128,14883,94291978,CLX5
2025-09-24T19:35:08.611277447Z,2025-09-24T19:35:08.609978891Z,160,1,432669,A,B,64.800000000,1,26,8058566338409,128,16100,94292006,CLX5
2025-09-24T19:35:08.611333700Z,2025-09-24T19:35:08.609979065Z,160,1,432669,A,A,64.810000000,1,26,8058566338410,128,14730,94292007,CLX5
2025-09-24T19:35:08.611386282Z,2025-09-24T19:35:08.609979247Z,160,1,432669,A,A,64.810000000,1,26,8058566338411,128,17816,94292010,CLX5
2025-09-24T19:35:08.611869859Z,2025-09-24T19:35:08.610071919Z,160,1,432669,A,A,64.810000000,1,26,8058566338426,128,14551,94292032,CLX5
2025-09-24T19:35:08.612040323Z,2025-09-24T19:35:08.610237013Z,160,1,432669,C,B,64.800000000,1,26,8058566338394,128,14927,94292044,CLX5
2025-09-24T19:35:08.612149634Z,2025-09-24T19:35:08.610299103Z,160,1,432669,M,A,64.840000000,4,26,8058566282770,128,14545,94292050,CLX5
2025-09-24T19:35:08.612270710Z,2025-09-24T19:35:08.610437029Z,160,1,432669,A,A,64.810000000,2,26,8058566338435,128,14955,94292053,CLX5
2025-09-24T19:35:08.612436267Z,2025-09-24T19:35:08.610551475Z,160,1,432669,A,B,64.780000000,1,26,8058566338439,128,13563,94292062,CLX5
2025-09-24T19:35:08.613055074Z,2025-09-24T19:35:08.610706913Z,160,1,432669,T,B,64.810000000,2,26,8058566338453,0,14950,94292086,CLX5
2025-09-24T19:35:08.613055074Z,2025-09-24T19:35:08.610706913Z,160,1,432669,F,A,64.810000000,1,26,8058566338410,0,14950,94292086,CLX5
2025-09-24T19:35:08.613055074Z,2025-09-24T19:35:08.610706913Z,160,1,432669,F,A,64.810000000,1,26,8058566338411,0,14950,94292086,CLX5
2025-09-24T19:35:08.613100914Z,2025-09-24T19:35:08.610706913Z,160,1,432669,C,A,64.810000000,1,26,8058566338410,0,18190,94292087,CLX5
2025-09-24T19:35:08.613100914Z,2025-09-24T19:35:08.610706913Z,160,1,432669,C,A,64.810000000,1,26,8058566338411,128,18190,94292087,CLX5
2025-09-24T19:35:08.613456847Z,2025-09-24T19:35:08.610856339Z,160,1,432669,C,A,64.810000000,2,26,8058566338435,128,17977,94292102,CLX5
2025-09-24T19:35:08.614311832Z,2025-09-24T19:35:08.611412155Z,160,1,432669,C,B,64.800000000,1,26,8058566338398,128,14926,94292133,CLX5
2025-09-24T19:35:08.614698891Z,2025-09-24T19:35:08.611697763Z,160,1,432669,C,A,64.810000000,1,26,8058566338426,128,14927,94292148,CLX5
2025-09-24T19:35:08.614824637Z,2025-09-24T19:35:08.611782027Z,160,1,432669,A,B,64.800000000,1,26,8058566338483,128,14904,94292154,CLX5
2025-09-24T19:35:08.614890006Z,2025-09-24T19:35:08.611845883Z,160,1,432669,C,A,64.840000000,4,26,8058566282770,128,14472,94292156,CLX5
2025-09-24T19:35:08.615061276Z,2025-09-24T19:35:08.612091977Z,160,1,432669,A,B,64.800000000,1,26,8058566338488,128,14759,94292163,CLX5
2025-09-24T19:35:08.615198810Z,2025-09-24T19:35:08.612214389Z,160,1,432669,A,B,64.810000000,2,26,8058566338492,128,17939,94292168,CLX5
2025-09-24T19:35:08.616023369Z,2025-09-24T19:35:08.613837047Z,160,1,432669,C,B,64.800000000,1,26,8058566338483,128,17300,94292209,CLX5
2025-09-24T19:35:08.616162039Z,2025-09-24T19:35:08.614223275Z,160,1,432669,A,B,64.800000000,1,26,8058566338508,128,14793,94292217,CLX5
2025-09-24T19:35:08.616248703Z,2025-09-24T19:35:08.614465627Z,160,1,432669,C,B,64.800000000,1,26,8058566338508,128,18264,94292220,CLX5
2025-09-24T19:35:08.616761708Z,2025-09-24T19:35:08.615147695Z,160,1,432669,M,A,64.840000000,4,26,8058566331102,128,15372,94292251,CLX5
2025-09-24T19:35:08.617207532Z,2025-09-24T19:35:08.615446109Z,160,1,432669,M,A,65.970000000,4,26,8058566321460,128,13868,94292276,CLX5
2025-09-24T19:35:08.617606179Z,2025-09-24T19:35:08.616207047Z,160,1,432669,A,A,65.700000000,6,26,8058566338533,128,14967,94292301,CLX5
2025-09-24T19:35:08.619828793Z,2025-09-24T19:35:08.618817001Z,160,1,432669,C,B,64.810000000,2,26,8058566338492,128,15269,94292431,CLX5
2025-09-24T19:35:08.620219876Z,2025-09-24T19:35:08.619149783Z,160,1,432669,A,A,64.810000000,1,26,8058566338579,128,16634,94292451,CLX5
2025-09-24T19:35:08.620269794Z,2025-09-24T19:35:08.619149971Z,160,1,432669,A,A,64.810000000,1,26,8058566338580,128,14518,94292455,CLX5
2025-09-24T19:35:08.621413700Z,2025-09-24T19:35:08.620221647Z,160,1,432669,A,A,64.810000000,1,26,8058566338600,128,14574,94292520,CLX5
2025-09-24T19:35:08.621438006Z,2025-09-24T19:35:08.620223069Z,160,1,432669,C,B,64.800000000,1,26,8058566338409,128,17432,94292522,CLX5
2025-09-24T19:35:08.621464102Z,2025-09-24T19:35:08.620223837Z,160,1,432669,M,A,64.940000000,1,26,8058565075241,128,14334,94292524,CLX5
2025-09-24T19:35:08.621704242Z,2025-09-24T19:35:08.620416173Z,160,1,432669,M,A,65.960000000,3,26,8058566331102,128,15118,94292535,CLX5
2025-09-24T19:35:08.621803256Z,2025-09-24T19:35:08.620593421Z,160,1,432669,M,A,64.830000000,3,26,8058566331622,128,14932,94292542,CLX5
2025-09-24T19:35:08.622485895Z,2025-09-24T19:35:08.621229239Z,160,1,432669,C,A,64.810000000,1,26,8058566338600,128,18499,94292577,CLX5
2025-09-24T19:35:08.626318359Z,2025-09-24T19:35:08.626224243Z,160,1,432669,A,A,65.950000000,3,26,8058566338645,128,17602,94292665,CLX5
2025-09-24T19:35:08.644675552Z,2025-09-24T19:35:08.644528295Z,160,1,432669,C,A,64.820000000,1,26,8058566337750,128,18142,94292693,CLX5
2025-09-24T19:35:08.662150866Z,2025-09-24T19:35:08.661943749Z,160,1,432669,A,A,64.820000000,1,26,8058566338676,128,18445,94292714,CLX5
2025-09-24T19:35:08.716292154Z,2025-09-24T19:35:08.716201383Z,160,1,432669,C,A,65.700000000,6,26,8058566338533,128,14143,94292812,CLX5
2025-09-24T19:35:08.811019053Z,2025-09-24T19:35:08.810885865Z,160,1,432669,A,B,64.760000000,2,26,8058566338861,128,18562,94293033,CLX5
2025-09-24T19:35:08.832064656Z,2025-09-24T19:35:08.831931151Z,160,1,432669,A,B,64.780000000,1,26,8058566338864,128,18756,94293043,CLX5
2025-09-24T19:35:09.938194128Z,2025-09-24T19:35:09.938053427Z,160,1,432669,A,B,64.780000000,1,26,8058566338999,128,18535,94293314,CLX5
2025-09-24T19:35:12.469546479Z,2025-09-24T19:35:12.469384201Z,160,1,432669,C,A,64.820000000,1,26,8058566336693,128,18568,94293619,CLX5
2025-09-24T19:35:12.469707605Z,2025-09-24T19:35:12.469555015Z,160,1,432669,C,A,64.810000000,1,26,8058566338580,128,18188,94293620,CLX5
2025-09-24T19:35:12.469899610Z,2025-09-24T19:35:12.469722663Z,160,1,432669,C,A,64.810000000,1,26,8058566338579,128,14823,94293626,CLX5
2025-09-24T19:35:12.470036683Z,2025-09-24T19:35:12.469903057Z,160,1,432669,A,B,64.800000000,1,26,8058566339145,128,18260,94293630,CLX5
2025-09-24T19:35:12.470556284Z,2025-09-24T19:35:12.470334251Z,160,1,432669,A,B,64.810000000,1,26,8058566339150,128,16266,94293642,CLX5
2025-09-24T19:35:12.470696069Z,2025-09-24T19:35:12.470383499Z,160,1,432669,A,B,64.800000000,2,26,8058566339151,128,15021,94293648,CLX5
2025-09-24T19:35:12.470986266Z,2025-09-24T19:35:12.470465575Z,160,1,432669,C,A,64.820000000,1,26,8058566338016,128,15779,94293660,CLX5
2025-09-24T19:35:12.471478097Z,2025-09-24T19:35:12.470559477Z,160,1,432669,C,B,64.800000000,1,26,8058566339145,128,17496,94293686,CLX5
2025-09-24T19:35:12.471883634Z,2025-09-24T19:35:12.470759053Z,160,1,432669,C,B,64.810000000,1,26,8058566339150,128,14934,94293707,CLX5
2025-09-24T19:35:12.472085147Z,2025-09-24T19:35:12.470804325Z,160,1,432669,A,B,64.810000000,1,26,8058566339168,128,14668,94293714,CLX5
2025-09-24T19:35:12.472445473Z,2025-09-24T19:35:12.470936203Z,160,1,432669,M,A,65.980000000,4,26,8058566331622,128,17612,94293731,CLX5
2025-09-24T19:35:12.473367440Z,2025-09-24T19:35:12.471252547Z,160,1,432669,C,B,64.810000000,1,26,8058566339168,128,14793,94293788,CLX5
2025-09-24T19:35:12.474017394Z,2025-09-24T19:35:12.471510353Z,160,1,432669,A,B,64.800000000,1,26,8058566339196,128,14682,94293819,CLX5
2025-09-24T19:35:12.474291027Z,2025-09-24T19:35:12.471915611Z,160,1,432669,C,B,64.800000000,1,26,8058566339196,128,18383,94293833,CLX5
2025-09-24T19:35:12.474787889Z,2025-09-24T19:35:12.473370445Z,160,1,432669,A,B,64.800000000,1,26,8058566339205,128,17500,94293865,CLX5
2025-09-24T19:35:12.475234104Z,2025-09-24T19:35:12.473512517Z,160,1,432669,C,B,64.800000000,1,26,8058566339205,128,15072,94293885,CLX5
2025-09-24T19:35:12.475293728Z,2025-09-24T19:35:12.473614619Z,160,1,432669,M,A,64.840000000,4,26,8058566321460,128,14625,94293888,CLX5
2025-09-24T19:35:12.505589300Z,2025-09-24T19:35:12.505494025Z,160,1,432669,M,A,64.930000000,1,26,8058565075241,128,17686,94294038,CLX5
2025-09-24T19:35:12.507574054Z,2025-09-24T19:35:12.507475935Z,160,1,432669,M,A,64.940000000,1,26,8058565075241,128,17790,94294062,CLX5
2025-09-24T19:35:12.516331359Z,2025-09-24T19:35:12.516226949Z,160,1,432669,A,A,65.700000000,6,26,8058566339267,128,18127,94294092,CLX5
2025-09-24T19:35:14.427005179Z,2025-09-24T19:35:14.426758613Z,160,1,432669,A,B,64.810000000,1,26,8058566339421,128,18584,94294428,CLX5
2025-09-24T19:35:14.427541714Z,2025-09-24T19:35:14.427411153Z,160,1,432669,C,A,64.820000000,2,26,8058566338023,128,19039,94294438,CLX5
2025-09-24T19:35:14.479975833Z,2025-09-24T19:35:14.479709301Z,160,1,432669,T,A,64.810000000,1,26,8058566339432,0,19312,94294467,CLX5
2025-09-24T19:35:14.479975833Z,2025-09-24T19:35:14.479709301Z,160,1,432669,F,B,64.810000000,1,26,8058566339421,0,19312,94294467,CLX5
2025-09-24T19:35:14.479984879Z,2025-09-24T19:35:14.479709301Z,160,1,432669,C,B,64.810000000,1,26,8058566339421,128,14528,94294468,CLX5
2025-09-24T19:35:14.480109382Z,2025-09-24T19:35:14.479975997Z,160,1,432669,A,A,64.820000000,2,26,8058566339433,128,18160,94294471,CLX5
2025-09-24T19:35:14.480182230Z,2025-09-24T19:35:14.479983117Z,160,1,432669,A,A,64.820000000,1,26,8058566339434,128,14957,94294475,CLX5
2025-09-24T19:35:14.480342780Z,2025-09-24T19:35:14.480146963Z,160,1,432669,A,A,64.820000000,1,26,8058566339438,128,15200,94294483,CLX5
2025-09-24T19:35:14.480371678Z,2025-09-24T19:35:14.480185515Z,160,1,432669,C,A,64.820000000,1,26,8058566339434,128,14916,94294484,CLX5
2025-09-24T19:35:14.480400960Z,2025-09-24T19:35:14.480218557Z,160,1,432669,A,A,64.820000000,1,26,8058566339439,128,15124,94294485,CLX5
2025-09-24T19:35:14.480496210Z,2025-09-24T19:35:14.480381173Z,160,1,432669,A,A,64.820000000,1,26,8058566339440,128,18153,94294486,CLX5
2025-09-24T19:35:14.515241496Z,2025-09-24T19:35:14.515089153Z,160,1,432669,A,A,64.820000000,1,26,8058566339448,128,18721,94294518,CLX5
2025-09-24T19:35:14.515394367Z,2025-09-24T19:35:14.515271007Z,160,1,432669,C,A,64.820000000,1,26,8058566339440,128,18672,94294519,CLX5
2025-09-24T19:35:14.515419295Z,2025-09-24T19:35:14.515280647Z,160,1,432669,C,A,64.820000000,1,26,8058566339439,128,15177,94294520,CLX5
2025-09-24T19:35:14.515447955Z,2025-09-24T19:35:14.515285465Z,160,1,432669,C,A,64.820000000,1,26,8058566339438,128,14963,94294521,CLX5
2025-09-24T19:35:14.517474309Z,2025-09-24T19:35:14.517337913Z,160,1,432669,A,A,64.810000000,2,26,8058566339451,128,19006,94294523,CLX5
2025-09-24T19:35:14.517660962Z,2025-09-24T19:35:14.517481907Z,160,1,432669,A,A,64.810000000,1,26,8058566339454,128,15334,94294532,CLX5
2025-09-24T19:35:14.517852491Z,2025-09-24T19:35:14.517632081Z,160,1,432669,C,B,64.800000000,2,26,8058566339151,128,14209,94294542,CLX5
2025-09-24T19:35:14.518056261Z,2025-09-24T19:35:14.517843271Z,160,1,432669,M,A,64.830000000,3,26,8058566331622,128,18239,94294552,CLX5
2025-09-24T19:35:14.616320477Z,2025-09-24T19:35:14.616216123Z,160,1,432669,C,A,65.700000000,6,26,8058566339267,128,18342,94294660,CLX5
2025-09-24T19:35:15.380407372Z,2025-09-24T19:35:15.380241673Z,160,1,432669,A,B,64.800000000,1,26,8058566339497,128,18906,94294677,CLX5
2025-09-24T19:35:15.380568781Z,2025-09-24T19:35:15.380414791Z,160,1,432669,C,A,64.810000000,1,26,8058566339454,128,18517,94294678,CLX5
2025-09-24T19:35:16.222256009Z,2025-09-24T19:35:16.222086497Z,160,1,432669,A,A,64.810000000,1,26,8058566339505,128,18825,94294703,CLX5
2025-09-24T19:35:18.787521833Z,2025-09-24T19:35:18.787380159Z,160,1,432669,A,B,64.780000000,1,26,8058566339518,128,17759,94294743,CLX5
2025-09-24T19:35:19.984256732Z,2025-09-24T19:35:19.984090837Z,160,1,432669,C,A,64.810000000,1,26,8058566339505,128,20334,94294753,CLX5
2025-09-24T19:35:20.085352207Z,2025-09-24T19:35:20.085212277Z,160,1,432669,A,A,64.820000000,1,26,8058566339533,128,18204,94294800,CLX5
2025-09-24T19:35:20.085589575Z,2025-09-24T19:35:20.085468873Z,160,1,432669,A,A,64.820000000,1,26,8058566339534,128,18307,94294801,CLX5
2025-09-24T19:35:20.563785693Z,2025-09-24T19:35:20.563635989Z,160,1,432669,A,A,64.810000000,1,26,8058566339546,128,14668,94294832,CLX5
2025-09-24T19:35:20.624432690Z,2025-09-24T19:35:20.624191981Z,160,1,432669,M,A,64.930000000,1,26,8058565075241,128,16587,94294862,CLX5
2025-09-24T19:35:20.625131634Z,2025-09-24T19:35:20.624981987Z,160,1,432669,M,A,64.940000000,1,26,8058565075241,128,14707,94294886,CLX5
2025-09-24T19:35:20.632493925Z,2025-09-24T19:35:20.632243837Z,160,1,432669,M,A,64.930000000,1,26,8058565075241,128,16176,94294920,CLX5
2025-09-24T19:35:20.633143089Z,2025-09-24T19:35:20.633055251Z,160,1,432669,M,A,64.940000000,1,26,8058565075241,128,17664,94294930,CLX5
2025-09-24T19:35:20.654590091Z,2025-09-24T19:35:20.654488935Z,160,1,432669,M,A,64.930000000,1,26,8058565075241,128,18034,94294970,CLX5
2025-09-24T19:35:20.751422396Z,2025-09-24T19:35:20.751096365Z,160,1,432669,M,A,64.940000000,1,26,8058565075241,128,16107,94295071,CLX5
2025-09-24T19:35:22.402532687Z,2025-09-24T19:35:22.402368501Z,160,1,432669,A,B,64.710000000,1,26,8058566339705,128,18173,94295303,CLX5
2025-09-24T19:35:30.158948500Z,2025-09-24T19:35:30.158845271Z,160,1,432669,M,A,64.930000000,1,26,8058565075241,128,14188,94295581,CLX5
2025-09-24T19:35:30.160245830Z,2025-09-24T19:35:30.160074475Z,160,1,432669,A,A,64.810000000,2,26,8058566339790,128,17871,94295605,CLX5
2025-09-24T19:35:30.160686301Z,2025-09-24T19:35:30.160181837Z,160,1,432669,A,A,64.810000000,2,26,8058566339797,128,21795,94295623,CLX5
2025-09-24T19:35:30.160854584Z,2025-09-24T19:35:30.160506899Z,160,1,432669,C,A,64.810000000,2,26,8058566339797,128,16881,94295634,CLX5
2025-09-24T19:35:30.160930873Z,2025-09-24T19:35:30.160514155Z,160,1,432669,A,A,64.810000000,1,26,8058566339800,128,18377,94295636,CLX5
2025-09-24T19:35:30.161293012Z,2025-09-24T19:35:30.160939531Z,160,1,432669,A,A,64.810000000,1,26,8058566339806,128,14601,94295654,CLX5
2025-09-24T19:35:30.161611500Z,2025-09-24T19:35:30.161265611Z,160,1,432669,C,B,64.760000000,2,26,8058566338861,128,18451,94295665,CLX5
2025-09-24T19:35:30.233583899Z,2025-09-24T19:35:30.233435573Z,160,1,432669,M,A,64.940000000,1,26,8058565075241,128,15403,94296097,CLX5
2025-09-24T19:35:30.233855104Z,2025-09-24T19:35:30.233689981Z,160,1,432669,C,A,64.810000000,2,26,8058566339790,128,18410,94296108,CLX5
2025-09-24T19:35:30.625265966Z,2025-09-24T19:35:30.625130127Z,160,1,432669,C,A,64.820000000,1,26,8058566339533,128,18607,94296282,CLX5
2025-09-24T19:35:31.350915508Z,2025-09-24T19:35:31.350766097Z,160,1,432669,C,A,64.820000000,1,26,8058566339534,128,17958,94296333,CLX5
2025-09-24T19:35:34.071473024Z,2025-09-24T19:35:34.071306905Z,160,1,432669,A,B,64.790000000,1,26,8058566340051,128,20531,94296452,CLX5
2025-09-24T19:35:34.492942413Z,2025-09-24T19:35:34.492297199Z,160,1,432669,A,A,64.810000000,1,26,8058566340057,128,18997,94296463,CLX5
2025-09-24T19:35:34.493358394Z,2025-09-24T19:35:34.492323675Z,160,1,432669,A,A,64.810000000,2,26,8058566340065,128,22081,94296479,CLX5
2025-09-24T19:35:34.494479645Z,2025-09-24T19:35:34.492491839Z,160,1,432669,A,A,64.810000000,1,26,8058566340088,128,16684,94296536,CLX5
2025-09-24T19:35:34.495467342Z,2025-09-24T19:35:34.492619917Z,160,1,432669,C,B,64.780000000,1,26,8058566338439,128,14896,94296597,CLX5
2025-09-24T19:35:34.495663824Z,2025-09-24T19:35:34.492673021Z,160,1,432669,C,B,64.800000000,1,26,8058566338488,128,18160,94296604,CLX5
2025-09-24T19:35:34.495707467Z,2025-09-24T19:35:34.492673351Z,160,1,432669,A,A,64.810000000,1,26,8058566340100,128,16140,94296605,CLX5
2025-09-24T19:35:34.496020633Z,2025-09-24T19:35:34.492791405Z,160,1,432669,A,A,64.810000000,1,26,8058566340105,128,16250,94296624,CLX5
2025-09-24T19:35:34.496080173Z,2025-09-24T19:35:34.492798987Z,160,1,432669,C,B,64.800000000,1,26,8058566338390,128,18067,94296626,CLX5
2025-09-24T19:35:34.496135290Z,2025-09-24T19:35:34.492802635Z,160,1,432669,A,A,64.810000000,1,26,8058566340109,128,15862,94296628,CLX5
2025-09-24T19:35:34.496212923Z,2025-09-24T19:35:34.492803307Z,160,1,432669,A,A,64.810000000,2,26,8058566340110,128,15705,94296630,CLX5
2025-09-24T19:35:34.496324039Z,2025-09-24T19:35:34.492833393Z,160,1,432669,C,B,64.800000000,1,26,8058566249950,128,15224,94296635,CLX5
2025-09-24T19:35:34.496519101Z,2025-09-24T19:35:34.492842991Z,160,1,432669,A,A,64.810000000,2,26,8058566340113,128,15262,94296642,CLX5
2025-09-24T19:35:34.497180690Z,2025-09-24T19:35:34.493080407Z,160,1,432669,A,B,64.540000000,8,26,8058566340123,128,15161,94296685,CLX5
2025-09-24T19:35:34.497412614Z,2025-09-24T19:35:34.493147663Z,160,1,432669,C,B,64.790000000,2,26,8058566335966,128,15335,94296696,CLX5
2025-09-24T19:35:34.498223487Z,2025-09-24T19:35:34.493324775Z,160,1,432669,C,B,64.800000000,2,26,8058566256559,128,14727,94296729,CLX5
2025-09-24T19:35:34.499634152Z,2025-09-24T19:35:34.494071969Z,160,1,432669,M,A,64.930000000,1,26,8058565075241,128,15101,94296819,CLX5
2025-09-24T19:35:34.499712607Z,2025-09-24T19:35:34.494092569Z,160,1,432669,A,A,64.840000000,2,26,8058566340173,128,15090,94296823,CLX5
2025-09-24T19:35:34.502166668Z,2025-09-24T19:35:34.495429079Z,160,1,432669,C,A,64.810000000,2,26,8058566340113,128,14282,94296968,CLX5
2025-09-24T19:35:34.502222806Z,2025-09-24T19:35:34.495496163Z,160,1,432669,C,B,64.780000000,1,26,8058566339518,128,15093,94296970,CLX5
2025-09-24T19:35:34.502464107Z,2025-09-24T19:35:34.495669723Z,160,1,432669,A,B,64.800000000,1,26,8058566340206,128,14150,94296982,CLX5
2025-09-24T19:35:34.502515698Z,2025-09-24T19:35:34.495718775Z,160,1,432669,A,B,64.800000000,1,26,8058566340208,128,15258,94296984,CLX5
2025-09-24T19:35:34.502565431Z,2025-09-24T19:35:34.495736555Z,160,1,432669,C,B,64.800000000,3,26,8058566250421,128,15745,94296986,CLX5
2025-09-24T19:35:34.503521664Z,2025-09-24T19:35:34.496189635Z,160,1,432669,C,B,64.800000000,1,26,8058566340206,128,14900,94297058,CLX5
2025-09-24T19:35:34.503775060Z,2025-09-24T19:35:34.496767529Z,160,1,432669,M,B,63.640000000,3,26,8058566221991,128,14583,94297072,CLX5
2025-09-24T19:35:34.503980812Z,2025-09-24T19:35:34.496934773Z,160,1,432669,M,B,64.800000000,2,26,8058566211150,128,16877,94297082,CLX5
2025-09-24T19:35:34.504755821Z,2025-09-24T19:35:34.497756229Z,160,1,432669,C,B,64.800000000,2,26,8058566211150,128,19400,94297119,CLX5
2025-09-24T19:35:34.506134631Z,2025-09-24T19:35:34.499586637Z,160,1,432669,C,A,64.840000000,2,26,8058566340173,128,18209,94297212,CLX5
2025-09-24T19:35:34.506356095Z,2025-09-24T19:35:34.499933145Z,160,1,432669,C,A,64.810000000,2,26,8058566340110,128,18872,94297228,CLX5
2025-09-24T19:35:34.506687094Z,2025-09-24T19:35:34.500418151Z,160,1,432669,A,B,64.800000000,1,26,8058566340266,128,14954,94297248,CLX5
2025-09-24T19:35:34.506863064Z,2025-09-24T19:35:34.500686479Z,160,1,432669,M,A,64.810000000,1,26,8058566331891,128,19030,94297258,CLX5
2025-09-24T19:35:34.507622983Z,2025-09-24T19:35:34.502181863Z,160,1,432669,C,A,64.810000000,1,26,8058566340105,128,18735,94297303,CLX5
2025-09-24T19:35:34.512092025Z,2025-09-24T19:35:34.511552049Z,160,1,432669,A,B,64.780000000,1,26,8058566340353,128,14677,94297597,CLX5
2025-09-24T19:35:34.515100284Z,2025-09-24T19:35:34.514959013Z,160,1,432669,M,A,64.820000000,1,26,8058566331891,128,19516,94297647,CLX5
2025-09-24T19:35:34.542344644Z,2025-09-24T19:35:34.542201115Z,160,1,432669,A,B,64.790000000,2,26,8058566340373,128,18256,94297708,CLX5
2025-09-24T19:35:34.542572620Z,2025-09-24T19:35:34.542395661Z,160,1,432669,C,A,64.810000000,1,26,8058566340088,128,17887,94297719,CLX5
2025-09-24T19:35:34.569618685Z,2025-09-24T19:35:34.569425731Z,160,1,432669,A,A,64.810000000,2,26,8058566340395,128,19428,94297770,CLX5
2025-09-24T19:35:34.569716116Z,2025-09-24T19:35:34.569426665Z,160,1,432669,C,B,64.790000000,2,26,8058566340373,128,18846,94297772,CLX5
2025-09-24T19:35:34.569782698Z,2025-09-24T19:35:34.569431273Z,160,1,432669,A,A,64.810000000,1,26,8058566340397,128,14246,94297775,CLX5
2025-09-24T19:35:34.569839865Z,2025-09-24T19:35:34.569432523Z,160,1,432669,C,B,64.800000000,1,26,8058566340208,128,18270,94297777,CLX5
2025-09-24T19:35:34.570304320Z,2025-09-24T19:35:34.569849337Z,160,1,432669,C,A,64.810000000,1,26,8058566340397,128,14462,94297793,CLX5
2025-09-24T19:35:34.570572038Z,2025-09-24T19:35:34.570282027Z,160,1,432669,A,B,64.800000000,1,26,8058566340404,128,19477,94297806,CLX5
2025-09-24T19:35:34.572703379Z,2025-09-24T19:35:34.572552327Z,160,1,432669,A,A,64.810000000,1,26,8058566340408,128,15291,94297813,CLX5
2025-09-24T19:35:34.572741393Z,2025-09-24T19:35:34.572553883Z,160,1,432669,C,B,64.800000000,1,26,8058566340404,128,15104,94297814,CLX5
2025-09-24T19:35:34.573064351Z,2025-09-24T19:35:34.572711335Z,160,1,432669,C,A,64.810000000,1,26,8058566340408,128,18503,94297821,CLX5
2025-09-24T19:35:34.573099793Z,2025-09-24T19:35:34.572749617Z,160,1,432669,A,B,64.800000000,1,26,8058566340410,128,15574,94297822,CLX5
2025-09-24T19:35:34.610795600Z,2025-09-24T19:35:34.610665967Z,160,1,432669,A,B,64.770000000,2,26,8058566340445,128,18329,94297886,CLX5
2025-09-24T19:35:34.622229560Z,2025-09-24T19:35:34.622125979Z,160,1,432669,C,B,64.540000000,8,26,8058566340123,128,18603,94297903,CLX5
2025-09-24T19:35:34.643802876Z,2025-09-24T19:35:34.643702737Z,160,1,432669,A,B,64.400000000,2,26,8058566340482,128,18429,94297934,CLX5
2025-09-24T19:35:34.647173106Z,2025-09-24T19:35:34.646997387Z,160,1,432669,C,A,64.810000000,2,26,8058566340395,128,16206,94297971,CLX5
2025-09-24T19:35:34.647493729Z,2025-09-24T19:35:34.647326155Z,160,1,432669,C,A,64.810000000,1,26,8058566340057,128,15685,94297984,CLX5
2025-09-24T19:35:34.647928310Z,2025-09-24T19:35:34.647710195Z,160,1,432669,A,B,64.790000000,2,26,8058566340495,128,13952,94297996,CLX5
2025-09-24T19:35:34.648315968Z,2025-09-24T19:35:34.647829193Z,160,1,432669,A,B,64.800000000,1,26,8058566340503,128,15646,94298010,CLX5
2025-09-24T19:35:34.648514247Z,2025-09-24T19:35:34.647926705Z,160,1,432669,C,B,64.800000000,1,26,8058566340503,128,14897,94298018,CLX5
2025-09-24T19:35:34.710788782Z,2025-09-24T19:35:34.710660705Z,160,1,432669,C,B,64.770000000,2,26,8058566340445,128,18488,94298227,CLX5
2025-09-24T19:35:34.724974188Z,2025-09-24T19:35:34.724633521Z,160,1,432669,C,A,64.810000000,1,26,8058566340109,128,16846,94298236,CLX5
2025-09-24T19:35:34.725021126Z,2025-09-24T19:35:34.724633669Z,160,1,432669,A,B,64.800000000,1,26,8058566340602,128,15375,94298238,CLX5
2025-09-24T19:35:34.725065084Z,2025-09-24T19:35:34.724639723Z,160,1,432669,C,A,64.810000000,1,26,8058566339546,128,20462,94298239,CLX5
2025-09-24T19:35:34.725153169Z,2025-09-24T19:35:34.724651395Z,160,1,432669,A,B,64.800000000,1,26,8058566340603,128,15591,94298241,CLX5
2025-09-24T19:35:34.725187842Z,2025-09-24T19:35:34.724655043Z,160,1,432669,A,B,64.800000000,1,26,8058566340604,128,17071,94298242,CLX5
2025-09-24T19:35:34.725230848Z,2025-09-24T19:35:34.724664375Z,160,1,432669,C,A,64.810000000,2,26,8058566340065,128,16106,94298243,CLX5
2025-09-24T19:35:34.725342233Z,2025-09-24T19:35:34.724722989Z,160,1,432669,A,B,64.800000000,2,26,8058566340607,128,14693,94298246,CLX5
2025-09-24T19:35:34.725512382Z,2025-09-24T19:35:34.724819063Z,160,1,432669,M,A,64.940000000,1,26,8058565075241,128,14485,94298253,CLX5
2025-09-24T19:35:34.725543415Z,2025-09-24T19:35:34.724871707Z,160,1,432669,C,B,64.800000000,1,26,8058566340603,128,15020,94298254,CLX5
2025-09-24T19:35:34.725598900Z,2025-09-24T19:35:34.724913867Z,160,1,432669,C,A,64.810000000,1,26,8058566340100,128,22058,94298255,CLX5
2025-09-24T19:35:34.725916981Z,2025-09-24T19:35:34.725038163Z,160,1,432669,C,B,64.800000000,2,26,8058566340607,128,17168,94298270,CLX5
2025-09-24T19:35:34.726899954Z,2025-09-24T19:35:34.725925931Z,160,1,432669,A,A,64.810000000,1,26,8058566340624,128,20510,94298309,CLX5
2025-09-24T19:35:34.746333374Z,2025-09-24T19:35:34.745980945Z,160,1,432669,T,B,64.810000000,4,26,8058566340666,0,18321,94298454,CLX5
2025-09-24T19:35:34.746333374Z,2025-09-24T19:35:34.745980945Z,160,1,432669,F,A,64.810000000,2,26,8058566339451,0,18321,94298454,CLX5
2025-09-24T19:35:34.746333374Z,2025-09-24T19:35:34.745980945Z,160,1,432669,F,A,64.810000000,1,26,8058566339800,0,18321,94298454,CLX5
2025-09-24T19:35:34.746333374Z,2025-09-24T19:35:34.745980945Z,160,1,432669,F,A,64.810000000,1,26,8058566339806,0,18321,94298454,CLX5
2025-09-24T19:35:34.746343649Z,2025-09-24T19:35:34.745980945Z,160,1,432669,C,A,64.810000000,2,26,8058566339451,0,15224,94298455,CLX5
2025-09-24T19:35:34.746343649Z,2025-09-24T19:35:34.745980945Z,160,1,432669,C,A,64.810000000,1,26,8058566339800,0,15224,94298455,CLX5
2025-09-24T19:35:34.746343649Z,2025-09-24T19:35:34.745980945Z,160,1,432669,C,A,64.810000000,1,26,8058566339806,128,15224,94298455,CLX5
2025-09-24T19:35:34.746694299Z,2025-09-24T19:35:34.746336455Z,160,1,432669,A,A,64.810000000,1,26,8058566340671,128,17903,94298469,CLX5
2025-09-24T19:35:34.746714051Z,2025-09-24T19:35:34.746336635Z,160,1,432669,A,A,64.810000000,1,26,8058566340672,128,17049,94298471,CLX5
2025-09-24T19:35:34.747004156Z,2025-09-24T19:35:34.746351181Z,160,1,432669,A,B,64.800000000,2,26,8058566340678,128,19033,94298484,CLX5
2025-09-24T19:35:34.747182131Z,2025-09-24T19:35:34.746383321Z,160,1,432669,M,A,64.930000000,1,26,8058565075241,128,14858,94298494,CLX5
2025-09-24T19:35:34.747278049Z,2025-09-24T19:35:34.746389311Z,160,1,432669,A,B,64.800000000,2,26,8058566340680,128,14978,94298497,CLX5
2025-09-24T19:35:34.747327344Z,2025-09-24T19:35:34.746407185Z,160,1,432669,T,N,64.810000000,1,26,0,0,14695,94298499,CLX5
2025-09-24T19:35:34.747327344Z,2025-09-24T19:35:34.746407185Z,160,1,432669,F,N,64.810000000,1,26,8058566340624,0,14695,94298499,CLX5
2025-09-24T19:35:34.747381816Z,2025-09-24T19:35:34.746407185Z,160,1,432669,C,A,64.810000000,1,26,8058566340624,128,17947,94298500,CLX5
2025-09-24T19:35:34.747440926Z,2025-09-24T19:35:34.746421143Z,160,1,432669,T,N,64.810000000,1,26,0,0,14849,94298504,CLX5
2025-09-24T19:35:34.747440926Z,2025-09-24T19:35:34.746421143Z,160,1,432669,F,N,64.810000000,1,26,8058566340671,0,14849,94298504,CLX5
2025-09-24T19:35:34.747491473Z,2025-09-24T19:35:34.746421143Z,160,1,432669,C,A,64.810000000,1,26,8058566340671,128,18637,94298505,CLX5
2025-09-24T19:35:34.747643037Z,2025-09-24T19:35:34.746704561Z,160,1,432669,C,B,64.800000000,2,26,8058566340678,128,16240,94298515,CLX5
2025-09-24T19:35:34.747971908Z,2025-09-24T19:35:34.747150749Z,160,1,432669,C,A,64.810000000,1,26,8058566340672,128,18237,94298528,CLX5
2025-09-24T19:35:34.748475667Z,2025-09-24T19:35:34.747974699Z,160,1,432669,A,A,64.820000000,1,26,8058566340698,128,13809,94298553,CLX5
2025-09-24T19:35:34.748625296Z,2025-09-24T19:35:34.748005361Z,160,1,432669,A,B,64.800000000,1,26,8058566340700,128,18219,94298558,CLX5
2025-09-24T19:35:34.748855468Z,2025-09-24T19:35:34.748202287Z,160,1,432669,A,A,64.810000000,1,26,8058566340703,128,14610,94298571,CLX5
2025-09-24T19:35:34.749361716Z,2025-09-24T19:35:34.748883473Z,160,1,432669,C,B,64.800000000,1,26,8058566340700,128,18137,94298600,CLX5
2025-09-24T19:35:34.749908710Z,2025-09-24T19:35:34.749762583Z,160,1,432669,A,A,64.810000000,1,26,8058566340712,128,18229,94298618,CLX5
2025-09-24T19:35:34.749929537Z,2025-09-24T19:35:34.749762763Z,160,1,432669,A,A,64.810000000,1,26,8058566340713,128,16047,94298620,CLX5
2025-09-24T19:35:34.752196047Z,2025-09-24T19:35:34.751682287Z,160,1,432669,A,A,64.810000000,1,26,8058566340741,128,17846,94298717,CLX5
2025-09-24T19:35:34.854509381Z,2025-09-24T19:35:34.854356919Z,160,1,432669,C,A,64.810000000,1,26,8058566340741,128,14596,94298896,CLX5
2025-09-24T19:35:35.119068728Z,2025-09-24T19:35:35.118606687Z,160,1,432669,M,A,64.940000000,1,26,8058565075241,128,17614,94299034,CLX5
2025-09-24T19:35:35.136499908Z,2025-09-24T19:35:35.136103913Z,160,1,432669,T,B,64.810000000,3,26,8058566340881,0,17725,94299128,CLX5
2025-09-24T19:35:35.136499908Z,2025-09-24T19:35:35.136103913Z,160,1,432669,F,A,64.810000000,1,26,8058566340703,0,17725,94299128,CLX5
2025-09-24T19:35:35.136499908Z,2025-09-24T19:35:35.136103913Z,160,1,432669,F,A,64.810000000,1,26,8058566340712,0,17725,94299128,CLX5
2025-09-24T19:35:35.136499908Z,2025-09-24T19:35:35.136103913Z,160,1,432669,F,A,64.810000000,1,26,8058566340713,0,17725,94299128,CLX5
2025-09-24T19:35:35.136509561Z,2025-09-24T19:35:35.136103913Z,160,1,432669,C,A,64.810000000,1,26,8058566340703,0,14554,94299129,CLX5
2025-09-24T19:35:35.136509561Z,2025-09-24T19:35:35.136103913Z,160,1,432669,C,A,64.810000000,1,26,8058566340712,0,14554,94299129,CLX5
2025-09-24T19:35:35.136509561Z,2025-09-24T19:35:35.136103913Z,160,1,432669,C,A,64.810000000,1,26,8058566340713,128,14554,94299129,CLX5
2025-09-24T19:35:35.136976250Z,2025-09-24T19:35:35.136431393Z,160,1,432669,M,A,64.930000000,1,26,8058565075241,128,13882,94299154,CLX5
2025-09-24T19:35:35.137231659Z,2025-09-24T19:35:35.136524125Z,160,1,432669,A,B,64.800000000,2,26,8058566340892,128,14103,94299166,CLX5
2025-09-24T19:35:35.137411722Z,2025-09-24T19:35:35.136605433Z,160,1,432669,A,B,64.800000000,1,26,8058566340896,128,18585,94299174,CLX5
2025-09-24T19:35:35.137439031Z,2025-09-24T19:35:35.136605609Z,160,1,432669,A,B,64.800000000,1,26,8058566340897,128,15007,94299175,CLX5
2025-09-24T19:35:35.137474380Z,2025-09-24T19:35:35.136619927Z,160,1,432669,C,A,64.820000000,2,26,8058566339433,128,14870,94299176,CLX5
2025-09-24T19:35:35.138135025Z,2025-09-24T19:35:35.137313593Z,160,1,432669,C,A,64.820000000,1,26,8058566340698,128,14757,94299216,CLX5
2025-09-24T19:35:35.138201853Z,2025-09-24T19:35:35.137500843Z,160,1,432669,A,B,64.800000000,3,26,8058566340905,128,15143,94299218,CLX5
2025-09-24T19:35:35.138236127Z,2025-09-24T19:35:35.137534805Z,160,1,432669,A,A,64.820000000,2,26,8058566340906,128,18062,94299219,CLX5
2025-09-24T19:35:35.224300986Z,2025-09-24T19:35:35.224138941Z,160,1,432669,C,B,64.800000000,2,26,8058566340892,128,15083,94299421,CLX5
2025-09-24T19:35:35.465713578Z,2025-09-24T19:35:35.465290459Z,160,1,432669,M,A,64.940000000,1,26,8058565075241,128,14832,94299580,CLX5
2025-09-24T19:35:35.516352919Z,2025-09-24T19:35:35.516247949Z,160,1,432669,A,A,65.700000000,6,26,8058566341057,128,18291,94299657,CLX5
2025-09-24T19:35:37.609466184Z,2025-09-24T19:35:37.609360191Z,160,1,432669,A,B,64.540000000,8,26,8058566341136,128,18945,94299947,CLX5
2025-09-24T19:35:37.611504579Z,2025-09-24T19:35:37.611194671Z,160,1,432669,M,A,64.930000000,1,26,8058565075241,128,14256,94300003,CLX5
2025-09-24T19:35:37.616394109Z,2025-09-24T19:35:37.616304409Z,160,1,432669,C,A,65.700000000,6,26,8058566341057,128,17905,94300033,CLX5
2025-09-24T19:35:39.547991163Z,2025-09-24T19:35:39.547830035Z,160,1,432669,M,B,64.750000000,1,26,8058566197138,128,18046,94300099,CLX5
2025-09-24T19:35:42.389129738Z,2025-09-24T19:35:42.388976019Z,160,1,432669,M,A,64.940000000,1,26,8058565075241,128,15451,94300285,CLX5
2025-09-24T19:35:42.391016922Z,2025-09-24T19:35:42.390790397Z,160,1,432669,A,B,64.810000000,1,26,8058566341228,128,18114,94300291,CLX5
2025-09-24T19:35:42.391277560Z,2025-09-24T19:35:42.391039447Z,160,1,432669,C,A,64.820000000,2,26,8058566340906,128,15683,94300309,CLX5
2025-09-24T19:35:42.391397746Z,2025-09-24T19:35:42.391078421Z,160,1,432669,A,B,64.810000000,1,26,8058566341232,128,14854,94300315,CLX5
2025-09-24T19:35:42.391634139Z,2025-09-24T19:35:42.391333751Z,160,1,432669,M,A,65.970000000,4,26,8058566331622,128,15775,94300330,CLX5
2025-09-24T19:35:42.391729597Z,2025-09-24T19:35:42.391355427Z,160,1,432669,M,B,64.800000000,3,26,8058566221991,128,14095,94300335,CLX5
2025-09-24T19:35:42.391944410Z,2025-09-24T19:35:42.391732939Z,160,1,432669,A,B,64.810000000,1,26,8058566341236,128,14694,94300344,CLX5
2025-09-24T19:35:42.392319973Z,2025-09-24T19:35:42.392185751Z,160,1,432669,M,B,64.800000000,1,26,8058566340051,128,18552,94300354,CLX5
2025-09-24T19:35:42.392475401Z,2025-09-24T19:35:42.392348847Z,160,1,432669,A,B,64.790000000,1,26,8058566341239,128,18918,94300355,CLX5
2025-09-24T19:35:42.416373916Z,2025-09-24T19:35:42.416266309Z,160,1,432669,A,A,65.700000000,6,26,8058566341243,128,18236,94300369,CLX5
2025-09-24T19:35:42.428744304Z,2025-09-24T19:35:42.428440741Z,160,1,432669,T,A,64.810000000,1,26,8058566341246,0,18672,94300376,CLX5
2025-09-24T19:35:42.428744304Z,2025-09-24T19:35:42.428440741Z,160,1,432669,F,B,64.810000000,1,26,8058566341228,0,18672,94300376,CLX5
2025-09-24T19:35:42.428752751Z,2025-09-24T19:35:42.428440741Z,160,1,432669,C,B,64.810000000,1,26,8058566341228,128,14520,94300377,CLX5
2025-09-24T19:35:42.428958695Z,2025-09-24T19:35:42.428727135Z,160,1,432669,C,B,64.810000000,1,26,8058566341236,128,17908,94300384,CLX5
2025-09-24T19:35:42.428981235Z,2025-09-24T19:35:42.428744453Z,160,1,432669,A,A,64.820000000,2,26,8058566341247,128,15222,94300386,CLX5
2025-09-24T19:35:42.429028357Z,2025-09-24T19:35:42.428777783Z,160,1,432669,M,A,64.820000000,1,26,8058566239191,128,15125,94300388,CLX5
2025-09-24T19:35:42.430479762Z,2025-09-24T19:35:42.430299009Z,160,1,432669,M,A,64.930000000,1,26,8058565075241,128,14583,94300419,CLX5
2025-09-24T19:35:42.516357459Z,2025-09-24T19:35:42.516250545Z,160,1,432669,C,A,65.700000000,6,26,8058566341243,128,18225,94300453,CLX5
2025-09-24T19:35:42.537752187Z,2025-09-24T19:35:42.537627227Z,160,1,432669,M,A,65.140000000,1,26,8058566239191,128,18732,94300460,CLX5
2025-09-24T19:35:42.684315219Z,2025-09-24T19:35:42.684165989Z,160,1,432669,M,A,64.940000000,1,26,8058565075241,128,16443,94300484,CLX5
2025-09-24T19:35:42.684477942Z,2025-09-24T19:35:42.684338379Z,160,1,432669,M,A,64.820000000,1,26,8058566239191,128,15097,94300486,CLX5
2025-09-24T19:35:42.716345223Z,2025-09-24T19:35:42.716235623Z,160,1,432669,A,A,65.700000000,6,26,8058566341282,128,19045,94300505,CLX5
2025-09-24T19:35:42.854066634Z,2025-09-24T19:35:42.853881455Z,160,1,432669,A,B,64.810000000,1,26,8058566341287,128,19174,94300522,CLX5
2025-09-24T19:35:42.854395375Z,2025-09-24T19:35:42.854088403Z,160,1,432669,M,A,65.140000000,1,26,8058566239191,128,15674,94300544,CLX5
2025-09-24T19:35:42.854703450Z,2025-09-24T19:35:42.854162357Z,160,1,432669,C,A,64.820000000,2,26,8058566341247,128,15109,94300560,CLX5
2025-09-24T19:35:42.854821700Z,2025-09-24T19:35:42.854171189Z,160,1,432669,A,B,64.810000000,1,26,8058566341296,128,14736,94300565,CLX5
2025-09-24T19:35:42.855350763Z,2025-09-24T19:35:42.854821811Z,160,1,432669,A,B,64.810000000,1,26,8058566341305,128,18381,94300596,CLX5
2025-09-24T19:35:42.872602985Z,2025-09-24T19:35:42.871787871Z,160,1,432669,A,B,64.810000000,1,26,8058566341357,128,18040,94300784,CLX5
2025-09-24T19:35:42.872980853Z,2025-09-24T19:35:42.872007239Z,160,1,432669,A,B,64.810000000,2,26,8058566341365,128,14672,94300803,CLX5
2025-09-24T19:35:42.873105608Z,2025-09-24T19:35:42.872147181Z,160,1,432669,A,B,64.810000000,2,26,8058566341366,128,16395,94300806,CLX5
2025-09-24T19:35:42.874329689Z,2025-09-24T19:35:42.873718193Z,160,1,432669,C,B,64.810000000,2,26,8058566341366,128,16446,94300864,CLX5
2025-09-24T19:35:42.874444660Z,2025-09-24T19:35:42.874344217Z,160,1,432669,C,B,64.810000000,2,26,8058566341365,128,15481,94300871,CLX5
2025-09-24T19:35:42.877473371Z,2025-09-24T19:35:42.877323465Z,160,1,432669,C,A,64.820000000,1,26,8058566338676,128,18386,94300883,CLX5
2025-09-24T19:35:42.890377567Z,2025-09-24T19:35:42.890092363Z,160,1,432669,C,B,64.810000000,1,26,8058566341287,128,18155,94300916,CLX5
2025-09-24T19:35:42.890470183Z,2025-09-24T19:35:42.890141589Z,160,1,432669,A,A,64.820000000,2,26,8058566341386,128,13832,94300920,CLX5
2025-09-24T19:35:42.890584440Z,2025-09-24T19:35:42.890328031Z,160,1,432669,C,B,64.810000000,1,26,8058566341357,128,15221,94300925,CLX5
2025-09-24T19:35:42.890852527Z,2025-09-24T19:35:42.890438773Z,160,1,432669,C,B,64.810000000,1,26,8058566341305,128,15013,94300938,CLX5
2025-09-24T19:35:42.892105637Z,2025-09-24T19:35:42.891782061Z,160,1,432669,M,A,64.930000000,1,26,8058565075241,128,14702,94300997,CLX5
2025-09-24T19:35:42.892263199Z,2025-09-24T19:35:42.892027253Z,160,1,432669,A,B,64.810000000,1,26,8058566341409,128,14558,94301005,CLX5
2025-09-24T19:35:42.892361161Z,2025-09-24T19:35:42.892097907Z,160,1,432669,A,B,64.810000000,2,26,8058566341410,128,16957,94301011,CLX5
2025-09-24T19:35:42.892462232Z,2025-09-24T19:35:42.892273137Z,160,1,432669,C,A,64.820000000,2,26,8058566341386,128,15250,94301016,CLX5
2025-09-24T19:35:42.894412105Z,2025-09-24T19:35:42.894102239Z,160,1,432669,M,A,64.940000000,1,26,8058565075241,128,18209,94301103,CLX5
2025-09-24T19:35:42.894486766Z,2025-09-24T19:35:42.894165559Z,160,1,432669,C,B,64.810000000,1,26,8058566341409,128,17388,94301105,CLX5
2025-09-24T19:35:42.895132159Z,2025-09-24T19:35:42.894930185Z,160,1,432669,A,A,64.820000000,1,26,8058566341439,128,15225,94301123,CLX5
2025-09-24T19:35:42.960914759Z,2025-09-24T19:35:42.960823501Z,160,1,432669,M,A,64.930000000,1,26,8058565075241,128,17876,94301229,CLX5
2025-09-24T19:35:42.961479432Z,2025-09-24T19:35:42.961195619Z,160,1,432669,A,B,64.810000000,1,26,8058566341496,128,21396,94301243,CLX5
2025-09-24T19:35:42.961515825Z,2025-09-24T19:35:42.961201571Z,160,1,432669,A,B,64.810000000,1,26,8058566341497,128,17434,94301244,CLX5
2025-09-24T19:35:42.961731277Z,2025-09-24T19:35:42.961516879Z,160,1,432669,M,A,64.940000000,1,26,8058565075241,128,14754,94301252,CLX5
2025-09-24T19:35:42.962798932Z,2025-09-24T19:35:42.962459595Z,160,1,432669,A,B,64.810000000,2,26,8058566341513,128,17244,94301308,CLX5
2025-09-24T19:35:43.400165989Z,2025-09-24T19:35:43.400009255Z,160,1,432669,C,B,64.810000000,1,26,8058566341232,128,19376,94301587,CLX5
2025-09-24T19:35:43.600390369Z,2025-09-24T19:35:43.600109335Z,160,1,432669,T,A,64.810000000,1,26,8058566341645,0,18311,94301626,CLX5
2025-09-24T19:35:43.600390369Z,2025-09-24T19:35:43.600109335Z,160,1,432669,F,B,64.810000000,1,26,8058566341296,0,18311,94301626,CLX5
2025-09-24T19:35:43.600402787Z,2025-09-24T19:35:43.600109335Z,160,1,432669,C,B,64.810000000,1,26,8058566341296,128,17436,94301627,CLX5
2025-09-24T19:35:43.600625794Z,2025-09-24T19:35:43.600413833Z,160,1,432669,C,B,64.810000000,2,26,8058566341513,128,15878,94301631,CLX5
2025-09-24T19:35:43.900316211Z,2025-09-24T19:35:43.900145273Z,160,1,432669,A,B,64.810000000,1,26,8058566341665,128,22342,94301700,CLX5
2025-09-24T19:35:44.178207908Z,2025-09-24T19:35:44.178052783Z,160,1,432669,C,B,64.810000000,1,26,8058566341497,128,21203,94301715,CLX5
2025-09-24T19:35:44.178516744Z,2025-09-24T19:35:44.178251397Z,160,1,432669,T,A,64.810000000,1,26,8058566341678,0,18645,94301718,CLX5
2025-09-24T19:35:44.178516744Z,2025-09-24T19:35:44.178251397Z,160,1,432669,F,B,64.810000000,1,26,8058566341410,0,18645,94301718,CLX5
2025-09-24T19:35:44.178525391Z,2025-09-24T19:35:44.178251397Z,160,1,432669,M,B,64.810000000,1,26,8058566341410,128,14634,94301719,CLX5
2025-09-24T19:35:44.178713333Z,2025-09-24T19:35:44.178516883Z,160,1,432669,A,A,64.820000000,2,26,8058566341681,128,14985,94301730,CLX5
2025-09-24T19:35:44.178929982Z,2025-09-24T19:35:44.178727249Z,160,1,432669,C,B,64.810000000,1,26,8058566341496,128,14743,94301740,CLX5
2025-09-24T19:35:44.179812652Z,2025-09-24T19:35:44.179668909Z,160,1,432669,C,A,64.820000000,2,26,8058566341681,128,15965,94301763,CLX5
2025-09-24T19:35:44.179959916Z,2025-09-24T19:35:44.179817761Z,160,1,432669,A,B,64.810000000,1,26,8058566341690,128,18375,94301764,CLX5
2025-09-24T19:35:44.180094624Z,2025-09-24T19:35:44.179960047Z,160,1,432669,A,B,64.810000000,1,26,8058566341691,128,21219,94301767,CLX5
2025-09-24T19:35:45.046693871Z,2025-09-24T19:35:45.046542773Z,160,1,432669,A,A,64.820000000,2,26,8058566341710,128,15226,94301836,CLX5
2025-09-24T19:35:45.046854951Z,2025-09-24T19:35:45.046711593Z,160,1,432669,C,B,64.810000000,1,26,8058566341691,128,18027,94301837,CLX5
2025-09-24T19:35:45.047000003Z,2025-09-24T19:35:45.046736415Z,160,1,432669,T,A,64.810000000,1,26,8058566341711,0,17917,94301839,CLX5
2025-09-24T19:35:45.047000003Z,2025-09-24T19:35:45.046736415Z,160,1,432669,F,B,64.810000000,1,26,8058566341410,0,17917,94301839,CLX5
2025-09-24T19:35:45.047008297Z,2025-09-24T19:35:45.046736415Z,160,1,432669,C,B,64.810000000,1,26,8058566341410,128,14528,94301840,CLX5
2025-09-24T19:35:45.047119889Z,2025-09-24T19:35:45.046974755Z,160,1,432669,C,B,64.810000000,1,26,8058566341690,128,18204,94301847,CLX5
2025-09-24T19:35:45.048169513Z,2025-09-24T19:35:45.048038541Z,160,1,432669,C,A,64.820000000,2,26,8058566341710,128,18421,94301875,CLX5
2025-09-24T19:35:45.081916950Z,2025-09-24T19:35:45.081767919Z,160,1,432669,C,A,64.840000000,1,26,8058566316078,128,18233,94301879,CLX5
2025-09-24T19:35:45.106754571Z,2025-09-24T19:35:45.106544331Z,160,1,432669,A,B,64.810000000,2,26,8058566341721,128,14774,94301884,CLX5
2025-09-24T19:35:45.106778253Z,2025-09-24T19:35:45.106571671Z,160,1,432669,A,B,64.810000000,1,26,8058566341722,128,16024,94301886,CLX5
2025-09-24T19:35:45.107449728Z,2025-09-24T19:35:45.107306057Z,160,1,432669,A,B,64.810000000,1,26,8058566341723,128,22830,94301890,CLX5
2025-09-24T19:35:45.107586325Z,2025-09-24T19:35:45.107449015Z,160,1,432669,A,B,64.810000000,1,26,8058566341724,128,19249,94301891,CLX5
2025-09-24T19:35:45.157174676Z,2025-09-24T19:35:45.157031537Z,160,1,432669,A,A,64.820000000,1,26,8058566341727,128,18794,94301897,CLX5
2025-09-24T19:35:45.157309476Z,2025-09-24T19:35:45.157179313Z,160,1,432669,C,B,64.810000000,1,26,8058566341722,128,20502,94301898,CLX5
2025-09-24T19:35:45.390216755Z,2025-09-24T19:35:45.390073297Z,160,1,432669,M,B,64.790000000,1,26,8058566197138,128,17705,94301910,CLX5
2025-09-24T19:35:45.673303819Z,2025-09-24T19:35:45.672949723Z,160,1,432669,C,B,64.810000000,1,26,8058566341723,128,23078,94301916,CLX5
2025-09-24T19:35:45.673409997Z,2025-09-24T19:35:45.672966081Z,160,1,432669,C,B,64.810000000,1,26,8058566341724,128,19392,94301920,CLX5
2025-09-24T19:35:45.673669083Z,2025-09-24T19:35:45.673032739Z,160,1,432669,A,A,64.820000000,2,26,8058566341732,128,18133,94301937,CLX5
2025-09-24T19:35:45.673751009Z,2025-09-24T19:35:45.673107403Z,160,1,432669,C,B,64.810000000,2,26,8058566341721,128,20152,94301939,CLX5
2025-09-24T19:35:45.674348183Z,2025-09-24T19:35:45.673592009Z,160,1,432669,C,A,64.820000000,2,26,8058566341732,128,14560,94301969,CLX5
2025-09-24T19:35:45.675076899Z,2025-09-24T19:35:45.674855487Z,160,1,432669,M,A,64.930000000,1,26,8058565075241,128,15135,94302000,CLX5
2025-09-24T19:35:45.677422870Z,2025-09-24T19:35:45.677031059Z,160,1,432669,A,B,64.810000000,1,26,8058566341766,128,14766,94302088,CLX5
2025-09-24T19:35:45.677476282Z,2025-09-24T19:35:45.677031235Z,160,1,432669,A,B,64.810000000,1,26,8058566341767,128,18281,94302091,CLX5
2025-09-24T19:35:45.677531322Z,2025-09-24T19:35:45.677061547Z,160,1,432669,M,A,64.940000000,1,26,8058565075241,128,13656,94302095,CLX5
2025-09-24T19:35:45.677821258Z,2025-09-24T19:35:45.677361285Z,160,1,432669,A,B,64.810000000,1,26,8058566341769,128,18663,94302111,CLX5
2025-09-24T19:35:45.706955346Z,2025-09-24T19:35:45.706814397Z,160,1,432669,C,B,64.810000000,1,26,8058566341769,128,17855,94302135,CLX5
2025-09-24T19:35:45.707092381Z,2025-09-24T19:35:45.706959349Z,160,1,432669,C,B,64.810000000,1,26,8058566341767,128,18122,94302138,CLX5
2025-09-24T19:35:46.789599032Z,2025-09-24T19:35:46.789302705Z,160,1,432669,T,A,64.810000000,1,26,8058566341821,0,18321,94302243,CLX5
2025-09-24T19:35:46.789599032Z,2025-09-24T19:35:46.789302705Z,160,1,432669,F,B,64.810000000,1,26,8058566341665,0,18321,94302243,CLX5
2025-09-24T19:35:46.789609868Z,2025-09-24T19:35:46.789302705Z,160,1,432669,C,B,64.810000000,1,26,8058566341665,128,16792,94302244,CLX5
2025-09-24T19:35:46.789752417Z,2025-09-24T19:35:46.789599159Z,160,1,432669,C,B,64.810000000,1,26,8058566341766,128,18604,94302247,CLX5
2025-09-24T19:35:46.789936881Z,2025-09-24T19:35:46.789797023Z,160,1,432669,C,B,64.790000000,1,26,8058566341239,128,15193,94302253,CLX5
2025-09-24T19:35:46.790129201Z,2025-09-24T19:35:46.789996503Z,160,1,432669,A,A,64.820000000,2,26,8058566341826,128,19118,94302260,CLX5
2025-09-24T19:35:46.790161501Z,2025-09-24T19:35:46.790039913Z,160,1,432669,M,B,63.640000000,3,26,8058566221991,128,15690,94302261,CLX5
2025-09-24T19:35:46.790404898Z,2025-09-24T19:35:46.790165667Z,160,1,432669,A,A,64.820000000,1,26,8058566341828,128,14939,94302268,CLX5
2025-09-24T19:35:46.790438113Z,2025-09-24T19:35:46.790205871Z,160,1,432669,A,A,64.820000000,1,26,8058566341829,128,18024,94302269,CLX5
2025-09-24T19:35:46.790601227Z,2025-09-24T19:35:46.790430615Z,160,1,432669,A,A,64.820000000,1,26,8058566341830,128,15217,94302279,CLX5
2025-09-24T19:35:46.816714413Z,2025-09-24T19:35:46.816612999Z,160,1,432669,C,A,65.700000000,6,26,8058566341282,128,18680,94302294,CLX5
2025-09-24T19:35:46.816865524Z,2025-09-24T19:35:46.816741289Z,160,1,432669,C,A,64.820000000,1,26,8058566341830,128,19144,94302295,CLX5
2025-09-24T19:35:46.816892003Z,2025-09-24T19:35:46.816750927Z,160,1,432669,C,A,64.820000000,1,26,8058566341829,128,15121,94302296,CLX5
2025-09-24T19:35:46.816921670Z,2025-09-24T19:35:46.816752731Z,160,1,432669,C,A,64.820000000,1,26,8058566341828,128,15626,94302297,CLX5
2025-09-24T19:35:47.967000060Z,2025-09-24T19:35:47.966741107Z,160,1,432669,C,A,64.820000000,2,26,8058566341826,128,18027,94302332,CLX5
2025-09-24T19:35:47.967031684Z,2025-09-24T19:35:47.966756581Z,160,1,432669,A,B,64.800000000,2,26,8058566341844,128,14818,94302333,CLX5
2025-09-24T19:35:47.967161723Z,2025-09-24T19:35:47.967042033Z,160,1,432669,C,B,64.800000000,2,26,8058566341844,128,18136,94302334,CLX5
2025-09-24T19:35:47.967215111Z,2025-09-24T19:35:47.967086979Z,160,1,432669,A,A,64.820000000,2,26,8058566341845,128,15224,94302335,CLX5
2025-09-24T19:35:47.967243956Z,2025-09-24T19:35:47.967113187Z,160,1,432669,M,B,64.800000000,3,26,8058566221991,128,13898,94302336,CLX5
2025-09-24T19:35:47.989413846Z,2025-09-24T19:35:47.989271621Z,160,1,432669,C,A,64.820000000,1,26,8058566341439,128,19229,94302340,CLX5
2025-09-24T19:35:48.007237838Z,2025-09-24T19:35:48.006890491Z,160,1,432669,T,A,64.810000000,1,26,8058566341850,128,18851,94302346,CLX5
2025-09-24T19:35:48.017174022Z,2025-09-24T19:35:48.016867139Z,160,1,432669,T,A,64.810000000,1,26,8058566341852,0,18774,94302355,CLX5
2025-09-24T19:35:48.017257430Z,2025-09-24T19:35:48.016867139Z,160,1,432669,A,A,64.810000000,1,26,8058566341852,128,14699,94302356,CLX5
2025-09-24T19:35:48.017750261Z,2025-09-24T19:35:48.017541643Z,160,1,432669,M,A,65.980000000,3,26,8058566321460,128,14863,94302382,CLX5
2025-09-24T19:35:48.201583690Z,2025-09-24T19:35:48.201445321Z,160,1,432669,M,A,64.830000000,3,26,8058566321460,128,17783,94302407,CLX5
2025-09-24T19:35:54.297303873Z,2025-09-24T19:35:54.297185753Z,160,1,432669,C,B,64.670000000,1,26,8058564139889,128,18952,94303077,CLX5
2025-09-24T19:35:55.378186332Z,2025-09-24T19:35:55.378005547Z,160,1,432669,C,A,64.820000000,1,26,8058566339448,128,21330,94303084,CLX5
2025-09-24T19:35:55.378540798Z,2025-09-24T19:35:55.378193295Z,160,1,432669,T,B,64.810000000,1,26,8058566342099,0,18042,94303085,CLX5
2025-09-24T19:35:55.378540798Z,2025-09-24T19:35:55.378193295Z,160,1,432669,F,A,64.810000000,1,26,8058566341852,0,18042,94303085,CLX5
2025-09-24T19:35:55.378552395Z,2025-09-24T19:35:55.378193295Z,160,1,432669,C,A,64.810000000,1,26,8058566341852,128,16980,94303086,CLX5
2025-09-24T19:35:55.379137703Z,2025-09-24T19:35:55.378829999Z,160,1,432669,M,A,64.840000000,4,26,8058566331622,128,19022,94303110,CLX5
2025-09-24T19:35:55.379373973Z,2025-09-24T19:35:55.379045431Z,160,1,432669,A,B,64.800000000,1,26,8058566342106,128,18839,94303121,CLX5
2025-09-24T19:35:55.379428683Z,2025-09-24T19:35:55.379166097Z,160,1,432669,A,B,64.800000000,1,26,8058566342108,128,15181,94303123,CLX5
2025-09-24T19:35:55.379521675Z,2025-09-24T19:35:55.379401557Z,160,1,432669,A,B,64.800000000,1,26,8058566342109,128,18135,94303125,CLX5
2025-09-24T19:35:55.416446939Z,2025-09-24T19:35:55.416340363Z,160,1,432669,A,A,65.700000000,6,26,8058566342111,128,18727,94303134,CLX5
2025-09-24T19:35:55.451892750Z,2025-09-24T19:35:55.451767389Z,160,1,432669,C,B,64.800000000,1,26,8058566342109,128,15061,94303157,CLX5
2025-09-24T19:35:55.451929374Z,2025-09-24T19:35:55.451779389Z,160,1,432669,C,B,64.800000000,1,26,8058566342108,128,18686,94303158,CLX5
2025-09-24T19:35:55.452044268Z,2025-09-24T19:35:55.451924935Z,160,1,432669,C,B,64.800000000,1,26,8058566342106,128,18083,94303159,CLX5
2025-09-24T19:35:55.616415444Z,2025-09-24T19:35:55.616307317Z,160,1,432669,C,A,65.700000000,6,26,8058566342111,128,18844,94303164,CLX5
2025-09-24T19:35:57.423520552Z,2025-09-24T19:35:57.423333575Z,160,1,432669,A,A,64.820000000,1,26,8058566342118,128,18445,94303170,CLX5
2025-09-24T19:35:58.961519096Z,2025-09-24T19:35:58.961285303Z,160,1,432669,A,A,64.810000000,1,26,8058566342123,128,18884,94303188,CLX5
2025-09-24T19:35:58.961646946Z,2025-09-24T19:35:58.961519225Z,160,1,432669,A,A,64.820000000,1,26,8058566342124,128,18748,94303191,CLX5
2025-09-24T19:35:58.962270821Z,2025-09-24T19:35:58.962129315Z,160,1,432669,A,A,64.810000000,1,26,8058566342126,128,18191,94303199,CLX5
2025-09-24T19:35:58.962293346Z,2025-09-24T19:35:58.962129493Z,160,1,432669,A,A,64.810000000,1,26,8058566342127,128,15246,94303201,CLX5
2025-09-24T19:35:58.962421457Z,2025-09-24T19:35:58.962170365Z,160,1,432669,M,A,65.970000000,3,26,8058566331622,128,14580,94303206,CLX5
2025-09-24T19:35:58.962927972Z,2025-09-24T19:35:58.962430569Z,160,1,432669,C,A,64.810000000,1,26,8058566342127,128,13607,94303219,CLX5
2025-09-24T19:35:58.963008869Z,2025-09-24T19:35:58.962588733Z,160,1,432669,C,A,64.810000000,1,26,8058566342126,128,17977,94303223,CLX5
2025-09-24T19:35:58.963030894Z,2025-09-24T19:35:58.962624653Z,160,1,432669,C,A,64.810000000,1,26,8058566342123,128,15337,94303225,CLX5
2025-09-24T19:35:58.963420641Z,2025-09-24T19:35:58.963300831Z,160,1,432669,M,A,64.840000000,4,26,8058566331102,128,18712,94303233,CLX5
2025-09-24T19:35:58.963838265Z,2025-09-24T19:35:58.963601105Z,160,1,432669,M,A,64.930000000,1,26,8058565075241,128,17146,94303244,CLX5
2025-09-24T19:35:58.963974171Z,2025-09-24T19:35:58.963629749Z,160,1,432669,M,B,63.640000000,3,26,8058566221991,128,18267,94303247,CLX5
2025-09-24T19:35:58.978185603Z,2025-09-24T19:35:58.978081949Z,160,1,432669,A,A,65.960000000,4,26,8058566342145,128,18303,94303275,CLX5
2025-09-24T19:35:59.064997377Z,2025-09-24T19:35:59.064787687Z,160,1,432669,M,A,64.940000000,1,26,8058565075241,128,14885,94303300,CLX5
2025-09-24T19:35:59.715685510Z,2025-09-24T19:35:59.715514123Z,160,1,432669,A,B,64.780000000,1,26,8058566342164,128,20242,94303346,CLX5
2025-09-24T19:35:59.780048327Z,2025-09-24T19:35:59.779890343Z,160,1,432669,M,B,64.750000000,1,26,8058566197138,128,18800,94303347,CLX5
2025-09-24T19:36:00.024939709Z,2025-09-24T19:36:00.024788961Z,160,1,432669,A,B,64.800000000,1,26,8058566342166,128,18883,94303350,CLX5
2025-09-24T19:36:00.025096979Z,2025-09-24T19:36:00.024959045Z,160,1,432669,C,A,64.820000000,1,26,8058566342124,128,18535,94303351,CLX5
2025-09-24T19:36:02.691010046Z,2025-09-24T19:36:02.690834215Z,160,1,432669,A,A,64.820000000,1,26,8058566342307,128,22338,94303694,CLX5
2025-09-24T19:36:03.047041854Z,2025-09-24T19:36:03.046763243Z,160,1,432669,A,B,64.810000000,1,26,8058566342310,128,22080,94303700,CLX5
2025-09-24T19:36:03.047063403Z,2025-09-24T19:36:03.046768657Z,160,1,432669,C,A,64.820000000,1,26,8058566342307,128,17680,94303702,CLX5
2025-09-24T19:36:03.047329624Z,2025-09-24T19:36:03.047055071Z,160,1,432669,A,B,64.810000000,1,26,8058566342313,128,17159,94303709,CLX5
2025-09-24T19:36:03.047347741Z,2025-09-24T19:36:03.047079375Z,160,1,432669,C,A,64.820000000,2,26,8058566341845,128,16404,94303711,CLX5
2025-09-24T19:36:03.047452352Z,2025-09-24T19:36:03.047101263Z,160,1,432669,A,B,64.810000000,1,26,8058566342315,128,17329,94303714,CLX5
2025-09-24T19:36:03.047646200Z,2025-09-24T19:36:03.047355807Z,160,1,432669,M,A,65.980000000,4,26,8058566321460,128,18447,94303727,CLX5
2025-09-24T19:36:03.047678401Z,2025-09-24T19:36:03.047460173Z,160,1,432669,C,B,64.800000000,1,26,8058566342166,128,15142,94303728,CLX5
2025-09-24T19:36:03.047709380Z,2025-09-24T19:36:03.047544053Z,160,1,432669,M,B,64.800000000,3,26,8058566221991,128,14828,94303729,CLX5
2025-09-24T19:36:03.047828491Z,2025-09-24T19:36:03.047707265Z,160,1,432669,A,B,64.800000000,1,26,8058566342317,128,17970,94303731,CLX5
2025-09-24T19:36:03.048312912Z,2025-09-24T19:36:03.048175859Z,160,1,432669,A,B,64.810000000,1,26,8058566342318,128,22921,94303732,CLX5
2025-09-24T19:36:03.080669320Z,2025-09-24T19:36:03.080346191Z,160,1,432669,T,A,64.810000000,1,26,8058566342330,0,18720,94303762,CLX5
2025-09-24T19:36:03.080669320Z,2025-09-24T19:36:03.080346191Z,160,1,432669,F,B,64.810000000,1,26,8058566342310,0,18720,94303762,CLX5
2025-09-24T19:36:03.080677998Z,2025-09-24T19:36:03.080346191Z,160,1,432669,C,B,64.810000000,1,26,8058566342310,128,14749,94303763,CLX5
2025-09-24T19:36:03.080807169Z,2025-09-24T19:36:03.080669409Z,160,1,432669,A,A,64.820000000,2,26,8058566342331,128,18668,94303765,CLX5
2025-09-24T19:36:03.728427952Z,2025-09-24T19:36:03.728236491Z,160,1,432669,A,B,64.810000000,1,26,8058566342375,128,21838,94303904,CLX5
2025-09-24T19:36:03.728570124Z,2025-09-24T19:36:03.728437985Z,160,1,432669,C,A,64.820000000,2,26,8058566342331,128,18956,94303905,CLX5
2025-09-24T19:36:03.728602186Z,2025-09-24T19:36:03.728470009Z,160,1,432669,C,B,64.800000000,1,26,8058566342317,128,15007,94303906,CLX5
2025-09-24T19:36:04.089745745Z,2025-09-24T19:36:04.089366839Z,160,1,432669,T,A,64.810000000,3,26,8058566342386,0,19649,94303921,CLX5
2025-09-24T19:36:04.089745745Z,2025-09-24T19:36:04.089366839Z,160,1,432669,F,B,64.810000000,1,26,8058566342315,0,19649,94303921,CLX5
2025-09-24T19:36:04.089745745Z,2025-09-24T19:36:04.089366839Z,160,1,432669,F,B,64.810000000,1,26,8058566342318,0,19649,94303921,CLX5
2025-09-24T19:36:04.089745745Z,2025-09-24T19:36:04.089366839Z,160,1,432669,F,B,64.810000000,1,26,8058566342375,0,19649,94303921,CLX5
2025-09-24T19:36:04.089756604Z,2025-09-24T19:36:04.089366839Z,160,1,432669,C,B,64.810000000,1,26,8058566342315,0,14807,94303922,CLX5
2025-09-24T19:36:04.089756604Z,2025-09-24T19:36:04.089366839Z,160,1,432669,C,B,64.810000000,1,26,8058566342318,0,14807,94303922,CLX5
2025-09-24T19:36:04.089756604Z,2025-09-24T19:36:04.089366839Z,160,1,432669,C,B,64.810000000,1,26,8058566342375,0,14807,94303922,CLX5
2025-09-24T19:36:04.089756604Z,2025-09-24T19:36:04.089366839Z,160,1,432669,C,B,64.810000000,1,26,8058566342313,128,14807,94303922,CLX5
2025-09-24T19:36:04.090013939Z,2025-09-24T19:36:04.089392201Z,160,1,432669,A,A,64.820000000,1,26,8058566342390,128,18064,94303931,CLX5
2025-09-24T19:36:04.090562562Z,2025-09-24T19:36:04.089397713Z,160,1,432669,A,A,64.810000000,2,26,8058566342398,128,18014,94303949,CLX5
2025-09-24T19:36:04.090915593Z,2025-09-24T19:36:04.089421077Z,160,1,432669,A,A,64.810000000,1,26,8058566342403,128,18004,94303963,CLX5
2025-09-24T19:36:04.091074553Z,2025-09-24T19:36:04.089473759Z,160,1,432669,A,A,64.820000000,2,26,8058566342405,128,14319,94303971,CLX5
2025-09-24T19:36:04.091120592Z,2025-09-24T19:36:04.089487373Z,160,1,432669,A,A,64.810000000,2,26,8058566342407,128,14529,94303972,CLX5
2025-09-24T19:36:04.091946149Z,2025-09-24T19:36:04.089771729Z,160,1,432669,C,A,64.810000000,1,26,8058566342403,128,21500,94303998,CLX5
2025-09-24T19:36:04.092210481Z,2025-09-24T19:36:04.089915147Z,160,1,432669,M,A,64.930000000,1,26,8058565075241,128,14708,94304014,CLX5
2025-09-24T19:36:04.092351993Z,2025-09-24T19:36:04.090053075Z,160,1,432669,M,B,63.640000000,3,26,8058566221991,128,18648,94304018,CLX5
2025-09-24T19:36:04.092460537Z,2025-09-24T19:36:04.090169287Z,160,1,432669,A,A,64.820000000,1,26,8058566342425,128,14176,94304022,CLX5
2025-09-24T19:36:04.092699933Z,2025-09-24T19:36:04.090333977Z,160,1,432669,C,A,64.810000000,2,26,8058566342407,128,14706,94304034,CLX5
2025-09-24T19:36:04.093300208Z,2025-09-24T19:36:04.090565441Z,160,1,432669,T,B,64.810000000,1,26,8058566342430,0,16817,94304057,CLX5
2025-09-24T19:36:04.093300208Z,2025-09-24T19:36:04.090565441Z,160,1,432669,F,A,64.810000000,1,26,8058566342398,0,16817,94304057,CLX5
2025-09-24T19:36:04.093330373Z,2025-09-24T19:36:04.090565441Z,160,1,432669,M,A,64.810000000,1,26,8058566342398,128,14538,94304058,CLX5
2025-09-24T19:36:04.093360101Z,2025-09-24T19:36:04.090565623Z,160,1,432669,T,B,64.810000000,1,26,8058566342431,0,14637,94304061,CLX5
2025-09-24T19:36:04.093360101Z,2025-09-24T19:36:04.090565623Z,160,1,432669,F,A,64.810000000,1,26,8058566342398,0,14637,94304061,CLX5
2025-09-24T19:36:04.093360101Z,2025-09-24T19:36:04.090565623Z,160,1,432669,C,A,64.810000000,1,26,8058566342398,128,14637,94304061,CLX5
2025-09-24T19:36:04.093854890Z,2025-09-24T19:36:04.090879771Z,160,1,432669,M,A,64.830000000,3,26,8058566321460,128,14041,94304084,CLX5
2025-09-24T19:36:04.094061863Z,2025-09-24T19:36:04.091034081Z,160,1,432669,C,A,64.820000000,1,26,8058566342390,128,15119,94304091,CLX5
2025-09-24T19:36:04.094844882Z,2025-09-24T19:36:04.091754465Z,160,1,432669,A,B,64.810000000,1,26,8058566342454,128,14504,94304121,CLX5
2025-09-24T19:36:04.095057238Z,2025-09-24T19:36:04.091880259Z,160,1,432669,A,B,64.810000000,1,26,8058566342459,128,14739,94304130,CLX5
2025-09-24T19:36:04.095105889Z,2025-09-24T19:36:04.091897459Z,160,1,432669,M,A,64.940000000,1,26,8058565075241,128,14868,94304134,CLX5
2025-09-24T19:36:04.095208081Z,2025-09-24T19:36:04.092032621Z,160,1,432669,A,B,64.810000000,1,26,8058566342461,128,14733,94304137,CLX5
2025-09-24T19:36:04.095584757Z,2025-09-24T19:36:04.093308561Z,160,1,432669,A,B,64.770000000,1,26,8058566342468,128,18150,94304156,CLX5
2025-09-24T19:36:04.095667997Z,2025-09-24T19:36:04.093379751Z,160,1,432669,C,A,64.820000000,2,26,8058566342405,128,15155,94304161,CLX5
2025-09-24T19:36:04.096260870Z,2025-09-24T19:36:04.094878495Z,160,1,432669,A,B,64.810000000,1,26,8058566342476,128,24074,94304187,CLX5
2025-09-24T19:36:04.096486842Z,2025-09-24T19:36:04.095107847Z,160,1,432669,M,A,65.980000000,4,26,8058566321460,128,14666,94304200,CLX5
2025-09-24T19:36:04.165505268Z,2025-09-24T19:36:04.165367839Z,160,1,432669,C,B,64.770000000,1,26,8058566342468,128,16662,94304400,CLX5
2025-09-24T19:36:04.178576235Z,2025-09-24T19:36:04.178419115Z,160,1,432669,C,B,64.810000000,1,26,8058566342476,128,24365,94304405,CLX5
2025-09-24T19:36:04.280402327Z,2025-09-24T19:36:04.280255609Z,160,1,432669,C,B,64.800000000,1,26,8058566339497,128,18627,94304451,CLX5
2025-09-24T19:36:04.653011253Z,2025-09-24T19:36:04.652892087Z,160,1,432669,C,A,65.010000000,1,26,8058566333574,128,17935,94304649,CLX5
2025-09-24T19:36:04.746790479Z,2025-09-24T19:36:04.746674153Z,160,1,432669,A,A,64.990000000,1,26,8058566342642,128,18361,94304683,CLX5
2025-09-24T19:36:05.788154238Z,2025-09-24T19:36:05.788006095Z,160,1,432669,M,B,64.790000000,1,26,8058566197138,128,18334,94304852,CLX5
2025-09-24T19:36:06.008774317Z,2025-09-24T19:36:06.008485079Z,160,1,432669,T,A,64.810000000,1,26,8058566342710,0,19217,94304855,CLX5
2025-09-24T19:36:06.008774317Z,2025-09-24T19:36:06.008485079Z,160,1,432669,F,B,64.810000000,1,26,8058566342454,0,19217,94304855,CLX5
2025-09-24T19:36:06.008784761Z,2025-09-24T19:36:06.008485079Z,160,1,432669,C,B,64.810000000,1,26,8058566342454,128,16403,94304856,CLX5
2025-09-24T19:36:07.250384567Z,2025-09-24T19:36:07.250079341Z,160,1,432669,T,A,64.810000000,1,26,8058566342718,0,20092,94304868,CLX5
2025-09-24T19:36:07.250384567Z,2025-09-24T19:36:07.250079341Z,160,1,432669,F,B,64.810000000,1,26,8058566342459,0,20092,94304868,CLX5
2025-09-24T19:36:07.250392838Z,2025-09-24T19:36:07.250079341Z,160,1,432669,C,B,64.810000000,1,26,8058566342459,128,14554,94304869,CLX5
2025-09-24T19:36:07.284481478Z,2025-09-24T19:36:07.284193145Z,160,1,432669,T,A,64.810000000,1,26,8058566342719,0,19186,94304872,CLX5
2025-09-24T19:36:07.284481478Z,2025-09-24T19:36:07.284193145Z,160,1,432669,F,B,64.810000000,1,26,8058566342461,0,19186,94304872,CLX5
2025-09-24T19:36:07.284492575Z,2025-09-24T19:36:07.284193145Z,160,1,432669,C,B,64.810000000,1,26,8058566342461,128,16755,94304873,CLX5
2025-09-24T19:36:07.285136211Z,2025-09-24T19:36:07.284887809Z,160,1,432669,A,A,64.820000000,2,26,8058566342729,128,18278,94304895,CLX5
2025-09-24T19:36:07.404697360Z,2025-09-24T19:36:07.404463379Z,160,1,432669,A,B,64.810000000,1,26,8058566342739,128,18142,94304923,CLX5
2025-09-24T19:36:07.404880166Z,2025-09-24T19:36:07.404717305Z,160,1,432669,C,A,64.820000000,2,26,8058566342729,128,16817,94304928,CLX5
2025-09-24T19:36:08.638896818Z,2025-09-24T19:36:08.638723793Z,160,1,432669,A,B,64.800000000,1,26,8058566342783,128,22417,94305058,CLX5
2025-09-24T19:36:08.639172308Z,2025-09-24T19:36:08.639041769Z,160,1,432669,M,B,64.800000000,3,26,8058566221991,128,20293,94305059,CLX5
2025-09-24T19:36:10.060269347Z,2025-09-24T19:36:10.059998673Z,160,1,432669,A,B,64.810000000,1,26,8058566342788,128,16564,94305076,CLX5
2025-09-24T19:36:10.060481488Z,2025-09-24T19:36:10.060269533Z,160,1,432669,A,B,64.810000000,1,26,8058566342790,128,21218,94305083,CLX5
2025-09-24T19:36:10.060599646Z,2025-09-24T19:36:10.060324463Z,160,1,432669,A,B,64.810000000,2,26,8058566342791,128,17702,94305089,CLX5
2025-09-24T19:36:10.060651921Z,2025-09-24T19:36:10.060367949Z,160,1,432669,T,A,64.810000000,1,26,8058566342792,0,17654,94305091,CLX5
2025-09-24T19:36:10.060651921Z,2025-09-24T19:36:10.060367949Z,160,1,432669,F,B,64.810000000,1,26,8058566342739,0,17654,94305091,CLX5
2025-09-24T19:36:10.060651921Z,2025-09-24T19:36:10.060367949Z,160,1,432669,C,B,64.810000000,1,26,8058566342739,128,17654,94305091,CLX5
2025-09-24T19:36:10.116609360Z,2025-09-24T19:36:10.116501223Z,160,1,432669,A,A,65.700000000,6,26,8058566342860,128,18114,94305310,CLX5
2025-09-24T19:36:11.594085891Z,2025-09-24T19:36:11.593774185Z,160,1,432669,T,A,64.810000000,1,26,8058566342912,0,17788,94305461,CLX5
2025-09-24T19:36:11.594085891Z,2025-09-24T19:36:11.593774185Z,160,1,432669,F,B,64.810000000,1,26,8058566342788,0,17788,94305461,CLX5
2025-09-24T19:36:11.594094807Z,2025-09-24T19:36:11.593774185Z,160,1,432669,C,B,64.810000000,1,26,8058566342788,128,14702,94305462,CLX5
2025-09-24T19:36:11.783324349Z,2025-09-24T19:36:11.783082635Z,160,1,432669,A,B,64.810000000,2,26,8058566342945,128,17582,94305568,CLX5
2025-09-24T19:36:12.064312002Z,2025-09-24T19:36:12.064154937Z,160,1,432669,C,B,64.810000000,2,26,8058566342945,128,22261,94305646,CLX5
2025-09-24T19:36:12.725078897Z,2025-09-24T19:36:12.724923683Z,160,1,432669,A,B,64.760000000,35,26,8058566342993,128,18594,94305668,CLX5
2025-09-24T19:36:12.725238233Z,2025-09-24T19:36:12.725092713Z,160,1,432669,A,B,64.810000000,2,26,8058566342994,128,22698,94305669,CLX5
2025-09-24T19:36:12.725270679Z,2025-09-24T19:36:12.725109781Z,160,1,432669,A,B,64.810000000,2,26,8058566342995,128,16503,94305670,CLX5
2025-09-24T19:36:12.725370461Z,2025-09-24T19:36:12.725243561Z,160,1,432669,A,B,64.810000000,1,26,8058566342996,128,19282,94305671,CLX5
2025-09-24T19:36:12.725427889Z,2025-09-24T19:36:12.725273357Z,160,1,432669,C,A,64.820000000,1,26,8058566338004,128,15060,94305674,CLX5
2025-09-24T19:36:12.725488849Z,2025-09-24T19:36:12.725275161Z,160,1,432669,A,B,64.810000000,1,26,8058566342997,128,18828,94305676,CLX5
2025-09-24T19:36:12.725613136Z,2025-09-24T19:36:12.725376169Z,160,1,432669,A,B,64.810000000,1,26,8058566342999,128,15857,94305680,CLX5
2025-09-24T19:36:12.727354215Z,2025-09-24T19:36:12.726255125Z,160,1,432669,C,A,64.820000000,1,26,8058566338002,128,19432,94305758,CLX5
2025-09-24T19:36:12.727387268Z,2025-09-24T19:36:12.726258331Z,160,1,432669,A,B,64.810000000,1,26,8058566343019,128,15505,94305759,CLX5
2025-09-24T19:36:12.727459088Z,2025-09-24T19:36:12.726258987Z,160,1,432669,A,B,64.810000000,1,26,8058566343021,128,15298,94305762,CLX5
2025-09-24T19:36:12.727504873Z,2025-09-24T19:36:12.726259271Z,160,1,432669,A,B,64.810000000,1,26,8058566343022,128,15153,94305764,CLX5
2025-09-24T19:36:12.727534448Z,2025-09-24T19:36:12.726260367Z,160,1,432669,C,A,64.850000000,2,26,8058566338063,128,14809,94305765,CLX5
2025-09-24T19:36:12.727650402Z,2025-09-24T19:36:12.726280103Z,160,1,432669,A,B,64.810000000,1,26,8058566343024,128,15152,94305769,CLX5
2025-09-24T19:36:12.728055148Z,2025-09-24T19:36:12.726430951Z,160,1,432669,A,B,64.810000000,2,26,8058566343029,128,15600,94305786,CLX5
2025-09-24T19:36:12.728663034Z,2025-09-24T19:36:12.726602937Z,160,1,432669,A,B,64.800000000,2,26,8058566343037,128,18348,94305813,CLX5
2025-09-24T19:36:12.728791659Z,2025-09-24T19:36:12.726608679Z,160,1,432669,C,A,64.820000000,3,26,8058566335916,128,18798,94305818,CLX5
2025-09-24T19:36:12.729205536Z,2025-09-24T19:36:12.727207191Z,160,1,432669,C,B,64.810000000,1,26,8058566343019,128,15433,94305836,CLX5
2025-09-24T19:36:12.729291831Z,2025-09-24T19:36:12.727223799Z,160,1,432669,C,B,64.810000000,1,26,8058566343022,128,18459,94305840,CLX5
2025-09-24T19:36:12.729326405Z,2025-09-24T19:36:12.727273371Z,160,1,432669,C,B,64.800000000,2,26,8058566343037,128,16057,94305841,CLX5
2025-09-24T19:36:12.729505117Z,2025-09-24T19:36:12.727360363Z,160,1,432669,A,A,64.820000000,1,26,8058566343048,128,15330,94305848,CLX5
2025-09-24T19:36:12.729551141Z,2025-09-24T19:36:12.727379447Z,160,1,432669,A,B,64.810000000,1,26,8058566343049,128,19366,94305850,CLX5
2025-09-24T19:36:12.729583349Z,2025-09-24T19:36:12.727384267Z,160,1,432669,C,A,64.820000000,1,26,8058566343048,128,15388,94305851,CLX5
2025-09-24T19:36:12.729666511Z,2025-09-24T19:36:12.727474483Z,160,1,432669,C,A,64.820000000,1,26,8058566337966,128,18057,94305853,CLX5
2025-09-24T19:36:12.729740742Z,2025-09-24T19:36:12.727593709Z,160,1,432669,A,B,64.810000000,1,26,8058566343050,128,14902,94305855,CLX5
2025-09-24T19:36:12.729774425Z,2025-09-24T19:36:12.727629363Z,160,1,432669,C,B,64.810000000,1,26,8058566343050,128,18276,94305856,CLX5
2025-09-24T19:36:12.729805327Z,2025-09-24T19:36:12.727781975Z,160,1,432669,A,A,64.820000000,1,26,8058566343051,128,15324,94305857,CLX5
2025-09-24T19:36:12.729854538Z,2025-09-24T19:36:12.727815653Z,160,1,432669,C,A,64.820000000,1,26,8058566343051,128,15074,94305859,CLX5
2025-09-24T19:36:12.730475649Z,2025-09-24T19:36:12.728814889Z,160,1,432669,T,B,64.820000000,3,26,8058566343060,0,14754,94305897,CLX5
2025-09-24T19:36:12.730475649Z,2025-09-24T19:36:12.728814889Z,160,1,432669,F,A,64.820000000,2,26,8058566335813,0,14754,94305897,CLX5
2025-09-24T19:36:12.730475649Z,2025-09-24T19:36:12.728814889Z,160,1,432669,F,A,64.820000000,1,26,8058566335826,0,14754,94305897,CLX5
2025-09-24T19:36:12.730475649Z,2025-09-24T19:36:12.728814889Z,160,1,432669,C,A,64.820000000,2,26,8058566335813,0,14754,94305897,CLX5
2025-09-24T19:36:12.730475649Z,2025-09-24T19:36:12.728814889Z,160,1,432669,C,A,64.820000000,1,26,8058566335826,128,14754,94305897,CLX5
2025-09-24T19:36:12.730824963Z,2025-09-24T19:36:12.729005173Z,160,1,432669,M,B,64.810000000,2,26,8058566319851,128,15007,94305918,CLX5
2025-09-24T19:36:12.730981996Z,2025-09-24T19:36:12.729092525Z,160,1,432669,C,A,64.820000000,2,26,8058566335833,128,16161,94305924,CLX5
2025-09-24T19:36:12.731309023Z,2025-09-24T19:36:12.729101591Z,160,1,432669,A,B,64.810000000,1,26,8058566343069,128,15131,94305938,CLX5
2025-09-24T19:36:12.731356829Z,2025-09-24T19:36:12.729104241Z,160,1,432669,A,B,64.810000000,1,26,8058566343070,128,18666,94305940,CLX5
2025-09-24T19:36:12.731729397Z,2025-09-24T19:36:12.729505177Z,160,1,432669,A,A,64.830000000,1,26,8058566343075,128,16787,94305961,CLX5
2025-09-24T19:36:12.731802883Z,2025-09-24T19:36:12.729747357Z,160,1,432669,C,A,64.850000000,1,26,8058566336056,128,14592,94305965,CLX5
2025-09-24T19:36:12.732587446Z,2025-09-24T19:36:12.730504379Z,160,1,432669,C,B,64.810000000,1,26,8058566343070,128,14609,94306012,CLX5
2025-09-24T19:36:12.733545468Z,2025-09-24T19:36:12.731364693Z,160,1,432669,C,B,64.810000000,1,26,8058566343069,128,19138,94306070,CLX5
2025-09-24T19:36:12.735969702Z,2025-09-24T19:36:12.733851137Z,160,1,432669,M,A,64.830000000,1,26,8058566331891,128,17258,94306205,CLX5
2025-09-24T19:36:12.742086854Z,2025-09-24T19:36:12.741954233Z,160,1,432669,A,B,64.810000000,1,26,8058566343148,128,17875,94306336,CLX5
2025-09-24T19:36:12.742248762Z,2025-09-24T19:36:12.742112031Z,160,1,432669,A,B,64.810000000,1,26,8058566343150,128,14712,94306339,CLX5
2025-09-24T19:36:12.776515209Z,2025-09-24T19:36:12.776404253Z,160,1,432669,C,B,64.710000000,1,26,8058566339705,128,19591,94306368,CLX5
2025-09-24T19:36:12.777172636Z,2025-09-24T19:36:12.777039401Z,160,1,432669,A,B,64.800000000,2,26,8058566343166,128,18849,94306369,CLX5
2025-09-24T19:36:12.791976103Z,2025-09-24T19:36:12.791829277Z,160,1,432669,C,B,64.800000000,2,26,8058566343166,128,15014,94306427,CLX5
2025-09-24T19:36:12.792183222Z,2025-09-24T19:36:12.792004103Z,160,1,432669,A,B,64.810000000,1,26,8058566343184,128,14743,94306437,CLX5
2025-09-24T19:36:12.811310080Z,2025-09-24T19:36:12.811172903Z,160,1,432669,A,A,64.870000000,2,26,8058566343201,128,18634,94306464,CLX5
2025-09-24T19:36:12.816824691Z,2025-09-24T19:36:12.816720921Z,160,1,432669,A,A,65.900000000,1,26,8058566343202,128,17827,94306465,CLX5
2025-09-24T19:36:12.910979777Z,2025-09-24T19:36:12.910840391Z,160,1,432669,A,B,64.770000000,2,26,8058566343229,128,18886,94306534,CLX5
2025-09-24T19:36:12.927178448Z,2025-09-24T19:36:12.927025911Z,160,1,432669,A,B,64.800000000,2,26,8058566343232,128,18141,94306539,CLX5
2025-09-24T19:36:12.927222713Z,2025-09-24T19:36:12.927030441Z,160,1,432669,C,B,64.770000000,2,26,8058566343229,128,13809,94306542,CLX5
2025-09-24T19:36:12.927368426Z,2025-09-24T19:36:12.927251999Z,160,1,432669,C,B,64.810000000,1,26,8058566343184,128,14914,94306547,CLX5
2025-09-24T19:36:13.010951567Z,2025-09-24T19:36:13.010812031Z,160,1,432669,C,B,64.780000000,2,26,8058566337984,128,18475,94306573,CLX5
2025-09-24T19:36:13.011110888Z,2025-09-24T19:36:13.010985901Z,160,1,432669,C,B,64.780000000,1,26,8058566342164,128,17698,94306574,CLX5
2025-09-24T19:36:13.542711388Z,2025-09-24T19:36:13.542564217Z,160,1,432669,C,B,64.810000000,1,26,8058566343150,128,17872,94306586,CLX5
2025-09-24T19:36:13.542738589Z,2025-09-24T19:36:13.542571935Z,160,1,432669,C,B,64.810000000,1,26,8058566343148,128,14921,94306587,CLX5
2025-09-24T19:36:17.527296053Z,2025-09-24T19:36:17.527125383Z,160,1,432669,M,A,64.950000000,1,26,8058565075241,128,14879,94306759,CLX5
2025-09-24T19:36:17.527929919Z,2025-09-24T19:36:17.527747917Z,160,1,432669,M,B,64.790000000,3,26,8058566335785,128,14832,94306778,CLX5
2025-09-24T19:36:17.638384545Z,2025-09-24T19:36:17.638270451Z,160,1,432669,M,A,64.940000000,1,26,8058565075241,128,14176,94306804,CLX5
2025-09-24T19:36:18.048432885Z,2025-09-24T19:36:18.046090371Z,160,1,432669,M,A,64.950000000,1,26,8058565075241,128,18689,94307149,CLX5
2025-09-24T19:36:18.050341956Z,2025-09-24T19:36:18.048466421Z,160,1,432669,C,A,64.820000000,3,26,8058566337340,128,20413,94307269,CLX5
2025-09-24T19:36:18.056400075Z,2025-09-24T19:36:18.056008653Z,160,1,432669,M,A,64.940000000,1,26,8058565075241,128,16231,94307523,CLX5
2025-09-24T19:36:18.057572919Z,2025-09-24T19:36:18.056902701Z,160,1,432669,M,B,64.810000000,1,26,8058566337316,128,15834,94307574,CLX5
2025-09-24T19:36:18.058519936Z,2025-09-24T19:36:18.058095007Z,160,1,432669,M,A,64.950000000,1,26,8058565075241,128,15610,94307631,CLX5
2025-09-24T19:36:18.077659726Z,2025-09-24T19:36:18.077509901Z,160,1,432669,M,A,64.940000000,1,26,8058565075241,128,14258,94307866,CLX5
2025-09-24T19:36:18.079825565Z,2025-09-24T19:36:18.079660551Z,160,1,432669,M,A,64.820000000,1,26,8058566331891,128,21158,94307890,CLX5
2025-09-24T19:36:18.083386202Z,2025-09-24T19:36:18.083181465Z,160,1,432669,A,A,64.820000000,1,26,8058566343791,128,20417,94307922,CLX5
2025-09-24T19:36:18.083915840Z,2025-09-24T19:36:18.083785719Z,160,1,432669,C,A,64.820000000,1,26,8058566343791,128,19367,94307938,CLX5
2025-09-24T19:36:18.163156986Z,2025-09-24T19:36:18.162994955Z,160,1,432669,M,A,64.830000000,1,26,8058566331891,128,20804,94308024,CLX5
2025-09-24T19:36:22.496836585Z,2025-09-24T19:36:22.496647629Z,160,1,432669,A,A,64.820000000,1,26,8058566343993,128,21375,94308303,CLX5
2025-09-24T19:36:24.051280031Z,2025-09-24T19:36:24.051123009Z,160,1,432669,C,B,64.780000000,1,26,8058566338999,128,21764,94308342,CLX5
2025-09-24T19:36:29.718625113Z,2025-09-24T19:36:29.718392195Z,160,1,432669,A,A,64.820000000,2,26,8058566344015,128,22495,94308425,CLX5
2025-09-24T19:36:29.718658419Z,2025-09-24T19:36:29.718460371Z,160,1,432669,A,A,64.820000000,1,26,8058566344016,128,16097,94308426,CLX5
2025-09-24T19:36:29.719037001Z,2025-09-24T19:36:29.718717005Z,160,1,432669,A,A,64.820000000,1,26,8058566344020,128,15790,94308435,CLX5
2025-09-24T19:36:29.757742969Z,2025-09-24T19:36:29.757577089Z,160,1,432669,M,B,64.710000000,35,26,8058566342993,128,19423,94308448,CLX5
2025-09-24T19:36:29.759187678Z,2025-09-24T19:36:29.759047381Z,160,1,432669,C,A,64.820000000,1,26,8058566344020,128,19384,94308451,CLX5
2025-09-24T19:36:31.101154744Z,2025-09-24T19:36:31.100962975Z,160,1,432669,A,A,64.850000000,1,26,8058566344029,128,14515,94308463,CLX5
2025-09-24T19:36:31.101196798Z,2025-09-24T19:36:31.100964665Z,160,1,432669,C,B,64.810000000,1,26,8058566343049,128,18298,94308464,CLX5
2025-09-24T19:36:31.101260999Z,2025-09-24T19:36:31.100978085Z,160,1,432669,A,A,64.820000000,1,26,8058566344031,128,16247,94308466,CLX5
2025-09-24T19:36:31.101618331Z,2025-09-24T19:36:31.101205153Z,160,1,432669,A,A,64.820000000,1,26,8058566344032,128,17874,94308480,CLX5
2025-09-24T19:36:31.101669254Z,2025-09-24T19:36:31.101207669Z,160,1,432669,A,A,64.820000000,2,26,8058566344033,128,15560,94308482,CLX5
2025-09-24T19:36:31.102008078Z,2025-09-24T19:36:31.101546535Z,160,1,432669,A,A,64.820000000,1,26,8058566344036,128,15730,94308491,CLX5
2025-09-24T19:36:31.102084237Z,2025-09-24T19:36:31.101552447Z,160,1,432669,A,A,64.820000000,1,26,8058566344038,128,15775,94308494,CLX5
2025-09-24T19:36:31.102133217Z,2025-09-24T19:36:31.101552811Z,160,1,432669,C,B,64.800000000,2,26,8058566343232,128,14857,94308496,CLX5
2025-09-24T19:36:31.102187665Z,2025-09-24T19:36:31.101554747Z,160,1,432669,C,B,64.810000000,2,26,8058566343029,128,14992,94308498,CLX5
2025-09-24T19:36:31.102585860Z,2025-09-24T19:36:31.101578577Z,160,1,432669,C,B,64.810000000,1,26,8058566343021,128,15053,94308508,CLX5
2025-09-24T19:36:31.102675251Z,2025-09-24T19:36:31.101602519Z,160,1,432669,C,B,64.810000000,2,26,8058566342994,128,16148,94308512,CLX5
2025-09-24T19:36:31.102727126Z,2025-09-24T19:36:31.101623695Z,160,1,432669,C,B,64.810000000,1,26,8058566342999,128,15448,94308514,CLX5
2025-09-24T19:36:31.102991773Z,2025-09-24T19:36:31.101844601Z,160,1,432669,M,B,63.650000000,4,26,8058566319851,128,15862,94308524,CLX5
2025-09-24T19:36:31.103816239Z,2025-09-24T19:36:31.102521121Z,160,1,432669,C,B,64.810000000,1,26,8058566342996,128,17956,94308553,CLX5
2025-09-24T19:36:31.104467892Z,2025-09-24T19:36:31.103831215Z,160,1,432669,A,A,64.820000000,1,26,8058566344068,128,18241,94308586,CLX5
2025-09-24T19:36:31.109202079Z,2025-09-24T19:36:31.109061505Z,160,1,432669,M,A,64.820000000,1,26,8058566331891,128,20280,94308600,CLX5
2025-09-24T19:36:31.210995223Z,2025-09-24T19:36:31.210855509Z,160,1,432669,A,B,64.780000000,2,26,8058566344082,128,17903,94308616,CLX5
2025-09-24T19:36:31.211020113Z,2025-09-24T19:36:31.210861155Z,160,1,432669,A,B,64.770000000,2,26,8058566344083,128,14498,94308617,CLX5
2025-09-24T19:36:33.476499154Z,2025-09-24T19:36:33.475878575Z,160,1,432669,C,A,64.940000000,1,26,8058565474962,128,505238,94308654,CLX5
2025-09-24T19:36:34.210015142Z,2025-09-24T19:36:34.208659605Z,160,1,432669,C,B,64.810000000,1,26,8058566342997,128,17111,94308775,CLX5
2025-09-24T19:36:37.543425044Z,2025-09-24T19:36:37.543102277Z,160,1,432669,C,A,64.820000000,1,26,8058566344036,128,17415,94309516,CLX5
2025-09-24T19:36:39.790848060Z,2025-09-24T19:36:39.790673047Z,160,1,432669,C,A,64.820000000,1,26,8058566337813,128,19004,94310003,CLX5
2025-09-24T19:36:39.923886443Z,2025-09-24T19:36:39.923533855Z,160,1,432669,T,A,64.810000000,1,26,8058566344629,0,17538,94310007,CLX5
2025-09-24T19:36:39.923886443Z,2025-09-24T19:36:39.923533855Z,160,1,432669,F,B,64.810000000,1,26,8058566342790,0,17538,94310007,CLX5
2025-09-24T19:36:39.923896833Z,2025-09-24T19:36:39.923533855Z,160,1,432669,C,B,64.810000000,1,26,8058566342790,128,15911,94310008,CLX5
2025-09-24T19:36:49.837393448Z,2025-09-24T19:36:49.837225371Z,160,1,432669,A,B,64.800000000,2,26,8058566344822,128,19678,94310563,CLX5
2025-09-24T19:36:49.837458280Z,2025-09-24T19:36:49.837236005Z,160,1,432669,C,B,64.770000000,2,26,8058566344083,128,15128,94310565,CLX5
2025-09-24T19:36:49.837605252Z,2025-09-24T19:36:49.837254725Z,160,1,432669,C,A,64.820000000,2,26,8058566344033,128,17243,94310570,CLX5
2025-09-24T19:36:49.837731665Z,2025-09-24T19:36:49.837261503Z,160,1,432669,A,B,64.810000000,2,26,8058566344827,128,20471,94310573,CLX5
2025-09-24T19:36:49.837835701Z,2025-09-24T19:36:49.837274943Z,160,1,432669,A,B,64.810000000,1,26,8058566344829,128,19389,94310577,CLX5
2025-09-24T19:36:49.838206050Z,2025-09-24T19:36:49.837613135Z,160,1,432669,A,B,64.810000000,1,26,8058566344836,128,18286,94310592,CLX5
2025-09-24T19:36:49.838239794Z,2025-09-24T19:36:49.837616149Z,160,1,432669,C,B,64.810000000,2,26,8058566344827,128,16062,94310593,CLX5
2025-09-24T19:36:49.838346794Z,2025-09-24T19:36:49.837731479Z,160,1,432669,A,B,64.810000000,1,26,8058566344837,128,16027,94310600,CLX5
2025-09-24T19:36:49.838689019Z,2025-09-24T19:36:49.838149253Z,160,1,432669,A,B,64.810000000,1,26,8058566344842,128,14077,94310619,CLX5
2025-09-24T19:36:49.838793155Z,2025-09-24T19:36:49.838262007Z,160,1,432669,C,A,64.820000000,1,26,8058566344038,128,16195,94310623,CLX5
2025-09-24T19:36:49.839070795Z,2025-09-24T19:36:49.838703839Z,160,1,432669,C,A,64.820000000,1,26,8058566344068,128,16424,94310640,CLX5
2025-09-24T19:36:49.905201435Z,2025-09-24T19:36:49.904997183Z,160,1,432669,C,B,64.800000000,2,26,8058566344822,128,15514,94310718,CLX5
2025-09-24T19:36:49.905235594Z,2025-09-24T19:36:49.904998839Z,160,1,432669,C,B,64.810000000,1,26,8058566344842,128,15061,94310721,CLX5
2025-09-24T19:36:49.905508788Z,2025-09-24T19:36:49.905038257Z,160,1,432669,C,B,64.810000000,1,26,8058566344829,128,17981,94310733,CLX5
2025-09-24T19:36:49.905766723Z,2025-09-24T19:36:49.905074025Z,160,1,432669,A,A,64.820000000,2,26,8058566344866,128,15805,94310741,CLX5
2025-09-24T19:36:49.905999907Z,2025-09-24T19:36:49.905529101Z,160,1,432669,C,A,64.820000000,2,26,8058566344866,128,14704,94310750,CLX5
2025-09-24T19:36:49.906177159Z,2025-09-24T19:36:49.905729041Z,160,1,432669,A,A,64.820000000,1,26,8058566344870,128,16070,94310756,CLX5
2025-09-24T19:36:49.911114157Z,2025-09-24T19:36:49.910978415Z,160,1,432669,C,B,64.780000000,2,26,8058566344082,128,19258,94310758,CLX5
2025-09-24T19:36:49.991656483Z,2025-09-24T19:36:49.991510877Z,160,1,432669,A,B,64.800000000,2,26,8058566344884,128,15244,94310783,CLX5
2025-09-24T19:36:50.241575311Z,2025-09-24T19:36:50.241429303Z,160,1,432669,C,B,64.800000000,2,26,8058566344884,128,19518,94310807,CLX5
2025-09-24T19:36:50.241931951Z,2025-09-24T19:36:50.241604783Z,160,1,432669,T,A,64.810000000,1,26,8058566344899,0,17170,94310815,CLX5
2025-09-24T19:36:50.241931951Z,2025-09-24T19:36:50.241604783Z,160,1,432669,F,B,64.810000000,1,26,8058566342791,0,17170,94310815,CLX5
2025-09-24T19:36:50.241943724Z,2025-09-24T19:36:50.241604783Z,160,1,432669,M,B,64.810000000,1,26,8058566342791,128,16335,94310816,CLX5
2025-09-24T19:36:50.242037477Z,2025-09-24T19:36:50.241895843Z,160,1,432669,A,A,64.820000000,2,26,8058566344901,128,19202,94310819,CLX5
2025-09-24T19:36:50.242066459Z,2025-09-24T19:36:50.241902659Z,160,1,432669,A,A,64.820000000,1,26,8058566344902,128,15086,94310820,CLX5
2025-09-24T19:36:50.242097846Z,2025-09-24T19:36:50.241932071Z,160,1,432669,A,A,64.820000000,2,26,8058566344903,128,15157,94310821,CLX5
2025-09-24T19:36:50.242144830Z,2025-09-24T19:36:50.241934567Z,160,1,432669,A,B,64.810000000,1,26,8058566344904,128,19890,94310822,CLX5
2025-09-24T19:36:50.242395069Z,2025-09-24T19:36:50.242266771Z,160,1,432669,C,A,64.820000000,2,26,8058566344903,128,15261,94310834,CLX5
2025-09-24T19:36:50.311423628Z,2025-09-24T19:36:50.311280143Z,160,1,432669,A,B,64.780000000,2,26,8058566344917,128,18239,94310859,CLX5
2025-09-24T19:36:50.339603870Z,2025-09-24T19:36:50.339442785Z,160,1,432669,A,B,64.810000000,1,26,8058566344919,128,19632,94310866,CLX5
2025-09-24T19:36:50.411086934Z,2025-09-24T19:36:50.410946437Z,160,1,432669,A,B,64.770000000,2,26,8058566344921,128,18950,94310872,CLX5
2025-09-24T19:36:51.356493868Z,2025-09-24T19:36:51.356299291Z,160,1,432669,C,A,64.820000000,1,26,8058566344902,128,19362,94310904,CLX5
2025-09-24T19:36:51.356669846Z,2025-09-24T19:36:51.356529991Z,160,1,432669,A,B,64.810000000,1,26,8058566344937,128,26968,94310909,CLX5
2025-09-24T19:36:51.356820758Z,2025-09-24T19:36:51.356682297Z,160,1,432669,C,B,64.810000000,1,26,8058566344937,128,18525,94310911,CLX5
2025-09-24T19:37:00.158908893Z,2025-09-24T19:37:00.158751029Z,160,1,432669,A,A,64.820000000,1,26,8058566344953,128,18812,94310984,CLX5
2025-09-24T19:37:00.173671406Z,2025-09-24T19:37:00.173519189Z,160,1,432669,M,A,64.830000000,1,26,8058566331891,128,18436,94310988,CLX5
2025-09-24T19:37:00.339767171Z,2025-09-24T19:37:00.339610795Z,160,1,432669,A,B,64.800000000,1,26,8058566344955,128,18079,94310993,CLX5
2025-09-24T19:37:00.506764616Z,2025-09-24T19:37:00.506604279Z,160,1,432669,M,B,64.740000000,35,26,8058566342993,128,18392,94310994,CLX5
2025-09-24T19:37:02.418002342Z,2025-09-24T19:37:02.417822017Z,160,1,432669,A,B,64.810000000,2,26,8058566344960,128,20541,94311008,CLX5
2025-09-24T19:37:02.418423260Z,2025-09-24T19:37:02.418270837Z,160,1,432669,C,A,64.820000000,1,26,8058566344870,128,19762,94311014,CLX5
2025-09-24T19:37:02.418459582Z,2025-09-24T19:37:02.418275367Z,160,1,432669,A,B,64.810000000,1,26,8058566344963,128,15842,94311015,CLX5
2025-09-24T19:37:02.418563251Z,2025-09-24T19:37:02.418439385Z,160,1,432669,C,B,64.810000000,1,26,8058566344963,128,19579,94311016,CLX5
2025-09-24T19:37:03.736528764Z,2025-09-24T19:37:03.736359365Z,160,1,432669,C,B,64.800000000,1,26,8058566271014,128,19256,94311022,CLX5
2025-09-24T19:37:03.858599793Z,2025-09-24T19:37:03.858476749Z,160,1,432669,C,A,64.990000000,1,26,8058566342642,128,18674,94311023,CLX5
2025-09-24T19:37:03.936659479Z,2025-09-24T19:37:03.936539143Z,160,1,432669,A,A,64.980000000,1,26,8058566344965,128,18664,94311024,CLX5
2025-09-24T19:37:04.463263750Z,2025-09-24T19:37:04.462637115Z,160,1,432669,C,A,64.820000000,2,26,8058566344901,128,16646,94311079,CLX5
2025-09-24T19:37:04.464241493Z,2025-09-24T19:37:04.463282381Z,160,1,432669,A,B,64.810000000,1,26,8058566344991,128,15903,94311126,CLX5
2025-09-24T19:37:04.468824362Z,2025-09-24T19:37:04.468667589Z,160,1,432669,C,A,64.820000000,1,26,8058566344032,128,19517,94311222,CLX5
2025-09-24T19:37:04.468956105Z,2025-09-24T19:37:04.468831531Z,160,1,432669,C,A,64.850000000,1,26,8058566344029,128,14580,94311224,CLX5
2025-09-24T19:37:04.469064496Z,2025-09-24T19:37:04.468884991Z,160,1,432669,A,B,64.800000000,2,26,8058566345015,128,18075,94311228,CLX5
2025-09-24T19:37:04.469196163Z,2025-09-24T19:37:04.468893485Z,160,1,432669,C,B,64.770000000,2,26,8058566344921,128,14652,94311232,CLX5
2025-09-24T19:37:04.469417772Z,2025-09-24T19:37:04.469055545Z,160,1,432669,C,A,64.820000000,2,26,8058566344015,128,14678,94311238,CLX5
2025-09-24T19:37:04.469431051Z,2025-09-24T19:37:04.469056103Z,160,1,432669,C,A,64.820000000,1,26,8058566344016,128,18471,94311239,CLX5
2025-09-24T19:37:04.472002387Z,2025-09-24T19:37:04.471181123Z,160,1,432669,M,B,64.810000000,1,26,8058566319851,128,17568,94311330,CLX5
2025-09-24T19:37:04.472578441Z,2025-09-24T19:37:04.471451487Z,160,1,432669,C,B,64.810000000,1,26,8058566344991,128,17628,94311358,CLX5
2025-09-24T19:37:04.474353219Z,2025-09-24T19:37:04.472475529Z,160,1,432669,A,B,64.810000000,1,26,8058566345085,128,18279,94311477,CLX5
2025-09-24T19:37:04.475173407Z,2025-09-24T19:37:04.473718887Z,160,1,432669,M,A,64.950000000,1,26,8058565075241,128,16260,94311529,CLX5
2025-09-24T19:37:04.476937627Z,2025-09-24T19:37:04.475683247Z,160,1,432669,C,B,64.810000000,1,26,8058566345085,128,18559,94311651,CLX5
2025-09-24T19:37:04.511173862Z,2025-09-24T19:37:04.511034533Z,160,1,432669,C,B,64.780000000,2,26,8058566344917,128,19759,94311827,CLX5
2025-09-24T19:37:04.572000549Z,2025-09-24T19:37:04.571847543Z,160,1,432669,C,A,64.820000000,1,26,8058566344031,128,19841,94311876,CLX5
2025-09-24T19:37:04.634951283Z,2025-09-24T19:37:04.634791813Z,160,1,432669,A,A,64.820000000,1,26,8058566345250,128,16724,94311940,CLX5
2025-09-24T19:37:04.635323137Z,2025-09-24T19:37:04.635170995Z,160,1,432669,C,A,64.820000000,1,26,8058566345250,128,16378,94311945,CLX5
2025-09-24T19:37:04.789598784Z,2025-09-24T19:37:04.789435575Z,160,1,432669,A,A,64.820000000,1,26,8058566345297,128,20774,94312015,CLX5
2025-09-24T19:37:04.827162070Z,2025-09-24T19:37:04.827003077Z,160,1,432669,A,B,64.810000000,1,26,8058566345298,128,18844,94312016,CLX5
2025-09-24T19:37:04.827369519Z,2025-09-24T19:37:04.827173737Z,160,1,432669,C,A,64.820000000,1,26,8058566345297,128,16587,94312018,CLX5
2025-09-24T19:37:06.000495160Z,2025-09-24T19:37:06.000337829Z,160,1,432669,A,A,64.820000000,1,26,8058566345380,128,19880,94312134,CLX5
2025-09-24T19:37:06.000640312Z,2025-09-24T19:37:06.000516821Z,160,1,432669,C,A,64.820000000,1,26,8058566345380,128,16388,94312139,CLX5
2025-09-24T19:37:08.730997570Z,2025-09-24T19:37:08.730253705Z,160,1,432669,T,N,64.820000000,1,26,0,0,18203,94312158,CLX5
2025-09-24T19:37:08.730997570Z,2025-09-24T19:37:08.730253705Z,160,1,432669,F,N,64.820000000,1,26,8058566335929,0,18203,94312158,CLX5
2025-09-24T19:37:08.731010748Z,2025-09-24T19:37:08.730253705Z,160,1,432669,C,A,64.820000000,1,26,8058566335929,128,17326,94312159,CLX5
2025-09-24T19:37:08.731203122Z,2025-09-24T19:37:08.730254639Z,160,1,432669,T,B,64.820000000,2,26,8058566345389,0,18217,94312164,CLX5
2025-09-24T19:37:08.731203122Z,2025-09-24T19:37:08.730254639Z,160,1,432669,F,A,64.820000000,1,26,8058566337236,0,18217,94312164,CLX5
2025-09-24T19:37:08.731203122Z,2025-09-24T19:37:08.730254639Z,160,1,432669,F,A,64.820000000,1,26,8058566341727,0,18217,94312164,CLX5
2025-09-24T19:37:08.731216600Z,2025-09-24T19:37:08.730254639Z,160,1,432669,C,A,64.820000000,1,26,8058566337236,0,17456,94312165,CLX5
2025-09-24T19:37:08.731216600Z,2025-09-24T19:37:08.730254639Z,160,1,432669,C,A,64.820000000,1,26,8058566341727,128,17456,94312165,CLX5
2025-09-24T19:37:08.731364870Z,2025-09-24T19:37:08.730254927Z,160,1,432669,T,B,64.820000000,4,26,8058566345390,0,18063,94312166,CLX5
2025-09-24T19:37:08.731364870Z,2025-09-24T19:37:08.730254927Z,160,1,432669,F,A,64.820000000,1,26,8058566342118,0,18063,94312166,CLX5
2025-09-24T19:37:08.731364870Z,2025-09-24T19:37:08.730254927Z,160,1,432669,F,A,64.820000000,1,26,8058566342425,0,18063,94312166,CLX5
2025-09-24T19:37:08.731364870Z,2025-09-24T19:37:08.730254927Z,160,1,432669,F,A,64.820000000,1,26,8058566343993,0,18063,94312166,CLX5
2025-09-24T19:37:08.731364870Z,2025-09-24T19:37:08.730254927Z,160,1,432669,F,A,64.820000000,1,26,8058566344953,0,18063,94312166,CLX5
2025-09-24T19:37:08.731375253Z,2025-09-24T19:37:08.730254927Z,160,1,432669,C,A,64.820000000,1,26,8058566342118,0,14775,94312167,CLX5
2025-09-24T19:37:08.731375253Z,2025-09-24T19:37:08.730254927Z,160,1,432669,C,A,64.820000000,1,26,8058566342425,0,14775,94312167,CLX5
2025-09-24T19:37:08.731375253Z,2025-09-24T19:37:08.730254927Z,160,1,432669,C,A,64.820000000,1,26,8058566343993,0,14775,94312167,CLX5
2025-09-24T19:37:08.731375253Z,2025-09-24T19:37:08.730254927Z,160,1,432669,C,A,64.820000000,1,26,8058566344953,128,14775,94312167,CLX5
2025-09-24T19:37:08.731407315Z,2025-09-24T19:37:08.730255119Z,160,1,432669,A,B,64.820000000,2,26,8058566345391,128,18143,94312170,CLX5
2025-09-24T19:37:08.731432627Z,2025-09-24T19:37:08.730255827Z,160,1,432669,A,B,64.810000000,2,26,8058566345393,128,19225,94312172,CLX5
2025-09-24T19:37:08.731679434Z,2025-09-24T19:37:08.730263507Z,160,1,432669,A,B,64.810000000,1,26,8058566345401,128,16850,94312182,CLX5
2025-09-24T19:37:08.732828562Z,2025-09-24T19:37:08.730307841Z,160,1,432669,C,A,64.830000000,1,26,8058566335771,128,15750,94312251,CLX5
2025-09-24T19:37:08.733118260Z,2025-09-24T19:37:08.730333603Z,160,1,432669,A,B,64.810000000,1,26,8058566345421,128,15121,94312259,CLX5
2025-09-24T19:37:08.733335131Z,2025-09-24T19:37:08.730408619Z,160,1,432669,A,B,64.820000000,2,26,8058566345427,128,18368,94312268,CLX5
2025-09-24T19:37:08.733558009Z,2025-09-24T19:37:08.730434803Z,160,1,432669,C,A,64.830000000,1,26,8058566335056,128,21781,94312278,CLX5
2025-09-24T19:37:08.733588167Z,2025-09-24T19:37:08.730434955Z,160,1,432669,C,A,64.830000000,1,26,8058566335057,128,15633,94312279,CLX5
2025-09-24T19:37:08.734126598Z,2025-09-24T19:37:08.730537365Z,160,1,432669,A,B,64.820000000,1,26,8058566345446,128,24046,94312297,CLX5
2025-09-24T19:37:08.734160127Z,2025-09-24T19:37:08.730655381Z,160,1,432669,A,B,64.820000000,1,26,8058566345447,128,16989,94312298,CLX5
2025-09-24T19:37:08.734187114Z,2025-09-24T19:37:08.730661181Z,160,1,432669,C,B,64.810000000,1,26,8058566345421,128,14941,94312299,CLX5
2025-09-24T19:37:08.734315539Z,2025-09-24T19:37:08.730731007Z,160,1,432669,A,B,64.820000000,1,26,8058566345451,128,16620,94312303,CLX5
2025-09-24T19:37:08.734377905Z,2025-09-24T19:37:08.730736135Z,160,1,432669,A,B,64.820000000,2,26,8058566345454,128,16542,94312305,CLX5
2025-09-24T19:37:08.734415351Z,2025-09-24T19:37:08.730743141Z,160,1,432669,C,A,64.830000000,1,26,8058566335720,128,14418,94312306,CLX5
2025-09-24T19:37:08.734479568Z,2025-09-24T19:37:08.730762015Z,160,1,432669,C,A,64.830000000,1,26,8058566335699,128,14898,94312309,CLX5
2025-09-24T19:37:08.734675198Z,2025-09-24T19:37:08.730796131Z,160,1,432669,C,A,64.830000000,1,26,8058566343075,128,19864,94312314,CLX5
2025-09-24T19:37:08.735325806Z,2025-09-24T19:37:08.731001523Z,160,1,432669,M,A,64.940000000,1,26,8058565075241,128,18612,94312346,CLX5
2025-09-24T19:37:08.735766599Z,2025-09-24T19:37:08.731113511Z,160,1,432669,A,B,64.820000000,1,26,8058566345478,128,14947,94312362,CLX5
2025-09-24T19:37:08.735910346Z,2025-09-24T19:37:08.731126587Z,160,1,432669,C,A,64.860000000,2,26,8058566335838,128,14704,94312368,CLX5
2025-09-24T19:37:08.735952661Z,2025-09-24T19:37:08.731166251Z,160,1,432669,A,B,64.820000000,2,26,8058566345482,128,15817,94312370,CLX5
2025-09-24T19:37:08.736093804Z,2025-09-24T19:37:08.731175641Z,160,1,432669,A,B,64.820000000,2,26,8058566345487,128,15715,94312374,CLX5
2025-09-24T19:37:08.736190705Z,2025-09-24T19:37:08.731203191Z,160,1,432669,A,B,64.820000000,1,26,8058566345493,128,16962,94312378,CLX5
2025-09-24T19:37:08.736379968Z,2025-09-24T19:37:08.731212945Z,160,1,432669,A,B,64.810000000,1,26,8058566345497,128,14476,94312387,CLX5
2025-09-24T19:37:08.736835377Z,2025-09-24T19:37:08.731371913Z,160,1,432669,A,A,64.830000000,1,26,8058566345503,128,13861,94312409,CLX5
2025-09-24T19:37:08.737087797Z,2025-09-24T19:37:08.731382513Z,160,1,432669,A,B,64.820000000,1,26,8058566345507,128,15377,94312421,CLX5
2025-09-24T19:37:08.737369830Z,2025-09-24T19:37:08.731417647Z,160,1,432669,A,A,64.830000000,1,26,8058566345514,128,19590,94312434,CLX5
2025-09-24T19:37:08.737401708Z,2025-09-24T19:37:08.731420161Z,160,1,432669,A,B,64.810000000,3,26,8058566345515,128,15283,94312435,CLX5
2025-09-24T19:37:08.738030713Z,2025-09-24T19:37:08.731519959Z,160,1,432669,A,B,64.790000000,1,26,8058566345526,128,14920,94312466,CLX5
2025-09-24T19:37:08.738145938Z,2025-09-24T19:37:08.731524125Z,160,1,432669,A,B,64.820000000,1,26,8058566345528,128,15407,94312471,CLX5
2025-09-24T19:37:08.738182808Z,2025-09-24T19:37:08.731528733Z,160,1,432669,A,A,64.830000000,1,26,8058566345529,128,15149,94312472,CLX5
2025-09-24T19:37:08.738352703Z,2025-09-24T19:37:08.731604551Z,160,1,432669,C,A,64.830000000,1,26,8058566345529,128,15734,94312481,CLX5
2025-09-24T19:37:08.738400662Z,2025-09-24T19:37:08.731670845Z,160,1,432669,M,A,65.990000000,4,26,8058566331102,128,19015,94312483,CLX5
2025-09-24T19:37:08.738751735Z,2025-09-24T19:37:08.731855175Z,160,1,432669,T,A,64.820000000,1,26,8058566345538,0,14711,94312502,CLX5
2025-09-24T19:37:08.738751735Z,2025-09-24T19:37:08.731855175Z,160,1,432669,F,B,64.820000000,1,26,8058566345391,0,14711,94312502,CLX5
2025-09-24T19:37:08.738789158Z,2025-09-24T19:37:08.731855175Z,160,1,432669,M,B,64.820000000,1,26,8058566345391,128,15919,94312503,CLX5
2025-09-24T19:37:08.738824729Z,2025-09-24T19:37:08.731862761Z,160,1,432669,M,B,64.810000000,1,26,8058566319508,128,18694,94312504,CLX5
2025-09-24T19:37:08.738859011Z,2025-09-24T19:37:08.731875067Z,160,1,432669,C,A,64.830000000,1,26,8058566345514,128,15747,94312505,CLX5
2025-09-24T19:37:08.739078824Z,2025-09-24T19:37:08.732009653Z,160,1,432669,M,B,64.800000000,1,26,8058566332677,128,14809,94312517,CLX5
2025-09-24T19:37:08.739163269Z,2025-09-24T19:37:08.732147233Z,160,1,432669,M,B,64.820000000,1,26,8058566344955,128,15146,94312521,CLX5
2025-09-24T19:37:08.739310902Z,2025-09-24T19:37:08.732289365Z,160,1,432669,A,B,64.820000000,3,26,8058566345544,128,14140,94312529,CLX5
2025-09-24T19:37:08.739851177Z,2025-09-24T19:37:08.732575085Z,160,1,432669,M,B,64.810000000,1,26,8058566340051,128,18687,94312559,CLX5
2025-09-24T19:37:08.740201159Z,2025-09-24T19:37:08.732659909Z,160,1,432669,A,B,64.820000000,1,26,8058566345553,128,23179,94312569,CLX5
2025-09-24T19:37:08.740322596Z,2025-09-24T19:37:08.732678877Z,160,1,432669,A,B,64.820000000,1,26,8058566345555,128,15114,94312573,CLX5
2025-09-24T19:37:08.740731888Z,2025-09-24T19:37:08.733166669Z,160,1,432669,M,A,64.840000000,1,26,8058566173085,128,18855,94312589,CLX5
2025-09-24T19:37:08.741276479Z,2025-09-24T19:37:08.733811493Z,160,1,432669,A,B,64.810000000,2,26,8058566345566,128,14993,94312613,CLX5
2025-09-24T19:37:08.741388294Z,2025-09-24T19:37:08.733867517Z,160,1,432669,C,B,64.820000000,2,26,8058566345487,128,15126,94312618,CLX5
2025-09-24T19:37:08.741941386Z,2025-09-24T19:37:08.734115609Z,160,1,432669,M,A,64.950000000,1,26,8058565075241,128,14798,94312642,CLX5
2025-09-24T19:37:08.742045652Z,2025-09-24T19:37:08.734215385Z,160,1,432669,A,B,64.810000000,1,26,8058566345576,128,14858,94312646,CLX5
2025-09-24T19:37:08.742226230Z,2025-09-24T19:37:08.734541905Z,160,1,432669,C,A,64.830000000,1,26,8058566345503,128,15921,94312654,CLX5
2025-09-24T19:37:08.742311228Z,2025-09-24T19:37:08.734690027Z,160,1,432669,C,A,64.830000000,1,26,8058566335746,128,19478,94312657,CLX5
2025-09-24T19:37:08.742673950Z,2025-09-24T19:37:08.734786195Z,160,1,432669,A,A,64.830000000,1,26,8058566345586,128,15579,94312670,CLX5
2025-09-24T19:37:08.743365690Z,2025-09-24T19:37:08.735349539Z,160,1,432669,A,A,64.830000000,1,26,8058566345595,128,16030,94312698,CLX5
2025-09-24T19:37:08.743820913Z,2025-09-24T19:37:08.735594691Z,160,1,432669,A,A,64.830000000,1,26,8058566345599,128,18508,94312718,CLX5
2025-09-24T19:37:08.743888025Z,2025-09-24T19:37:08.735609911Z,160,1,432669,C,B,64.820000000,1,26,8058566345447,128,15231,94312721,CLX5
2025-09-24T19:37:08.744087226Z,2025-09-24T19:37:08.735731811Z,160,1,432669,A,B,64.820000000,1,26,8058566345602,128,16348,94312732,CLX5
2025-09-24T19:37:08.744219899Z,2025-09-24T19:37:08.735771727Z,160,1,432669,A,A,64.830000000,1,26,8058566345604,128,18852,94312739,CLX5
2025-09-24T19:37:08.744285559Z,2025-09-24T19:37:08.735775047Z,160,1,432669,A,A,64.830000000,1,26,8058566345605,128,15560,94312742,CLX5
2025-09-24T19:37:08.744720271Z,2025-09-24T19:37:08.735964985Z,160,1,432669,A,A,64.830000000,1,26,8058566345612,128,15215,94312763,CLX5
2025-09-24T19:37:08.744748140Z,2025-09-24T19:37:08.736099015Z,160,1,432669,C,A,64.860000000,1,26,8058566335777,128,14631,94312764,CLX5
2025-09-24T19:37:08.745942410Z,2025-09-24T19:37:08.736808941Z,160,1,432669,C,A,64.830000000,1,26,8058566345604,128,15351,94312850,CLX5
2025-09-24T19:37:08.746461873Z,2025-09-24T19:37:08.737258565Z,160,1,432669,A,A,64.830000000,1,26,8058566345625,128,15681,94312877,CLX5
2025-09-24T19:37:08.747102105Z,2025-09-24T19:37:08.737612023Z,160,1,432669,C,B,64.820000000,1,26,8058566345493,128,18351,94312915,CLX5
2025-09-24T19:37:08.747607891Z,2025-09-24T19:37:08.737731385Z,160,1,432669,A,B,64.820000000,1,26,8058566345648,128,18577,94312944,CLX5
2025-09-24T19:37:08.747644861Z,2025-09-24T19:37:08.737732843Z,160,1,432669,C,A,64.830000000,1,26,8058566345599,128,15105,94312945,CLX5
2025-09-24T19:37:08.747854414Z,2025-09-24T19:37:08.738006643Z,160,1,432669,A,B,64.820000000,1,26,8058566345652,128,15505,94312955,CLX5
2025-09-24T19:37:08.749239222Z,2025-09-24T19:37:08.738789199Z,160,1,432669,C,B,64.820000000,2,26,8058566345482,128,14956,94313035,CLX5
2025-09-24T19:37:08.749336730Z,2025-09-24T19:37:08.738869777Z,160,1,432669,A,A,64.830000000,2,26,8058566345667,128,18711,94313038,CLX5
2025-09-24T19:37:08.749731438Z,2025-09-24T19:37:08.739203747Z,160,1,432669,C,B,64.820000000,1,26,8058566345652,128,14099,94313058,CLX5
2025-09-24T19:37:08.749946435Z,2025-09-24T19:37:08.739361547Z,160,1,432669,C,B,64.820000000,1,26,8058566345553,128,14743,94313069,CLX5
2025-09-24T19:37:08.750611857Z,2025-09-24T19:37:08.739921373Z,160,1,432669,C,B,64.820000000,1,26,8058566345602,128,14904,94313104,CLX5
2025-09-24T19:37:08.751148484Z,2025-09-24T19:37:08.740576085Z,160,1,432669,C,A,64.830000000,1,26,8058566345595,128,15008,94313131,CLX5
2025-09-24T19:37:08.751654854Z,2025-09-24T19:37:08.741125371Z,160,1,432669,A,A,64.830000000,1,26,8058566345701,128,15139,94313157,CLX5
2025-09-24T19:37:08.751841015Z,2025-09-24T19:37:08.741397577Z,160,1,432669,A,A,64.830000000,1,26,8058566345702,128,18653,94313168,CLX5
2025-09-24T19:37:08.751975047Z,2025-09-24T19:37:08.741495089Z,160,1,432669,M,B,64.810000000,1,26,8058566329044,128,14174,94313173,CLX5
2025-09-24T19:37:08.752979907Z,2025-09-24T19:37:08.742200581Z,160,1,432669,C,A,64.830000000,2,26,8058566345667,128,18688,94313239,CLX5
2025-09-24T19:37:08.753288112Z,2025-09-24T19:37:08.742678679Z,160,1,432669,A,A,64.830000000,1,26,8058566345712,128,18419,94313252,CLX5
2025-09-24T19:37:08.753650536Z,2025-09-24T19:37:08.743517567Z,160,1,432669,A,A,64.830000000,1,26,8058566345716,128,15139,94313273,CLX5
2025-09-24T19:37:08.753709730Z,2025-09-24T19:37:08.743726357Z,160,1,432669,C,A,64.830000000,1,26,8058566345701,128,18718,94313276,CLX5
2025-09-24T19:37:08.754027880Z,2025-09-24T19:37:08.744244889Z,160,1,432669,C,B,64.810000000,1,26,8058566345576,128,18304,94313290,CLX5
2025-09-24T19:37:08.754238539Z,2025-09-24T19:37:08.744727517Z,160,1,432669,C,A,64.830000000,1,26,8058566345716,128,18620,94313302,CLX5
2025-09-24T19:37:08.754829837Z,2025-09-24T19:37:08.745479413Z,160,1,432669,C,B,64.810000000,2,26,8058566345566,128,18009,94313341,CLX5
2025-09-24T19:37:08.755063634Z,2025-09-24T19:37:08.745511139Z,160,1,432669,C,B,64.820000000,2,26,8058566345427,128,17762,94313351,CLX5
2025-09-24T19:37:08.755139324Z,2025-09-24T19:37:08.745517697Z,160,1,432669,C,B,64.820000000,3,26,8058566345544,128,16400,94313354,CLX5
2025-09-24T19:37:08.755273633Z,2025-09-24T19:37:08.745542311Z,160,1,432669,A,A,64.830000000,1,26,8058566345735,128,15107,94313358,CLX5
2025-09-24T19:37:08.755386101Z,2025-09-24T19:37:08.745592535Z,160,1,432669,A,A,64.830000000,2,26,8058566345738,128,18617,94313365,CLX5
2025-09-24T19:37:08.755590263Z,2025-09-24T19:37:08.745620545Z,160,1,432669,A,A,64.830000000,1,26,8058566345742,128,18859,94313373,CLX5
2025-09-24T19:37:08.755616719Z,2025-09-24T19:37:08.745620737Z,160,1,432669,A,A,64.830000000,1,26,8058566345743,128,14334,94313374,CLX5
2025-09-24T19:37:08.755811167Z,2025-09-24T19:37:08.745748681Z,160,1,432669,A,A,64.830000000,1,26,8058566345746,128,18662,94313382,CLX5
2025-09-24T19:37:08.755899059Z,2025-09-24T19:37:08.745765115Z,160,1,432669,C,B,64.820000000,1,26,8058566345391,128,15079,94313384,CLX5
2025-09-24T19:37:08.757128839Z,2025-09-24T19:37:08.746369639Z,160,1,432669,C,A,64.830000000,2,26,8058566345738,128,18152,94313458,CLX5
2025-09-24T19:37:08.758749679Z,2025-09-24T19:37:08.748249217Z,160,1,432669,C,A,64.830000000,1,26,8058566345746,128,14253,94313569,CLX5
2025-09-24T19:37:08.759728866Z,2025-09-24T19:37:08.749341399Z,160,1,432669,C,A,64.830000000,1,26,8058566345712,128,19231,94313617,CLX5
2025-09-24T19:37:08.759754654Z,2025-09-24T19:37:08.749344145Z,160,1,432669,C,A,64.830000000,1,26,8058566345735,128,15220,94313618,CLX5
2025-09-24T19:37:08.759855250Z,2025-09-24T19:37:08.749736269Z,160,1,432669,A,A,64.830000000,1,26,8058566345788,128,15003,94313622,CLX5
2025-09-24T19:37:08.760055403Z,2025-09-24T19:37:08.749929007Z,160,1,432669,A,A,64.830000000,1,26,8058566345790,128,17468,94313630,CLX5
2025-09-24T19:37:08.760711010Z,2025-09-24T19:37:08.750290797Z,160,1,432669,C,B,64.820000000,1,26,8058566345648,128,14552,94313663,CLX5
2025-09-24T19:37:08.760926707Z,2025-09-24T19:37:08.750407105Z,160,1,432669,C,B,64.820000000,1,26,8058566345478,128,17127,94313669,CLX5
2025-09-24T19:37:08.761742925Z,2025-09-24T19:37:08.751225067Z,160,1,432669,A,A,64.830000000,2,26,8058566345824,128,15381,94313714,CLX5
2025-09-24T19:37:08.761826425Z,2025-09-24T19:37:08.751910015Z,160,1,432669,A,A,64.830000000,1,26,8058566345827,128,17235,94313718,CLX5
2025-09-24T19:37:08.762526566Z,2025-09-24T19:37:08.752989873Z,160,1,432669,C,A,64.830000000,2,26,8058566345824,128,15318,94313760,CLX5
2025-09-24T19:37:08.762562898Z,2025-09-24T19:37:08.752990755Z,160,1,432669,A,A,64.830000000,2,26,8058566345835,128,18826,94313761,CLX5
2025-09-24T19:37:08.763166453Z,2025-09-24T19:37:08.753995235Z,160,1,432669,C,A,64.830000000,2,26,8058566345835,128,15050,94313798,CLX5
2025-09-24T19:37:08.764424563Z,2025-09-24T19:37:08.755031049Z,160,1,432669,A,A,64.830000000,2,26,8058566345856,128,18345,94313895,CLX5
2025-09-24T19:37:08.764875002Z,2025-09-24T19:37:08.755822381Z,160,1,432669,C,A,64.830000000,2,26,8058566345856,128,14089,94313920,CLX5
2025-09-24T19:37:08.765142966Z,2025-09-24T19:37:08.756105741Z,160,1,432669,C,B,64.820000000,1,26,8058566345507,128,18884,94313932,CLX5
2025-09-24T19:37:08.765299092Z,2025-09-24T19:37:08.756133907Z,160,1,432669,C,B,64.820000000,2,26,8058566345454,128,16917,94313937,CLX5
2025-09-24T19:37:08.765341338Z,2025-09-24T19:37:08.756134053Z,160,1,432669,C,B,64.820000000,1,26,8058566345446,128,16992,94313938,CLX5
2025-09-24T19:37:08.765358494Z,2025-09-24T19:37:08.756135653Z,160,1,432669,T,A,64.820000000,4,26,8058566345868,0,16955,94313939,CLX5
2025-09-24T19:37:08.765358494Z,2025-09-24T19:37:08.756135653Z,160,1,432669,F,B,64.820000000,1,26,8058566345451,0,16955,94313939,CLX5
2025-09-24T19:37:08.765358494Z,2025-09-24T19:37:08.756135653Z,160,1,432669,F,B,64.820000000,1,26,8058566345528,0,16955,94313939,CLX5
2025-09-24T19:37:08.765358494Z,2025-09-24T19:37:08.756135653Z,160,1,432669,F,B,64.820000000,1,26,8058566344955,0,16955,94313939,CLX5
2025-09-24T19:37:08.765358494Z,2025-09-24T19:37:08.756135653Z,160,1,432669,F,B,64.820000000,1,26,8058566345555,0,16955,94313939,CLX5
2025-09-24T19:37:08.765401054Z,2025-09-24T19:37:08.756135653Z,160,1,432669,C,B,64.820000000,1,26,8058566345451,0,15103,94313940,CLX5
2025-09-24T19:37:08.765401054Z,2025-09-24T19:37:08.756135653Z,160,1,432669,C,B,64.820000000,1,26,8058566345528,0,15103,94313940,CLX5
2025-09-24T19:37:08.765401054Z,2025-09-24T19:37:08.756135653Z,160,1,432669,C,B,64.820000000,1,26,8058566344955,0,15103,94313940,CLX5
2025-09-24T19:37:08.765401054Z,2025-09-24T19:37:08.756135653Z,160,1,432669,C,B,64.820000000,1,26,8058566345555,128,15103,94313940,CLX5
2025-09-24T19:37:08.765473258Z,2025-09-24T19:37:08.756135845Z,160,1,432669,A,A,64.820000000,2,26,8058566345869,128,18048,94313943,CLX5
2025-09-24T19:37:08.765826181Z,2025-09-24T19:37:08.756171787Z,160,1,432669,A,A,64.830000000,1,26,8058566345875,128,18432,94313961,CLX5
2025-09-24T19:37:08.766037017Z,2025-09-24T19:37:08.756193711Z,160,1,432669,A,A,64.830000000,2,26,8058566345878,128,18377,94313970,CLX5
2025-09-24T19:37:08.766396699Z,2025-09-24T19:37:08.756388161Z,160,1,432669,A,A,64.860000000,1,26,8058566345884,128,14726,94313986,CLX5
2025-09-24T19:37:08.766520586Z,2025-09-24T19:37:08.756424081Z,160,1,432669,M,A,64.840000000,1,26,8058566332416,128,18453,94313990,CLX5
2025-09-24T19:37:08.766694920Z,2025-09-24T19:37:08.756455779Z,160,1,432669,A,A,64.820000000,1,26,8058566345892,128,14805,94313998,CLX5
2025-09-24T19:37:08.766938448Z,2025-09-24T19:37:08.756491951Z,160,1,432669,A,A,64.820000000,1,26,8058566345893,128,16765,94314010,CLX5
2025-09-24T19:37:08.767456321Z,2025-09-24T19:37:08.756792593Z,160,1,432669,A,A,64.820000000,2,26,8058566345905,128,17676,94314032,CLX5
2025-09-24T19:37:08.768088083Z,2025-09-24T19:37:08.757042353Z,160,1,432669,A,A,64.820000000,3,26,8058566345913,128,16758,94314060,CLX5
2025-09-24T19:37:08.768401234Z,2025-09-24T19:37:08.757134049Z,160,1,432669,A,A,64.820000000,1,26,8058566345920,128,16233,94314074,CLX5
2025-09-24T19:37:08.768435439Z,2025-09-24T19:37:08.757161541Z,160,1,432669,A,A,64.830000000,1,26,8058566345921,128,18457,94314075,CLX5
2025-09-24T19:37:08.768962889Z,2025-09-24T19:37:08.757832111Z,160,1,432669,C,A,64.820000000,3,26,8058566345913,128,16829,94314106,CLX5
2025-09-24T19:37:08.769057939Z,2025-09-24T19:37:08.757932809Z,160,1,432669,A,A,64.860000000,2,26,8058566345929,128,14815,94314111,CLX5
2025-09-24T19:37:08.769225486Z,2025-09-24T19:37:08.757955483Z,160,1,432669,A,B,64.810000000,1,26,8058566345933,128,14917,94314119,CLX5
2025-09-24T19:37:08.769379101Z,2025-09-24T19:37:08.758176715Z,160,1,432669,A,A,64.820000000,7,26,8058566345937,128,18361,94314126,CLX5
2025-09-24T19:37:08.769613512Z,2025-09-24T19:37:08.758642985Z,160,1,432669,A,B,63.680000000,4,26,8058566345944,128,13857,94314139,CLX5
2025-09-24T19:37:08.770035982Z,2025-09-24T19:37:08.759206309Z,160,1,432669,A,A,64.820000000,2,26,8058566345959,128,18350,94314164,CLX5
2025-09-24T19:37:08.770387823Z,2025-09-24T19:37:08.759606917Z,160,1,432669,M,A,64.940000000,1,26,8058565075241,128,14822,94314179,CLX5
2025-09-24T19:37:08.770526892Z,2025-09-24T19:37:08.759846869Z,160,1,432669,C,B,64.810000000,2,26,8058566345393,128,15033,94314185,CLX5
2025-09-24T19:37:08.770624300Z,2025-09-24T19:37:08.759855317Z,160,1,432669,A,A,64.830000000,1,26,8058566345966,128,14818,94314188,CLX5
2025-09-24T19:37:08.771135286Z,2025-09-24T19:37:08.760878575Z,160,1,432669,M,A,64.950000000,1,26,8058565075241,128,16438,94314217,CLX5
2025-09-24T19:37:08.771897401Z,2025-09-24T19:37:08.761620813Z,160,1,432669,M,A,64.940000000,1,26,8058565075241,128,14545,94314259,CLX5
2025-09-24T19:37:08.773466826Z,2025-09-24T19:37:08.762994015Z,160,1,432669,C,B,64.810000000,1,26,8058566345401,128,18764,94314358,CLX5
2025-09-24T19:37:08.774318041Z,2025-09-24T19:37:08.763804235Z,160,1,432669,M,A,64.830000000,1,26,8058566332416,128,18664,94314405,CLX5
2025-09-24T19:37:08.774739550Z,2025-09-24T19:37:08.765358563Z,160,1,432669,A,A,64.820000000,1,26,8058566346042,128,17512,94314426,CLX5
2025-09-24T19:37:08.774850874Z,2025-09-24T19:37:08.765375669Z,160,1,432669,A,A,64.820000000,1,26,8058566346045,128,18722,94314433,CLX5
2025-09-24T19:37:08.774887659Z,2025-09-24T19:37:08.765410649Z,160,1,432669,A,B,64.810000000,1,26,8058566346046,128,15076,94314434,CLX5
2025-09-24T19:37:08.774921226Z,2025-09-24T19:37:08.765475889Z,160,1,432669,A,A,64.820000000,3,26,8058566346047,128,15017,94314435,CLX5
2025-09-24T19:37:08.775042917Z,2025-09-24T19:37:08.765515957Z,160,1,432669,A,A,64.820000000,2,26,8058566346050,128,17243,94314440,CLX5
2025-09-24T19:37:08.775173609Z,2025-09-24T19:37:08.765618115Z,160,1,432669,M,B,63.660000000,4,26,8058566329044,128,15248,94314448,CLX5
2025-09-24T19:37:08.775257716Z,2025-09-24T19:37:08.765633475Z,160,1,432669,M,B,63.650000000,4,26,8058566319508,128,16959,94314451,CLX5
2025-09-24T19:37:08.775604212Z,2025-09-24T19:37:08.765840211Z,160,1,432669,M,A,64.840000000,4,26,8058566321460,128,14734,94314462,CLX5
2025-09-24T19:37:08.775854036Z,2025-09-24T19:37:08.766573023Z,160,1,432669,C,B,64.810000000,1,26,8058566346046,128,18017,94314470,CLX5
2025-09-24T19:37:08.776264756Z,2025-09-24T19:37:08.767185995Z,160,1,432669,C,A,64.820000000,2,26,8058566346050,128,14983,94314488,CLX5
2025-09-24T19:37:08.777178375Z,2025-09-24T19:37:08.769239343Z,160,1,432669,C,B,64.810000000,1,26,8058566345933,128,14819,94314536,CLX5
2025-09-24T19:37:08.777307223Z,2025-09-24T19:37:08.769385257Z,160,1,432669,C,A,64.820000000,7,26,8058566345937,128,15992,94314541,CLX5
2025-09-24T19:37:08.777349200Z,2025-09-24T19:37:08.769387235Z,160,1,432669,C,B,64.810000000,2,26,8058566344960,128,19217,94314542,CLX5
2025-09-24T19:37:08.777395984Z,2025-09-24T19:37:08.769407125Z,160,1,432669,C,B,64.810000000,3,26,8058566345515,128,15041,94314544,CLX5
2025-09-24T19:37:08.779241867Z,2025-09-24T19:37:08.774902691Z,160,1,432669,C,A,64.820000000,1,26,8058566346042,128,18962,94314675,CLX5
2025-09-24T19:37:08.779635984Z,2025-09-24T19:37:08.775623445Z,160,1,432669,A,B,64.800000000,1,26,8058566346121,128,17245,94314694,CLX5
2025-09-24T19:37:08.780082384Z,2025-09-24T19:37:08.776271879Z,160,1,432669,C,A,64.820000000,1,26,8058566346045,128,15742,94314709,CLX5
2025-09-24T19:37:08.780167950Z,2025-09-24T19:37:08.776787357Z,160,1,432669,A,A,64.820000000,1,26,8058566346128,128,20336,94314713,CLX5
2025-09-24T19:37:08.780431022Z,2025-09-24T19:37:08.777186699Z,160,1,432669,A,B,64.810000000,1,26,8058566346132,128,18309,94314723,CLX5
2025-09-24T19:37:08.780780850Z,2025-09-24T19:37:08.778724265Z,160,1,432669,A,B,63.670000000,4,26,8058566346145,128,14737,94314747,CLX5
2025-09-24T19:37:08.785177350Z,2025-09-24T19:37:08.785041861Z,160,1,432669,C,A,64.830000000,1,26,8058566345586,128,18399,94314811,CLX5
2025-09-24T19:37:08.788550620Z,2025-09-24T19:37:08.788421679Z,160,1,432669,C,A,64.820000000,1,26,8058566346128,128,19224,94314823,CLX5
2025-09-24T19:37:08.794263986Z,2025-09-24T19:37:08.794118375Z,160,1,432669,M,A,64.820000000,1,26,8058566331891,128,19617,94314831,CLX5
2025-09-24T19:37:08.808132868Z,2025-09-24T19:37:08.807982505Z,160,1,432669,A,B,64.810000000,1,26,8058566346182,128,19138,94314863,CLX5
2025-09-24T19:37:08.808278604Z,2025-09-24T19:37:08.808141263Z,160,1,432669,C,B,64.810000000,1,26,8058566346132,128,15087,94314865,CLX5
2025-09-24T19:37:08.808403236Z,2025-09-24T19:37:08.808286889Z,160,1,432669,A,B,64.810000000,1,26,8058566346183,128,13915,94314867,CLX5
2025-09-24T19:37:08.816773112Z,2025-09-24T19:37:08.816632895Z,160,1,432669,M,A,64.820000000,1,26,8058566332416,128,19102,94314950,CLX5
2025-09-24T19:37:08.820161811Z,2025-09-24T19:37:08.820037827Z,160,1,432669,M,A,64.830000000,1,26,8058566332416,128,19619,94314955,CLX5
2025-09-24T19:37:08.820299053Z,2025-09-24T19:37:08.820170511Z,160,1,432669,C,B,64.810000000,1,26,8058566346183,128,18676,94314956,CLX5
2025-09-24T19:37:08.829339727Z,2025-09-24T19:37:08.829202329Z,160,1,432669,M,A,64.820000000,1,26,8058566332416,128,19805,94314965,CLX5
2025-09-24T19:37:08.829478735Z,2025-09-24T19:37:08.829348167Z,160,1,432669,A,B,64.810000000,1,26,8058566346197,128,18568,94314966,CLX5
2025-09-24T19:37:08.829610932Z,2025-09-24T19:37:08.829486787Z,160,1,432669,C,B,64.810000000,1,26,8058566346197,128,18472,94314967,CLX5
2025-09-24T19:37:08.847162887Z,2025-09-24T19:37:08.846900629Z,160,1,432669,A,B,64.810000000,1,26,8058566346236,128,14341,94315025,CLX5
2025-09-24T19:37:08.847295283Z,2025-09-24T19:37:08.847170935Z,160,1,432669,A,B,64.810000000,1,26,8058566346246,128,15409,94315036,CLX5
2025-09-24T19:37:08.847438791Z,2025-09-24T19:37:08.847303139Z,160,1,432669,C,B,64.810000000,1,26,8058566346246,128,18813,94315040,CLX5
2025-09-24T19:37:08.856192494Z,2025-09-24T19:37:08.855797277Z,160,1,432669,C,B,64.810000000,1,26,8058566343024,128,18768,94315072,CLX5
2025-09-24T19:37:08.856278636Z,2025-09-24T19:37:08.855800895Z,160,1,432669,A,B,64.810000000,1,26,8058566346262,128,15306,94315075,CLX5
2025-09-24T19:37:08.856323009Z,2025-09-24T19:37:08.855801933Z,160,1,432669,A,A,64.820000000,1,26,8058566346263,128,18983,94315076,CLX5
2025-09-24T19:37:08.856406356Z,2025-09-24T19:37:08.855808433Z,160,1,432669,C,B,64.800000000,2,26,8058566345015,128,15128,94315080,CLX5
2025-09-24T19:37:08.856446873Z,2025-09-24T19:37:08.855808613Z,160,1,432669,A,A,64.820000000,1,26,8058566346265,128,19079,94315081,CLX5
2025-09-24T19:37:08.856485094Z,2025-09-24T19:37:08.855810263Z,160,1,432669,C,B,64.810000000,1,26,8058566346236,128,16855,94315082,CLX5
2025-09-24T19:37:08.856666310Z,2025-09-24T19:37:08.855818693Z,160,1,432669,C,B,64.810000000,1,26,8058566346262,128,15281,94315086,CLX5
2025-09-24T19:37:08.856706858Z,2025-09-24T19:37:08.855825701Z,160,1,432669,C,B,64.810000000,1,26,8058566346182,128,19229,94315087,CLX5
2025-09-24T19:37:08.857206938Z,2025-09-24T19:37:08.856128009Z,160,1,432669,C,B,64.810000000,1,26,8058566344904,128,16065,94315106,CLX5
2025-09-24T19:37:08.857349601Z,2025-09-24T19:37:08.856155425Z,160,1,432669,A,A,64.820000000,3,26,8058566346278,128,19128,94315112,CLX5
2025-09-24T19:37:08.867456994Z,2025-09-24T19:37:08.867325091Z,160,1,432669,C,B,64.810000000,1,26,8058566345497,128,19335,94315273,CLX5
2025-09-24T19:37:08.867654252Z,2025-09-24T19:37:08.867462115Z,160,1,432669,C,B,64.810000000,1,26,8058566344836,128,18172,94315280,CLX5
2025-09-24T19:37:08.867794351Z,2025-09-24T19:37:08.867664225Z,160,1,432669,A,B,64.810000000,1,26,8058566346339,128,19447,94315281,CLX5
2025-09-24T19:37:08.889485763Z,2025-09-24T19:37:08.889085257Z,160,1,432669,A,A,64.820000000,1,26,8058566346410,128,15189,94315414,CLX5
2025-09-24T19:37:08.890856103Z,2025-09-24T19:37:08.890716725Z,160,1,432669,M,B,63.640000000,4,26,8058566319851,128,19642,94315428,CLX5
2025-09-24T19:37:08.911242282Z,2025-09-24T19:37:08.911118897Z,160,1,432669,A,B,64.780000000,2,26,8058566346446,128,14980,94315475,CLX5
2025-09-24T19:37:08.911276840Z,2025-09-24T19:37:08.911124905Z,160,1,432669,A,B,64.770000000,2,26,8058566346447,128,18143,94315476,CLX5
2025-09-24T19:37:08.913181680Z,2025-09-24T19:37:08.913053173Z,160,1,432669,C,B,64.790000000,1,26,8058566345526,128,18509,94315488,CLX5
2025-09-24T19:37:08.923456273Z,2025-09-24T19:37:08.923366189Z,160,1,432669,C,B,64.540000000,8,26,8058566341136,128,17908,94315552,CLX5
2025-09-24T19:37:09.005973567Z,2025-09-24T19:37:09.005829127Z,160,1,432669,C,A,64.830000000,1,26,8058566345612,128,18848,94315720,CLX5
2025-09-24T19:37:09.006409284Z,2025-09-24T19:37:09.006283551Z,160,1,432669,A,A,64.820000000,1,26,8058566346598,128,18830,94315721,CLX5
2025-09-24T19:37:09.006560757Z,2025-09-24T19:37:09.006422687Z,160,1,432669,C,B,64.810000000,1,26,8058566346339,128,22380,94315722,CLX5
2025-09-24T19:37:09.009926317Z,2025-09-24T19:37:09.009793789Z,160,1,432669,M,A,64.830000000,1,26,8058566173085,128,18919,94315731,CLX5
2025-09-24T19:37:09.020495261Z,2025-09-24T19:37:09.020339787Z,160,1,432669,C,B,64.770000000,2,26,8058566346447,128,14736,94315839,CLX5
2025-09-24T19:37:09.102240779Z,2025-09-24T19:37:09.102100513Z,160,1,432669,A,B,64.810000000,1,26,8058566346733,128,20557,94316001,CLX5
2025-09-24T19:37:13.046995854Z,2025-09-24T19:37:13.046826379Z,160,1,432669,A,A,64.820000000,1,26,8058566346946,128,18940,94316492,CLX5
2025-09-24T19:37:14.397706165Z,2025-09-24T19:37:14.397532889Z,160,1,432669,A,A,64.850000000,1,26,8058566346951,128,14945,94316504,CLX5
2025-09-24T19:37:14.398007144Z,2025-09-24T19:37:14.397553103Z,160,1,432669,C,B,64.810000000,1,26,8058566346733,128,19297,94316513,CLX5
2025-09-24T19:37:15.023605641Z,2025-09-24T19:37:15.023415121Z,160,1,432669,A,B,64.810000000,1,26,8058566346991,128,16348,94316669,CLX5
2025-09-24T19:37:18.565261037Z,2025-09-24T19:37:18.565105679Z,160,1,432669,C,B,64.810000000,1,26,8058566346991,128,20788,94316889,CLX5
2025-09-24T19:37:18.565515025Z,2025-09-24T19:37:18.565330615Z,160,1,432669,A,A,64.850000000,2,26,8058566347088,128,14584,94316892,CLX5
2025-09-24T19:37:18.565565964Z,2025-09-24T19:37:18.565330979Z,160,1,432669,C,B,64.810000000,1,26,8058566342791,128,19524,94316893,CLX5
2025-09-24T19:37:18.566041568Z,2025-09-24T19:37:18.565384719Z,160,1,432669,C,B,64.810000000,1,26,8058566344837,128,19507,94316909,CLX5
2025-09-24T19:37:18.611211882Z,2025-09-24T19:37:18.611083925Z,160,1,432669,C,A,64.870000000,2,26,8058566343201,128,17874,94317076,CLX5
2025-09-24T19:37:18.616870961Z,2025-09-24T19:37:18.616766047Z,160,1,432669,C,A,65.900000000,1,26,8058566343202,128,18553,94317077,CLX5
2025-09-24T19:37:18.797295875Z,2025-09-24T19:37:18.796971005Z,160,1,432669,A,B,64.810000000,1,26,8058566347174,128,19949,94317247,CLX5
2025-09-24T19:37:18.797568915Z,2025-09-24T19:37:18.797033941Z,160,1,432669,A,B,64.810000000,1,26,8058566347179,128,16702,94317258,CLX5
2025-09-24T19:37:18.797611959Z,2025-09-24T19:37:18.797034133Z,160,1,432669,A,B,64.810000000,1,26,8058566347180,128,19799,94317259,CLX5
2025-09-24T19:37:18.797983428Z,2025-09-24T19:37:18.797337939Z,160,1,432669,A,B,64.810000000,1,26,8058566347186,128,14914,94317278,CLX5
2025-09-24T19:37:18.798037623Z,2025-09-24T19:37:18.797342355Z,160,1,432669,C,A,64.850000000,2,26,8058566347088,128,14804,94317280,CLX5
2025-09-24T19:37:18.798307132Z,2025-09-24T19:37:18.797349383Z,160,1,432669,A,B,64.810000000,1,26,8058566347192,128,16300,94317293,CLX5
2025-09-24T19:37:18.799340214Z,2025-09-24T19:37:18.798107211Z,160,1,432669,A,B,64.800000000,2,26,8058566347206,128,19414,94317337,CLX5
2025-09-24T19:37:18.799392574Z,2025-09-24T19:37:18.798113279Z,160,1,432669,A,B,64.540000000,8,26,8058566347210,128,14737,94317340,CLX5
2025-09-24T19:37:18.799884674Z,2025-09-24T19:37:18.798317173Z,160,1,432669,A,B,64.810000000,1,26,8058566347219,128,19400,94317361,CLX5
2025-09-24T19:37:18.800969264Z,2025-09-24T19:37:18.799274519Z,160,1,432669,C,B,64.810000000,1,26,8058566347192,128,14657,94317424,CLX5
2025-09-24T19:37:18.801256704Z,2025-09-24T19:37:18.799893021Z,160,1,432669,A,B,64.810000000,1,26,8058566347239,128,19403,94317443,CLX5
2025-09-24T19:37:18.801539359Z,2025-09-24T19:37:18.800336693Z,160,1,432669,A,A,64.820000000,1,26,8058566347241,128,16091,94317460,CLX5
2025-09-24T19:37:18.801578202Z,2025-09-24T19:37:18.800340035Z,160,1,432669,A,A,64.820000000,1,26,8058566347242,128,18802,94317461,CLX5
2025-09-24T19:37:18.801952629Z,2025-09-24T19:37:18.800977905Z,160,1,432669,C,B,64.810000000,1,26,8058566347239,128,15013,94317482,CLX5
2025-09-24T19:37:18.802559333Z,2025-09-24T19:37:18.801684533Z,160,1,432669,C,B,64.800000000,2,26,8058566347206,128,14739,94317524,CLX5
2025-09-24T19:37:18.802681983Z,2025-09-24T19:37:18.801697799Z,160,1,432669,C,B,64.810000000,1,26,8058566347219,128,17924,94317529,CLX5
2025-09-24T19:37:18.817137614Z,2025-09-24T19:37:18.817032565Z,160,1,432669,A,A,65.900000000,1,26,8058566347325,128,18210,94317731,CLX5
2025-09-24T19:37:18.823155508Z,2025-09-24T19:37:18.823056163Z,160,1,432669,C,B,64.540000000,8,26,8058566347210,128,18087,94317736,CLX5
2025-09-24T19:37:18.886513215Z,2025-09-24T19:37:18.886365313Z,160,1,432669,A,B,64.750000000,1,26,8058566347345,128,18384,94317775,CLX5
2025-09-24T19:37:18.911245283Z,2025-09-24T19:37:18.911114479Z,160,1,432669,A,A,64.870000000,2,26,8058566347355,128,14891,94317795,CLX5
2025-09-24T19:37:18.911282299Z,2025-09-24T19:37:18.911118817Z,160,1,432669,A,B,64.770000000,2,26,8058566347356,128,14744,94317796,CLX5
2025-09-24T19:37:19.034512127Z,2025-09-24T19:37:19.034358353Z,160,1,432669,C,B,64.810000000,1,26,8058566347186,128,21635,94317838,CLX5
2025-09-24T19:37:20.672377045Z,2025-09-24T19:37:20.672260509Z,160,1,432669,C,A,69.000000000,1,26,8058355891698,128,18436,94317905,CLX5
2025-09-24T19:37:24.109589063Z,2025-09-24T19:37:24.108298697Z,160,1,432669,C,B,64.810000000,1,26,8058566347180,128,18657,94318054,CLX5
2025-09-24T19:37:24.109809590Z,2025-09-24T19:37:24.108451213Z,160,1,432669,C,B,64.810000000,1,26,8058566347179,128,20301,94318069,CLX5
2025-09-24T19:37:24.110515137Z,2025-09-24T19:37:24.109001751Z,160,1,432669,C,B,64.810000000,1,26,8058566347174,128,20090,94318112,CLX5
2025-09-24T19:37:24.112681306Z,2025-09-24T19:37:24.109436745Z,160,1,432669,C,B,64.770000000,2,26,8058566347356,128,18562,94318264,CLX5
2025-09-24T19:37:24.121564703Z,2025-09-24T19:37:24.118937889Z,160,1,432669,C,B,64.810000000,2,26,8058566342995,128,17407,94318856,CLX5
2025-09-24T19:37:24.122782695Z,2025-09-24T19:37:24.121019461Z,160,1,432669,M,B,64.790000000,1,26,8058566337316,128,18474,94318929,CLX5
2025-09-24T19:37:24.212798559Z,2025-09-24T19:37:24.212483629Z,160,1,432669,A,B,64.810000000,1,26,8058566347887,128,18541,94319315,CLX5
2025-09-24T19:37:24.212845259Z,2025-09-24T19:37:24.212483841Z,160,1,432669,A,B,64.810000000,1,26,8058566347888,128,19154,94319316,CLX5
2025-09-24T19:37:24.213337659Z,2025-09-24T19:37:24.212835953Z,160,1,432669,M,B,64.800000000,1,26,8058566337316,128,15068,94319348,CLX5
2025-09-24T19:37:24.213396569Z,2025-09-24T19:37:24.212844633Z,160,1,432669,A,B,64.810000000,1,26,8058566347895,128,16593,94319350,CLX5
2025-09-24T19:37:24.356987767Z,2025-09-24T19:37:24.356882649Z,160,1,432669,C,A,69.500000000,1,26,8058355890181,128,14480,94319748,CLX5
2025-09-24T19:37:28.391473045Z,2025-09-24T19:37:28.391108673Z,160,1,432669,T,B,64.820000000,1,26,8058566348566,0,20177,94320674,CLX5
2025-09-24T19:37:28.391473045Z,2025-09-24T19:37:28.391108673Z,160,1,432669,F,A,64.820000000,1,26,8058566345869,0,20177,94320674,CLX5
2025-09-24T19:37:28.391485501Z,2025-09-24T19:37:28.391108673Z,160,1,432669,M,A,64.820000000,1,26,8058566345869,128,17617,94320675,CLX5
2025-09-24T19:37:28.391733460Z,2025-09-24T19:37:28.391447787Z,160,1,432669,A,B,64.810000000,1,26,8058566348569,128,20420,94320679,CLX5
2025-09-24T19:37:28.391877513Z,2025-09-24T19:37:28.391475471Z,160,1,432669,A,B,64.810000000,1,26,8058566348572,128,16790,94320685,CLX5
2025-09-24T19:37:28.392387470Z,2025-09-24T19:37:28.391880863Z,160,1,432669,C,B,64.810000000,1,26,8058566348569,128,19776,94320707,CLX5
2025-09-24T19:37:28.393908245Z,2025-09-24T19:37:28.393075759Z,160,1,432669,A,B,64.810000000,2,26,8058566348602,128,16009,94320784,CLX5
2025-09-24T19:37:28.511262257Z,2025-09-24T19:37:28.511115377Z,160,1,432669,A,B,64.770000000,2,26,8058566348682,128,18004,94321033,CLX5
2025-09-24T19:37:28.587498839Z,2025-09-24T19:37:28.587340393Z,160,1,432669,A,B,64.810000000,1,26,8058566348697,128,19224,94321059,CLX5
2025-09-24T19:37:28.587667767Z,2025-09-24T19:37:28.587534381Z,160,1,432669,A,B,64.810000000,1,26,8058566348698,128,19260,94321060,CLX5
2025-09-24T19:37:28.587833124Z,2025-09-24T19:37:28.587698937Z,160,1,432669,A,B,64.810000000,1,26,8058566348700,128,16051,94321062,CLX5
2025-09-24T19:37:29.315032994Z,2025-09-24T19:37:29.314886941Z,160,1,432669,A,B,64.800000000,1,26,8058566348718,128,18958,94321092,CLX5
2025-09-24T19:37:29.315065003Z,2025-09-24T19:37:29.314894061Z,160,1,432669,C,B,64.810000000,1,26,8058566348700,128,16441,94321093,CLX5
2025-09-24T19:37:29.315098217Z,2025-09-24T19:37:29.314905351Z,160,1,432669,C,B,64.810000000,1,26,8058566348698,128,15735,94321094,CLX5
2025-09-24T19:37:32.075184331Z,2025-09-24T19:37:32.074995371Z,160,1,432669,C,B,64.810000000,1,26,8058566348697,128,20854,94321322,CLX5
2025-09-24T19:37:32.633506697Z,2025-09-24T19:37:32.633371189Z,160,1,432669,A,B,64.800000000,1,26,8058566348768,128,18838,94321477,CLX5
2025-09-24T19:37:33.739674608Z,2025-09-24T19:37:33.739518907Z,160,1,432669,A,B,64.800000000,1,26,8058566348815,128,21216,94321541,CLX5
2025-09-24T19:37:35.513061719Z,2025-09-24T19:37:35.512701327Z,160,1,432669,T,A,64.810000000,1,26,8058566348826,0,18260,94321553,CLX5
2025-09-24T19:37:35.513061719Z,2025-09-24T19:37:35.512701327Z,160,1,432669,F,B,64.810000000,1,26,8058566344919,0,18260,94321553,CLX5
2025-09-24T19:37:35.513074244Z,2025-09-24T19:37:35.512701327Z,160,1,432669,C,B,64.810000000,1,26,8058566344919,128,17423,94321554,CLX5
2025-09-24T19:37:35.513845106Z,2025-09-24T19:37:35.513689045Z,160,1,432669,C,B,64.810000000,1,26,8058566348572,128,14746,94321560,CLX5
2025-09-24T19:37:35.513895085Z,2025-09-24T19:37:35.513696993Z,160,1,432669,C,B,64.810000000,2,26,8058566348602,128,17020,94321561,CLX5
2025-09-24T19:37:36.203970164Z,2025-09-24T19:37:36.203833779Z,160,1,432669,A,B,64.810000000,1,26,8058566348830,128,20293,94321574,CLX5
2025-09-24T19:37:36.204142733Z,2025-09-24T19:37:36.204016171Z,160,1,432669,C,B,64.800000000,1,26,8058566348815,128,18383,94321575,CLX5
2025-09-24T19:37:36.204171900Z,2025-09-24T19:37:36.204024675Z,160,1,432669,C,B,64.800000000,1,26,8058566348768,128,17382,94321576,CLX5
2025-09-24T19:37:36.695819207Z,2025-09-24T19:37:36.695662915Z,160,1,432669,A,B,64.800000000,1,26,8058566348834,128,19297,94321590,CLX5
2025-09-24T19:37:37.058132577Z,2025-09-24T19:37:37.057991289Z,160,1,432669,C,B,64.800000000,1,26,8058566348718,128,19386,94321591,CLX5
2025-09-24T19:37:38.929895588Z,2025-09-24T19:37:38.929726699Z,160,1,432669,C,B,64.810000000,1,26,8058566348830,128,18818,94321600,CLX5
2025-09-24T19:37:38.930164052Z,2025-09-24T19:37:38.929942363Z,160,1,432669,C,B,64.770000000,2,26,8058566348682,128,17195,94321604,CLX5
2025-09-24T19:37:40.478897453Z,2025-09-24T19:37:40.478745769Z,160,1,432669,A,B,64.810000000,2,26,8058566348847,128,20019,94321654,CLX5
2025-09-24T19:37:40.478932725Z,2025-09-24T19:37:40.478747497Z,160,1,432669,A,B,64.810000000,1,26,8058566348848,128,15958,94321655,CLX5
2025-09-24T19:37:40.611306018Z,2025-09-24T19:37:40.611163461Z,160,1,432669,A,B,64.770000000,2,26,8058566348887,128,18120,94321738,CLX5
2025-09-24T19:37:49.646205117Z,2025-09-24T19:37:49.646073981Z,160,1,432669,A,A,64.950000000,1,26,8058566349026,128,20347,94322025,CLX5
2025-09-24T19:37:50.911752180Z,2025-09-24T19:37:50.911241681Z,160,1,432669,T,B,64.820000000,11,26,8058566349029,0,24726,94322034,CLX5
2025-09-24T19:37:50.911752180Z,2025-09-24T19:37:50.911241681Z,160,1,432669,F,A,64.820000000,1,26,8058566345869,0,24726,94322034,CLX5
2025-09-24T19:37:50.911752180Z,2025-09-24T19:37:50.911241681Z,160,1,432669,F,A,64.820000000,1,26,8058566345892,0,24726,94322034,CLX5
2025-09-24T19:37:50.911752180Z,2025-09-24T19:37:50.911241681Z,160,1,432669,F,A,64.820000000,2,26,8058566345905,0,24726,94322034,CLX5
2025-09-24T19:37:50.911752180Z,2025-09-24T19:37:50.911241681Z,160,1,432669,F,A,64.820000000,1,26,8058566345920,0,24726,94322034,CLX5
2025-09-24T19:37:50.911752180Z,2025-09-24T19:37:50.911241681Z,160,1,432669,F,A,64.820000000,2,26,8058566345959,0,24726,94322034,CLX5
2025-09-24T19:37:50.911752180Z,2025-09-24T19:37:50.911241681Z,160,1,432669,F,A,64.820000000,3,26,8058566346047,0,24726,94322034,CLX5
2025-09-24T19:37:50.911752180Z,2025-09-24T19:37:50.911241681Z,160,1,432669,F,A,64.820000000,1,26,8058566345893,0,24726,94322034,CLX5
2025-09-24T19:37:50.911769082Z,2025-09-24T19:37:50.911241681Z,160,1,432669,C,A,64.820000000,1,26,8058566345869,0,19975,94322035,CLX5
2025-09-24T19:37:50.911769082Z,2025-09-24T19:37:50.911241681Z,160,1,432669,C,A,64.820000000,1,26,8058566345892,0,19975,94322035,CLX5
2025-09-24T19:37:50.911769082Z,2025-09-24T19:37:50.911241681Z,160,1,432669,C,A,64.820000000,2,26,8058566345905,0,19975,94322035,CLX5
2025-09-24T19:37:50.911769082Z,2025-09-24T19:37:50.911241681Z,160,1,432669,C,A,64.820000000,1,26,8058566345920,0,19975,94322035,CLX5
2025-09-24T19:37:50.911769082Z,2025-09-24T19:37:50.911241681Z,160,1,432669,C,A,64.820000000,2,26,8058566345959,0,19975,94322035,CLX5
2025-09-24T19:37:50.911769082Z,2025-09-24T19:37:50.911241681Z,160,1,432669,C,A,64.820000000,3,26,8058566346047,0,19975,94322035,CLX5
2025-09-24T19:37:50.911769082Z,2025-09-24T19:37:50.911241681Z,160,1,432669,C,A,64.820000000,1,26,8058566345893,128,19975,94322035,CLX5
2025-09-24T19:37:50.911912238Z,2025-09-24T19:37:50.911650413Z,160,1,432669,A,B,64.810000000,1,26,8058566349034,128,21124,94322040,CLX5
2025-09-24T19:37:50.912070407Z,2025-09-24T19:37:50.911663487Z,160,1,432669,A,B,64.810000000,1,26,8058566349036,128,18904,94322044,CLX5
2025-09-24T19:37:50.912135499Z,2025-09-24T19:37:50.911680671Z,160,1,432669,A,B,64.810000000,1,26,8058566349038,128,18746,94322047,CLX5
2025-09-24T19:37:50.912171347Z,2025-09-24T19:37:50.911693457Z,160,1,432669,A,B,64.810000000,1,26,8058566349039,128,21323,94322048,CLX5
2025-09-24T19:37:50.912209814Z,2025-09-24T19:37:50.911722757Z,160,1,432669,C,A,64.820000000,1,26,8058566346263,128,17967,94322049,CLX5
2025-09-24T19:37:50.912245701Z,2025-09-24T19:37:50.911724963Z,160,1,432669,A,B,64.810000000,1,26,8058566349040,128,19335,94322050,CLX5
2025-09-24T19:37:50.912539422Z,2025-09-24T19:37:50.911753601Z,160,1,432669,T,B,64.820000000,7,26,8058566349044,0,22700,94322060,CLX5
2025-09-24T19:37:50.912539422Z,2025-09-24T19:37:50.911753601Z,160,1,432669,F,A,64.820000000,1,26,8058566331891,0,22700,94322060,CLX5
2025-09-24T19:37:50.912539422Z,2025-09-24T19:37:50.911753601Z,160,1,432669,F,A,64.820000000,1,26,8058566346265,0,22700,94322060,CLX5
2025-09-24T19:37:50.912539422Z,2025-09-24T19:37:50.911753601Z,160,1,432669,F,A,64.820000000,3,26,8058566346278,0,22700,94322060,CLX5
2025-09-24T19:37:50.912539422Z,2025-09-24T19:37:50.911753601Z,160,1,432669,F,A,64.820000000,1,26,8058566346410,0,22700,94322060,CLX5
2025-09-24T19:37:50.912539422Z,2025-09-24T19:37:50.911753601Z,160,1,432669,F,A,64.820000000,1,26,8058566332416,0,22700,94322060,CLX5
2025-09-24T19:37:50.912539422Z,2025-09-24T19:37:50.911753601Z,160,1,432669,C,A,64.820000000,1,26,8058566331891,0,22700,94322060,CLX5
2025-09-24T19:37:50.912539422Z,2025-09-24T19:37:50.911753601Z,160,1,432669,C,A,64.820000000,1,26,8058566346265,0,22700,94322060,CLX5
2025-09-24T19:37:50.912539422Z,2025-09-24T19:37:50.911753601Z,160,1,432669,C,A,64.820000000,3,26,8058566346278,0,22700,94322060,CLX5
2025-09-24T19:37:50.912539422Z,2025-09-24T19:37:50.911753601Z,160,1,432669,C,A,64.820000000,1,26,8058566346410,0,22700,94322060,CLX5
2025-09-24T19:37:50.912539422Z,2025-09-24T19:37:50.911753601Z,160,1,432669,C,A,64.820000000,1,26,8058566332416,128,22700,94322060,CLX5
2025-09-24T19:37:50.912969634Z,2025-09-24T19:37:50.911782773Z,160,1,432669,A,A,64.820000000,2,26,8058566349051,128,15080,94322075,CLX5
2025-09-24T19:37:50.913260575Z,2025-09-24T19:37:50.911940205Z,160,1,432669,C,B,64.810000000,1,26,8058566349040,128,15807,94322089,CLX5
2025-09-24T19:37:50.913319485Z,2025-09-24T19:37:50.912067899Z,160,1,432669,A,A,64.820000000,1,26,8058566349053,128,19638,94322091,CLX5
2025-09-24T19:37:50.913581244Z,2025-09-24T19:37:50.912221185Z,160,1,432669,C,A,64.850000000,1,26,8058566346951,128,14968,94322102,CLX5
2025-09-24T19:37:50.913649616Z,2025-09-24T19:37:50.912355445Z,160,1,432669,A,B,64.800000000,2,26,8058566349059,128,17715,94322104,CLX5
2025-09-24T19:37:50.913714639Z,2025-09-24T19:37:50.912359265Z,160,1,432669,A,B,64.540000000,8,26,8058566349061,128,14210,94322107,CLX5
2025-09-24T19:37:50.913745787Z,2025-09-24T19:37:50.912365275Z,160,1,432669,C,B,64.770000000,2,26,8058566348887,128,18267,94322108,CLX5
2025-09-24T19:37:50.913891001Z,2025-09-24T19:37:50.912418417Z,160,1,432669,A,B,64.810000000,1,26,8058566349065,128,13943,94322112,CLX5
2025-09-24T19:37:50.914737431Z,2025-09-24T19:37:50.912582687Z,160,1,432669,M,B,64.810000000,1,26,8058566337316,128,17411,94322144,CLX5
2025-09-24T19:37:50.914802039Z,2025-09-24T19:37:50.912603709Z,160,1,432669,A,A,64.820000000,1,26,8058566349075,128,16594,94322146,CLX5
2025-09-24T19:37:50.915101882Z,2025-09-24T19:37:50.912796143Z,160,1,432669,A,B,64.790000000,1,26,8058566349077,128,14556,94322160,CLX5
2025-09-24T19:37:50.915896335Z,2025-09-24T19:37:50.913182907Z,160,1,432669,A,B,64.810000000,1,26,8058566349088,128,15116,94322200,CLX5
2025-09-24T19:37:50.915993889Z,2025-09-24T19:37:50.913265601Z,160,1,432669,A,A,64.820000000,2,26,8058566349090,128,16530,94322203,CLX5
2025-09-24T19:37:50.917883692Z,2025-09-24T19:37:50.914934697Z,160,1,432669,C,B,64.810000000,1,26,8058566349088,128,15611,94322306,CLX5
2025-09-24T19:37:50.919049770Z,2025-09-24T19:37:50.915906041Z,160,1,432669,A,B,64.810000000,1,26,8058566349126,128,16038,94322371,CLX5
2025-09-24T19:37:50.919222200Z,2025-09-24T19:37:50.916019065Z,160,1,432669,A,B,64.810000000,1,26,8058566349128,128,14237,94322376,CLX5
2025-09-24T19:37:50.919870381Z,2025-09-24T19:37:50.917193383Z,160,1,432669,C,B,64.810000000,1,26,8058566349126,128,14175,94322418,CLX5
2025-09-24T19:37:50.920143351Z,2025-09-24T19:37:50.917667101Z,160,1,432669,C,A,64.820000000,1,26,8058566349053,128,15671,94322426,CLX5
2025-09-24T19:37:50.920214903Z,2025-09-24T19:37:50.917910489Z,160,1,432669,A,B,64.810000000,1,26,8058566349144,128,13729,94322429,CLX5
2025-09-24T19:37:50.920425662Z,2025-09-24T19:37:50.918140419Z,160,1,432669,A,B,64.810000000,1,26,8058566349146,128,14949,94322441,CLX5
2025-09-24T19:37:50.920900852Z,2025-09-24T19:37:50.919203477Z,160,1,432669,C,B,64.810000000,1,26,8058566349146,128,16228,94322461,CLX5
2025-09-24T19:37:50.921182863Z,2025-09-24T19:37:50.920085003Z,160,1,432669,A,A,64.820000000,1,26,8058566349161,128,14617,94322485,CLX5
2025-09-24T19:37:50.921259974Z,2025-09-24T19:37:50.920151319Z,160,1,432669,A,B,64.810000000,1,26,8058566349162,128,14932,94322487,CLX5
2025-09-24T19:37:50.921300245Z,2025-09-24T19:37:50.920378329Z,160,1,432669,C,B,64.810000000,1,26,8058566349162,128,14837,94322489,CLX5
2025-09-24T19:37:50.921851625Z,2025-09-24T19:37:50.920926925Z,160,1,432669,A,B,64.810000000,1,26,8058566349182,128,14657,94322526,CLX5
2025-09-24T19:37:50.922181701Z,2025-09-24T19:37:50.921866591Z,160,1,432669,C,B,64.800000000,1,26,8058566346121,128,18166,94322538,CLX5
2025-09-24T19:37:50.924637706Z,2025-09-24T19:37:50.924219197Z,160,1,432669,T,A,64.810000000,1,26,8058566349198,0,17364,94322585,CLX5
2025-09-24T19:37:50.924637706Z,2025-09-24T19:37:50.924219197Z,160,1,432669,F,B,64.810000000,1,26,8058566345298,0,17364,94322585,CLX5
2025-09-24T19:37:50.924654447Z,2025-09-24T19:37:50.924219197Z,160,1,432669,C,B,64.810000000,1,26,8058566345298,128,18976,94322586,CLX5
2025-09-24T19:37:50.924713450Z,2025-09-24T19:37:50.924544237Z,160,1,432669,A,A,64.820000000,2,26,8058566349201,128,16699,94322588,CLX5
2025-09-24T19:37:50.924749275Z,2025-09-24T19:37:50.924545793Z,160,1,432669,A,A,64.820000000,1,26,8058566349202,128,17918,94322589,CLX5
2025-09-24T19:37:50.925004998Z,2025-09-24T19:37:50.924646703Z,160,1,432669,A,A,64.850000000,1,26,8058566349206,128,17298,94322601,CLX5
2025-09-24T19:37:50.925141211Z,2025-09-24T19:37:50.924722367Z,160,1,432669,C,A,64.820000000,1,26,8058566349202,128,16793,94322607,CLX5
2025-09-24T19:37:50.925199653Z,2025-09-24T19:37:50.924855553Z,160,1,432669,A,A,64.820000000,1,26,8058566349209,128,15579,94322609,CLX5
2025-09-24T19:37:50.925343061Z,2025-09-24T19:37:50.925073809Z,160,1,432669,A,A,64.820000000,1,26,8058566349211,128,15667,94322615,CLX5
2025-09-24T19:37:50.925428113Z,2025-09-24T19:37:50.925201119Z,160,1,432669,A,A,64.820000000,1,26,8058566349212,128,19238,94322618,CLX5
2025-09-24T19:37:50.925584792Z,2025-09-24T19:37:50.925351217Z,160,1,432669,C,A,64.820000000,1,26,8058566349212,128,14473,94322624,CLX5
2025-09-24T19:37:50.927117440Z,2025-09-24T19:37:50.926985123Z,160,1,432669,C,B,64.810000000,1,26,8058566349036,128,18109,94322656,CLX5
2025-09-24T19:37:50.985499678Z,2025-09-24T19:37:50.985367655Z,160,1,432669,C,A,64.850000000,1,26,8058566349206,128,17876,94322782,CLX5
2025-09-24T19:37:50.985656135Z,2025-09-24T19:37:50.985521305Z,160,1,432669,C,B,64.810000000,1,26,8058566349182,128,19404,94322783,CLX5
2025-09-24T19:37:50.985687222Z,2025-09-24T19:37:50.985528293Z,160,1,432669,C,B,64.810000000,1,26,8058566349144,128,15395,94322784,CLX5
2025-09-24T19:37:50.985719860Z,2025-09-24T19:37:50.985536875Z,160,1,432669,C,B,64.810000000,1,26,8058566349128,128,14255,94322785,CLX5
2025-09-24T19:37:51.011424323Z,2025-09-24T19:37:51.011299007Z,160,1,432669,C,B,64.780000000,2,26,8058566346446,128,17912,94322822,CLX5
2025-09-24T19:37:51.093411577Z,2025-09-24T19:37:51.093275935Z,160,1,432669,C,B,64.790000000,1,26,8058566349077,128,18739,94322917,CLX5
2025-09-24T19:37:51.268640414Z,2025-09-24T19:37:51.268490461Z,160,1,432669,A,A,64.820000000,1,26,8058566349378,128,19082,94322980,CLX5
2025-09-24T19:37:56.072435135Z,2025-09-24T19:37:56.072296803Z,160,1,432669,M,A,64.940000000,1,26,8058566125142,128,19731,94323116,CLX5
2025-09-24T19:37:56.461610266Z,2025-09-24T19:37:56.461442669Z,160,1,432669,A,A,64.820000000,1,26,8058566349454,128,22009,94323120,CLX5
2025-09-24T19:37:56.461756854Z,2025-09-24T19:37:56.461618285Z,160,1,432669,C,B,64.810000000,1,26,8058566349039,128,18980,94323121,CLX5
2025-09-24T19:37:56.461789969Z,2025-09-24T19:37:56.461621127Z,160,1,432669,C,B,64.810000000,1,26,8058566349034,128,15649,94323122,CLX5
2025-09-24T19:37:56.462865013Z,2025-09-24T19:37:56.462729897Z,160,1,432669,A,A,64.850000000,1,26,8058566349467,128,18261,94323161,CLX5
2025-09-24T19:37:56.526101437Z,2025-09-24T19:37:56.525937369Z,160,1,432669,C,B,64.810000000,1,26,8058566349038,128,17867,94323163,CLX5
2025-09-24T19:37:56.526166975Z,2025-09-24T19:37:56.525938749Z,160,1,432669,C,B,64.800000000,2,26,8058566349059,128,15043,94323165,CLX5
2025-09-24T19:37:56.526219818Z,2025-09-24T19:37:56.525949233Z,160,1,432669,C,B,64.810000000,1,26,8058566348848,128,19150,94323166,CLX5
2025-09-24T19:37:56.526405134Z,2025-09-24T19:37:56.525963977Z,160,1,432669,A,A,64.820000000,3,26,8058566349469,128,18355,94323175,CLX5
2025-09-24T19:37:56.526443924Z,2025-09-24T19:37:56.525973961Z,160,1,432669,C,B,64.810000000,1,26,8058566349065,128,16741,94323176,CLX5
2025-09-24T19:37:56.526472415Z,2025-09-24T19:37:56.525988439Z,160,1,432669,A,B,64.800000000,1,26,8058566349470,128,13826,94323177,CLX5
2025-09-24T19:37:56.527201247Z,2025-09-24T19:37:56.526595093Z,160,1,432669,A,B,64.810000000,1,26,8058566349485,128,16375,94323212,CLX5
2025-09-24T19:37:56.527464373Z,2025-09-24T19:37:56.526982377Z,160,1,432669,C,B,64.810000000,2,26,8058566348847,128,18760,94323223,CLX5
2025-09-24T19:37:56.611380179Z,2025-09-24T19:37:56.611230699Z,160,1,432669,A,B,64.780000000,2,26,8058566349492,128,18404,94323243,CLX5
2025-09-24T19:37:56.623384734Z,2025-09-24T19:37:56.623276901Z,160,1,432669,C,B,64.540000000,8,26,8058566349061,128,18312,94323244,CLX5
2025-09-24T19:37:59.710001341Z,2025-09-24T19:37:59.709866941Z,160,1,432669,M,A,64.950000000,1,26,8058566131103,128,22314,94323261,CLX5
2025-09-24T19:38:00.025541202Z,2025-09-24T19:38:00.025375377Z,160,1,432669,A,B,64.810000000,1,26,8058566349498,128,22043,94323268,CLX5
2025-09-24T19:38:00.179092928Z,2025-09-24T19:38:00.178935273Z,160,1,432669,A,A,64.820000000,1,26,8058566349502,128,20629,94323273,CLX5
2025-09-24T19:38:01.285948991Z,2025-09-24T19:38:01.285776431Z,160,1,432669,A,B,64.810000000,1,26,8058566349504,128,25824,94323275,CLX5
2025-09-24T19:38:04.290506745Z,2025-09-24T19:38:04.290367409Z,160,1,432669,C,A,64.980000000,1,26,8058566344965,128,22573,94323309,CLX5
2025-09-24T19:38:04.306008467Z,2025-09-24T19:38:04.305884031Z,160,1,432669,A,A,64.970000000,1,26,8058566349514,128,20559,94323310,CLX5
2025-09-24T19:38:05.091198554Z,2025-09-24T19:38:05.091021395Z,160,1,432669,C,B,64.810000000,1,26,8058566349485,128,27614,94323311,CLX5
2025-09-24T19:38:07.125253681Z,2025-09-24T19:38:07.121646557Z,160,1,432669,C,B,64.810000000,1,26,8058566347888,128,16656,94323579,CLX5
2025-09-24T19:38:07.126181838Z,2025-09-24T19:38:07.121946737Z,160,1,432669,C,B,64.810000000,1,26,8058566347887,128,16691,94323637,CLX5
2025-09-24T19:38:07.126276066Z,2025-09-24T19:38:07.121974747Z,160,1,432669,A,A,64.820000000,1,26,8058566349632,128,15126,94323639,CLX5
2025-09-24T19:38:07.126303167Z,2025-09-24T19:38:07.121974927Z,160,1,432669,A,A,64.820000000,1,26,8058566349633,128,13809,94323640,CLX5
2025-09-24T19:38:07.126344092Z,2025-09-24T19:38:07.121983253Z,160,1,432669,A,A,64.820000000,1,26,8058566349634,128,17944,94323642,CLX5
2025-09-24T19:38:07.127070866Z,2025-09-24T19:38:07.122118473Z,160,1,432669,T,A,64.810000000,2,26,8058566349645,0,14341,94323671,CLX5
2025-09-24T19:38:07.127070866Z,2025-09-24T19:38:07.122118473Z,160,1,432669,F,B,64.810000000,1,26,8058566340051,0,14341,94323671,CLX5
2025-09-24T19:38:07.127070866Z,2025-09-24T19:38:07.122118473Z,160,1,432669,F,B,64.810000000,1,26,8058566347895,0,14341,94323671,CLX5
2025-09-24T19:38:07.127070866Z,2025-09-24T19:38:07.122118473Z,160,1,432669,C,B,64.810000000,1,26,8058566340051,0,14341,94323671,CLX5
2025-09-24T19:38:07.127070866Z,2025-09-24T19:38:07.122118473Z,160,1,432669,C,B,64.810000000,1,26,8058566347895,128,14341,94323671,CLX5
2025-09-24T19:38:07.127534644Z,2025-09-24T19:38:07.122236299Z,160,1,432669,T,A,64.810000000,3,26,8058566349653,0,15250,94323690,CLX5
2025-09-24T19:38:07.127534644Z,2025-09-24T19:38:07.122236299Z,160,1,432669,F,B,64.810000000,1,26,8058566337316,0,15250,94323690,CLX5
2025-09-24T19:38:07.127534644Z,2025-09-24T19:38:07.122236299Z,160,1,432669,F,B,64.810000000,1,26,8058566349498,0,15250,94323690,CLX5
2025-09-24T19:38:07.127534644Z,2025-09-24T19:38:07.122236299Z,160,1,432669,F,B,64.810000000,1,26,8058566349504,0,15250,94323690,CLX5
2025-09-24T19:38:07.127597579Z,2025-09-24T19:38:07.122236299Z,160,1,432669,C,B,64.810000000,1,26,8058566337316,0,18279,94323691,CLX5
2025-09-24T19:38:07.127597579Z,2025-09-24T19:38:07.122236299Z,160,1,432669,C,B,64.810000000,1,26,8058566349498,0,18279,94323691,CLX5
2025-09-24T19:38:07.127597579Z,2025-09-24T19:38:07.122236299Z,160,1,432669,C,B,64.810000000,1,26,8058566349504,128,18279,94323691,CLX5
2025-09-24T19:38:07.127660866Z,2025-09-24T19:38:07.122236491Z,160,1,432669,A,A,64.810000000,1,26,8058566349654,128,13597,94323694,CLX5
2025-09-24T19:38:07.127687300Z,2025-09-24T19:38:07.122236665Z,160,1,432669,A,A,64.810000000,1,26,8058566349655,128,16016,94323697,CLX5
2025-09-24T19:38:07.127744060Z,2025-09-24T19:38:07.122236951Z,160,1,432669,A,A,64.850000000,2,26,8058566349656,128,14356,94323700,CLX5
2025-09-24T19:38:07.127904487Z,2025-09-24T19:38:07.122248989Z,160,1,432669,A,A,64.820000000,1,26,8058566349663,128,14803,94323706,CLX5
2025-09-24T19:38:07.128652571Z,2025-09-24T19:38:07.122537647Z,160,1,432669,A,B,64.540000000,8,26,8058566349679,128,14865,94323747,CLX5
2025-09-24T19:38:07.132115817Z,2025-09-24T19:38:07.125343449Z,160,1,432669,A,A,64.820000000,3,26,8058566349748,128,14852,94324000,CLX5
2025-09-24T19:38:07.133594646Z,2025-09-24T19:38:07.126561403Z,160,1,432669,C,A,64.810000000,1,26,8058566349654,128,14821,94324087,CLX5
2025-09-24T19:38:07.133715384Z,2025-09-24T19:38:07.126561549Z,160,1,432669,C,A,64.810000000,1,26,8058566349655,128,18225,94324090,CLX5
2025-09-24T19:38:07.133761186Z,2025-09-24T19:38:07.126582563Z,160,1,432669,A,B,64.800000000,1,26,8058566349770,128,14643,94324094,CLX5
2025-09-24T19:38:07.134843172Z,2025-09-24T19:38:07.127136939Z,160,1,432669,M,A,64.810000000,1,26,8058566349502,128,18041,94324146,CLX5
2025-09-24T19:38:07.135447464Z,2025-09-24T19:38:07.127548665Z,160,1,432669,A,A,64.810000000,1,26,8058566349788,128,14722,94324180,CLX5
2025-09-24T19:38:07.135706743Z,2025-09-24T19:38:07.127662861Z,160,1,432669,A,A,64.810000000,1,26,8058566349791,128,18152,94324190,CLX5
2025-09-24T19:38:07.135786227Z,2025-09-24T19:38:07.127679411Z,160,1,432669,A,A,64.810000000,1,26,8058566349793,128,18413,94324195,CLX5
2025-09-24T19:38:07.135870894Z,2025-09-24T19:38:07.127702603Z,160,1,432669,C,A,64.850000000,1,26,8058566312900,128,15320,94324200,CLX5
2025-09-24T19:38:07.136082736Z,2025-09-24T19:38:07.127866815Z,160,1,432669,M,B,63.630000000,3,26,8058566221991,128,14113,94324211,CLX5
2025-09-24T19:38:07.136117555Z,2025-09-24T19:38:07.127879967Z,160,1,432669,M,B,63.620000000,3,26,8058566332677,128,14848,94324212,CLX5
2025-09-24T19:38:07.136360200Z,2025-09-24T19:38:07.127983777Z,160,1,432669,C,A,64.820000000,1,26,8058566347242,128,18721,94324223,CLX5
2025-09-24T19:38:07.136386464Z,2025-09-24T19:38:07.127987251Z,160,1,432669,C,A,64.820000000,1,26,8058566347241,128,15903,94324224,CLX5
2025-09-24T19:38:07.136532637Z,2025-09-24T19:38:07.128082057Z,160,1,432669,M,A,64.830000000,3,26,8058566331102,128,14404,94324230,CLX5
2025-09-24T19:38:07.136909675Z,2025-09-24T19:38:07.128482417Z,160,1,432669,A,A,64.810000000,1,26,8058566349807,128,20466,94324249,CLX5
2025-09-24T19:38:07.137132045Z,2025-09-24T19:38:07.128763837Z,160,1,432669,A,A,64.810000000,2,26,8058566349810,128,15027,94324261,CLX5
2025-09-24T19:38:07.140075874Z,2025-09-24T19:38:07.132243607Z,160,1,432669,C,A,64.810000000,1,26,8058566349791,128,16401,94324439,CLX5
2025-09-24T19:38:07.142050981Z,2025-09-24T19:38:07.132926501Z,160,1,432669,C,A,64.810000000,1,26,8058566349807,128,20423,94324576,CLX5
2025-09-24T19:38:07.142407821Z,2025-09-24T19:38:07.133605517Z,160,1,432669,C,A,64.810000000,2,26,8058566349810,128,18999,94324595,CLX5
2025-09-24T19:38:07.142460258Z,2025-09-24T19:38:07.133745845Z,160,1,432669,A,A,64.820000000,1,26,8058566349883,128,18010,94324598,CLX5
2025-09-24T19:38:07.142486652Z,2025-09-24T19:38:07.133789119Z,160,1,432669,A,A,64.820000000,1,26,8058566349884,128,15028,94324599,CLX5
2025-09-24T19:38:07.143072391Z,2025-09-24T19:38:07.134876311Z,160,1,432669,A,A,64.820000000,1,26,8058566349897,128,19161,94324631,CLX5
2025-09-24T19:38:07.143241480Z,2025-09-24T19:38:07.135252441Z,160,1,432669,A,A,64.810000000,2,26,8058566349900,128,18117,94324640,CLX5
2025-09-24T19:38:07.144968760Z,2025-09-24T19:38:07.137795273Z,160,1,432669,C,A,64.810000000,2,26,8058566349900,128,20852,94324741,CLX5
2025-09-24T19:38:07.146013900Z,2025-09-24T19:38:07.139478275Z,160,1,432669,T,B,64.810000000,1,26,8058566349952,0,14853,94324809,CLX5
2025-09-24T19:38:07.146013900Z,2025-09-24T19:38:07.139478275Z,160,1,432669,F,A,64.810000000,1,26,8058566349502,0,14853,94324809,CLX5
2025-09-24T19:38:07.146059225Z,2025-09-24T19:38:07.139478275Z,160,1,432669,C,A,64.810000000,1,26,8058566349502,128,14757,94324810,CLX5
2025-09-24T19:38:07.146259048Z,2025-09-24T19:38:07.139910827Z,160,1,432669,T,B,64.810000000,1,26,8058566349958,0,14560,94324826,CLX5
2025-09-24T19:38:07.146259048Z,2025-09-24T19:38:07.139910827Z,160,1,432669,F,A,64.810000000,1,26,8058566349788,0,14560,94324826,CLX5
2025-09-24T19:38:07.146309441Z,2025-09-24T19:38:07.139910827Z,160,1,432669,C,A,64.810000000,1,26,8058566349788,128,18486,94324827,CLX5
2025-09-24T19:38:07.146513719Z,2025-09-24T19:38:07.140203211Z,160,1,432669,A,B,64.800000000,1,26,8058566349963,128,14881,94324838,CLX5
2025-09-24T19:38:07.146651890Z,2025-09-24T19:38:07.140294041Z,160,1,432669,A,A,64.810000000,2,26,8058566349966,128,16991,94324843,CLX5
2025-09-24T19:38:07.146780308Z,2025-09-24T19:38:07.140414017Z,160,1,432669,C,B,64.800000000,1,26,8058566349963,128,14921,94324850,CLX5
2025-09-24T19:38:07.149531370Z,2025-09-24T19:38:07.146030827Z,160,1,432669,C,A,64.810000000,2,26,8058566349966,128,18291,94325019,CLX5
2025-09-24T19:38:07.150044306Z,2025-09-24T19:38:07.146492507Z,160,1,432669,C,A,64.820000000,1,26,8058566349897,128,18164,94325054,CLX5
2025-09-24T19:38:07.150071738Z,2025-09-24T19:38:07.146497519Z,160,1,432669,C,A,64.820000000,1,26,8058566349884,128,15585,94325055,CLX5
2025-09-24T19:38:07.150098409Z,2025-09-24T19:38:07.146502569Z,160,1,432669,C,A,64.820000000,1,26,8058566349883,128,14821,94325056,CLX5
2025-09-24T19:38:07.150107579Z,2025-09-24T19:38:07.146534553Z,160,1,432669,T,B,64.810000000,1,26,8058566350034,0,14329,94325057,CLX5
2025-09-24T19:38:07.150107579Z,2025-09-24T19:38:07.146534553Z,160,1,432669,F,A,64.810000000,1,26,8058566349793,0,14329,94325057,CLX5
2025-09-24T19:38:07.150158202Z,2025-09-24T19:38:07.146534553Z,160,1,432669,C,A,64.810000000,1,26,8058566349793,128,19505,94325058,CLX5
2025-09-24T19:38:07.152357432Z,2025-09-24T19:38:07.149540181Z,160,1,432669,A,A,64.810000000,2,26,8058566350079,128,14470,94325203,CLX5
2025-09-24T19:38:07.152704918Z,2025-09-24T19:38:07.150129517Z,160,1,432669,C,A,64.810000000,2,26,8058566350079,128,17067,94325221,CLX5
2025-09-24T19:38:07.153188810Z,2025-09-24T19:38:07.150662621Z,160,1,432669,C,A,64.830000000,1,26,8058566345790,128,15217,94325251,CLX5
2025-09-24T19:38:07.153520030Z,2025-09-24T19:38:07.150810627Z,160,1,432669,C,A,64.820000000,1,26,8058566349663,128,18048,94325280,CLX5
2025-09-24T19:38:07.156438055Z,2025-09-24T19:38:07.155211689Z,160,1,432669,M,A,64.810000000,1,26,8058566349161,128,14781,94325502,CLX5
2025-09-24T19:38:07.156966680Z,2025-09-24T19:38:07.156521339Z,160,1,432669,T,B,64.810000000,1,26,8058566350168,0,14640,94325548,CLX5
2025-09-24T19:38:07.156966680Z,2025-09-24T19:38:07.156521339Z,160,1,432669,F,A,64.810000000,1,26,8058566349161,0,14640,94325548,CLX5
2025-09-24T19:38:07.157016874Z,2025-09-24T19:38:07.156521339Z,160,1,432669,C,A,64.810000000,1,26,8058566349161,128,14503,94325549,CLX5
2025-09-24T19:38:07.157290974Z,2025-09-24T19:38:07.156908067Z,160,1,432669,M,A,65.980000000,3,26,8058566321460,128,15592,94325571,CLX5
2025-09-24T19:38:07.157787982Z,2025-09-24T19:38:07.157454783Z,160,1,432669,M,A,64.840000000,4,26,8058566331622,128,15024,94325606,CLX5
2025-09-24T19:38:07.160891761Z,2025-09-24T19:38:07.160780863Z,160,1,432669,M,A,64.930000000,1,26,8058565075241,128,17402,94325691,CLX5
2025-09-24T19:38:07.161656226Z,2025-09-24T19:38:07.161552555Z,160,1,432669,M,A,64.940000000,1,26,8058565075241,128,14094,94325715,CLX5
2025-09-24T19:38:07.164405346Z,2025-09-24T19:38:07.164266777Z,160,1,432669,A,A,64.820000000,1,26,8058566350235,128,18425,94325736,CLX5
2025-09-24T19:38:07.166785806Z,2025-09-24T19:38:07.166569427Z,160,1,432669,A,B,64.810000000,1,26,8058566350242,128,18247,94325751,CLX5
2025-09-24T19:38:07.167277239Z,2025-09-24T19:38:07.167148531Z,160,1,432669,M,A,65.970000000,4,26,8058566331102,128,18583,94325773,CLX5
2025-09-24T19:38:07.167422583Z,2025-09-24T19:38:07.167282389Z,160,1,432669,C,B,64.810000000,1,26,8058566350242,128,18629,94325776,CLX5
2025-09-24T19:38:07.178573589Z,2025-09-24T19:38:07.178418683Z,160,1,432669,A,A,64.820000000,1,26,8058566350259,128,18554,94325808,CLX5
2025-09-24T19:38:07.178603232Z,2025-09-24T19:38:07.178419067Z,160,1,432669,A,A,64.820000000,1,26,8058566350260,128,15185,94325809,CLX5
2025-09-24T19:38:07.211504572Z,2025-09-24T19:38:07.211378311Z,160,1,432669,C,A,64.870000000,2,26,8058566347355,128,17908,94326015,CLX5
2025-09-24T19:38:07.217140844Z,2025-09-24T19:38:07.217050469Z,160,1,432669,C,A,65.900000000,1,26,8058566347325,128,17436,94326072,CLX5
2025-09-24T19:38:07.223543694Z,2025-09-24T19:38:07.223436875Z,160,1,432669,C,B,64.540000000,8,26,8058566349679,128,18076,94326074,CLX5
2025-09-24T19:38:07.311862638Z,2025-09-24T19:38:07.311692559Z,160,1,432669,A,B,64.760000000,2,26,8058566350576,128,14452,94326398,CLX5
2025-09-24T19:38:08.030757178Z,2025-09-24T19:38:08.030604441Z,160,1,432669,A,B,64.780000000,1,26,8058566350923,128,18032,94327028,CLX5
2025-09-24T19:38:09.136935556Z,2025-09-24T19:38:09.136779313Z,160,1,432669,A,B,64.780000000,1,26,8058566351014,128,17805,94327260,CLX5
2025-09-24T19:38:10.047798764Z,2025-09-24T19:38:10.047636205Z,160,1,432669,C,B,64.800000000,1,26,8058566348834,128,18743,94327301,CLX5
2025-09-24T19:38:12.368601220Z,2025-09-24T19:38:12.365403637Z,160,1,432669,A,B,64.810000000,2,26,8058566351337,128,17161,94328104,CLX5
2025-09-24T19:38:12.370489671Z,2025-09-24T19:38:12.366614623Z,160,1,432669,A,B,64.810000000,1,26,8058566351375,128,18562,94328211,CLX5
2025-09-24T19:38:12.370964117Z,2025-09-24T19:38:12.366755065Z,160,1,432669,M,A,64.930000000,1,26,8058565075241,128,14983,94328253,CLX5
2025-09-24T19:38:12.371637018Z,2025-09-24T19:38:12.366989351Z,160,1,432669,A,B,64.810000000,2,26,8058566351394,128,18396,94328290,CLX5
2025-09-24T19:38:12.372461607Z,2025-09-24T19:38:12.367197489Z,160,1,432669,A,B,64.800000000,1,26,8058566351406,128,15057,94328352,CLX5
2025-09-24T19:38:12.374247053Z,2025-09-24T19:38:12.368734325Z,160,1,432669,C,B,64.810000000,2,26,8058566351337,128,21082,94328481,CLX5
2025-09-24T19:38:12.374742217Z,2025-09-24T19:38:12.368951755Z,160,1,432669,A,B,64.540000000,8,26,8058566351450,128,15482,94328514,CLX5
2025-09-24T19:38:12.374840071Z,2025-09-24T19:38:12.368958551Z,160,1,432669,A,B,64.810000000,1,26,8058566351452,128,22500,94328517,CLX5
2025-09-24T19:38:12.374886955Z,2025-09-24T19:38:12.368960229Z,160,1,432669,M,B,64.800000000,3,26,8058566332677,128,15158,94328520,CLX5
2025-09-24T19:38:12.375440539Z,2025-09-24T19:38:12.369038399Z,160,1,432669,A,B,64.810000000,1,26,8058566351466,128,17048,94328547,CLX5
2025-09-24T19:38:12.375747085Z,2025-09-24T19:38:12.369157685Z,160,1,432669,A,B,64.810000000,1,26,8058566351469,128,17207,94328560,CLX5
2025-09-24T19:38:12.377883518Z,2025-09-24T19:38:12.370767245Z,160,1,432669,C,B,64.810000000,1,26,8058566351375,128,17474,94328691,CLX5
2025-09-24T19:38:12.378513561Z,2025-09-24T19:38:12.371298603Z,160,1,432669,M,A,64.940000000,1,26,8058565075241,128,18779,94328734,CLX5
2025-09-24T19:38:12.378740147Z,2025-09-24T19:38:12.371396537Z,160,1,432669,C,A,64.850000000,2,26,8058566349656,128,18592,94328748,CLX5
2025-09-24T19:38:12.378870861Z,2025-09-24T19:38:12.371409503Z,160,1,432669,A,B,64.810000000,1,26,8058566351515,128,19358,94328751,CLX5
2025-09-24T19:38:12.379006360Z,2025-09-24T19:38:12.371521983Z,160,1,432669,C,A,64.820000000,1,26,8058566349634,128,15348,94328757,CLX5
2025-09-24T19:38:12.379086228Z,2025-09-24T19:38:12.371584093Z,160,1,432669,A,B,64.810000000,1,26,8058566351518,128,20356,94328760,CLX5
2025-09-24T19:38:12.379116447Z,2025-09-24T19:38:12.371589583Z,160,1,432669,C,A,64.820000000,1,26,8058566349633,128,14307,94328761,CLX5
2025-09-24T19:38:12.379652706Z,2025-09-24T19:38:12.371857201Z,160,1,432669,A,B,64.800000000,2,26,8058566351526,128,15025,94328802,CLX5
2025-09-24T19:38:12.379772062Z,2025-09-24T19:38:12.371884043Z,160,1,432669,A,B,64.810000000,1,26,8058566351528,128,16447,94328806,CLX5
2025-09-24T19:38:12.382114508Z,2025-09-24T19:38:12.374223401Z,160,1,432669,A,B,64.810000000,2,26,8058566351589,128,19546,94328964,CLX5
2025-09-24T19:38:12.382349027Z,2025-09-24T19:38:12.374339479Z,160,1,432669,C,B,64.810000000,1,26,8058566351469,128,15938,94328975,CLX5
2025-09-24T19:38:12.382941516Z,2025-09-24T19:38:12.374628829Z,160,1,432669,C,A,64.820000000,2,26,8058566349201,128,15270,94329010,CLX5
2025-09-24T19:38:12.383275702Z,2025-09-24T19:38:12.374759633Z,160,1,432669,A,B,64.810000000,2,26,8058566351602,128,15926,94329025,CLX5
2025-09-24T19:38:12.384633147Z,2025-09-24T19:38:12.375157091Z,160,1,432669,C,A,64.820000000,3,26,8058566349469,128,18603,94329090,CLX5
2025-09-24T19:38:12.385120910Z,2025-09-24T19:38:12.375439993Z,160,1,432669,A,B,64.810000000,1,26,8058566351637,128,15466,94329117,CLX5
2025-09-24T19:38:12.386021511Z,2025-09-24T19:38:12.376569193Z,160,1,432669,C,B,64.800000000,2,26,8058566351526,128,18218,94329170,CLX5
2025-09-24T19:38:12.387288476Z,2025-09-24T19:38:12.377896161Z,160,1,432669,C,B,64.800000000,1,26,8058566351406,128,18224,94329252,CLX5
2025-09-24T19:38:12.387549643Z,2025-09-24T19:38:12.378617989Z,160,1,432669,A,B,64.810000000,1,26,8058566351692,128,15496,94329266,CLX5
2025-09-24T19:38:12.387656489Z,2025-09-24T19:38:12.378822135Z,160,1,432669,A,B,64.810000000,1,26,8058566351694,128,15487,94329270,CLX5
2025-09-24T19:38:12.388130305Z,2025-09-24T19:38:12.379294205Z,160,1,432669,C,B,64.810000000,2,26,8058566351602,128,15735,94329303,CLX5
2025-09-24T19:38:12.388426892Z,2025-09-24T19:38:12.379792249Z,160,1,432669,C,B,64.810000000,1,26,8058566351528,128,19382,94329318,CLX5
2025-09-24T19:38:12.389017468Z,2025-09-24T19:38:12.380461205Z,160,1,432669,A,B,64.810000000,1,26,8058566351721,128,16315,94329347,CLX5
2025-09-24T19:38:12.390763862Z,2025-09-24T19:38:12.382231655Z,160,1,432669,C,B,64.810000000,1,26,8058566351694,128,19331,94329447,CLX5
2025-09-24T19:38:12.390808488Z,2025-09-24T19:38:12.382249317Z,160,1,432669,C,B,64.810000000,1,26,8058566351692,128,15979,94329449,CLX5
2025-09-24T19:38:12.391616551Z,2025-09-24T19:38:12.383233371Z,160,1,432669,A,B,64.810000000,1,26,8058566351754,128,19589,94329493,CLX5
2025-09-24T19:38:12.392819998Z,2025-09-24T19:38:12.385135451Z,160,1,432669,C,A,64.820000000,1,26,8058566349454,128,15147,94329565,CLX5
2025-09-24T19:38:12.393484720Z,2025-09-24T19:38:12.386047065Z,160,1,432669,A,B,64.800000000,1,26,8058566351793,128,13738,94329608,CLX5
2025-09-24T19:38:12.394266718Z,2025-09-24T19:38:12.387319489Z,160,1,432669,A,B,64.800000000,1,26,8058566351813,128,14949,94329659,CLX5
2025-09-24T19:38:12.398086050Z,2025-09-24T19:38:12.390828999Z,160,1,432669,A,B,64.810000000,1,26,8058566351892,128,14829,94329891,CLX5
2025-09-24T19:38:12.400022530Z,2025-09-24T19:38:12.391574617Z,160,1,432669,C,B,64.810000000,2,26,8058566351589,128,16247,94330008,CLX5
2025-09-24T19:38:12.400094503Z,2025-09-24T19:38:12.391593393Z,160,1,432669,A,A,64.820000000,1,26,8058566351921,128,15377,94330011,CLX5
2025-09-24T19:38:12.400180546Z,2025-09-24T19:38:12.391640277Z,160,1,432669,C,B,64.810000000,1,26,8058566351637,128,18499,94330014,CLX5
2025-09-24T19:38:12.401039877Z,2025-09-24T19:38:12.392557613Z,160,1,432669,M,A,64.830000000,1,26,8058566349378,128,15814,94330078,CLX5
2025-09-24T19:38:12.401294932Z,2025-09-24T19:38:12.392828859Z,160,1,432669,C,B,64.810000000,1,26,8058566351466,128,19591,94330095,CLX5
2025-09-24T19:38:12.401416822Z,2025-09-24T19:38:12.392946165Z,160,1,432669,C,A,64.820000000,1,26,8058566351921,128,18545,94330102,CLX5
2025-09-24T19:38:12.402804449Z,2025-09-24T19:38:12.394442701Z,160,1,432669,A,A,64.820000000,1,26,8058566351988,128,19212,94330210,CLX5
2025-09-24T19:38:12.403386125Z,2025-09-24T19:38:12.395323961Z,160,1,432669,C,A,64.820000000,1,26,8058566351988,128,16025,94330253,CLX5
2025-09-24T19:38:12.404266491Z,2025-09-24T19:38:12.396497393Z,160,1,432669,A,A,64.820000000,1,26,8058566352042,128,15506,94330322,CLX5
2025-09-24T19:38:12.404425765Z,2025-09-24T19:38:12.396826447Z,160,1,432669,C,B,64.810000000,1,26,8058566351892,128,20026,94330329,CLX5
2025-09-24T19:38:12.404512975Z,2025-09-24T19:38:12.396836105Z,160,1,432669,C,B,64.810000000,1,26,8058566351754,128,16504,94330331,CLX5
2025-09-24T19:38:12.404563852Z,2025-09-24T19:38:12.396838237Z,160,1,432669,C,B,64.810000000,1,26,8058566351721,128,19204,94330332,CLX5
2025-09-24T19:38:12.409043446Z,2025-09-24T19:38:12.405304065Z,160,1,432669,A,A,64.820000000,2,26,8058566352156,128,15223,94330623,CLX5
2025-09-24T19:38:12.409096650Z,2025-09-24T19:38:12.405388329Z,160,1,432669,A,A,64.820000000,1,26,8058566352157,128,14911,94330626,CLX5
2025-09-24T19:38:12.410050886Z,2025-09-24T19:38:12.407697007Z,160,1,432669,M,A,64.820000000,1,26,8058566349378,128,16329,94330689,CLX5
2025-09-24T19:38:12.411964481Z,2025-09-24T19:38:12.411420569Z,160,1,432669,A,A,64.870000000,2,26,8058566352248,128,17911,94330850,CLX5
2025-09-24T19:38:12.417180072Z,2025-09-24T19:38:12.417080461Z,160,1,432669,A,A,65.900000000,1,26,8058566352282,128,18297,94330917,CLX5
2025-09-24T19:38:12.423977232Z,2025-09-24T19:38:12.423876501Z,160,1,432669,C,B,64.540000000,8,26,8058566351450,128,18462,94330945,CLX5
2025-09-24T19:38:12.460469870Z,2025-09-24T19:38:12.460299117Z,160,1,432669,C,B,64.810000000,1,26,8058566351518,128,17729,94331358,CLX5
2025-09-24T19:38:12.460791414Z,2025-09-24T19:38:12.460509829Z,160,1,432669,A,A,64.850000000,2,26,8058566352446,128,17294,94331371,CLX5
2025-09-24T19:38:12.511538255Z,2025-09-24T19:38:12.511417247Z,160,1,432669,C,A,64.870000000,2,26,8058566352248,128,17743,94331585,CLX5
2025-09-24T19:38:12.511697422Z,2025-09-24T19:38:12.511566635Z,160,1,432669,C,B,64.800000000,1,26,8058566351813,128,18222,94331586,CLX5
2025-09-24T19:38:12.511727664Z,2025-09-24T19:38:12.511575945Z,160,1,432669,C,B,64.800000000,1,26,8058566351793,128,14658,94331587,CLX5
2025-09-24T19:38:12.517174418Z,2025-09-24T19:38:12.517081823Z,160,1,432669,C,A,65.900000000,1,26,8058566352282,128,16337,94331608,CLX5
2025-09-24T19:38:12.577757624Z,2025-09-24T19:38:12.577599433Z,160,1,432669,A,B,64.810000000,1,26,8058566352744,128,22051,94331861,CLX5
2025-09-24T19:38:13.635566860Z,2025-09-24T19:38:13.635439813Z,160,1,432669,M,A,64.950000000,1,26,8058566157942,128,20387,94332712,CLX5
2025-09-24T19:38:13.751879208Z,2025-09-24T19:38:13.751709329Z,160,1,432669,C,B,64.810000000,1,26,8058566352744,128,20458,94332730,CLX5
2025-09-24T19:38:14.666450806Z,2025-09-24T19:38:14.666214315Z,160,1,432669,A,B,64.810000000,1,26,8058566353168,128,21074,94332790,CLX5
2025-09-24T19:38:14.666570147Z,2025-09-24T19:38:14.666227101Z,160,1,432669,A,B,64.810000000,1,26,8058566353170,128,20308,94332795,CLX5
2025-09-24T19:38:14.666607439Z,2025-09-24T19:38:14.666227755Z,160,1,432669,A,B,64.810000000,1,26,8058566353171,128,15159,94332796,CLX5
2025-09-24T19:38:14.666645998Z,2025-09-24T19:38:14.666235243Z,160,1,432669,A,B,64.810000000,1,26,8058566353172,128,16390,94332797,CLX5
2025-09-24T19:38:14.667007760Z,2025-09-24T19:38:14.666488057Z,160,1,432669,C,B,64.810000000,1,26,8058566353168,128,16613,94332809,CLX5
2025-09-24T19:38:14.667097527Z,2025-09-24T19:38:14.666533405Z,160,1,432669,C,B,64.810000000,1,26,8058566353172,128,16431,94332811,CLX5
2025-09-24T19:38:14.667256779Z,2025-09-24T19:38:14.666549365Z,160,1,432669,C,A,64.850000000,2,26,8058566352446,128,17972,94332819,CLX5
2025-09-24T19:38:14.667375997Z,2025-09-24T19:38:14.666555137Z,160,1,432669,A,B,64.810000000,2,26,8058566353182,128,19752,94332824,CLX5
2025-09-24T19:38:14.667607199Z,2025-09-24T19:38:14.666701993Z,160,1,432669,A,B,64.810000000,1,26,8058566353185,128,16042,94332833,CLX5
2025-09-24T19:38:14.667836489Z,2025-09-24T19:38:14.666938297Z,160,1,432669,C,B,64.810000000,1,26,8058566353185,128,15930,94332845,CLX5
2025-09-24T19:38:14.668257615Z,2025-09-24T19:38:14.667572213Z,160,1,432669,C,B,64.780000000,1,26,8058566351014,128,14763,94332867,CLX5
2025-09-24T19:38:14.668288351Z,2025-09-24T19:38:14.667586017Z,160,1,432669,C,B,64.780000000,1,26,8058566350923,128,15553,94332868,CLX5
2025-09-24T19:38:14.668548588Z,2025-09-24T19:38:14.668260405Z,160,1,432669,C,B,64.810000000,1,26,8058566353170,128,19825,94332878,CLX5
2025-09-24T19:38:14.668806591Z,2025-09-24T19:38:14.668672979Z,160,1,432669,A,B,64.810000000,1,26,8058566353195,128,19657,94332882,CLX5
2025-09-24T19:38:14.669026197Z,2025-09-24T19:38:14.668900141Z,160,1,432669,C,B,64.810000000,1,26,8058566353195,128,20248,94332887,CLX5
2025-09-24T19:38:14.680787361Z,2025-09-24T19:38:14.680599069Z,160,1,432669,C,B,64.810000000,2,26,8058566353182,128,17650,94332893,CLX5
2025-09-24T19:38:14.711484414Z,2025-09-24T19:38:14.711341405Z,160,1,432669,A,A,64.850000000,2,26,8058566353200,128,18329,94332897,CLX5
2025-09-24T19:38:15.923420149Z,2025-09-24T19:38:15.923278791Z,160,1,432669,A,B,64.810000000,1,26,8058566353210,128,18602,94332923,CLX5
2025-09-24T19:38:16.006299674Z,2025-09-24T19:38:16.006131717Z,160,1,432669,A,B,64.810000000,1,26,8058566353212,128,18482,94332926,CLX5
2025-09-24T19:38:16.962947715Z,2025-09-24T19:38:16.962788523Z,160,1,432669,A,B,64.810000000,1,26,8058566353228,128,20256,94332960,CLX5
2025-09-24T19:38:16.963104595Z,2025-09-24T19:38:16.962972623Z,160,1,432669,C,B,64.810000000,1,26,8058566353228,128,19436,94332961,CLX5
2025-09-24T19:38:19.128975935Z,2025-09-24T19:38:19.128824743Z,160,1,432669,A,B,64.810000000,1,26,8058566353233,128,16528,94332981,CLX5
2025-09-24T19:38:19.420339399Z,2025-09-24T19:38:19.420167167Z,160,1,432669,M,A,64.930000000,4,26,8058566144143,128,19376,94332986,CLX5
2025-09-24T19:38:19.708034008Z,2025-09-24T19:38:19.707811703Z,160,1,432669,A,B,64.810000000,2,26,8058566353245,128,14893,94333005,CLX5
2025-09-24T19:38:19.708124159Z,2025-09-24T19:38:19.707855087Z,160,1,432669,A,B,64.810000000,1,26,8058566353247,128,15668,94333010,CLX5
2025-09-24T19:38:19.708363662Z,2025-09-24T19:38:19.708128947Z,160,1,432669,C,A,64.820000000,1,26,8058566349075,128,16342,94333020,CLX5
2025-09-24T19:38:19.747420350Z,2025-09-24T19:38:19.747278573Z,160,1,432669,C,B,64.810000000,2,26,8058566353245,128,15571,94333110,CLX5
2025-09-24T19:38:19.747558828Z,2025-09-24T19:38:19.747433011Z,160,1,432669,C,B,64.810000000,1,26,8058566353233,128,21355,94333111,CLX5
2025-09-24T19:38:21.679419275Z,2025-09-24T19:38:21.679247851Z,160,1,432669,A,B,64.800000000,1,26,8058566353307,128,20245,94333169,CLX5
2025-09-24T19:38:22.247462396Z,2025-09-24T19:38:22.247245801Z,160,1,432669,A,B,64.810000000,1,26,8058566353311,128,15844,94333174,CLX5
2025-09-24T19:38:24.154575509Z,2025-09-24T19:38:24.154426597Z,160,1,432669,A,B,64.810000000,2,26,8058566353346,128,21929,94333249,CLX5
2025-09-24T19:38:25.977531490Z,2025-09-24T19:38:25.977352699Z,160,1,432669,C,B,64.810000000,1,26,8058566353311,128,15825,94333299,CLX5
2025-09-24T19:38:25.977570502Z,2025-09-24T19:38:25.977374743Z,160,1,432669,C,B,64.810000000,2,26,8058566353346,128,15757,94333300,CLX5
2025-09-24T19:38:25.977756847Z,2025-09-24T19:38:25.977577521Z,160,1,432669,A,B,64.810000000,1,26,8058566353362,128,13604,94333304,CLX5
2025-09-24T19:38:27.230754559Z,2025-09-24T19:38:27.230545445Z,160,1,432669,C,B,64.810000000,1,26,8058566353362,128,19073,94333363,CLX5
2025-09-24T19:38:27.230873062Z,2025-09-24T19:38:27.230629113Z,160,1,432669,C,B,64.810000000,1,26,8058566353171,128,18953,94333366,CLX5
2025-09-24T19:38:27.231492929Z,2025-09-24T19:38:27.231183565Z,160,1,432669,C,B,64.810000000,1,26,8058566353247,128,19218,94333399,CLX5
2025-09-24T19:38:30.717241479Z,2025-09-24T19:38:30.717125543Z,160,1,432669,C,A,65.700000000,6,26,8058566342860,128,19335,94333469,CLX5
2025-09-24T19:38:32.119664454Z,2025-09-24T19:38:32.119449679Z,160,1,432669,A,B,64.810000000,1,26,8058566353428,128,16429,94333496,CLX5
2025-09-24T19:38:32.119726105Z,2025-09-24T19:38:32.119525843Z,160,1,432669,C,B,64.810000000,1,26,8058566353210,128,16595,94333498,CLX5
2025-09-24T19:38:32.502773005Z,2025-09-24T19:38:32.502616587Z,160,1,432669,C,B,64.810000000,1,26,8058566353428,128,22318,94333520,CLX5
2025-09-24T19:38:33.195779094Z,2025-09-24T19:38:33.195397441Z,160,1,432669,T,A,64.810000000,1,26,8058566353440,0,18823,94333555,CLX5
2025-09-24T19:38:33.195779094Z,2025-09-24T19:38:33.195397441Z,160,1,432669,F,B,64.810000000,1,26,8058566351394,0,18823,94333555,CLX5
2025-09-24T19:38:33.195792349Z,2025-09-24T19:38:33.195397441Z,160,1,432669,M,B,64.810000000,1,26,8058566351394,128,17904,94333556,CLX5
2025-09-24T19:38:33.198756781Z,2025-09-24T19:38:33.198598881Z,160,1,432669,A,A,64.820000000,1,26,8058566353445,128,18763,94333566,CLX5
2025-09-24T19:38:33.199129679Z,2025-09-24T19:38:33.198821955Z,160,1,432669,T,A,64.810000000,1,26,8058566353452,0,14925,94333577,CLX5
2025-09-24T19:38:33.199129679Z,2025-09-24T19:38:33.198821955Z,160,1,432669,F,B,64.810000000,1,26,8058566351394,0,14925,94333577,CLX5
2025-09-24T19:38:33.199129679Z,2025-09-24T19:38:33.198821955Z,160,1,432669,C,B,64.810000000,1,26,8058566351394,128,14925,94333577,CLX5
2025-09-24T19:38:33.199390555Z,2025-09-24T19:38:33.199126281Z,160,1,432669,T,A,64.810000000,1,26,8058566353455,0,18198,94333585,CLX5
2025-09-24T19:38:33.199390555Z,2025-09-24T19:38:33.199126281Z,160,1,432669,F,B,64.810000000,1,26,8058566351452,0,18198,94333585,CLX5
2025-09-24T19:38:33.199399801Z,2025-09-24T19:38:33.199126281Z,160,1,432669,C,B,64.810000000,1,26,8058566351452,128,14508,94333586,CLX5
2025-09-24T19:38:33.199477949Z,2025-09-24T19:38:33.199129833Z,160,1,432669,T,A,64.810000000,2,26,8058566353456,0,15260,94333588,CLX5
2025-09-24T19:38:33.199477949Z,2025-09-24T19:38:33.199129833Z,160,1,432669,F,B,64.810000000,1,26,8058566351515,0,15260,94333588,CLX5
2025-09-24T19:38:33.199477949Z,2025-09-24T19:38:33.199129833Z,160,1,432669,F,B,64.810000000,1,26,8058566353212,0,15260,94333588,CLX5
2025-09-24T19:38:33.199492041Z,2025-09-24T19:38:33.199129833Z,160,1,432669,C,B,64.810000000,1,26,8058566351515,0,19049,94333589,CLX5
2025-09-24T19:38:33.199492041Z,2025-09-24T19:38:33.199129833Z,160,1,432669,C,B,64.810000000,1,26,8058566353212,128,19049,94333589,CLX5
2025-09-24T19:38:33.199699421Z,2025-09-24T19:38:33.199390979Z,160,1,432669,A,A,64.820000000,1,26,8058566353460,128,18406,94333598,CLX5
2025-09-24T19:38:33.200167369Z,2025-09-24T19:38:33.199565135Z,160,1,432669,A,A,64.810000000,1,26,8058566353464,128,13897,94333618,CLX5
2025-09-24T19:38:33.200684406Z,2025-09-24T19:38:33.199625883Z,160,1,432669,C,A,64.820000000,1,26,8058566353445,128,18097,94333646,CLX5
2025-09-24T19:38:33.200884367Z,2025-09-24T19:38:33.199740481Z,160,1,432669,A,A,64.820000000,1,26,8058566353471,128,14927,94333655,CLX5
2025-09-24T19:38:33.201107935Z,2025-09-24T19:38:33.199796367Z,160,1,432669,M,B,63.620000000,3,26,8058566332677,128,15220,94333662,CLX5
2025-09-24T19:38:33.201142970Z,2025-09-24T19:38:33.199969201Z,160,1,432669,A,A,64.820000000,1,26,8058566353472,128,18154,94333663,CLX5
2025-09-24T19:38:33.201850783Z,2025-09-24T19:38:33.200424489Z,160,1,432669,M,A,64.830000000,3,26,8058566321460,128,14456,94333697,CLX5
2025-09-24T19:38:33.201928439Z,2025-09-24T19:38:33.200552221Z,160,1,432669,C,A,64.820000000,1,26,8058566350260,128,15256,94333700,CLX5
2025-09-24T19:38:33.201954319Z,2025-09-24T19:38:33.200554121Z,160,1,432669,C,A,64.820000000,1,26,8058566350259,128,13725,94333701,CLX5
2025-09-24T19:38:33.202007746Z,2025-09-24T19:38:33.200609569Z,160,1,432669,C,A,64.840000000,4,26,8058566331622,128,18145,94333704,CLX5
2025-09-24T19:38:33.202070443Z,2025-09-24T19:38:33.200714185Z,160,1,432669,A,A,64.820000000,1,26,8058566353485,128,15115,94333706,CLX5
2025-09-24T19:38:33.202321565Z,2025-09-24T19:38:33.201994539Z,160,1,432669,M,A,64.930000000,1,26,8058565075241,128,14590,94333717,CLX5
2025-09-24T19:38:33.202618627Z,2025-09-24T19:38:33.202493735Z,160,1,432669,M,A,65.980000000,3,26,8058566321460,128,18284,94333720,CLX5
2025-09-24T19:38:33.202652210Z,2025-09-24T19:38:33.202516083Z,160,1,432669,M,B,64.800000000,3,26,8058566221991,128,15340,94333721,CLX5
2025-09-24T19:38:33.202982902Z,2025-09-24T19:38:33.202652953Z,160,1,432669,T,B,64.810000000,1,26,8058566353492,0,16533,94333723,CLX5
2025-09-24T19:38:33.202982902Z,2025-09-24T19:38:33.202652953Z,160,1,432669,F,A,64.810000000,1,26,8058566353464,0,16533,94333723,CLX5
2025-09-24T19:38:33.202991902Z,2025-09-24T19:38:33.202652953Z,160,1,432669,C,A,64.810000000,1,26,8058566353464,128,14465,94333724,CLX5
2025-09-24T19:38:33.203018259Z,2025-09-24T19:38:33.202690929Z,160,1,432669,M,A,64.940000000,1,26,8058565075241,128,16339,94333727,CLX5
2025-09-24T19:38:33.203274319Z,2025-09-24T19:38:33.202983607Z,160,1,432669,A,B,64.810000000,1,26,8058566353496,128,18381,94333733,CLX5
2025-09-24T19:38:33.203297212Z,2025-09-24T19:38:33.202983785Z,160,1,432669,A,B,64.810000000,1,26,8058566353497,128,15230,94333735,CLX5
2025-09-24T19:38:33.203392808Z,2025-09-24T19:38:33.203015031Z,160,1,432669,A,B,64.810000000,1,26,8058566353499,128,17061,94333739,CLX5
2025-09-24T19:38:33.203539142Z,2025-09-24T19:38:33.203208405Z,160,1,432669,M,A,64.840000000,4,26,8058566331102,128,14479,94333750,CLX5
2025-09-24T19:38:33.203618580Z,2025-09-24T19:38:33.203302269Z,160,1,432669,C,A,64.820000000,1,26,8058566353485,128,18977,94333752,CLX5
2025-09-24T19:38:33.203692803Z,2025-09-24T19:38:33.203309661Z,160,1,432669,C,A,64.820000000,1,26,8058566353460,128,15013,94333754,CLX5
2025-09-24T19:38:33.203741884Z,2025-09-24T19:38:33.203312329Z,160,1,432669,C,A,64.820000000,1,26,8058566353472,128,18495,94333756,CLX5
2025-09-24T19:38:33.203768916Z,2025-09-24T19:38:33.203337885Z,160,1,432669,C,A,64.820000000,1,26,8058566353471,128,15098,94333757,CLX5
2025-09-24T19:38:33.203917017Z,2025-09-24T19:38:33.203530989Z,160,1,432669,A,B,64.810000000,1,26,8058566353501,128,18281,94333761,CLX5
2025-09-24T19:38:33.204027388Z,2025-09-24T19:38:33.203647221Z,160,1,432669,C,B,64.810000000,1,26,8058566353499,128,14503,94333766,CLX5
2025-09-24T19:38:33.210197107Z,2025-09-24T19:38:33.210040423Z,160,1,432669,A,B,64.810000000,1,26,8058566353518,128,20254,94333832,CLX5
2025-09-24T19:38:33.210251110Z,2025-09-24T19:38:33.210062965Z,160,1,432669,A,B,64.810000000,1,26,8058566353520,128,15056,94333835,CLX5
2025-09-24T19:38:33.210404172Z,2025-09-24T19:38:33.210196473Z,160,1,432669,A,B,64.810000000,1,26,8058566353523,128,18690,94333841,CLX5
2025-09-24T19:38:33.217198773Z,2025-09-24T19:38:33.217091831Z,160,1,432669,A,A,65.700000000,6,26,8058566353536,128,19005,94333882,CLX5
2025-09-24T19:38:33.236036501Z,2025-09-24T19:38:33.235745959Z,160,1,432669,T,A,64.810000000,1,26,8058566353538,0,17924,94333886,CLX5
2025-09-24T19:38:33.236036501Z,2025-09-24T19:38:33.235745959Z,160,1,432669,F,B,64.810000000,1,26,8058566353496,0,17924,94333886,CLX5
2025-09-24T19:38:33.236048635Z,2025-09-24T19:38:33.235745959Z,160,1,432669,C,B,64.810000000,1,26,8058566353496,128,17078,94333887,CLX5
2025-09-24T19:38:33.236154237Z,2025-09-24T19:38:33.236011733Z,160,1,432669,C,B,64.810000000,1,26,8058566353518,128,20831,94333888,CLX5
2025-09-24T19:38:33.236212617Z,2025-09-24T19:38:33.236021159Z,160,1,432669,C,B,64.810000000,1,26,8058566353520,128,14419,94333890,CLX5
2025-09-24T19:38:33.236256606Z,2025-09-24T19:38:33.236036711Z,160,1,432669,A,A,64.820000000,1,26,8058566353540,128,18111,94333892,CLX5
2025-09-24T19:38:33.236352286Z,2025-09-24T19:38:33.236037067Z,160,1,432669,C,B,64.810000000,1,26,8058566353523,128,18302,94333896,CLX5
2025-09-24T19:38:33.236455792Z,2025-09-24T19:38:33.236214955Z,160,1,432669,A,B,64.810000000,1,26,8058566353543,128,18348,94333900,CLX5
2025-09-24T19:38:33.236605436Z,2025-09-24T19:38:33.236468845Z,160,1,432669,C,A,64.820000000,1,26,8058566353540,128,19825,94333908,CLX5
2025-09-24T19:38:33.236952693Z,2025-09-24T19:38:33.236803965Z,160,1,432669,A,B,64.810000000,1,26,8058566353548,128,21147,94333919,CLX5
2025-09-24T19:38:33.237089205Z,2025-09-24T19:38:33.236952147Z,160,1,432669,A,B,64.810000000,1,26,8058566353549,128,21775,94333921,CLX5
2025-09-24T19:38:33.239610516Z,2025-09-24T19:38:33.239463491Z,160,1,432669,A,B,64.810000000,1,26,8058566353552,128,19350,94333930,CLX5
2025-09-24T19:38:33.240033754Z,2025-09-24T19:38:33.239908623Z,160,1,432669,A,B,64.780000000,1,26,8058566353553,128,17735,94333932,CLX5
2025-09-24T19:38:33.351414306Z,2025-09-24T19:38:33.351254207Z,160,1,432669,A,B,64.810000000,2,26,8058566353579,128,19797,94333999,CLX5
2025-09-24T19:38:33.360340447Z,2025-09-24T19:38:33.360190915Z,160,1,432669,A,B,64.810000000,1,26,8058566353587,128,20388,94334025,CLX5
2025-09-24T19:38:34.195707475Z,2025-09-24T19:38:34.195416985Z,160,1,432669,T,A,64.810000000,1,26,8058566353600,0,18277,94334058,CLX5
2025-09-24T19:38:34.195707475Z,2025-09-24T19:38:34.195416985Z,160,1,432669,F,B,64.810000000,1,26,8058566353497,0,18277,94334058,CLX5
2025-09-24T19:38:34.195718480Z,2025-09-24T19:38:34.195416985Z,160,1,432669,C,B,64.810000000,1,26,8058566353497,128,16067,94334059,CLX5
2025-09-24T19:38:34.195842382Z,2025-09-24T19:38:34.195692473Z,160,1,432669,C,B,64.810000000,1,26,8058566353552,128,16043,94334061,CLX5
2025-09-24T19:38:34.196673759Z,2025-09-24T19:38:34.196473361Z,160,1,432669,C,B,64.810000000,2,26,8058566353579,128,16540,94334076,CLX5
2025-09-24T19:38:34.196783102Z,2025-09-24T19:38:34.196647631Z,160,1,432669,A,B,64.810000000,1,26,8058566353602,128,16567,94334079,CLX5
