ts_recv,ts_event,rtype,publisher_id,instrument_id,action,side,price,size,channel_id,order_id,flags,ts_in_delta,sequence,symbol
2025-09-24T19:41:47.036097679Z,2025-09-24T19:41:47.029795965Z,160,1,432669,C,B,64.810000000,1,26,8058566356317,0,18751,94371491,CLX5
2025-09-24T19:41:47.036097679Z,2025-09-24T19:41:47.029795965Z,160,1,432669,C,B,64.810000000,1,26,8058566356356,128,18751,94371491,CLX5
2025-09-24T19:41:47.036107754Z,2025-09-24T19:41:47.029797169Z,160,1,432669,T,A,64.810000000,1,26,8058566367184,0,14580,94371492,CLX5
2025-09-24T19:41:47.036107754Z,2025-09-24T19:41:47.029797169Z,160,1,432669,F,B,64.810000000,1,26,8058566356357,0,14580,94371492,CLX5
2025-09-24T19:41:47.036129710Z,2025-09-24T19:41:47.029797169Z,160,1,432669,C,B,64.810000000,1,26,8058566356357,128,14953,94371493,CLX5
2025-09-24T19:41:47.036158719Z,2025-09-24T19:41:47.029797345Z,160,1,432669,C,A,64.830000000,1,26,8058566365806,128,15181,94371494,CLX5
2025-09-24T19:41:47.036232548Z,2025-09-24T19:41:47.029881839Z,160,1,432669,T,A,64.810000000,1,26,8058566367187,0,14860,94371499,CLX5
2025-09-24T19:41:47.036232548Z,2025-09-24T19:41:47.029881839Z,160,1,432669,F,B,64.810000000,1,26,8058566356397,0,14860,94371499,CLX5
2025-09-24T19:41:47.036257929Z,2025-09-24T19:41:47.029881839Z,160,1,432669,C,B,64.810000000,1,26,8058566356397,128,14854,94371500,CLX5
2025-09-24T19:41:47.036288862Z,2025-09-24T19:41:47.029892551Z,160,1,432669,C,B,64.790000000,1,26,8058566357917,128,18251,94371501,CLX5
2025-09-24T19:41:47.036839973Z,2025-09-24T19:41:47.030032169Z,160,1,432669,T,A,64.810000000,1,26,8058566367195,0,14708,94371522,CLX5
2025-09-24T19:41:47.036839973Z,2025-09-24T19:41:47.030032169Z,160,1,432669,F,B,64.810000000,1,26,8058566356476,0,14708,94371522,CLX5
2025-09-24T19:41:47.036868602Z,2025-09-24T19:41:47.030032169Z,160,1,432669,C,B,64.810000000,1,26,8058566356476,128,14969,94371523,CLX5
2025-09-24T19:41:47.036883148Z,2025-09-24T19:41:47.030046393Z,160,1,432669,T,A,64.810000000,1,26,8058566367196,0,13621,94371524,CLX5
2025-09-24T19:41:47.036883148Z,2025-09-24T19:41:47.030046393Z,160,1,432669,F,B,64.810000000,1,26,8058566221991,0,13621,94371524,CLX5
2025-09-24T19:41:47.036883148Z,2025-09-24T19:41:47.030046393Z,160,1,432669,C,B,64.810000000,1,26,8058566221991,128,13621,94371524,CLX5
2025-09-24T19:41:47.037105856Z,2025-09-24T19:41:47.030121097Z,160,1,432669,C,B,64.810000000,1,26,8058566357915,128,14907,94371537,CLX5
2025-09-24T19:41:47.038454639Z,2025-09-24T19:41:47.030721129Z,160,1,432669,M,A,64.940000000,1,26,8058565075241,128,17858,94371605,CLX5
2025-09-24T19:41:47.038720607Z,2025-09-24T19:41:47.030881653Z,160,1,432669,C,B,64.810000000,1,26,8058566367076,128,15543,94371618,CLX5
2025-09-24T19:41:47.038818990Z,2025-09-24T19:41:47.030975595Z,160,1,432669,C,B,64.800000000,2,26,8058566358149,128,14400,94371622,CLX5
2025-09-24T19:41:47.040314039Z,2025-09-24T19:41:47.032384677Z,160,1,432669,M,A,64.820000000,1,26,8058566239191,128,14211,94371699,CLX5
2025-09-24T19:41:47.040548673Z,2025-09-24T19:41:47.032739113Z,160,1,432669,M,A,64.830000000,3,26,8058566321460,128,14961,94371713,CLX5
2025-09-24T19:41:47.040634147Z,2025-09-24T19:41:47.032787263Z,160,1,432669,C,A,64.820000000,2,26,8058566367135,128,13826,94371716,CLX5
2025-09-24T19:41:47.040661748Z,2025-09-24T19:41:47.032803449Z,160,1,432669,A,A,64.850000000,2,26,8058566367269,128,14826,94371717,CLX5
2025-09-24T19:41:47.041151537Z,2025-09-24T19:41:47.033150263Z,160,1,432669,M,A,64.840000000,1,26,8058566173085,128,20478,94371742,CLX5
2025-09-24T19:41:47.041179859Z,2025-09-24T19:41:47.033189161Z,160,1,432669,M,B,63.660000000,4,26,8058566319508,128,14520,94371745,CLX5
2025-09-24T19:41:47.041946682Z,2025-09-24T19:41:47.033952347Z,160,1,432669,C,A,64.820000000,2,26,8058566367146,128,15093,94371783,CLX5
2025-09-24T19:41:47.041973623Z,2025-09-24T19:41:47.033953941Z,160,1,432669,A,A,64.830000000,1,26,8058566367287,128,13607,94371784,CLX5
2025-09-24T19:41:47.042622894Z,2025-09-24T19:41:47.034345679Z,160,1,432669,M,B,63.650000000,4,26,8058566319851,128,14506,94371831,CLX5
2025-09-24T19:41:47.044403216Z,2025-09-24T19:41:47.036354429Z,160,1,432669,C,B,64.810000000,3,26,8058566358168,128,16020,94371921,CLX5
2025-09-24T19:41:47.045890356Z,2025-09-24T19:41:47.037737497Z,160,1,432669,M,A,64.830000000,1,26,8058566349378,128,18457,94372032,CLX5
2025-09-24T19:41:47.046656158Z,2025-09-24T19:41:47.038547703Z,160,1,432669,A,B,64.810000000,1,26,8058566367335,128,15256,94372085,CLX5
2025-09-24T19:41:47.046704048Z,2025-09-24T19:41:47.038668503Z,160,1,432669,C,B,64.810000000,1,26,8058566367335,128,14937,94372087,CLX5
2025-09-24T19:41:47.048754976Z,2025-09-24T19:41:47.041182881Z,160,1,432669,C,A,64.830000000,1,26,8058566367287,128,15155,94372199,CLX5
2025-09-24T19:41:47.050424958Z,2025-09-24T19:41:47.044418131Z,160,1,432669,A,A,64.820000000,1,26,8058566367390,128,17957,94372302,CLX5
2025-09-24T19:41:47.050989785Z,2025-09-24T19:41:47.045595519Z,160,1,432669,A,B,64.810000000,1,26,8058566367398,128,14969,94372340,CLX5
2025-09-24T19:41:47.051829464Z,2025-09-24T19:41:47.047424717Z,160,1,432669,M,A,64.820000000,1,26,8058566361816,128,17793,94372400,CLX5
2025-09-24T19:41:47.080179428Z,2025-09-24T19:41:47.080029199Z,160,1,432669,A,A,64.820000000,1,26,8058566367586,128,18758,94372913,CLX5
2025-09-24T19:41:47.080361296Z,2025-09-24T19:41:47.080228179Z,160,1,432669,A,A,64.820000000,1,26,8058566367587,128,18100,94372914,CLX5
2025-09-24T19:41:47.105324190Z,2025-09-24T19:41:47.105004953Z,160,1,432669,C,B,64.810000000,1,26,8058566367096,128,15525,94372989,CLX5
2025-09-24T19:41:47.105364361Z,2025-09-24T19:41:47.105006067Z,160,1,432669,C,B,64.810000000,1,26,8058566367158,128,19179,94372990,CLX5
2025-09-24T19:41:47.112540892Z,2025-09-24T19:41:47.112416979Z,160,1,432669,C,A,64.870000000,2,26,8058566364454,128,18341,94373013,CLX5
2025-09-24T19:41:47.112574068Z,2025-09-24T19:41:47.112417633Z,160,1,432669,A,B,64.780000000,2,26,8058566367628,128,14300,94373014,CLX5
2025-09-24T19:41:47.115312742Z,2025-09-24T19:41:47.115035745Z,160,1,432669,T,A,64.810000000,1,26,8058566367629,0,18033,94373016,CLX5
2025-09-24T19:41:47.115312742Z,2025-09-24T19:41:47.115035745Z,160,1,432669,F,B,64.810000000,1,26,8058566356716,0,18033,94373016,CLX5
2025-09-24T19:41:47.115326281Z,2025-09-24T19:41:47.115035745Z,160,1,432669,M,B,64.810000000,1,26,8058566356716,128,15891,94373017,CLX5
2025-09-24T19:41:47.118195871Z,2025-09-24T19:41:47.118094631Z,160,1,432669,C,A,65.900000000,1,26,8058566358031,128,17332,94373022,CLX5
2025-09-24T19:41:47.118240243Z,2025-09-24T19:41:47.118143645Z,160,1,432669,A,B,64.160000000,2,26,8058566367633,128,15972,94373024,CLX5
2025-09-24T19:41:47.118246871Z,2025-09-24T19:41:47.118150211Z,160,1,432669,C,A,65.700000000,6,26,8058566358032,128,14124,94373025,CLX5
2025-09-24T19:41:47.240933042Z,2025-09-24T19:41:47.240787429Z,160,1,432669,A,B,64.780000000,1,26,8058566367754,128,14567,94373211,CLX5
2025-09-24T19:41:47.524299358Z,2025-09-24T19:41:47.524164677Z,160,1,432669,C,B,64.780000000,1,26,8058566367754,128,17922,94373407,CLX5
2025-09-24T19:41:47.524917066Z,2025-09-24T19:41:47.524750731Z,160,1,432669,A,B,64.810000000,1,26,8058566367869,128,15910,94373415,CLX5
2025-09-24T19:41:47.618187302Z,2025-09-24T19:41:47.618080039Z,160,1,432669,A,A,65.700000000,6,26,8058566367917,128,18188,94373500,CLX5
2025-09-24T19:41:47.731398395Z,2025-09-24T19:41:47.731268567Z,160,1,432669,C,A,64.820000000,2,26,8058566367149,128,18556,94373555,CLX5
2025-09-24T19:41:47.839268955Z,2025-09-24T19:41:47.839114681Z,160,1,432669,M,A,64.820000000,1,26,8058566366236,128,19812,94373614,CLX5
2025-09-24T19:41:48.292623911Z,2025-09-24T19:41:48.292462853Z,160,1,432669,C,A,64.820000000,1,26,8058566361816,128,19576,94373821,CLX5
2025-09-24T19:41:48.340887388Z,2025-09-24T19:41:48.340743595Z,160,1,432669,A,B,64.780000000,1,26,8058566368080,128,18219,94373830,CLX5
2025-09-24T19:41:49.753353368Z,2025-09-24T19:41:49.753175173Z,160,1,432669,C,B,64.810000000,1,26,8058566367869,128,16897,94374060,CLX5
2025-09-24T19:41:49.755404757Z,2025-09-24T19:41:49.755014529Z,160,1,432669,A,B,64.810000000,1,26,8058566368194,128,15126,94374141,CLX5
2025-09-24T19:41:49.818453657Z,2025-09-24T19:41:49.818354973Z,160,1,432669,C,A,65.700000000,6,26,8058566367917,128,18121,94374305,CLX5
2025-09-24T19:41:49.819516721Z,2025-09-24T19:41:49.819360413Z,160,1,432669,C,B,64.780000000,1,26,8058566368080,128,14703,94374307,CLX5
2025-09-24T19:41:50.294590867Z,2025-09-24T19:41:50.293727245Z,160,1,432669,A,A,64.820000000,1,26,8058566368315,128,18540,94374494,CLX5
2025-09-24T19:41:50.294659684Z,2025-09-24T19:41:50.293737495Z,160,1,432669,C,B,64.810000000,1,26,8058566356779,128,15733,94374498,CLX5
2025-09-24T19:41:50.294753114Z,2025-09-24T19:41:50.293737861Z,160,1,432669,C,B,64.810000000,1,26,8058566367398,128,15901,94374500,CLX5
2025-09-24T19:41:50.295098550Z,2025-09-24T19:41:50.293796073Z,160,1,432669,A,A,64.820000000,2,26,8058566368321,128,14916,94374512,CLX5
2025-09-24T19:41:50.295121189Z,2025-09-24T19:41:50.293796975Z,160,1,432669,T,A,64.810000000,1,26,8058566368322,0,14787,94374514,CLX5
2025-09-24T19:41:50.295121189Z,2025-09-24T19:41:50.293796975Z,160,1,432669,F,B,64.810000000,1,26,8058566356716,0,14787,94374514,CLX5
2025-09-24T19:41:50.295156577Z,2025-09-24T19:41:50.293796975Z,160,1,432669,C,B,64.810000000,1,26,8058566356716,128,16566,94374515,CLX5
2025-09-24T19:41:50.295173733Z,2025-09-24T19:41:50.293806363Z,160,1,432669,T,A,64.810000000,2,26,8058566368323,0,16960,94374516,CLX5
2025-09-24T19:41:50.295173733Z,2025-09-24T19:41:50.293806363Z,160,1,432669,F,B,64.810000000,1,26,8058566357958,0,16960,94374516,CLX5
2025-09-24T19:41:50.295173733Z,2025-09-24T19:41:50.293806363Z,160,1,432669,F,B,64.810000000,1,26,8058566358079,0,16960,94374516,CLX5
2025-09-24T19:41:50.295173733Z,2025-09-24T19:41:50.293806363Z,160,1,432669,C,B,64.810000000,1,26,8058566357958,0,16960,94374516,CLX5
2025-09-24T19:41:50.295173733Z,2025-09-24T19:41:50.293806363Z,160,1,432669,M,B,64.810000000,1,26,8058566358079,128,16960,94374516,CLX5
2025-09-24T19:41:50.295329145Z,2025-09-24T19:41:50.293812181Z,160,1,432669,T,A,64.810000000,1,26,8058566368325,0,15024,94374521,CLX5
2025-09-24T19:41:50.295329145Z,2025-09-24T19:41:50.293812181Z,160,1,432669,F,B,64.810000000,1,26,8058566358079,0,15024,94374521,CLX5
2025-09-24T19:41:50.295329145Z,2025-09-24T19:41:50.293812181Z,160,1,432669,C,B,64.810000000,1,26,8058566358079,128,15024,94374521,CLX5
2025-09-24T19:41:50.295370799Z,2025-09-24T19:41:50.293820013Z,160,1,432669,T,A,64.810000000,2,26,8058566368326,0,14441,94374524,CLX5
2025-09-24T19:41:50.295370799Z,2025-09-24T19:41:50.293820013Z,160,1,432669,F,B,64.810000000,1,26,8058566197138,0,14441,94374524,CLX5
2025-09-24T19:41:50.295370799Z,2025-09-24T19:41:50.293820013Z,160,1,432669,F,B,64.810000000,1,26,8058566365981,0,14441,94374524,CLX5
2025-09-24T19:41:50.295419987Z,2025-09-24T19:41:50.293820013Z,160,1,432669,C,B,64.810000000,1,26,8058566197138,0,19596,94374525,CLX5
2025-09-24T19:41:50.295419987Z,2025-09-24T19:41:50.293820013Z,160,1,432669,C,B,64.810000000,1,26,8058566365981,128,19596,94374525,CLX5
2025-09-24T19:41:50.295709877Z,2025-09-24T19:41:50.293949435Z,160,1,432669,C,B,64.810000000,1,26,8058566368194,128,18236,94374541,CLX5
2025-09-24T19:41:50.296830952Z,2025-09-24T19:41:50.294497815Z,160,1,432669,A,A,64.820000000,2,26,8058566368345,128,13726,94374613,CLX5
2025-09-24T19:41:50.297125433Z,2025-09-24T19:41:50.294499835Z,160,1,432669,T,A,64.810000000,1,26,8058566368350,0,16076,94374625,CLX5
2025-09-24T19:41:50.297125433Z,2025-09-24T19:41:50.294499835Z,160,1,432669,F,B,64.810000000,1,26,8058566367028,0,16076,94374625,CLX5
2025-09-24T19:41:50.297125433Z,2025-09-24T19:41:50.294499835Z,160,1,432669,C,B,64.810000000,1,26,8058566367028,128,16076,94374625,CLX5
2025-09-24T19:41:50.297331945Z,2025-09-24T19:41:50.294571265Z,160,1,432669,A,A,64.810000000,2,26,8058566368355,128,14642,94374636,CLX5
2025-09-24T19:41:50.297437041Z,2025-09-24T19:41:50.294571795Z,160,1,432669,A,A,64.810000000,2,26,8058566368358,128,14736,94374642,CLX5
2025-09-24T19:41:50.297457906Z,2025-09-24T19:41:50.294571975Z,160,1,432669,A,A,64.810000000,1,26,8058566368359,128,14289,94374644,CLX5
2025-09-24T19:41:50.298165965Z,2025-09-24T19:41:50.294950019Z,160,1,432669,A,B,64.800000000,1,26,8058566368370,128,18206,94374675,CLX5
2025-09-24T19:41:50.299376284Z,2025-09-24T19:41:50.295789771Z,160,1,432669,M,A,64.930000000,1,26,8058565075241,128,14911,94374737,CLX5
2025-09-24T19:41:50.299570079Z,2025-09-24T19:41:50.296078833Z,160,1,432669,C,B,64.780000000,1,26,8058566340353,128,17283,94374747,CLX5
2025-09-24T19:41:50.300259384Z,2025-09-24T19:41:50.296815715Z,160,1,432669,M,A,64.830000000,1,26,8058566173085,128,14914,94374790,CLX5
2025-09-24T19:41:50.300309448Z,2025-09-24T19:41:50.296838447Z,160,1,432669,A,A,64.810000000,1,26,8058566368399,128,22219,94374791,CLX5
2025-09-24T19:41:50.300339452Z,2025-09-24T19:41:50.296888385Z,160,1,432669,T,N,64.810000000,1,26,0,0,16669,94374794,CLX5
2025-09-24T19:41:50.300339452Z,2025-09-24T19:41:50.296888385Z,160,1,432669,F,N,64.810000000,1,26,8058566368355,0,16669,94374794,CLX5
2025-09-24T19:41:50.300375630Z,2025-09-24T19:41:50.296888385Z,160,1,432669,M,A,64.810000000,1,26,8058566368355,128,14755,94374795,CLX5
2025-09-24T19:41:50.300514800Z,2025-09-24T19:41:50.297031819Z,160,1,432669,A,A,64.810000000,1,26,8058566368402,128,18602,94374802,CLX5
2025-09-24T19:41:50.300791073Z,2025-09-24T19:41:50.297130735Z,160,1,432669,M,A,64.810000000,2,26,8058566362865,128,20792,94374812,CLX5
2025-09-24T19:41:50.300820770Z,2025-09-24T19:41:50.297145941Z,160,1,432669,A,A,64.810000000,1,26,8058566368407,128,16605,94374813,CLX5
2025-09-24T19:41:50.300856327Z,2025-09-24T19:41:50.297157825Z,160,1,432669,C,B,64.790000000,2,26,8058566365698,128,15013,94374814,CLX5
2025-09-24T19:41:50.300894287Z,2025-09-24T19:41:50.297159015Z,160,1,432669,A,A,64.810000000,2,26,8058566368409,128,19149,94374815,CLX5
2025-09-24T19:41:50.301490470Z,2025-09-24T19:41:50.297215691Z,160,1,432669,A,A,64.810000000,2,26,8058566368420,128,16311,94374843,CLX5
2025-09-24T19:41:50.302273896Z,2025-09-24T19:41:50.297340103Z,160,1,432669,A,A,64.810000000,1,26,8058566368431,128,14677,94374885,CLX5
2025-09-24T19:41:50.302341745Z,2025-09-24T19:41:50.297342387Z,160,1,432669,A,A,64.810000000,1,26,8058566368432,128,19496,94374887,CLX5
2025-09-24T19:41:50.302385128Z,2025-09-24T19:41:50.297362489Z,160,1,432669,C,B,64.800000000,3,26,8058566332677,128,14883,94374889,CLX5
2025-09-24T19:41:50.302459113Z,2025-09-24T19:41:50.297379883Z,160,1,432669,C,B,64.800000000,1,26,8058566329044,128,18325,94374893,CLX5
2025-09-24T19:41:50.302487988Z,2025-09-24T19:41:50.297401213Z,160,1,432669,A,A,64.810000000,1,26,8058566368434,128,15661,94374894,CLX5
2025-09-24T19:41:50.302839568Z,2025-09-24T19:41:50.297487283Z,160,1,432669,M,A,64.810000000,1,26,8058566366055,128,15820,94374910,CLX5
2025-09-24T19:41:50.302877021Z,2025-09-24T19:41:50.297487783Z,160,1,432669,C,B,64.800000000,1,26,8058566340896,128,17252,94374911,CLX5
2025-09-24T19:41:50.302905858Z,2025-09-24T19:41:50.297487955Z,160,1,432669,C,B,64.800000000,1,26,8058566340897,128,15462,94374912,CLX5
2025-09-24T19:41:50.303040827Z,2025-09-24T19:41:50.297538583Z,160,1,432669,T,B,64.810000000,1,26,8058566368443,0,14409,94374919,CLX5
2025-09-24T19:41:50.303040827Z,2025-09-24T19:41:50.297538583Z,160,1,432669,F,A,64.810000000,1,26,8058566368355,0,14409,94374919,CLX5
2025-09-24T19:41:50.303072728Z,2025-09-24T19:41:50.297538583Z,160,1,432669,C,A,64.810000000,1,26,8058566368355,128,19807,94374920,CLX5
2025-09-24T19:41:50.303119566Z,2025-09-24T19:41:50.297571335Z,160,1,432669,M,A,64.820000000,4,26,8058566363632,128,14765,94374923,CLX5
2025-09-24T19:41:50.303769874Z,2025-09-24T19:41:50.297848111Z,160,1,432669,M,A,64.820000000,1,26,8058566349378,128,15257,94374952,CLX5
2025-09-24T19:41:50.303829821Z,2025-09-24T19:41:50.297893153Z,160,1,432669,C,A,64.820000000,1,26,8058566367587,128,14954,94374955,CLX5
2025-09-24T19:41:50.304000592Z,2025-09-24T19:41:50.298022287Z,160,1,432669,C,B,64.800000000,2,26,8058566340680,128,18658,94374964,CLX5
2025-09-24T19:41:50.304023846Z,2025-09-24T19:41:50.298029255Z,160,1,432669,A,A,64.840000000,1,26,8058566368454,128,14511,94374965,CLX5
2025-09-24T19:41:50.304501724Z,2025-09-24T19:41:50.298397055Z,160,1,432669,A,A,64.810000000,1,26,8058566368462,128,15137,94374996,CLX5
2025-09-24T19:41:50.304725093Z,2025-09-24T19:41:50.298412029Z,160,1,432669,A,A,64.810000000,2,26,8058566368465,128,16335,94375013,CLX5
2025-09-24T19:41:50.305754589Z,2025-09-24T19:41:50.299024385Z,160,1,432669,T,N,64.810000000,1,26,0,0,14245,94375077,CLX5
2025-09-24T19:41:50.305754589Z,2025-09-24T19:41:50.299024385Z,160,1,432669,F,N,64.810000000,1,26,8058566368358,0,14245,94375077,CLX5
2025-09-24T19:41:50.305754589Z,2025-09-24T19:41:50.299024385Z,160,1,432669,M,A,64.810000000,1,26,8058566368358,128,14245,94375077,CLX5
2025-09-24T19:41:50.306042220Z,2025-09-24T19:41:50.299492539Z,160,1,432669,C,A,64.820000000,1,26,8058566367586,128,18046,94375096,CLX5
2025-09-24T19:41:50.306609781Z,2025-09-24T19:41:50.299926555Z,160,1,432669,C,A,64.810000000,1,26,8058566368432,128,16988,94375138,CLX5
2025-09-24T19:41:50.306664959Z,2025-09-24T19:41:50.299972883Z,160,1,432669,T,B,64.810000000,5,26,8058566368502,0,14738,94375142,CLX5
2025-09-24T19:41:50.306664959Z,2025-09-24T19:41:50.299972883Z,160,1,432669,F,A,64.810000000,1,26,8058566368358,0,14738,94375142,CLX5
2025-09-24T19:41:50.306664959Z,2025-09-24T19:41:50.299972883Z,160,1,432669,F,A,64.810000000,1,26,8058566368359,0,14738,94375142,CLX5
2025-09-24T19:41:50.306664959Z,2025-09-24T19:41:50.299972883Z,160,1,432669,F,A,64.810000000,1,26,8058566368399,0,14738,94375142,CLX5
2025-09-24T19:41:50.306664959Z,2025-09-24T19:41:50.299972883Z,160,1,432669,F,A,64.810000000,1,26,8058566368402,0,14738,94375142,CLX5
2025-09-24T19:41:50.306664959Z,2025-09-24T19:41:50.299972883Z,160,1,432669,F,A,64.810000000,1,26,8058566362865,0,14738,94375142,CLX5
2025-09-24T19:41:50.306696461Z,2025-09-24T19:41:50.299972883Z,160,1,432669,C,A,64.810000000,1,26,8058566368358,0,20598,94375143,CLX5
2025-09-24T19:41:50.306696461Z,2025-09-24T19:41:50.299972883Z,160,1,432669,C,A,64.810000000,1,26,8058566368359,0,20598,94375143,CLX5
2025-09-24T19:41:50.306696461Z,2025-09-24T19:41:50.299972883Z,160,1,432669,C,A,64.810000000,1,26,8058566368399,0,20598,94375143,CLX5
2025-09-24T19:41:50.306696461Z,2025-09-24T19:41:50.299972883Z,160,1,432669,C,A,64.810000000,1,26,8058566368402,0,20598,94375143,CLX5
2025-09-24T19:41:50.306696461Z,2025-09-24T19:41:50.299972883Z,160,1,432669,M,A,64.810000000,1,26,8058566362865,128,20598,94375143,CLX5
2025-09-24T19:41:50.306719953Z,2025-09-24T19:41:50.299974629Z,160,1,432669,C,A,64.810000000,1,26,8058566368434,128,14834,94375144,CLX5
2025-09-24T19:41:50.306979354Z,2025-09-24T19:41:50.300134519Z,160,1,432669,A,A,64.840000000,2,26,8058566368507,128,14927,94375165,CLX5
2025-09-24T19:41:50.307358204Z,2025-09-24T19:41:50.300361819Z,160,1,432669,C,A,64.810000000,2,26,8058566368420,128,16433,94375183,CLX5
2025-09-24T19:41:50.307637096Z,2025-09-24T19:41:50.300899049Z,160,1,432669,C,A,64.810000000,2,26,8058566368409,128,20354,94375198,CLX5
2025-09-24T19:41:50.307645904Z,2025-09-24T19:41:50.300917229Z,160,1,432669,M,B,64.460000000,10,26,8058566151203,128,15149,94375199,CLX5
2025-09-24T19:41:50.307723637Z,2025-09-24T19:41:50.301053985Z,160,1,432669,C,A,64.810000000,2,26,8058566368465,128,16970,94375203,CLX5
2025-09-24T19:41:50.308102656Z,2025-09-24T19:41:50.301948609Z,160,1,432669,T,B,64.810000000,2,26,8058566368522,0,14939,94375225,CLX5
2025-09-24T19:41:50.308102656Z,2025-09-24T19:41:50.301948609Z,160,1,432669,F,A,64.810000000,1,26,8058566362865,0,14939,94375225,CLX5
2025-09-24T19:41:50.308102656Z,2025-09-24T19:41:50.301948609Z,160,1,432669,F,A,64.810000000,1,26,8058566368407,0,14939,94375225,CLX5
2025-09-24T19:41:50.308151890Z,2025-09-24T19:41:50.301948609Z,160,1,432669,C,A,64.810000000,1,26,8058566362865,0,23233,94375226,CLX5
2025-09-24T19:41:50.308151890Z,2025-09-24T19:41:50.301948609Z,160,1,432669,C,A,64.810000000,1,26,8058566368407,128,23233,94375226,CLX5
2025-09-24T19:41:50.308188837Z,2025-09-24T19:41:50.301950279Z,160,1,432669,C,A,64.810000000,1,26,8058566368462,128,13551,94375227,CLX5
2025-09-24T19:41:50.308477113Z,2025-09-24T19:41:50.302281005Z,160,1,432669,C,A,64.810000000,1,26,8058566368431,128,18534,94375243,CLX5
2025-09-24T19:41:50.308699238Z,2025-09-24T19:41:50.302467543Z,160,1,432669,A,B,64.800000000,1,26,8058566368530,128,18644,94375256,CLX5
2025-09-24T19:41:50.309445126Z,2025-09-24T19:41:50.303450117Z,160,1,432669,A,A,64.810000000,1,26,8058566368538,128,14559,94375299,CLX5
2025-09-24T19:41:50.309477519Z,2025-09-24T19:41:50.303567751Z,160,1,432669,A,B,64.800000000,1,26,8058566368539,128,15089,94375302,CLX5
2025-09-24T19:41:50.309593373Z,2025-09-24T19:41:50.303592651Z,160,1,432669,C,A,64.810000000,1,26,8058566368538,128,18226,94375306,CLX5
2025-09-24T19:41:50.309779311Z,2025-09-24T19:41:50.303762083Z,160,1,432669,C,B,64.800000000,1,26,8058566368530,128,14918,94375319,CLX5
2025-09-24T19:41:50.310232208Z,2025-09-24T19:41:50.304117423Z,160,1,432669,A,B,64.800000000,1,26,8058566368548,128,14764,94375349,CLX5
2025-09-24T19:41:50.310262074Z,2025-09-24T19:41:50.304117671Z,160,1,432669,A,B,64.800000000,2,26,8058566368549,128,14083,94375350,CLX5
2025-09-24T19:41:50.310348531Z,2025-09-24T19:41:50.304144357Z,160,1,432669,T,N,64.810000000,1,26,0,0,14617,94375354,CLX5
2025-09-24T19:41:50.310348531Z,2025-09-24T19:41:50.304144357Z,160,1,432669,F,N,64.810000000,1,26,8058566366055,0,14617,94375354,CLX5
2025-09-24T19:41:50.310419129Z,2025-09-24T19:41:50.304144357Z,160,1,432669,C,A,64.810000000,1,26,8058566366055,128,19764,94375355,CLX5
2025-09-24T19:41:50.310589409Z,2025-09-24T19:41:50.304236187Z,160,1,432669,C,A,64.840000000,2,26,8058566368507,128,14861,94375364,CLX5
2025-09-24T19:41:50.310700786Z,2025-09-24T19:41:50.304342723Z,160,1,432669,A,B,64.800000000,2,26,8058566368553,128,15005,94375368,CLX5
2025-09-24T19:41:50.310732556Z,2025-09-24T19:41:50.304342901Z,160,1,432669,A,B,64.800000000,1,26,8058566368554,128,16981,94375369,CLX5
2025-09-24T19:41:50.311231639Z,2025-09-24T19:41:50.305397859Z,160,1,432669,C,B,64.770000000,1,26,8058566331225,128,17975,94375403,CLX5
2025-09-24T19:41:50.311255983Z,2025-09-24T19:41:50.305398007Z,160,1,432669,C,B,64.760000000,1,26,8058566321133,128,14645,94375404,CLX5
2025-09-24T19:41:50.314427502Z,2025-09-24T19:41:50.306849845Z,160,1,432669,T,A,64.810000000,1,26,8058566357512,0,13639,94375615,CLX5
2025-09-24T19:41:50.314427502Z,2025-09-24T19:41:50.306849845Z,160,1,432669,F,A,64.810000000,1,26,8058566357512,0,13639,94375615,CLX5
2025-09-24T19:41:50.314514719Z,2025-09-24T19:41:50.306849845Z,160,1,432669,C,A,64.850000000,1,26,8058566357512,128,19501,94375616,CLX5
2025-09-24T19:41:50.314709221Z,2025-09-24T19:41:50.306946321Z,160,1,432669,A,A,64.850000000,2,26,8058566368599,128,18661,94375631,CLX5
2025-09-24T19:41:50.315501655Z,2025-09-24T19:41:50.307311163Z,160,1,432669,A,B,64.810000000,1,26,8058566368606,128,15652,94375688,CLX5
2025-09-24T19:41:50.316439771Z,2025-09-24T19:41:50.308883303Z,160,1,432669,A,B,64.810000000,1,26,8058566368621,128,16778,94375747,CLX5
2025-09-24T19:41:50.316530122Z,2025-09-24T19:41:50.308897107Z,160,1,432669,A,B,64.800000000,2,26,8058566368623,128,14918,94375752,CLX5
2025-09-24T19:41:50.316716836Z,2025-09-24T19:41:50.309459509Z,160,1,432669,C,B,64.810000000,1,26,8058566368621,128,13667,94375762,CLX5
2025-09-24T19:41:50.316825864Z,2025-09-24T19:41:50.309788679Z,160,1,432669,C,B,64.800000000,2,26,8058566368623,128,14791,94375768,CLX5
2025-09-24T19:41:50.317096546Z,2025-09-24T19:41:50.310461839Z,160,1,432669,C,B,64.800000000,1,26,8058566368539,128,14689,94375780,CLX5
2025-09-24T19:41:50.317148744Z,2025-09-24T19:41:50.310474089Z,160,1,432669,A,B,64.800000000,2,26,8058566368631,128,14454,94375782,CLX5
2025-09-24T19:41:50.317236630Z,2025-09-24T19:41:50.310764437Z,160,1,432669,C,B,64.800000000,2,26,8058566368631,128,17561,94375785,CLX5
2025-09-24T19:41:50.318244853Z,2025-09-24T19:41:50.313051115Z,160,1,432669,A,B,64.800000000,1,26,8058566368651,128,17794,94375853,CLX5
2025-09-24T19:41:50.318637749Z,2025-09-24T19:41:50.313946735Z,160,1,432669,A,B,64.800000000,2,26,8058566368659,128,14491,94375873,CLX5
2025-09-24T19:41:50.319356567Z,2025-09-24T19:41:50.314330411Z,160,1,432669,M,A,65.980000000,4,26,8058566363632,128,14679,94375914,CLX5
2025-09-24T19:41:50.319409771Z,2025-09-24T19:41:50.314361111Z,160,1,432669,M,B,64.800000000,4,26,8058566319851,128,18224,94375916,CLX5
2025-09-24T19:41:50.319545470Z,2025-09-24T19:41:50.314547151Z,160,1,432669,C,B,64.800000000,2,26,8058566368659,128,15243,94375925,CLX5
2025-09-24T19:41:50.319595495Z,2025-09-24T19:41:50.314671483Z,160,1,432669,C,B,64.800000000,4,26,8058566319851,128,14936,94375928,CLX5
2025-09-24T19:41:50.320061999Z,2025-09-24T19:41:50.316446351Z,160,1,432669,A,B,64.770000000,1,26,8058566368670,128,14840,94375956,CLX5
2025-09-24T19:41:50.320454303Z,2025-09-24T19:41:50.316853217Z,160,1,432669,A,B,64.800000000,1,26,8058566368676,128,15190,94375975,CLX5
2025-09-24T19:41:50.320535254Z,2025-09-24T19:41:50.317121797Z,160,1,432669,A,B,64.800000000,1,26,8058566368678,128,14927,94375978,CLX5
2025-09-24T19:41:50.320709811Z,2025-09-24T19:41:50.317176339Z,160,1,432669,A,B,64.810000000,2,26,8058566368680,128,17800,94375984,CLX5
2025-09-24T19:41:50.320731114Z,2025-09-24T19:41:50.317176519Z,160,1,432669,A,B,64.810000000,2,26,8058566368681,128,14068,94375986,CLX5
2025-09-24T19:41:50.320789449Z,2025-09-24T19:41:50.317176781Z,160,1,432669,A,B,64.810000000,2,26,8058566368682,128,16772,94375988,CLX5
2025-09-24T19:41:50.320824499Z,2025-09-24T19:41:50.317176961Z,160,1,432669,A,B,64.810000000,1,26,8058566368683,128,19772,94375989,CLX5
2025-09-24T19:41:50.321116869Z,2025-09-24T19:41:50.317330759Z,160,1,432669,A,B,64.810000000,2,26,8058566368688,128,15522,94376003,CLX5
2025-09-24T19:41:50.321171924Z,2025-09-24T19:41:50.317343199Z,160,1,432669,C,A,64.820000000,2,26,8058566368321,128,13899,94376005,CLX5
2025-09-24T19:41:50.322315508Z,2025-09-24T19:41:50.319373893Z,160,1,432669,C,A,64.820000000,1,26,8058566368315,128,18302,94376064,CLX5
2025-09-24T19:41:50.322354781Z,2025-09-24T19:41:50.319448483Z,160,1,432669,A,B,64.810000000,1,26,8058566368705,128,15789,94376065,CLX5
2025-09-24T19:41:50.322638028Z,2025-09-24T19:41:50.320017237Z,160,1,432669,C,A,64.820000000,2,26,8058566368345,128,18772,94376082,CLX5
2025-09-24T19:41:50.322846068Z,2025-09-24T19:41:50.320206579Z,160,1,432669,C,A,64.820000000,2,26,8058566367127,128,18150,94376092,CLX5
2025-09-24T19:41:50.323561867Z,2025-09-24T19:41:50.320801659Z,160,1,432669,C,B,64.810000000,2,26,8058566368688,128,22470,94376133,CLX5
2025-09-24T19:41:50.323671870Z,2025-09-24T19:41:50.320982245Z,160,1,432669,M,B,64.800000000,4,26,8058566319508,128,18143,94376138,CLX5
2025-09-24T19:41:50.324118907Z,2025-09-24T19:41:50.321535663Z,160,1,432669,A,B,64.780000000,1,26,8058566368731,128,18380,94376157,CLX5
2025-09-24T19:41:50.324358979Z,2025-09-24T19:41:50.321783311Z,160,1,432669,A,B,64.810000000,1,26,8058566368735,128,15700,94376168,CLX5
2025-09-24T19:41:50.324392700Z,2025-09-24T19:41:50.321788015Z,160,1,432669,A,B,64.810000000,1,26,8058566368736,128,15629,94376169,CLX5
2025-09-24T19:41:50.324562803Z,2025-09-24T19:41:50.321927631Z,160,1,432669,A,B,64.810000000,1,26,8058566368739,128,14907,94376175,CLX5
2025-09-24T19:41:50.325212359Z,2025-09-24T19:41:50.322079343Z,160,1,432669,M,A,64.940000000,1,26,8058565075241,128,14693,94376222,CLX5
2025-09-24T19:41:50.325999848Z,2025-09-24T19:41:50.322674575Z,160,1,432669,A,B,64.810000000,2,26,8058566368764,128,14914,94376267,CLX5
2025-09-24T19:41:50.326133012Z,2025-09-24T19:41:50.322768267Z,160,1,432669,C,A,64.820000000,1,26,8058566367142,128,17859,94376272,CLX5
2025-09-24T19:41:50.326935261Z,2025-09-24T19:41:50.323143803Z,160,1,432669,A,B,64.810000000,1,26,8058566368778,128,18196,94376325,CLX5
2025-09-24T19:41:50.328758159Z,2025-09-24T19:41:50.325912933Z,160,1,432669,C,B,64.810000000,1,26,8058566368739,128,16407,94376423,CLX5
2025-09-24T19:41:50.333669392Z,2025-09-24T19:41:50.333538415Z,160,1,432669,A,B,64.800000000,1,26,8058566368829,128,14621,94376544,CLX5
2025-09-24T19:41:50.344722933Z,2025-09-24T19:41:50.344443151Z,160,1,432669,T,A,64.810000000,1,26,8058566368842,0,18410,94376574,CLX5
2025-09-24T19:41:50.344722933Z,2025-09-24T19:41:50.344443151Z,160,1,432669,F,B,64.810000000,1,26,8058566368606,0,18410,94376574,CLX5
2025-09-24T19:41:50.344733739Z,2025-09-24T19:41:50.344443151Z,160,1,432669,C,B,64.810000000,1,26,8058566368606,128,15944,94376575,CLX5
2025-09-24T19:41:50.344898789Z,2025-09-24T19:41:50.344726759Z,160,1,432669,C,B,64.810000000,1,26,8058566368778,128,15162,94376578,CLX5
2025-09-24T19:41:50.348476682Z,2025-09-24T19:41:50.348326947Z,160,1,432669,A,A,64.820000000,1,26,8058566368849,128,19054,94376593,CLX5
2025-09-24T19:41:50.350072441Z,2025-09-24T19:41:50.349939137Z,160,1,432669,A,A,64.820000000,1,26,8058566368852,128,18617,94376597,CLX5
2025-09-24T19:41:50.359782653Z,2025-09-24T19:41:50.359653985Z,160,1,432669,A,B,64.790000000,2,26,8058566368882,128,18518,94376653,CLX5
2025-09-24T19:41:50.399352979Z,2025-09-24T19:41:50.399072745Z,160,1,432669,A,B,64.810000000,1,26,8058566368955,128,18456,94376788,CLX5
2025-09-24T19:41:50.440929845Z,2025-09-24T19:41:50.440792773Z,160,1,432669,A,B,64.780000000,1,26,8058566369032,128,16579,94376909,CLX5
2025-09-24T19:41:50.474692476Z,2025-09-24T19:41:50.474566099Z,160,1,432669,C,A,64.840000000,1,26,8058566368454,128,18064,94376978,CLX5
2025-09-24T19:41:50.474845400Z,2025-09-24T19:41:50.474720845Z,160,1,432669,C,B,64.800000000,1,26,8058566368678,128,18204,94376979,CLX5
2025-09-24T19:41:50.563998396Z,2025-09-24T19:41:50.563861437Z,160,1,432669,C,B,64.810000000,1,26,8058566368955,128,18857,94377098,CLX5
2025-09-24T19:41:50.591896535Z,2025-09-24T19:41:50.591741409Z,160,1,432669,A,B,64.810000000,2,26,8058566369168,128,19158,94377145,CLX5
2025-09-24T19:41:50.618251113Z,2025-09-24T19:41:50.618147691Z,160,1,432669,A,A,65.700000000,6,26,8058566369177,128,18260,94377165,CLX5
2025-09-24T19:41:51.476073987Z,2025-09-24T19:41:51.475934007Z,160,1,432669,C,B,64.800000000,1,26,8058566368676,128,18138,94377388,CLX5
2025-09-24T19:41:51.476102232Z,2025-09-24T19:41:51.475946293Z,160,1,432669,C,B,64.800000000,1,26,8058566368651,128,14565,94377389,CLX5
2025-09-24T19:41:51.669916883Z,2025-09-24T19:41:51.669760821Z,160,1,432669,C,B,64.810000000,2,26,8058566368764,128,15252,94377520,CLX5
2025-09-24T19:41:51.718245746Z,2025-09-24T19:41:51.718147197Z,160,1,432669,C,A,65.700000000,6,26,8058566369177,128,16263,94377640,CLX5
2025-09-24T19:41:52.504711656Z,2025-09-24T19:41:52.504575809Z,160,1,432669,A,B,64.760000000,1,26,8058566369432,128,18005,94377786,CLX5
2025-09-24T19:41:53.251657692Z,2025-09-24T19:41:53.251461843Z,160,1,432669,A,B,64.810000000,2,26,8058566369475,128,14982,94377859,CLX5
2025-09-24T19:41:55.244181868Z,2025-09-24T19:41:55.244052675Z,160,1,432669,A,B,64.260000000,1,26,8058566369534,128,18035,94378035,CLX5
2025-09-24T19:41:55.849508788Z,2025-09-24T19:41:55.849180405Z,160,1,432669,C,B,64.810000000,2,26,8058566369475,128,15118,94378059,CLX5
2025-09-24T19:41:55.849758905Z,2025-09-24T19:41:55.849580227Z,160,1,432669,A,A,64.820000000,1,26,8058566369540,128,14898,94378069,CLX5
2025-09-24T19:41:55.851427750Z,2025-09-24T19:41:55.851298687Z,160,1,432669,A,B,64.810000000,2,26,8058566369547,128,17762,94378100,CLX5
2025-09-24T19:41:55.851572411Z,2025-09-24T19:41:55.851431929Z,160,1,432669,C,A,64.820000000,1,26,8058566369540,128,15327,94378103,CLX5
2025-09-24T19:41:57.255164952Z,2025-09-24T19:41:57.254820689Z,160,1,432669,T,B,64.820000000,2,26,8058566369600,0,18533,94378236,CLX5
2025-09-24T19:41:57.255164952Z,2025-09-24T19:41:57.254820689Z,160,1,432669,F,A,64.820000000,2,26,8058566367045,0,18533,94378236,CLX5
2025-09-24T19:41:57.255174920Z,2025-09-24T19:41:57.254820689Z,160,1,432669,C,A,64.820000000,2,26,8058566367045,128,15114,94378237,CLX5
2025-09-24T19:41:57.255393382Z,2025-09-24T19:41:57.255142965Z,160,1,432669,A,B,64.810000000,1,26,8058566369603,128,14959,94378240,CLX5
2025-09-24T19:41:57.255432694Z,2025-09-24T19:41:57.255157251Z,160,1,432669,C,A,64.820000000,1,26,8058566367123,128,17925,94378241,CLX5
2025-09-24T19:41:57.255721493Z,2025-09-24T19:41:57.255180999Z,160,1,432669,T,B,64.820000000,12,26,8058566369605,0,17359,94378248,CLX5
2025-09-24T19:41:57.255721493Z,2025-09-24T19:41:57.255180999Z,160,1,432669,F,A,64.820000000,1,26,8058566367047,0,17359,94378248,CLX5
2025-09-24T19:41:57.255721493Z,2025-09-24T19:41:57.255180999Z,160,1,432669,F,A,64.820000000,1,26,8058566367054,0,17359,94378248,CLX5
2025-09-24T19:41:57.255721493Z,2025-09-24T19:41:57.255180999Z,160,1,432669,F,A,64.820000000,1,26,8058566367089,0,17359,94378248,CLX5
2025-09-24T19:41:57.255721493Z,2025-09-24T19:41:57.255180999Z,160,1,432669,F,A,64.820000000,2,26,8058566367111,0,17359,94378248,CLX5
2025-09-24T19:41:57.255721493Z,2025-09-24T19:41:57.255180999Z,160,1,432669,F,A,64.820000000,1,26,8058566367116,0,17359,94378248,CLX5
2025-09-24T19:41:57.255721493Z,2025-09-24T19:41:57.255180999Z,160,1,432669,F,A,64.820000000,3,26,8058566367120,0,17359,94378248,CLX5
2025-09-24T19:41:57.255721493Z,2025-09-24T19:41:57.255180999Z,160,1,432669,F,A,64.820000000,1,26,8058566367121,0,17359,94378248,CLX5
2025-09-24T19:41:57.255721493Z,2025-09-24T19:41:57.255180999Z,160,1,432669,F,A,64.820000000,1,26,8058566366218,0,17359,94378248,CLX5
2025-09-24T19:41:57.255721493Z,2025-09-24T19:41:57.255180999Z,160,1,432669,F,A,64.820000000,1,26,8058566239191,0,17359,94378248,CLX5
2025-09-24T19:41:57.255730732Z,2025-09-24T19:41:57.255180999Z,160,1,432669,C,A,64.820000000,1,26,8058566367047,0,15374,94378249,CLX5
2025-09-24T19:41:57.255730732Z,2025-09-24T19:41:57.255180999Z,160,1,432669,C,A,64.820000000,1,26,8058566367054,0,15374,94378249,CLX5
2025-09-24T19:41:57.255730732Z,2025-09-24T19:41:57.255180999Z,160,1,432669,C,A,64.820000000,1,26,8058566367089,0,15374,94378249,CLX5
2025-09-24T19:41:57.255730732Z,2025-09-24T19:41:57.255180999Z,160,1,432669,C,A,64.820000000,2,26,8058566367111,0,15374,94378249,CLX5
2025-09-24T19:41:57.255730732Z,2025-09-24T19:41:57.255180999Z,160,1,432669,C,A,64.820000000,1,26,8058566367116,0,15374,94378249,CLX5
2025-09-24T19:41:57.255730732Z,2025-09-24T19:41:57.255180999Z,160,1,432669,C,A,64.820000000,3,26,8058566367120,0,15374,94378249,CLX5
2025-09-24T19:41:57.255730732Z,2025-09-24T19:41:57.255180999Z,160,1,432669,C,A,64.820000000,1,26,8058566367121,0,15374,94378249,CLX5
2025-09-24T19:41:57.255730732Z,2025-09-24T19:41:57.255180999Z,160,1,432669,C,A,64.820000000,1,26,8058566366218,0,15374,94378249,CLX5
2025-09-24T19:41:57.255730732Z,2025-09-24T19:41:57.255180999Z,160,1,432669,C,A,64.820000000,1,26,8058566239191,128,15374,94378249,CLX5
2025-09-24T19:41:57.255799157Z,2025-09-24T19:41:57.255592995Z,160,1,432669,A,B,64.810000000,1,26,8058566369607,128,18762,94378254,CLX5
2025-09-24T19:41:57.255916371Z,2025-09-24T19:41:57.255634483Z,160,1,432669,A,B,64.810000000,1,26,8058566369609,128,18479,94378260,CLX5
2025-09-24T19:41:57.256508652Z,2025-09-24T19:41:57.255722939Z,160,1,432669,T,N,64.820000000,1,26,0,0,18545,94378281,CLX5
2025-09-24T19:41:57.256508652Z,2025-09-24T19:41:57.255722939Z,160,1,432669,F,N,64.820000000,1,26,8058566367390,0,18545,94378281,CLX5
2025-09-24T19:41:57.256519833Z,2025-09-24T19:41:57.255722939Z,160,1,432669,C,A,64.820000000,1,26,8058566367390,128,15706,94378282,CLX5
2025-09-24T19:41:57.256653097Z,2025-09-24T19:41:57.255723293Z,160,1,432669,T,B,64.820000000,4,26,8058566369620,0,19679,94378287,CLX5
2025-09-24T19:41:57.256653097Z,2025-09-24T19:41:57.255723293Z,160,1,432669,F,A,64.820000000,1,26,8058566366236,0,19679,94378287,CLX5
2025-09-24T19:41:57.256653097Z,2025-09-24T19:41:57.255723293Z,160,1,432669,F,A,64.820000000,1,26,8058566368849,0,19679,94378287,CLX5
2025-09-24T19:41:57.256653097Z,2025-09-24T19:41:57.255723293Z,160,1,432669,F,A,64.820000000,1,26,8058566368852,0,19679,94378287,CLX5
2025-09-24T19:41:57.256653097Z,2025-09-24T19:41:57.255723293Z,160,1,432669,F,A,64.820000000,1,26,8058566349378,0,19679,94378287,CLX5
2025-09-24T19:41:57.256663641Z,2025-09-24T19:41:57.255723293Z,160,1,432669,C,A,64.820000000,1,26,8058566366236,0,14880,94378288,CLX5
2025-09-24T19:41:57.256663641Z,2025-09-24T19:41:57.255723293Z,160,1,432669,C,A,64.820000000,1,26,8058566368849,0,14880,94378288,CLX5
2025-09-24T19:41:57.256663641Z,2025-09-24T19:41:57.255723293Z,160,1,432669,C,A,64.820000000,1,26,8058566368852,0,14880,94378288,CLX5
2025-09-24T19:41:57.256663641Z,2025-09-24T19:41:57.255723293Z,160,1,432669,C,A,64.820000000,1,26,8058566349378,128,14880,94378288,CLX5
2025-09-24T19:41:57.256696356Z,2025-09-24T19:41:57.255724527Z,160,1,432669,A,B,64.810000000,1,26,8058566369621,128,17878,94378291,CLX5
2025-09-24T19:41:57.256745767Z,2025-09-24T19:41:57.255735069Z,160,1,432669,C,B,64.810000000,1,26,8058566369609,128,16692,94378296,CLX5
2025-09-24T19:41:57.256966739Z,2025-09-24T19:41:57.255755325Z,160,1,432669,A,B,64.810000000,2,26,8058566369628,128,17495,94378304,CLX5
2025-09-24T19:41:57.257068341Z,2025-09-24T19:41:57.255767323Z,160,1,432669,M,B,64.810000000,1,26,8058566368370,128,18354,94378311,CLX5
2025-09-24T19:41:57.257223261Z,2025-09-24T19:41:57.255919553Z,160,1,432669,A,A,64.820000000,1,26,8058566369631,128,14539,94378317,CLX5
2025-09-24T19:41:57.258204560Z,2025-09-24T19:41:57.256508879Z,160,1,432669,T,B,64.820000000,1,26,8058566369642,0,15126,94378353,CLX5
2025-09-24T19:41:57.258204560Z,2025-09-24T19:41:57.256508879Z,160,1,432669,F,A,64.820000000,1,26,8058566369631,0,15126,94378353,CLX5
2025-09-24T19:41:57.258260214Z,2025-09-24T19:41:57.256508879Z,160,1,432669,C,A,64.820000000,1,26,8058566369631,128,18404,94378354,CLX5
2025-09-24T19:41:57.258594783Z,2025-09-24T19:41:57.256661157Z,160,1,432669,A,B,64.790000000,1,26,8058566369648,128,13896,94378370,CLX5
2025-09-24T19:41:57.259404604Z,2025-09-24T19:41:57.256724975Z,160,1,432669,A,B,64.810000000,1,26,8058566369659,128,18344,94378402,CLX5
2025-09-24T19:41:57.259448593Z,2025-09-24T19:41:57.256753199Z,160,1,432669,A,B,64.810000000,1,26,8058566369660,128,15575,94378404,CLX5
2025-09-24T19:41:57.259491483Z,2025-09-24T19:41:57.256768769Z,160,1,432669,A,B,64.810000000,1,26,8058566369661,128,14899,94378406,CLX5
2025-09-24T19:41:57.259524206Z,2025-09-24T19:41:57.256774799Z,160,1,432669,A,B,64.810000000,1,26,8058566369662,128,18181,94378407,CLX5
2025-09-24T19:41:57.259533598Z,2025-09-24T19:41:57.256824255Z,160,1,432669,A,A,65.140000000,1,26,8058566369663,128,14689,94378408,CLX5
2025-09-24T19:41:57.259836774Z,2025-09-24T19:41:57.256964427Z,160,1,432669,M,A,65.990000000,4,26,8058566321460,128,18686,94378422,CLX5
2025-09-24T19:41:57.260308170Z,2025-09-24T19:41:57.257130845Z,160,1,432669,C,B,64.780000000,1,26,8058566369032,128,13486,94378438,CLX5
2025-09-24T19:41:57.260399826Z,2025-09-24T19:41:57.257186429Z,160,1,432669,A,B,64.810000000,1,26,8058566369670,128,15159,94378441,CLX5
2025-09-24T19:41:57.260481476Z,2025-09-24T19:41:57.257218241Z,160,1,432669,C,A,64.850000000,2,26,8058566367269,128,17769,94378445,CLX5
2025-09-24T19:41:57.260548449Z,2025-09-24T19:41:57.257232635Z,160,1,432669,A,B,64.820000000,1,26,8058566369673,128,14545,94378447,CLX5
2025-09-24T19:41:57.260716648Z,2025-09-24T19:41:57.257263243Z,160,1,432669,C,B,64.810000000,1,26,8058566369662,128,14695,94378455,CLX5
2025-09-24T19:41:57.260773413Z,2025-09-24T19:41:57.257355899Z,160,1,432669,A,B,64.820000000,1,26,8058566369675,128,15168,94378457,CLX5
2025-09-24T19:41:57.260936077Z,2025-09-24T19:41:57.257437975Z,160,1,432669,C,B,64.810000000,1,26,8058566369661,128,14406,94378465,CLX5
2025-09-24T19:41:57.260965636Z,2025-09-24T19:41:57.257449129Z,160,1,432669,C,B,64.810000000,1,26,8058566369660,128,14973,94378466,CLX5
2025-09-24T19:41:57.260994165Z,2025-09-24T19:41:57.257450705Z,160,1,432669,C,B,64.810000000,1,26,8058566369659,128,14815,94378467,CLX5
2025-09-24T19:41:57.261062683Z,2025-09-24T19:41:57.257461777Z,160,1,432669,C,B,64.820000000,1,26,8058566369675,128,14366,94378470,CLX5
2025-09-24T19:41:57.261153072Z,2025-09-24T19:41:57.257518823Z,160,1,432669,M,B,64.820000000,1,26,8058566369168,128,14470,94378475,CLX5
2025-09-24T19:41:57.261884331Z,2025-09-24T19:41:57.258472753Z,160,1,432669,A,B,64.810000000,1,26,8058566369687,128,18617,94378513,CLX5
2025-09-24T19:41:57.262022824Z,2025-09-24T19:41:57.258585413Z,160,1,432669,C,B,64.820000000,1,26,8058566369673,128,13505,94378521,CLX5
2025-09-24T19:41:57.262141635Z,2025-09-24T19:41:57.258626173Z,160,1,432669,A,B,64.810000000,3,26,8058566369689,128,14554,94378529,CLX5
2025-09-24T19:41:57.262338371Z,2025-09-24T19:41:57.258853125Z,160,1,432669,C,B,64.810000000,1,26,8058566369687,128,15881,94378538,CLX5
2025-09-24T19:41:57.262566033Z,2025-09-24T19:41:57.259191165Z,160,1,432669,A,B,64.810000000,1,26,8058566369695,128,14965,94378550,CLX5
2025-09-24T19:41:57.262940014Z,2025-09-24T19:41:57.259376917Z,160,1,432669,C,B,64.810000000,1,26,8058566369695,128,14692,94378564,CLX5
2025-09-24T19:41:57.263286609Z,2025-09-24T19:41:57.260332113Z,160,1,432669,A,B,64.810000000,1,26,8058566369702,128,14832,94378581,CLX5
2025-09-24T19:41:57.263449494Z,2025-09-24T19:41:57.260557127Z,160,1,432669,A,B,64.820000000,1,26,8058566369705,128,17915,94378588,CLX5
2025-09-24T19:41:57.263469668Z,2025-09-24T19:41:57.260565575Z,160,1,432669,C,B,64.800000000,1,26,8058566368829,128,17060,94378590,CLX5
2025-09-24T19:41:57.263518180Z,2025-09-24T19:41:57.260571373Z,160,1,432669,A,B,64.820000000,2,26,8058566369706,128,14716,94378592,CLX5
2025-09-24T19:41:57.263639195Z,2025-09-24T19:41:57.260723873Z,160,1,432669,A,A,64.860000000,1,26,8058566369708,128,17947,94378599,CLX5
2025-09-24T19:41:57.265155002Z,2025-09-24T19:41:57.262754969Z,160,1,432669,M,A,64.840000000,1,26,8058566173085,128,18852,94378698,CLX5
2025-09-24T19:41:57.265497489Z,2025-09-24T19:41:57.263520075Z,160,1,432669,A,B,64.820000000,2,26,8058566369738,128,13653,94378720,CLX5
2025-09-24T19:41:57.312874441Z,2025-09-24T19:41:57.312749025Z,160,1,432669,A,A,64.870000000,2,26,8058566369754,128,17726,94378782,CLX5
2025-09-24T19:41:57.313018695Z,2025-09-24T19:41:57.312879061Z,160,1,432669,C,B,64.820000000,2,26,8058566369738,128,20678,94378783,CLX5
2025-09-24T19:41:57.318514238Z,2025-09-24T19:41:57.318412929Z,160,1,432669,A,A,65.900000000,1,26,8058566369756,128,17592,94378788,CLX5
2025-09-24T19:41:57.318559601Z,2025-09-24T19:41:57.318460447Z,160,1,432669,A,A,65.700000000,6,26,8058566369757,128,14310,94378789,CLX5
2025-09-24T19:41:57.478168846Z,2025-09-24T19:41:57.478027197Z,160,1,432669,A,B,64.810000000,1,26,8058566369797,128,18898,94378871,CLX5
2025-09-24T19:41:57.564731873Z,2025-09-24T19:41:57.564602265Z,160,1,432669,C,B,64.790000000,1,26,8058566369648,128,17956,94378881,CLX5
2025-09-24T19:41:57.564875858Z,2025-09-24T19:41:57.564759525Z,160,1,432669,C,B,64.810000000,1,26,8058566369702,128,18266,94378882,CLX5
2025-09-24T19:41:58.508732394Z,2025-09-24T19:41:58.508448879Z,160,1,432669,T,A,64.820000000,1,26,8058566369828,0,19516,94378936,CLX5
2025-09-24T19:41:58.508732394Z,2025-09-24T19:41:58.508448879Z,160,1,432669,F,B,64.820000000,1,26,8058566369168,0,19516,94378936,CLX5
2025-09-24T19:41:58.508744534Z,2025-09-24T19:41:58.508448879Z,160,1,432669,C,B,64.820000000,1,26,8058566369168,128,17599,94378937,CLX5
2025-09-24T19:41:58.508915629Z,2025-09-24T19:41:58.508743739Z,160,1,432669,A,A,64.860000000,1,26,8058566369830,128,15167,94378942,CLX5
2025-09-24T19:41:58.508970738Z,2025-09-24T19:41:58.508755489Z,160,1,432669,C,B,64.820000000,2,26,8058566369706,128,17782,94378943,CLX5
2025-09-24T19:41:58.542634858Z,2025-09-24T19:41:58.542369749Z,160,1,432669,T,A,64.820000000,1,26,8058566369838,0,17778,94378965,CLX5
2025-09-24T19:41:58.542634858Z,2025-09-24T19:41:58.542369749Z,160,1,432669,F,B,64.820000000,1,26,8058566369705,0,17778,94378965,CLX5
2025-09-24T19:41:58.542646736Z,2025-09-24T19:41:58.542369749Z,160,1,432669,C,B,64.820000000,1,26,8058566369705,128,17209,94378966,CLX5
2025-09-24T19:41:58.543427415Z,2025-09-24T19:41:58.543292979Z,160,1,432669,A,A,64.850000000,2,26,8058566369841,128,18345,94378975,CLX5
2025-09-24T19:41:58.565495221Z,2025-09-24T19:41:58.565367129Z,160,1,432669,C,A,64.860000000,1,26,8058566369830,128,18030,94379046,CLX5
2025-09-24T19:41:58.612492259Z,2025-09-24T19:41:58.612370321Z,160,1,432669,C,A,64.870000000,2,26,8058566369754,128,18497,94379072,CLX5
2025-09-24T19:41:58.618238264Z,2025-09-24T19:41:58.618139397Z,160,1,432669,C,A,65.900000000,1,26,8058566369756,128,18353,94379073,CLX5
2025-09-24T19:41:58.740906188Z,2025-09-24T19:41:58.740776309Z,160,1,432669,A,B,64.780000000,1,26,8058566369877,128,17962,94379089,CLX5
2025-09-24T19:42:00.024545506Z,2025-09-24T19:42:00.024400275Z,160,1,432669,A,A,64.870000000,1,26,8058566369899,128,18016,94379135,CLX5
2025-09-24T19:42:02.123574503Z,2025-09-24T19:42:02.123181331Z,160,1,432669,T,B,64.830000000,1,26,8058566369988,0,18329,94379386,CLX5
2025-09-24T19:42:02.123574503Z,2025-09-24T19:42:02.123181331Z,160,1,432669,F,A,64.830000000,1,26,8058566365417,0,18329,94379386,CLX5
2025-09-24T19:42:02.123585024Z,2025-09-24T19:42:02.123181331Z,160,1,432669,M,A,64.830000000,1,26,8058566365417,128,15342,94379387,CLX5
2025-09-24T19:42:02.123774472Z,2025-09-24T19:42:02.123538357Z,160,1,432669,A,B,64.820000000,2,26,8058566369989,128,17247,94379390,CLX5
2025-09-24T19:42:02.123853096Z,2025-09-24T19:42:02.123545519Z,160,1,432669,C,A,64.830000000,1,26,8058566367079,128,16447,94379395,CLX5
2025-09-24T19:42:02.123921852Z,2025-09-24T19:42:02.123645527Z,160,1,432669,A,B,64.810000000,1,26,8058566369993,128,14285,94379398,CLX5
2025-09-24T19:42:02.124052328Z,2025-09-24T19:42:02.123857545Z,160,1,432669,A,A,64.830000000,1,26,8058566369995,128,16120,94379404,CLX5
2025-09-24T19:42:02.124105217Z,2025-09-24T19:42:02.123859155Z,160,1,432669,C,B,64.820000000,2,26,8058566369989,128,18262,94379405,CLX5
2025-09-24T19:42:02.124249701Z,2025-09-24T19:42:02.124128155Z,160,1,432669,A,B,64.810000000,1,26,8058566370000,128,13782,94379414,CLX5
2025-09-24T19:42:02.124303604Z,2025-09-24T19:42:02.124184773Z,160,1,432669,C,B,64.780000000,1,26,8058566369877,128,18179,94379415,CLX5
2025-09-24T19:42:02.124425672Z,2025-09-24T19:42:02.124222135Z,160,1,432669,A,B,64.810000000,1,26,8058566370002,128,13699,94379420,CLX5
2025-09-24T19:42:02.429292006Z,2025-09-24T19:42:02.429172723Z,160,1,432669,M,A,64.930000000,1,26,8058566157942,128,17970,94379450,CLX5
2025-09-24T19:42:03.041174915Z,2025-09-24T19:42:03.041024419Z,160,1,432669,A,B,64.780000000,1,26,8058566370019,128,18417,94379481,CLX5
2025-09-24T19:42:03.099191528Z,2025-09-24T19:42:03.099043873Z,160,1,432669,C,A,64.830000000,1,26,8058566369995,128,19164,94379484,CLX5
2025-09-24T19:42:04.543209553Z,2025-09-24T19:42:04.543074167Z,160,1,432669,C,A,65.100000000,1,26,8058566364843,128,24922,94379490,CLX5
2025-09-24T19:42:05.014633970Z,2025-09-24T19:42:05.014517407Z,160,1,432669,C,A,65.070000000,1,26,8058566364716,128,21301,94379491,CLX5
2025-09-24T19:42:05.061393197Z,2025-09-24T19:42:05.061265769Z,160,1,432669,A,A,65.060000000,1,26,8058566370024,128,20546,94379492,CLX5
2025-09-24T19:42:05.202095562Z,2025-09-24T19:42:05.201975535Z,160,1,432669,C,A,65.100000000,1,26,8058566364828,128,20553,94379494,CLX5
2025-09-24T19:42:05.264654491Z,2025-09-24T19:42:05.264534111Z,160,1,432669,A,A,65.090000000,1,26,8058566370025,128,20852,94379495,CLX5
2025-09-24T19:42:05.498488040Z,2025-09-24T19:42:05.498361419Z,160,1,432669,C,B,64.660000000,4,26,8058564618281,128,28168,94379496,CLX5
2025-09-24T19:42:06.442070297Z,2025-09-24T19:42:06.441906217Z,160,1,432669,A,A,64.830000000,1,26,8058566370028,128,19853,94379506,CLX5
2025-09-24T19:42:07.200743026Z,2025-09-24T19:42:07.200582685Z,160,1,432669,A,A,64.830000000,1,26,8058566370042,128,18313,94379601,CLX5
2025-09-24T19:42:07.367971919Z,2025-09-24T19:42:07.366939723Z,160,1,432669,A,B,64.820000000,2,26,8058566370063,128,16352,94379686,CLX5
2025-09-24T19:42:07.368063260Z,2025-09-24T19:42:07.366940051Z,160,1,432669,A,B,64.820000000,3,26,8058566370064,128,18284,94379691,CLX5
2025-09-24T19:42:07.368149640Z,2025-09-24T19:42:07.366941003Z,160,1,432669,A,B,64.820000000,2,26,8058566370066,128,15828,94379695,CLX5
2025-09-24T19:42:07.368279902Z,2025-09-24T19:42:07.366942513Z,160,1,432669,C,A,64.850000000,2,26,8058566369841,128,18678,94379700,CLX5
2025-09-24T19:42:07.369506881Z,2025-09-24T19:42:07.367292327Z,160,1,432669,C,A,64.850000000,1,26,8058566367153,128,17353,94379755,CLX5
2025-09-24T19:42:07.369626757Z,2025-09-24T19:42:07.367303195Z,160,1,432669,A,B,64.820000000,1,26,8058566370086,128,19993,94379761,CLX5
2025-09-24T19:42:07.369637577Z,2025-09-24T19:42:07.367323565Z,160,1,432669,A,B,64.820000000,1,26,8058566370087,128,13448,94379762,CLX5
2025-09-24T19:42:07.369870284Z,2025-09-24T19:42:07.367523581Z,160,1,432669,C,B,64.780000000,1,26,8058566370019,128,14675,94379773,CLX5
2025-09-24T19:42:07.369960158Z,2025-09-24T19:42:07.367531127Z,160,1,432669,C,B,64.820000000,2,26,8058566370066,128,14927,94379775,CLX5
2025-09-24T19:42:07.370174542Z,2025-09-24T19:42:07.367542417Z,160,1,432669,A,B,64.790000000,1,26,8058566370097,128,14414,94379781,CLX5
2025-09-24T19:42:07.370486112Z,2025-09-24T19:42:07.367648451Z,160,1,432669,A,B,64.820000000,1,26,8058566370103,128,19855,94379794,CLX5
2025-09-24T19:42:07.370657743Z,2025-09-24T19:42:07.367686563Z,160,1,432669,A,B,64.820000000,2,26,8058566370108,128,15876,94379800,CLX5
2025-09-24T19:42:07.370789717Z,2025-09-24T19:42:07.367791869Z,160,1,432669,A,B,64.800000000,2,26,8058566370110,128,15785,94379807,CLX5
2025-09-24T19:42:07.371124701Z,2025-09-24T19:42:07.367985781Z,160,1,432669,A,B,64.820000000,1,26,8058566370120,128,14380,94379825,CLX5
2025-09-24T19:42:07.371322880Z,2025-09-24T19:42:07.368005809Z,160,1,432669,A,B,64.820000000,1,26,8058566370122,128,15911,94379837,CLX5
2025-09-24T19:42:07.371648126Z,2025-09-24T19:42:07.368065131Z,160,1,432669,A,B,64.820000000,1,26,8058566370126,128,15607,94379859,CLX5
2025-09-24T19:42:07.371812140Z,2025-09-24T19:42:07.368094891Z,160,1,432669,A,B,64.820000000,1,26,8058566370128,128,14388,94379866,CLX5
2025-09-24T19:42:07.371894250Z,2025-09-24T19:42:07.368121807Z,160,1,432669,A,B,64.820000000,1,26,8058566370130,128,18778,94379870,CLX5
2025-09-24T19:42:07.372120829Z,2025-09-24T19:42:07.368327545Z,160,1,432669,C,B,64.820000000,1,26,8058566370120,128,15019,94379883,CLX5
2025-09-24T19:42:07.372291231Z,2025-09-24T19:42:07.368589287Z,160,1,432669,C,B,64.820000000,3,26,8058566370064,128,20182,94379895,CLX5
2025-09-24T19:42:07.372320660Z,2025-09-24T19:42:07.368599559Z,160,1,432669,C,B,64.820000000,2,26,8058566370063,128,16041,94379896,CLX5
2025-09-24T19:42:07.372754503Z,2025-09-24T19:42:07.369079693Z,160,1,432669,A,B,64.820000000,3,26,8058566370142,128,14806,94379913,CLX5
2025-09-24T19:42:07.372983816Z,2025-09-24T19:42:07.369188955Z,160,1,432669,C,B,64.820000000,2,26,8058566370108,128,15927,94379926,CLX5
2025-09-24T19:42:07.374121879Z,2025-09-24T19:42:07.369831407Z,160,1,432669,A,A,64.830000000,1,26,8058566370157,128,15447,94379980,CLX5
2025-09-24T19:42:07.374173670Z,2025-09-24T19:42:07.369844067Z,160,1,432669,C,B,64.820000000,1,26,8058566370103,128,15912,94379982,CLX5
2025-09-24T19:42:07.375206867Z,2025-09-24T19:42:07.371339489Z,160,1,432669,C,B,64.820000000,1,26,8058566370122,128,16054,94380039,CLX5
2025-09-24T19:42:07.375370829Z,2025-09-24T19:42:07.371610467Z,160,1,432669,M,B,64.810000000,3,26,8058566345944,128,14931,94380050,CLX5
2025-09-24T19:42:07.375842331Z,2025-09-24T19:42:07.372368257Z,160,1,432669,C,B,64.800000000,2,26,8058566370110,128,13534,94380069,CLX5
2025-09-24T19:42:07.376516046Z,2025-09-24T19:42:07.372980845Z,160,1,432669,C,B,64.820000000,3,26,8058566370142,128,13597,94380098,CLX5
2025-09-24T19:42:07.418237246Z,2025-09-24T19:42:07.418130955Z,160,1,432669,A,A,65.900000000,1,26,8058566370239,128,18358,94380279,CLX5
2025-09-24T19:42:07.512563545Z,2025-09-24T19:42:07.512434159Z,160,1,432669,A,A,64.870000000,2,26,8058566370295,128,18190,94380359,CLX5
2025-09-24T19:42:07.515447886Z,2025-09-24T19:42:07.515293875Z,160,1,432669,C,B,64.820000000,1,26,8058566370130,128,22535,94380362,CLX5
2025-09-24T19:42:07.515482721Z,2025-09-24T19:42:07.515308313Z,160,1,432669,C,B,64.820000000,1,26,8058566370128,128,13337,94380363,CLX5
2025-09-24T19:42:07.527589529Z,2025-09-24T19:42:07.527436187Z,160,1,432669,C,B,64.820000000,1,26,8058566370126,128,18446,94380374,CLX5
2025-09-24T19:42:07.527923008Z,2025-09-24T19:42:07.527602701Z,160,1,432669,A,A,64.850000000,2,26,8058566370305,128,15594,94380394,CLX5
2025-09-24T19:42:07.612557386Z,2025-09-24T19:42:07.612431335Z,160,1,432669,C,A,64.870000000,2,26,8058566370295,128,20143,94380446,CLX5
2025-09-24T19:42:07.618212450Z,2025-09-24T19:42:07.618114017Z,160,1,432669,C,A,65.900000000,1,26,8058566370239,128,17978,94380447,CLX5
2025-09-24T19:42:07.640981210Z,2025-09-24T19:42:07.640844085Z,160,1,432669,A,B,64.790000000,1,26,8058566370342,128,18485,94380465,CLX5
2025-09-24T19:42:07.641327690Z,2025-09-24T19:42:07.641140903Z,160,1,432669,A,B,64.820000000,2,26,8058566370344,128,14365,94380471,CLX5
2025-09-24T19:42:07.674786480Z,2025-09-24T19:42:07.674658593Z,160,1,432669,C,B,64.790000000,1,26,8058566370097,128,18212,94380505,CLX5
2025-09-24T19:42:08.944600506Z,2025-09-24T19:42:08.944454923Z,160,1,432669,C,B,64.810000000,1,26,8058566370002,128,18515,94380596,CLX5
2025-09-24T19:42:08.944755212Z,2025-09-24T19:42:08.944632017Z,160,1,432669,C,B,64.810000000,1,26,8058566370000,128,14840,94380598,CLX5
2025-09-24T19:42:08.944910286Z,2025-09-24T19:42:08.944766007Z,160,1,432669,C,B,64.820000000,2,26,8058566370344,128,14646,94380601,CLX5
2025-09-24T19:42:08.944931927Z,2025-09-24T19:42:08.944782441Z,160,1,432669,C,B,64.810000000,1,26,8058566369993,128,14109,94380603,CLX5
2025-09-24T19:42:08.945303190Z,2025-09-24T19:42:08.944982919Z,160,1,432669,T,A,64.820000000,2,26,8058566370420,0,18625,94380607,CLX5
2025-09-24T19:42:08.945303190Z,2025-09-24T19:42:08.944982919Z,160,1,432669,F,B,64.820000000,1,26,8058566370086,0,18625,94380607,CLX5
2025-09-24T19:42:08.945303190Z,2025-09-24T19:42:08.944982919Z,160,1,432669,F,B,64.820000000,1,26,8058566370087,0,18625,94380607,CLX5
2025-09-24T19:42:08.945313081Z,2025-09-24T19:42:08.944982919Z,160,1,432669,C,B,64.820000000,1,26,8058566370086,0,14600,94380608,CLX5
2025-09-24T19:42:08.945313081Z,2025-09-24T19:42:08.944982919Z,160,1,432669,C,B,64.820000000,1,26,8058566370087,128,14600,94380608,CLX5
2025-09-24T19:42:08.945497821Z,2025-09-24T19:42:08.945303507Z,160,1,432669,A,A,64.820000000,1,26,8058566370421,128,18810,94380612,CLX5
2025-09-24T19:42:08.945641499Z,2025-09-24T19:42:08.945305715Z,160,1,432669,A,A,64.820000000,1,26,8058566370424,128,14479,94380618,CLX5
2025-09-24T19:42:08.945899941Z,2025-09-24T19:42:08.945502201Z,160,1,432669,T,B,64.820000000,1,26,8058566370431,0,14425,94380633,CLX5
2025-09-24T19:42:08.945899941Z,2025-09-24T19:42:08.945502201Z,160,1,432669,F,A,64.820000000,1,26,8058566370421,0,14425,94380633,CLX5
2025-09-24T19:42:08.945948069Z,2025-09-24T19:42:08.945502201Z,160,1,432669,C,A,64.820000000,1,26,8058566370421,128,18365,94380634,CLX5
2025-09-24T19:42:08.946146563Z,2025-09-24T19:42:08.945636979Z,160,1,432669,M,B,63.660000000,4,26,8058566345944,128,18321,94380647,CLX5
2025-09-24T19:42:08.946191635Z,2025-09-24T19:42:08.945637515Z,160,1,432669,M,A,64.820000000,1,26,8058566369899,128,14773,94380648,CLX5
2025-09-24T19:42:08.946255851Z,2025-09-24T19:42:08.945686013Z,160,1,432669,C,A,64.830000000,1,26,8058566370028,128,18244,94380653,CLX5
2025-09-24T19:42:08.946621346Z,2025-09-24T19:42:08.945910355Z,160,1,432669,T,N,64.820000000,1,26,0,0,15109,94380668,CLX5
2025-09-24T19:42:08.946621346Z,2025-09-24T19:42:08.945910355Z,160,1,432669,F,N,64.820000000,1,26,8058566370424,0,15109,94380668,CLX5
2025-09-24T19:42:08.946621346Z,2025-09-24T19:42:08.945910355Z,160,1,432669,C,A,64.820000000,1,26,8058566370424,128,15109,94380668,CLX5
2025-09-24T19:42:08.946802639Z,2025-09-24T19:42:08.946080229Z,160,1,432669,A,A,64.850000000,1,26,8058566370445,128,18318,94380676,CLX5
2025-09-24T19:42:08.946868184Z,2025-09-24T19:42:08.946287867Z,160,1,432669,A,A,64.830000000,1,26,8058566370447,128,14538,94380679,CLX5
2025-09-24T19:42:08.946967735Z,2025-09-24T19:42:08.946388375Z,160,1,432669,T,B,64.820000000,1,26,8058566370448,0,15578,94380685,CLX5
2025-09-24T19:42:08.946967735Z,2025-09-24T19:42:08.946388375Z,160,1,432669,F,A,64.820000000,1,26,8058566369899,0,15578,94380685,CLX5
2025-09-24T19:42:08.947008360Z,2025-09-24T19:42:08.946388375Z,160,1,432669,C,A,64.820000000,1,26,8058566369899,128,14496,94380686,CLX5
2025-09-24T19:42:08.947404396Z,2025-09-24T19:42:08.946770285Z,160,1,432669,A,B,64.820000000,1,26,8058566370456,128,18110,94380705,CLX5
2025-09-24T19:42:08.947486368Z,2025-09-24T19:42:08.946960875Z,160,1,432669,C,B,64.790000000,1,26,8058566370342,128,13650,94380710,CLX5
2025-09-24T19:42:08.947598536Z,2025-09-24T19:42:08.946973833Z,160,1,432669,A,B,64.790000000,1,26,8058566370459,128,14942,94380716,CLX5
2025-09-24T19:42:08.948128475Z,2025-09-24T19:42:08.947440335Z,160,1,432669,C,A,64.830000000,1,26,8058566370447,128,14877,94380739,CLX5
2025-09-24T19:42:08.955727706Z,2025-09-24T19:42:08.955601281Z,160,1,432669,A,A,64.830000000,1,26,8058566370474,128,18382,94380780,CLX5
2025-09-24T19:42:08.955908414Z,2025-09-24T19:42:08.955755525Z,160,1,432669,A,A,64.830000000,1,26,8058566370475,128,16063,94380784,CLX5
2025-09-24T19:42:09.124796021Z,2025-09-24T19:42:09.124667311Z,160,1,432669,C,A,64.850000000,1,26,8058566370445,128,18126,94380805,CLX5
2025-09-24T19:42:09.124953515Z,2025-09-24T19:42:09.124837933Z,160,1,432669,C,A,64.830000000,1,26,8058566370475,128,14934,94380807,CLX5
2025-09-24T19:42:09.124981284Z,2025-09-24T19:42:09.124842733Z,160,1,432669,C,A,64.830000000,1,26,8058566370474,128,15233,94380808,CLX5
2025-09-24T19:42:09.125182421Z,2025-09-24T19:42:09.124989493Z,160,1,432669,A,B,64.820000000,1,26,8058566370486,128,14250,94380813,CLX5
2025-09-24T19:42:09.141010517Z,2025-09-24T19:42:09.140871665Z,160,1,432669,A,B,64.780000000,1,26,8058566370489,128,18091,94380819,CLX5
2025-09-24T19:42:09.254798522Z,2025-09-24T19:42:09.254666849Z,160,1,432669,C,B,64.790000000,1,26,8058566370459,128,18275,94380828,CLX5
2025-09-24T19:42:09.538022392Z,2025-09-24T19:42:09.537861761Z,160,1,432669,C,B,64.770000000,1,26,8058566219742,128,22785,94380864,CLX5
2025-09-24T19:42:10.463290335Z,2025-09-24T19:42:10.462992677Z,160,1,432669,T,A,64.820000000,2,26,8058566370550,0,18899,94380948,CLX5
2025-09-24T19:42:10.463290335Z,2025-09-24T19:42:10.462992677Z,160,1,432669,F,B,64.820000000,1,26,8058566370456,0,18899,94380948,CLX5
2025-09-24T19:42:10.463290335Z,2025-09-24T19:42:10.462992677Z,160,1,432669,F,B,64.820000000,1,26,8058566370486,0,18899,94380948,CLX5
2025-09-24T19:42:10.463300126Z,2025-09-24T19:42:10.462992677Z,160,1,432669,C,B,64.820000000,1,26,8058566370456,0,14552,94380949,CLX5
2025-09-24T19:42:10.463300126Z,2025-09-24T19:42:10.462992677Z,160,1,432669,C,B,64.820000000,1,26,8058566370486,128,14552,94380949,CLX5
2025-09-24T19:42:10.464024605Z,2025-09-24T19:42:10.463883689Z,160,1,432669,A,A,64.830000000,1,26,8058566370551,128,17406,94380955,CLX5
2025-09-24T19:42:10.464053219Z,2025-09-24T19:42:10.463941343Z,160,1,432669,A,A,64.830000000,1,26,8058566370552,128,15233,94380956,CLX5
2025-09-24T19:42:10.464183841Z,2025-09-24T19:42:10.464065043Z,160,1,432669,A,A,64.830000000,1,26,8058566370553,128,18642,94380957,CLX5
2025-09-24T19:42:10.464207417Z,2025-09-24T19:42:10.464093803Z,160,1,432669,A,A,64.830000000,1,26,8058566370554,128,14735,94380958,CLX5
2025-09-24T19:42:10.470300877Z,2025-09-24T19:42:10.470195219Z,160,1,432669,A,B,63.670000000,4,26,8058566370556,128,17684,94380960,CLX5
2025-09-24T19:42:10.833954686Z,2025-09-24T19:42:10.833802943Z,160,1,432669,C,A,64.830000000,1,26,8058566370554,128,20905,94381108,CLX5
2025-09-24T19:42:10.833978186Z,2025-09-24T19:42:10.833815403Z,160,1,432669,C,A,64.830000000,1,26,8058566370553,128,14893,94381109,CLX5
2025-09-24T19:42:10.834006800Z,2025-09-24T19:42:10.833817131Z,160,1,432669,C,A,64.830000000,1,26,8058566370552,128,14794,94381110,CLX5
2025-09-24T19:42:11.090206601Z,2025-09-24T19:42:11.089817057Z,160,1,432669,A,B,64.810000000,1,26,8058566370641,128,14805,94381201,CLX5
2025-09-24T19:42:11.090294640Z,2025-09-24T19:42:11.090018205Z,160,1,432669,A,B,64.820000000,2,26,8058566370642,128,14555,94381203,CLX5
2025-09-24T19:42:11.090445744Z,2025-09-24T19:42:11.090136627Z,160,1,432669,T,A,64.820000000,2,26,8058566370644,0,17756,94381213,CLX5
2025-09-24T19:42:11.090445744Z,2025-09-24T19:42:11.090136627Z,160,1,432669,F,B,64.820000000,2,26,8058566370642,0,17756,94381213,CLX5
2025-09-24T19:42:11.090464159Z,2025-09-24T19:42:11.090136627Z,160,1,432669,C,B,64.820000000,2,26,8058566370642,128,14529,94381214,CLX5
2025-09-24T19:42:11.090497804Z,2025-09-24T19:42:11.090231491Z,160,1,432669,A,B,64.810000000,1,26,8058566370645,128,14690,94381217,CLX5
2025-09-24T19:42:11.090578355Z,2025-09-24T19:42:11.090301875Z,160,1,432669,A,B,64.820000000,1,26,8058566370647,128,16254,94381220,CLX5
2025-09-24T19:42:11.090868099Z,2025-09-24T19:42:11.090458885Z,160,1,432669,T,A,64.820000000,2,26,8058566370649,0,17345,94381227,CLX5
2025-09-24T19:42:11.090868099Z,2025-09-24T19:42:11.090458885Z,160,1,432669,F,B,64.820000000,1,26,8058566370647,0,17345,94381227,CLX5
2025-09-24T19:42:11.090876838Z,2025-09-24T19:42:11.090458885Z,160,1,432669,C,B,64.820000000,1,26,8058566370647,128,14824,94381228,CLX5
2025-09-24T19:42:11.090925143Z,2025-09-24T19:42:11.090494385Z,160,1,432669,A,A,64.870000000,1,26,8058566370651,128,17059,94381233,CLX5
2025-09-24T19:42:11.090967227Z,2025-09-24T19:42:11.090523587Z,160,1,432669,A,B,64.810000000,1,26,8058566370652,128,18103,94381235,CLX5
2025-09-24T19:42:11.091252885Z,2025-09-24T19:42:11.090870343Z,160,1,432669,A,A,64.820000000,1,26,8058566370659,128,14316,94381246,CLX5
2025-09-24T19:42:11.091581541Z,2025-09-24T19:42:11.091293205Z,160,1,432669,T,B,64.820000000,1,26,8058566370663,0,18222,94381254,CLX5
2025-09-24T19:42:11.091581541Z,2025-09-24T19:42:11.091293205Z,160,1,432669,F,A,64.820000000,1,26,8058566370659,0,18222,94381254,CLX5
2025-09-24T19:42:11.091591010Z,2025-09-24T19:42:11.091293205Z,160,1,432669,C,A,64.820000000,1,26,8058566370659,128,14533,94381255,CLX5
2025-09-24T19:42:11.091686859Z,2025-09-24T19:42:11.091401947Z,160,1,432669,M,A,64.820000000,1,26,8058566370651,128,16777,94381261,CLX5
2025-09-24T19:42:11.091805148Z,2025-09-24T19:42:11.091456877Z,160,1,432669,C,A,64.830000000,1,26,8058566370551,128,14538,94381267,CLX5
2025-09-24T19:42:11.091942144Z,2025-09-24T19:42:11.091589735Z,160,1,432669,A,B,64.790000000,1,26,8058566370670,128,15921,94381273,CLX5
2025-09-24T19:42:11.092061232Z,2025-09-24T19:42:11.091816245Z,160,1,432669,A,A,64.850000000,1,26,8058566370671,128,14344,94381281,CLX5
2025-09-24T19:42:11.142060281Z,2025-09-24T19:42:11.141889959Z,160,1,432669,A,A,64.820000000,1,26,8058566370675,128,16849,94381300,CLX5
2025-09-24T19:42:11.142208013Z,2025-09-24T19:42:11.142075865Z,160,1,432669,C,B,64.810000000,1,26,8058566369670,128,14696,94381304,CLX5
2025-09-24T19:42:11.142237134Z,2025-09-24T19:42:11.142089975Z,160,1,432669,A,B,64.800000000,1,26,8058566370676,128,14474,94381305,CLX5
2025-09-24T19:42:11.274809895Z,2025-09-24T19:42:11.274676753Z,160,1,432669,C,B,64.790000000,1,26,8058566370670,128,18334,94381318,CLX5
2025-09-24T19:42:11.387023158Z,2025-09-24T19:42:11.386878021Z,160,1,432669,C,B,64.810000000,1,26,8058566370652,128,18856,94381321,CLX5
2025-09-24T19:42:11.387049591Z,2025-09-24T19:42:11.386880633Z,160,1,432669,C,B,64.810000000,1,26,8058566370645,128,14788,94381322,CLX5
2025-09-24T19:42:11.501907013Z,2025-09-24T19:42:11.501787007Z,160,1,432669,C,B,64.810000000,1,26,8058566370641,128,15237,94381368,CLX5
2025-09-24T19:42:13.871627456Z,2025-09-24T19:42:13.871475109Z,160,1,432669,M,A,64.830000000,3,26,8058566321460,128,18157,94381463,CLX5
2025-09-24T19:42:14.325032211Z,2025-09-24T19:42:14.324862797Z,160,1,432669,A,A,64.820000000,2,26,8058566370745,128,19451,94381479,CLX5
2025-09-24T19:42:14.325710113Z,2025-09-24T19:42:14.325397591Z,160,1,432669,A,A,64.820000000,1,26,8058566370752,128,20867,94381501,CLX5
2025-09-24T19:42:14.325911226Z,2025-09-24T19:42:14.325538703Z,160,1,432669,A,A,64.820000000,1,26,8058566370754,128,16571,94381508,CLX5
2025-09-24T19:42:14.442891527Z,2025-09-24T19:42:14.442718083Z,160,1,432669,M,A,64.820000000,1,26,8058566370042,128,21875,94381538,CLX5
2025-09-24T19:42:14.549333746Z,2025-09-24T19:42:14.549192015Z,160,1,432669,A,A,64.820000000,1,26,8058566370780,128,19472,94381590,CLX5
2025-09-24T19:42:14.554319279Z,2025-09-24T19:42:14.554028435Z,160,1,432669,T,A,64.810000000,1,26,8058566370042,0,16774,94381594,CLX5
2025-09-24T19:42:14.554319279Z,2025-09-24T19:42:14.554028435Z,160,1,432669,F,A,64.810000000,1,26,8058566370042,0,16774,94381594,CLX5
2025-09-24T19:42:14.554319279Z,2025-09-24T19:42:14.554028435Z,160,1,432669,F,B,64.810000000,1,26,8058566368680,0,16774,94381594,CLX5
2025-09-24T19:42:14.554330422Z,2025-09-24T19:42:14.554028435Z,160,1,432669,M,B,64.810000000,1,26,8058566368680,0,16513,94381595,CLX5
2025-09-24T19:42:14.554330422Z,2025-09-24T19:42:14.554028435Z,160,1,432669,C,A,64.820000000,1,26,8058566370042,128,16513,94381595,CLX5
2025-09-24T19:42:14.554433513Z,2025-09-24T19:42:14.554294843Z,160,1,432669,A,A,64.820000000,2,26,8058566370782,128,19456,94381596,CLX5
2025-09-24T19:42:14.554463686Z,2025-09-24T19:42:14.554304365Z,160,1,432669,A,A,64.820000000,1,26,8058566370783,128,16171,94381597,CLX5
2025-09-24T19:42:14.554537571Z,2025-09-24T19:42:14.554370315Z,160,1,432669,C,A,64.820000000,1,26,8058566370783,128,14845,94381601,CLX5
2025-09-24T19:42:14.560133348Z,2025-09-24T19:42:14.559858777Z,160,1,432669,T,A,64.810000000,1,26,8058566370790,0,17999,94381617,CLX5
2025-09-24T19:42:14.560133348Z,2025-09-24T19:42:14.559858777Z,160,1,432669,F,B,64.810000000,1,26,8058566368680,0,17999,94381617,CLX5
2025-09-24T19:42:14.560143116Z,2025-09-24T19:42:14.559858777Z,160,1,432669,C,B,64.810000000,1,26,8058566368680,128,14961,94381618,CLX5
2025-09-24T19:42:14.564840412Z,2025-09-24T19:42:14.564582823Z,160,1,432669,T,A,64.810000000,1,26,8058566370796,0,19356,94381647,CLX5
2025-09-24T19:42:14.564840412Z,2025-09-24T19:42:14.564582823Z,160,1,432669,F,B,64.810000000,1,26,8058566368681,0,19356,94381647,CLX5
2025-09-24T19:42:14.564850195Z,2025-09-24T19:42:14.564582823Z,160,1,432669,M,B,64.810000000,1,26,8058566368681,128,14894,94381648,CLX5
2025-09-24T19:42:14.564981708Z,2025-09-24T19:42:14.564846581Z,160,1,432669,C,A,64.820000000,2,26,8058566370782,128,19505,94381649,CLX5
2025-09-24T19:42:14.565090183Z,2025-09-24T19:42:14.564898073Z,160,1,432669,A,A,64.820000000,1,26,8058566370798,128,19720,94381654,CLX5
2025-09-24T19:42:14.565139025Z,2025-09-24T19:42:14.565017531Z,160,1,432669,A,A,64.820000000,1,26,8058566370799,128,16039,94381655,CLX5
2025-09-24T19:42:14.565238959Z,2025-09-24T19:42:14.565117597Z,160,1,432669,A,A,64.820000000,1,26,8058566370800,128,17646,94381656,CLX5
2025-09-24T19:42:14.569593007Z,2025-09-24T19:42:14.569347843Z,160,1,432669,T,A,64.810000000,1,26,8058566370816,0,18138,94381701,CLX5
2025-09-24T19:42:14.569593007Z,2025-09-24T19:42:14.569347843Z,160,1,432669,F,B,64.810000000,1,26,8058566368681,0,18138,94381701,CLX5
2025-09-24T19:42:14.569606055Z,2025-09-24T19:42:14.569347843Z,160,1,432669,C,B,64.810000000,1,26,8058566368681,128,15597,94381702,CLX5
2025-09-24T19:42:14.569738927Z,2025-09-24T19:42:14.569578213Z,160,1,432669,A,A,64.820000000,1,26,8058566370818,128,16814,94381704,CLX5
2025-09-24T19:42:14.569767618Z,2025-09-24T19:42:14.569594513Z,160,1,432669,A,A,64.820000000,1,26,8058566370819,128,14397,94381705,CLX5
2025-09-24T19:42:14.574146609Z,2025-09-24T19:42:14.573900691Z,160,1,432669,T,A,64.810000000,1,26,8058566370825,0,18221,94381724,CLX5
2025-09-24T19:42:14.574146609Z,2025-09-24T19:42:14.573900691Z,160,1,432669,F,B,64.810000000,1,26,8058566368682,0,18221,94381724,CLX5
2025-09-24T19:42:14.574157168Z,2025-09-24T19:42:14.573900691Z,160,1,432669,M,B,64.810000000,1,26,8058566368682,128,15473,94381725,CLX5
2025-09-24T19:42:14.574651734Z,2025-09-24T19:42:14.574512241Z,160,1,432669,A,A,64.820000000,1,26,8058566370831,128,19756,94381739,CLX5
2025-09-24T19:42:14.574792616Z,2025-09-24T19:42:14.574671593Z,160,1,432669,C,A,64.820000000,1,26,8058566370831,128,17803,94381740,CLX5
2025-09-24T19:42:14.575066670Z,2025-09-24T19:42:14.574942245Z,160,1,432669,A,A,64.820000000,1,26,8058566370832,128,18957,94381741,CLX5
2025-09-24T19:42:14.575347675Z,2025-09-24T19:42:14.575199783Z,160,1,432669,C,A,64.820000000,1,26,8058566370832,128,15441,94381744,CLX5
2025-09-24T19:42:14.577035220Z,2025-09-24T19:42:14.576907453Z,160,1,432669,A,A,64.820000000,1,26,8058566370836,128,19471,94381750,CLX5
2025-09-24T19:42:14.578679836Z,2025-09-24T19:42:14.578536807Z,160,1,432669,A,A,64.820000000,1,26,8058566370837,128,19834,94381763,CLX5
2025-09-24T19:42:14.578803586Z,2025-09-24T19:42:14.578688615Z,160,1,432669,C,A,64.820000000,1,26,8058566370836,128,19081,94381765,CLX5
2025-09-24T19:42:14.618314997Z,2025-09-24T19:42:14.618206903Z,160,1,432669,C,A,65.700000000,6,26,8058566369757,128,18220,94381771,CLX5
2025-09-24T19:42:14.835805256Z,2025-09-24T19:42:14.835658907Z,160,1,432669,C,A,64.820000000,1,26,8058566370819,128,20315,94381808,CLX5
2025-09-24T19:42:15.811670312Z,2025-09-24T19:42:15.811529075Z,160,1,432669,C,A,64.820000000,1,26,8058566370800,128,21224,94381860,CLX5
2025-09-24T19:42:15.811832237Z,2025-09-24T19:42:15.811691173Z,160,1,432669,C,A,64.820000000,1,26,8058566370818,128,15811,94381863,CLX5
2025-09-24T19:42:15.811985783Z,2025-09-24T19:42:15.811865059Z,160,1,432669,C,A,64.820000000,1,26,8058566370799,128,16078,94381869,CLX5
2025-09-24T19:42:16.043647026Z,2025-09-24T19:42:16.043485233Z,160,1,432669,A,A,64.820000000,1,26,8058566370895,128,15983,94381917,CLX5
2025-09-24T19:42:16.043782578Z,2025-09-24T19:42:16.043667105Z,160,1,432669,C,A,64.820000000,1,26,8058566370895,128,16072,94381919,CLX5
2025-09-24T19:42:16.043838509Z,2025-09-24T19:42:16.043707769Z,160,1,432669,A,A,64.820000000,1,26,8058566370896,128,18770,94381921,CLX5
2025-09-24T19:42:16.043990942Z,2025-09-24T19:42:16.043820487Z,160,1,432669,A,A,64.820000000,1,26,8058566370897,128,14430,94381924,CLX5
2025-09-24T19:42:16.364771069Z,2025-09-24T19:42:16.364629059Z,160,1,432669,C,A,64.820000000,1,26,8058566370897,128,19283,94381937,CLX5
2025-09-24T19:42:16.364799291Z,2025-09-24T19:42:16.364639387Z,160,1,432669,C,A,64.820000000,1,26,8058566370896,128,15772,94381938,CLX5
2025-09-24T19:42:17.470953813Z,2025-09-24T19:42:17.470797845Z,160,1,432669,C,A,64.820000000,1,26,8058566370798,128,21290,94382014,CLX5
2025-09-24T19:42:18.846044281Z,2025-09-24T19:42:18.845888035Z,160,1,432669,C,B,64.750000000,1,26,8058566347345,128,18886,94382024,CLX5
2025-09-24T19:42:19.003745496Z,2025-09-24T19:42:19.003588647Z,160,1,432669,A,B,64.760000000,1,26,8058566370942,128,19658,94382025,CLX5
2025-09-24T19:42:20.213061569Z,2025-09-24T19:42:20.212884839Z,160,1,432669,A,A,64.820000000,2,26,8058566370946,128,28029,94382031,CLX5
2025-09-24T19:42:20.213099437Z,2025-09-24T19:42:20.212963941Z,160,1,432669,A,A,64.820000000,1,26,8058566370947,128,19769,94382032,CLX5
2025-09-24T19:42:20.843853259Z,2025-09-24T19:42:20.843525491Z,160,1,432669,T,A,64.810000000,1,26,8058566370837,0,20707,94382041,CLX5
2025-09-24T19:42:20.843853259Z,2025-09-24T19:42:20.843525491Z,160,1,432669,F,A,64.810000000,1,26,8058566370837,0,20707,94382041,CLX5
2025-09-24T19:42:20.843853259Z,2025-09-24T19:42:20.843525491Z,160,1,432669,F,B,64.810000000,1,26,8058566368682,0,20707,94382041,CLX5
2025-09-24T19:42:20.843868066Z,2025-09-24T19:42:20.843525491Z,160,1,432669,C,B,64.810000000,1,26,8058566368682,0,18736,94382042,CLX5
2025-09-24T19:42:20.843868066Z,2025-09-24T19:42:20.843525491Z,160,1,432669,C,A,64.820000000,1,26,8058566370837,128,18736,94382042,CLX5
2025-09-24T19:42:20.843987191Z,2025-09-24T19:42:20.843819911Z,160,1,432669,A,A,64.820000000,1,26,8058566370949,128,19133,94382044,CLX5
2025-09-24T19:42:20.844016904Z,2025-09-24T19:42:20.843822273Z,160,1,432669,A,A,64.820000000,1,26,8058566370950,128,19118,94382045,CLX5
2025-09-24T19:42:20.844074854Z,2025-09-24T19:42:20.843831085Z,160,1,432669,A,A,64.820000000,1,26,8058566370951,128,21437,94382047,CLX5
2025-09-24T19:42:20.844123105Z,2025-09-24T19:42:20.843879467Z,160,1,432669,C,A,64.820000000,1,26,8058566370951,128,18234,94382049,CLX5
2025-09-24T19:42:20.844229975Z,2025-09-24T19:42:20.844024997Z,160,1,432669,A,A,64.820000000,1,26,8058566370955,128,18513,94382053,CLX5
2025-09-24T19:42:20.849772055Z,2025-09-24T19:42:20.849500077Z,160,1,432669,T,A,64.810000000,1,26,8058566370959,0,20575,94382073,CLX5
2025-09-24T19:42:20.849772055Z,2025-09-24T19:42:20.849500077Z,160,1,432669,F,B,64.810000000,1,26,8058566368683,0,20575,94382073,CLX5
2025-09-24T19:42:20.849784381Z,2025-09-24T19:42:20.849500077Z,160,1,432669,C,B,64.810000000,1,26,8058566368683,128,17460,94382074,CLX5
2025-09-24T19:42:20.854096322Z,2025-09-24T19:42:20.853827239Z,160,1,432669,T,A,64.810000000,1,26,8058566370960,0,21809,94382084,CLX5
2025-09-24T19:42:20.854096322Z,2025-09-24T19:42:20.853827239Z,160,1,432669,F,B,64.810000000,1,26,8058566368705,0,21809,94382084,CLX5
2025-09-24T19:42:20.854113785Z,2025-09-24T19:42:20.853827239Z,160,1,432669,C,B,64.810000000,1,26,8058566368705,128,22637,94382085,CLX5
2025-09-24T19:42:20.858344153Z,2025-09-24T19:42:20.858192609Z,160,1,432669,A,A,64.820000000,1,26,8058566370963,128,23245,94382093,CLX5
2025-09-24T19:42:20.858506737Z,2025-09-24T19:42:20.858366495Z,160,1,432669,A,B,64.810000000,1,26,8058566370964,128,21968,94382094,CLX5
2025-09-24T19:42:20.864376069Z,2025-09-24T19:42:20.864238959Z,160,1,432669,C,B,64.810000000,1,26,8058566370964,128,23051,94382095,CLX5
2025-09-24T19:42:21.289434632Z,2025-09-24T19:42:21.289284933Z,160,1,432669,C,A,64.820000000,1,26,8058566370955,128,23410,94382098,CLX5
2025-09-24T19:42:21.289647150Z,2025-09-24T19:42:21.289457763Z,160,1,432669,C,A,64.820000000,1,26,8058566370950,128,22119,94382105,CLX5
2025-09-24T19:42:21.289777787Z,2025-09-24T19:42:21.289654805Z,160,1,432669,C,A,64.820000000,1,26,8058566370949,128,18003,94382107,CLX5
2025-09-24T19:42:21.573668801Z,2025-09-24T19:42:21.573507271Z,160,1,432669,A,A,64.820000000,1,26,8058566370967,128,24737,94382115,CLX5
2025-09-24T19:42:24.314711897Z,2025-09-24T19:42:24.314564801Z,160,1,432669,A,B,64.350000000,2,26,8058566370970,128,23487,94382128,CLX5
2025-09-24T19:42:25.248279064Z,2025-09-24T19:42:25.248123877Z,160,1,432669,C,A,64.820000000,2,26,8058566370946,128,22811,94382142,CLX5
2025-09-24T19:42:25.248308116Z,2025-09-24T19:42:25.248124453Z,160,1,432669,C,A,64.820000000,1,26,8058566370947,128,19061,94382143,CLX5
2025-09-24T19:42:25.248588405Z,2025-09-24T19:42:25.248445405Z,160,1,432669,A,B,64.810000000,1,26,8058566370977,128,21933,94382147,CLX5
2025-09-24T19:42:25.249449772Z,2025-09-24T19:42:25.249277073Z,160,1,432669,C,A,64.820000000,1,26,8058566370754,128,19315,94382162,CLX5
2025-09-24T19:42:25.318551452Z,2025-09-24T19:42:25.318438259Z,160,1,432669,A,A,65.700000000,6,26,8058566370999,128,22552,94382201,CLX5
2025-09-24T19:42:25.564787197Z,2025-09-24T19:42:25.564641263Z,160,1,432669,C,A,64.820000000,2,26,8058566370745,128,22482,94382211,CLX5
2025-09-24T19:42:25.565517880Z,2025-09-24T19:42:25.565379181Z,160,1,432669,A,B,64.810000000,2,26,8058566371004,128,20774,94382213,CLX5
2025-09-24T19:42:25.565545834Z,2025-09-24T19:42:25.565379701Z,160,1,432669,A,B,64.810000000,2,26,8058566371005,128,16716,94382214,CLX5
2025-09-24T19:42:25.565582873Z,2025-09-24T19:42:25.565379879Z,160,1,432669,A,B,64.810000000,2,26,8058566371006,128,20355,94382215,CLX5
2025-09-24T19:42:25.565609790Z,2025-09-24T19:42:25.565380053Z,160,1,432669,A,B,64.810000000,1,26,8058566371007,128,17260,94382216,CLX5
2025-09-24T19:42:25.567246196Z,2025-09-24T19:42:25.566933237Z,160,1,432669,T,B,64.820000000,1,26,8058566369797,0,20339,94382243,CLX5
2025-09-24T19:42:25.567246196Z,2025-09-24T19:42:25.566933237Z,160,1,432669,F,B,64.820000000,1,26,8058566369797,0,20339,94382243,CLX5
2025-09-24T19:42:25.567246196Z,2025-09-24T19:42:25.566933237Z,160,1,432669,F,A,64.820000000,1,26,8058566370651,0,20339,94382243,CLX5
2025-09-24T19:42:25.567260419Z,2025-09-24T19:42:25.566933237Z,160,1,432669,C,B,64.810000000,1,26,8058566369797,0,19283,94382244,CLX5
2025-09-24T19:42:25.567260419Z,2025-09-24T19:42:25.566933237Z,160,1,432669,C,A,64.820000000,1,26,8058566370651,128,19283,94382244,CLX5
2025-09-24T19:42:25.567584390Z,2025-09-24T19:42:25.567246815Z,160,1,432669,T,B,64.820000000,2,26,8058566371012,0,20646,94382248,CLX5
2025-09-24T19:42:25.567584390Z,2025-09-24T19:42:25.567246815Z,160,1,432669,F,A,64.820000000,1,26,8058566370675,0,20646,94382248,CLX5
2025-09-24T19:42:25.567584390Z,2025-09-24T19:42:25.567246815Z,160,1,432669,F,A,64.820000000,1,26,8058566370752,0,20646,94382248,CLX5
2025-09-24T19:42:25.567598889Z,2025-09-24T19:42:25.567246815Z,160,1,432669,C,A,64.820000000,1,26,8058566370675,0,18938,94382249,CLX5
2025-09-24T19:42:25.567598889Z,2025-09-24T19:42:25.567246815Z,160,1,432669,C,A,64.820000000,1,26,8058566370752,128,18938,94382249,CLX5
2025-09-24T19:42:25.612621279Z,2025-09-24T19:42:25.612487127Z,160,1,432669,A,B,64.810000000,1,26,8058566371028,128,20924,94382295,CLX5
2025-09-24T19:42:25.612780807Z,2025-09-24T19:42:25.612652373Z,160,1,432669,A,B,64.810000000,1,26,8058566371029,128,20527,94382296,CLX5
2025-09-24T19:42:25.613112442Z,2025-09-24T19:42:25.612801609Z,160,1,432669,T,B,64.820000000,3,26,8058566371030,0,22121,94382297,CLX5
2025-09-24T19:42:25.613112442Z,2025-09-24T19:42:25.612801609Z,160,1,432669,F,A,64.820000000,1,26,8058566370780,0,22121,94382297,CLX5
2025-09-24T19:42:25.613112442Z,2025-09-24T19:42:25.612801609Z,160,1,432669,F,A,64.820000000,1,26,8058566370963,0,22121,94382297,CLX5
2025-09-24T19:42:25.613112442Z,2025-09-24T19:42:25.612801609Z,160,1,432669,F,A,64.820000000,1,26,8058566370967,0,22121,94382297,CLX5
2025-09-24T19:42:25.613125421Z,2025-09-24T19:42:25.612801609Z,160,1,432669,C,A,64.820000000,1,26,8058566370780,0,17718,94382298,CLX5
2025-09-24T19:42:25.613125421Z,2025-09-24T19:42:25.612801609Z,160,1,432669,C,A,64.820000000,1,26,8058566370963,0,17718,94382298,CLX5
2025-09-24T19:42:25.613125421Z,2025-09-24T19:42:25.612801609Z,160,1,432669,C,A,64.820000000,1,26,8058566370967,128,17718,94382298,CLX5
2025-09-24T19:42:25.613170662Z,2025-09-24T19:42:25.612807251Z,160,1,432669,A,B,64.810000000,1,26,8058566371031,128,19649,94382301,CLX5
2025-09-24T19:42:25.613881416Z,2025-09-24T19:42:25.613281549Z,160,1,432669,C,A,64.830000000,3,26,8058566321460,128,16056,94382332,CLX5
2025-09-24T19:42:25.614221845Z,2025-09-24T19:42:25.613689837Z,160,1,432669,C,A,64.850000000,1,26,8058566370671,128,15982,94382350,CLX5
2025-09-24T19:42:25.614255236Z,2025-09-24T19:42:25.613702625Z,160,1,432669,C,B,64.780000000,1,26,8058566370489,128,18877,94382351,CLX5
2025-09-24T19:42:25.614474665Z,2025-09-24T19:42:25.613946991Z,160,1,432669,A,A,64.830000000,1,26,8058566371043,128,16495,94382361,CLX5
2025-09-24T19:42:25.620209404Z,2025-09-24T19:42:25.620024675Z,160,1,432669,A,A,64.820000000,1,26,8058566371053,128,16939,94382412,CLX5
2025-09-24T19:42:25.620364969Z,2025-09-24T19:42:25.620210177Z,160,1,432669,A,A,64.820000000,2,26,8058566371054,128,17847,94382415,CLX5
2025-09-24T19:42:25.620489886Z,2025-09-24T19:42:25.620245869Z,160,1,432669,A,B,64.810000000,1,26,8058566371056,128,14766,94382421,CLX5
2025-09-24T19:42:25.621911686Z,2025-09-24T19:42:25.621646639Z,160,1,432669,T,B,64.820000000,1,26,8058566371057,0,17072,94382424,CLX5
2025-09-24T19:42:25.621911686Z,2025-09-24T19:42:25.621646639Z,160,1,432669,F,A,64.820000000,1,26,8058566371053,0,17072,94382424,CLX5
2025-09-24T19:42:25.621920149Z,2025-09-24T19:42:25.621646639Z,160,1,432669,C,A,64.820000000,1,26,8058566371053,128,15140,94382425,CLX5
2025-09-24T19:42:25.626291768Z,2025-09-24T19:42:25.626138509Z,160,1,432669,A,A,64.820000000,1,26,8058566371061,128,17974,94382434,CLX5
2025-09-24T19:42:25.626433041Z,2025-09-24T19:42:25.626304103Z,160,1,432669,C,B,64.810000000,1,26,8058566371056,128,18438,94382437,CLX5
2025-09-24T19:42:25.659485565Z,2025-09-24T19:42:25.659345539Z,160,1,432669,A,A,64.850000000,1,26,8058566371070,128,18499,94382454,CLX5
2025-09-24T19:42:25.841042348Z,2025-09-24T19:42:25.840901941Z,160,1,432669,A,B,64.780000000,1,26,8058566371099,128,18787,94382516,CLX5
2025-09-24T19:42:26.074928715Z,2025-09-24T19:42:26.074779547Z,160,1,432669,C,B,64.810000000,1,26,8058566371031,128,19039,94382523,CLX5
2025-09-24T19:42:26.074953942Z,2025-09-24T19:42:26.074793947Z,160,1,432669,C,B,64.810000000,1,26,8058566371029,128,14555,94382524,CLX5
2025-09-24T19:42:26.075081148Z,2025-09-24T19:42:26.074964667Z,160,1,432669,C,B,64.810000000,1,26,8058566371028,128,18419,94382525,CLX5
2025-09-24T19:42:27.683121422Z,2025-09-24T19:42:27.682970211Z,160,1,432669,A,B,64.810000000,4,26,8058566371116,128,18606,94382565,CLX5
2025-09-24T19:42:29.622431351Z,2025-09-24T19:42:29.622068315Z,160,1,432669,T,A,64.810000000,4,26,8058566371127,0,25995,94382597,CLX5
2025-09-24T19:42:29.622431351Z,2025-09-24T19:42:29.622068315Z,160,1,432669,F,B,64.810000000,1,26,8058566368735,0,25995,94382597,CLX5
2025-09-24T19:42:29.622431351Z,2025-09-24T19:42:29.622068315Z,160,1,432669,F,B,64.810000000,1,26,8058566368736,0,25995,94382597,CLX5
2025-09-24T19:42:29.622431351Z,2025-09-24T19:42:29.622068315Z,160,1,432669,F,B,64.810000000,2,26,8058566369547,0,25995,94382597,CLX5
2025-09-24T19:42:29.622447263Z,2025-09-24T19:42:29.622068315Z,160,1,432669,C,B,64.810000000,1,26,8058566368735,0,19826,94382598,CLX5
2025-09-24T19:42:29.622447263Z,2025-09-24T19:42:29.622068315Z,160,1,432669,C,B,64.810000000,1,26,8058566368736,0,19826,94382598,CLX5
2025-09-24T19:42:29.622447263Z,2025-09-24T19:42:29.622068315Z,160,1,432669,C,B,64.810000000,2,26,8058566369547,128,19826,94382598,CLX5
2025-09-24T19:42:29.622533467Z,2025-09-24T19:42:29.622363903Z,160,1,432669,A,A,64.820000000,1,26,8058566371128,128,18846,94382599,CLX5
2025-09-24T19:42:29.622577217Z,2025-09-24T19:42:29.622366649Z,160,1,432669,A,A,64.820000000,1,26,8058566371129,128,18316,94382601,CLX5
2025-09-24T19:42:29.622614871Z,2025-09-24T19:42:29.622378629Z,160,1,432669,A,A,64.820000000,1,26,8058566371130,128,17017,94382602,CLX5
2025-09-24T19:42:29.622858759Z,2025-09-24T19:42:29.622431795Z,160,1,432669,A,A,64.820000000,1,26,8058566371134,128,16720,94382610,CLX5
2025-09-24T19:42:29.622897499Z,2025-09-24T19:42:29.622447343Z,160,1,432669,A,A,64.820000000,2,26,8058566371135,128,19388,94382611,CLX5
2025-09-24T19:42:29.623073104Z,2025-09-24T19:42:29.622497971Z,160,1,432669,A,B,64.810000000,1,26,8058566371137,128,15284,94382617,CLX5
2025-09-24T19:42:29.623162064Z,2025-09-24T19:42:29.622555895Z,160,1,432669,A,A,64.820000000,1,26,8058566371140,128,16277,94382621,CLX5
2025-09-24T19:42:29.623195333Z,2025-09-24T19:42:29.622581209Z,160,1,432669,C,A,64.820000000,1,26,8058566371130,128,17958,94382622,CLX5
2025-09-24T19:42:29.623227909Z,2025-09-24T19:42:29.622716035Z,160,1,432669,C,A,64.820000000,2,26,8058566371135,128,16236,94382623,CLX5
2025-09-24T19:42:29.623602727Z,2025-09-24T19:42:29.623097965Z,160,1,432669,C,A,64.820000000,1,26,8058566371134,128,19657,94382636,CLX5
2025-09-24T19:42:32.504650277Z,2025-09-24T19:42:32.504308487Z,160,1,432669,C,B,64.780000000,1,26,8058566368731,128,17477,94382690,CLX5
2025-09-24T19:42:32.504682608Z,2025-09-24T19:42:32.504308633Z,160,1,432669,C,B,64.770000000,1,26,8058566368670,128,20927,94382691,CLX5
2025-09-24T19:42:32.504739560Z,2025-09-24T19:42:32.504309533Z,160,1,432669,C,B,64.780000000,1,26,8058566371099,128,16707,94382693,CLX5
2025-09-24T19:42:32.504798616Z,2025-09-24T19:42:32.504309839Z,160,1,432669,C,B,64.790000000,2,26,8058566368882,128,16417,94382695,CLX5
2025-09-24T19:42:32.504942877Z,2025-09-24T19:42:32.504311241Z,160,1,432669,C,B,64.720000000,2,26,8058566331591,128,20358,94382700,CLX5
2025-09-24T19:42:32.505024550Z,2025-09-24T19:42:32.504311539Z,160,1,432669,C,B,64.780000000,2,26,8058566367628,128,16897,94382703,CLX5
2025-09-24T19:42:32.505166023Z,2025-09-24T19:42:32.504343401Z,160,1,432669,A,A,64.820000000,1,26,8058566371156,128,22909,94382707,CLX5
2025-09-24T19:42:32.505209513Z,2025-09-24T19:42:32.504388575Z,160,1,432669,A,A,64.820000000,3,26,8058566371158,128,16480,94382709,CLX5
2025-09-24T19:42:32.505480864Z,2025-09-24T19:42:32.504468399Z,160,1,432669,A,A,64.820000000,2,26,8058566371162,128,19485,94382720,CLX5
2025-09-24T19:42:32.505551792Z,2025-09-24T19:42:32.504468755Z,160,1,432669,A,A,64.820000000,1,26,8058566371164,128,14920,94382722,CLX5
2025-09-24T19:42:32.505615464Z,2025-09-24T19:42:32.504469731Z,160,1,432669,A,A,64.820000000,2,26,8058566371166,128,15748,94382725,CLX5
2025-09-24T19:42:32.505727540Z,2025-09-24T19:42:32.504493865Z,160,1,432669,C,B,64.810000000,2,26,8058566371005,128,14121,94382730,CLX5
2025-09-24T19:42:32.505758496Z,2025-09-24T19:42:32.504494017Z,160,1,432669,C,B,64.810000000,1,26,8058566371007,128,15068,94382731,CLX5
2025-09-24T19:42:32.505792886Z,2025-09-24T19:42:32.504507053Z,160,1,432669,C,B,64.810000000,2,26,8058566371004,128,18957,94382732,CLX5
2025-09-24T19:42:32.505821423Z,2025-09-24T19:42:32.504507225Z,160,1,432669,A,A,64.820000000,2,26,8058566371167,128,15869,94382733,CLX5
2025-09-24T19:42:32.505850874Z,2025-09-24T19:42:32.504507571Z,160,1,432669,A,A,64.820000000,2,26,8058566371168,128,16229,94382734,CLX5
2025-09-24T19:42:32.505933653Z,2025-09-24T19:42:32.504520551Z,160,1,432669,C,B,64.810000000,2,26,8058566371006,128,16163,94382737,CLX5
2025-09-24T19:42:32.506180153Z,2025-09-24T19:42:32.505160919Z,160,1,432669,C,A,64.820000000,1,26,8058566371156,128,14381,94382749,CLX5
2025-09-24T19:42:32.506214941Z,2025-09-24T19:42:32.505182633Z,160,1,432669,C,A,64.820000000,2,26,8058566371166,128,19275,94382750,CLX5
2025-09-24T19:42:32.506757843Z,2025-09-24T19:42:32.505733669Z,160,1,432669,A,A,64.820000000,1,26,8058566371179,128,15444,94382782,CLX5
2025-09-24T19:42:32.506911703Z,2025-09-24T19:42:32.505825977Z,160,1,432669,C,A,64.820000000,2,26,8058566371168,128,15700,94382787,CLX5
2025-09-24T19:42:32.524918871Z,2025-09-24T19:42:32.524786889Z,160,1,432669,A,B,64.770000000,1,26,8058566371203,128,17953,94382877,CLX5
2025-09-24T19:42:32.541309813Z,2025-09-24T19:42:32.541174767Z,160,1,432669,A,B,64.780000000,1,26,8058566371213,128,18964,94382892,CLX5
2025-09-24T19:42:32.574079564Z,2025-09-24T19:42:32.573939715Z,160,1,432669,A,B,64.790000000,2,26,8058566371218,128,17936,94382897,CLX5
2025-09-24T19:42:32.574103893Z,2025-09-24T19:42:32.573943995Z,160,1,432669,A,B,64.780000000,2,26,8058566371219,128,14522,94382898,CLX5
2025-09-24T19:42:34.140542275Z,2025-09-24T19:42:34.140395501Z,160,1,432669,C,A,64.820000000,2,26,8058566371167,128,19369,94382944,CLX5
2025-09-24T19:42:34.140699737Z,2025-09-24T19:42:34.140556081Z,160,1,432669,A,B,64.780000000,1,26,8058566371248,128,14561,94382948,CLX5
2025-09-24T19:42:39.256976958Z,2025-09-24T19:42:39.256801885Z,160,1,432669,A,B,64.810000000,2,26,8058566371324,128,19469,94383112,CLX5
2025-09-24T19:42:42.232526020Z,2025-09-24T19:42:42.232266533Z,160,1,432669,A,A,64.820000000,1,26,8058566371341,128,19280,94383147,CLX5
2025-09-24T19:42:42.232567390Z,2025-09-24T19:42:42.232275077Z,160,1,432669,C,B,64.810000000,1,26,8058566371137,128,22393,94383148,CLX5
2025-09-24T19:42:42.232669790Z,2025-09-24T19:42:42.232508539Z,160,1,432669,A,B,64.810000000,1,26,8058566371343,128,21987,94383152,CLX5
2025-09-24T19:42:42.232715100Z,2025-09-24T19:42:42.232571781Z,160,1,432669,C,A,64.820000000,1,26,8058566371341,128,19098,94383155,CLX5
2025-09-24T19:42:42.232776897Z,2025-09-24T19:42:42.232574259Z,160,1,432669,C,B,64.810000000,1,26,8058566371343,128,27053,94383157,CLX5
2025-09-24T19:42:42.233279665Z,2025-09-24T19:42:42.232785583Z,160,1,432669,A,B,64.810000000,1,26,8058566371349,128,16754,94383170,CLX5
2025-09-24T19:42:42.318750520Z,2025-09-24T19:42:42.318642369Z,160,1,432669,C,A,65.700000000,6,26,8058566370999,128,18932,94383177,CLX5
2025-09-24T19:42:50.970582179Z,2025-09-24T19:42:50.970411487Z,160,1,432669,M,A,64.890000000,3,26,8058566144143,128,20709,94383331,CLX5
2025-09-24T19:42:51.361883335Z,2025-09-24T19:42:51.361548493Z,160,1,432669,T,A,64.810000000,1,26,8058566371404,0,19815,94383332,CLX5
2025-09-24T19:42:51.361883335Z,2025-09-24T19:42:51.361548493Z,160,1,432669,F,B,64.810000000,1,26,8058566369603,0,19815,94383332,CLX5
2025-09-24T19:42:51.361893073Z,2025-09-24T19:42:51.361548493Z,160,1,432669,C,B,64.810000000,1,26,8058566369603,128,15160,94383333,CLX5
2025-09-24T19:42:51.362079633Z,2025-09-24T19:42:51.361882539Z,160,1,432669,A,A,64.820000000,1,26,8058566371406,128,15774,94383336,CLX5
2025-09-24T19:42:51.362117747Z,2025-09-24T19:42:51.361886187Z,160,1,432669,C,B,64.810000000,1,26,8058566371349,128,18669,94383337,CLX5
2025-09-24T19:42:51.362184099Z,2025-09-24T19:42:51.362041699Z,160,1,432669,C,A,64.820000000,1,26,8058566371406,128,15538,94383341,CLX5
2025-09-24T19:42:51.362268290Z,2025-09-24T19:42:51.362098663Z,160,1,432669,A,B,64.810000000,1,26,8058566371408,128,14746,94383348,CLX5
2025-09-24T19:42:51.724876981Z,2025-09-24T19:42:51.724563825Z,160,1,432669,T,A,64.810000000,1,26,8058566371415,0,19572,94383363,CLX5
2025-09-24T19:42:51.724876981Z,2025-09-24T19:42:51.724563825Z,160,1,432669,F,B,64.810000000,1,26,8058566369607,0,19572,94383363,CLX5
2025-09-24T19:42:51.724886864Z,2025-09-24T19:42:51.724563825Z,160,1,432669,C,B,64.810000000,1,26,8058566369607,128,14884,94383364,CLX5
2025-09-24T19:42:51.725022356Z,2025-09-24T19:42:51.724873873Z,160,1,432669,A,A,64.820000000,1,26,8058566371416,128,15416,94383366,CLX5
2025-09-24T19:42:51.725052575Z,2025-09-24T19:42:51.724877365Z,160,1,432669,A,A,64.820000000,1,26,8058566371417,128,15503,94383367,CLX5
2025-09-24T19:42:51.725091741Z,2025-09-24T19:42:51.724957965Z,160,1,432669,C,A,64.820000000,1,26,8058566371416,128,18428,94383369,CLX5
2025-09-24T19:42:51.725123327Z,2025-09-24T19:42:51.724964857Z,160,1,432669,C,B,64.810000000,1,26,8058566371408,128,15257,94383370,CLX5
2025-09-24T19:42:51.725250064Z,2025-09-24T19:42:51.725113361Z,160,1,432669,C,A,64.820000000,1,26,8058566371417,128,14455,94383378,CLX5
2025-09-24T19:42:52.088806356Z,2025-09-24T19:42:52.088516897Z,160,1,432669,T,A,64.810000000,1,26,8058566371420,0,17717,94383388,CLX5
2025-09-24T19:42:52.088806356Z,2025-09-24T19:42:52.088516897Z,160,1,432669,F,B,64.810000000,1,26,8058566369621,0,17717,94383388,CLX5
2025-09-24T19:42:52.088816792Z,2025-09-24T19:42:52.088516897Z,160,1,432669,C,B,64.810000000,1,26,8058566369621,128,15621,94383389,CLX5
2025-09-24T19:42:52.088925804Z,2025-09-24T19:42:52.088785203Z,160,1,432669,A,A,64.820000000,2,26,8058566371421,128,18954,94383390,CLX5
2025-09-24T19:42:52.088951592Z,2025-09-24T19:42:52.088806745Z,160,1,432669,A,A,64.820000000,1,26,8058566371422,128,15078,94383391,CLX5
2025-09-24T19:42:52.089100737Z,2025-09-24T19:42:52.088970823Z,160,1,432669,A,A,64.820000000,1,26,8058566371423,128,18848,94383392,CLX5
2025-09-24T19:42:52.451890073Z,2025-09-24T19:42:52.451612515Z,160,1,432669,T,A,64.810000000,1,26,8058566371426,0,18066,94383402,CLX5
2025-09-24T19:42:52.451890073Z,2025-09-24T19:42:52.451612515Z,160,1,432669,F,B,64.810000000,1,26,8058566369628,0,18066,94383402,CLX5
2025-09-24T19:42:52.451902199Z,2025-09-24T19:42:52.451612515Z,160,1,432669,M,B,64.810000000,1,26,8058566369628,128,16578,94383403,CLX5
2025-09-24T19:42:52.452231891Z,2025-09-24T19:42:52.451923963Z,160,1,432669,C,B,64.810000000,3,26,8058566369689,128,15539,94383411,CLX5
2025-09-24T19:42:52.452268200Z,2025-09-24T19:42:52.452043499Z,160,1,432669,M,A,64.820000000,1,26,8058566369708,128,16598,94383412,CLX5
2025-09-24T19:42:52.452295217Z,2025-09-24T19:42:52.452140549Z,160,1,432669,A,A,64.860000000,2,26,8058566371432,128,17989,94383413,CLX5
2025-09-24T19:42:52.704421722Z,2025-09-24T19:42:52.704253029Z,160,1,432669,A,B,64.810000000,1,26,8058566371442,128,19345,94383455,CLX5
2025-09-24T19:42:52.704588093Z,2025-09-24T19:42:52.704437801Z,160,1,432669,C,A,64.820000000,1,26,8058566371422,128,16212,94383457,CLX5
2025-09-24T19:42:52.815025846Z,2025-09-24T19:42:52.814734093Z,160,1,432669,T,A,64.810000000,1,26,8058566371444,0,19013,94383459,CLX5
2025-09-24T19:42:52.815025846Z,2025-09-24T19:42:52.814734093Z,160,1,432669,F,B,64.810000000,1,26,8058566369628,0,19013,94383459,CLX5
2025-09-24T19:42:52.815036421Z,2025-09-24T19:42:52.814734093Z,160,1,432669,C,B,64.810000000,1,26,8058566369628,128,15547,94383460,CLX5
2025-09-24T19:42:52.825594400Z,2025-09-24T19:42:52.825440193Z,160,1,432669,A,B,64.810000000,1,26,8058566371445,128,19242,94383469,CLX5
2025-09-24T19:42:52.825768734Z,2025-09-24T19:42:52.825633355Z,160,1,432669,A,A,64.820000000,1,26,8058566371446,128,20053,94383470,CLX5
2025-09-24T19:42:52.825923171Z,2025-09-24T19:42:52.825800293Z,160,1,432669,A,A,64.820000000,1,26,8058566371447,128,18183,94383471,CLX5
2025-09-24T19:42:52.826078368Z,2025-09-24T19:42:52.825959011Z,160,1,432669,A,A,64.820000000,1,26,8058566371448,128,14993,94383473,CLX5
2025-09-24T19:42:53.178150515Z,2025-09-24T19:42:53.177834091Z,160,1,432669,T,A,64.810000000,1,26,8058566371451,0,20470,94383485,CLX5
2025-09-24T19:42:53.178150515Z,2025-09-24T19:42:53.177834091Z,160,1,432669,F,B,64.810000000,1,26,8058566368370,0,20470,94383485,CLX5
2025-09-24T19:42:53.178161650Z,2025-09-24T19:42:53.177834091Z,160,1,432669,C,B,64.810000000,1,26,8058566368370,128,16394,94383486,CLX5
2025-09-24T19:42:53.178338181Z,2025-09-24T19:42:53.178194497Z,160,1,432669,A,B,64.800000000,1,26,8058566371452,128,17241,94383487,CLX5
2025-09-24T19:42:53.541198771Z,2025-09-24T19:42:53.540934129Z,160,1,432669,T,A,64.810000000,1,26,8058566371455,0,19217,94383490,CLX5
2025-09-24T19:42:53.541198771Z,2025-09-24T19:42:53.540934129Z,160,1,432669,F,B,64.810000000,1,26,8058566370977,0,19217,94383490,CLX5
2025-09-24T19:42:53.541210006Z,2025-09-24T19:42:53.540934129Z,160,1,432669,C,B,64.810000000,1,26,8058566370977,128,16238,94383491,CLX5
2025-09-24T19:42:53.904333076Z,2025-09-24T19:42:53.904073695Z,160,1,432669,T,A,64.810000000,1,26,8058566371457,0,22952,94383493,CLX5
2025-09-24T19:42:53.904333076Z,2025-09-24T19:42:53.904073695Z,160,1,432669,F,B,64.810000000,1,26,8058566371116,0,22952,94383493,CLX5
2025-09-24T19:42:53.904346761Z,2025-09-24T19:42:53.904073695Z,160,1,432669,M,B,64.810000000,3,26,8058566371116,128,18796,94383494,CLX5
2025-09-24T19:42:54.267395693Z,2025-09-24T19:42:54.267138541Z,160,1,432669,T,A,64.810000000,1,26,8058566371460,0,17790,94383510,CLX5
2025-09-24T19:42:54.267395693Z,2025-09-24T19:42:54.267138541Z,160,1,432669,F,B,64.810000000,1,26,8058566371116,0,17790,94383510,CLX5
2025-09-24T19:42:54.267407873Z,2025-09-24T19:42:54.267138541Z,160,1,432669,M,B,64.810000000,2,26,8058566371116,128,17515,94383511,CLX5
2025-09-24T19:42:54.274202504Z,2025-09-24T19:42:54.273859859Z,160,1,432669,T,A,64.810000000,6,26,8058566371461,0,17987,94383519,CLX5
2025-09-24T19:42:54.274202504Z,2025-09-24T19:42:54.273859859Z,160,1,432669,F,B,64.810000000,2,26,8058566371116,0,17987,94383519,CLX5
2025-09-24T19:42:54.274202504Z,2025-09-24T19:42:54.273859859Z,160,1,432669,F,B,64.810000000,2,26,8058566371324,0,17987,94383519,CLX5
2025-09-24T19:42:54.274202504Z,2025-09-24T19:42:54.273859859Z,160,1,432669,F,B,64.810000000,1,26,8058566371442,0,17987,94383519,CLX5
2025-09-24T19:42:54.274202504Z,2025-09-24T19:42:54.273859859Z,160,1,432669,F,B,64.810000000,1,26,8058566371445,0,17987,94383519,CLX5
2025-09-24T19:42:54.274212495Z,2025-09-24T19:42:54.273859859Z,160,1,432669,C,B,64.810000000,2,26,8058566371116,0,14570,94383520,CLX5
2025-09-24T19:42:54.274212495Z,2025-09-24T19:42:54.273859859Z,160,1,432669,C,B,64.810000000,2,26,8058566371324,0,14570,94383520,CLX5
2025-09-24T19:42:54.274212495Z,2025-09-24T19:42:54.273859859Z,160,1,432669,C,B,64.810000000,1,26,8058566371442,0,14570,94383520,CLX5
2025-09-24T19:42:54.274212495Z,2025-09-24T19:42:54.273859859Z,160,1,432669,C,B,64.810000000,1,26,8058566371445,128,14570,94383520,CLX5
2025-09-24T19:42:54.275048826Z,2025-09-24T19:42:54.274202831Z,160,1,432669,A,A,64.820000000,1,26,8058566371468,128,15020,94383544,CLX5
2025-09-24T19:42:54.275085151Z,2025-09-24T19:42:54.274203007Z,160,1,432669,A,A,64.820000000,2,26,8058566371469,128,18777,94383545,CLX5
2025-09-24T19:42:54.275238213Z,2025-09-24T19:42:54.274206269Z,160,1,432669,A,A,64.820000000,1,26,8058566371471,128,15280,94383550,CLX5
2025-09-24T19:42:54.275478031Z,2025-09-24T19:42:54.274227809Z,160,1,432669,A,A,64.820000000,1,26,8058566371475,128,15379,94383558,CLX5
2025-09-24T19:42:54.275506116Z,2025-09-24T19:42:54.274253691Z,160,1,432669,A,A,64.820000000,3,26,8058566371476,128,15053,94383559,CLX5
2025-09-24T19:42:54.275522765Z,2025-09-24T19:42:54.274270451Z,160,1,432669,T,A,64.810000000,2,26,8058566371477,128,15005,94383560,CLX5
2025-09-24T19:42:54.275691601Z,2025-09-24T19:42:54.274276191Z,160,1,432669,M,A,64.830000000,1,26,8058566173085,128,16964,94383565,CLX5
2025-09-24T19:42:54.275715869Z,2025-09-24T19:42:54.274339931Z,160,1,432669,A,A,64.820000000,2,26,8058566371478,128,14654,94383566,CLX5
2025-09-24T19:42:54.275902106Z,2025-09-24T19:42:54.274760259Z,160,1,432669,C,A,64.820000000,2,26,8058566371469,128,15277,94383574,CLX5
2025-09-24T19:42:54.275971461Z,2025-09-24T19:42:54.274825421Z,160,1,432669,C,B,64.780000000,1,26,8058566371248,128,17981,94383576,CLX5
2025-09-24T19:42:54.276041637Z,2025-09-24T19:42:54.274833505Z,160,1,432669,C,B,64.800000000,1,26,8058566370676,128,14490,94383579,CLX5
2025-09-24T19:42:54.276614735Z,2025-09-24T19:42:54.275154667Z,160,1,432669,C,A,64.820000000,1,26,8058566371471,128,15292,94383605,CLX5
2025-09-24T19:42:54.276642236Z,2025-09-24T19:42:54.275159331Z,160,1,432669,C,A,64.820000000,1,26,8058566371475,128,15360,94383606,CLX5
2025-09-24T19:42:54.276672915Z,2025-09-24T19:42:54.275186845Z,160,1,432669,A,B,64.800000000,2,26,8058566371490,128,14852,94383607,CLX5
2025-09-24T19:42:54.276993953Z,2025-09-24T19:42:54.275515495Z,160,1,432669,C,B,64.800000000,2,26,8058566371490,128,14581,94383617,CLX5
2025-09-24T19:42:54.277376014Z,2025-09-24T19:42:54.275686925Z,160,1,432669,A,A,64.820000000,1,26,8058566371502,128,13984,94383632,CLX5
2025-09-24T19:42:54.277409643Z,2025-09-24T19:42:54.275719583Z,160,1,432669,C,B,64.790000000,2,26,8058566371218,128,14562,94383633,CLX5
2025-09-24T19:42:54.277462386Z,2025-09-24T19:42:54.275726265Z,160,1,432669,T,A,64.810000000,1,26,8058566371504,128,14565,94383635,CLX5
2025-09-24T19:42:54.277760884Z,2025-09-24T19:42:54.275891263Z,160,1,432669,M,A,64.830000000,3,26,8058566363632,128,18754,94383646,CLX5
2025-09-24T19:42:54.277862047Z,2025-09-24T19:42:54.275935997Z,160,1,432669,M,B,63.650000000,3,26,8058566319508,128,17981,94383649,CLX5
2025-09-24T19:42:54.278092596Z,2025-09-24T19:42:54.276124321Z,160,1,432669,M,A,64.930000000,1,26,8058565075241,128,14688,94383662,CLX5
2025-09-24T19:42:54.278456102Z,2025-09-24T19:42:54.276252131Z,160,1,432669,C,A,64.820000000,1,26,8058566371502,128,18915,94383691,CLX5
2025-09-24T19:42:54.279550813Z,2025-09-24T19:42:54.276865753Z,160,1,432669,A,A,64.820000000,1,26,8058566371529,128,18069,94383751,CLX5
2025-09-24T19:42:54.280582099Z,2025-09-24T19:42:54.277422911Z,160,1,432669,A,B,64.810000000,1,26,8058566371537,128,18082,94383798,CLX5
2025-09-24T19:42:54.280604293Z,2025-09-24T19:42:54.277426215Z,160,1,432669,A,B,64.810000000,1,26,8058566371538,128,15082,94383800,CLX5
2025-09-24T19:42:54.280974665Z,2025-09-24T19:42:54.277606821Z,160,1,432669,C,A,64.830000000,3,26,8058566363632,128,14768,94383818,CLX5
2025-09-24T19:42:54.281427193Z,2025-09-24T19:42:54.278058963Z,160,1,432669,C,A,64.820000000,1,26,8058566371529,128,15601,94383838,CLX5
2025-09-24T19:42:54.282086187Z,2025-09-24T19:42:54.279042187Z,160,1,432669,A,B,64.800000000,2,26,8058566371555,128,17787,94383877,CLX5
2025-09-24T19:42:54.282727456Z,2025-09-24T19:42:54.280617939Z,160,1,432669,C,A,64.820000000,1,26,8058566371468,128,15066,94383910,CLX5
2025-09-24T19:42:54.282906014Z,2025-09-24T19:42:54.281172833Z,160,1,432669,A,B,64.810000000,2,26,8058566371569,128,14277,94383918,CLX5
2025-09-24T19:42:54.283417483Z,2025-09-24T19:42:54.282387851Z,160,1,432669,T,A,64.810000000,1,26,8058566371061,0,14587,94383950,CLX5
2025-09-24T19:42:54.283417483Z,2025-09-24T19:42:54.282387851Z,160,1,432669,F,A,64.810000000,1,26,8058566371061,0,14587,94383950,CLX5
2025-09-24T19:42:54.283417483Z,2025-09-24T19:42:54.282387851Z,160,1,432669,F,B,64.810000000,1,26,8058566371537,0,14587,94383950,CLX5
2025-09-24T19:42:54.283417483Z,2025-09-24T19:42:54.282387851Z,160,1,432669,C,B,64.810000000,1,26,8058566371537,0,14587,94383950,CLX5
2025-09-24T19:42:54.283417483Z,2025-09-24T19:42:54.282387851Z,160,1,432669,C,A,64.820000000,1,26,8058566371061,128,14587,94383950,CLX5
2025-09-24T19:42:54.283587202Z,2025-09-24T19:42:54.282488379Z,160,1,432669,A,B,64.780000000,1,26,8058566371575,128,18181,94383955,CLX5
2025-09-24T19:42:54.284377357Z,2025-09-24T19:42:54.283015165Z,160,1,432669,A,B,64.810000000,1,26,8058566371585,128,20574,94383991,CLX5
2025-09-24T19:42:54.284502833Z,2025-09-24T19:42:54.283039203Z,160,1,432669,C,A,64.820000000,2,26,8058566371478,128,16183,94383996,CLX5
2025-09-24T19:42:54.284796140Z,2025-09-24T19:42:54.283151057Z,160,1,432669,M,A,64.940000000,1,26,8058565075241,128,14676,94384008,CLX5
2025-09-24T19:42:54.284796140Z,2025-09-24T19:42:54.283154071Z,160,1,432669,A,B,64.810000000,2,26,8058566371593,128,14676,94384008,CLX5
2025-09-24T19:42:54.285121455Z,2025-09-24T19:42:54.283429079Z,160,1,432669,A,B,64.810000000,1,26,8058566371603,128,18091,94384021,CLX5
2025-09-24T19:42:54.285154431Z,2025-09-24T19:42:54.283432631Z,160,1,432669,A,B,64.810000000,1,26,8058566371604,128,14578,94384022,CLX5
2025-09-24T19:42:54.285903699Z,2025-09-24T19:42:54.283831303Z,160,1,432669,A,B,64.810000000,2,26,8058566371614,128,15970,94384049,CLX5
2025-09-24T19:42:54.285939755Z,2025-09-24T19:42:54.283831481Z,160,1,432669,A,B,64.810000000,1,26,8058566371615,128,18928,94384050,CLX5
2025-09-24T19:42:54.286141690Z,2025-09-24T19:42:54.283962491Z,160,1,432669,A,B,64.810000000,1,26,8058566371616,128,14932,94384056,CLX5
2025-09-24T19:42:54.286337227Z,2025-09-24T19:42:54.284231009Z,160,1,432669,A,B,64.810000000,2,26,8058566371620,128,14189,94384066,CLX5
2025-09-24T19:42:54.287738847Z,2025-09-24T19:42:54.286074993Z,160,1,432669,M,B,64.800000000,4,26,8058566345944,128,14493,94384132,CLX5
2025-09-24T19:42:54.287823384Z,2025-09-24T19:42:54.286150463Z,160,1,432669,A,A,64.820000000,1,26,8058566371639,128,18209,94384134,CLX5
2025-09-24T19:42:54.288286317Z,2025-09-24T19:42:54.286317131Z,160,1,432669,C,A,64.820000000,1,26,8058566371639,128,18449,94384158,CLX5
2025-09-24T19:42:54.288488014Z,2025-09-24T19:42:54.286528399Z,160,1,432669,A,A,64.820000000,1,26,8058566371652,128,18263,94384168,CLX5
2025-09-24T19:42:54.289182542Z,2025-09-24T19:42:54.287535413Z,160,1,432669,C,B,64.810000000,1,26,8058566371616,128,14674,94384201,CLX5
2025-09-24T19:42:54.289310123Z,2025-09-24T19:42:54.287831505Z,160,1,432669,C,A,64.820000000,1,26,8058566371652,128,14981,94384206,CLX5
2025-09-24T19:42:54.289653884Z,2025-09-24T19:42:54.288294395Z,160,1,432669,A,A,64.820000000,1,26,8058566371662,128,16194,94384223,CLX5
2025-09-24T19:42:54.289733767Z,2025-09-24T19:42:54.288382501Z,160,1,432669,A,A,64.820000000,1,26,8058566371664,128,18009,94384226,CLX5
2025-09-24T19:42:54.289952652Z,2025-09-24T19:42:54.288545693Z,160,1,432669,C,A,64.820000000,1,26,8058566371662,128,18045,94384239,CLX5
2025-09-24T19:42:54.289978632Z,2025-09-24T19:42:54.288546865Z,160,1,432669,C,A,64.820000000,1,26,8058566371423,128,15326,94384240,CLX5
2025-09-24T19:42:54.296423426Z,2025-09-24T19:42:54.296294527Z,160,1,432669,C,A,64.820000000,1,26,8058566371448,128,18382,94384357,CLX5
2025-09-24T19:42:54.296587654Z,2025-09-24T19:42:54.296446873Z,160,1,432669,A,B,64.800000000,1,26,8058566371714,128,18023,94384358,CLX5
2025-09-24T19:42:54.313075612Z,2025-09-24T19:42:54.312944975Z,160,1,432669,A,B,64.790000000,2,26,8058566371722,128,18206,94384373,CLX5
2025-09-24T19:42:54.318829681Z,2025-09-24T19:42:54.318728315Z,160,1,432669,A,A,65.700000000,6,26,8058566371724,128,14359,94384377,CLX5
2025-09-24T19:42:54.630542920Z,2025-09-24T19:42:54.630232357Z,160,1,432669,T,A,64.810000000,1,26,8058566371827,0,17656,94384579,CLX5
2025-09-24T19:42:54.630542920Z,2025-09-24T19:42:54.630232357Z,160,1,432669,F,B,64.810000000,1,26,8058566371538,0,17656,94384579,CLX5
2025-09-24T19:42:54.630555199Z,2025-09-24T19:42:54.630232357Z,160,1,432669,C,B,64.810000000,1,26,8058566371538,128,16831,94384580,CLX5
2025-09-24T19:42:54.993593374Z,2025-09-24T19:42:54.993325525Z,160,1,432669,T,A,64.810000000,1,26,8058566371850,0,18629,94384615,CLX5
2025-09-24T19:42:54.993593374Z,2025-09-24T19:42:54.993325525Z,160,1,432669,F,B,64.810000000,1,26,8058566371569,0,18629,94384615,CLX5
2025-09-24T19:42:54.993604517Z,2025-09-24T19:42:54.993325525Z,160,1,432669,M,B,64.810000000,1,26,8058566371569,128,16248,94384616,CLX5
2025-09-24T19:42:56.186690891Z,2025-09-24T19:42:56.186539275Z,160,1,432669,C,A,64.820000000,1,26,8058566371447,128,18278,94384773,CLX5
2025-09-24T19:42:56.186719252Z,2025-09-24T19:42:56.186553693Z,160,1,432669,C,A,64.820000000,1,26,8058566371446,128,15345,94384774,CLX5
2025-09-24T19:43:00.021458946Z,2025-09-24T19:43:00.021333429Z,160,1,432669,A,B,64.710000000,1,26,8058566371963,128,21399,94384932,CLX5
2025-09-24T19:43:00.393634778Z,2025-09-24T19:43:00.393332979Z,160,1,432669,C,B,64.810000000,2,26,8058566371593,128,15714,94384942,CLX5
2025-09-24T19:43:00.418579809Z,2025-09-24T19:43:00.418470315Z,160,1,432669,C,A,65.700000000,6,26,8058566371724,128,18136,94384959,CLX5
2025-09-24T19:43:00.680156997Z,2025-09-24T19:43:00.679941555Z,160,1,432669,C,A,64.820000000,2,26,8058566371421,128,20109,94384968,CLX5
2025-09-24T19:43:00.680393682Z,2025-09-24T19:43:00.680100755Z,160,1,432669,A,B,64.810000000,2,26,8058566371980,128,16044,94384976,CLX5
2025-09-24T19:43:00.718551128Z,2025-09-24T19:43:00.718439295Z,160,1,432669,A,A,65.700000000,6,26,8058566371985,128,18622,94385014,CLX5
2025-09-24T19:43:01.612119480Z,2025-09-24T19:43:01.611976547Z,160,1,432669,C,B,64.780000000,1,26,8058566371213,128,18269,94385043,CLX5
2025-09-24T19:43:02.101948453Z,2025-09-24T19:43:02.101549253Z,160,1,432669,A,A,64.820000000,1,26,8058566372003,128,15586,94385071,CLX5
2025-09-24T19:43:02.103117318Z,2025-09-24T19:43:02.101709527Z,160,1,432669,C,B,64.810000000,2,26,8058566371980,128,16030,94385158,CLX5
2025-09-24T19:43:02.133317149Z,2025-09-24T19:43:02.133094323Z,160,1,432669,C,B,64.810000000,2,26,8058566371614,128,18652,94385467,CLX5
2025-09-24T19:43:02.133351692Z,2025-09-24T19:43:02.133094479Z,160,1,432669,C,B,64.810000000,1,26,8058566371615,128,16283,94385468,CLX5
2025-09-24T19:43:03.915443514Z,2025-09-24T19:43:03.915289407Z,160,1,432669,C,A,65.090000000,1,26,8058566370025,128,19318,94385795,CLX5
2025-09-24T19:43:04.009308918Z,2025-09-24T19:43:04.009125513Z,160,1,432669,A,A,65.080000000,1,26,8058566372242,128,19203,94385796,CLX5
2025-09-24T19:43:04.353561768Z,2025-09-24T19:43:04.353303081Z,160,1,432669,A,A,65.080000000,1,26,8058566372244,128,18033,94385804,CLX5
2025-09-24T19:43:04.541339811Z,2025-09-24T19:43:04.541141967Z,160,1,432669,C,A,65.070000000,1,26,8058566364722,128,19660,94385805,CLX5
2025-09-24T19:43:04.651417843Z,2025-09-24T19:43:04.651295779Z,160,1,432669,A,A,65.060000000,1,26,8058566372245,128,17878,94385806,CLX5
2025-09-24T19:43:04.729568958Z,2025-09-24T19:43:04.729453669Z,160,1,432669,C,A,65.060000000,1,26,8058566370024,128,17643,94385807,CLX5
2025-09-24T19:43:04.760928431Z,2025-09-24T19:43:04.760818249Z,160,1,432669,A,A,65.050000000,1,26,8058566372246,128,18528,94385808,CLX5
2025-09-24T19:43:06.211655738Z,2025-09-24T19:43:06.211208099Z,160,1,432669,A,A,64.820000000,1,26,8058566372283,128,15785,94386017,CLX5
2025-09-24T19:43:06.303430767Z,2025-09-24T19:43:06.303279901Z,160,1,432669,C,B,64.810000000,2,26,8058566371620,128,20226,94386177,CLX5
2025-09-24T19:43:06.303788751Z,2025-09-24T19:43:06.303445859Z,160,1,432669,C,B,64.810000000,1,26,8058566371585,128,18641,94386189,CLX5
2025-09-24T19:43:06.303822411Z,2025-09-24T19:43:06.303450541Z,160,1,432669,A,A,64.820000000,1,26,8058566372332,128,17544,94386190,CLX5
2025-09-24T19:43:06.304088363Z,2025-09-24T19:43:06.303577891Z,160,1,432669,C,B,64.810000000,1,26,8058566371569,128,15925,94386205,CLX5
2025-09-24T19:43:06.304366003Z,2025-09-24T19:43:06.303739453Z,160,1,432669,A,A,64.820000000,2,26,8058566372336,128,15202,94386222,CLX5
2025-09-24T19:43:06.304668595Z,2025-09-24T19:43:06.303794343Z,160,1,432669,A,A,64.820000000,2,26,8058566372341,128,16144,94386239,CLX5
2025-09-24T19:43:06.304806959Z,2025-09-24T19:43:06.303830725Z,160,1,432669,T,A,64.810000000,1,26,8058566372342,0,13479,94386245,CLX5
2025-09-24T19:43:06.304806959Z,2025-09-24T19:43:06.303830725Z,160,1,432669,F,B,64.810000000,1,26,8058566371603,0,13479,94386245,CLX5
2025-09-24T19:43:06.304806959Z,2025-09-24T19:43:06.303830725Z,160,1,432669,C,B,64.810000000,1,26,8058566371603,128,13479,94386245,CLX5
2025-09-24T19:43:06.304893769Z,2025-09-24T19:43:06.303854379Z,160,1,432669,T,A,64.810000000,1,26,8058566372343,0,14639,94386250,CLX5
2025-09-24T19:43:06.304893769Z,2025-09-24T19:43:06.303854379Z,160,1,432669,F,B,64.810000000,1,26,8058566371604,0,14639,94386250,CLX5
2025-09-24T19:43:06.304893769Z,2025-09-24T19:43:06.303854379Z,160,1,432669,C,B,64.810000000,1,26,8058566371604,128,14639,94386250,CLX5
2025-09-24T19:43:06.305382367Z,2025-09-24T19:43:06.304056181Z,160,1,432669,T,A,64.810000000,1,26,8058566372344,128,14460,94386279,CLX5
2025-09-24T19:43:06.305490258Z,2025-09-24T19:43:06.304092159Z,160,1,432669,A,A,64.820000000,2,26,8058566372345,128,15520,94386284,CLX5
2025-09-24T19:43:06.305614652Z,2025-09-24T19:43:06.304175043Z,160,1,432669,T,A,64.810000000,2,26,8058566372351,128,15187,94386292,CLX5
2025-09-24T19:43:06.305749606Z,2025-09-24T19:43:06.304448975Z,160,1,432669,T,A,64.810000000,1,26,8058566372355,0,14350,94386301,CLX5
2025-09-24T19:43:06.305852620Z,2025-09-24T19:43:06.304448975Z,160,1,432669,A,A,64.810000000,1,26,8058566372355,128,17196,94386302,CLX5
2025-09-24T19:43:06.306163636Z,2025-09-24T19:43:06.304454755Z,160,1,432669,A,A,64.810000000,1,26,8058566372360,128,14669,94386314,CLX5
2025-09-24T19:43:06.306193771Z,2025-09-24T19:43:06.304464853Z,160,1,432669,A,A,64.810000000,1,26,8058566372362,128,14623,94386317,CLX5
2025-09-24T19:43:06.306310731Z,2025-09-24T19:43:06.304557067Z,160,1,432669,A,A,64.810000000,1,26,8058566372364,128,14775,94386322,CLX5
2025-09-24T19:43:06.306446606Z,2025-09-24T19:43:06.304678483Z,160,1,432669,A,A,64.810000000,1,26,8058566372366,128,22569,94386331,CLX5
2025-09-24T19:43:06.306802985Z,2025-09-24T19:43:06.304823955Z,160,1,432669,C,B,64.800000000,2,26,8058566371555,128,13982,94386345,CLX5
2025-09-24T19:43:06.307419879Z,2025-09-24T19:43:06.305230439Z,160,1,432669,A,A,64.810000000,1,26,8058566372384,128,14758,94386373,CLX5
2025-09-24T19:43:06.308113424Z,2025-09-24T19:43:06.305463997Z,160,1,432669,C,A,64.810000000,1,26,8058566372360,128,14907,94386420,CLX5
2025-09-24T19:43:06.308197185Z,2025-09-24T19:43:06.305472597Z,160,1,432669,A,A,64.820000000,1,26,8058566372394,128,17937,94386424,CLX5
2025-09-24T19:43:06.308259667Z,2025-09-24T19:43:06.305499745Z,160,1,432669,C,A,64.810000000,1,26,8058566372364,128,18105,94386426,CLX5
2025-09-24T19:43:06.308456249Z,2025-09-24T19:43:06.305616309Z,160,1,432669,A,A,64.810000000,1,26,8058566372398,128,17911,94386435,CLX5
2025-09-24T19:43:06.308613473Z,2025-09-24T19:43:06.305853335Z,160,1,432669,M,A,64.810000000,2,26,8058566371054,128,20507,94386446,CLX5
2025-09-24T19:43:06.309273320Z,2025-09-24T19:43:06.306002091Z,160,1,432669,M,A,64.810000000,2,26,8058566371432,128,19874,94386483,CLX5
2025-09-24T19:43:06.309831710Z,2025-09-24T19:43:06.306041679Z,160,1,432669,C,B,64.780000000,1,26,8058566371575,128,14602,94386517,CLX5
2025-09-24T19:43:06.310238883Z,2025-09-24T19:43:06.306098775Z,160,1,432669,M,A,64.830000000,3,26,8058566331102,128,14451,94386539,CLX5
2025-09-24T19:43:06.310437923Z,2025-09-24T19:43:06.306168049Z,160,1,432669,C,B,64.800000000,2,26,8058566368553,128,14816,94386550,CLX5
2025-09-24T19:43:06.310469194Z,2025-09-24T19:43:06.306168201Z,160,1,432669,C,B,64.800000000,1,26,8058566368554,128,15316,94386551,CLX5
2025-09-24T19:43:06.310506440Z,2025-09-24T19:43:06.306168375Z,160,1,432669,A,A,64.810000000,2,26,8058566372433,128,19430,94386552,CLX5
2025-09-24T19:43:06.310533626Z,2025-09-24T19:43:06.306168555Z,160,1,432669,A,A,64.810000000,1,26,8058566372434,128,15941,94386553,CLX5
2025-09-24T19:43:06.310659840Z,2025-09-24T19:43:06.306197713Z,160,1,432669,C,B,64.800000000,1,26,8058566368548,128,14005,94386559,CLX5
2025-09-24T19:43:06.310750083Z,2025-09-24T19:43:06.306212399Z,160,1,432669,C,B,64.800000000,2,26,8058566368549,128,18116,94386562,CLX5
2025-09-24T19:43:06.310805760Z,2025-09-24T19:43:06.306223765Z,160,1,432669,C,B,64.800000000,1,26,8058566355166,128,14048,94386564,CLX5
2025-09-24T19:43:06.310838890Z,2025-09-24T19:43:06.306223937Z,160,1,432669,A,A,64.810000000,2,26,8058566372438,128,15755,94386565,CLX5
2025-09-24T19:43:06.311270383Z,2025-09-24T19:43:06.306442463Z,160,1,432669,A,A,64.810000000,2,26,8058566372442,128,15321,94386589,CLX5
2025-09-24T19:43:06.311418108Z,2025-09-24T19:43:06.306468707Z,160,1,432669,A,A,64.810000000,1,26,8058566372446,128,18879,94386596,CLX5
2025-09-24T19:43:06.312885241Z,2025-09-24T19:43:06.307374409Z,160,1,432669,A,A,64.810000000,1,26,8058566372466,128,15870,94386686,CLX5
2025-09-24T19:43:06.313359787Z,2025-09-24T19:43:06.307624401Z,160,1,432669,M,B,63.640000000,3,26,8058566345944,128,14732,94386713,CLX5
2025-09-24T19:43:06.314125450Z,2025-09-24T19:43:06.308113843Z,160,1,432669,A,A,64.810000000,1,26,8058566372488,128,14145,94386746,CLX5
2025-09-24T19:43:06.314367403Z,2025-09-24T19:43:06.308277957Z,160,1,432669,A,A,64.810000000,1,26,8058566372490,128,14983,94386755,CLX5
2025-09-24T19:43:06.314485830Z,2025-09-24T19:43:06.308309119Z,160,1,432669,C,B,64.800000000,1,26,8058566371714,128,14439,94386761,CLX5
2025-09-24T19:43:06.314517486Z,2025-09-24T19:43:06.308324285Z,160,1,432669,A,A,64.810000000,2,26,8058566372493,128,14941,94386762,CLX5
2025-09-24T19:43:06.315279002Z,2025-09-24T19:43:06.308646313Z,160,1,432669,A,A,64.820000000,1,26,8058566372502,128,15015,94386805,CLX5
2025-09-24T19:43:06.315898853Z,2025-09-24T19:43:06.309466503Z,160,1,432669,C,B,64.790000000,2,26,8058566371722,128,14320,94386847,CLX5
2025-09-24T19:43:06.315994587Z,2025-09-24T19:43:06.309489503Z,160,1,432669,A,A,64.840000000,2,26,8058566372513,128,14823,94386849,CLX5
2025-09-24T19:43:06.316175802Z,2025-09-24T19:43:06.309509047Z,160,1,432669,M,A,64.930000000,1,26,8058565075241,128,19483,94386854,CLX5
2025-09-24T19:43:06.317069301Z,2025-09-24T19:43:06.309790295Z,160,1,432669,A,A,64.810000000,2,26,8058566372536,128,15483,94386910,CLX5
2025-09-24T19:43:06.319944649Z,2025-09-24T19:43:06.311151093Z,160,1,432669,C,A,64.810000000,1,26,8058566372490,128,15186,94387097,CLX5
2025-09-24T19:43:06.320062354Z,2025-09-24T19:43:06.311175301Z,160,1,432669,C,A,64.810000000,2,26,8058566372493,128,15092,94387103,CLX5
2025-09-24T19:43:06.320901111Z,2025-09-24T19:43:06.311961777Z,160,1,432669,M,A,64.820000000,3,26,8058566354590,128,14907,94387144,CLX5
2025-09-24T19:43:06.322057475Z,2025-09-24T19:43:06.312841713Z,160,1,432669,A,A,64.810000000,2,26,8058566372582,128,14938,94387213,CLX5
2025-09-24T19:43:06.322194000Z,2025-09-24T19:43:06.312916627Z,160,1,432669,C,B,64.800000000,3,26,8058566340905,128,17570,94387219,CLX5
2025-09-24T19:43:06.322247951Z,2025-09-24T19:43:06.312978737Z,160,1,432669,C,A,64.860000000,2,26,8058566365758,128,14560,94387222,CLX5
2025-09-24T19:43:06.324177120Z,2025-09-24T19:43:06.315057409Z,160,1,432669,A,B,64.790000000,1,26,8058566372615,128,15290,94387337,CLX5
2025-09-24T19:43:06.324513018Z,2025-09-24T19:43:06.315624419Z,160,1,432669,M,A,64.810000000,1,26,8058566371664,128,16158,94387352,CLX5
2025-09-24T19:43:06.326905742Z,2025-09-24T19:43:06.317401607Z,160,1,432669,A,A,64.920000000,2,26,8058566372672,128,16445,94387509,CLX5
2025-09-24T19:43:06.326905742Z,2025-09-24T19:43:06.317405543Z,160,1,432669,C,B,64.800000000,1,26,8058566340604,128,16445,94387509,CLX5
2025-09-24T19:43:06.327490482Z,2025-09-24T19:43:06.318744915Z,160,1,432669,C,A,65.480000000,2,26,8058566302430,128,15035,94387549,CLX5
2025-09-24T19:43:06.327490482Z,2025-09-24T19:43:06.318748869Z,160,1,432669,C,A,65.700000000,6,26,8058566371985,128,15035,94387549,CLX5
2025-09-24T19:43:06.328192052Z,2025-09-24T19:43:06.319459277Z,160,1,432669,A,B,63.660000000,3,26,8058566372703,128,14503,94387601,CLX5
2025-09-24T19:43:06.328845831Z,2025-09-24T19:43:06.319977461Z,160,1,432669,C,A,64.820000000,1,26,8058566372502,128,14518,94387645,CLX5
2025-09-24T19:43:06.328875873Z,2025-09-24T19:43:06.319986851Z,160,1,432669,C,A,64.820000000,1,26,8058566372394,128,18094,94387646,CLX5
2025-09-24T19:43:06.329245731Z,2025-09-24T19:43:06.320497355Z,160,1,432669,C,B,64.800000000,1,26,8058566340266,128,14848,94387676,CLX5
2025-09-24T19:43:06.329278607Z,2025-09-24T19:43:06.320500139Z,160,1,432669,C,B,64.800000000,1,26,8058566340410,128,18148,94387677,CLX5
2025-09-24T19:43:06.329821524Z,2025-09-24T19:43:06.321340603Z,160,1,432669,C,A,64.810000000,2,26,8058566372442,128,18970,94387716,CLX5
2025-09-24T19:43:06.330136425Z,2025-09-24T19:43:06.321982199Z,160,1,432669,A,A,64.840000000,1,26,8058566372739,128,14748,94387738,CLX5
2025-09-24T19:43:06.330520298Z,2025-09-24T19:43:06.322090885Z,160,1,432669,A,A,64.810000000,3,26,8058566372746,128,15736,94387757,CLX5
2025-09-24T19:43:06.330550648Z,2025-09-24T19:43:06.322117129Z,160,1,432669,T,A,64.800000000,1,26,8058566372747,0,14525,94387759,CLX5
2025-09-24T19:43:06.330550648Z,2025-09-24T19:43:06.322117129Z,160,1,432669,F,B,64.800000000,1,26,8058566250102,0,14525,94387759,CLX5
2025-09-24T19:43:06.330550648Z,2025-09-24T19:43:06.322117129Z,160,1,432669,M,B,64.800000000,1,26,8058566250102,128,14525,94387759,CLX5
2025-09-24T19:43:06.330609650Z,2025-09-24T19:43:06.322200031Z,160,1,432669,C,B,64.770000000,1,26,8058566371203,128,14720,94387763,CLX5
2025-09-24T19:43:06.331095876Z,2025-09-24T19:43:06.323493191Z,160,1,432669,A,B,64.800000000,2,26,8058566372753,128,14916,94387792,CLX5
2025-09-24T19:43:06.332770197Z,2025-09-24T19:43:06.325146987Z,160,1,432669,A,B,64.770000000,1,26,8058566372772,128,17762,94387896,CLX5
2025-09-24T19:43:06.333372400Z,2025-09-24T19:43:06.325991691Z,160,1,432669,C,B,64.540000000,8,26,8058566358150,128,14462,94387931,CLX5
2025-09-24T19:43:06.339148140Z,2025-09-24T19:43:06.335129627Z,160,1,432669,C,B,64.780000000,2,26,8058566371219,128,14940,94388289,CLX5
2025-09-24T19:43:06.339349069Z,2025-09-24T19:43:06.335131115Z,160,1,432669,C,B,64.770000000,1,26,8058566372772,128,18170,94388299,CLX5
2025-09-24T19:43:06.339375126Z,2025-09-24T19:43:06.335131267Z,160,1,432669,C,B,64.760000000,1,26,8058566369432,128,14859,94388300,CLX5
2025-09-24T19:43:06.340446607Z,2025-09-24T19:43:06.335172707Z,160,1,432669,C,B,64.800000000,1,26,8058566250102,128,15103,94388351,CLX5
2025-09-24T19:43:06.340500464Z,2025-09-24T19:43:06.335189813Z,160,1,432669,T,A,64.800000000,16,26,8058566372898,0,18317,94388355,CLX5
2025-09-24T19:43:06.340500464Z,2025-09-24T19:43:06.335189813Z,160,1,432669,F,B,64.800000000,1,26,8058566253602,0,18317,94388355,CLX5
2025-09-24T19:43:06.340500464Z,2025-09-24T19:43:06.335189813Z,160,1,432669,F,B,64.800000000,3,26,8058566253809,0,18317,94388355,CLX5
2025-09-24T19:43:06.340500464Z,2025-09-24T19:43:06.335189813Z,160,1,432669,F,B,64.800000000,1,26,8058565996850,0,18317,94388355,CLX5
2025-09-24T19:43:06.340500464Z,2025-09-24T19:43:06.335189813Z,160,1,432669,F,B,64.800000000,1,26,8058566304485,0,18317,94388355,CLX5
2025-09-24T19:43:06.340500464Z,2025-09-24T19:43:06.335189813Z,160,1,432669,F,B,64.800000000,1,26,8058566328479,0,18317,94388355,CLX5
2025-09-24T19:43:06.340500464Z,2025-09-24T19:43:06.335189813Z,160,1,432669,F,B,64.800000000,1,26,8058566354454,0,18317,94388355,CLX5
2025-09-24T19:43:06.340500464Z,2025-09-24T19:43:06.335189813Z,160,1,432669,F,B,64.800000000,5,26,8058566363486,0,18317,94388355,CLX5
2025-09-24T19:43:06.340500464Z,2025-09-24T19:43:06.335189813Z,160,1,432669,F,B,64.800000000,1,26,8058566371452,0,18317,94388355,CLX5
2025-09-24T19:43:06.340500464Z,2025-09-24T19:43:06.335189813Z,160,1,432669,F,B,64.800000000,1,26,8058566372753,0,18317,94388355,CLX5
2025-09-24T19:43:06.340500464Z,2025-09-24T19:43:06.335189813Z,160,1,432669,F,B,64.800000000,1,26,8058566342783,0,18317,94388355,CLX5
2025-09-24T19:43:06.340555926Z,2025-09-24T19:43:06.335189813Z,160,1,432669,C,B,64.800000000,1,26,8058566253602,0,18713,94388356,CLX5
2025-09-24T19:43:06.340555926Z,2025-09-24T19:43:06.335189813Z,160,1,432669,C,B,64.800000000,3,26,8058566253809,0,18713,94388356,CLX5
2025-09-24T19:43:06.340555926Z,2025-09-24T19:43:06.335189813Z,160,1,432669,C,B,64.800000000,1,26,8058565996850,0,18713,94388356,CLX5
2025-09-24T19:43:06.340555926Z,2025-09-24T19:43:06.335189813Z,160,1,432669,C,B,64.800000000,1,26,8058566304485,0,18713,94388356,CLX5
2025-09-24T19:43:06.340555926Z,2025-09-24T19:43:06.335189813Z,160,1,432669,C,B,64.800000000,1,26,8058566328479,0,18713,94388356,CLX5
2025-09-24T19:43:06.340555926Z,2025-09-24T19:43:06.335189813Z,160,1,432669,C,B,64.800000000,1,26,8058566354454,0,18713,94388356,CLX5
2025-09-24T19:43:06.340555926Z,2025-09-24T19:43:06.335189813Z,160,1,432669,C,B,64.800000000,5,26,8058566363486,0,18713,94388356,CLX5
2025-09-24T19:43:06.340555926Z,2025-09-24T19:43:06.335189813Z,160,1,432669,C,B,64.800000000,1,26,8058566371452,0,18713,94388356,CLX5
2025-09-24T19:43:06.340555926Z,2025-09-24T19:43:06.335189813Z,160,1,432669,C,B,64.800000000,1,26,8058566342783,0,18713,94388356,CLX5
2025-09-24T19:43:06.340555926Z,2025-09-24T19:43:06.335189813Z,160,1,432669,M,B,64.800000000,1,26,8058566372753,128,18713,94388356,CLX5
2025-09-24T19:43:06.340610750Z,2025-09-24T19:43:06.335194133Z,160,1,432669,T,A,64.800000000,2,26,8058566372899,0,16251,94388361,CLX5
2025-09-24T19:43:06.340610750Z,2025-09-24T19:43:06.335194133Z,160,1,432669,F,B,64.800000000,1,26,8058566372753,0,16251,94388361,CLX5
2025-09-24T19:43:06.340610750Z,2025-09-24T19:43:06.335194133Z,160,1,432669,C,B,64.800000000,1,26,8058566372753,128,16251,94388361,CLX5
2025-09-24T19:43:06.341329752Z,2025-09-24T19:43:06.335302265Z,160,1,432669,A,A,64.800000000,1,26,8058566372917,128,18775,94388397,CLX5
2025-09-24T19:43:06.341514024Z,2025-09-24T19:43:06.335372533Z,160,1,432669,A,A,64.800000000,1,26,8058566372921,128,14315,94388411,CLX5
2025-09-24T19:43:06.341611494Z,2025-09-24T19:43:06.335458813Z,160,1,432669,A,B,64.790000000,1,26,8058566372923,128,14079,94388417,CLX5
2025-09-24T19:43:06.341869198Z,2025-09-24T19:43:06.335630167Z,160,1,432669,C,A,64.800000000,1,26,8058566372921,128,18581,94388431,CLX5
2025-09-24T19:43:06.341947645Z,2025-09-24T19:43:06.335771511Z,160,1,432669,T,N,64.800000000,1,26,0,0,14991,94388439,CLX5
2025-09-24T19:43:06.341947645Z,2025-09-24T19:43:06.335771511Z,160,1,432669,F,N,64.800000000,1,26,8058566372917,0,14991,94388439,CLX5
2025-09-24T19:43:06.342050421Z,2025-09-24T19:43:06.335771511Z,160,1,432669,C,A,64.800000000,1,26,8058566372917,128,19219,94388440,CLX5
2025-09-24T19:43:06.343195380Z,2025-09-24T19:43:06.336525595Z,160,1,432669,A,B,64.790000000,1,26,8058566372953,128,18453,94388504,CLX5
2025-09-24T19:43:06.345475829Z,2025-09-24T19:43:06.339176249Z,160,1,432669,A,B,64.780000000,1,26,8058566372991,128,14702,94388655,CLX5
2025-09-24T19:43:06.346793778Z,2025-09-24T19:43:06.340500647Z,160,1,432669,A,A,64.800000000,1,26,8058566373015,128,14492,94388746,CLX5
2025-09-24T19:43:06.346872463Z,2025-09-24T19:43:06.340503525Z,160,1,432669,A,A,64.810000000,1,26,8058566373017,128,13593,94388750,CLX5
2025-09-24T19:43:06.347060313Z,2025-09-24T19:43:06.340613479Z,160,1,432669,A,B,64.790000000,1,26,8058566373022,128,14863,94388755,CLX5
2025-09-24T19:43:06.347069652Z,2025-09-24T19:43:06.340616417Z,160,1,432669,C,B,64.550000000,1,26,8058566302298,128,14516,94388756,CLX5
2025-09-24T19:43:06.347400097Z,2025-09-24T19:43:06.340681327Z,160,1,432669,A,B,64.790000000,2,26,8058566373027,128,14489,94388768,CLX5
2025-09-24T19:43:06.347435761Z,2025-09-24T19:43:06.340688355Z,160,1,432669,A,B,64.790000000,2,26,8058566373028,128,17118,94388769,CLX5
2025-09-24T19:43:06.347465120Z,2025-09-24T19:43:06.340688533Z,160,1,432669,A,B,64.790000000,1,26,8058566373029,128,14750,94388770,CLX5
2025-09-24T19:43:06.347534136Z,2025-09-24T19:43:06.340704503Z,160,1,432669,M,A,64.800000000,2,26,8058566372582,128,17993,94388772,CLX5
2025-09-24T19:43:06.347571214Z,2025-09-24T19:43:06.340728251Z,160,1,432669,T,B,64.800000000,2,26,8058566373030,0,14628,94388775,CLX5
2025-09-24T19:43:06.347571214Z,2025-09-24T19:43:06.340728251Z,160,1,432669,F,A,64.800000000,1,26,8058566373015,0,14628,94388775,CLX5
2025-09-24T19:43:06.347571214Z,2025-09-24T19:43:06.340728251Z,160,1,432669,F,A,64.800000000,1,26,8058566372582,0,14628,94388775,CLX5
2025-09-24T19:43:06.347609466Z,2025-09-24T19:43:06.340728251Z,160,1,432669,C,A,64.800000000,1,26,8058566373015,0,14847,94388776,CLX5
2025-09-24T19:43:06.347609466Z,2025-09-24T19:43:06.340728251Z,160,1,432669,M,A,64.800000000,1,26,8058566372582,128,14847,94388776,CLX5
2025-09-24T19:43:06.347644607Z,2025-09-24T19:43:06.340744397Z,160,1,432669,T,B,64.800000000,1,26,8058566373031,0,14118,94388779,CLX5
2025-09-24T19:43:06.347644607Z,2025-09-24T19:43:06.340744397Z,160,1,432669,F,A,64.800000000,1,26,8058566372582,0,14118,94388779,CLX5
2025-09-24T19:43:06.347715797Z,2025-09-24T19:43:06.340744397Z,160,1,432669,A,B,64.800000000,2,26,8058566373031,0,14670,94388780,CLX5
2025-09-24T19:43:06.347715797Z,2025-09-24T19:43:06.340744397Z,160,1,432669,C,A,64.800000000,1,26,8058566372582,128,14670,94388780,CLX5
2025-09-24T19:43:06.347773356Z,2025-09-24T19:43:06.340788037Z,160,1,432669,C,B,64.790000000,3,26,8058566201605,128,14832,94388785,CLX5
2025-09-24T19:43:06.348126179Z,2025-09-24T19:43:06.341155317Z,160,1,432669,C,A,66.160000000,4,26,8058566230492,128,14620,94388807,CLX5
2025-09-24T19:43:06.348126179Z,2025-09-24T19:43:06.341155529Z,160,1,432669,C,A,64.810000000,1,26,8058566373017,128,14620,94388807,CLX5
2025-09-24T19:43:06.348341032Z,2025-09-24T19:43:06.341330451Z,160,1,432669,T,A,64.800000000,2,26,8058566371054,0,14040,94388822,CLX5
2025-09-24T19:43:06.348341032Z,2025-09-24T19:43:06.341330451Z,160,1,432669,F,A,64.800000000,2,26,8058566371054,0,14040,94388822,CLX5
2025-09-24T19:43:06.348341032Z,2025-09-24T19:43:06.341330451Z,160,1,432669,F,B,64.800000000,2,26,8058566373031,0,14040,94388822,CLX5
2025-09-24T19:43:06.348341032Z,2025-09-24T19:43:06.341330451Z,160,1,432669,C,B,64.800000000,2,26,8058566373031,0,14040,94388822,CLX5
2025-09-24T19:43:06.348341032Z,2025-09-24T19:43:06.341330451Z,160,1,432669,C,A,64.810000000,2,26,8058566371054,128,14040,94388822,CLX5
2025-09-24T19:43:06.348461970Z,2025-09-24T19:43:06.341332507Z,160,1,432669,A,A,64.800000000,3,26,8058566373039,128,14592,94388825,CLX5
2025-09-24T19:43:06.348790688Z,2025-09-24T19:43:06.341482797Z,160,1,432669,M,A,64.800000000,2,26,8058566368599,128,14913,94388845,CLX5
2025-09-24T19:43:06.348873474Z,2025-09-24T19:43:06.341518745Z,160,1,432669,T,B,64.800000000,5,26,8058566373048,0,15008,94388849,CLX5
2025-09-24T19:43:06.348873474Z,2025-09-24T19:43:06.341518745Z,160,1,432669,F,A,64.800000000,3,26,8058566373039,0,15008,94388849,CLX5
2025-09-24T19:43:06.348873474Z,2025-09-24T19:43:06.341518745Z,160,1,432669,F,A,64.800000000,2,26,8058566368599,0,15008,94388849,CLX5
2025-09-24T19:43:06.348924535Z,2025-09-24T19:43:06.341518745Z,160,1,432669,C,A,64.800000000,3,26,8058566373039,0,18535,94388850,CLX5
2025-09-24T19:43:06.348924535Z,2025-09-24T19:43:06.341518745Z,160,1,432669,C,A,64.800000000,2,26,8058566368599,128,18535,94388850,CLX5
2025-09-24T19:43:06.349002637Z,2025-09-24T19:43:06.341552835Z,160,1,432669,M,A,64.820000000,1,26,8058566338645,128,14858,94388856,CLX5
2025-09-24T19:43:06.349097825Z,2025-09-24T19:43:06.341692931Z,160,1,432669,C,A,64.810000000,1,26,8058566372446,128,15282,94388862,CLX5
2025-09-24T19:43:06.349213411Z,2025-09-24T19:43:06.341901301Z,160,1,432669,A,A,64.830000000,1,26,8058566373058,128,14459,94388865,CLX5
2025-09-24T19:43:06.349237632Z,2025-09-24T19:43:06.341904105Z,160,1,432669,C,A,64.890000000,1,26,8058566302714,128,14598,94388866,CLX5
2025-09-24T19:43:06.349392783Z,2025-09-24T19:43:06.341952177Z,160,1,432669,A,B,64.800000000,2,26,8058566373060,128,16749,94388871,CLX5
2025-09-24T19:43:06.349885706Z,2025-09-24T19:43:06.342469921Z,160,1,432669,M,A,65.960000000,3,26,8058566354590,128,14573,94388900,CLX5
2025-09-24T19:43:06.349917646Z,2025-09-24T19:43:06.342491463Z,160,1,432669,C,A,64.820000000,1,26,8058566338645,128,19090,94388901,CLX5
2025-09-24T19:43:06.349967440Z,2025-09-24T19:43:06.342638279Z,160,1,432669,C,B,64.800000000,2,26,8058566373060,128,15284,94388902,CLX5
2025-09-24T19:43:06.351265814Z,2025-09-24T19:43:06.343522419Z,160,1,432669,A,B,64.800000000,2,26,8058566373087,128,17670,94388972,CLX5
2025-09-24T19:43:06.351288753Z,2025-09-24T19:43:06.343524435Z,160,1,432669,A,B,64.800000000,2,26,8058566373088,128,14910,94388974,CLX5
2025-09-24T19:43:06.351669745Z,2025-09-24T19:43:06.343648999Z,160,1,432669,A,B,64.800000000,2,26,8058566373095,128,16897,94388992,CLX5
2025-09-24T19:43:06.352290894Z,2025-09-24T19:43:06.344044835Z,160,1,432669,A,B,64.800000000,1,26,8058566373104,128,16670,94389024,CLX5
2025-09-24T19:43:06.352499764Z,2025-09-24T19:43:06.344046293Z,160,1,432669,A,B,64.800000000,2,26,8058566373111,128,16125,94389032,CLX5
2025-09-24T19:43:06.352599537Z,2025-09-24T19:43:06.344057481Z,160,1,432669,C,A,64.810000000,2,26,8058566372536,128,14774,94389037,CLX5
2025-09-24T19:43:06.352649816Z,2025-09-24T19:43:06.344068405Z,160,1,432669,A,B,64.790000000,1,26,8058566373114,128,14390,94389039,CLX5
2025-09-24T19:43:06.352697798Z,2025-09-24T19:43:06.344133911Z,160,1,432669,A,B,64.800000000,3,26,8058566373116,128,13891,94389041,CLX5
2025-09-24T19:43:06.353163058Z,2025-09-24T19:43:06.344786261Z,160,1,432669,A,B,64.790000000,1,26,8058566373123,128,14686,94389062,CLX5
2025-09-24T19:43:06.353242757Z,2025-09-24T19:43:06.344900515Z,160,1,432669,A,B,64.800000000,1,26,8058566373125,128,15807,94389067,CLX5
2025-09-24T19:43:06.353278851Z,2025-09-24T19:43:06.344924629Z,160,1,432669,A,B,64.800000000,1,26,8058566373126,128,19441,94389068,CLX5
2025-09-24T19:43:06.353331356Z,2025-09-24T19:43:06.344955077Z,160,1,432669,C,B,64.790000000,1,26,8058566373114,128,14495,94389071,CLX5
2025-09-24T19:43:06.353579907Z,2025-09-24T19:43:06.345134727Z,160,1,432669,A,B,64.800000000,1,26,8058566373133,128,14271,94389084,CLX5
2025-09-24T19:43:06.353615126Z,2025-09-24T19:43:06.345135589Z,160,1,432669,C,A,64.840000000,2,26,8058566372513,128,18253,94389085,CLX5
2025-09-24T19:43:06.353986104Z,2025-09-24T19:43:06.345146091Z,160,1,432669,A,B,64.800000000,1,26,8058566373139,128,15591,94389097,CLX5
2025-09-24T19:43:06.354087904Z,2025-09-24T19:43:06.345200503Z,160,1,432669,A,B,64.790000000,1,26,8058566373141,128,14783,94389102,CLX5
2025-09-24T19:43:06.354187109Z,2025-09-24T19:43:06.345278835Z,160,1,432669,C,A,64.810000000,1,26,8058566372488,128,15846,94389108,CLX5
2025-09-24T19:43:06.354532891Z,2025-09-24T19:43:06.345641123Z,160,1,432669,A,B,64.780000000,1,26,8058566373151,128,14230,94389126,CLX5
2025-09-24T19:43:06.354599918Z,2025-09-24T19:43:06.345666639Z,160,1,432669,C,B,64.790000000,1,26,8058566373141,128,14687,94389128,CLX5
2025-09-24T19:43:06.355233600Z,2025-09-24T19:43:06.345968335Z,160,1,432669,M,A,64.820000000,1,26,8058566173085,128,14889,94389166,CLX5
2025-09-24T19:43:06.355377117Z,2025-09-24T19:43:06.346310327Z,160,1,432669,A,B,64.790000000,1,26,8058566373161,128,14790,94389177,CLX5
2025-09-24T19:43:06.355502125Z,2025-09-24T19:43:06.346441247Z,160,1,432669,A,B,64.790000000,1,26,8058566373162,128,15104,94389180,CLX5
2025-09-24T19:43:06.355615207Z,2025-09-24T19:43:06.346799925Z,160,1,432669,A,B,64.770000000,1,26,8058566373167,128,15057,94389186,CLX5
2025-09-24T19:43:06.355693593Z,2025-09-24T19:43:06.346802997Z,160,1,432669,A,B,64.800000000,1,26,8058566373169,128,14166,94389189,CLX5
2025-09-24T19:43:06.355754845Z,2025-09-24T19:43:06.346823233Z,160,1,432669,A,A,64.810000000,2,26,8058566373174,128,17858,94389191,CLX5
2025-09-24T19:43:06.355824053Z,2025-09-24T19:43:06.347026475Z,160,1,432669,C,A,64.830000000,3,26,8058566331102,128,14721,94389194,CLX5
2025-09-24T19:43:06.356051907Z,2025-09-24T19:43:06.347261703Z,160,1,432669,A,B,64.800000000,1,26,8058566373180,128,13978,94389202,CLX5
2025-09-24T19:43:06.356230427Z,2025-09-24T19:43:06.347407349Z,160,1,432669,C,B,64.790000000,1,26,8058566373161,128,14771,94389209,CLX5
2025-09-24T19:43:06.356368069Z,2025-09-24T19:43:06.347567891Z,160,1,432669,A,A,64.810000000,1,26,8058566373191,128,14796,94389216,CLX5
2025-09-24T19:43:06.356409600Z,2025-09-24T19:43:06.347571503Z,160,1,432669,A,B,64.800000000,1,26,8058566373193,128,17678,94389217,CLX5
2025-09-24T19:43:06.356509637Z,2025-09-24T19:43:06.347583807Z,160,1,432669,A,B,64.800000000,1,26,8058566373197,128,19917,94389222,CLX5
2025-09-24T19:43:06.356745406Z,2025-09-24T19:43:06.347743085Z,160,1,432669,A,B,64.800000000,2,26,8058566373205,128,14797,94389235,CLX5
2025-09-24T19:43:06.356754929Z,2025-09-24T19:43:06.347746329Z,160,1,432669,T,A,64.800000000,2,26,8058566364431,0,14965,94389236,CLX5
2025-09-24T19:43:06.356754929Z,2025-09-24T19:43:06.347746329Z,160,1,432669,F,A,64.800000000,2,26,8058566364431,0,14965,94389236,CLX5
2025-09-24T19:43:06.356754929Z,2025-09-24T19:43:06.347746329Z,160,1,432669,F,B,64.800000000,2,26,8058566373087,0,14965,94389236,CLX5
2025-09-24T19:43:06.356804270Z,2025-09-24T19:43:06.347746329Z,160,1,432669,C,B,64.800000000,2,26,8058566373087,0,16063,94389237,CLX5
2025-09-24T19:43:06.356804270Z,2025-09-24T19:43:06.347746329Z,160,1,432669,C,A,64.840000000,2,26,8058566364431,128,16063,94389237,CLX5
2025-09-24T19:43:06.356847521Z,2025-09-24T19:43:06.347769407Z,160,1,432669,A,B,64.800000000,1,26,8058566373207,128,15199,94389239,CLX5
2025-09-24T19:43:06.356914994Z,2025-09-24T19:43:06.347842921Z,160,1,432669,A,A,64.840000000,2,26,8058566373208,128,17804,94389242,CLX5
2025-09-24T19:43:06.357627169Z,2025-09-24T19:43:06.348116015Z,160,1,432669,C,B,64.800000000,3,26,8058566373116,128,15094,94389273,CLX5
2025-09-24T19:43:06.357661774Z,2025-09-24T19:43:06.348116335Z,160,1,432669,C,B,64.800000000,2,26,8058566373095,128,15199,94389274,CLX5
2025-09-24T19:43:06.357698536Z,2025-09-24T19:43:06.348116489Z,160,1,432669,C,B,64.800000000,1,26,8058566373180,128,18816,94389275,CLX5
2025-09-24T19:43:06.357744053Z,2025-09-24T19:43:06.348142541Z,160,1,432669,M,B,64.790000000,2,26,8058566319508,128,13842,94389277,CLX5
2025-09-24T19:43:06.357780178Z,2025-09-24T19:43:06.348155385Z,160,1,432669,C,A,64.810000000,1,26,8058566373191,128,14835,94389278,CLX5
2025-09-24T19:43:06.357853794Z,2025-09-24T19:43:06.348196051Z,160,1,432669,C,B,64.800000000,1,26,8058566373197,128,14355,94389280,CLX5
2025-09-24T19:43:06.359065335Z,2025-09-24T19:43:06.349395747Z,160,1,432669,C,B,64.800000000,1,26,8058566373207,128,18607,94389352,CLX5
2025-09-24T19:43:06.359117349Z,2025-09-24T19:43:06.349423701Z,160,1,432669,A,A,64.810000000,1,26,8058566373248,128,14988,94389354,CLX5
2025-09-24T19:43:06.359137569Z,2025-09-24T19:43:06.349545961Z,160,1,432669,A,A,64.850000000,1,26,8058566373250,128,14771,94389356,CLX5
2025-09-24T19:43:06.359194429Z,2025-09-24T19:43:06.349553083Z,160,1,432669,A,B,64.800000000,1,26,8058566373251,128,15486,94389358,CLX5
2025-09-24T19:43:06.359272316Z,2025-09-24T19:43:06.349584899Z,160,1,432669,C,A,64.810000000,1,26,8058566373248,128,18631,94389362,CLX5
2025-09-24T19:43:06.359445129Z,2025-09-24T19:43:06.349905023Z,160,1,432669,A,A,64.810000000,1,26,8058566373255,128,14901,94389372,CLX5
2025-09-24T19:43:06.359486046Z,2025-09-24T19:43:06.349967921Z,160,1,432669,A,A,64.810000000,2,26,8058566373257,128,17997,94389374,CLX5
2025-09-24T19:43:06.359540548Z,2025-09-24T19:43:06.350033179Z,160,1,432669,C,A,64.810000000,1,26,8058566373255,128,14831,94389377,CLX5
2025-09-24T19:43:06.359584145Z,2025-09-24T19:43:06.350156649Z,160,1,432669,A,A,64.810000000,1,26,8058566373258,128,18386,94389379,CLX5
2025-09-24T19:43:06.359711473Z,2025-09-24T19:43:06.350262531Z,160,1,432669,M,B,63.630000000,4,26,8058566319508,128,17957,94389384,CLX5
2025-09-24T19:43:06.359760799Z,2025-09-24T19:43:06.350582619Z,160,1,432669,A,B,64.790000000,1,26,8058566373260,128,14667,94389386,CLX5
2025-09-24T19:43:06.360534826Z,2025-09-24T19:43:06.351678547Z,160,1,432669,C,B,64.800000000,1,26,8058566373139,128,15883,94389422,CLX5
2025-09-24T19:43:06.360570851Z,2025-09-24T19:43:06.351856139Z,160,1,432669,C,B,64.800000000,1,26,8058566373251,128,14673,94389425,CLX5
2025-09-24T19:43:06.360627334Z,2025-09-24T19:43:06.351894497Z,160,1,432669,M,B,64.790000000,2,26,8058566370556,128,14730,94389428,CLX5
2025-09-24T19:43:06.360713638Z,2025-09-24T19:43:06.352298697Z,160,1,432669,C,B,64.800000000,1,26,8058566373169,128,15741,94389433,CLX5
2025-09-24T19:43:06.360823740Z,2025-09-24T19:43:06.352524133Z,160,1,432669,C,B,64.800000000,2,26,8058566373205,128,15658,94389437,CLX5
2025-09-24T19:43:06.361008503Z,2025-09-24T19:43:06.352784993Z,160,1,432669,M,B,64.790000000,1,26,8058566365565,128,14963,94389447,CLX5
2025-09-24T19:43:06.361353609Z,2025-09-24T19:43:06.353182761Z,160,1,432669,C,A,64.810000000,1,26,8058566373258,128,18155,94389465,CLX5
2025-09-24T19:43:06.361401261Z,2025-09-24T19:43:06.353348105Z,160,1,432669,A,A,64.810000000,1,26,8058566373283,128,14322,94389467,CLX5
2025-09-24T19:43:06.361602205Z,2025-09-24T19:43:06.353572637Z,160,1,432669,C,A,64.810000000,1,26,8058566373283,128,15015,94389476,CLX5
2025-09-24T19:43:06.362361456Z,2025-09-24T19:43:06.354991723Z,160,1,432669,C,A,64.810000000,2,26,8058566373174,128,14204,94389516,CLX5
2025-09-24T19:43:06.363070303Z,2025-09-24T19:43:06.356097557Z,160,1,432669,M,A,64.830000000,3,26,8058566275289,128,15378,94389548,CLX5
2025-09-24T19:43:06.363139960Z,2025-09-24T19:43:06.356254221Z,160,1,432669,C,B,64.790000000,1,26,8058566373260,128,14821,94389550,CLX5
2025-09-24T19:43:06.363169519Z,2025-09-24T19:43:06.356263035Z,160,1,432669,C,B,64.790000000,1,26,8058566373162,128,13763,94389551,CLX5
2025-09-24T19:43:06.363381399Z,2025-09-24T19:43:06.356754743Z,160,1,432669,C,B,64.800000000,1,26,8058566373193,128,15848,94389560,CLX5
2025-09-24T19:43:06.364234886Z,2025-09-24T19:43:06.359537277Z,160,1,432669,A,B,64.800000000,1,26,8058566373330,128,14804,94389601,CLX5
2025-09-24T19:43:06.364302243Z,2025-09-24T19:43:06.359592915Z,160,1,432669,A,B,64.800000000,1,26,8058566373331,128,15804,94389603,CLX5
2025-09-24T19:43:06.364526811Z,2025-09-24T19:43:06.360554889Z,160,1,432669,C,B,64.800000000,1,26,8058566373330,128,19768,94389613,CLX5
2025-09-24T19:43:06.364649454Z,2025-09-24T19:43:06.360686173Z,160,1,432669,A,B,64.800000000,1,26,8058566373338,128,14421,94389618,CLX5
2025-09-24T19:43:06.364797855Z,2025-09-24T19:43:06.360832165Z,160,1,432669,C,B,64.800000000,1,26,8058566373331,128,15356,94389625,CLX5
2025-09-24T19:43:06.364906790Z,2025-09-24T19:43:06.361018049Z,160,1,432669,A,A,65.950000000,3,26,8058566373342,128,13967,94389633,CLX5
2025-09-24T19:43:06.365203491Z,2025-09-24T19:43:06.361722333Z,160,1,432669,A,B,63.680000000,4,26,8058566373348,128,14557,94389653,CLX5
2025-09-24T19:43:06.365363710Z,2025-09-24T19:43:06.362152951Z,160,1,432669,C,B,64.800000000,1,26,8058566373338,128,15906,94389664,CLX5
2025-09-24T19:43:06.365610401Z,2025-09-24T19:43:06.362360723Z,160,1,432669,A,B,64.800000000,1,26,8058566373355,128,16381,94389675,CLX5
2025-09-24T19:43:06.365641489Z,2025-09-24T19:43:06.362511667Z,160,1,432669,C,B,64.800000000,1,26,8058566373355,128,14514,94389677,CLX5
2025-09-24T19:43:06.366659304Z,2025-09-24T19:43:06.364199445Z,160,1,432669,A,A,64.810000000,2,26,8058566373371,128,18011,94389742,CLX5
2025-09-24T19:43:06.366990248Z,2025-09-24T19:43:06.365113017Z,160,1,432669,A,A,64.810000000,1,26,8058566373380,128,19407,94389758,CLX5
2025-09-24T19:43:06.374404177Z,2025-09-24T19:43:06.374272837Z,160,1,432669,A,A,64.840000000,2,26,8058566373402,128,17725,94389821,CLX5
2025-09-24T19:43:06.380573058Z,2025-09-24T19:43:06.380474337Z,160,1,432669,A,A,65.940000000,4,26,8058566373408,128,17693,94389845,CLX5
2025-09-24T19:43:06.381408223Z,2025-09-24T19:43:06.381308885Z,160,1,432669,A,B,63.670000000,4,26,8058566373409,128,17906,94389846,CLX5
2025-09-24T19:43:06.384975464Z,2025-09-24T19:43:06.384822197Z,160,1,432669,A,B,64.800000000,1,26,8058566373417,128,19329,94389861,CLX5
2025-09-24T19:43:06.396064848Z,2025-09-24T19:43:06.395929733Z,160,1,432669,A,B,64.780000000,2,26,8058566373431,128,18549,94389923,CLX5
2025-09-24T19:43:06.396090920Z,2025-09-24T19:43:06.395932037Z,160,1,432669,A,B,64.770000000,2,26,8058566373432,128,14568,94389924,CLX5
2025-09-24T19:43:06.415708411Z,2025-09-24T19:43:06.415572385Z,160,1,432669,A,A,64.810000000,1,26,8058566373469,128,19261,94389993,CLX5
2025-09-24T19:43:06.415859207Z,2025-09-24T19:43:06.415737919Z,160,1,432669,A,A,64.810000000,1,26,8058566373470,128,18459,94389994,CLX5
2025-09-24T19:43:06.416123463Z,2025-09-24T19:43:06.415889343Z,160,1,432669,A,A,64.810000000,1,26,8058566373472,128,13886,94389998,CLX5
2025-09-24T19:43:06.417380328Z,2025-09-24T19:43:06.416715081Z,160,1,432669,C,B,64.800000000,2,26,8058566373111,128,15778,94390029,CLX5
2025-09-24T19:43:06.417414088Z,2025-09-24T19:43:06.416739809Z,160,1,432669,T,A,64.800000000,1,26,8058566373483,0,14534,94390032,CLX5
2025-09-24T19:43:06.417414088Z,2025-09-24T19:43:06.416739809Z,160,1,432669,F,B,64.800000000,1,26,8058566373088,0,14534,94390032,CLX5
2025-09-24T19:43:06.417447717Z,2025-09-24T19:43:06.416739809Z,160,1,432669,M,B,64.800000000,1,26,8058566373088,128,15786,94390033,CLX5
2025-09-24T19:43:06.418251248Z,2025-09-24T19:43:06.417156315Z,160,1,432669,A,A,64.810000000,2,26,8058566373494,128,14130,94390061,CLX5
2025-09-24T19:43:06.418551919Z,2025-09-24T19:43:06.417414413Z,160,1,432669,C,B,64.800000000,1,26,8058566373104,128,19938,94390077,CLX5
2025-09-24T19:43:06.418619024Z,2025-09-24T19:43:06.417423817Z,160,1,432669,T,A,64.800000000,1,26,8058566373499,0,14409,94390080,CLX5
2025-09-24T19:43:06.418619024Z,2025-09-24T19:43:06.417423817Z,160,1,432669,F,B,64.800000000,1,26,8058566373088,0,14409,94390080,CLX5
2025-09-24T19:43:06.418665032Z,2025-09-24T19:43:06.417423817Z,160,1,432669,C,B,64.800000000,1,26,8058566373088,128,22203,94390081,CLX5
2025-09-24T19:43:06.418682979Z,2025-09-24T19:43:06.417475809Z,160,1,432669,T,A,64.800000000,1,26,8058566373500,0,14665,94390083,CLX5
2025-09-24T19:43:06.418682979Z,2025-09-24T19:43:06.417475809Z,160,1,432669,F,B,64.800000000,1,26,8058566373125,0,14665,94390083,CLX5
2025-09-24T19:43:06.418682979Z,2025-09-24T19:43:06.417475809Z,160,1,432669,C,B,64.800000000,1,26,8058566373125,128,14665,94390083,CLX5
2025-09-24T19:43:06.419279185Z,2025-09-24T19:43:06.418689271Z,160,1,432669,T,A,64.800000000,1,26,8058566373506,0,14616,94390114,CLX5
2025-09-24T19:43:06.419279185Z,2025-09-24T19:43:06.418689271Z,160,1,432669,F,B,64.800000000,1,26,8058566373126,0,14616,94390114,CLX5
2025-09-24T19:43:06.419327551Z,2025-09-24T19:43:06.418689271Z,160,1,432669,C,B,64.800000000,1,26,8058566373126,128,17791,94390115,CLX5
2025-09-24T19:43:06.419471006Z,2025-09-24T19:43:06.418911311Z,160,1,432669,T,A,64.800000000,1,26,8058566373508,0,14239,94390124,CLX5
2025-09-24T19:43:06.419471006Z,2025-09-24T19:43:06.418911311Z,160,1,432669,F,B,64.800000000,1,26,8058566373133,0,14239,94390124,CLX5
2025-09-24T19:43:06.419521231Z,2025-09-24T19:43:06.418911311Z,160,1,432669,C,B,64.800000000,1,26,8058566373133,128,18531,94390125,CLX5
2025-09-24T19:43:06.432437682Z,2025-09-24T19:43:06.432305137Z,160,1,432669,C,B,64.790000000,1,26,8058566373123,128,19093,94390234,CLX5
2025-09-24T19:43:06.435885452Z,2025-09-24T19:43:06.435620505Z,160,1,432669,T,A,64.800000000,1,26,8058566373565,0,18049,94390241,CLX5
2025-09-24T19:43:06.435885452Z,2025-09-24T19:43:06.435620505Z,160,1,432669,F,B,64.800000000,1,26,8058566373417,0,18049,94390241,CLX5
2025-09-24T19:43:06.435895067Z,2025-09-24T19:43:06.435620505Z,160,1,432669,C,B,64.800000000,1,26,8058566373417,128,14755,94390242,CLX5
2025-09-24T19:43:06.436178175Z,2025-09-24T19:43:06.436056017Z,160,1,432669,C,A,64.820000000,1,26,8058566372283,128,18228,94390248,CLX5
2025-09-24T19:43:06.436308452Z,2025-09-24T19:43:06.436178969Z,160,1,432669,M,B,63.620000000,4,26,8058566370556,128,18820,94390249,CLX5
2025-09-24T19:43:06.436407542Z,2025-09-24T19:43:06.436198705Z,160,1,432669,M,B,63.610000000,4,26,8058566365565,128,18978,94390252,CLX5
2025-09-24T19:43:06.436557686Z,2025-09-24T19:43:06.436358595Z,160,1,432669,A,A,64.810000000,1,26,8058566373570,128,15002,94390258,CLX5
2025-09-24T19:43:06.438177513Z,2025-09-24T19:43:06.438083333Z,160,1,432669,A,B,63.650000000,4,26,8058566373581,128,17729,94390283,CLX5
2025-09-24T19:43:06.461133854Z,2025-09-24T19:43:06.460929615Z,160,1,432669,A,A,64.800000000,1,26,8058566373621,128,17878,94390352,CLX5
2025-09-24T19:43:06.461304402Z,2025-09-24T19:43:06.461149541Z,160,1,432669,A,A,64.800000000,1,26,8058566373622,128,18276,94390355,CLX5
2025-09-24T19:43:06.461476817Z,2025-09-24T19:43:06.461270361Z,160,1,432669,M,A,64.800000000,1,26,8058566373250,128,14550,94390367,CLX5
2025-09-24T19:43:06.461545557Z,2025-09-24T19:43:06.461388915Z,160,1,432669,M,A,64.820000000,4,26,8058566354590,128,14698,94390371,CLX5
2025-09-24T19:43:06.472441799Z,2025-09-24T19:43:06.472243273Z,160,1,432669,C,B,64.780000000,1,26,8058566373151,128,17907,94390426,CLX5
2025-09-24T19:43:06.472590791Z,2025-09-24T19:43:06.472472491Z,160,1,432669,A,B,64.780000000,1,26,8058566373651,128,14599,94390430,CLX5
2025-09-24T19:43:06.472636476Z,2025-09-24T19:43:06.472486527Z,160,1,432669,C,A,64.810000000,1,26,8058566373472,128,14839,94390432,CLX5
2025-09-24T19:43:06.472669806Z,2025-09-24T19:43:06.472491441Z,160,1,432669,C,A,64.810000000,1,26,8058566373470,128,18354,94390433,CLX5
2025-09-24T19:43:06.472694695Z,2025-09-24T19:43:06.472500617Z,160,1,432669,C,A,64.810000000,1,26,8058566373469,128,14941,94390434,CLX5
2025-09-24T19:43:06.472940412Z,2025-09-24T19:43:06.472675541Z,160,1,432669,T,B,64.800000000,1,26,8058566373653,0,17529,94390436,CLX5
2025-09-24T19:43:06.472940412Z,2025-09-24T19:43:06.472675541Z,160,1,432669,F,A,64.800000000,1,26,8058566373621,0,17529,94390436,CLX5
2025-09-24T19:43:06.472949120Z,2025-09-24T19:43:06.472675541Z,160,1,432669,C,A,64.800000000,1,26,8058566373621,128,14623,94390437,CLX5
2025-09-24T19:43:06.473207424Z,2025-09-24T19:43:06.472940625Z,160,1,432669,T,B,64.800000000,2,26,8058566373655,0,18132,94390443,CLX5
2025-09-24T19:43:06.473207424Z,2025-09-24T19:43:06.472940625Z,160,1,432669,F,A,64.800000000,1,26,8058566373622,0,18132,94390443,CLX5
2025-09-24T19:43:06.473207424Z,2025-09-24T19:43:06.472940625Z,160,1,432669,F,A,64.800000000,1,26,8058566373250,0,18132,94390443,CLX5
2025-09-24T19:43:06.473217584Z,2025-09-24T19:43:06.472940625Z,160,1,432669,C,A,64.800000000,1,26,8058566373622,0,14734,94390444,CLX5
2025-09-24T19:43:06.473217584Z,2025-09-24T19:43:06.472940625Z,160,1,432669,C,A,64.800000000,1,26,8058566373250,128,14734,94390444,CLX5
2025-09-24T19:43:06.473348775Z,2025-09-24T19:43:06.473187851Z,160,1,432669,M,A,65.960000000,4,26,8058566275289,128,13539,94390451,CLX5
2025-09-24T19:43:06.473705046Z,2025-09-24T19:43:06.473358223Z,160,1,432669,A,B,64.790000000,1,26,8058566373663,128,14058,94390464,CLX5
2025-09-24T19:43:06.473738284Z,2025-09-24T19:43:06.473426093Z,160,1,432669,A,B,64.790000000,1,26,8058566373664,128,14840,94390465,CLX5
2025-09-24T19:43:06.473956392Z,2025-09-24T19:43:06.473790187Z,160,1,432669,M,A,64.830000000,3,26,8058566373342,128,14304,94390474,CLX5
2025-09-24T19:43:06.474030108Z,2025-09-24T19:43:06.473910027Z,160,1,432669,A,B,64.780000000,1,26,8058566373672,128,18494,94390476,CLX5
2025-09-24T19:43:06.476051378Z,2025-09-24T19:43:06.475943005Z,160,1,432669,A,A,65.950000000,3,26,8058566373687,128,14004,94390500,CLX5
2025-09-24T19:43:06.505894683Z,2025-09-24T19:43:06.505769237Z,160,1,432669,A,B,64.780000000,1,26,8058566373788,128,16725,94390639,CLX5
2025-09-24T19:43:06.509305338Z,2025-09-24T19:43:06.509174089Z,160,1,432669,A,B,64.790000000,4,26,8058566373792,128,18591,94390648,CLX5
2025-09-24T19:43:06.509519138Z,2025-09-24T19:43:06.509310403Z,160,1,432669,A,B,64.800000000,2,26,8058566373793,128,18130,94390649,CLX5
2025-09-24T19:43:06.509689671Z,2025-09-24T19:43:06.509543635Z,160,1,432669,A,B,64.800000000,1,26,8058566373795,128,13943,94390655,CLX5
2025-09-24T19:43:06.509838647Z,2025-09-24T19:43:06.509710573Z,160,1,432669,M,A,65.970000000,3,26,8058566354590,128,18514,94390662,CLX5
2025-09-24T19:43:06.509868866Z,2025-09-24T19:43:06.509736127Z,160,1,432669,M,B,64.790000000,3,26,8058566365565,128,14680,94390663,CLX5
2025-09-24T19:43:06.522409448Z,2025-09-24T19:43:06.522291911Z,160,1,432669,C,A,64.830000000,1,26,8058566373058,128,18030,94390704,CLX5
2025-09-24T19:43:06.522564860Z,2025-09-24T19:43:06.522446061Z,160,1,432669,A,A,64.810000000,1,26,8058566373829,128,15060,94390709,CLX5
2025-09-24T19:43:06.522710504Z,2025-09-24T19:43:06.522592129Z,160,1,432669,A,A,64.810000000,1,26,8058566373830,128,18238,94390710,CLX5
2025-09-24T19:43:06.522849390Z,2025-09-24T19:43:06.522736141Z,160,1,432669,A,A,64.810000000,1,26,8058566373831,128,18256,94390711,CLX5
2025-09-24T19:43:06.533830598Z,2025-09-24T19:43:06.533706595Z,160,1,432669,C,B,64.780000000,1,26,8058566373788,128,17663,94390733,CLX5
2025-09-24T19:43:06.590181460Z,2025-09-24T19:43:06.590035411Z,160,1,432669,A,B,64.790000000,2,26,8058566373929,128,17975,94390848,CLX5
2025-09-24T19:43:06.641279248Z,2025-09-24T19:43:06.641154423Z,160,1,432669,A,B,64.770000000,1,26,8058566373988,128,18574,94390939,CLX5
2025-09-24T19:43:06.655123050Z,2025-09-24T19:43:06.654989487Z,160,1,432669,C,B,64.770000000,1,26,8058566373167,128,18389,94390960,CLX5
2025-09-24T19:43:06.655149744Z,2025-09-24T19:43:06.654991079Z,160,1,432669,A,B,64.760000000,1,26,8058566374003,128,14574,94390961,CLX5
2025-09-24T19:43:06.655177798Z,2025-09-24T19:43:06.654993535Z,160,1,432669,A,B,64.750000000,1,26,8058566374004,128,14539,94390962,CLX5
2025-09-24T19:43:06.655280044Z,2025-09-24T19:43:06.655160339Z,160,1,432669,C,A,64.810000000,1,26,8058566373831,128,14933,94390964,CLX5
2025-09-24T19:43:06.667175631Z,2025-09-24T19:43:06.667080977Z,160,1,432669,A,B,64.550000000,1,26,8058566374013,128,17665,94391000,CLX5
2025-09-24T19:43:06.944189368Z,2025-09-24T19:43:06.944033861Z,160,1,432669,C,A,64.810000000,1,26,8058566373830,128,18689,94391225,CLX5
2025-09-24T19:43:06.944218665Z,2025-09-24T19:43:06.944039621Z,160,1,432669,C,A,64.810000000,1,26,8058566373829,128,14821,94391226,CLX5
2025-09-24T19:43:06.945424723Z,2025-09-24T19:43:06.945115561Z,160,1,432669,C,A,64.810000000,2,26,8058566373371,128,18231,94391249,CLX5
2025-09-24T19:43:06.945790010Z,2025-09-24T19:43:06.945483303Z,160,1,432669,A,B,64.800000000,2,26,8058566374169,128,14064,94391260,CLX5
2025-09-24T19:43:06.946802673Z,2025-09-24T19:43:06.946263535Z,160,1,432669,A,B,64.770000000,1,26,8058566374183,128,17937,94391300,CLX5
2025-09-24T19:43:07.018574412Z,2025-09-24T19:43:07.018465385Z,160,1,432669,A,A,65.480000000,2,26,8058566374206,128,17904,94391366,CLX5
2025-09-24T19:43:07.045059284Z,2025-09-24T19:43:07.044933893Z,160,1,432669,C,B,64.770000000,1,26,8058566373988,128,17785,94391383,CLX5
2025-09-24T19:43:07.064475508Z,2025-09-24T19:43:07.064333523Z,160,1,432669,A,B,64.790000000,1,26,8058566374245,128,17871,94391419,CLX5
2025-09-24T19:43:07.241260575Z,2025-09-24T19:43:07.241120049Z,160,1,432669,A,B,64.780000000,1,26,8058566374292,128,18653,94391486,CLX5
2025-09-24T19:43:07.627450969Z,2025-09-24T19:43:07.627284453Z,160,1,432669,A,B,64.800000000,1,26,8058566374322,128,20475,94391553,CLX5
2025-09-24T19:43:07.945029556Z,2025-09-24T19:43:07.944870923Z,160,1,432669,A,A,64.810000000,50,26,8058566374339,128,18733,94391586,CLX5
2025-09-24T19:43:07.945475248Z,2025-09-24T19:43:07.945029603Z,160,1,432669,T,A,64.800000000,5,26,8058566374340,0,17930,94391587,CLX5
2025-09-24T19:43:07.945475248Z,2025-09-24T19:43:07.945029603Z,160,1,432669,F,B,64.800000000,2,26,8058566373793,0,17930,94391587,CLX5
2025-09-24T19:43:07.945475248Z,2025-09-24T19:43:07.945029603Z,160,1,432669,F,B,64.800000000,1,26,8058566373795,0,17930,94391587,CLX5
2025-09-24T19:43:07.945475248Z,2025-09-24T19:43:07.945029603Z,160,1,432669,F,B,64.800000000,2,26,8058566374169,0,17930,94391587,CLX5
2025-09-24T19:43:07.945487259Z,2025-09-24T19:43:07.945029603Z,160,1,432669,C,B,64.800000000,2,26,8058566373793,0,14689,94391588,CLX5
2025-09-24T19:43:07.945487259Z,2025-09-24T19:43:07.945029603Z,160,1,432669,C,B,64.800000000,1,26,8058566373795,0,14689,94391588,CLX5
2025-09-24T19:43:07.945487259Z,2025-09-24T19:43:07.945029603Z,160,1,432669,C,B,64.800000000,2,26,8058566374169,0,14689,94391588,CLX5
2025-09-24T19:43:07.945487259Z,2025-09-24T19:43:07.945029603Z,160,1,432669,C,B,64.800000000,1,26,8058566374322,128,14689,94391588,CLX5
2025-09-24T19:43:07.945664596Z,2025-09-24T19:43:07.945030535Z,160,1,432669,A,A,64.800000000,2,26,8058566374344,128,14510,94391598,CLX5
2025-09-24T19:43:07.945718224Z,2025-09-24T19:43:07.945030711Z,160,1,432669,A,A,64.800000000,1,26,8058566374345,128,14648,94391602,CLX5
2025-09-24T19:43:07.945742284Z,2025-09-24T19:43:07.945030889Z,160,1,432669,C,B,64.790000000,2,26,8058566373028,128,14800,94391604,CLX5
2025-09-24T19:43:07.945795358Z,2025-09-24T19:43:07.945031037Z,160,1,432669,C,B,64.790000000,1,26,8058566373029,128,18534,94391606,CLX5
2025-09-24T19:43:07.945992900Z,2025-09-24T19:43:07.945036617Z,160,1,432669,A,A,64.800000000,1,26,8058566374350,128,16492,94391612,CLX5
2025-09-24T19:43:07.946037004Z,2025-09-24T19:43:07.945039739Z,160,1,432669,A,A,64.800000000,1,26,8058566374353,128,14483,94391615,CLX5
2025-09-24T19:43:07.946084371Z,2025-09-24T19:43:07.945067041Z,160,1,432669,A,A,64.800000000,1,26,8058566374356,128,18509,94391618,CLX5
2025-09-24T19:43:07.946120604Z,2025-09-24T19:43:07.945091789Z,160,1,432669,C,B,64.790000000,1,26,8058566226389,128,16457,94391619,CLX5
2025-09-24T19:43:07.946344126Z,2025-09-24T19:43:07.945420459Z,160,1,432669,A,A,64.800000000,1,26,8058566374361,128,20554,94391627,CLX5
2025-09-24T19:43:07.946748925Z,2025-09-24T19:43:07.945486869Z,160,1,432669,A,A,64.800000000,1,26,8058566374367,128,16633,94391643,CLX5
2025-09-24T19:43:07.946758286Z,2025-09-24T19:43:07.945492071Z,160,1,432669,C,B,64.550000000,1,26,8058566374013,128,14310,94391644,CLX5
2025-09-24T19:43:07.946818502Z,2025-09-24T19:43:07.945494721Z,160,1,432669,C,A,64.800000000,1,26,8058566374361,128,15472,94391646,CLX5
2025-09-24T19:43:07.947324173Z,2025-09-24T19:43:07.945673255Z,160,1,432669,C,A,64.800000000,1,26,8058566374353,128,17428,94391668,CLX5
2025-09-24T19:43:07.947365336Z,2025-09-24T19:43:07.945674079Z,160,1,432669,C,A,64.800000000,1,26,8058566374345,128,18216,94391669,CLX5
2025-09-24T19:43:07.947518052Z,2025-09-24T19:43:07.945727167Z,160,1,432669,A,B,64.790000000,1,26,8058566374376,128,14756,94391677,CLX5
2025-09-24T19:43:07.947821596Z,2025-09-24T19:43:07.945798913Z,160,1,432669,M,A,64.800000000,2,26,8058566373208,128,17984,94391687,CLX5
2025-09-24T19:43:07.948276989Z,2025-09-24T19:43:07.946048599Z,160,1,432669,M,A,64.820000000,4,26,8058566354590,128,13558,94391705,CLX5
2025-09-24T19:43:07.948316385Z,2025-09-24T19:43:07.946052707Z,160,1,432669,C,B,64.770000000,1,26,8058566374183,128,18045,94391706,CLX5
2025-09-24T19:43:07.948501148Z,2025-09-24T19:43:07.946072675Z,160,1,432669,A,A,64.830000000,1,26,8058566374388,128,13352,94391712,CLX5
2025-09-24T19:43:07.948683055Z,2025-09-24T19:43:07.946323705Z,160,1,432669,A,A,64.800000000,1,26,8058566374393,128,16432,94391721,CLX5
2025-09-24T19:43:07.948707115Z,2025-09-24T19:43:07.946325949Z,160,1,432669,C,A,64.810000000,1,26,8058566373570,128,13509,94391722,CLX5
2025-09-24T19:43:07.948803233Z,2025-09-24T19:43:07.946491581Z,160,1,432669,T,N,64.800000000,2,26,0,0,15052,94391726,CLX5
2025-09-24T19:43:07.948803233Z,2025-09-24T19:43:07.946491581Z,160,1,432669,F,N,64.800000000,2,26,8058566374344,0,15052,94391726,CLX5
2025-09-24T19:43:07.948840648Z,2025-09-24T19:43:07.946491581Z,160,1,432669,C,A,64.800000000,2,26,8058566374344,128,18860,94391727,CLX5
2025-09-24T19:43:07.949009476Z,2025-09-24T19:43:07.946543323Z,160,1,432669,M,B,63.610000000,4,26,8058566365565,128,18630,94391732,CLX5
2025-09-24T19:43:07.949196859Z,2025-09-24T19:43:07.946754937Z,160,1,432669,C,A,64.800000000,1,26,8058566374367,128,19276,94391738,CLX5
2025-09-24T19:43:07.949523909Z,2025-09-24T19:43:07.947484137Z,160,1,432669,C,B,64.780000000,1,26,8058566374292,128,18152,94391756,CLX5
2025-09-24T19:43:07.949589255Z,2025-09-24T19:43:07.947519963Z,160,1,432669,C,A,64.830000000,3,26,8058566373342,128,14383,94391760,CLX5
2025-09-24T19:43:07.949912589Z,2025-09-24T19:43:07.948345277Z,160,1,432669,A,B,64.770000000,1,26,8058566374406,128,14378,94391778,CLX5
2025-09-24T19:43:07.949956309Z,2025-09-24T19:43:07.948803677Z,160,1,432669,T,B,64.800000000,3,26,8058566374408,0,14535,94391781,CLX5
2025-09-24T19:43:07.949956309Z,2025-09-24T19:43:07.948803677Z,160,1,432669,F,A,64.800000000,1,26,8058566374350,0,14535,94391781,CLX5
2025-09-24T19:43:07.949956309Z,2025-09-24T19:43:07.948803677Z,160,1,432669,F,A,64.800000000,1,26,8058566374356,0,14535,94391781,CLX5
2025-09-24T19:43:07.949956309Z,2025-09-24T19:43:07.948803677Z,160,1,432669,F,A,64.800000000,1,26,8058566373208,0,14535,94391781,CLX5
2025-09-24T19:43:07.950006288Z,2025-09-24T19:43:07.948803677Z,160,1,432669,C,A,64.800000000,1,26,8058566374350,0,14607,94391782,CLX5
2025-09-24T19:43:07.950006288Z,2025-09-24T19:43:07.948803677Z,160,1,432669,C,A,64.800000000,1,26,8058566374356,0,14607,94391782,CLX5
2025-09-24T19:43:07.950006288Z,2025-09-24T19:43:07.948803677Z,160,1,432669,M,A,64.800000000,1,26,8058566373208,128,14607,94391782,CLX5
2025-09-24T19:43:07.950611663Z,2025-09-24T19:43:07.949795851Z,160,1,432669,T,B,64.800000000,1,26,8058566373929,0,14562,94391811,CLX5
2025-09-24T19:43:07.950611663Z,2025-09-24T19:43:07.949795851Z,160,1,432669,F,B,64.800000000,1,26,8058566373929,0,14562,94391811,CLX5
2025-09-24T19:43:07.950611663Z,2025-09-24T19:43:07.949795851Z,160,1,432669,F,A,64.800000000,1,26,8058566373208,0,14562,94391811,CLX5
2025-09-24T19:43:07.950689365Z,2025-09-24T19:43:07.949795851Z,160,1,432669,C,B,64.790000000,2,26,8058566373929,0,19805,94391812,CLX5
2025-09-24T19:43:07.950689365Z,2025-09-24T19:43:07.949795851Z,160,1,432669,C,A,64.800000000,1,26,8058566373208,128,19805,94391812,CLX5
2025-09-24T19:43:07.951024372Z,2025-09-24T19:43:07.949961979Z,160,1,432669,T,B,64.800000000,1,26,8058566374425,0,14592,94391838,CLX5
2025-09-24T19:43:07.951024372Z,2025-09-24T19:43:07.949961979Z,160,1,432669,F,A,64.800000000,1,26,8058566374393,0,14592,94391838,CLX5
2025-09-24T19:43:07.951075549Z,2025-09-24T19:43:07.949961979Z,160,1,432669,C,A,64.800000000,1,26,8058566374393,128,14558,94391839,CLX5
2025-09-24T19:43:07.951266486Z,2025-09-24T19:43:07.950106609Z,160,1,432669,C,A,64.820000000,4,26,8058566354590,128,14534,94391850,CLX5
2025-09-24T19:43:07.951839761Z,2025-09-24T19:43:07.950846371Z,160,1,432669,M,B,64.790000000,3,26,8058566370556,128,17049,94391880,CLX5
2025-09-24T19:43:07.951885908Z,2025-09-24T19:43:07.951024769Z,160,1,432669,A,B,64.790000000,2,26,8058566374443,128,15619,94391882,CLX5
2025-09-24T19:43:07.951918062Z,2025-09-24T19:43:07.951024981Z,160,1,432669,A,B,64.790000000,1,26,8058566374444,128,14994,94391883,CLX5
2025-09-24T19:43:07.951975490Z,2025-09-24T19:43:07.951035847Z,160,1,432669,A,B,64.790000000,1,26,8058566374445,128,14781,94391886,CLX5
2025-09-24T19:43:07.952145547Z,2025-09-24T19:43:07.951301121Z,160,1,432669,A,A,64.810000000,1,26,8058566374447,128,18441,94391894,CLX5
2025-09-24T19:43:07.952240605Z,2025-09-24T19:43:07.951876385Z,160,1,432669,A,A,64.810000000,1,26,8058566374450,128,17971,94391900,CLX5
2025-09-24T19:43:07.952273980Z,2025-09-24T19:43:07.951925997Z,160,1,432669,C,B,64.790000000,1,26,8058566374445,128,14836,94391901,CLX5
2025-09-24T19:43:07.952303294Z,2025-09-24T19:43:07.951948499Z,160,1,432669,A,A,64.810000000,1,26,8058566374451,128,14570,94391902,CLX5
2025-09-24T19:43:07.952472844Z,2025-09-24T19:43:07.952158403Z,160,1,432669,A,B,64.790000000,1,26,8058566374453,128,14674,94391911,CLX5
2025-09-24T19:43:07.952627926Z,2025-09-24T19:43:07.952500225Z,160,1,432669,C,A,64.810000000,1,26,8058566374451,128,18666,94391920,CLX5
2025-09-24T19:43:07.952652846Z,2025-09-24T19:43:07.952507289Z,160,1,432669,C,A,64.810000000,1,26,8058566374450,128,15386,94391921,CLX5
2025-09-24T19:43:07.952679978Z,2025-09-24T19:43:07.952516639Z,160,1,432669,C,A,64.810000000,1,26,8058566374447,128,15111,94391922,CLX5
2025-09-24T19:43:07.952844690Z,2025-09-24T19:43:07.952582551Z,160,1,432669,M,B,64.780000000,1,26,8058566374453,128,18490,94391929,CLX5
2025-09-24T19:43:07.953521147Z,2025-09-24T19:43:07.953394423Z,160,1,432669,M,B,64.790000000,1,26,8058566374453,128,19347,94391961,CLX5
2025-09-24T19:43:07.953672735Z,2025-09-24T19:43:07.953550783Z,160,1,432669,A,B,64.780000000,1,26,8058566374469,128,16520,94391964,CLX5
2025-09-24T19:43:07.957077069Z,2025-09-24T19:43:07.956952583Z,160,1,432669,C,B,64.790000000,4,26,8058566373792,128,19016,94391969,CLX5
2025-09-24T19:43:07.967105794Z,2025-09-24T19:43:07.966885401Z,160,1,432669,A,B,64.800000000,1,26,8058566374474,128,17960,94391988,CLX5
2025-09-24T19:43:07.967409806Z,2025-09-24T19:43:07.967168933Z,160,1,432669,A,B,64.800000000,1,26,8058566374476,128,13509,94391996,CLX5
2025-09-24T19:43:07.967438459Z,2025-09-24T19:43:07.967237705Z,160,1,432669,M,B,64.780000000,1,26,8058566374453,128,14783,94391999,CLX5
2025-09-24T19:43:08.067156000Z,2025-09-24T19:43:08.067068539Z,160,1,432669,A,B,64.550000000,1,26,8058566374518,128,14043,94392073,CLX5
2025-09-24T19:43:08.125138603Z,2025-09-24T19:43:08.124998063Z,160,1,432669,C,A,64.830000000,1,26,8058566374388,128,18257,94392120,CLX5
2025-09-24T19:43:08.141299378Z,2025-09-24T19:43:08.141154613Z,160,1,432669,A,B,64.780000000,1,26,8058566374540,128,18314,94392123,CLX5
2025-09-24T19:43:09.120027496Z,2025-09-24T19:43:09.119738989Z,160,1,432669,T,A,64.800000000,1,26,8058566374580,0,17995,94392189,CLX5
2025-09-24T19:43:09.120027496Z,2025-09-24T19:43:09.119738989Z,160,1,432669,F,B,64.800000000,1,26,8058566374474,0,17995,94392189,CLX5
2025-09-24T19:43:09.120036320Z,2025-09-24T19:43:09.119738989Z,160,1,432669,C,B,64.800000000,1,26,8058566374474,128,14324,94392190,CLX5
2025-09-24T19:43:09.120279633Z,2025-09-24T19:43:09.120038361Z,160,1,432669,T,A,64.800000000,1,26,8058566374581,0,18500,94392193,CLX5
2025-09-24T19:43:09.120279633Z,2025-09-24T19:43:09.120038361Z,160,1,432669,F,B,64.800000000,1,26,8058566374476,0,18500,94392193,CLX5
2025-09-24T19:43:09.120288533Z,2025-09-24T19:43:09.120038361Z,160,1,432669,C,B,64.800000000,1,26,8058566374476,128,14699,94392194,CLX5
2025-09-24T19:43:09.120455495Z,2025-09-24T19:43:09.120259209Z,160,1,432669,A,B,64.800000000,4,26,8058566374583,128,14707,94392200,CLX5
2025-09-24T19:43:09.120495767Z,2025-09-24T19:43:09.120292423Z,160,1,432669,C,B,64.550000000,1,26,8058566374518,128,14445,94392204,CLX5
2025-09-24T19:43:09.120717001Z,2025-09-24T19:43:09.120480787Z,160,1,432669,T,A,64.800000000,1,26,8058566374585,0,18858,94392208,CLX5
2025-09-24T19:43:09.120717001Z,2025-09-24T19:43:09.120480787Z,160,1,432669,F,B,64.800000000,1,26,8058566374583,0,18858,94392208,CLX5
2025-09-24T19:43:09.120726270Z,2025-09-24T19:43:09.120480787Z,160,1,432669,M,B,64.800000000,3,26,8058566374583,128,14391,94392209,CLX5
2025-09-24T19:43:09.128838659Z,2025-09-24T19:43:09.128673871Z,160,1,432669,A,B,64.800000000,1,26,8058566374590,128,21873,94392221,CLX5
2025-09-24T19:43:09.128968628Z,2025-09-24T19:43:09.128824875Z,160,1,432669,A,B,64.800000000,1,26,8058566374591,128,22733,94392222,CLX5
2025-09-24T19:43:09.129958881Z,2025-09-24T19:43:09.129821327Z,160,1,432669,A,B,64.800000000,1,26,8058566374593,128,20373,94392224,CLX5
2025-09-24T19:43:09.152928310Z,2025-09-24T19:43:09.152632821Z,160,1,432669,A,B,64.770000000,1,26,8058566374603,128,14758,94392260,CLX5
2025-09-24T19:43:09.153119732Z,2025-09-24T19:43:09.152851269Z,160,1,432669,A,B,64.800000000,2,26,8058566374606,128,19256,94392268,CLX5
2025-09-24T19:43:09.171185184Z,2025-09-24T19:43:09.171033615Z,160,1,432669,M,B,64.800000000,2,26,8058566374583,128,19372,94392286,CLX5
2025-09-24T19:43:09.233910081Z,2025-09-24T19:43:09.233759973Z,160,1,432669,C,B,64.800000000,2,26,8058566374583,128,19871,94392295,CLX5
2025-09-24T19:43:09.234065049Z,2025-09-24T19:43:09.233926737Z,160,1,432669,C,B,64.800000000,2,26,8058566374606,128,18131,94392296,CLX5
2025-09-24T19:43:09.267136406Z,2025-09-24T19:43:09.267024885Z,160,1,432669,A,B,64.550000000,1,26,8058566374614,128,17900,94392299,CLX5
2025-09-24T19:43:09.313097294Z,2025-09-24T19:43:09.312958341Z,160,1,432669,A,B,64.760000000,2,26,8058566374618,128,18510,94392307,CLX5
2025-09-24T19:43:10.013787296Z,2025-09-24T19:43:10.013636229Z,160,1,432669,A,B,64.790000000,1,26,8058566374625,128,18592,94392319,CLX5
2025-09-24T19:43:10.024102185Z,2025-09-24T19:43:10.023963527Z,160,1,432669,A,A,64.840000000,1,26,8058566374626,128,17873,94392320,CLX5
2025-09-24T19:43:10.046079314Z,2025-09-24T19:43:10.045927913Z,160,1,432669,C,B,64.800000000,1,26,8058566374593,128,18012,94392326,CLX5
2025-09-24T19:43:10.345272327Z,2025-09-24T19:43:10.345098651Z,160,1,432669,A,B,64.800000000,1,26,8058566374637,128,14530,94392346,CLX5
2025-09-24T19:43:10.345576831Z,2025-09-24T19:43:10.345320439Z,160,1,432669,T,A,64.800000000,2,26,8058566374639,0,17882,94392353,CLX5
2025-09-24T19:43:10.345576831Z,2025-09-24T19:43:10.345320439Z,160,1,432669,F,B,64.800000000,1,26,8058566374590,0,17882,94392353,CLX5
2025-09-24T19:43:10.345576831Z,2025-09-24T19:43:10.345320439Z,160,1,432669,F,B,64.800000000,1,26,8058566374591,0,17882,94392353,CLX5
2025-09-24T19:43:10.345587014Z,2025-09-24T19:43:10.345320439Z,160,1,432669,C,B,64.800000000,1,26,8058566374590,0,14885,94392354,CLX5
2025-09-24T19:43:10.345587014Z,2025-09-24T19:43:10.345320439Z,160,1,432669,C,B,64.800000000,1,26,8058566374591,128,14885,94392354,CLX5
2025-09-24T19:43:10.345730646Z,2025-09-24T19:43:10.345553883Z,160,1,432669,C,B,64.800000000,1,26,8058566374637,128,13775,94392359,CLX5
2025-09-24T19:43:10.345945889Z,2025-09-24T19:43:10.345734183Z,160,1,432669,C,B,64.550000000,1,26,8058566374614,128,14984,94392371,CLX5
2025-09-24T19:43:10.346447881Z,2025-09-24T19:43:10.346188743Z,160,1,432669,C,B,64.770000000,1,26,8058566374603,128,14674,94392389,CLX5
2025-09-24T19:43:10.346864031Z,2025-09-24T19:43:10.346474253Z,160,1,432669,A,B,64.770000000,1,26,8058566374654,128,14779,94392409,CLX5
2025-09-24T19:43:10.347004583Z,2025-09-24T19:43:10.346672713Z,160,1,432669,A,B,64.790000000,1,26,8058566374657,128,14841,94392419,CLX5
2025-09-24T19:43:10.348821153Z,2025-09-24T19:43:10.348693597Z,160,1,432669,C,B,64.760000000,2,26,8058566374618,128,18496,94392445,CLX5
2025-09-24T19:43:10.423872563Z,2025-09-24T19:43:10.423737513Z,160,1,432669,A,B,64.790000000,1,26,8058566374666,128,17558,94392459,CLX5
2025-09-24T19:43:10.424004207Z,2025-09-24T19:43:10.423886191Z,160,1,432669,C,B,64.790000000,1,26,8058566374666,128,18151,94392460,CLX5
2025-09-24T19:43:10.424517888Z,2025-09-24T19:43:10.424391397Z,160,1,432669,A,B,64.790000000,1,26,8058566374667,128,18178,94392461,CLX5
2025-09-24T19:43:10.467524916Z,2025-09-24T19:43:10.467412337Z,160,1,432669,A,B,62.950000000,1,26,8058566374668,128,18416,94392463,CLX5
2025-09-24T19:43:10.480046298Z,2025-09-24T19:43:10.479931951Z,160,1,432669,A,B,63.240000000,1,26,8058566374669,128,18194,94392464,CLX5
2025-09-24T19:43:10.612811701Z,2025-09-24T19:43:10.612671963Z,160,1,432669,A,B,64.760000000,2,26,8058566374675,128,18061,94392472,CLX5
2025-09-24T19:43:10.612837304Z,2025-09-24T19:43:10.612674825Z,160,1,432669,A,B,64.750000000,2,26,8058566374676,128,14318,94392473,CLX5
2025-09-24T19:43:11.119889231Z,2025-09-24T19:43:11.119744551Z,160,1,432669,A,B,64.770000000,1,26,8058566374682,128,18652,94392491,CLX5
2025-09-24T19:43:11.122562606Z,2025-09-24T19:43:11.122420395Z,160,1,432669,A,B,64.790000000,4,26,8058566374683,128,18373,94392492,CLX5
2025-09-24T19:43:11.122726573Z,2025-09-24T19:43:11.122588117Z,160,1,432669,C,B,64.790000000,1,26,8058566374667,128,14649,94392495,CLX5
2025-09-24T19:43:11.586289267Z,2025-09-24T19:43:11.586152587Z,160,1,432669,C,B,64.790000000,4,26,8058566374683,128,18602,94392514,CLX5
2025-09-24T19:43:12.140094198Z,2025-09-24T19:43:12.139885435Z,160,1,432669,A,B,64.800000000,1,26,8058566374744,128,16201,94392705,CLX5
2025-09-24T19:43:12.140431678Z,2025-09-24T19:43:12.139924647Z,160,1,432669,A,B,64.800000000,2,26,8058566374748,128,14506,94392717,CLX5
2025-09-24T19:43:12.140450332Z,2025-09-24T19:43:12.139924825Z,160,1,432669,C,A,64.810000000,2,26,8058566372438,128,15849,94392719,CLX5
2025-09-24T19:43:12.140522182Z,2025-09-24T19:43:12.139924973Z,160,1,432669,A,B,64.800000000,2,26,8058566374749,128,22543,94392721,CLX5
2025-09-24T19:43:12.140558852Z,2025-09-24T19:43:12.139925153Z,160,1,432669,A,B,64.800000000,3,26,8058566374750,128,18532,94392722,CLX5
2025-09-24T19:43:12.140597542Z,2025-09-24T19:43:12.139946001Z,160,1,432669,C,B,64.800000000,2,26,8058566374749,128,16839,94392723,CLX5
2025-09-24T19:43:12.140672011Z,2025-09-24T19:43:12.140102761Z,160,1,432669,A,B,64.800000000,1,26,8058566374752,128,16767,94392727,CLX5
2025-09-24T19:43:12.140787858Z,2025-09-24T19:43:12.140182939Z,160,1,432669,A,B,64.800000000,1,26,8058566374755,128,16171,94392732,CLX5
2025-09-24T19:43:12.142402139Z,2025-09-24T19:43:12.142255487Z,160,1,432669,C,B,64.800000000,3,26,8058566374750,128,13902,94392833,CLX5
2025-09-24T19:43:12.142705484Z,2025-09-24T19:43:12.142566859Z,160,1,432669,C,B,64.800000000,1,26,8058566374752,128,19688,94392843,CLX5
2025-09-24T19:43:12.143226229Z,2025-09-24T19:43:12.143091705Z,160,1,432669,C,B,64.800000000,2,26,8058566374748,128,18118,94392846,CLX5
2025-09-24T19:43:12.180080455Z,2025-09-24T19:43:12.179971317Z,160,1,432669,C,B,63.240000000,1,26,8058566374669,128,18715,94392880,CLX5
2025-09-24T19:43:12.185158903Z,2025-09-24T19:43:12.185022691Z,160,1,432669,A,B,64.740000000,1,26,8058566374787,128,18484,94392881,CLX5
2025-09-24T19:43:12.267152165Z,2025-09-24T19:43:12.267057189Z,160,1,432669,A,B,64.550000000,1,26,8058566374798,128,17704,94392900,CLX5
2025-09-24T19:43:12.289820009Z,2025-09-24T19:43:12.289528377Z,160,1,432669,A,B,64.770000000,1,26,8058566374806,128,13664,94392922,CLX5
2025-09-24T19:43:12.290048654Z,2025-09-24T19:43:12.289826539Z,160,1,432669,A,B,64.800000000,2,26,8058566374809,128,14572,94392934,CLX5
2025-09-24T19:43:12.300579071Z,2025-09-24T19:43:12.300426007Z,160,1,432669,C,B,64.800000000,2,26,8058566374809,128,18231,94392951,CLX5
2025-09-24T19:43:13.508813101Z,2025-09-24T19:43:13.508502731Z,160,1,432669,T,A,64.800000000,1,26,8058566374855,0,18330,94393023,CLX5
2025-09-24T19:43:13.508813101Z,2025-09-24T19:43:13.508502731Z,160,1,432669,F,B,64.800000000,1,26,8058566374744,0,18330,94393023,CLX5
2025-09-24T19:43:13.508823392Z,2025-09-24T19:43:13.508502731Z,160,1,432669,C,B,64.800000000,1,26,8058566374744,128,16051,94393024,CLX5
2025-09-24T19:43:14.976190921Z,2025-09-24T19:43:14.976064277Z,160,1,432669,A,A,65.000000000,2,26,8058566374865,128,19556,94393072,CLX5
2025-09-24T19:43:15.903443561Z,2025-09-24T19:43:15.903286225Z,160,1,432669,M,B,64.710000000,35,26,8058566342993,128,18100,94393211,CLX5
2025-09-24T19:43:16.748171685Z,2025-09-24T19:43:16.747832571Z,160,1,432669,T,A,64.800000000,1,26,8058566374949,0,19049,94393279,CLX5
2025-09-24T19:43:16.748171685Z,2025-09-24T19:43:16.747832571Z,160,1,432669,F,B,64.800000000,1,26,8058566374755,0,19049,94393279,CLX5
2025-09-24T19:43:16.748184055Z,2025-09-24T19:43:16.747832571Z,160,1,432669,C,B,64.800000000,1,26,8058566374755,128,17794,94393280,CLX5
2025-09-24T19:43:16.748319294Z,2025-09-24T19:43:16.748182281Z,160,1,432669,C,B,64.790000000,1,26,8058566373022,128,18105,94393283,CLX5
2025-09-24T19:43:16.748374511Z,2025-09-24T19:43:16.748188963Z,160,1,432669,C,B,64.550000000,1,26,8058566374798,128,14745,94393285,CLX5
2025-09-24T19:43:16.749474736Z,2025-09-24T19:43:16.748812995Z,160,1,432669,C,B,64.770000000,1,26,8058566374806,128,14912,94393315,CLX5
2025-09-24T19:43:16.811993163Z,2025-09-24T19:43:16.811859155Z,160,1,432669,C,B,64.760000000,2,26,8058566374675,128,18391,94393426,CLX5
2025-09-24T19:43:16.818896345Z,2025-09-24T19:43:16.818786555Z,160,1,432669,C,A,65.480000000,2,26,8058566374206,128,14727,94393430,CLX5
2025-09-24T19:43:16.880061848Z,2025-09-24T19:43:16.879946919Z,160,1,432669,A,B,63.240000000,1,26,8058566374987,128,18602,94393442,CLX5
2025-09-24T19:43:16.898434519Z,2025-09-24T19:43:16.898195695Z,160,1,432669,A,A,64.800000000,2,26,8058566374994,128,18440,94393459,CLX5
2025-09-24T19:43:16.899362146Z,2025-09-24T19:43:16.898571171Z,160,1,432669,M,A,64.800000000,1,26,8058566374626,128,15021,94393512,CLX5
2025-09-24T19:43:16.899426017Z,2025-09-24T19:43:16.898761455Z,160,1,432669,M,A,64.820000000,4,26,8058566275289,128,15079,94393517,CLX5
2025-09-24T19:43:16.900209620Z,2025-09-24T19:43:16.899428779Z,160,1,432669,A,A,64.800000000,1,26,8058566375018,128,15565,94393557,CLX5
2025-09-24T19:43:16.900390451Z,2025-09-24T19:43:16.899482517Z,160,1,432669,A,A,64.830000000,1,26,8058566375021,128,16973,94393565,CLX5
2025-09-24T19:43:16.980078831Z,2025-09-24T19:43:16.979977713Z,160,1,432669,C,A,66.360000000,1,26,8058566227548,128,18294,94393746,CLX5
2025-09-24T19:43:16.987876410Z,2025-09-24T19:43:16.987730025Z,160,1,432669,C,A,64.800000000,1,26,8058566375018,128,18959,94393749,CLX5
2025-09-24T19:43:17.067203891Z,2025-09-24T19:43:17.067082967Z,160,1,432669,A,A,65.050000000,1,26,8058566375109,128,23366,94393807,CLX5
2025-09-24T19:43:17.449691935Z,2025-09-24T19:43:17.448359513Z,160,1,432669,C,A,64.800000000,2,26,8058566374994,128,14925,94394103,CLX5
2025-09-24T19:43:17.451086427Z,2025-09-24T19:43:17.449724687Z,160,1,432669,T,B,64.800000000,1,26,8058566375221,0,17932,94394191,CLX5
2025-09-24T19:43:17.451086427Z,2025-09-24T19:43:17.449724687Z,160,1,432669,F,A,64.800000000,1,26,8058566374626,0,17932,94394191,CLX5
2025-09-24T19:43:17.451145491Z,2025-09-24T19:43:17.449724687Z,160,1,432669,C,A,64.800000000,1,26,8058566374626,128,14952,94394192,CLX5
2025-09-24T19:43:17.452373643Z,2025-09-24T19:43:17.451101881Z,160,1,432669,A,B,64.770000000,1,26,8058566375244,128,15315,94394268,CLX5
2025-09-24T19:43:17.452546848Z,2025-09-24T19:43:17.451109905Z,160,1,432669,A,B,64.790000000,1,26,8058566375245,128,15694,94394278,CLX5
2025-09-24T19:43:17.452943638Z,2025-09-24T19:43:17.451148843Z,160,1,432669,C,A,65.050000000,1,26,8058566375109,128,14754,94394303,CLX5
2025-09-24T19:43:17.453125345Z,2025-09-24T19:43:17.451329507Z,160,1,432669,C,A,64.820000000,4,26,8058566275289,128,15047,94394312,CLX5
2025-09-24T19:43:17.453237067Z,2025-09-24T19:43:17.451566155Z,160,1,432669,M,B,64.790000000,1,26,8058566374453,128,15709,94394318,CLX5
2025-09-24T19:43:17.453320959Z,2025-09-24T19:43:17.451652935Z,160,1,432669,C,A,64.830000000,1,26,8058566375021,128,14871,94394322,CLX5
2025-09-24T19:43:17.454008068Z,2025-09-24T19:43:17.452717607Z,160,1,432669,M,A,64.830000000,3,26,8058566373687,128,15055,94394361,CLX5
2025-09-24T19:43:17.463458934Z,2025-09-24T19:43:17.463326999Z,160,1,432669,C,B,64.790000000,1,26,8058566375245,128,18518,94394457,CLX5
2025-09-24T19:43:17.464080882Z,2025-09-24T19:43:17.463927013Z,160,1,432669,M,B,64.780000000,1,26,8058566374453,128,18602,94394478,CLX5
2025-09-24T19:43:17.470151880Z,2025-09-24T19:43:17.470046761Z,160,1,432669,A,A,65.950000000,3,26,8058566375302,128,19247,94394496,CLX5
2025-09-24T19:43:17.580525969Z,2025-09-24T19:43:17.580415571Z,160,1,432669,A,A,66.360000000,1,26,8058566375430,128,18874,94394709,CLX5
2025-09-24T19:43:17.635190216Z,2025-09-24T19:43:17.635051773Z,160,1,432669,C,B,64.770000000,1,26,8058566375244,128,18541,94394758,CLX5
2025-09-24T19:43:18.360071840Z,2025-09-24T19:43:18.359918311Z,160,1,432669,A,B,64.790000000,1,26,8058566375550,128,18653,94394926,CLX5
2025-09-24T19:43:19.085183259Z,2025-09-24T19:43:19.085021257Z,160,1,432669,A,A,64.810000000,1,26,8058566375561,128,19093,94394959,CLX5
2025-09-24T19:43:19.518667231Z,2025-09-24T19:43:19.518554799Z,160,1,432669,A,A,65.480000000,2,26,8058566375572,128,19149,94395034,CLX5
2025-09-24T19:43:20.560503440Z,2025-09-24T19:43:20.560303317Z,160,1,432669,A,B,64.790000000,1,26,8058566375595,128,14992,94395090,CLX5
2025-09-24T19:43:21.428057288Z,2025-09-24T19:43:21.427594019Z,160,1,432669,T,A,64.790000000,1,26,8058566375603,0,19392,94395122,CLX5
2025-09-24T19:43:21.428057288Z,2025-09-24T19:43:21.427594019Z,160,1,432669,F,B,64.790000000,1,26,8058564297544,0,19392,94395122,CLX5
2025-09-24T19:43:21.428072947Z,2025-09-24T19:43:21.427594019Z,160,1,432669,T,A,64.790000000,2,26,8058565496184,0,15986,94395123,CLX5
2025-09-24T19:43:21.428072947Z,2025-09-24T19:43:21.427594019Z,160,1,432669,F,B,64.790000000,1,26,8058564297544,0,15986,94395123,CLX5
2025-09-24T19:43:21.428072947Z,2025-09-24T19:43:21.427594019Z,160,1,432669,F,B,64.790000000,1,26,8058564363073,0,15986,94395123,CLX5
2025-09-24T19:43:21.428072947Z,2025-09-24T19:43:21.427594019Z,160,1,432669,C,B,64.790000000,2,26,8058564297544,0,15986,94395123,CLX5
2025-09-24T19:43:21.428072947Z,2025-09-24T19:43:21.427594019Z,160,1,432669,M,B,64.790000000,1,26,8058564363073,128,15986,94395123,CLX5
2025-09-24T19:43:21.438437937Z,2025-09-24T19:43:21.438297087Z,160,1,432669,A,B,64.790000000,1,26,8058566375621,128,18663,94395184,CLX5
2025-09-24T19:43:21.643394666Z,2025-09-24T19:43:21.643250717Z,160,1,432669,A,B,64.790000000,4,26,8058566375638,128,19123,94395204,CLX5
2025-09-24T19:43:21.645380295Z,2025-09-24T19:43:21.645249753Z,160,1,432669,C,B,64.790000000,4,26,8058566375638,128,19148,94395206,CLX5
2025-09-24T19:43:22.409227046Z,2025-09-24T19:43:22.409072657Z,160,1,432669,C,B,64.790000000,1,26,8058566375550,128,20033,94395214,CLX5
2025-09-24T19:43:23.420271046Z,2025-09-24T19:43:23.420115533Z,160,1,432669,A,B,64.790000000,1,26,8058566375642,128,20422,94395244,CLX5
2025-09-24T19:43:23.425388516Z,2025-09-24T19:43:23.425250211Z,160,1,432669,A,B,64.790000000,4,26,8058566375644,128,17928,94395248,CLX5
2025-09-24T19:43:23.941648302Z,2025-09-24T19:43:23.941499485Z,160,1,432669,A,B,64.790000000,3,26,8058566375645,128,20876,94395249,CLX5
2025-09-24T19:43:24.847655405Z,2025-09-24T19:43:24.847304585Z,160,1,432669,T,A,64.790000000,1,26,8058566375647,0,22654,94395254,CLX5
2025-09-24T19:43:24.847655405Z,2025-09-24T19:43:24.847304585Z,160,1,432669,F,B,64.790000000,1,26,8058564363073,0,22654,94395254,CLX5
2025-09-24T19:43:24.847666172Z,2025-09-24T19:43:24.847304585Z,160,1,432669,C,B,64.790000000,1,26,8058564363073,128,16237,94395255,CLX5
2025-09-24T19:43:24.851056238Z,2025-09-24T19:43:24.850918309Z,160,1,432669,C,B,64.790000000,4,26,8058566375644,128,18335,94395277,CLX5
2025-09-24T19:43:24.854449215Z,2025-09-24T19:43:24.854314851Z,160,1,432669,A,B,64.790000000,4,26,8058566375655,128,18587,94395278,CLX5
2025-09-24T19:43:24.857934155Z,2025-09-24T19:43:24.857799957Z,160,1,432669,A,B,64.790000000,1,26,8058566375656,128,18552,94395279,CLX5
2025-09-24T19:43:24.904440206Z,2025-09-24T19:43:24.904329047Z,160,1,432669,A,B,64.510000000,1,26,8058566375658,128,17635,94395281,CLX5
2025-09-24T19:43:29.421946334Z,2025-09-24T19:43:29.421594081Z,160,1,432669,A,B,64.770000000,1,26,8058566375676,128,18613,94395347,CLX5
2025-09-24T19:43:29.422324469Z,2025-09-24T19:43:29.421971595Z,160,1,432669,A,B,64.800000000,2,26,8058566375679,128,21243,94395359,CLX5
2025-09-24T19:43:29.422585069Z,2025-09-24T19:43:29.422324839Z,160,1,432669,A,B,64.800000000,1,26,8058566375682,128,18083,94395371,CLX5
2025-09-24T19:43:29.422639648Z,2025-09-24T19:43:29.422383551Z,160,1,432669,A,B,64.800000000,1,26,8058566375684,128,18150,94395374,CLX5
2025-09-24T19:43:29.422710999Z,2025-09-24T19:43:29.422517657Z,160,1,432669,A,A,64.840000000,1,26,8058566375686,128,14633,94395377,CLX5
2025-09-24T19:43:29.480112358Z,2025-09-24T19:43:29.480003723Z,160,1,432669,C,B,63.240000000,1,26,8058566374987,128,19350,94395388,CLX5
2025-09-24T19:43:29.480291846Z,2025-09-24T19:43:29.480163651Z,160,1,432669,A,A,64.810000000,1,26,8058566375688,128,18288,94395389,CLX5
2025-09-24T19:43:29.480449254Z,2025-09-24T19:43:29.480307473Z,160,1,432669,C,B,64.800000000,1,26,8058566375682,128,14449,94395391,CLX5
2025-09-24T19:43:29.480480088Z,2025-09-24T19:43:29.480327169Z,160,1,432669,A,A,64.810000000,1,26,8058566375689,128,13915,94395393,CLX5
2025-09-24T19:43:29.480606440Z,2025-09-24T19:43:29.480465077Z,160,1,432669,C,B,64.800000000,2,26,8058566375679,128,16219,94395395,CLX5
2025-09-24T19:43:29.480625194Z,2025-09-24T19:43:29.480482337Z,160,1,432669,A,A,64.810000000,1,26,8058566375691,128,15974,94395397,CLX5
2025-09-24T19:43:29.489267921Z,2025-09-24T19:43:29.488967575Z,160,1,432669,T,A,64.800000000,1,26,8058566375703,0,17579,94395460,CLX5
2025-09-24T19:43:29.489267921Z,2025-09-24T19:43:29.488967575Z,160,1,432669,F,B,64.800000000,1,26,8058566375684,0,17579,94395460,CLX5
2025-09-24T19:43:29.489277589Z,2025-09-24T19:43:29.488967575Z,160,1,432669,C,B,64.800000000,1,26,8058566375684,128,14761,94395461,CLX5
2025-09-24T19:43:29.492920199Z,2025-09-24T19:43:29.492781353Z,160,1,432669,C,B,64.790000000,4,26,8058566375655,128,17951,94395485,CLX5
2025-09-24T19:43:29.493089503Z,2025-09-24T19:43:29.492950901Z,160,1,432669,C,A,64.810000000,1,26,8058566375691,128,14291,94395487,CLX5
2025-09-24T19:43:29.493117649Z,2025-09-24T19:43:29.492962249Z,160,1,432669,C,A,64.810000000,1,26,8058566375689,128,14524,94395488,CLX5
2025-09-24T19:43:29.493145503Z,2025-09-24T19:43:29.492967087Z,160,1,432669,C,A,64.810000000,1,26,8058566375688,128,14867,94395489,CLX5
2025-09-24T19:43:29.605254801Z,2025-09-24T19:43:29.605117287Z,160,1,432669,C,B,64.770000000,1,26,8058566375676,128,17863,94395503,CLX5
2025-09-24T19:43:29.607443210Z,2025-09-24T19:43:29.607304319Z,160,1,432669,A,B,64.790000000,4,26,8058566375720,128,18340,94395505,CLX5
2025-09-24T19:43:29.680108987Z,2025-09-24T19:43:29.679997803Z,160,1,432669,A,B,63.240000000,1,26,8058566375724,128,18529,94395510,CLX5
2025-09-24T19:43:30.025266271Z,2025-09-24T19:43:30.024281599Z,160,1,432669,A,A,64.850000000,1,26,8058566375726,128,22730,94395512,CLX5
2025-09-24T19:43:31.571690255Z,2025-09-24T19:43:31.571305587Z,160,1,432669,T,B,64.810000000,3,26,8058566375823,0,18194,94395718,CLX5
2025-09-24T19:43:31.571690255Z,2025-09-24T19:43:31.571305587Z,160,1,432669,F,A,64.810000000,1,26,8058566372355,0,18194,94395718,CLX5
2025-09-24T19:43:31.571690255Z,2025-09-24T19:43:31.571305587Z,160,1,432669,F,A,64.810000000,1,26,8058566372362,0,18194,94395718,CLX5
2025-09-24T19:43:31.571690255Z,2025-09-24T19:43:31.571305587Z,160,1,432669,F,A,64.810000000,1,26,8058566372366,0,18194,94395718,CLX5
2025-09-24T19:43:31.571704386Z,2025-09-24T19:43:31.571305587Z,160,1,432669,C,A,64.810000000,1,26,8058566372355,0,16704,94395719,CLX5
2025-09-24T19:43:31.571704386Z,2025-09-24T19:43:31.571305587Z,160,1,432669,C,A,64.810000000,1,26,8058566372362,0,16704,94395719,CLX5
2025-09-24T19:43:31.571704386Z,2025-09-24T19:43:31.571305587Z,160,1,432669,C,A,64.810000000,1,26,8058566372366,128,16704,94395719,CLX5
2025-09-24T19:43:31.571966783Z,2025-09-24T19:43:31.571639387Z,160,1,432669,A,B,64.800000000,2,26,8058566375826,128,17990,94395722,CLX5
2025-09-24T19:43:31.573020938Z,2025-09-24T19:43:31.572025807Z,160,1,432669,A,B,64.800000000,1,26,8058566375838,128,18601,94395770,CLX5
2025-09-24T19:43:31.580545653Z,2025-09-24T19:43:31.580443655Z,160,1,432669,C,B,63.240000000,1,26,8058566375724,128,17898,94395915,CLX5
2025-09-24T19:43:31.585785197Z,2025-09-24T19:43:31.585617867Z,160,1,432669,A,B,64.800000000,1,26,8058566375849,128,21650,94395932,CLX5
2025-09-24T19:43:31.712916987Z,2025-09-24T19:43:31.712779865Z,160,1,432669,A,B,64.760000000,2,26,8058566375867,128,18015,94395974,CLX5
2025-09-24T19:43:31.741324218Z,2025-09-24T19:43:31.741206437Z,160,1,432669,A,A,66.160000000,4,26,8058566375873,128,18332,94395985,CLX5
2025-09-24T19:43:31.767243205Z,2025-09-24T19:43:31.767124583Z,160,1,432669,A,B,64.550000000,1,26,8058566375878,128,19046,94395991,CLX5
2025-09-24T19:43:32.323660916Z,2025-09-24T19:43:32.323508903Z,160,1,432669,C,B,64.790000000,1,26,8058566375642,128,18402,94396019,CLX5
2025-09-24T19:43:32.600184565Z,2025-09-24T19:43:32.600008531Z,160,1,432669,C,B,64.800000000,1,26,8058566375838,128,19375,94396020,CLX5
2025-09-24T19:43:32.929817221Z,2025-09-24T19:43:32.929487837Z,160,1,432669,T,A,64.800000000,1,26,8058566375898,0,18923,94396025,CLX5
2025-09-24T19:43:32.929817221Z,2025-09-24T19:43:32.929487837Z,160,1,432669,F,B,64.800000000,1,26,8058566375826,0,18923,94396025,CLX5
2025-09-24T19:43:32.929826513Z,2025-09-24T19:43:32.929487837Z,160,1,432669,M,B,64.800000000,1,26,8058566375826,128,14753,94396026,CLX5
2025-09-24T19:43:32.929933198Z,2025-09-24T19:43:32.929780951Z,160,1,432669,C,B,64.800000000,1,26,8058566375826,128,17871,94396029,CLX5
2025-09-24T19:43:32.941305352Z,2025-09-24T19:43:32.941194271Z,160,1,432669,C,A,66.160000000,4,26,8058566375873,128,18280,94396045,CLX5
2025-09-24T19:43:33.547926585Z,2025-09-24T19:43:33.547632683Z,160,1,432669,T,A,64.800000000,1,26,8058566375912,0,17893,94396102,CLX5
2025-09-24T19:43:33.547926585Z,2025-09-24T19:43:33.547632683Z,160,1,432669,F,B,64.800000000,1,26,8058566375849,0,17893,94396102,CLX5
2025-09-24T19:43:33.547936891Z,2025-09-24T19:43:33.547632683Z,160,1,432669,C,B,64.800000000,1,26,8058566375849,128,15906,94396103,CLX5
2025-09-24T19:43:33.548066860Z,2025-09-24T19:43:33.547942345Z,160,1,432669,C,B,64.550000000,1,26,8058566375878,128,13992,94396107,CLX5
2025-09-24T19:43:33.548145338Z,2025-09-24T19:43:33.548010733Z,160,1,432669,A,A,64.810000000,1,26,8058566375914,128,14924,94396110,CLX5
2025-09-24T19:43:33.548215268Z,2025-09-24T19:43:33.548097531Z,160,1,432669,A,A,64.810000000,1,26,8058566375915,128,14615,94396112,CLX5
2025-09-24T19:43:33.548295413Z,2025-09-24T19:43:33.548177323Z,160,1,432669,A,A,64.810000000,1,26,8058566375916,128,17899,94396113,CLX5
2025-09-24T19:43:33.548896856Z,2025-09-24T19:43:33.548577069Z,160,1,432669,C,B,64.760000000,2,26,8058566375867,128,17485,94396123,CLX5
2025-09-24T19:43:33.552438186Z,2025-09-24T19:43:33.552295561Z,160,1,432669,C,B,64.790000000,4,26,8058566375720,128,17848,94396134,CLX5
2025-09-24T19:43:33.552599127Z,2025-09-24T19:43:33.552465857Z,160,1,432669,C,A,64.810000000,1,26,8058566375916,128,18431,94396135,CLX5
2025-09-24T19:43:33.552624378Z,2025-09-24T19:43:33.552479757Z,160,1,432669,C,A,64.810000000,1,26,8058566375915,128,14711,94396136,CLX5
2025-09-24T19:43:33.552651726Z,2025-09-24T19:43:33.552481485Z,160,1,432669,C,A,64.810000000,1,26,8058566375914,128,14603,94396137,CLX5
2025-09-24T19:43:33.680104662Z,2025-09-24T19:43:33.679993157Z,160,1,432669,A,B,63.240000000,1,26,8058566375925,128,20959,94396145,CLX5
2025-09-24T19:43:33.753320768Z,2025-09-24T19:43:33.753172185Z,160,1,432669,M,B,64.740000000,1,26,8058566194413,128,19810,94396148,CLX5
2025-09-24T19:43:34.347892495Z,2025-09-24T19:43:34.347741047Z,160,1,432669,A,B,64.790000000,1,26,8058566375931,128,18491,94396177,CLX5
2025-09-24T19:43:36.716027917Z,2025-09-24T19:43:36.715813703Z,160,1,432669,A,A,64.800000000,2,26,8058566375973,128,14542,94396318,CLX5
2025-09-24T19:43:36.716388144Z,2025-09-24T19:43:36.716174705Z,160,1,432669,M,A,64.800000000,1,26,8058566375726,128,13658,94396333,CLX5
2025-09-24T19:43:36.716479477Z,2025-09-24T19:43:36.716355713Z,160,1,432669,M,A,64.820000000,4,26,8058566375302,128,18526,94396337,CLX5
2025-09-24T19:43:36.716501296Z,2025-09-24T19:43:36.716359591Z,160,1,432669,C,A,64.810000000,1,26,8058566375561,128,14484,94396338,CLX5
2025-09-24T19:43:36.716876352Z,2025-09-24T19:43:36.716657833Z,160,1,432669,A,A,64.830000000,1,26,8058566375979,128,13438,94396341,CLX5
2025-09-24T19:43:36.718713526Z,2025-09-24T19:43:36.718613095Z,160,1,432669,C,A,65.480000000,2,26,8058566375572,128,18115,94396349,CLX5
2025-09-24T19:43:36.740557078Z,2025-09-24T19:43:36.740149645Z,160,1,432669,T,B,64.800000000,1,26,8058566375988,0,13621,94396411,CLX5
2025-09-24T19:43:36.740557078Z,2025-09-24T19:43:36.740149645Z,160,1,432669,F,A,64.800000000,1,26,8058566375973,0,13621,94396411,CLX5
2025-09-24T19:43:36.740557078Z,2025-09-24T19:43:36.740149645Z,160,1,432669,M,A,64.800000000,1,26,8058566375973,128,13621,94396411,CLX5
2025-09-24T19:43:36.740695909Z,2025-09-24T19:43:36.740236715Z,160,1,432669,T,B,64.800000000,2,26,8058566375991,0,18243,94396416,CLX5
2025-09-24T19:43:36.740695909Z,2025-09-24T19:43:36.740236715Z,160,1,432669,F,A,64.800000000,1,26,8058566375973,0,18243,94396416,CLX5
2025-09-24T19:43:36.740695909Z,2025-09-24T19:43:36.740236715Z,160,1,432669,F,A,64.800000000,1,26,8058566375726,0,18243,94396416,CLX5
2025-09-24T19:43:36.740706545Z,2025-09-24T19:43:36.740236715Z,160,1,432669,C,A,64.800000000,1,26,8058566375973,0,14896,94396417,CLX5
2025-09-24T19:43:36.740706545Z,2025-09-24T19:43:36.740236715Z,160,1,432669,C,A,64.800000000,1,26,8058566375726,128,14896,94396417,CLX5
2025-09-24T19:43:36.741538391Z,2025-09-24T19:43:36.740884955Z,160,1,432669,C,A,64.820000000,4,26,8058566375302,128,18711,94396457,CLX5
2025-09-24T19:43:36.741767750Z,2025-09-24T19:43:36.740949829Z,160,1,432669,A,B,64.790000000,3,26,8058566376004,128,17905,94396467,CLX5
2025-09-24T19:43:36.755216965Z,2025-09-24T19:43:36.755122779Z,160,1,432669,A,A,65.950000000,3,26,8058566376042,128,14220,94396622,CLX5
2025-09-24T19:43:36.766723174Z,2025-09-24T19:43:36.766571693Z,160,1,432669,A,A,64.810000000,1,26,8058566376054,128,18170,94396645,CLX5
2025-09-24T19:43:36.819003161Z,2025-09-24T19:43:36.818907719Z,160,1,432669,A,A,65.480000000,2,26,8058566376070,128,17987,94396673,CLX5
2025-09-24T19:43:36.843169485Z,2025-09-24T19:43:36.843040401Z,160,1,432669,C,B,64.790000000,3,26,8058566376004,128,15428,94396678,CLX5
2025-09-24T19:43:36.944567076Z,2025-09-24T19:43:36.944416785Z,160,1,432669,A,B,64.790000000,3,26,8058566376105,128,18493,94396744,CLX5
2025-09-24T19:43:36.975286116Z,2025-09-24T19:43:36.975155587Z,160,1,432669,C,A,64.830000000,1,26,8058566375979,128,17816,94396759,CLX5
2025-09-24T19:43:37.045932483Z,2025-09-24T19:43:37.045784989Z,160,1,432669,C,B,64.790000000,3,26,8058566376105,128,18753,94396762,CLX5
2025-09-24T19:43:37.147416249Z,2025-09-24T19:43:37.147194489Z,160,1,432669,A,B,64.800000000,3,26,8058566376117,128,18655,94396768,CLX5
2025-09-24T19:43:37.180238715Z,2025-09-24T19:43:37.179945693Z,160,1,432669,T,A,64.800000000,1,26,8058566376137,0,17535,94396813,CLX5
2025-09-24T19:43:37.180238715Z,2025-09-24T19:43:37.179945693Z,160,1,432669,F,B,64.800000000,1,26,8058566376117,0,17535,94396813,CLX5
2025-09-24T19:43:37.180247831Z,2025-09-24T19:43:37.179945693Z,160,1,432669,M,B,64.800000000,2,26,8058566376117,128,14421,94396814,CLX5
2025-09-24T19:43:37.180265349Z,2025-09-24T19:43:37.180030937Z,160,1,432669,C,B,63.240000000,1,26,8058566375925,128,14551,94396816,CLX5
2025-09-24T19:43:37.198229700Z,2025-09-24T19:43:37.198022673Z,160,1,432669,M,B,64.800000000,1,26,8058566376117,128,17523,94396863,CLX5
2025-09-24T19:43:37.250397546Z,2025-09-24T19:43:37.250245557Z,160,1,432669,C,B,64.800000000,1,26,8058566376117,128,18086,94396884,CLX5
2025-09-24T19:43:37.250581111Z,2025-09-24T19:43:37.250443559Z,160,1,432669,A,A,64.810000000,1,26,8058566376154,128,17675,94396887,CLX5
2025-09-24T19:43:37.250736961Z,2025-09-24T19:43:37.250617253Z,160,1,432669,A,A,64.810000000,1,26,8058566376155,128,18389,94396888,CLX5
2025-09-24T19:43:37.250887988Z,2025-09-24T19:43:37.250770099Z,160,1,432669,A,A,64.810000000,1,26,8058566376156,128,17765,94396889,CLX5
2025-09-24T19:43:37.380134441Z,2025-09-24T19:43:37.380023325Z,160,1,432669,A,B,63.240000000,1,26,8058566376164,128,17580,94396911,CLX5
2025-09-24T19:43:37.478659701Z,2025-09-24T19:43:37.478518933Z,160,1,432669,C,A,64.810000000,1,26,8058566376156,128,18538,94396914,CLX5
2025-09-24T19:43:37.478684606Z,2025-09-24T19:43:37.478533813Z,160,1,432669,C,A,64.810000000,1,26,8058566376155,128,14778,94396915,CLX5
2025-09-24T19:43:37.478711569Z,2025-09-24T19:43:37.478535253Z,160,1,432669,C,A,64.810000000,1,26,8058566376154,128,14365,94396916,CLX5
2025-09-24T19:43:37.569082933Z,2025-09-24T19:43:37.568934481Z,160,1,432669,A,A,64.840000000,2,26,8058566376166,128,18506,94396918,CLX5
2025-09-24T19:43:38.582874831Z,2025-09-24T19:43:38.582285719Z,160,1,432669,A,B,64.800000000,2,26,8058566376197,128,17645,94396977,CLX5
2025-09-24T19:43:38.583807472Z,2025-09-24T19:43:38.582933365Z,160,1,432669,A,B,64.800000000,1,26,8058566376211,128,14240,94397025,CLX5
2025-09-24T19:43:38.584382382Z,2025-09-24T19:43:38.583662203Z,160,1,432669,A,A,64.830000000,1,26,8058566376217,128,14516,94397062,CLX5
2025-09-24T19:43:38.593721317Z,2025-09-24T19:43:38.593566007Z,160,1,432669,M,B,64.790000000,35,26,8058566342993,128,18077,94397091,CLX5
2025-09-24T19:43:38.593876199Z,2025-09-24T19:43:38.593727183Z,160,1,432669,A,B,64.800000000,2,26,8058566376233,128,20405,94397092,CLX5
2025-09-24T19:43:38.593911970Z,2025-09-24T19:43:38.593729623Z,160,1,432669,A,B,64.800000000,1,26,8058566376234,128,17226,94397093,CLX5
2025-09-24T19:43:38.594438383Z,2025-09-24T19:43:38.594318481Z,160,1,432669,A,B,64.770000000,1,26,8058566376237,128,17576,94397097,CLX5
2025-09-24T19:43:38.594584541Z,2025-09-24T19:43:38.594442813Z,160,1,432669,A,B,64.800000000,2,26,8058566376239,128,20574,94397099,CLX5
2025-09-24T19:43:38.594612748Z,2025-09-24T19:43:38.594442989Z,160,1,432669,A,B,64.800000000,1,26,8058566376240,128,16039,94397100,CLX5
2025-09-24T19:43:38.595112667Z,2025-09-24T19:43:38.594584483Z,160,1,432669,A,B,64.800000000,1,26,8058566376247,128,18781,94397116,CLX5
2025-09-24T19:43:38.624543987Z,2025-09-24T19:43:38.624391571Z,160,1,432669,M,B,64.680000000,1,26,8058566194413,128,17537,94397212,CLX5
2025-09-24T19:43:38.680161485Z,2025-09-24T19:43:38.680056655Z,160,1,432669,C,B,63.240000000,1,26,8058566376164,128,18120,94397220,CLX5
2025-09-24T19:43:38.765294593Z,2025-09-24T19:43:38.765164155Z,160,1,432669,C,A,64.830000000,1,26,8058566376217,128,18052,94397247,CLX5
2025-09-24T19:43:38.767257106Z,2025-09-24T19:43:38.767157757Z,160,1,432669,A,B,64.550000000,1,26,8058566376294,128,18068,94397248,CLX5
2025-09-24T19:43:39.600174730Z,2025-09-24T19:43:39.600008719Z,160,1,432669,C,B,64.800000000,1,26,8058566376211,128,23248,94397271,CLX5
2025-09-24T19:43:40.023603931Z,2025-09-24T19:43:40.023450829Z,160,1,432669,A,A,64.850000000,1,26,8058566376307,128,21603,94397273,CLX5
2025-09-24T19:43:42.712953200Z,2025-09-24T19:43:42.712815313Z,160,1,432669,A,B,64.760000000,2,26,8058566376344,128,22060,94397445,CLX5
2025-09-24T19:43:43.033488858Z,2025-09-24T19:43:43.033342977Z,160,1,432669,C,B,64.760000000,2,26,8058566376344,128,22658,94397480,CLX5
2025-09-24T19:43:43.212953418Z,2025-09-24T19:43:43.212816215Z,160,1,432669,A,B,64.760000000,2,26,8058566376385,128,20012,94397557,CLX5
2025-09-24T19:43:43.499801375Z,2025-09-24T19:43:43.499485485Z,160,1,432669,T,A,64.800000000,1,26,8058566376391,0,21006,94397564,CLX5
2025-09-24T19:43:43.499801375Z,2025-09-24T19:43:43.499485485Z,160,1,432669,F,B,64.800000000,1,26,8058566376197,0,21006,94397564,CLX5
2025-09-24T19:43:43.499814815Z,2025-09-24T19:43:43.499485485Z,160,1,432669,M,B,64.800000000,1,26,8058566376197,128,17850,94397565,CLX5
2025-09-24T19:43:43.500028062Z,2025-09-24T19:43:43.499801735Z,160,1,432669,C,B,64.800000000,1,26,8058566376247,128,18343,94397570,CLX5
2025-09-24T19:43:43.500069378Z,2025-09-24T19:43:43.499801883Z,160,1,432669,C,B,64.800000000,1,26,8058566376240,128,20620,94397571,CLX5
2025-09-24T19:43:43.510075109Z,2025-09-24T19:43:43.509924353Z,160,1,432669,A,B,64.800000000,1,26,8058566376399,128,22126,94397582,CLX5
2025-09-24T19:43:44.895319341Z,2025-09-24T19:43:44.895197771Z,160,1,432669,A,A,65.000000000,1,26,8058566376405,128,18552,94397617,CLX5
2025-09-24T19:43:46.329817896Z,2025-09-24T19:43:46.329530539Z,160,1,432669,T,A,64.800000000,1,26,8058566376412,0,17491,94397655,CLX5
2025-09-24T19:43:46.329817896Z,2025-09-24T19:43:46.329530539Z,160,1,432669,F,B,64.800000000,1,26,8058566376197,0,17491,94397655,CLX5
2025-09-24T19:43:46.329828985Z,2025-09-24T19:43:46.329530539Z,160,1,432669,C,B,64.800000000,1,26,8058566376197,128,16116,94397656,CLX5
2025-09-24T19:43:46.355613709Z,2025-09-24T19:43:46.355451103Z,160,1,432669,C,B,64.800000000,1,26,8058566376399,128,19912,94397676,CLX5
2025-09-24T19:43:46.355774213Z,2025-09-24T19:43:46.355623473Z,160,1,432669,C,B,64.800000000,1,26,8058566376234,128,16497,94397678,CLX5
2025-09-24T19:43:46.517211088Z,2025-09-24T19:43:46.517066693Z,160,1,432669,C,B,64.780000000,1,26,8058566374469,128,19163,94397795,CLX5
2025-09-24T19:43:46.517236776Z,2025-09-24T19:43:46.517071299Z,160,1,432669,C,B,64.770000000,1,26,8058566374682,128,14375,94397796,CLX5
2025-09-24T19:43:46.517265152Z,2025-09-24T19:43:46.517079747Z,160,1,432669,C,B,64.780000000,1,26,8058566373651,128,14196,94397797,CLX5
2025-09-24T19:43:46.517394192Z,2025-09-24T19:43:46.517276883Z,160,1,432669,C,B,64.770000000,1,26,8058566374654,128,17657,94397798,CLX5
2025-09-24T19:43:46.689283425Z,2025-09-24T19:43:46.689120093Z,160,1,432669,A,B,64.800000000,2,26,8058566376475,128,21270,94397840,CLX5
2025-09-24T19:43:46.748754334Z,2025-09-24T19:43:46.748466459Z,160,1,432669,T,A,64.800000000,2,26,8058566376478,0,18311,94397845,CLX5
2025-09-24T19:43:46.748754334Z,2025-09-24T19:43:46.748466459Z,160,1,432669,F,B,64.800000000,2,26,8058566376233,0,18311,94397845,CLX5
2025-09-24T19:43:46.748766345Z,2025-09-24T19:43:46.748466459Z,160,1,432669,C,B,64.800000000,2,26,8058566376233,128,17238,94397846,CLX5
2025-09-24T19:43:46.748881646Z,2025-09-24T19:43:46.748728757Z,160,1,432669,C,B,64.800000000,2,26,8058566376239,128,17773,94397847,CLX5
2025-09-24T19:43:46.749595826Z,2025-09-24T19:43:46.749445749Z,160,1,432669,C,B,64.800000000,2,26,8058566376475,128,17961,94397853,CLX5
2025-09-24T19:43:46.749691237Z,2025-09-24T19:43:46.749598133Z,160,1,432669,C,B,64.550000000,1,26,8058566376294,128,19647,94397856,CLX5
2025-09-24T19:43:46.749768026Z,2025-09-24T19:43:46.749636703Z,160,1,432669,A,A,64.810000000,1,26,8058566376482,128,14884,94397858,CLX5
2025-09-24T19:43:46.749839991Z,2025-09-24T19:43:46.749719319Z,160,1,432669,A,A,64.810000000,1,26,8058566376483,128,18274,94397859,CLX5
2025-09-24T19:43:46.749916718Z,2025-09-24T19:43:46.749797765Z,160,1,432669,A,A,64.810000000,1,26,8058566376484,128,14823,94397860,CLX5
2025-09-24T19:43:46.750442786Z,2025-09-24T19:43:46.750194173Z,160,1,432669,C,B,64.770000000,1,26,8058566376237,128,13767,94397866,CLX5
2025-09-24T19:43:46.750474572Z,2025-09-24T19:43:46.750197283Z,160,1,432669,A,A,64.830000000,1,26,8058566376486,128,15203,94397867,CLX5
2025-09-24T19:43:46.880190973Z,2025-09-24T19:43:46.880083467Z,160,1,432669,A,B,63.240000000,1,26,8058566376516,128,18207,94397950,CLX5
2025-09-24T19:43:47.070328054Z,2025-09-24T19:43:47.070185069Z,160,1,432669,C,A,64.810000000,1,26,8058566376484,128,18460,94397986,CLX5
2025-09-24T19:43:47.070353397Z,2025-09-24T19:43:47.070192213Z,160,1,432669,C,A,64.810000000,1,26,8058566376483,128,14412,94397987,CLX5
2025-09-24T19:43:47.070381220Z,2025-09-24T19:43:47.070202637Z,160,1,432669,C,A,64.810000000,1,26,8058566376482,128,14595,94397988,CLX5
2025-09-24T19:43:47.623381314Z,2025-09-24T19:43:47.623225673Z,160,1,432669,A,B,64.770000000,1,26,8058566376562,128,18533,94398002,CLX5
2025-09-24T19:43:48.329929856Z,2025-09-24T19:43:48.329595359Z,160,1,432669,T,A,64.790000000,1,26,8058566376572,0,18230,94398030,CLX5
2025-09-24T19:43:48.329929856Z,2025-09-24T19:43:48.329595359Z,160,1,432669,F,B,64.790000000,1,26,8058564363614,0,18230,94398030,CLX5
2025-09-24T19:43:48.329942374Z,2025-09-24T19:43:48.329595359Z,160,1,432669,M,B,64.790000000,2,26,8058564363614,128,14946,94398031,CLX5
2025-09-24T19:43:49.004346431Z,2025-09-24T19:43:49.004005349Z,160,1,432669,C,A,64.830000000,1,26,8058566376486,128,15713,94398076,CLX5
2025-09-24T19:43:49.004385690Z,2025-09-24T19:43:49.004007865Z,160,1,432669,A,B,64.770000000,1,26,8058566376586,128,18410,94398077,CLX5
2025-09-24T19:43:49.004500008Z,2025-09-24T19:43:49.004192329Z,160,1,432669,A,B,64.800000000,2,26,8058566376588,128,16939,94398081,CLX5
2025-09-24T19:43:49.052891305Z,2025-09-24T19:43:49.052596389Z,160,1,432669,T,A,64.800000000,1,26,8058566376605,0,19681,94398160,CLX5
2025-09-24T19:43:49.052891305Z,2025-09-24T19:43:49.052596389Z,160,1,432669,F,B,64.800000000,1,26,8058566376588,0,19681,94398160,CLX5
2025-09-24T19:43:49.052900743Z,2025-09-24T19:43:49.052596389Z,160,1,432669,M,B,64.800000000,1,26,8058566376588,128,16132,94398161,CLX5
2025-09-24T19:43:49.080631859Z,2025-09-24T19:43:49.080523075Z,160,1,432669,C,B,63.240000000,1,26,8058566376516,128,19022,94398170,CLX5
2025-09-24T19:43:49.167346695Z,2025-09-24T19:43:49.167238237Z,160,1,432669,A,B,64.550000000,1,26,8058566376609,128,18852,94398179,CLX5
2025-09-24T19:43:49.209072233Z,2025-09-24T19:43:49.208918061Z,160,1,432669,C,B,64.800000000,1,26,8058566376588,128,18413,94398183,CLX5
2025-09-24T19:43:49.209167337Z,2025-09-24T19:43:49.209075803Z,160,1,432669,C,B,64.550000000,1,26,8058566376609,128,16136,94398186,CLX5
2025-09-24T19:43:49.209235716Z,2025-09-24T19:43:49.209110437Z,160,1,432669,A,A,64.810000000,1,26,8058566376612,128,14523,94398187,CLX5
