ts_recv,ts_event,rtype,publisher_id,instrument_id,action,side,price,size,channel_id,order_id,flags,ts_in_delta,sequence,symbol
2025-09-24T19:38:34.201129148Z,2025-09-24T19:38:34.200854091Z,160,1,432669,A,B,64.810000000,1,26,8058566353605,128,15991,94334095,CLX5
2025-09-24T19:38:34.207587451Z,2025-09-24T19:38:34.207440533Z,160,1,432669,C,B,64.810000000,1,26,8058566353605,128,19738,94334099,CLX5
2025-09-24T19:38:35.195850293Z,2025-09-24T19:38:35.195558327Z,160,1,432669,T,A,64.810000000,1,26,8058566353626,0,17995,94334151,CLX5
2025-09-24T19:38:35.195850293Z,2025-09-24T19:38:35.195558327Z,160,1,432669,F,B,64.810000000,1,26,8058566353501,0,17995,94334151,CLX5
2025-09-24T19:38:35.195862165Z,2025-09-24T19:38:35.195558327Z,160,1,432669,C,B,64.810000000,1,26,8058566353501,128,17090,94334152,CLX5
2025-09-24T19:38:35.569981034Z,2025-09-24T19:38:35.569818053Z,160,1,432669,C,B,64.810000000,1,26,8058566353602,128,22090,94334160,CLX5
2025-09-24T19:38:35.743865068Z,2025-09-24T19:38:35.743697603Z,160,1,432669,A,B,64.810000000,1,26,8058566353630,128,14695,94334180,CLX5
2025-09-24T19:38:35.743990606Z,2025-09-24T19:38:35.743849315Z,160,1,432669,A,B,64.810000000,1,26,8058566353632,128,14793,94334184,CLX5
2025-09-24T19:38:35.744193747Z,2025-09-24T19:38:35.744026425Z,160,1,432669,A,B,64.810000000,2,26,8058566353635,128,16405,94334188,CLX5
2025-09-24T19:38:35.801760959Z,2025-09-24T19:38:35.801627207Z,160,1,432669,A,B,64.810000000,1,26,8058566353639,128,19451,94334209,CLX5
2025-09-24T19:38:36.196024154Z,2025-09-24T19:38:36.195739125Z,160,1,432669,T,A,64.810000000,1,26,8058566353643,0,18744,94334222,CLX5
2025-09-24T19:38:36.196024154Z,2025-09-24T19:38:36.195739125Z,160,1,432669,F,B,64.810000000,1,26,8058566353543,0,18744,94334222,CLX5
2025-09-24T19:38:36.196034114Z,2025-09-24T19:38:36.195739125Z,160,1,432669,C,B,64.810000000,1,26,8058566353543,128,15701,94334223,CLX5
2025-09-24T19:38:36.196156182Z,2025-09-24T19:38:36.196020757Z,160,1,432669,C,B,64.810000000,1,26,8058566353639,128,19351,94334224,CLX5
2025-09-24T19:38:36.196304920Z,2025-09-24T19:38:36.196171683Z,160,1,432669,C,B,64.810000000,2,26,8058566353635,128,19743,94334225,CLX5
2025-09-24T19:38:36.197319533Z,2025-09-24T19:38:36.197186781Z,160,1,432669,A,A,64.820000000,1,26,8058566353645,128,18566,94334247,CLX5
2025-09-24T19:38:36.197368882Z,2025-09-24T19:38:36.197193019Z,160,1,432669,C,B,64.810000000,1,26,8058566353549,128,17001,94334248,CLX5
2025-09-24T19:38:36.348917368Z,2025-09-24T19:38:36.348765285Z,160,1,432669,C,B,64.810000000,1,26,8058566353632,128,22778,94334257,CLX5
2025-09-24T19:38:38.077692088Z,2025-09-24T19:38:38.077382919Z,160,1,432669,T,A,64.810000000,1,26,8058566353649,0,19170,94334272,CLX5
2025-09-24T19:38:38.077692088Z,2025-09-24T19:38:38.077382919Z,160,1,432669,F,B,64.810000000,1,26,8058566353548,0,19170,94334272,CLX5
2025-09-24T19:38:38.077702502Z,2025-09-24T19:38:38.077382919Z,160,1,432669,C,B,64.810000000,1,26,8058566353548,128,15540,94334273,CLX5
2025-09-24T19:38:38.077810431Z,2025-09-24T19:38:38.077664665Z,160,1,432669,A,A,64.820000000,1,26,8058566353650,128,18310,94334276,CLX5
2025-09-24T19:38:38.077997598Z,2025-09-24T19:38:38.077851321Z,160,1,432669,A,A,64.820000000,1,26,8058566353653,128,14588,94334282,CLX5
2025-09-24T19:38:38.078165596Z,2025-09-24T19:38:38.078032005Z,160,1,432669,A,A,64.820000000,1,26,8058566353654,128,18442,94334286,CLX5
2025-09-24T19:38:38.078317499Z,2025-09-24T19:38:38.078195197Z,160,1,432669,A,A,64.820000000,1,26,8058566353655,128,18078,94334288,CLX5
2025-09-24T19:38:39.003365232Z,2025-09-24T19:38:39.003218183Z,160,1,432669,C,A,64.820000000,1,26,8058566353655,128,18111,94334294,CLX5
2025-09-24T19:38:39.003541256Z,2025-09-24T19:38:39.003414937Z,160,1,432669,C,A,64.820000000,1,26,8058566353654,128,18767,94334295,CLX5
2025-09-24T19:38:39.003760017Z,2025-09-24T19:38:39.003575481Z,160,1,432669,C,A,64.820000000,1,26,8058566353653,128,14972,94334299,CLX5
2025-09-24T19:38:39.062597020Z,2025-09-24T19:38:39.062478117Z,160,1,432669,C,B,64.610000000,2,26,8058566285281,128,18280,94334301,CLX5
2025-09-24T19:38:42.155109102Z,2025-09-24T19:38:42.154785265Z,160,1,432669,A,B,64.810000000,2,26,8058566353724,128,16617,94334477,CLX5
2025-09-24T19:38:42.155260199Z,2025-09-24T19:38:42.155109365Z,160,1,432669,A,B,64.810000000,1,26,8058566353727,128,26513,94334483,CLX5
2025-09-24T19:38:42.166024958Z,2025-09-24T19:38:42.165873889Z,160,1,432669,C,B,64.810000000,2,26,8058566353724,128,14633,94334501,CLX5
2025-09-24T19:38:42.166177291Z,2025-09-24T19:38:42.166040767Z,160,1,432669,C,B,64.810000000,1,26,8058566353727,128,17163,94334503,CLX5
2025-09-24T19:38:42.630011759Z,2025-09-24T19:38:42.629858399Z,160,1,432669,C,B,64.810000000,1,26,8058566353630,128,18352,94335475,CLX5
2025-09-24T19:38:43.134385007Z,2025-09-24T19:38:43.134077807Z,160,1,432669,T,A,64.810000000,1,26,8058566354358,0,18245,94336091,CLX5
2025-09-24T19:38:43.134385007Z,2025-09-24T19:38:43.134077807Z,160,1,432669,F,B,64.810000000,1,26,8058566353587,0,18245,94336091,CLX5
2025-09-24T19:38:43.134397195Z,2025-09-24T19:38:43.134077807Z,160,1,432669,C,B,64.810000000,1,26,8058566353587,128,14486,94336092,CLX5
2025-09-24T19:38:43.134601710Z,2025-09-24T19:38:43.134395899Z,160,1,432669,C,B,64.800000000,1,26,8058566340602,128,14128,94336096,CLX5
2025-09-24T19:38:43.134683237Z,2025-09-24T19:38:43.134482431Z,160,1,432669,M,B,64.790000000,1,26,8058566335785,128,18123,94336100,CLX5
2025-09-24T19:38:43.134779976Z,2025-09-24T19:38:43.134639939Z,160,1,432669,A,A,64.820000000,1,26,8058566354360,128,18787,94336101,CLX5
2025-09-24T19:38:43.134846490Z,2025-09-24T19:38:43.134720519Z,160,1,432669,A,A,64.820000000,1,26,8058566354361,128,15006,94336102,CLX5
2025-09-24T19:38:43.134882684Z,2025-09-24T19:38:43.134720959Z,160,1,432669,M,B,63.630000000,3,26,8058566221991,128,17997,94336103,CLX5
2025-09-24T19:38:43.134927088Z,2025-09-24T19:38:43.134807645Z,160,1,432669,A,A,64.820000000,1,26,8058566354362,128,14202,94336104,CLX5
2025-09-24T19:38:43.134971837Z,2025-09-24T19:38:43.134843085Z,160,1,432669,A,A,64.820000000,1,26,8058566354363,128,15815,94336105,CLX5
2025-09-24T19:38:43.135004606Z,2025-09-24T19:38:43.134846291Z,160,1,432669,A,A,64.820000000,1,26,8058566354364,128,18147,94336106,CLX5
2025-09-24T19:38:43.136130473Z,2025-09-24T19:38:43.135823875Z,160,1,432669,M,A,64.930000000,1,26,8058565075241,128,13180,94336130,CLX5
2025-09-24T19:38:43.428021771Z,2025-09-24T19:38:43.427868257Z,160,1,432669,A,B,64.780000000,1,26,8058566354399,128,17706,94336197,CLX5
2025-09-24T19:38:43.428064600Z,2025-09-24T19:38:43.427890241Z,160,1,432669,C,A,64.820000000,1,26,8058566354362,128,15076,94336198,CLX5
2025-09-24T19:38:43.428099228Z,2025-09-24T19:38:43.427903949Z,160,1,432669,C,A,64.820000000,1,26,8058566354361,128,15018,94336199,CLX5
2025-09-24T19:38:43.428134362Z,2025-09-24T19:38:43.427905869Z,160,1,432669,C,A,64.820000000,1,26,8058566354360,128,18102,94336200,CLX5
2025-09-24T19:38:43.779024716Z,2025-09-24T19:38:43.778913157Z,160,1,432669,C,B,64.540000000,2,26,8058566286168,128,19269,94336246,CLX5
2025-09-24T19:38:44.534276662Z,2025-09-24T19:38:44.534113665Z,160,1,432669,A,B,64.790000000,1,26,8058566354444,128,18752,94336292,CLX5
2025-09-24T19:38:44.534305222Z,2025-09-24T19:38:44.534127891Z,160,1,432669,A,B,64.780000000,1,26,8058566354445,128,14562,94336293,CLX5
2025-09-24T19:38:45.839472889Z,2025-09-24T19:38:45.839322139Z,160,1,432669,M,B,64.750000000,1,26,8058566197138,128,23419,94336313,CLX5
2025-09-24T19:38:46.072124097Z,2025-09-24T19:38:46.071967087Z,160,1,432669,A,B,64.800000000,1,26,8058566354454,128,21489,94336324,CLX5
2025-09-24T19:38:46.280245535Z,2025-09-24T19:38:46.280088519Z,160,1,432669,C,B,64.800000000,1,26,8058566353307,128,22621,94336328,CLX5
2025-09-24T19:38:46.726050867Z,2025-09-24T19:38:46.725897883Z,160,1,432669,C,B,64.500000000,2,26,8058566285914,128,21920,94336342,CLX5
2025-09-24T19:38:52.277357415Z,2025-09-24T19:38:52.277193239Z,160,1,432669,C,B,64.790000000,1,26,8058566354444,128,26795,94336411,CLX5
2025-09-24T19:38:52.277712296Z,2025-09-24T19:38:52.277388593Z,160,1,432669,T,A,64.800000000,1,26,8058566354481,0,21051,94336412,CLX5
2025-09-24T19:38:52.277712296Z,2025-09-24T19:38:52.277388593Z,160,1,432669,F,B,64.800000000,1,26,8058566248704,0,21051,94336412,CLX5
2025-09-24T19:38:52.277726534Z,2025-09-24T19:38:52.277388593Z,160,1,432669,C,B,64.800000000,1,26,8058566248704,128,18673,94336413,CLX5
2025-09-24T19:38:52.278096798Z,2025-09-24T19:38:52.277678811Z,160,1,432669,A,A,64.820000000,1,26,8058566354484,128,20606,94336419,CLX5
2025-09-24T19:38:52.278222544Z,2025-09-24T19:38:52.277688561Z,160,1,432669,A,A,64.810000000,1,26,8058566354487,128,18505,94336421,CLX5
2025-09-24T19:38:52.278274957Z,2025-09-24T19:38:52.277718931Z,160,1,432669,A,A,64.810000000,1,26,8058566354488,128,18250,94336424,CLX5
2025-09-24T19:38:52.278326188Z,2025-09-24T19:38:52.278002427Z,160,1,432669,A,A,64.820000000,1,26,8058566354489,128,19478,94336427,CLX5
2025-09-24T19:38:52.278415261Z,2025-09-24T19:38:52.278045509Z,160,1,432669,C,A,64.810000000,1,26,8058566354488,128,18344,94336430,CLX5
2025-09-24T19:38:52.278759079Z,2025-09-24T19:38:52.278288341Z,160,1,432669,M,B,64.780000000,1,26,8058566335785,128,21370,94336441,CLX5
2025-09-24T19:38:52.278889018Z,2025-09-24T19:38:52.278481503Z,160,1,432669,M,A,64.830000000,3,26,8058566321460,128,18001,94336445,CLX5
2025-09-24T19:38:52.279002937Z,2025-09-24T19:38:52.278659787Z,160,1,432669,C,A,64.820000000,1,26,8058566354364,128,21005,94336450,CLX5
2025-09-24T19:38:52.279102011Z,2025-09-24T19:38:52.278820387Z,160,1,432669,M,A,65.970000000,3,26,8058566331102,128,18461,94336455,CLX5
2025-09-24T19:38:52.279186571Z,2025-09-24T19:38:52.278859209Z,160,1,432669,A,A,64.810000000,1,26,8058566354493,128,20993,94336458,CLX5
2025-09-24T19:38:52.279401362Z,2025-09-24T19:38:52.279032675Z,160,1,432669,T,N,64.810000000,2,26,0,0,19815,94336461,CLX5
2025-09-24T19:38:52.279401362Z,2025-09-24T19:38:52.279032675Z,160,1,432669,F,N,64.810000000,1,26,8058566354487,0,19815,94336461,CLX5
2025-09-24T19:38:52.279401362Z,2025-09-24T19:38:52.279032675Z,160,1,432669,F,N,64.810000000,1,26,8058566354493,0,19815,94336461,CLX5
2025-09-24T19:38:52.279416652Z,2025-09-24T19:38:52.279032675Z,160,1,432669,C,A,64.810000000,1,26,8058566354487,0,19791,94336462,CLX5
2025-09-24T19:38:52.279416652Z,2025-09-24T19:38:52.279032675Z,160,1,432669,C,A,64.810000000,1,26,8058566354493,128,19791,94336462,CLX5
2025-09-24T19:38:52.279465371Z,2025-09-24T19:38:52.279041793Z,160,1,432669,A,A,64.820000000,1,26,8058566354495,128,17140,94336465,CLX5
2025-09-24T19:38:52.279621190Z,2025-09-24T19:38:52.279336385Z,160,1,432669,A,B,64.800000000,1,26,8058566354499,128,20515,94336472,CLX5
2025-09-24T19:38:52.279855310Z,2025-09-24T19:38:52.279416599Z,160,1,432669,C,B,64.800000000,1,26,8058566354499,128,19860,94336482,CLX5
2025-09-24T19:38:52.280044935Z,2025-09-24T19:38:52.279480243Z,160,1,432669,A,A,64.820000000,3,26,8058566354507,128,19104,94336493,CLX5
2025-09-24T19:38:52.280075239Z,2025-09-24T19:38:52.279493491Z,160,1,432669,A,A,64.820000000,1,26,8058566354509,128,17102,94336495,CLX5
2025-09-24T19:38:52.280245272Z,2025-09-24T19:38:52.279650637Z,160,1,432669,A,A,64.820000000,1,26,8058566354514,128,17468,94336504,CLX5
2025-09-24T19:38:52.280289561Z,2025-09-24T19:38:52.279684137Z,160,1,432669,M,A,64.840000000,4,26,8058566342145,128,16928,94336506,CLX5
2025-09-24T19:38:52.280360313Z,2025-09-24T19:38:52.279846467Z,160,1,432669,C,A,64.820000000,1,26,8058566354489,128,18392,94336509,CLX5
2025-09-24T19:38:52.280519788Z,2025-09-24T19:38:52.280011311Z,160,1,432669,M,A,64.820000000,1,26,8058566354507,128,17647,94336515,CLX5
2025-09-24T19:38:52.285091505Z,2025-09-24T19:38:52.284456971Z,160,1,432669,A,B,64.800000000,1,26,8058566354571,128,17646,94336816,CLX5
2025-09-24T19:38:52.285256132Z,2025-09-24T19:38:52.284745631Z,160,1,432669,A,B,64.800000000,1,26,8058566354574,128,14811,94336821,CLX5
2025-09-24T19:38:52.285646317Z,2025-09-24T19:38:52.285114637Z,160,1,432669,A,B,64.800000000,1,26,8058566354582,128,14720,94336843,CLX5
2025-09-24T19:38:52.294151454Z,2025-09-24T19:38:52.294043877Z,160,1,432669,A,A,65.960000000,4,26,8058566354590,128,18161,94336863,CLX5
2025-09-24T19:38:52.329036756Z,2025-09-24T19:38:52.328890319Z,160,1,432669,A,A,64.820000000,1,26,8058566354651,128,18300,94336988,CLX5
2025-09-24T19:38:52.830441354Z,2025-09-24T19:38:52.830298165Z,160,1,432669,C,A,64.820000000,1,26,8058566354514,128,18723,94337152,CLX5
2025-09-24T19:38:52.830604246Z,2025-09-24T19:38:52.830479193Z,160,1,432669,C,A,64.820000000,1,26,8058566354509,128,18283,94337153,CLX5
2025-09-24T19:38:53.383513343Z,2025-09-24T19:38:53.383362845Z,160,1,432669,A,B,64.790000000,1,26,8058566354883,128,18543,94337562,CLX5
2025-09-24T19:38:53.383557993Z,2025-09-24T19:38:53.383396733Z,160,1,432669,C,A,64.820000000,1,26,8058566354495,128,15047,94337563,CLX5
2025-09-24T19:38:54.707253089Z,2025-09-24T19:38:54.706996439Z,160,1,432669,A,B,64.810000000,1,26,8058566355165,128,17764,94338308,CLX5
2025-09-24T19:38:54.707378128Z,2025-09-24T19:38:54.707255167Z,160,1,432669,A,B,64.800000000,1,26,8058566355166,128,18796,94338312,CLX5
2025-09-24T19:38:54.707497976Z,2025-09-24T19:38:54.707299037Z,160,1,432669,A,A,64.820000000,1,26,8058566355169,128,14917,94338317,CLX5
2025-09-24T19:38:54.707634573Z,2025-09-24T19:38:54.707408223Z,160,1,432669,M,A,64.820000000,1,26,8058566239191,128,15565,94338321,CLX5
2025-09-24T19:38:54.707693713Z,2025-09-24T19:38:54.707508003Z,160,1,432669,C,A,64.820000000,1,26,8058566355169,128,18008,94338323,CLX5
2025-09-24T19:38:54.707721744Z,2025-09-24T19:38:54.707538855Z,160,1,432669,M,A,65.980000000,4,26,8058566321460,128,15186,94338324,CLX5
2025-09-24T19:38:54.707757431Z,2025-09-24T19:38:54.707566059Z,160,1,432669,M,B,64.800000000,3,26,8058566332677,128,14664,94338325,CLX5
2025-09-24T19:38:54.753706046Z,2025-09-24T19:38:54.753415153Z,160,1,432669,T,A,64.810000000,1,26,8058566355204,0,18036,94338431,CLX5
2025-09-24T19:38:54.753706046Z,2025-09-24T19:38:54.753415153Z,160,1,432669,F,B,64.810000000,1,26,8058566355165,0,18036,94338431,CLX5
2025-09-24T19:38:54.753714839Z,2025-09-24T19:38:54.753415153Z,160,1,432669,C,B,64.810000000,1,26,8058566355165,128,14622,94338432,CLX5
2025-09-24T19:38:54.753875221Z,2025-09-24T19:38:54.753728675Z,160,1,432669,M,A,65.140000000,1,26,8058566239191,128,14969,94338436,CLX5
2025-09-24T19:38:54.754008899Z,2025-09-24T19:38:54.753876067Z,160,1,432669,A,A,64.820000000,1,26,8058566355205,128,13737,94338441,CLX5
2025-09-24T19:38:54.754101861Z,2025-09-24T19:38:54.753910875Z,160,1,432669,A,A,64.820000000,1,26,8058566355206,128,18331,94338446,CLX5
2025-09-24T19:38:54.754162722Z,2025-09-24T19:38:54.754045193Z,160,1,432669,A,A,64.820000000,1,26,8058566355207,128,15091,94338447,CLX5
2025-09-24T19:38:54.761432942Z,2025-09-24T19:38:54.761194919Z,160,1,432669,A,B,64.810000000,1,26,8058566355224,128,17706,94338507,CLX5
2025-09-24T19:38:54.761522709Z,2025-09-24T19:38:54.761283139Z,160,1,432669,C,A,64.820000000,1,26,8058566355207,128,15300,94338511,CLX5
2025-09-24T19:38:54.761560538Z,2025-09-24T19:38:54.761289685Z,160,1,432669,C,A,64.820000000,1,26,8058566355206,128,17373,94338512,CLX5
2025-09-24T19:38:54.761569562Z,2025-09-24T19:38:54.761377849Z,160,1,432669,M,A,64.940000000,1,26,8058565075241,128,14525,94338513,CLX5
2025-09-24T19:38:54.761569562Z,2025-09-24T19:38:54.761436751Z,160,1,432669,C,A,64.820000000,1,26,8058566353645,128,14525,94338513,CLX5
2025-09-24T19:38:54.761772034Z,2025-09-24T19:38:54.761552349Z,160,1,432669,C,A,64.820000000,1,26,8058566355205,128,17268,94338519,CLX5
2025-09-24T19:38:54.765046337Z,2025-09-24T19:38:54.764881885Z,160,1,432669,A,B,64.810000000,1,26,8058566355227,128,18034,94338520,CLX5
2025-09-24T19:38:54.765065076Z,2025-09-24T19:38:54.764882063Z,160,1,432669,A,B,64.810000000,1,26,8058566355228,128,16074,94338522,CLX5
2025-09-24T19:38:54.765193655Z,2025-09-24T19:38:54.765046575Z,160,1,432669,A,B,64.810000000,1,26,8058566355229,128,17409,94338526,CLX5
2025-09-24T19:38:54.859824586Z,2025-09-24T19:38:54.859504029Z,160,1,432669,M,A,64.830000000,1,26,8058566354507,128,19214,94338700,CLX5
2025-09-24T19:38:55.065492144Z,2025-09-24T19:38:55.065338839Z,160,1,432669,M,B,64.790000000,1,26,8058566197138,128,18025,94338801,CLX5
2025-09-24T19:38:57.428465633Z,2025-09-24T19:38:57.428337491Z,160,1,432669,M,A,64.930000000,3,26,8058566144143,128,17997,94338911,CLX5
2025-09-24T19:38:57.785755257Z,2025-09-24T19:38:57.785213379Z,160,1,432669,A,B,64.810000000,1,26,8058566355494,128,21275,94339173,CLX5
2025-09-24T19:38:57.816448572Z,2025-09-24T19:38:57.816289109Z,160,1,432669,A,B,64.810000000,1,26,8058566355579,128,19769,94339386,CLX5
2025-09-24T19:38:57.816504272Z,2025-09-24T19:38:57.816289571Z,160,1,432669,C,A,64.850000000,2,26,8058566353200,128,14480,94339388,CLX5
2025-09-24T19:38:57.816690348Z,2025-09-24T19:38:57.816290491Z,160,1,432669,C,A,64.820000000,1,26,8058566354484,128,15342,94339394,CLX5
2025-09-24T19:38:57.816761208Z,2025-09-24T19:38:57.816294159Z,160,1,432669,A,B,64.810000000,2,26,8058566355583,128,15220,94339396,CLX5
2025-09-24T19:38:57.816885495Z,2025-09-24T19:38:57.816308441Z,160,1,432669,A,B,64.810000000,1,26,8058566355585,128,14569,94339401,CLX5
2025-09-24T19:38:57.817055153Z,2025-09-24T19:38:57.816422503Z,160,1,432669,C,A,64.820000000,1,26,8058566353650,128,18207,94339408,CLX5
2025-09-24T19:38:57.817376866Z,2025-09-24T19:38:57.817039297Z,160,1,432669,C,B,64.810000000,1,26,8058566355585,128,15588,94339426,CLX5
2025-09-24T19:38:57.817814457Z,2025-09-24T19:38:57.817516721Z,160,1,432669,A,A,65.900000000,1,26,8058566355594,128,14622,94339451,CLX5
2025-09-24T19:38:57.817814457Z,2025-09-24T19:38:57.817521215Z,160,1,432669,C,B,64.810000000,2,26,8058566355583,128,14622,94339451,CLX5
2025-09-24T19:38:57.904494508Z,2025-09-24T19:38:57.904363033Z,160,1,432669,A,A,64.850000000,2,26,8058566355753,128,18094,94339935,CLX5
2025-09-24T19:38:57.917360275Z,2025-09-24T19:38:57.917267919Z,160,1,432669,C,A,65.900000000,1,26,8058566355594,128,17463,94339986,CLX5
2025-09-24T19:38:57.917530570Z,2025-09-24T19:38:57.917397395Z,160,1,432669,C,B,64.800000000,1,26,8058566354582,128,18320,94339988,CLX5
2025-09-24T19:38:57.917685959Z,2025-09-24T19:38:57.917562469Z,160,1,432669,C,B,64.800000000,1,26,8058566354574,128,18831,94339989,CLX5
2025-09-24T19:38:58.709402376Z,2025-09-24T19:38:58.709233761Z,160,1,432669,C,B,64.810000000,1,26,8058566355579,128,20953,94340397,CLX5
2025-09-24T19:38:58.709567504Z,2025-09-24T19:38:58.709444261Z,160,1,432669,C,B,64.800000000,1,26,8058566354571,128,17453,94340398,CLX5
2025-09-24T19:38:58.844482217Z,2025-09-24T19:38:58.844345305Z,160,1,432669,C,B,64.810000000,1,26,8058566355494,128,21136,94340411,CLX5
2025-09-24T19:39:00.174982423Z,2025-09-24T19:39:00.174667933Z,160,1,432669,T,A,64.810000000,1,26,8058566356117,0,18128,94340602,CLX5
2025-09-24T19:39:00.174982423Z,2025-09-24T19:39:00.174667933Z,160,1,432669,F,B,64.810000000,1,26,8058566355224,0,18128,94340602,CLX5
2025-09-24T19:39:00.174994629Z,2025-09-24T19:39:00.174667933Z,160,1,432669,C,B,64.810000000,1,26,8058566355224,128,18109,94340603,CLX5
2025-09-24T19:39:00.175105535Z,2025-09-24T19:39:00.174955921Z,160,1,432669,C,B,64.810000000,1,26,8058566355228,128,18785,94340605,CLX5
2025-09-24T19:39:00.175123966Z,2025-09-24T19:39:00.174956841Z,160,1,432669,A,A,64.820000000,1,26,8058566356118,128,15085,94340607,CLX5
2025-09-24T19:39:00.175302547Z,2025-09-24T19:39:00.175128443Z,160,1,432669,A,B,64.810000000,1,26,8058566356120,128,13710,94340612,CLX5
2025-09-24T19:39:00.605137269Z,2025-09-24T19:39:00.604934217Z,160,1,432669,A,B,64.810000000,1,26,8058566356126,128,34647,94340645,CLX5
2025-09-24T19:39:00.605298003Z,2025-09-24T19:39:00.605148613Z,160,1,432669,A,B,64.810000000,1,26,8058566356127,128,25417,94340646,CLX5
2025-09-24T19:39:01.304758011Z,2025-09-24T19:39:01.304591901Z,160,1,432669,A,B,64.810000000,1,26,8058566356130,128,19934,94340650,CLX5
2025-09-24T19:39:02.049068997Z,2025-09-24T19:39:02.048908067Z,160,1,432669,C,A,65.050000000,1,26,8058566020533,128,20954,94340652,CLX5
2025-09-24T19:39:03.685278438Z,2025-09-24T19:39:03.685146925Z,160,1,432669,C,A,65.130000000,1,26,8058566333583,128,19308,94340666,CLX5
2025-09-24T19:39:03.747678511Z,2025-09-24T19:39:03.747565637Z,160,1,432669,A,A,65.090000000,1,26,8058566356134,128,18135,94340667,CLX5
2025-09-24T19:39:04.008712353Z,2025-09-24T19:39:04.008615503Z,160,1,432669,C,A,64.970000000,1,26,8058566349514,128,18206,94340692,CLX5
2025-09-24T19:39:04.371749495Z,2025-09-24T19:39:04.371632455Z,160,1,432669,A,B,64.560000000,6,26,8058566356144,128,17886,94340703,CLX5
2025-09-24T19:39:04.570835111Z,2025-09-24T19:39:04.570714809Z,160,1,432669,A,B,64.620000000,15,26,8058566356146,128,17435,94340706,CLX5
2025-09-24T19:39:04.594302940Z,2025-09-24T19:39:04.594193779Z,160,1,432669,C,A,65.140000000,1,26,8058566326983,128,18235,94340707,CLX5
2025-09-24T19:39:04.688112032Z,2025-09-24T19:39:04.688000399Z,160,1,432669,A,A,65.090000000,1,26,8058566356147,128,18327,94340708,CLX5
2025-09-24T19:39:05.915810761Z,2025-09-24T19:39:05.915687085Z,160,1,432669,A,B,64.610000000,15,26,8058566356153,128,18291,94340721,CLX5
2025-09-24T19:39:06.067060760Z,2025-09-24T19:39:06.066863731Z,160,1,432669,A,B,64.810000000,1,26,8058566356157,128,16303,94340750,CLX5
2025-09-24T19:39:06.067405728Z,2025-09-24T19:39:06.067082255Z,160,1,432669,A,B,64.810000000,2,26,8058566356161,128,15540,94340759,CLX5
2025-09-24T19:39:06.067481955Z,2025-09-24T19:39:06.067107925Z,160,1,432669,A,B,64.810000000,1,26,8058566356162,128,19106,94340763,CLX5
2025-09-24T19:39:06.068525129Z,2025-09-24T19:39:06.067937539Z,160,1,432669,C,A,64.820000000,2,26,8058566352156,128,15679,94340806,CLX5
2025-09-24T19:39:06.068562245Z,2025-09-24T19:39:06.067937867Z,160,1,432669,C,A,64.820000000,1,26,8058566352157,128,18675,94340807,CLX5
2025-09-24T19:39:06.068895216Z,2025-09-24T19:39:06.068265921Z,160,1,432669,A,B,64.810000000,1,26,8058566356181,128,19726,94340822,CLX5
2025-09-24T19:39:06.069068007Z,2025-09-24T19:39:06.068267399Z,160,1,432669,C,A,64.820000000,1,26,8058566356118,128,16646,94340828,CLX5
2025-09-24T19:39:06.069113985Z,2025-09-24T19:39:06.068267649Z,160,1,432669,C,A,64.850000000,2,26,8058566355753,128,14849,94340830,CLX5
2025-09-24T19:39:06.069157021Z,2025-09-24T19:39:06.068271239Z,160,1,432669,A,B,64.810000000,1,26,8058566356185,128,19487,94340832,CLX5
2025-09-24T19:39:06.069531433Z,2025-09-24T19:39:06.068430015Z,160,1,432669,C,B,64.780000000,1,26,8058566353553,128,14655,94340849,CLX5
2025-09-24T19:39:06.070254927Z,2025-09-24T19:39:06.069162235Z,160,1,432669,C,B,64.810000000,1,26,8058566356185,128,15651,94340879,CLX5
2025-09-24T19:39:06.070422104Z,2025-09-24T19:39:06.069559791Z,160,1,432669,C,B,64.780000000,1,26,8058566354445,128,14600,94340884,CLX5
2025-09-24T19:39:06.070468581Z,2025-09-24T19:39:06.069740973Z,160,1,432669,A,B,64.810000000,1,26,8058566356197,128,15821,94340886,CLX5
2025-09-24T19:39:06.071312093Z,2025-09-24T19:39:06.070925293Z,160,1,432669,C,B,64.810000000,1,26,8058566356197,128,14570,94340933,CLX5
2025-09-24T19:39:06.071619783Z,2025-09-24T19:39:06.071285623Z,160,1,432669,M,B,64.810000000,1,26,8058566221991,128,19501,94340946,CLX5
2025-09-24T19:39:06.071650963Z,2025-09-24T19:39:06.071396133Z,160,1,432669,C,B,64.810000000,1,26,8058566356162,128,16418,94340947,CLX5
2025-09-24T19:39:06.071796830Z,2025-09-24T19:39:06.071662789Z,160,1,432669,C,B,64.810000000,1,26,8058566356157,128,16216,94340953,CLX5
2025-09-24T19:39:06.072105465Z,2025-09-24T19:39:06.071860501Z,160,1,432669,A,B,64.810000000,1,26,8058566356221,128,19396,94340972,CLX5
2025-09-24T19:39:06.079374441Z,2025-09-24T19:39:06.079242269Z,160,1,432669,C,B,64.810000000,1,26,8058566356221,128,19011,94341024,CLX5
2025-09-24T19:39:06.079506399Z,2025-09-24T19:39:06.079381961Z,160,1,432669,C,B,64.810000000,1,26,8058566356181,128,18119,94341025,CLX5
2025-09-24T19:39:06.079539767Z,2025-09-24T19:39:06.079383249Z,160,1,432669,A,B,64.810000000,1,26,8058566356243,128,16274,94341026,CLX5
2025-09-24T19:39:06.101310181Z,2025-09-24T19:39:06.101170601Z,160,1,432669,A,A,64.850000000,2,26,8058566356249,128,17888,94341041,CLX5
2025-09-24T19:39:06.240179736Z,2025-09-24T19:39:06.240037883Z,160,1,432669,A,B,64.780000000,1,26,8058566356258,128,20245,94341063,CLX5
2025-09-24T19:39:09.975976617Z,2025-09-24T19:39:09.975824407Z,160,1,432669,C,B,64.790000000,1,26,8058566354883,128,19151,94341131,CLX5
2025-09-24T19:39:10.024481532Z,2025-09-24T19:39:10.024304015Z,160,1,432669,A,A,64.820000000,1,26,8058566356287,128,18470,94341132,CLX5
2025-09-24T19:39:10.835776327Z,2025-09-24T19:39:10.835454637Z,160,1,432669,T,A,64.810000000,1,26,8058566356290,0,21451,94341154,CLX5
2025-09-24T19:39:10.835776327Z,2025-09-24T19:39:10.835454637Z,160,1,432669,F,B,64.810000000,1,26,8058566355227,0,21451,94341154,CLX5
2025-09-24T19:39:10.835788307Z,2025-09-24T19:39:10.835454637Z,160,1,432669,C,B,64.810000000,1,26,8058566355227,128,17523,94341155,CLX5
2025-09-24T19:39:10.835892496Z,2025-09-24T19:39:10.835745505Z,160,1,432669,A,A,64.820000000,1,26,8058566356291,128,18903,94341156,CLX5
2025-09-24T19:39:10.836174521Z,2025-09-24T19:39:10.835776845Z,160,1,432669,C,B,64.810000000,1,26,8058566356243,128,16500,94341163,CLX5
2025-09-24T19:39:10.836563831Z,2025-09-24T19:39:10.836437689Z,160,1,432669,M,B,63.630000000,4,26,8058566221991,128,14881,94341171,CLX5
2025-09-24T19:39:11.033956713Z,2025-09-24T19:39:11.033763417Z,160,1,432669,A,B,64.810000000,1,26,8058566356300,128,19245,94341182,CLX5
2025-09-24T19:39:11.274903272Z,2025-09-24T19:39:11.274582367Z,160,1,432669,T,A,64.810000000,1,26,8058566356310,0,17811,94341214,CLX5
2025-09-24T19:39:11.274903272Z,2025-09-24T19:39:11.274582367Z,160,1,432669,F,B,64.810000000,1,26,8058566355229,0,17811,94341214,CLX5
2025-09-24T19:39:11.274915098Z,2025-09-24T19:39:11.274582367Z,160,1,432669,C,B,64.810000000,1,26,8058566355229,128,17014,94341215,CLX5
2025-09-24T19:39:11.845859455Z,2025-09-24T19:39:11.845570727Z,160,1,432669,T,A,64.810000000,1,26,8058566356312,0,17919,94341224,CLX5
2025-09-24T19:39:11.845859455Z,2025-09-24T19:39:11.845570727Z,160,1,432669,F,B,64.810000000,1,26,8058566356120,0,17919,94341224,CLX5
2025-09-24T19:39:11.845870805Z,2025-09-24T19:39:11.845570727Z,160,1,432669,C,B,64.810000000,1,26,8058566356120,128,16367,94341225,CLX5
2025-09-24T19:39:11.846065007Z,2025-09-24T19:39:11.845861381Z,160,1,432669,C,B,64.810000000,1,26,8058566356300,128,16767,94341227,CLX5
2025-09-24T19:39:12.326218667Z,2025-09-24T19:39:12.325905293Z,160,1,432669,A,B,64.810000000,1,26,8058566356316,128,16539,94341241,CLX5
2025-09-24T19:39:12.326351278Z,2025-09-24T19:39:12.326218239Z,160,1,432669,A,B,64.810000000,1,26,8058566356317,128,16249,94341243,CLX5
2025-09-24T19:39:12.417003145Z,2025-09-24T19:39:12.416699009Z,160,1,432669,T,A,64.810000000,1,26,8058566356322,0,17735,94341256,CLX5
2025-09-24T19:39:12.417003145Z,2025-09-24T19:39:12.416699009Z,160,1,432669,F,B,64.810000000,1,26,8058566356126,0,17735,94341256,CLX5
2025-09-24T19:39:12.417014365Z,2025-09-24T19:39:12.416699009Z,160,1,432669,C,B,64.810000000,1,26,8058566356126,128,16091,94341257,CLX5
2025-09-24T19:39:12.988056675Z,2025-09-24T19:39:12.987785937Z,160,1,432669,T,A,64.810000000,1,26,8058566356325,0,17673,94341266,CLX5
2025-09-24T19:39:12.988056675Z,2025-09-24T19:39:12.987785937Z,160,1,432669,F,B,64.810000000,1,26,8058566356127,0,17673,94341266,CLX5
2025-09-24T19:39:12.988069999Z,2025-09-24T19:39:12.987785937Z,160,1,432669,C,B,64.810000000,1,26,8058566356127,128,17442,94341267,CLX5
2025-09-24T19:39:13.559164138Z,2025-09-24T19:39:13.558886285Z,160,1,432669,T,A,64.810000000,1,26,8058566356328,0,18144,94341277,CLX5
2025-09-24T19:39:13.559164138Z,2025-09-24T19:39:13.558886285Z,160,1,432669,F,B,64.810000000,1,26,8058566356130,0,18144,94341277,CLX5
2025-09-24T19:39:13.559177025Z,2025-09-24T19:39:13.558886285Z,160,1,432669,C,B,64.810000000,1,26,8058566356130,128,17720,94341278,CLX5
2025-09-24T19:39:14.130288699Z,2025-09-24T19:39:14.129986207Z,160,1,432669,T,A,64.810000000,1,26,8058566356337,0,23727,94341307,CLX5
2025-09-24T19:39:14.130288699Z,2025-09-24T19:39:14.129986207Z,160,1,432669,F,B,64.810000000,1,26,8058566356161,0,23727,94341307,CLX5
2025-09-24T19:39:14.130299919Z,2025-09-24T19:39:14.129986207Z,160,1,432669,M,B,64.810000000,1,26,8058566356161,128,17986,94341308,CLX5
2025-09-24T19:39:14.355283218Z,2025-09-24T19:39:14.355106413Z,160,1,432669,A,B,64.810000000,1,26,8058566356356,128,22285,94341385,CLX5
2025-09-24T19:39:14.355324488Z,2025-09-24T19:39:14.355106625Z,160,1,432669,A,B,64.810000000,1,26,8058566356357,128,17007,94341386,CLX5
2025-09-24T19:39:14.510526514Z,2025-09-24T19:39:14.509431279Z,160,1,432669,A,B,64.810000000,1,26,8058566356397,128,20418,94341520,CLX5
2025-09-24T19:39:14.510581200Z,2025-09-24T19:39:14.509447059Z,160,1,432669,A,B,64.810000000,1,26,8058566356398,128,16737,94341522,CLX5
2025-09-24T19:39:14.512748789Z,2025-09-24T19:39:14.510592481Z,160,1,432669,C,B,64.810000000,1,26,8058566356398,128,18346,94341643,CLX5
2025-09-24T19:39:14.514655895Z,2025-09-24T19:39:14.512986347Z,160,1,432669,A,B,64.810000000,1,26,8058566356476,128,17592,94341761,CLX5
2025-09-24T19:39:14.514829523Z,2025-09-24T19:39:14.513058477Z,160,1,432669,A,B,64.810000000,1,26,8058566356480,128,19296,94341768,CLX5
2025-09-24T19:39:14.514923552Z,2025-09-24T19:39:14.513063375Z,160,1,432669,C,B,64.780000000,1,26,8058566356258,128,17908,94341770,CLX5
2025-09-24T19:39:14.515485990Z,2025-09-24T19:39:14.513480533Z,160,1,432669,A,B,64.810000000,1,26,8058566356492,128,15679,94341799,CLX5
2025-09-24T19:39:14.516450056Z,2025-09-24T19:39:14.514953395Z,160,1,432669,C,B,64.780000000,1,26,8058566354399,128,15331,94341854,CLX5
2025-09-24T19:39:14.516490228Z,2025-09-24T19:39:14.515002757Z,160,1,432669,C,B,64.810000000,1,26,8058566356492,128,16487,94341855,CLX5
2025-09-24T19:39:14.602637073Z,2025-09-24T19:39:14.602477111Z,160,1,432669,M,B,64.810000000,1,26,8058566221991,128,19095,94342425,CLX5
2025-09-24T19:39:14.641668766Z,2025-09-24T19:39:14.641163211Z,160,1,432669,C,A,64.820000000,1,26,8058566349211,128,14952,94342504,CLX5
2025-09-24T19:39:14.641895790Z,2025-09-24T19:39:14.641180511Z,160,1,432669,C,A,64.850000000,2,26,8058566356249,128,14008,94342513,CLX5
2025-09-24T19:39:14.642016014Z,2025-09-24T19:39:14.641183275Z,160,1,432669,A,B,64.810000000,2,26,8058566356716,128,18356,94342518,CLX5
2025-09-24T19:39:14.642047639Z,2025-09-24T19:39:14.641190897Z,160,1,432669,C,A,64.820000000,1,26,8058566356291,128,15404,94342519,CLX5
2025-09-24T19:39:14.642086467Z,2025-09-24T19:39:14.641191069Z,160,1,432669,A,B,64.810000000,1,26,8058566356717,128,16018,94342520,CLX5
2025-09-24T19:39:14.642123490Z,2025-09-24T19:39:14.641191493Z,160,1,432669,C,A,64.820000000,1,26,8058566349632,128,18907,94342521,CLX5
2025-09-24T19:39:14.642364714Z,2025-09-24T19:39:14.641233481Z,160,1,432669,C,A,64.820000000,1,26,8058566349209,128,15101,94342528,CLX5
2025-09-24T19:39:14.642590625Z,2025-09-24T19:39:14.641607961Z,160,1,432669,C,A,64.820000000,1,26,8058566352042,128,16052,94342535,CLX5
2025-09-24T19:39:14.643158439Z,2025-09-24T19:39:14.642026331Z,160,1,432669,A,A,64.820000000,1,26,8058566356729,128,15853,94342568,CLX5
2025-09-24T19:39:14.643200054Z,2025-09-24T19:39:14.642126107Z,160,1,432669,M,B,64.810000000,1,26,8058566349770,128,15820,94342569,CLX5
2025-09-24T19:39:14.643880843Z,2025-09-24T19:39:14.643725973Z,160,1,432669,C,B,64.810000000,1,26,8058566356717,128,19559,94342602,CLX5
2025-09-24T19:39:14.643913727Z,2025-09-24T19:39:14.643727125Z,160,1,432669,A,A,64.820000000,1,26,8058566356740,128,14334,94342603,CLX5
2025-09-24T19:39:14.643952225Z,2025-09-24T19:39:14.643730101Z,160,1,432669,A,B,64.810000000,1,26,8058566356741,128,15947,94342604,CLX5
2025-09-24T19:39:14.655243358Z,2025-09-24T19:39:14.655115697Z,160,1,432669,C,A,64.820000000,1,26,8058566356740,128,18485,94342621,CLX5
2025-09-24T19:39:14.655281749Z,2025-09-24T19:39:14.655131037Z,160,1,432669,C,B,64.810000000,1,26,8058566356741,128,15392,94342622,CLX5
2025-09-24T19:39:14.701402085Z,2025-09-24T19:39:14.701097919Z,160,1,432669,T,A,64.810000000,1,26,8058566356773,0,18652,94342662,CLX5
2025-09-24T19:39:14.701402085Z,2025-09-24T19:39:14.701097919Z,160,1,432669,F,B,64.810000000,1,26,8058566356161,0,18652,94342662,CLX5
2025-09-24T19:39:14.701413228Z,2025-09-24T19:39:14.701097919Z,160,1,432669,C,B,64.810000000,1,26,8058566356161,128,15676,94342663,CLX5
2025-09-24T19:39:14.701637803Z,2025-09-24T19:39:14.701408773Z,160,1,432669,A,A,64.820000000,1,26,8058566356776,128,18694,94342666,CLX5
2025-09-24T19:39:14.711686400Z,2025-09-24T19:39:14.711544697Z,160,1,432669,A,B,64.810000000,1,26,8058566356779,128,18957,94342680,CLX5
2025-09-24T19:39:14.711783800Z,2025-09-24T19:39:14.711653845Z,160,1,432669,A,A,64.870000000,2,26,8058566356780,128,18218,94342681,CLX5
2025-09-24T19:39:14.711812653Z,2025-09-24T19:39:14.711691377Z,160,1,432669,C,A,64.820000000,1,26,8058566356776,128,15024,94342682,CLX5
2025-09-24T19:39:14.717449522Z,2025-09-24T19:39:14.717345893Z,160,1,432669,A,A,65.900000000,1,26,8058566356783,128,18599,94342692,CLX5
2025-09-24T19:39:14.812115935Z,2025-09-24T19:39:14.811978423Z,160,1,432669,A,B,64.770000000,2,26,8058566356820,128,18408,94342759,CLX5
2025-09-24T19:39:15.840193240Z,2025-09-24T19:39:15.840045003Z,160,1,432669,A,B,64.780000000,1,26,8058566356890,128,21034,94342903,CLX5
2025-09-24T19:39:16.059622370Z,2025-09-24T19:39:16.059468283Z,160,1,432669,C,A,64.820000000,1,26,8058566356729,128,15564,94342915,CLX5
2025-09-24T19:39:16.060564772Z,2025-09-24T19:39:16.060415089Z,160,1,432669,C,B,64.780000000,1,26,8058566356890,128,15100,94342925,CLX5
2025-09-24T19:39:19.263997573Z,2025-09-24T19:39:19.263873583Z,160,1,432669,M,B,64.650000000,6,26,8058566356144,128,18366,94343099,CLX5
2025-09-24T19:39:19.886100932Z,2025-09-24T19:39:19.885943779Z,160,1,432669,A,B,64.540000000,8,26,8058566356965,128,13179,94343105,CLX5
2025-09-24T19:39:19.886548215Z,2025-09-24T19:39:19.886399105Z,160,1,432669,A,A,64.820000000,1,26,8058566356968,128,15782,94343111,CLX5
2025-09-24T19:39:19.886590230Z,2025-09-24T19:39:19.886429517Z,160,1,432669,A,A,64.820000000,1,26,8058566356969,128,15946,94343113,CLX5
2025-09-24T19:39:19.887244408Z,2025-09-24T19:39:19.886554617Z,160,1,432669,C,A,64.820000000,1,26,8058566356968,128,15267,94343166,CLX5
2025-09-24T19:39:19.887404175Z,2025-09-24T19:39:19.886847099Z,160,1,432669,A,B,64.800000000,2,26,8058566356976,128,18117,94343173,CLX5
2025-09-24T19:39:19.887463776Z,2025-09-24T19:39:19.886852281Z,160,1,432669,A,B,64.810000000,1,26,8058566356977,128,15815,94343175,CLX5
2025-09-24T19:39:19.887493580Z,2025-09-24T19:39:19.886854433Z,160,1,432669,C,B,64.770000000,2,26,8058566356820,128,16781,94343176,CLX5
2025-09-24T19:39:19.887523608Z,2025-09-24T19:39:19.886895077Z,160,1,432669,A,B,64.810000000,1,26,8058566356978,128,15588,94343177,CLX5
2025-09-24T19:39:19.887812384Z,2025-09-24T19:39:19.887675215Z,160,1,432669,M,B,64.810000000,1,26,8058566319851,128,16477,94343190,CLX5
2025-09-24T19:39:19.888354533Z,2025-09-24T19:39:19.888232605Z,160,1,432669,C,B,64.800000000,2,26,8058566356976,128,18415,94343198,CLX5
2025-09-24T19:39:19.888410079Z,2025-09-24T19:39:19.888246851Z,160,1,432669,C,B,64.810000000,1,26,8058566356978,128,14862,94343200,CLX5
2025-09-24T19:39:19.888655358Z,2025-09-24T19:39:19.888513239Z,160,1,432669,C,B,64.810000000,1,26,8058566356977,128,15641,94343207,CLX5
2025-09-24T19:39:19.924450989Z,2025-09-24T19:39:19.924345807Z,160,1,432669,C,B,64.540000000,8,26,8058566356965,128,18258,94343211,CLX5
2025-09-24T19:39:20.011757166Z,2025-09-24T19:39:20.011620319Z,160,1,432669,A,B,64.770000000,2,26,8058566356984,128,18686,94343213,CLX5
2025-09-24T19:39:20.023640375Z,2025-09-24T19:39:20.023497473Z,160,1,432669,A,A,64.830000000,1,26,8058566356987,128,18618,94343216,CLX5
2025-09-24T19:39:20.919177811Z,2025-09-24T19:39:20.919030281Z,160,1,432669,A,B,64.800000000,1,26,8058566357018,128,18543,94343259,CLX5
2025-09-24T19:39:22.335981737Z,2025-09-24T19:39:22.335816213Z,160,1,432669,A,B,64.810000000,1,26,8058566357038,128,20137,94343298,CLX5
2025-09-24T19:39:22.336180639Z,2025-09-24T19:39:22.336037811Z,160,1,432669,C,A,64.820000000,1,26,8058566356969,128,15656,94343301,CLX5
2025-09-24T19:39:26.273939345Z,2025-09-24T19:39:26.273762983Z,160,1,432669,A,A,64.850000000,2,26,8058566357121,128,25159,94343517,CLX5
2025-09-24T19:39:26.274245738Z,2025-09-24T19:39:26.273809079Z,160,1,432669,A,A,64.820000000,1,26,8058566357126,128,18523,94343527,CLX5
2025-09-24T19:39:26.274294020Z,2025-09-24T19:39:26.274004873Z,160,1,432669,A,A,64.820000000,1,26,8058566357127,128,21331,94343529,CLX5
2025-09-24T19:39:26.274679489Z,2025-09-24T19:39:26.274298965Z,160,1,432669,C,A,64.820000000,1,26,8058566357127,128,25132,94343553,CLX5
2025-09-24T19:39:26.312080669Z,2025-09-24T19:39:26.311944953Z,160,1,432669,C,A,64.870000000,2,26,8058566356780,128,19935,94343559,CLX5
2025-09-24T19:39:26.317643915Z,2025-09-24T19:39:26.317539681Z,160,1,432669,C,A,65.900000000,1,26,8058566356783,128,20718,94343560,CLX5
2025-09-24T19:39:26.388358208Z,2025-09-24T19:39:26.388207637Z,160,1,432669,A,A,64.820000000,1,26,8058566357134,128,14962,94343578,CLX5
2025-09-24T19:39:26.389668769Z,2025-09-24T19:39:26.389543957Z,160,1,432669,C,A,64.820000000,1,26,8058566357134,128,18360,94343587,CLX5
2025-09-24T19:39:26.540470257Z,2025-09-24T19:39:26.540322123Z,160,1,432669,A,B,64.780000000,1,26,8058566357138,128,19052,94343598,CLX5
2025-09-24T19:39:29.467035917Z,2025-09-24T19:39:29.466379947Z,160,1,432669,T,N,64.820000000,8,26,0,0,18895,94343689,CLX5
2025-09-24T19:39:29.467035917Z,2025-09-24T19:39:29.466379947Z,160,1,432669,F,N,64.820000000,1,26,8058566346598,0,18895,94343689,CLX5
2025-09-24T19:39:29.467035917Z,2025-09-24T19:39:29.466379947Z,160,1,432669,F,N,64.820000000,1,26,8058566346946,0,18895,94343689,CLX5
2025-09-24T19:39:29.467035917Z,2025-09-24T19:39:29.466379947Z,160,1,432669,F,N,64.820000000,2,26,8058566349051,0,18895,94343689,CLX5
2025-09-24T19:39:29.467035917Z,2025-09-24T19:39:29.466379947Z,160,1,432669,F,N,64.820000000,2,26,8058566349090,0,18895,94343689,CLX5
2025-09-24T19:39:29.467035917Z,2025-09-24T19:39:29.466379947Z,160,1,432669,F,N,64.820000000,2,26,8058566349748,0,18895,94343689,CLX5
2025-09-24T19:39:29.467048066Z,2025-09-24T19:39:29.466379947Z,160,1,432669,C,A,64.820000000,1,26,8058566346598,0,16276,94343690,CLX5
2025-09-24T19:39:29.467048066Z,2025-09-24T19:39:29.466379947Z,160,1,432669,C,A,64.820000000,1,26,8058566346946,0,16276,94343690,CLX5
2025-09-24T19:39:29.467048066Z,2025-09-24T19:39:29.466379947Z,160,1,432669,C,A,64.820000000,2,26,8058566349051,0,16276,94343690,CLX5
2025-09-24T19:39:29.467048066Z,2025-09-24T19:39:29.466379947Z,160,1,432669,C,A,64.820000000,2,26,8058566349090,0,16276,94343690,CLX5
2025-09-24T19:39:29.467048066Z,2025-09-24T19:39:29.466379947Z,160,1,432669,M,A,64.820000000,1,26,8058566349748,128,16276,94343690,CLX5
2025-09-24T19:39:29.467242798Z,2025-09-24T19:39:29.466886401Z,160,1,432669,C,A,64.820000000,1,26,8058566357126,128,20295,94343700,CLX5
2025-09-24T19:39:29.467523348Z,2025-09-24T19:39:29.466999503Z,160,1,432669,A,B,64.810000000,1,26,8058566357185,128,14930,94343711,CLX5
2025-09-24T19:39:29.467578895Z,2025-09-24T19:39:29.467027863Z,160,1,432669,A,B,64.810000000,2,26,8058566357187,128,18380,94343713,CLX5
2025-09-24T19:39:29.467644003Z,2025-09-24T19:39:29.467036219Z,160,1,432669,A,B,64.810000000,2,26,8058566357189,128,13745,94343715,CLX5
2025-09-24T19:39:29.468236261Z,2025-09-24T19:39:29.467063879Z,160,1,432669,C,A,64.850000000,1,26,8058566349467,128,14121,94343736,CLX5
2025-09-24T19:39:29.468571944Z,2025-09-24T19:39:29.467203477Z,160,1,432669,C,B,64.810000000,1,26,8058566357185,128,14834,94343749,CLX5
2025-09-24T19:39:29.468745549Z,2025-09-24T19:39:29.467365823Z,160,1,432669,A,A,64.820000000,1,26,8058566357200,128,18567,94343754,CLX5
2025-09-24T19:39:29.469147015Z,2025-09-24T19:39:29.467613781Z,160,1,432669,A,B,64.790000000,1,26,8058566357205,128,18550,94343775,CLX5
2025-09-24T19:39:29.469372849Z,2025-09-24T19:39:29.467648587Z,160,1,432669,C,A,64.850000000,2,26,8058566357121,128,18380,94343783,CLX5
2025-09-24T19:39:29.469491852Z,2025-09-24T19:39:29.467656941Z,160,1,432669,A,A,64.820000000,1,26,8058566357211,128,19620,94343787,CLX5
2025-09-24T19:39:29.469865326Z,2025-09-24T19:39:29.467830289Z,160,1,432669,C,B,64.780000000,1,26,8058566357138,128,14295,94343806,CLX5
2025-09-24T19:39:29.469956468Z,2025-09-24T19:39:29.467850583Z,160,1,432669,A,B,64.800000000,2,26,8058566357217,128,17983,94343808,CLX5
2025-09-24T19:39:29.470067000Z,2025-09-24T19:39:29.467857457Z,160,1,432669,C,B,64.770000000,2,26,8058566356984,128,14358,94343813,CLX5
2025-09-24T19:39:29.470076861Z,2025-09-24T19:39:29.467858723Z,160,1,432669,A,B,64.540000000,8,26,8058566357219,128,16069,94343814,CLX5
2025-09-24T19:39:29.470619186Z,2025-09-24T19:39:29.468060985Z,160,1,432669,A,B,64.810000000,1,26,8058566357223,128,15271,94343835,CLX5
2025-09-24T19:39:29.471074041Z,2025-09-24T19:39:29.468510363Z,160,1,432669,A,A,64.820000000,1,26,8058566357228,128,19701,94343854,CLX5
2025-09-24T19:39:29.471348540Z,2025-09-24T19:39:29.468802515Z,160,1,432669,A,A,64.820000000,1,26,8058566357230,128,16198,94343866,CLX5
2025-09-24T19:39:29.471586401Z,2025-09-24T19:39:29.468830373Z,160,1,432669,A,A,64.820000000,2,26,8058566357234,128,18888,94343875,CLX5
2025-09-24T19:39:29.471622034Z,2025-09-24T19:39:29.468833983Z,160,1,432669,C,B,64.810000000,2,26,8058566357187,128,15551,94343876,CLX5
2025-09-24T19:39:29.471655133Z,2025-09-24T19:39:29.468849919Z,160,1,432669,C,B,64.810000000,2,26,8058566357189,128,15171,94343877,CLX5
2025-09-24T19:39:29.471714512Z,2025-09-24T19:39:29.468925275Z,160,1,432669,C,A,64.820000000,1,26,8058566357228,128,16111,94343880,CLX5
2025-09-24T19:39:29.471775603Z,2025-09-24T19:39:29.469031869Z,160,1,432669,C,B,64.800000000,2,26,8058566357217,128,16879,94343883,CLX5
2025-09-24T19:39:29.471814454Z,2025-09-24T19:39:29.469033653Z,160,1,432669,A,A,64.820000000,1,26,8058566357238,128,16523,94343884,CLX5
2025-09-24T19:39:29.471876958Z,2025-09-24T19:39:29.469033831Z,160,1,432669,A,A,64.820000000,1,26,8058566357239,128,18122,94343886,CLX5
2025-09-24T19:39:29.471906410Z,2025-09-24T19:39:29.469034009Z,160,1,432669,A,A,64.820000000,1,26,8058566357240,128,15853,94343887,CLX5
2025-09-24T19:39:29.472160366Z,2025-09-24T19:39:29.469692377Z,160,1,432669,A,A,64.820000000,1,26,8058566357248,128,15048,94343899,CLX5
2025-09-24T19:39:29.472492255Z,2025-09-24T19:39:29.470203171Z,160,1,432669,C,A,64.820000000,1,26,8058566357248,128,17792,94343917,CLX5
2025-09-24T19:39:29.472672549Z,2025-09-24T19:39:29.470633865Z,160,1,432669,C,B,64.810000000,1,26,8058566357223,128,14917,94343925,CLX5
2025-09-24T19:39:29.472724217Z,2025-09-24T19:39:29.470703059Z,160,1,432669,C,A,64.820000000,2,26,8058566357234,128,18856,94343927,CLX5
2025-09-24T19:39:29.472892447Z,2025-09-24T19:39:29.471099059Z,160,1,432669,A,A,64.820000000,1,26,8058566357258,128,15738,94343932,CLX5
2025-09-24T19:39:29.473020281Z,2025-09-24T19:39:29.471630109Z,160,1,432669,C,A,64.820000000,1,26,8058566357258,128,14506,94343938,CLX5
2025-09-24T19:39:29.473151641Z,2025-09-24T19:39:29.471822483Z,160,1,432669,A,A,64.820000000,1,26,8058566357260,128,18799,94343942,CLX5
2025-09-24T19:39:29.473219275Z,2025-09-24T19:39:29.472008773Z,160,1,432669,C,A,64.820000000,1,26,8058566357260,128,16421,94343945,CLX5
2025-09-24T19:39:29.473293767Z,2025-09-24T19:39:29.472056445Z,160,1,432669,M,A,64.830000000,1,26,8058566349378,128,15163,94343947,CLX5
2025-09-24T19:39:29.473829273Z,2025-09-24T19:39:29.472497451Z,160,1,432669,C,A,64.820000000,1,26,8058566357239,128,16163,94343970,CLX5
2025-09-24T19:39:29.475183485Z,2025-09-24T19:39:29.474733403Z,160,1,432669,A,B,64.810000000,2,26,8058566357300,128,14178,94344045,CLX5
2025-09-24T19:39:29.482771257Z,2025-09-24T19:39:29.482593173Z,160,1,432669,C,B,64.810000000,2,26,8058566357300,128,15586,94344124,CLX5
2025-09-24T19:39:29.511836158Z,2025-09-24T19:39:29.511697187Z,160,1,432669,A,A,64.870000000,2,26,8058566357337,128,18772,94344140,CLX5
2025-09-24T19:39:29.517426405Z,2025-09-24T19:39:29.517325361Z,160,1,432669,A,A,65.900000000,1,26,8058566357340,128,19707,94344144,CLX5
2025-09-24T19:39:29.524198059Z,2025-09-24T19:39:29.524098629Z,160,1,432669,C,B,64.540000000,8,26,8058566357219,128,18919,94344155,CLX5
2025-09-24T19:39:29.570365007Z,2025-09-24T19:39:29.570178631Z,160,1,432669,A,A,64.820000000,1,26,8058566357351,128,16067,94344171,CLX5
2025-09-24T19:39:29.570498885Z,2025-09-24T19:39:29.570370297Z,160,1,432669,C,B,64.810000000,1,26,8058566357038,128,15491,94344174,CLX5
2025-09-24T19:39:29.589459633Z,2025-09-24T19:39:29.589321147Z,160,1,432669,A,A,64.850000000,2,26,8058566357362,128,18284,94344213,CLX5
2025-09-24T19:39:29.589733710Z,2025-09-24T19:39:29.589323989Z,160,1,432669,A,A,64.820000000,2,26,8058566357367,128,15238,94344219,CLX5
2025-09-24T19:39:29.589949860Z,2025-09-24T19:39:29.589608271Z,160,1,432669,A,A,64.820000000,3,26,8058566357369,128,15937,94344227,CLX5
2025-09-24T19:39:29.590209646Z,2025-09-24T19:39:29.589688545Z,160,1,432669,A,A,64.820000000,1,26,8058566357375,128,19192,94344237,CLX5
2025-09-24T19:39:29.590432677Z,2025-09-24T19:39:29.589700139Z,160,1,432669,A,A,64.820000000,2,26,8058566357378,128,18287,94344247,CLX5
2025-09-24T19:39:29.590757147Z,2025-09-24T19:39:29.589954931Z,160,1,432669,C,B,64.810000000,1,26,8058566356480,128,20148,94344263,CLX5
2025-09-24T19:39:29.590811004Z,2025-09-24T19:39:29.589998245Z,160,1,432669,C,A,64.820000000,2,26,8058566357378,128,14321,94344265,CLX5
2025-09-24T19:39:29.591418368Z,2025-09-24T19:39:29.590608297Z,160,1,432669,M,B,63.640000000,4,26,8058566319851,128,14629,94344298,CLX5
2025-09-24T19:39:29.593418365Z,2025-09-24T19:39:29.593276097Z,160,1,432669,M,A,64.820000000,1,26,8058566349378,128,19326,94344305,CLX5
2025-09-24T19:39:29.611813719Z,2025-09-24T19:39:29.611685473Z,160,1,432669,C,A,64.870000000,2,26,8058566357337,128,18989,94344316,CLX5
2025-09-24T19:39:29.617505851Z,2025-09-24T19:39:29.617406437Z,160,1,432669,C,A,65.900000000,1,26,8058566357340,128,18684,94344317,CLX5
2025-09-24T19:39:29.642944632Z,2025-09-24T19:39:29.642793899Z,160,1,432669,A,A,64.820000000,1,26,8058566357415,128,18461,94344382,CLX5
2025-09-24T19:39:29.643083471Z,2025-09-24T19:39:29.642950909Z,160,1,432669,C,B,64.790000000,1,26,8058566357205,128,19433,94344383,CLX5
2025-09-24T19:39:29.740290582Z,2025-09-24T19:39:29.740146123Z,160,1,432669,A,B,64.780000000,1,26,8058566357425,128,17785,94344409,CLX5
2025-09-24T19:39:29.812136484Z,2025-09-24T19:39:29.811997207Z,160,1,432669,A,B,64.770000000,2,26,8058566357432,128,18561,94344425,CLX5
2025-09-24T19:39:30.023834154Z,2025-09-24T19:39:30.023691043Z,160,1,432669,A,A,64.840000000,1,26,8058566357446,128,18077,94344459,CLX5
2025-09-24T19:39:32.001812577Z,2025-09-24T19:39:32.001636549Z,160,1,432669,A,A,64.820000000,1,26,8058566357455,128,20712,94344498,CLX5
2025-09-24T19:39:32.385869766Z,2025-09-24T19:39:32.385684713Z,160,1,432669,C,A,64.850000000,2,26,8058566357362,128,16683,94344507,CLX5
2025-09-24T19:39:32.386097789Z,2025-09-24T19:39:32.385957571Z,160,1,432669,C,B,64.780000000,1,26,8058566357425,128,21431,94344512,CLX5
2025-09-24T19:39:32.397881078Z,2025-09-24T19:39:32.397748195Z,160,1,432669,C,B,64.770000000,2,26,8058566357432,128,20410,94344520,CLX5
2025-09-24T19:39:32.411821367Z,2025-09-24T19:39:32.411679273Z,160,1,432669,A,A,64.850000000,2,26,8058566357461,128,20526,94344522,CLX5
2025-09-24T19:39:32.540488042Z,2025-09-24T19:39:32.540344239Z,160,1,432669,A,B,64.780000000,1,26,8058566357463,128,20277,94344529,CLX5
2025-09-24T19:39:32.711917888Z,2025-09-24T19:39:32.711547673Z,160,1,432669,T,B,64.820000000,1,26,8058566357464,0,22579,94344530,CLX5
2025-09-24T19:39:32.711917888Z,2025-09-24T19:39:32.711547673Z,160,1,432669,F,A,64.820000000,1,26,8058566349748,0,22579,94344530,CLX5
2025-09-24T19:39:32.711929707Z,2025-09-24T19:39:32.711547673Z,160,1,432669,C,A,64.820000000,1,26,8058566349748,128,17398,94344531,CLX5
2025-09-24T19:39:33.595703147Z,2025-09-24T19:39:33.595533795Z,160,1,432669,A,B,64.810000000,1,26,8058566357469,128,25845,94344544,CLX5
2025-09-24T19:39:33.595843438Z,2025-09-24T19:39:33.595710869Z,160,1,432669,A,B,64.810000000,1,26,8058566357470,128,22862,94344545,CLX5
2025-09-24T19:39:37.862964183Z,2025-09-24T19:39:37.862805025Z,160,1,432669,C,A,64.820000000,3,26,8058566357369,128,19692,94344648,CLX5
2025-09-24T19:39:40.024201703Z,2025-09-24T19:39:40.024044219Z,160,1,432669,A,A,64.850000000,1,26,8058566357512,128,21927,94344702,CLX5
2025-09-24T19:39:40.761092138Z,2025-09-24T19:39:40.760957669Z,160,1,432669,C,A,64.820000000,1,26,8058566357240,128,15704,94344754,CLX5
2025-09-24T19:39:40.761239956Z,2025-09-24T19:39:40.761110859Z,160,1,432669,C,A,64.820000000,1,26,8058566357415,128,19270,94344759,CLX5
2025-09-24T19:39:40.762244615Z,2025-09-24T19:39:40.762103783Z,160,1,432669,M,A,64.830000000,1,26,8058566349378,128,20181,94344763,CLX5
2025-09-24T19:39:40.763168663Z,2025-09-24T19:39:40.763047997Z,160,1,432669,C,A,64.820000000,1,26,8058566357375,128,15898,94344765,CLX5
2025-09-24T19:39:40.911910110Z,2025-09-24T19:39:40.911761851Z,160,1,432669,A,B,64.770000000,2,26,8058566357527,128,18486,94344783,CLX5
2025-09-24T19:39:40.948645182Z,2025-09-24T19:39:40.948504347Z,160,1,432669,A,B,64.800000000,1,26,8058566357528,128,18168,94344784,CLX5
2025-09-24T19:39:42.651906968Z,2025-09-24T19:39:42.651707889Z,160,1,432669,A,A,64.820000000,1,26,8058566357540,128,19056,94344830,CLX5
2025-09-24T19:39:42.652143492Z,2025-09-24T19:39:42.651913879Z,160,1,432669,A,A,64.820000000,1,26,8058566357544,128,19099,94344843,CLX5
2025-09-24T19:39:42.890716913Z,2025-09-24T19:39:42.890579603Z,160,1,432669,C,B,64.800000000,1,26,8058566357528,128,19141,94344908,CLX5
2025-09-24T19:39:42.894401421Z,2025-09-24T19:39:42.894272963Z,160,1,432669,C,B,64.810000000,1,26,8058566357470,128,20929,94344915,CLX5
2025-09-24T19:39:44.321453488Z,2025-09-24T19:39:44.321263711Z,160,1,432669,A,B,64.810000000,4,26,8058566357569,128,25078,94344947,CLX5
2025-09-24T19:39:44.321601727Z,2025-09-24T19:39:44.321461327Z,160,1,432669,C,A,64.820000000,1,26,8058566357544,128,21229,94344948,CLX5
2025-09-24T19:39:44.321612325Z,2025-09-24T19:39:44.321462753Z,160,1,432669,A,B,64.810000000,1,26,8058566357570,128,14700,94344949,CLX5
2025-09-24T19:39:44.321834035Z,2025-09-24T19:39:44.321610045Z,160,1,432669,C,A,64.820000000,1,26,8058566357540,128,14673,94344955,CLX5
2025-09-24T19:39:45.413774631Z,2025-09-24T19:39:45.413415487Z,160,1,432669,T,A,64.810000000,1,26,8058566357577,0,18028,94344967,CLX5
2025-09-24T19:39:45.413774631Z,2025-09-24T19:39:45.413415487Z,160,1,432669,F,B,64.810000000,1,26,8058566356316,0,18028,94344967,CLX5
2025-09-24T19:39:45.413786281Z,2025-09-24T19:39:45.413415487Z,160,1,432669,C,B,64.810000000,1,26,8058566356316,128,16447,94344968,CLX5
2025-09-24T19:39:45.414172680Z,2025-09-24T19:39:45.413752319Z,160,1,432669,A,A,64.820000000,1,26,8058566357580,128,16005,94344974,CLX5
2025-09-24T19:39:45.414216883Z,2025-09-24T19:39:45.413752509Z,160,1,432669,C,B,64.810000000,1,26,8058566357570,128,19565,94344975,CLX5
2025-09-24T19:39:45.414247571Z,2025-09-24T19:39:45.413754007Z,160,1,432669,A,A,64.820000000,1,26,8058566357581,128,14276,94344976,CLX5
2025-09-24T19:39:46.397504062Z,2025-09-24T19:39:46.397371377Z,160,1,432669,M,A,64.940000000,1,26,8058566157942,128,20721,94345030,CLX5
2025-09-24T19:39:47.103259156Z,2025-09-24T19:39:47.103096869Z,160,1,432669,C,A,64.820000000,1,26,8058566357580,128,18751,94345056,CLX5
2025-09-24T19:39:47.103445932Z,2025-09-24T19:39:47.103265551Z,160,1,432669,C,A,64.820000000,1,26,8058566357581,128,15872,94345059,CLX5
2025-09-24T19:39:47.103492992Z,2025-09-24T19:39:47.103267127Z,160,1,432669,A,B,64.810000000,1,26,8058566357599,128,18989,94345060,CLX5
2025-09-24T19:39:47.881820159Z,2025-09-24T19:39:47.881675811Z,160,1,432669,A,A,64.820000000,1,26,8058566357605,128,23683,94345083,CLX5
2025-09-24T19:39:47.881848596Z,2025-09-24T19:39:47.881681417Z,160,1,432669,A,A,64.820000000,1,26,8058566357606,128,18055,94345084,CLX5
2025-09-24T19:39:50.024287472Z,2025-09-24T19:39:50.024131683Z,160,1,432669,A,A,64.860000000,1,26,8058566357626,128,19354,94345152,CLX5
2025-09-24T19:39:50.282228645Z,2025-09-24T19:39:50.282079135Z,160,1,432669,C,A,64.820000000,1,26,8058566357605,128,15843,94345154,CLX5
2025-09-24T19:39:50.283071234Z,2025-09-24T19:39:50.282937395Z,160,1,432669,A,A,64.820000000,2,26,8058566357633,128,19831,94345178,CLX5
2025-09-24T19:39:50.283215005Z,2025-09-24T19:39:50.283076645Z,160,1,432669,C,B,64.810000000,1,26,8058566357599,128,19232,94345182,CLX5
2025-09-24T19:39:50.317979122Z,2025-09-24T19:39:50.317848615Z,160,1,432669,C,B,64.770000000,2,26,8058566357527,128,18283,94345223,CLX5
2025-09-24T19:39:53.000855327Z,2025-09-24T19:39:53.000674857Z,160,1,432669,C,A,64.820000000,1,26,8058566354651,128,24851,94345427,CLX5
2025-09-24T19:39:53.340267207Z,2025-09-24T19:39:53.340043521Z,160,1,432669,C,A,64.820000000,1,26,8058566357606,128,16012,94345447,CLX5
2025-09-24T19:39:53.340311280Z,2025-09-24T19:39:53.340045461Z,160,1,432669,A,B,64.810000000,1,26,8058566357716,128,18938,94345448,CLX5
2025-09-24T19:39:53.511924305Z,2025-09-24T19:39:53.511780501Z,160,1,432669,A,B,64.770000000,2,26,8058566357719,128,18401,94345465,CLX5
2025-09-24T19:39:53.647669355Z,2025-09-24T19:39:53.646813713Z,160,1,432669,A,A,64.820000000,1,26,8058566357723,128,15648,94345476,CLX5
2025-09-24T19:39:53.647854226Z,2025-09-24T19:39:53.646952965Z,160,1,432669,C,B,64.770000000,2,26,8058566357719,128,14737,94345484,CLX5
2025-09-24T19:39:53.647945367Z,2025-09-24T19:39:53.646993975Z,160,1,432669,C,B,64.810000000,1,26,8058566357716,128,19498,94345486,CLX5
2025-09-24T19:39:53.647978881Z,2025-09-24T19:39:53.646995491Z,160,1,432669,A,A,64.820000000,1,26,8058566357726,128,16078,94345487,CLX5
2025-09-24T19:39:53.648031924Z,2025-09-24T19:39:53.647023425Z,160,1,432669,C,A,64.820000000,1,26,8058566357723,128,16051,94345489,CLX5
2025-09-24T19:39:53.648083270Z,2025-09-24T19:39:53.647068199Z,160,1,432669,A,A,64.820000000,1,26,8058566357728,128,15552,94345491,CLX5
2025-09-24T19:39:53.648682240Z,2025-09-24T19:39:53.647912923Z,160,1,432669,C,A,64.820000000,1,26,8058566357728,128,16399,94345529,CLX5
2025-09-24T19:39:53.648750880Z,2025-09-24T19:39:53.647950957Z,160,1,432669,A,B,64.810000000,1,26,8058566357740,128,16017,94345531,CLX5
2025-09-24T19:39:53.648787504Z,2025-09-24T19:39:53.647995595Z,160,1,432669,A,A,64.820000000,1,26,8058566357741,128,18789,94345532,CLX5
2025-09-24T19:39:53.648959174Z,2025-09-24T19:39:53.648230765Z,160,1,432669,A,B,64.810000000,1,26,8058566357744,128,15236,94345542,CLX5
2025-09-24T19:39:53.649178526Z,2025-09-24T19:39:53.648831335Z,160,1,432669,A,B,64.540000000,8,26,8058566357751,128,18911,94345557,CLX5
2025-09-24T19:39:53.649294549Z,2025-09-24T19:39:53.648969393Z,160,1,432669,C,B,64.810000000,1,26,8058566357744,128,18559,94345562,CLX5
2025-09-24T19:39:53.649596235Z,2025-09-24T19:39:53.649299545Z,160,1,432669,C,B,64.810000000,1,26,8058566357740,128,18751,94345578,CLX5
2025-09-24T19:39:53.650774869Z,2025-09-24T19:39:53.650606545Z,160,1,432669,A,A,64.820000000,3,26,8058566357771,128,18616,94345622,CLX5
2025-09-24T19:39:57.002946717Z,2025-09-24T19:39:57.002626109Z,160,1,432669,T,B,64.820000000,1,26,8058566357875,0,17837,94345976,CLX5
2025-09-24T19:39:57.002946717Z,2025-09-24T19:39:57.002626109Z,160,1,432669,F,A,64.820000000,1,26,8058566350235,0,17837,94345976,CLX5
2025-09-24T19:39:57.002960102Z,2025-09-24T19:39:57.002626109Z,160,1,432669,C,A,64.820000000,1,26,8058566350235,128,16393,94345977,CLX5
2025-09-24T19:39:57.003322096Z,2025-09-24T19:39:57.003161537Z,160,1,432669,A,B,64.810000000,1,26,8058566357881,128,15842,94345994,CLX5
2025-09-24T19:39:57.010824832Z,2025-09-24T19:39:57.010664525Z,160,1,432669,A,A,64.820000000,1,26,8058566357888,128,20097,94346011,CLX5
2025-09-24T19:39:57.013809000Z,2025-09-24T19:39:57.013630833Z,160,1,432669,C,B,64.810000000,1,26,8058566357881,128,16582,94346018,CLX5
2025-09-24T19:39:57.117665464Z,2025-09-24T19:39:57.117557981Z,160,1,432669,C,A,65.700000000,6,26,8058566353536,128,18585,94346049,CLX5
2025-09-24T19:39:58.064729464Z,2025-09-24T19:39:58.064557563Z,160,1,432669,A,B,64.790000000,1,26,8058566357903,128,16402,94346130,CLX5
2025-09-24T19:39:58.258891368Z,2025-09-24T19:39:58.258753925Z,160,1,432669,C,B,64.790000000,1,26,8058566357903,128,18183,94346152,CLX5
2025-09-24T19:39:58.314150199Z,2025-09-24T19:39:58.313962567Z,160,1,432669,A,B,64.810000000,1,26,8058566357915,128,15853,94346178,CLX5
2025-09-24T19:39:58.314282987Z,2025-09-24T19:39:58.313977867Z,160,1,432669,A,B,64.790000000,1,26,8058566357917,128,14546,94346182,CLX5
2025-09-24T19:39:58.314404786Z,2025-09-24T19:39:58.314156921Z,160,1,432669,C,A,64.820000000,1,26,8058566357726,128,15163,94346186,CLX5
2025-09-24T19:39:58.314439505Z,2025-09-24T19:39:58.314158417Z,160,1,432669,A,B,64.810000000,1,26,8058566357919,128,14781,94346187,CLX5
2025-09-24T19:39:58.314475676Z,2025-09-24T19:39:58.314173489Z,160,1,432669,A,B,64.810000000,1,26,8058566357920,128,18182,94346188,CLX5
2025-09-24T19:39:58.314545330Z,2025-09-24T19:39:58.314199445Z,160,1,432669,C,A,64.820000000,3,26,8058566357771,128,14465,94346190,CLX5
2025-09-24T19:39:58.314795377Z,2025-09-24T19:39:58.314380033Z,160,1,432669,C,B,64.810000000,1,26,8058566357920,128,17493,94346196,CLX5
2025-09-24T19:39:58.314916708Z,2025-09-24T19:39:58.314560909Z,160,1,432669,C,A,64.820000000,1,26,8058566357741,128,18705,94346201,CLX5
2025-09-24T19:39:58.317890194Z,2025-09-24T19:39:58.317774579Z,160,1,432669,A,A,65.700000000,6,26,8058566357925,128,18020,94346208,CLX5
2025-09-24T19:39:58.393511760Z,2025-09-24T19:39:58.393334495Z,160,1,432669,A,A,64.820000000,1,26,8058566357928,128,15803,94346219,CLX5
2025-09-24T19:39:58.406342193Z,2025-09-24T19:39:58.406212903Z,160,1,432669,C,B,64.810000000,1,26,8058566357919,128,18088,94346237,CLX5
2025-09-24T19:39:58.417617162Z,2025-09-24T19:39:58.417517441Z,160,1,432669,C,A,65.700000000,6,26,8058566357925,128,18950,94346243,CLX5
2025-09-24T19:39:58.506464900Z,2025-09-24T19:39:58.506310895Z,160,1,432669,A,A,64.820000000,3,26,8058566357933,128,19080,94346244,CLX5
2025-09-24T19:40:00.003671375Z,2025-09-24T19:40:00.003516463Z,160,1,432669,M,B,64.740000000,17,26,8058566163289,128,17895,94346284,CLX5
2025-09-24T19:40:00.051287290Z,2025-09-24T19:40:00.051147833Z,160,1,432669,A,B,64.810000000,1,26,8058566357958,128,18523,94346372,CLX5
2025-09-24T19:40:00.051429210Z,2025-09-24T19:40:00.051293171Z,160,1,432669,C,A,64.820000000,1,26,8058566357928,128,14983,94346378,CLX5
2025-09-24T19:40:00.051464160Z,2025-09-24T19:40:00.051297569Z,160,1,432669,C,A,64.820000000,2,26,8058566357633,128,15571,94346379,CLX5
2025-09-24T19:40:00.051727816Z,2025-09-24T19:40:00.051445037Z,160,1,432669,C,A,64.820000000,3,26,8058566357933,128,19565,94346391,CLX5
2025-09-24T19:40:00.056755426Z,2025-09-24T19:40:00.056557693Z,160,1,432669,C,A,64.820000000,1,26,8058566357351,128,15785,94346500,CLX5
2025-09-24T19:40:00.056795744Z,2025-09-24T19:40:00.056558001Z,160,1,432669,C,A,64.820000000,2,26,8058566357367,128,19318,94346501,CLX5
2025-09-24T19:40:00.056818053Z,2025-09-24T19:40:00.056558193Z,160,1,432669,C,A,64.850000000,2,26,8058566357461,128,14543,94346502,CLX5
2025-09-24T19:40:00.057697383Z,2025-09-24T19:40:00.057442661Z,160,1,432669,A,A,64.820000000,2,26,8058566358015,128,19713,94346534,CLX5
2025-09-24T19:40:00.111981264Z,2025-09-24T19:40:00.111833957Z,160,1,432669,A,A,64.870000000,2,26,8058566358030,128,18108,94346574,CLX5
2025-09-24T19:40:00.117668582Z,2025-09-24T19:40:00.117559893Z,160,1,432669,A,A,65.900000000,1,26,8058566358031,128,17825,94346575,CLX5
2025-09-24T19:40:00.117709922Z,2025-09-24T19:40:00.117611251Z,160,1,432669,A,A,65.700000000,6,26,8058566358032,128,14202,94346576,CLX5
2025-09-24T19:40:00.124441543Z,2025-09-24T19:40:00.124336463Z,160,1,432669,C,B,64.540000000,8,26,8058566357751,128,18545,94346590,CLX5
2025-09-24T19:40:00.213241008Z,2025-09-24T19:40:00.212940421Z,160,1,432669,C,A,64.820000000,2,26,8058566358015,128,17976,94346617,CLX5
2025-09-24T19:40:00.213377651Z,2025-09-24T19:40:00.213240985Z,160,1,432669,C,A,64.820000000,1,26,8058566357238,128,15523,94346621,CLX5
2025-09-24T19:40:00.213520860Z,2025-09-24T19:40:00.213388913Z,160,1,432669,A,B,64.810000000,2,26,8058566358051,128,19761,94346624,CLX5
2025-09-24T19:40:00.214284527Z,2025-09-24T19:40:00.214145531Z,160,1,432669,M,B,64.810000000,1,26,8058566319851,128,18398,94346626,CLX5
2025-09-24T19:40:00.221235446Z,2025-09-24T19:40:00.221075485Z,160,1,432669,M,A,64.830000000,1,26,8058566357888,128,22715,94346632,CLX5
2025-09-24T19:40:00.411979691Z,2025-09-24T19:40:00.411838461Z,160,1,432669,A,B,64.770000000,2,26,8058566358067,128,18493,94346654,CLX5
2025-09-24T19:40:01.466026005Z,2025-09-24T19:40:01.465853197Z,160,1,432669,A,B,64.810000000,2,26,8058566358079,128,23448,94346675,CLX5
2025-09-24T19:40:01.949856243Z,2025-09-24T19:40:01.949698323Z,160,1,432669,A,B,64.810000000,1,26,8058566358085,128,18578,94346683,CLX5
2025-09-24T19:40:02.530077386Z,2025-09-24T19:40:02.529883071Z,160,1,432669,M,A,64.900000000,3,26,8058566144143,128,30875,94346684,CLX5
2025-09-24T19:40:03.687326662Z,2025-09-24T19:40:03.687175747Z,160,1,432669,C,A,65.090000000,1,26,8058566356147,128,24267,94346689,CLX5
2025-09-24T19:40:03.702826293Z,2025-09-24T19:40:03.702708745Z,160,1,432669,A,A,65.080000000,1,26,8058566358088,128,20745,94346691,CLX5
2025-09-24T19:40:04.816388078Z,2025-09-24T19:40:04.816249145Z,160,1,432669,C,A,65.090000000,1,26,8058566356134,128,21482,94346694,CLX5
2025-09-24T19:40:04.879232209Z,2025-09-24T19:40:04.879097265Z,160,1,432669,A,A,65.080000000,1,26,8058566358089,128,24574,94346695,CLX5
2025-09-24T19:40:07.645361655Z,2025-09-24T19:40:07.645201137Z,160,1,432669,C,A,64.870000000,1,26,8058566325711,128,19200,94346786,CLX5
2025-09-24T19:40:07.761281696Z,2025-09-24T19:40:07.761137007Z,160,1,432669,A,A,64.860000000,1,26,8058566358118,128,18514,94346787,CLX5
2025-09-24T19:40:09.540848388Z,2025-09-24T19:40:09.540520899Z,160,1,432669,T,B,64.820000000,1,26,8058566358146,0,18358,94346871,CLX5
2025-09-24T19:40:09.540848388Z,2025-09-24T19:40:09.540520899Z,160,1,432669,F,A,64.820000000,1,26,8058566354363,0,18358,94346871,CLX5
2025-09-24T19:40:09.540861551Z,2025-09-24T19:40:09.540520899Z,160,1,432669,C,A,64.820000000,1,26,8058566354363,128,18099,94346872,CLX5
2025-09-24T19:40:09.541004545Z,2025-09-24T19:40:09.540851143Z,160,1,432669,C,A,64.820000000,1,26,8058566357230,128,21212,94346873,CLX5
2025-09-24T19:40:09.541040716Z,2025-09-24T19:40:09.540857019Z,160,1,432669,A,B,64.780000000,1,26,8058566358147,128,13731,94346874,CLX5
2025-09-24T19:40:09.541111821Z,2025-09-24T19:40:09.540901023Z,160,1,432669,C,A,64.820000000,1,26,8058566357211,128,17496,94346876,CLX5
2025-09-24T19:40:09.541658178Z,2025-09-24T19:40:09.541487713Z,160,1,432669,A,B,64.800000000,2,26,8058566358149,128,14557,94346879,CLX5
2025-09-24T19:40:09.541667547Z,2025-09-24T19:40:09.541489669Z,160,1,432669,A,B,64.540000000,8,26,8058566358150,128,14496,94346880,CLX5
2025-09-24T19:40:09.541667547Z,2025-09-24T19:40:09.541494853Z,160,1,432669,C,B,64.770000000,2,26,8058566358067,128,14496,94346880,CLX5
2025-09-24T19:40:09.542019841Z,2025-09-24T19:40:09.541679339Z,160,1,432669,T,B,64.820000000,3,26,8058566358151,0,18169,94346882,CLX5
2025-09-24T19:40:09.542019841Z,2025-09-24T19:40:09.541679339Z,160,1,432669,F,A,64.820000000,1,26,8058566356287,0,18169,94346882,CLX5
2025-09-24T19:40:09.542019841Z,2025-09-24T19:40:09.541679339Z,160,1,432669,F,A,64.820000000,1,26,8058566357200,0,18169,94346882,CLX5
2025-09-24T19:40:09.542019841Z,2025-09-24T19:40:09.541679339Z,160,1,432669,F,A,64.820000000,1,26,8058566357455,0,18169,94346882,CLX5
2025-09-24T19:40:09.542029686Z,2025-09-24T19:40:09.541679339Z,160,1,432669,C,A,64.820000000,1,26,8058566356287,0,14863,94346883,CLX5
2025-09-24T19:40:09.542029686Z,2025-09-24T19:40:09.541679339Z,160,1,432669,C,A,64.820000000,1,26,8058566357200,0,14863,94346883,CLX5
2025-09-24T19:40:09.542029686Z,2025-09-24T19:40:09.541679339Z,160,1,432669,C,A,64.820000000,1,26,8058566357455,128,14863,94346883,CLX5
2025-09-24T19:40:09.542060551Z,2025-09-24T19:40:09.541696619Z,160,1,432669,A,B,64.810000000,1,26,8058566358152,128,14865,94346886,CLX5
2025-09-24T19:40:09.542091538Z,2025-09-24T19:40:09.541835715Z,160,1,432669,A,B,64.810000000,1,26,8058566358154,128,13870,94346889,CLX5
2025-09-24T19:40:09.542242956Z,2025-09-24T19:40:09.541906311Z,160,1,432669,C,A,64.830000000,1,26,8058566345966,128,17231,94346893,CLX5
2025-09-24T19:40:09.542275687Z,2025-09-24T19:40:09.541947205Z,160,1,432669,A,B,64.810000000,1,26,8058566358156,128,15351,94346894,CLX5
2025-09-24T19:40:09.542366590Z,2025-09-24T19:40:09.541981437Z,160,1,432669,C,B,64.780000000,1,26,8058566357463,128,15153,94346896,CLX5
2025-09-24T19:40:09.542423189Z,2025-09-24T19:40:09.542020125Z,160,1,432669,A,B,64.820000000,1,26,8058566358158,128,14595,94346897,CLX5
2025-09-24T19:40:09.543389252Z,2025-09-24T19:40:09.542085017Z,160,1,432669,A,B,64.810000000,1,26,8058566358167,128,18016,94346934,CLX5
2025-09-24T19:40:09.543493564Z,2025-09-24T19:40:09.542133839Z,160,1,432669,A,B,64.810000000,3,26,8058566358168,128,18150,94346940,CLX5
2025-09-24T19:40:09.543815070Z,2025-09-24T19:40:09.542437513Z,160,1,432669,C,B,64.800000000,1,26,8058566349470,128,14706,94346955,CLX5
2025-09-24T19:40:09.543932192Z,2025-09-24T19:40:09.542465737Z,160,1,432669,C,B,64.780000000,1,26,8058566335785,128,15321,94346960,CLX5
2025-09-24T19:40:09.543999480Z,2025-09-24T19:40:09.542470553Z,160,1,432669,A,B,64.820000000,1,26,8058566358178,128,14950,94346962,CLX5
2025-09-24T19:40:09.544233094Z,2025-09-24T19:40:09.542570121Z,160,1,432669,A,A,64.830000000,1,26,8058566358182,128,15304,94346977,CLX5
2025-09-24T19:40:09.545039344Z,2025-09-24T19:40:09.542788051Z,160,1,432669,M,B,64.810000000,1,26,8058566319508,128,17844,94347015,CLX5
2025-09-24T19:40:09.545165128Z,2025-09-24T19:40:09.542806291Z,160,1,432669,M,B,64.800000000,1,26,8058566329044,128,15208,94347020,CLX5
2025-09-24T19:40:09.545872119Z,2025-09-24T19:40:09.542920025Z,160,1,432669,A,B,64.820000000,1,26,8058566358203,128,14288,94347048,CLX5
2025-09-24T19:40:09.545994163Z,2025-09-24T19:40:09.542987127Z,160,1,432669,M,A,65.990000000,4,26,8058566342145,128,15352,94347055,CLX5
2025-09-24T19:40:09.546078769Z,2025-09-24T19:40:09.543047527Z,160,1,432669,A,B,64.820000000,2,26,8058566358204,128,14510,94347058,CLX5
2025-09-24T19:40:09.546762346Z,2025-09-24T19:40:09.543505043Z,160,1,432669,A,B,64.820000000,2,26,8058566358215,128,20589,94347088,CLX5
2025-09-24T19:40:09.546884789Z,2025-09-24T19:40:09.543521037Z,160,1,432669,A,B,64.820000000,2,26,8058566358218,128,17908,94347091,CLX5
2025-09-24T19:40:09.547042766Z,2025-09-24T19:40:09.543603785Z,160,1,432669,C,A,64.830000000,1,26,8058566345875,128,13851,94347096,CLX5
2025-09-24T19:40:09.547350119Z,2025-09-24T19:40:09.543912891Z,160,1,432669,A,B,64.820000000,2,26,8058566358223,128,16401,94347111,CLX5
2025-09-24T19:40:09.547569410Z,2025-09-24T19:40:09.544037435Z,160,1,432669,C,A,64.830000000,2,26,8058566345878,128,18007,94347118,CLX5
2025-09-24T19:40:09.547729599Z,2025-09-24T19:40:09.544175959Z,160,1,432669,A,B,64.820000000,1,26,8058566358230,128,15825,94347126,CLX5
2025-09-24T19:40:09.548457471Z,2025-09-24T19:40:09.544633301Z,160,1,432669,C,A,64.830000000,1,26,8058566345742,128,14949,94347162,CLX5
2025-09-24T19:40:09.548492244Z,2025-09-24T19:40:09.544633455Z,160,1,432669,C,A,64.830000000,1,26,8058566345743,128,17268,94347163,CLX5
2025-09-24T19:40:09.549196578Z,2025-09-24T19:40:09.545564403Z,160,1,432669,M,A,64.840000000,1,26,8058566173085,128,13489,94347202,CLX5
2025-09-24T19:40:09.549771373Z,2025-09-24T19:40:09.546492931Z,160,1,432669,A,B,64.820000000,1,26,8058566358254,128,15792,94347228,CLX5
2025-09-24T19:40:09.551010453Z,2025-09-24T19:40:09.547739493Z,160,1,432669,A,A,64.830000000,1,26,8058566358269,128,16357,94347292,CLX5
2025-09-24T19:40:09.554286408Z,2025-09-24T19:40:09.554102323Z,160,1,432669,C,A,64.830000000,1,26,8058566358269,128,15036,94347457,CLX5
2025-09-24T19:40:09.554434263Z,2025-09-24T19:40:09.554304585Z,160,1,432669,A,A,64.830000000,1,26,8058566358309,128,18335,94347460,CLX5
2025-09-24T19:40:09.554702900Z,2025-09-24T19:40:09.554533881Z,160,1,432669,C,A,64.830000000,1,26,8058566358309,128,15836,94347479,CLX5
2025-09-24T19:40:09.554867400Z,2025-09-24T19:40:09.554693311Z,160,1,432669,A,A,64.830000000,1,26,8058566358311,128,14812,94347488,CLX5
2025-09-24T19:40:09.565485441Z,2025-09-24T19:40:09.565225909Z,160,1,432669,C,B,64.810000000,1,26,8058566357469,128,15893,94347659,CLX5
2025-09-24T19:40:09.603257661Z,2025-09-24T19:40:09.603113593Z,160,1,432669,C,A,64.830000000,1,26,8058566358311,128,18293,94347739,CLX5
2025-09-24T19:40:09.603390380Z,2025-09-24T19:40:09.603262233Z,160,1,432669,C,B,64.780000000,1,26,8058566358147,128,18469,94347743,CLX5
2025-09-24T19:40:09.603429392Z,2025-09-24T19:40:09.603287979Z,160,1,432669,C,B,64.810000000,1,26,8058566358167,128,14973,94347745,CLX5
2025-09-24T19:40:09.609388145Z,2025-09-24T19:40:09.609275141Z,160,1,432669,M,B,64.390000000,4,26,8058559498241,128,18223,94347751,CLX5
2025-09-24T19:40:09.612090262Z,2025-09-24T19:40:09.611919689Z,160,1,432669,C,B,64.780000000,2,26,8058566349492,128,15357,94347757,CLX5
2025-09-24T19:40:09.617702015Z,2025-09-24T19:40:09.617600315Z,160,1,432669,C,B,64.160000000,2,26,8058566337918,128,17917,94347759,CLX5
2025-09-24T19:40:09.627621297Z,2025-09-24T19:40:09.627492755Z,160,1,432669,C,B,64.820000000,1,26,8058566358254,128,20454,94347762,CLX5
2025-09-24T19:40:09.627753739Z,2025-09-24T19:40:09.627626669Z,160,1,432669,C,B,64.820000000,2,26,8058566358215,128,19899,94347763,CLX5
2025-09-24T19:40:09.630920812Z,2025-09-24T19:40:09.630809601Z,160,1,432669,M,B,64.390000000,4,26,8058559498258,128,17116,94347765,CLX5
2025-09-24T19:40:09.689247758Z,2025-09-24T19:40:09.689103337Z,160,1,432669,A,B,64.820000000,1,26,8058566358471,128,18943,94347931,CLX5
2025-09-24T19:40:09.689402540Z,2025-09-24T19:40:09.689276917Z,160,1,432669,C,B,64.810000000,1,26,8058566358156,128,14494,94347935,CLX5
2025-09-24T19:40:09.689437159Z,2025-09-24T19:40:09.689286515Z,160,1,432669,C,B,64.810000000,1,26,8058566358152,128,17788,94347936,CLX5
2025-09-24T19:40:09.710745246Z,2025-09-24T19:40:09.710598767Z,160,1,432669,A,B,64.820000000,1,26,8058566358483,128,19593,94347966,CLX5
2025-09-24T19:40:09.710909481Z,2025-09-24T19:40:09.710766317Z,160,1,432669,A,A,64.830000000,1,26,8058566358485,128,19161,94347970,CLX5
2025-09-24T19:40:09.711582022Z,2025-09-24T19:40:09.711455701Z,160,1,432669,C,A,64.830000000,1,26,8058566358485,128,18220,94347973,CLX5
2025-09-24T19:40:09.712026832Z,2025-09-24T19:40:09.711835363Z,160,1,432669,C,A,64.830000000,1,26,8058566345921,128,17000,94347978,CLX5
2025-09-24T19:40:09.712179241Z,2025-09-24T19:40:09.711924255Z,160,1,432669,M,A,64.950000000,1,26,8058565075241,128,15556,94347984,CLX5
2025-09-24T19:40:09.714832550Z,2025-09-24T19:40:09.713410981Z,160,1,432669,M,A,64.840000000,1,26,8058566354507,128,14969,94348097,CLX5
2025-09-24T19:40:09.715789164Z,2025-09-24T19:40:09.713728267Z,160,1,432669,C,A,64.830000000,2,26,8058566335294,128,14889,94348140,CLX5
2025-09-24T19:40:09.715997960Z,2025-09-24T19:40:09.713734603Z,160,1,432669,C,A,64.830000000,1,26,8058566345625,128,14814,94348150,CLX5
2025-09-24T19:40:09.716565774Z,2025-09-24T19:40:09.713795193Z,160,1,432669,A,B,64.820000000,1,26,8058566358552,128,17874,94348176,CLX5
2025-09-24T19:40:09.716666561Z,2025-09-24T19:40:09.713798055Z,160,1,432669,C,A,64.830000000,1,26,8058566335292,128,18362,94348178,CLX5
2025-09-24T19:40:09.716700873Z,2025-09-24T19:40:09.713798785Z,160,1,432669,A,B,64.820000000,1,26,8058566358553,128,15945,94348179,CLX5
2025-09-24T19:40:09.716733711Z,2025-09-24T19:40:09.713799399Z,160,1,432669,A,B,64.820000000,1,26,8058566358554,128,15674,94348180,CLX5
2025-09-24T19:40:09.717132605Z,2025-09-24T19:40:09.713846437Z,160,1,432669,C,B,64.820000000,1,26,8058566358552,128,19781,94348195,CLX5
2025-09-24T19:40:09.717401260Z,2025-09-24T19:40:09.714006713Z,160,1,432669,C,B,64.820000000,1,26,8058566358553,128,17093,94348210,CLX5
2025-09-24T19:40:09.718369166Z,2025-09-24T19:40:09.714350339Z,160,1,432669,C,B,64.760000000,2,26,8058566350576,128,18238,94348261,CLX5
2025-09-24T19:40:09.718646207Z,2025-09-24T19:40:09.714415883Z,160,1,432669,C,A,64.860000000,2,26,8058566345929,128,14710,94348275,CLX5
2025-09-24T19:40:09.718774364Z,2025-09-24T19:40:09.714420031Z,160,1,432669,C,A,64.830000000,1,26,8058566345788,128,15554,94348280,CLX5
2025-09-24T19:40:09.719604598Z,2025-09-24T19:40:09.714705543Z,160,1,432669,A,B,64.810000000,2,26,8058566358590,128,14611,94348329,CLX5
2025-09-24T19:40:09.719909831Z,2025-09-24T19:40:09.714798217Z,160,1,432669,A,B,64.820000000,1,26,8058566358597,128,18031,94348345,CLX5
2025-09-24T19:40:09.720079089Z,2025-09-24T19:40:09.714863935Z,160,1,432669,T,B,64.830000000,1,26,8058566358602,0,14982,94348355,CLX5
2025-09-24T19:40:09.720079089Z,2025-09-24T19:40:09.714863935Z,160,1,432669,F,A,64.830000000,1,26,8058566335059,0,14982,94348355,CLX5
2025-09-24T19:40:09.720119446Z,2025-09-24T19:40:09.714863935Z,160,1,432669,M,A,64.830000000,1,26,8058566335059,128,19323,94348356,CLX5
2025-09-24T19:40:09.720187633Z,2025-09-24T19:40:09.714864289Z,160,1,432669,T,B,64.830000000,1,26,8058566358604,0,14889,94348360,CLX5
2025-09-24T19:40:09.720187633Z,2025-09-24T19:40:09.714864289Z,160,1,432669,F,A,64.830000000,1,26,8058566335059,0,14889,94348360,CLX5
2025-09-24T19:40:09.720187633Z,2025-09-24T19:40:09.714864289Z,160,1,432669,C,A,64.830000000,1,26,8058566335059,128,14889,94348360,CLX5
2025-09-24T19:40:09.720594283Z,2025-09-24T19:40:09.715066409Z,160,1,432669,A,B,64.800000000,1,26,8058566358610,128,14947,94348381,CLX5
2025-09-24T19:40:09.720706559Z,2025-09-24T19:40:09.715128939Z,160,1,432669,C,A,64.830000000,1,26,8058566345827,128,14485,94348385,CLX5
2025-09-24T19:40:09.720942368Z,2025-09-24T19:40:09.715411935Z,160,1,432669,A,B,64.820000000,1,26,8058566358616,128,15095,94348396,CLX5
2025-09-24T19:40:09.721181004Z,2025-09-24T19:40:09.715745885Z,160,1,432669,C,B,64.820000000,1,26,8058566358554,128,14840,94348405,CLX5
2025-09-24T19:40:09.721308017Z,2025-09-24T19:40:09.716117927Z,160,1,432669,A,B,64.820000000,1,26,8058566358622,128,15553,94348411,CLX5
2025-09-24T19:40:09.721349932Z,2025-09-24T19:40:09.716177945Z,160,1,432669,A,B,64.820000000,1,26,8058566358623,128,13578,94348413,CLX5
2025-09-24T19:40:09.721860526Z,2025-09-24T19:40:09.716575251Z,160,1,432669,C,B,64.820000000,1,26,8058566358623,128,17600,94348443,CLX5
2025-09-24T19:40:09.722059819Z,2025-09-24T19:40:09.716797001Z,160,1,432669,C,B,64.820000000,1,26,8058566358622,128,17164,94348454,CLX5
2025-09-24T19:40:09.722261685Z,2025-09-24T19:40:09.717433339Z,160,1,432669,A,B,64.820000000,2,26,8058566358628,128,17614,94348465,CLX5
2025-09-24T19:40:09.723010476Z,2025-09-24T19:40:09.718570485Z,160,1,432669,A,B,64.820000000,1,26,8058566358639,128,18157,94348507,CLX5
2025-09-24T19:40:09.723038085Z,2025-09-24T19:40:09.718571617Z,160,1,432669,A,B,64.820000000,1,26,8058566358640,128,14761,94348508,CLX5
2025-09-24T19:40:09.723571302Z,2025-09-24T19:40:09.718748249Z,160,1,432669,A,B,64.820000000,1,26,8058566358649,128,14927,94348539,CLX5
2025-09-24T19:40:09.724302331Z,2025-09-24T19:40:09.719928383Z,160,1,432669,C,B,64.820000000,1,26,8058566358597,128,15584,94348583,CLX5
2025-09-24T19:40:09.724492608Z,2025-09-24T19:40:09.720092497Z,160,1,432669,C,B,64.820000000,1,26,8058566358649,128,13989,94348594,CLX5
2025-09-24T19:40:09.724781783Z,2025-09-24T19:40:09.720323427Z,160,1,432669,A,A,64.870000000,1,26,8058566358671,128,17896,94348608,CLX5
2025-09-24T19:40:09.724886870Z,2025-09-24T19:40:09.720360537Z,160,1,432669,M,B,64.820000000,2,26,8058566346145,128,16721,94348611,CLX5
2025-09-24T19:40:09.725120676Z,2025-09-24T19:40:09.720714627Z,160,1,432669,A,A,64.830000000,1,26,8058566358675,128,16239,94348618,CLX5
2025-09-24T19:40:09.725635877Z,2025-09-24T19:40:09.720950777Z,160,1,432669,C,B,64.820000000,1,26,8058566358639,128,14816,94348642,CLX5
2025-09-24T19:40:09.726033019Z,2025-09-24T19:40:09.721869379Z,160,1,432669,C,B,64.820000000,1,26,8058566358640,128,15164,94348663,CLX5
2025-09-24T19:40:09.726710038Z,2025-09-24T19:40:09.723015759Z,160,1,432669,A,A,64.830000000,1,26,8058566358700,128,16378,94348697,CLX5
2025-09-24T19:40:09.726977910Z,2025-09-24T19:40:09.723545811Z,160,1,432669,M,A,64.840000000,1,26,8058566357888,128,19335,94348711,CLX5
2025-09-24T19:40:09.727849967Z,2025-09-24T19:40:09.725374759Z,160,1,432669,A,A,64.830000000,2,26,8058566358717,128,15786,94348764,CLX5
2025-09-24T19:40:09.727886183Z,2025-09-24T19:40:09.725638939Z,160,1,432669,A,A,64.830000000,1,26,8058566358719,128,15687,94348765,CLX5
2025-09-24T19:40:09.728500420Z,2025-09-24T19:40:09.726057195Z,160,1,432669,A,B,64.820000000,1,26,8058566358730,128,15188,94348797,CLX5
2025-09-24T19:40:09.728930962Z,2025-09-24T19:40:09.726585689Z,160,1,432669,M,B,63.670000000,4,26,8058566346145,128,15678,94348816,CLX5
2025-09-24T19:40:09.729022733Z,2025-09-24T19:40:09.726727379Z,160,1,432669,A,B,64.800000000,1,26,8058566358736,128,14439,94348821,CLX5
2025-09-24T19:40:09.729228853Z,2025-09-24T19:40:09.727002945Z,160,1,432669,A,B,64.820000000,1,26,8058566358739,128,15040,94348830,CLX5
2025-09-24T19:40:09.729530070Z,2025-09-24T19:40:09.727492445Z,160,1,432669,M,A,64.830000000,1,26,8058566357888,128,16424,94348847,CLX5
2025-09-24T19:40:09.730281503Z,2025-09-24T19:40:09.728092497Z,160,1,432669,C,A,64.830000000,1,26,8058566358719,128,15337,94348896,CLX5
2025-09-24T19:40:09.734880730Z,2025-09-24T19:40:09.734743159Z,160,1,432669,A,B,64.820000000,1,26,8058566358818,128,18808,94349061,CLX5
2025-09-24T19:40:09.735500849Z,2025-09-24T19:40:09.735231817Z,160,1,432669,T,B,64.830000000,1,26,8058566358819,0,17828,94349066,CLX5
2025-09-24T19:40:09.735500849Z,2025-09-24T19:40:09.735231817Z,160,1,432669,F,A,64.830000000,1,26,8058566335783,0,17828,94349066,CLX5
2025-09-24T19:40:09.735574013Z,2025-09-24T19:40:09.735231817Z,160,1,432669,M,A,64.830000000,2,26,8058566335783,128,16231,94349067,CLX5
2025-09-24T19:40:09.812427327Z,2025-09-24T19:40:09.812292245Z,160,1,432669,C,B,64.790000000,2,26,8058566340495,128,17814,94349432,CLX5
2025-09-24T19:40:09.812459198Z,2025-09-24T19:40:09.812293109Z,160,1,432669,A,A,64.880000000,2,26,8058566358952,128,14321,94349433,CLX5
2025-09-24T19:40:09.812694101Z,2025-09-24T19:40:09.812560323Z,160,1,432669,A,A,64.830000000,1,26,8058566358954,128,14600,94349435,CLX5
2025-09-24T19:40:09.812913438Z,2025-09-24T19:40:09.812760857Z,160,1,432669,C,A,64.830000000,1,26,8058566358700,128,19249,94349440,CLX5
2025-09-24T19:40:09.816973073Z,2025-09-24T19:40:09.816847109Z,160,1,432669,C,A,64.860000000,1,26,8058566345884,128,18029,94349446,CLX5
2025-09-24T19:40:09.846071849Z,2025-09-24T19:40:09.845918313Z,160,1,432669,A,A,64.830000000,1,26,8058566359049,128,15631,94349644,CLX5
2025-09-24T19:40:09.856664855Z,2025-09-24T19:40:09.856532777Z,160,1,432669,C,A,64.830000000,1,26,8058566359049,128,18831,94349715,CLX5
2025-09-24T19:40:09.894140520Z,2025-09-24T19:40:09.894009925Z,160,1,432669,C,B,64.800000000,1,26,8058566358610,128,18070,94349810,CLX5
2025-09-24T19:40:09.957884313Z,2025-09-24T19:40:09.957766107Z,160,1,432669,C,A,65.150000000,1,26,8058566337859,128,18610,94349873,CLX5
2025-09-24T19:40:09.982611790Z,2025-09-24T19:40:09.982447041Z,160,1,432669,A,A,64.830000000,1,26,8058566359202,128,19220,94349928,CLX5
2025-09-24T19:40:10.067043376Z,2025-09-24T19:40:10.066931359Z,160,1,432669,A,A,65.110000000,1,26,8058566359226,128,17842,94349976,CLX5
2025-09-24T19:40:10.208457565Z,2025-09-24T19:40:10.208081783Z,160,1,432669,C,B,64.810000000,2,26,8058566358590,128,14169,94350037,CLX5
2025-09-24T19:40:10.208503481Z,2025-09-24T19:40:10.208082147Z,160,1,432669,A,A,64.830000000,1,26,8058566359249,128,18381,94350039,CLX5
2025-09-24T19:40:10.209263055Z,2025-09-24T19:40:10.208395999Z,160,1,432669,C,B,64.820000000,1,26,8058566358483,128,17805,94350073,CLX5
2025-09-24T19:40:10.209301076Z,2025-09-24T19:40:10.208408843Z,160,1,432669,C,B,64.820000000,2,26,8058566358628,128,15018,94350075,CLX5
2025-09-24T19:40:10.209336787Z,2025-09-24T19:40:10.208411205Z,160,1,432669,A,A,64.830000000,1,26,8058566359261,128,15047,94350076,CLX5
2025-09-24T19:40:10.209409581Z,2025-09-24T19:40:10.208421245Z,160,1,432669,A,A,64.830000000,2,26,8058566359262,128,15162,94350078,CLX5
2025-09-24T19:40:10.209560316Z,2025-09-24T19:40:10.208465153Z,160,1,432669,C,B,64.820000000,1,26,8058566358818,128,15724,94350085,CLX5
2025-09-24T19:40:10.209685440Z,2025-09-24T19:40:10.208477019Z,160,1,432669,C,B,64.820000000,1,26,8058566358739,128,13770,94350091,CLX5
2025-09-24T19:40:10.209796050Z,2025-09-24T19:40:10.208488847Z,160,1,432669,C,B,64.820000000,1,26,8058566358730,128,19828,94350096,CLX5
2025-09-24T19:40:10.209880356Z,2025-09-24T19:40:10.208496505Z,160,1,432669,A,A,64.830000000,2,26,8058566359273,128,15371,94350101,CLX5
2025-09-24T19:40:10.210796932Z,2025-09-24T19:40:10.208952657Z,160,1,432669,C,A,64.830000000,2,26,8058566359273,128,15613,94350146,CLX5
2025-09-24T19:40:10.211090653Z,2025-09-24T19:40:10.209234501Z,160,1,432669,C,B,64.820000000,1,26,8058566358616,128,18979,94350165,CLX5
2025-09-24T19:40:10.211207245Z,2025-09-24T19:40:10.209316385Z,160,1,432669,A,A,64.830000000,1,26,8058566359301,128,18399,94350169,CLX5
2025-09-24T19:40:10.212089531Z,2025-09-24T19:40:10.210847441Z,160,1,432669,A,A,64.860000000,2,26,8058566359312,128,14402,94350227,CLX5
2025-09-24T19:40:10.212348410Z,2025-09-24T19:40:10.211130379Z,160,1,432669,C,B,64.820000000,2,26,8058566358223,128,14788,94350236,CLX5
2025-09-24T19:40:10.212384120Z,2025-09-24T19:40:10.211130647Z,160,1,432669,C,B,64.820000000,1,26,8058566358230,128,16037,94350237,CLX5
2025-09-24T19:40:10.212416843Z,2025-09-24T19:40:10.211251315Z,160,1,432669,M,A,64.940000000,1,26,8058565075241,128,14573,94350240,CLX5
2025-09-24T19:40:10.212777807Z,2025-09-24T19:40:10.211882775Z,160,1,432669,C,A,64.880000000,2,26,8058566358952,128,13603,94350259,CLX5
2025-09-24T19:40:10.215084474Z,2025-09-24T19:40:10.214992135Z,160,1,432669,M,A,64.950000000,1,26,8058565075241,128,14571,94350329,CLX5
2025-09-24T19:40:10.312368597Z,2025-09-24T19:40:10.312230911Z,160,1,432669,A,B,64.790000000,2,26,8058566359368,128,17949,94350457,CLX5
2025-09-24T19:40:10.600157175Z,2025-09-24T19:40:10.600010125Z,160,1,432669,C,B,64.820000000,1,26,8058566358178,128,19332,94350657,CLX5
2025-09-24T19:40:10.600848430Z,2025-09-24T19:40:10.600510339Z,160,1,432669,T,A,64.820000000,1,26,8058566359490,0,17663,94350658,CLX5
2025-09-24T19:40:10.600848430Z,2025-09-24T19:40:10.600510339Z,160,1,432669,F,B,64.820000000,1,26,8058566358158,0,17663,94350658,CLX5
2025-09-24T19:40:10.600859773Z,2025-09-24T19:40:10.600510339Z,160,1,432669,C,B,64.820000000,1,26,8058566358158,128,16231,94350659,CLX5
2025-09-24T19:40:12.589642055Z,2025-09-24T19:40:12.589463389Z,160,1,432669,A,B,64.820000000,2,26,8058566359580,128,20947,94350836,CLX5
2025-09-24T19:40:12.589692870Z,2025-09-24T19:40:12.589549575Z,160,1,432669,A,B,64.820000000,1,26,8058566359581,128,16209,94350838,CLX5
2025-09-24T19:40:12.589868917Z,2025-09-24T19:40:12.589737803Z,160,1,432669,C,A,64.830000000,1,26,8058566359261,128,15059,94350841,CLX5
2025-09-24T19:40:13.056711333Z,2025-09-24T19:40:13.056530953Z,160,1,432669,M,B,64.820000000,4,26,8058566357569,128,24829,94350879,CLX5
2025-09-24T19:40:13.056864679Z,2025-09-24T19:40:13.056719815Z,160,1,432669,C,A,64.830000000,1,26,8058566359249,128,18732,94350880,CLX5
2025-09-24T19:40:13.056898861Z,2025-09-24T19:40:13.056722273Z,160,1,432669,A,B,64.820000000,1,26,8058566359590,128,15868,94350881,CLX5
2025-09-24T19:40:13.232270292Z,2025-09-24T19:40:13.232111317Z,160,1,432669,A,A,64.830000000,1,26,8058566359592,128,18206,94350886,CLX5
2025-09-24T19:40:14.543889180Z,2025-09-24T19:40:14.543429801Z,160,1,432669,C,A,64.830000000,2,26,8058566359262,128,14156,94350951,CLX5
2025-09-24T19:40:14.544547667Z,2025-09-24T19:40:14.543561585Z,160,1,432669,A,B,64.820000000,1,26,8058566359620,128,15348,94350980,CLX5
2025-09-24T19:40:14.545677106Z,2025-09-24T19:40:14.543804645Z,160,1,432669,C,A,64.830000000,2,26,8058566358717,128,15183,94351033,CLX5
2025-09-24T19:40:14.546113690Z,2025-09-24T19:40:14.544031951Z,160,1,432669,A,B,64.820000000,2,26,8058566359642,128,17988,94351055,CLX5
2025-09-24T19:40:14.546145845Z,2025-09-24T19:40:14.544032127Z,160,1,432669,C,A,64.860000000,2,26,8058566359312,128,14533,94351056,CLX5
2025-09-24T19:40:14.546294184Z,2025-09-24T19:40:14.544037589Z,160,1,432669,A,B,64.820000000,1,26,8058566359645,128,14741,94351061,CLX5
2025-09-24T19:40:14.546352480Z,2025-09-24T19:40:14.544045999Z,160,1,432669,A,B,64.820000000,1,26,8058566359647,128,14889,94351063,CLX5
2025-09-24T19:40:14.546384012Z,2025-09-24T19:40:14.544048993Z,160,1,432669,A,B,64.820000000,1,26,8058566359648,128,14847,94351064,CLX5
2025-09-24T19:40:14.546543787Z,2025-09-24T19:40:14.544089581Z,160,1,432669,C,A,64.830000000,1,26,8058566358675,128,15806,94351068,CLX5
2025-09-24T19:40:14.547114035Z,2025-09-24T19:40:14.544313077Z,160,1,432669,A,B,64.810000000,2,26,8058566359659,128,14799,94351097,CLX5
2025-09-24T19:40:14.547259632Z,2025-09-24T19:40:14.544338593Z,160,1,432669,A,B,64.820000000,1,26,8058566359663,128,19820,94351103,CLX5
2025-09-24T19:40:14.547778850Z,2025-09-24T19:40:14.544562341Z,160,1,432669,C,A,64.830000000,1,26,8058566359301,128,19690,94351135,CLX5
2025-09-24T19:40:14.548207417Z,2025-09-24T19:40:14.545021161Z,160,1,432669,A,B,64.820000000,1,26,8058566359682,128,15196,94351164,CLX5
2025-09-24T19:40:14.550093649Z,2025-09-24T19:40:14.546121119Z,160,1,432669,C,B,64.820000000,1,26,8058566359645,128,19201,94351270,CLX5
2025-09-24T19:40:14.550369946Z,2025-09-24T19:40:14.546391943Z,160,1,432669,C,B,64.820000000,1,26,8058566359648,128,14931,94351287,CLX5
2025-09-24T19:40:14.550405456Z,2025-09-24T19:40:14.546392691Z,160,1,432669,C,B,64.820000000,1,26,8058566359647,128,18582,94351288,CLX5
2025-09-24T19:40:14.553538878Z,2025-09-24T19:40:14.550267981Z,160,1,432669,T,B,64.830000000,3,26,8058566359770,0,14690,94351474,CLX5
2025-09-24T19:40:14.553538878Z,2025-09-24T19:40:14.550267981Z,160,1,432669,F,A,64.830000000,2,26,8058566335783,0,14690,94351474,CLX5
2025-09-24T19:40:14.553538878Z,2025-09-24T19:40:14.550267981Z,160,1,432669,F,A,64.830000000,1,26,8058566276097,0,14690,94351474,CLX5
2025-09-24T19:40:14.553586913Z,2025-09-24T19:40:14.550267981Z,160,1,432669,C,A,64.830000000,2,26,8058566335783,0,16296,94351475,CLX5
2025-09-24T19:40:14.553586913Z,2025-09-24T19:40:14.550267981Z,160,1,432669,C,A,64.830000000,1,26,8058566276097,128,16296,94351475,CLX5
2025-09-24T19:40:14.554259999Z,2025-09-24T19:40:14.550639371Z,160,1,432669,A,B,64.820000000,1,26,8058566359778,128,19020,94351503,CLX5
2025-09-24T19:40:14.554290887Z,2025-09-24T19:40:14.550640581Z,160,1,432669,A,B,64.820000000,1,26,8058566359779,128,15165,94351504,CLX5
2025-09-24T19:40:14.555856856Z,2025-09-24T19:40:14.553557529Z,160,1,432669,C,B,64.800000000,1,26,8058566358736,128,14368,94351609,CLX5
2025-09-24T19:40:14.556016622Z,2025-09-24T19:40:14.553836721Z,160,1,432669,C,B,64.820000000,1,26,8058566359778,128,18171,94351620,CLX5
2025-09-24T19:40:14.556047571Z,2025-09-24T19:40:14.553900809Z,160,1,432669,C,B,64.820000000,1,26,8058566359779,128,15068,94351621,CLX5
2025-09-24T19:40:14.556076416Z,2025-09-24T19:40:14.554123711Z,160,1,432669,A,B,64.800000000,1,26,8058566359807,128,14398,94351622,CLX5
2025-09-24T19:40:14.557502571Z,2025-09-24T19:40:14.556055643Z,160,1,432669,A,A,64.830000000,1,26,8058566359833,128,15622,94351705,CLX5
2025-09-24T19:40:14.557566926Z,2025-09-24T19:40:14.556202807Z,160,1,432669,M,A,64.840000000,1,26,8058566357888,128,19243,94351707,CLX5
2025-09-24T19:40:14.557635643Z,2025-09-24T19:40:14.556257121Z,160,1,432669,C,A,64.830000000,1,26,8058566359833,128,15862,94351711,CLX5
2025-09-24T19:40:14.558232870Z,2025-09-24T19:40:14.557502627Z,160,1,432669,A,A,64.840000000,1,26,8058566359844,128,17921,94351748,CLX5
2025-09-24T19:40:14.558745314Z,2025-09-24T19:40:14.558305419Z,160,1,432669,A,A,64.830000000,1,26,8058566359857,128,16326,94351772,CLX5
2025-09-24T19:40:14.559203962Z,2025-09-24T19:40:14.558754335Z,160,1,432669,C,A,64.830000000,1,26,8058566359857,128,15940,94351792,CLX5
2025-09-24T19:40:14.563450011Z,2025-09-24T19:40:14.563278155Z,160,1,432669,A,A,64.830000000,1,26,8058566359884,128,16337,94351866,CLX5
2025-09-24T19:40:14.563550030Z,2025-09-24T19:40:14.563417637Z,160,1,432669,A,B,64.820000000,1,26,8058566359885,128,17405,94351867,CLX5
2025-09-24T19:40:14.563628024Z,2025-09-24T19:40:14.563482069Z,160,1,432669,A,B,64.820000000,1,26,8058566359886,128,15302,94351868,CLX5
2025-09-24T19:40:14.563696526Z,2025-09-24T19:40:14.563572131Z,160,1,432669,A,B,64.820000000,1,26,8058566359887,128,18600,94351869,CLX5
2025-09-24T19:40:14.563790379Z,2025-09-24T19:40:14.563636429Z,160,1,432669,C,B,64.820000000,1,26,8058566359885,128,18055,94351872,CLX5
2025-09-24T19:40:14.563819968Z,2025-09-24T19:40:14.563657721Z,160,1,432669,A,B,64.820000000,1,26,8058566359888,128,15780,94351873,CLX5
2025-09-24T19:40:14.563956043Z,2025-09-24T19:40:14.563826807Z,160,1,432669,C,A,64.830000000,1,26,8058566359884,128,19485,94351874,CLX5
2025-09-24T19:40:14.572428873Z,2025-09-24T19:40:14.572276451Z,160,1,432669,M,A,64.840000000,1,26,8058566349378,128,20214,94351886,CLX5
2025-09-24T19:40:14.612110240Z,2025-09-24T19:40:14.611973389Z,160,1,432669,C,B,64.790000000,2,26,8058566359368,128,17826,94352046,CLX5
2025-09-24T19:40:14.612144783Z,2025-09-24T19:40:14.611974271Z,160,1,432669,A,A,64.880000000,2,26,8058566359936,128,14883,94352047,CLX5
2025-09-24T19:40:14.672272231Z,2025-09-24T19:40:14.671902737Z,160,1,432669,A,A,64.830000000,1,26,8058566360007,128,14973,94352149,CLX5
2025-09-24T19:40:14.672407423Z,2025-09-24T19:40:14.672284687Z,160,1,432669,C,A,64.830000000,1,26,8058566360007,128,16107,94352155,CLX5
2025-09-24T19:40:14.672892743Z,2025-09-24T19:40:14.672761939Z,160,1,432669,A,A,64.830000000,1,26,8058566360011,128,19567,94352158,CLX5
2025-09-24T19:40:14.674925555Z,2025-09-24T19:40:14.674820395Z,160,1,432669,A,B,64.520000000,1,26,8058566360017,128,17921,94352176,CLX5
2025-09-24T19:40:14.685507333Z,2025-09-24T19:40:14.685358425Z,160,1,432669,M,A,64.830000000,1,26,8058566357888,128,16271,94352188,CLX5
2025-09-24T19:40:14.733812773Z,2025-09-24T19:40:14.733499553Z,160,1,432669,T,A,64.820000000,1,26,8058566360054,0,17902,94352256,CLX5
2025-09-24T19:40:14.733812773Z,2025-09-24T19:40:14.733499553Z,160,1,432669,F,B,64.820000000,1,26,8058566358203,0,17902,94352256,CLX5
2025-09-24T19:40:14.733822341Z,2025-09-24T19:40:14.733499553Z,160,1,432669,C,B,64.820000000,1,26,8058566358203,128,14780,94352257,CLX5
2025-09-24T19:40:14.733923927Z,2025-09-24T19:40:14.733787983Z,160,1,432669,C,B,64.820000000,2,26,8058566359642,128,18511,94352258,CLX5
2025-09-24T19:40:14.733964038Z,2025-09-24T19:40:14.733791457Z,160,1,432669,A,A,64.830000000,2,26,8058566360055,128,16492,94352259,CLX5
2025-09-24T19:40:14.734002013Z,2025-09-24T19:40:14.733793417Z,160,1,432669,A,A,64.830000000,1,26,8058566360057,128,14944,94352260,CLX5
2025-09-24T19:40:14.734038568Z,2025-09-24T19:40:14.733793877Z,160,1,432669,A,A,64.830000000,1,26,8058566360058,128,18031,94352261,CLX5
2025-09-24T19:40:14.788664654Z,2025-09-24T19:40:14.788520467Z,160,1,432669,C,A,64.830000000,1,26,8058566360058,128,19229,94352318,CLX5
2025-09-24T19:40:14.788823937Z,2025-09-24T19:40:14.788695563Z,160,1,432669,C,B,64.820000000,1,26,8058566359888,128,18211,94352319,CLX5
2025-09-24T19:40:14.788856345Z,2025-09-24T19:40:14.788709961Z,160,1,432669,C,B,64.820000000,1,26,8058566359887,128,14967,94352320,CLX5
2025-09-24T19:40:14.788891563Z,2025-09-24T19:40:14.788712191Z,160,1,432669,C,B,64.820000000,1,26,8058566359886,128,15124,94352321,CLX5
2025-09-24T19:40:16.205392149Z,2025-09-24T19:40:16.205225735Z,160,1,432669,M,A,64.840000000,1,26,8058566357888,128,20041,94352613,CLX5
2025-09-24T19:40:16.209700135Z,2025-09-24T19:40:16.209561497Z,160,1,432669,M,A,64.830000000,1,26,8058566357888,128,19644,94352616,CLX5
2025-09-24T19:40:16.593529449Z,2025-09-24T19:40:16.593280127Z,160,1,432669,C,A,64.830000000,1,26,8058566360057,128,19677,94352671,CLX5
2025-09-24T19:40:16.593561834Z,2025-09-24T19:40:16.593300727Z,160,1,432669,C,A,64.830000000,1,26,8058566360011,128,16009,94352672,CLX5
2025-09-24T19:40:16.593641687Z,2025-09-24T19:40:16.593515221Z,160,1,432669,A,A,64.830000000,1,26,8058566360260,128,21067,94352674,CLX5
2025-09-24T19:40:16.593768746Z,2025-09-24T19:40:16.593646369Z,160,1,432669,A,A,64.830000000,1,26,8058566360261,128,19081,94352677,CLX5
2025-09-24T19:40:16.707470388Z,2025-09-24T19:40:16.707320351Z,160,1,432669,M,A,64.840000000,1,26,8058566357888,128,19352,94352710,CLX5
2025-09-24T19:40:16.711632661Z,2025-09-24T19:40:16.711491347Z,160,1,432669,M,A,64.830000000,1,26,8058566357888,128,20067,94352712,CLX5
2025-09-24T19:40:18.469184929Z,2025-09-24T19:40:18.469007057Z,160,1,432669,A,B,64.820000000,2,26,8058566360367,128,20638,94352936,CLX5
2025-09-24T19:40:18.469518646Z,2025-09-24T19:40:18.469384051Z,160,1,432669,C,A,64.830000000,1,26,8058566360261,128,21396,94352938,CLX5
2025-09-24T19:40:19.004632662Z,2025-09-24T19:40:19.004444803Z,160,1,432669,A,A,64.830000000,1,26,8058566360371,128,15835,94352953,CLX5
2025-09-24T19:40:19.006138139Z,2025-09-24T19:40:19.005999455Z,160,1,432669,A,B,64.820000000,11,26,8058566360382,128,18297,94352980,CLX5
2025-09-24T19:40:19.010205645Z,2025-09-24T19:40:19.010067775Z,160,1,432669,M,A,64.840000000,1,26,8058566357888,128,19243,94353015,CLX5
2025-09-24T19:40:19.014330556Z,2025-09-24T19:40:19.014185417Z,160,1,432669,M,A,64.830000000,1,26,8058566357888,128,20045,94353033,CLX5
2025-09-24T19:40:20.103556197Z,2025-09-24T19:40:20.103413167Z,160,1,432669,M,A,64.840000000,1,26,8058566357888,128,22470,94353077,CLX5
2025-09-24T19:40:20.107890592Z,2025-09-24T19:40:20.107752617Z,160,1,432669,M,A,64.830000000,1,26,8058566357888,128,19943,94353085,CLX5
2025-09-24T19:40:20.425241889Z,2025-09-24T19:40:20.425028505Z,160,1,432669,C,A,64.830000000,1,26,8058566360371,128,18232,94353104,CLX5
2025-09-24T19:40:20.425384299Z,2025-09-24T19:40:20.425256765Z,160,1,432669,C,A,64.830000000,1,26,8058566360260,128,19024,94353109,CLX5
2025-09-24T19:40:20.552572672Z,2025-09-24T19:40:20.551917107Z,160,1,432669,M,A,64.850000000,1,26,8058566354507,128,15252,94353198,CLX5
2025-09-24T19:40:20.604345464Z,2025-09-24T19:40:20.604182135Z,160,1,432669,M,A,64.840000000,1,26,8058566357888,128,19479,94353324,CLX5
2025-09-24T19:40:22.010235773Z,2025-09-24T19:40:22.010076775Z,160,1,432669,A,A,64.830000000,4,26,8058566360505,128,19410,94353371,CLX5
2025-09-24T19:40:23.098029044Z,2025-09-24T19:40:23.097853279Z,160,1,432669,A,A,64.830000000,1,26,8058566360518,128,20419,94353406,CLX5
2025-09-24T19:40:25.272617625Z,2025-09-24T19:40:25.272451065Z,160,1,432669,C,A,64.830000000,4,26,8058566360505,128,20381,94353429,CLX5
2025-09-24T19:40:25.385819335Z,2025-09-24T19:40:25.385676417Z,160,1,432669,A,A,64.830000000,1,26,8058566360528,128,19558,94353431,CLX5
2025-09-24T19:40:25.386062948Z,2025-09-24T19:40:25.385941941Z,160,1,432669,A,A,64.830000000,1,26,8058566360530,128,19559,94353433,CLX5
2025-09-24T19:40:26.900075664Z,2025-09-24T19:40:26.899930747Z,160,1,432669,A,A,64.830000000,1,26,8058566360556,128,19249,94353530,CLX5
2025-09-24T19:40:27.372321987Z,2025-09-24T19:40:27.372170255Z,160,1,432669,C,A,64.830000000,1,26,8058566360556,128,18834,94353565,CLX5
2025-09-24T19:40:28.101066629Z,2025-09-24T19:40:28.100914287Z,160,1,432669,A,A,64.840000000,1,26,8058566360573,128,20976,94353572,CLX5
2025-09-24T19:40:32.198580654Z,2025-09-24T19:40:32.198417827Z,160,1,432669,A,A,64.830000000,1,26,8058566360593,128,20039,94353610,CLX5
2025-09-24T19:40:32.427813648Z,2025-09-24T19:40:32.425279989Z,160,1,432669,C,A,64.830000000,1,26,8058566360593,128,20081,94353921,CLX5
2025-09-24T19:40:32.428776546Z,2025-09-24T19:40:32.426226775Z,160,1,432669,A,B,64.820000000,1,26,8058566360707,128,18465,94353977,CLX5
2025-09-24T19:40:32.430341632Z,2025-09-24T19:40:32.428558861Z,160,1,432669,C,B,64.820000000,1,26,8058566360707,128,14049,94354096,CLX5
2025-09-24T19:40:32.432320357Z,2025-09-24T19:40:32.430955431Z,160,1,432669,A,B,64.820000000,1,26,8058566360787,128,15049,94354241,CLX5
2025-09-24T19:40:32.433759437Z,2025-09-24T19:40:32.432667863Z,160,1,432669,C,B,64.820000000,1,26,8058566360787,128,15095,94354331,CLX5
2025-09-24T19:40:32.938343283Z,2025-09-24T19:40:32.938203365Z,160,1,432669,C,B,64.780000000,1,26,8058566338864,128,18272,94355049,CLX5
2025-09-24T19:40:35.982357920Z,2025-09-24T19:40:35.982194431Z,160,1,432669,C,A,64.860000000,1,26,8058566358118,128,18842,94355239,CLX5
2025-09-24T19:40:36.056429418Z,2025-09-24T19:40:36.056281563Z,160,1,432669,A,A,64.840000000,1,26,8058566361263,128,18078,94355248,CLX5
2025-09-24T19:40:37.197931024Z,2025-09-24T19:40:37.197698863Z,160,1,432669,A,A,64.830000000,1,26,8058566361294,128,14952,94355324,CLX5
2025-09-24T19:40:37.197966419Z,2025-09-24T19:40:37.197706273Z,160,1,432669,A,A,64.830000000,1,26,8058566361295,128,19442,94355325,CLX5
2025-09-24T19:40:37.198025598Z,2025-09-24T19:40:37.197829609Z,160,1,432669,A,A,64.830000000,2,26,8058566361297,128,15610,94355328,CLX5
2025-09-24T19:40:37.198076537Z,2025-09-24T19:40:37.197846735Z,160,1,432669,A,A,64.830000000,1,26,8058566361299,128,14569,94355330,CLX5
2025-09-24T19:40:37.198117991Z,2025-09-24T19:40:37.197854223Z,160,1,432669,A,A,64.830000000,1,26,8058566361300,128,14917,94355332,CLX5
2025-09-24T19:40:37.198275070Z,2025-09-24T19:40:37.197921841Z,160,1,432669,C,B,64.800000000,1,26,8058566359807,128,14721,94355339,CLX5
2025-09-24T19:40:37.198541298Z,2025-09-24T19:40:37.198109205Z,160,1,432669,C,B,64.820000000,1,26,8058566359590,128,15068,94355349,CLX5
2025-09-24T19:40:37.198796460Z,2025-09-24T19:40:37.198149655Z,160,1,432669,C,B,64.810000000,2,26,8058566359659,128,14721,94355357,CLX5
2025-09-24T19:40:37.200147025Z,2025-09-24T19:40:37.198683451Z,160,1,432669,C,B,64.820000000,1,26,8058566359663,128,15430,94355424,CLX5
2025-09-24T19:40:37.200196021Z,2025-09-24T19:40:37.198701211Z,160,1,432669,A,B,64.820000000,1,26,8058566361324,128,18533,94355426,CLX5
2025-09-24T19:40:37.200205882Z,2025-09-24T19:40:37.198702669Z,160,1,432669,A,A,64.860000000,2,26,8058566361326,128,15027,94355427,CLX5
2025-09-24T19:40:37.200561378Z,2025-09-24T19:40:37.198985511Z,160,1,432669,C,B,64.820000000,1,26,8058566359620,128,16705,94355445,CLX5
2025-09-24T19:40:37.200881932Z,2025-09-24T19:40:37.199341789Z,160,1,432669,C,A,64.830000000,1,26,8058566361300,128,14621,94355463,CLX5
2025-09-24T19:40:37.200993854Z,2025-09-24T19:40:37.199358801Z,160,1,432669,C,A,64.830000000,1,26,8058566361294,128,14959,94355468,CLX5
2025-09-24T19:40:37.201353919Z,2025-09-24T19:40:37.199720801Z,160,1,432669,A,A,64.830000000,1,26,8058566361347,128,15073,94355487,CLX5
2025-09-24T19:40:37.201525820Z,2025-09-24T19:40:37.199765115Z,160,1,432669,A,A,64.830000000,1,26,8058566361350,128,18638,94355497,CLX5
2025-09-24T19:40:37.201624833Z,2025-09-24T19:40:37.199850203Z,160,1,432669,M,A,64.830000000,1,26,8058566349378,128,19338,94355502,CLX5
2025-09-24T19:40:37.202122509Z,2025-09-24T19:40:37.200182713Z,160,1,432669,M,A,64.840000000,3,26,8058566342145,128,14789,94355529,CLX5
2025-09-24T19:40:37.202158649Z,2025-09-24T19:40:37.200201281Z,160,1,432669,C,A,64.830000000,1,26,8058566361347,128,18748,94355530,CLX5
2025-09-24T19:40:37.202369354Z,2025-09-24T19:40:37.200370463Z,160,1,432669,C,A,64.830000000,1,26,8058566361350,128,19024,94355541,CLX5
2025-09-24T19:40:37.202702296Z,2025-09-24T19:40:37.200885307Z,160,1,432669,C,A,64.830000000,1,26,8058566361295,128,15197,94355563,CLX5
2025-09-24T19:40:37.202766244Z,2025-09-24T19:40:37.200886133Z,160,1,432669,A,A,64.830000000,1,26,8058566361372,128,19090,94355565,CLX5
2025-09-24T19:40:37.203040766Z,2025-09-24T19:40:37.201530629Z,160,1,432669,C,A,64.830000000,1,26,8058566361372,128,16166,94355583,CLX5
2025-09-24T19:40:37.203696388Z,2025-09-24T19:40:37.202705943Z,160,1,432669,A,A,64.830000000,1,26,8058566361391,128,18684,94355624,CLX5
2025-09-24T19:40:37.203778445Z,2025-09-24T19:40:37.202771221Z,160,1,432669,C,A,64.830000000,1,26,8058566361391,128,15542,94355630,CLX5
2025-09-24T19:40:37.203867099Z,2025-09-24T19:40:37.203045691Z,160,1,432669,A,A,64.830000000,1,26,8058566361393,128,15533,94355636,CLX5
2025-09-24T19:40:37.204395524Z,2025-09-24T19:40:37.203701517Z,160,1,432669,C,A,64.830000000,1,26,8058566361393,128,17342,94355667,CLX5
2025-09-24T19:40:37.204424476Z,2025-09-24T19:40:37.203704933Z,160,1,432669,A,A,64.830000000,1,26,8058566361401,128,15545,94355668,CLX5
2025-09-24T19:40:37.204549484Z,2025-09-24T19:40:37.203875039Z,160,1,432669,C,A,64.830000000,1,26,8058566361401,128,15554,94355675,CLX5
2025-09-24T19:40:37.204815544Z,2025-09-24T19:40:37.204400229Z,160,1,432669,A,A,64.830000000,1,26,8058566361408,128,18792,94355691,CLX5
2025-09-24T19:40:37.204854548Z,2025-09-24T19:40:37.204429279Z,160,1,432669,C,A,64.830000000,1,26,8058566361408,128,15553,94355693,CLX5
2025-09-24T19:40:37.205100550Z,2025-09-24T19:40:37.204823707Z,160,1,432669,A,A,64.830000000,1,26,8058566361410,128,15645,94355711,CLX5
2025-09-24T19:40:37.205223016Z,2025-09-24T19:40:37.205108639Z,160,1,432669,C,A,64.830000000,1,26,8058566361410,128,19273,94355716,CLX5
2025-09-24T19:40:37.205261283Z,2025-09-24T19:40:37.205135979Z,160,1,432669,M,A,64.830000000,1,26,8058566357888,128,16211,94355717,CLX5
2025-09-24T19:40:37.208380451Z,2025-09-24T19:40:37.208199109Z,160,1,432669,A,B,64.800000000,1,26,8058566361422,128,13655,94355746,CLX5
2025-09-24T19:40:37.212150595Z,2025-09-24T19:40:37.212024021Z,160,1,432669,C,A,64.880000000,2,26,8058566359936,128,18430,94355754,CLX5
2025-09-24T19:40:37.312499298Z,2025-09-24T19:40:37.312362423Z,160,1,432669,A,B,64.790000000,2,26,8058566361454,128,17895,94355847,CLX5
2025-09-24T19:40:37.312524602Z,2025-09-24T19:40:37.312367763Z,160,1,432669,A,B,64.780000000,2,26,8058566361455,128,14504,94355848,CLX5
2025-09-24T19:40:37.699514790Z,2025-09-24T19:40:37.699374281Z,160,1,432669,A,A,64.830000000,1,26,8058566361538,128,20066,94356013,CLX5
2025-09-24T19:40:39.607799262Z,2025-09-24T19:40:39.607229981Z,160,1,432669,T,B,64.830000000,13,26,8058566361658,0,18506,94356336,CLX5
2025-09-24T19:40:39.607799262Z,2025-09-24T19:40:39.607229981Z,160,1,432669,F,A,64.830000000,1,26,8058566345605,0,18506,94356336,CLX5
2025-09-24T19:40:39.607799262Z,2025-09-24T19:40:39.607229981Z,160,1,432669,F,A,64.830000000,1,26,8058566345702,0,18506,94356336,CLX5
2025-09-24T19:40:39.607799262Z,2025-09-24T19:40:39.607229981Z,160,1,432669,F,A,64.830000000,1,26,8058566356987,0,18506,94356336,CLX5
2025-09-24T19:40:39.607799262Z,2025-09-24T19:40:39.607229981Z,160,1,432669,F,A,64.830000000,1,26,8058566358182,0,18506,94356336,CLX5
2025-09-24T19:40:39.607799262Z,2025-09-24T19:40:39.607229981Z,160,1,432669,F,A,64.830000000,1,26,8058566358954,0,18506,94356336,CLX5
2025-09-24T19:40:39.607799262Z,2025-09-24T19:40:39.607229981Z,160,1,432669,F,A,64.830000000,1,26,8058566359202,0,18506,94356336,CLX5
2025-09-24T19:40:39.607799262Z,2025-09-24T19:40:39.607229981Z,160,1,432669,F,A,64.830000000,1,26,8058566359592,0,18506,94356336,CLX5
2025-09-24T19:40:39.607799262Z,2025-09-24T19:40:39.607229981Z,160,1,432669,F,A,64.830000000,2,26,8058566360055,0,18506,94356336,CLX5
2025-09-24T19:40:39.607799262Z,2025-09-24T19:40:39.607229981Z,160,1,432669,F,A,64.830000000,1,26,8058566360518,0,18506,94356336,CLX5
2025-09-24T19:40:39.607799262Z,2025-09-24T19:40:39.607229981Z,160,1,432669,F,A,64.830000000,1,26,8058566360528,0,18506,94356336,CLX5
2025-09-24T19:40:39.607799262Z,2025-09-24T19:40:39.607229981Z,160,1,432669,F,A,64.830000000,1,26,8058566360530,0,18506,94356336,CLX5
2025-09-24T19:40:39.607799262Z,2025-09-24T19:40:39.607229981Z,160,1,432669,F,A,64.830000000,1,26,8058566361297,0,18506,94356336,CLX5
2025-09-24T19:40:39.607811142Z,2025-09-24T19:40:39.607229981Z,160,1,432669,C,A,64.830000000,1,26,8058566345605,0,16195,94356337,CLX5
2025-09-24T19:40:39.607811142Z,2025-09-24T19:40:39.607229981Z,160,1,432669,C,A,64.830000000,1,26,8058566345702,0,16195,94356337,CLX5
2025-09-24T19:40:39.607811142Z,2025-09-24T19:40:39.607229981Z,160,1,432669,C,A,64.830000000,1,26,8058566356987,0,16195,94356337,CLX5
2025-09-24T19:40:39.607811142Z,2025-09-24T19:40:39.607229981Z,160,1,432669,C,A,64.830000000,1,26,8058566358182,0,16195,94356337,CLX5
2025-09-24T19:40:39.607811142Z,2025-09-24T19:40:39.607229981Z,160,1,432669,C,A,64.830000000,1,26,8058566358954,0,16195,94356337,CLX5
2025-09-24T19:40:39.607811142Z,2025-09-24T19:40:39.607229981Z,160,1,432669,C,A,64.830000000,1,26,8058566359202,0,16195,94356337,CLX5
2025-09-24T19:40:39.607811142Z,2025-09-24T19:40:39.607229981Z,160,1,432669,C,A,64.830000000,1,26,8058566359592,0,16195,94356337,CLX5
2025-09-24T19:40:39.607811142Z,2025-09-24T19:40:39.607229981Z,160,1,432669,C,A,64.830000000,2,26,8058566360055,0,16195,94356337,CLX5
2025-09-24T19:40:39.607811142Z,2025-09-24T19:40:39.607229981Z,160,1,432669,C,A,64.830000000,1,26,8058566360518,0,16195,94356337,CLX5
2025-09-24T19:40:39.607811142Z,2025-09-24T19:40:39.607229981Z,160,1,432669,C,A,64.830000000,1,26,8058566360528,0,16195,94356337,CLX5
2025-09-24T19:40:39.607811142Z,2025-09-24T19:40:39.607229981Z,160,1,432669,C,A,64.830000000,1,26,8058566360530,0,16195,94356337,CLX5
2025-09-24T19:40:39.607811142Z,2025-09-24T19:40:39.607229981Z,160,1,432669,M,A,64.830000000,1,26,8058566361297,128,16195,94356337,CLX5
2025-09-24T19:40:39.607822285Z,2025-09-24T19:40:39.607232515Z,160,1,432669,C,B,64.820000000,1,26,8058566361324,128,18355,94356338,CLX5
2025-09-24T19:40:39.607845532Z,2025-09-24T19:40:39.607427597Z,160,1,432669,C,B,64.820000000,2,26,8058566360367,128,17251,94356339,CLX5
2025-09-24T19:40:39.607914702Z,2025-09-24T19:40:39.607646659Z,160,1,432669,C,A,64.830000000,1,26,8058566361538,128,21262,94356342,CLX5
2025-09-24T19:40:39.607978581Z,2025-09-24T19:40:39.607658467Z,160,1,432669,A,A,64.830000000,1,26,8058566361663,128,18882,94356344,CLX5
2025-09-24T19:40:39.608050615Z,2025-09-24T19:40:39.607724973Z,160,1,432669,A,B,64.820000000,1,26,8058566361665,128,15228,94356346,CLX5
2025-09-24T19:40:39.608082608Z,2025-09-24T19:40:39.607728717Z,160,1,432669,A,B,64.820000000,1,26,8058566361666,128,14740,94356347,CLX5
2025-09-24T19:40:39.608115953Z,2025-09-24T19:40:39.607728891Z,160,1,432669,A,B,64.820000000,1,26,8058566361667,128,17835,94356348,CLX5
2025-09-24T19:40:39.608142217Z,2025-09-24T19:40:39.607742233Z,160,1,432669,A,B,64.820000000,1,26,8058566361668,128,14748,94356349,CLX5
2025-09-24T19:40:39.608481157Z,2025-09-24T19:40:39.607803209Z,160,1,432669,A,A,64.830000000,2,26,8058566361675,128,16148,94356364,CLX5
2025-09-24T19:40:39.608607862Z,2025-09-24T19:40:39.607817147Z,160,1,432669,C,B,64.820000000,1,26,8058566361666,128,15512,94356368,CLX5
2025-09-24T19:40:39.608800459Z,2025-09-24T19:40:39.607838209Z,160,1,432669,C,B,64.820000000,1,26,8058566361667,128,15328,94356379,CLX5
2025-09-24T19:40:39.608898850Z,2025-09-24T19:40:39.607851265Z,160,1,432669,A,A,64.830000000,1,26,8058566361679,128,16742,94356385,CLX5
2025-09-24T19:40:39.608935942Z,2025-09-24T19:40:39.607851533Z,160,1,432669,A,A,64.830000000,1,26,8058566361680,128,16126,94356386,CLX5
2025-09-24T19:40:39.608973933Z,2025-09-24T19:40:39.607857735Z,160,1,432669,A,A,64.830000000,2,26,8058566361681,128,19490,94356387,CLX5
2025-09-24T19:40:39.609068223Z,2025-09-24T19:40:39.607869369Z,160,1,432669,C,B,64.820000000,1,26,8058566361668,128,17903,94356390,CLX5
2025-09-24T19:40:39.609282077Z,2025-09-24T19:40:39.607919191Z,160,1,432669,A,A,64.830000000,1,26,8058566361684,128,18960,94356400,CLX5
2025-09-24T19:40:39.609326227Z,2025-09-24T19:40:39.607921019Z,160,1,432669,A,A,64.830000000,1,26,8058566361686,128,16010,94356402,CLX5
2025-09-24T19:40:39.609357767Z,2025-09-24T19:40:39.607926545Z,160,1,432669,A,A,64.830000000,1,26,8058566361687,128,15929,94356403,CLX5
2025-09-24T19:40:39.609444332Z,2025-09-24T19:40:39.607976559Z,160,1,432669,C,A,64.830000000,1,26,8058566361299,128,16496,94356405,CLX5
2025-09-24T19:40:39.609619250Z,2025-09-24T19:40:39.608028051Z,160,1,432669,M,A,64.830000000,1,26,8058566358671,128,15467,94356414,CLX5
2025-09-24T19:40:39.609689088Z,2025-09-24T19:40:39.608055909Z,160,1,432669,A,A,64.830000000,1,26,8058566361689,128,16078,94356418,CLX5
2025-09-24T19:40:39.609727908Z,2025-09-24T19:40:39.608082269Z,160,1,432669,M,B,63.660000000,4,26,8058566319508,128,18054,94356419,CLX5
2025-09-24T19:40:39.609941063Z,2025-09-24T19:40:39.608358507Z,160,1,432669,A,B,64.800000000,1,26,8058566361692,128,17433,94356428,CLX5
2025-09-24T19:40:39.610441374Z,2025-09-24T19:40:39.608949207Z,160,1,432669,C,A,64.830000000,2,26,8058566361681,128,19237,94356454,CLX5
2025-09-24T19:40:39.610496629Z,2025-09-24T19:40:39.608978755Z,160,1,432669,C,B,64.820000000,1,26,8058566361665,128,14107,94356456,CLX5
2025-09-24T19:40:39.611027319Z,2025-09-24T19:40:39.610446741Z,160,1,432669,A,B,64.820000000,1,26,8058566361706,128,14678,94356484,CLX5
2025-09-24T19:40:39.611060004Z,2025-09-24T19:40:39.610501343Z,160,1,432669,C,B,64.820000000,1,26,8058566361706,128,14846,94356485,CLX5
2025-09-24T19:40:39.611093671Z,2025-09-24T19:40:39.610514917Z,160,1,432669,A,B,64.820000000,1,26,8058566361707,128,18116,94356486,CLX5
2025-09-24T19:40:39.611120672Z,2025-09-24T19:40:39.610907827Z,160,1,432669,A,B,64.820000000,1,26,8058566361708,128,15049,94356487,CLX5
2025-09-24T19:40:39.611198106Z,2025-09-24T19:40:39.611064339Z,160,1,432669,C,B,64.820000000,1,26,8058566361708,128,17752,94356490,CLX5
2025-09-24T19:40:39.611320365Z,2025-09-24T19:40:39.611202533Z,160,1,432669,A,B,64.820000000,1,26,8058566361709,128,18207,94356491,CLX5
2025-09-24T19:40:39.611346022Z,2025-09-24T19:40:39.611205953Z,160,1,432669,A,B,64.820000000,1,26,8058566361710,128,13633,94356492,CLX5
2025-09-24T19:40:39.611548158Z,2025-09-24T19:40:39.611414455Z,160,1,432669,M,A,64.840000000,1,26,8058566349378,128,19689,94356493,CLX5
2025-09-24T19:40:39.615737669Z,2025-09-24T19:40:39.615566617Z,160,1,432669,C,B,64.820000000,1,26,8058566361707,128,14647,94356519,CLX5
2025-09-24T19:40:39.615864429Z,2025-09-24T19:40:39.615746111Z,160,1,432669,C,B,64.820000000,1,26,8058566361710,128,18198,94356520,CLX5
2025-09-24T19:40:39.615892391Z,2025-09-24T19:40:39.615764581Z,160,1,432669,A,B,64.820000000,1,26,8058566361716,128,14885,94356521,CLX5
2025-09-24T19:40:39.616008222Z,2025-09-24T19:40:39.615885975Z,160,1,432669,A,B,64.820000000,1,26,8058566361717,128,18436,94356522,CLX5
2025-09-24T19:40:39.616049231Z,2025-09-24T19:40:39.615924873Z,160,1,432669,A,B,64.820000000,1,26,8058566361718,128,14889,94356523,CLX5
2025-09-24T19:40:39.616129452Z,2025-09-24T19:40:39.616012959Z,160,1,432669,C,B,64.820000000,1,26,8058566361709,128,20069,94356524,CLX5
2025-09-24T19:40:39.618108024Z,2025-09-24T19:40:39.617962537Z,160,1,432669,A,A,64.830000000,1,26,8058566361719,128,19656,94356525,CLX5
2025-09-24T19:40:39.784307429Z,2025-09-24T19:40:39.784178857Z,160,1,432669,C,B,64.800000000,1,26,8058566361692,128,17826,94356613,CLX5
2025-09-24T19:40:40.071096613Z,2025-09-24T19:40:40.070742571Z,160,1,432669,T,B,64.830000000,3,26,8058566361807,0,18168,94356778,CLX5
2025-09-24T19:40:40.071096613Z,2025-09-24T19:40:40.070742571Z,160,1,432669,F,A,64.830000000,1,26,8058566361297,0,18168,94356778,CLX5
2025-09-24T19:40:40.071096613Z,2025-09-24T19:40:40.070742571Z,160,1,432669,F,A,64.830000000,1,26,8058566357888,0,18168,94356778,CLX5
2025-09-24T19:40:40.071096613Z,2025-09-24T19:40:40.070742571Z,160,1,432669,F,A,64.830000000,1,26,8058566361663,0,18168,94356778,CLX5
2025-09-24T19:40:40.071108347Z,2025-09-24T19:40:40.070742571Z,160,1,432669,C,A,64.830000000,1,26,8058566361297,0,15974,94356779,CLX5
2025-09-24T19:40:40.071108347Z,2025-09-24T19:40:40.070742571Z,160,1,432669,C,A,64.830000000,1,26,8058566357888,0,15974,94356779,CLX5
2025-09-24T19:40:40.071108347Z,2025-09-24T19:40:40.070742571Z,160,1,432669,C,A,64.830000000,1,26,8058566361663,128,15974,94356779,CLX5
2025-09-24T19:40:40.071202767Z,2025-09-24T19:40:40.071073105Z,160,1,432669,C,A,64.830000000,1,26,8058566361689,128,19456,94356780,CLX5
2025-09-24T19:40:40.071278726Z,2025-09-24T19:40:40.071075005Z,160,1,432669,C,A,64.830000000,1,26,8058566361686,128,16376,94356783,CLX5
2025-09-24T19:40:40.071315773Z,2025-09-24T19:40:40.071109639Z,160,1,432669,A,A,64.830000000,1,26,8058566361810,128,18987,94356784,CLX5
2025-09-24T19:40:40.071352681Z,2025-09-24T19:40:40.071113365Z,160,1,432669,A,B,64.820000000,1,26,8058566361811,128,15605,94356785,CLX5
2025-09-24T19:40:40.078726999Z,2025-09-24T19:40:40.078566477Z,160,1,432669,A,A,64.830000000,1,26,8058566361816,128,19384,94356809,CLX5
2025-09-24T19:40:40.081411133Z,2025-09-24T19:40:40.081274055Z,160,1,432669,A,A,64.830000000,1,26,8058566361818,128,18769,94356811,CLX5
2025-09-24T19:40:40.128431403Z,2025-09-24T19:40:40.128291667Z,160,1,432669,C,B,64.820000000,1,26,8058566361718,128,18402,94356828,CLX5
2025-09-24T19:40:40.128462666Z,2025-09-24T19:40:40.128310635Z,160,1,432669,C,B,64.820000000,1,26,8058566361717,128,14699,94356829,CLX5
2025-09-24T19:40:40.128583351Z,2025-09-24T19:40:40.128461869Z,160,1,432669,C,B,64.820000000,1,26,8058566361716,128,18410,94356830,CLX5
2025-09-24T19:40:40.169534919Z,2025-09-24T19:40:40.169411491Z,160,1,432669,C,A,65.450000000,10,26,8058565931419,128,18419,94356835,CLX5
2025-09-24T19:40:40.235637259Z,2025-09-24T19:40:40.235486741Z,160,1,432669,A,A,64.830000000,2,26,8058566361834,128,19586,94356849,CLX5
2025-09-24T19:40:40.235771106Z,2025-09-24T19:40:40.235643501Z,160,1,432669,A,A,64.830000000,1,26,8058566361835,128,19162,94356850,CLX5
2025-09-24T19:40:40.619630226Z,2025-09-24T19:40:40.619340163Z,160,1,432669,C,A,64.830000000,1,26,8058566361835,128,14980,94356911,CLX5
2025-09-24T19:40:40.619669738Z,2025-09-24T19:40:40.619341449Z,160,1,432669,A,B,64.820000000,1,26,8058566361866,128,18578,94356912,CLX5
2025-09-24T19:40:40.619708558Z,2025-09-24T19:40:40.619383919Z,160,1,432669,C,A,64.830000000,2,26,8058566361834,128,16240,94356913,CLX5
2025-09-24T19:40:40.619923648Z,2025-09-24T19:40:40.619567501Z,160,1,432669,C,B,64.820000000,1,26,8058566361866,128,14913,94356926,CLX5
2025-09-24T19:40:40.619976538Z,2025-09-24T19:40:40.619579061Z,160,1,432669,C,A,64.860000000,2,26,8058566361326,128,13632,94356928,CLX5
2025-09-24T19:40:40.620260882Z,2025-09-24T19:40:40.619747867Z,160,1,432669,C,A,64.830000000,1,26,8058566361719,128,15911,94356939,CLX5
2025-09-24T19:40:40.620294242Z,2025-09-24T19:40:40.619748433Z,160,1,432669,C,A,64.830000000,1,26,8058566361818,128,14706,94356940,CLX5
2025-09-24T19:40:40.620368780Z,2025-09-24T19:40:40.619928713Z,160,1,432669,A,B,64.820000000,1,26,8058566361873,128,17144,94356944,CLX5
2025-09-24T19:40:40.627197816Z,2025-09-24T19:40:40.627045955Z,160,1,432669,M,A,64.840000000,1,26,8058566361816,128,20291,94356957,CLX5
2025-09-24T19:40:40.627356484Z,2025-09-24T19:40:40.627227867Z,160,1,432669,A,B,64.820000000,1,26,8058566361878,128,18248,94356958,CLX5
2025-09-24T19:40:40.627486574Z,2025-09-24T19:40:40.627361359Z,160,1,432669,C,B,64.820000000,1,26,8058566361873,128,19223,94356959,CLX5
2025-09-24T19:40:40.627513332Z,2025-09-24T19:40:40.627381057Z,160,1,432669,A,B,64.820000000,1,26,8058566361879,128,14721,94356960,CLX5
2025-09-24T19:40:40.627630784Z,2025-09-24T19:40:40.627509711Z,160,1,432669,A,B,64.820000000,1,26,8058566361880,128,18291,94356961,CLX5
2025-09-24T19:40:40.712180137Z,2025-09-24T19:40:40.712045309Z,160,1,432669,A,A,64.880000000,2,26,8058566361892,128,18845,94356987,CLX5
2025-09-24T19:40:41.234611344Z,2025-09-24T19:40:41.234465375Z,160,1,432669,C,B,64.820000000,1,26,8058566361880,128,18444,94357072,CLX5
2025-09-24T19:40:41.234642762Z,2025-09-24T19:40:41.234472653Z,160,1,432669,C,B,64.820000000,1,26,8058566361879,128,16029,94357073,CLX5
2025-09-24T19:40:41.234762865Z,2025-09-24T19:40:41.234646023Z,160,1,432669,C,B,64.820000000,1,26,8058566361878,128,18105,94357074,CLX5
2025-09-24T19:40:41.234806368Z,2025-09-24T19:40:41.234652685Z,160,1,432669,A,A,64.830000000,2,26,8058566361940,128,16454,94357075,CLX5
2025-09-24T19:40:41.235007305Z,2025-09-24T19:40:41.234875547Z,160,1,432669,A,A,64.830000000,1,26,8058566361941,128,19135,94357076,CLX5
2025-09-24T19:40:41.235134379Z,2025-09-24T19:40:41.235012629Z,160,1,432669,A,A,64.830000000,1,26,8058566361942,128,19210,94357077,CLX5
2025-09-24T19:40:42.144374444Z,2025-09-24T19:40:42.144224093Z,160,1,432669,A,A,64.830000000,2,26,8058566361955,128,23128,94357094,CLX5
2025-09-24T19:40:43.202717529Z,2025-09-24T19:40:43.202567681Z,160,1,432669,A,A,64.830000000,2,26,8058566361982,128,21527,94357186,CLX5
2025-09-24T19:40:43.306151558Z,2025-09-24T19:40:43.306022931Z,160,1,432669,C,A,64.830000000,2,26,8058566361982,128,21214,94357202,CLX5
2025-09-24T19:40:43.306306639Z,2025-09-24T19:40:43.306182573Z,160,1,432669,C,A,64.830000000,1,26,8058566361941,128,21260,94357203,CLX5
2025-09-24T19:40:43.306445494Z,2025-09-24T19:40:43.306312205Z,160,1,432669,A,B,64.820000000,1,26,8058566361986,128,20674,94357204,CLX5
2025-09-24T19:40:43.306579741Z,2025-09-24T19:40:43.306450841Z,160,1,432669,C,B,64.820000000,1,26,8058566361986,128,21331,94357205,CLX5
2025-09-24T19:40:44.741063707Z,2025-09-24T19:40:44.740929047Z,160,1,432669,C,A,64.830000000,1,26,8058566361942,128,21585,94357225,CLX5
2025-09-24T19:40:44.741130266Z,2025-09-24T19:40:44.741000525Z,160,1,432669,A,A,64.830000000,1,26,8058566361992,128,18316,94357226,CLX5
2025-09-24T19:40:45.350333446Z,2025-09-24T19:40:45.350189859Z,160,1,432669,C,A,64.830000000,2,26,8058566361955,128,24872,94357243,CLX5
2025-09-24T19:40:45.350363819Z,2025-09-24T19:40:45.350198691Z,160,1,432669,C,A,64.830000000,2,26,8058566361940,128,18141,94357244,CLX5
2025-09-24T19:40:45.350473307Z,2025-09-24T19:40:45.350341799Z,160,1,432669,C,A,64.830000000,1,26,8058566361810,128,22536,94357245,CLX5
2025-09-24T19:40:47.172009498Z,2025-09-24T19:40:47.171803045Z,160,1,432669,M,B,64.820000000,1,26,8058566130074,128,24411,94357257,CLX5
2025-09-24T19:40:47.172179539Z,2025-09-24T19:40:47.172018787Z,160,1,432669,A,B,64.820000000,1,26,8058566361998,128,22289,94357258,CLX5
2025-09-24T19:40:47.318572514Z,2025-09-24T19:40:47.318419871Z,160,1,432669,A,B,64.820000000,1,26,8058566362000,128,23689,94357274,CLX5
2025-09-24T19:40:47.318708559Z,2025-09-24T19:40:47.318578593Z,160,1,432669,C,B,64.820000000,1,26,8058566361998,128,20815,94357275,CLX5
2025-09-24T19:40:47.318735921Z,2025-09-24T19:40:47.318600535Z,160,1,432669,A,B,64.820000000,1,26,8058566362001,128,17537,94357276,CLX5
2025-09-24T19:40:47.318861091Z,2025-09-24T19:40:47.318737617Z,160,1,432669,A,B,64.820000000,1,26,8058566362002,128,20602,94357277,CLX5
2025-09-24T19:40:47.319004308Z,2025-09-24T19:40:47.318865369Z,160,1,432669,C,A,64.830000000,1,26,8058566361680,128,22055,94357278,CLX5
2025-09-24T19:40:47.319289535Z,2025-09-24T19:40:47.319071031Z,160,1,432669,C,A,64.830000000,1,26,8058566361687,128,17685,94357285,CLX5
2025-09-24T19:40:47.406850568Z,2025-09-24T19:40:47.406417269Z,160,1,432669,T,B,64.830000000,6,26,8058566362009,0,21296,94357301,CLX5
2025-09-24T19:40:47.406850568Z,2025-09-24T19:40:47.406417269Z,160,1,432669,F,A,64.830000000,2,26,8058566361675,0,21296,94357301,CLX5
2025-09-24T19:40:47.406850568Z,2025-09-24T19:40:47.406417269Z,160,1,432669,F,A,64.830000000,1,26,8058566361679,0,21296,94357301,CLX5
2025-09-24T19:40:47.406850568Z,2025-09-24T19:40:47.406417269Z,160,1,432669,F,A,64.830000000,1,26,8058566361684,0,21296,94357301,CLX5
2025-09-24T19:40:47.406850568Z,2025-09-24T19:40:47.406417269Z,160,1,432669,F,A,64.830000000,1,26,8058566358671,0,21296,94357301,CLX5
2025-09-24T19:40:47.406850568Z,2025-09-24T19:40:47.406417269Z,160,1,432669,F,A,64.830000000,1,26,8058566361992,0,21296,94357301,CLX5
2025-09-24T19:40:47.406865466Z,2025-09-24T19:40:47.406417269Z,160,1,432669,A,B,64.830000000,2,26,8058566362009,0,19367,94357302,CLX5
2025-09-24T19:40:47.406865466Z,2025-09-24T19:40:47.406417269Z,160,1,432669,C,A,64.830000000,2,26,8058566361675,0,19367,94357302,CLX5
2025-09-24T19:40:47.406865466Z,2025-09-24T19:40:47.406417269Z,160,1,432669,C,A,64.830000000,1,26,8058566361679,0,19367,94357302,CLX5
2025-09-24T19:40:47.406865466Z,2025-09-24T19:40:47.406417269Z,160,1,432669,C,A,64.830000000,1,26,8058566361684,0,19367,94357302,CLX5
2025-09-24T19:40:47.406865466Z,2025-09-24T19:40:47.406417269Z,160,1,432669,C,A,64.830000000,1,26,8058566358671,0,19367,94357302,CLX5
2025-09-24T19:40:47.406865466Z,2025-09-24T19:40:47.406417269Z,160,1,432669,C,A,64.830000000,1,26,8058566361992,128,19367,94357302,CLX5
2025-09-24T19:40:47.407007677Z,2025-09-24T19:40:47.406753043Z,160,1,432669,A,B,64.820000000,1,26,8058566362014,128,18037,94357311,CLX5
2025-09-24T19:40:47.407052280Z,2025-09-24T19:40:47.406772109Z,160,1,432669,C,B,64.820000000,1,26,8058566362014,128,22607,94357313,CLX5
2025-09-24T19:40:47.407775337Z,2025-09-24T19:40:47.406910283Z,160,1,432669,C,B,64.800000000,1,26,8058566361422,128,18078,94357340,CLX5
2025-09-24T19:40:47.407875065Z,2025-09-24T19:40:47.406919731Z,160,1,432669,A,B,64.820000000,3,26,8058566362025,128,15377,94357343,CLX5
2025-09-24T19:40:47.407953942Z,2025-09-24T19:40:47.406930731Z,160,1,432669,A,A,64.840000000,1,26,8058566362027,128,18427,94357346,CLX5
2025-09-24T19:40:47.408311473Z,2025-09-24T19:40:47.407263739Z,160,1,432669,M,B,64.810000000,1,26,8058566319508,128,14904,94357367,CLX5
2025-09-24T19:40:47.408405602Z,2025-09-24T19:40:47.407376305Z,160,1,432669,C,A,64.840000000,1,26,8058566362027,128,15069,94357370,CLX5
2025-09-24T19:40:47.408465272Z,2025-09-24T19:40:47.407383295Z,160,1,432669,A,B,64.800000000,1,26,8058566362033,128,18591,94357372,CLX5
2025-09-24T19:40:47.408516211Z,2025-09-24T19:40:47.407398443Z,160,1,432669,A,B,64.830000000,1,26,8058566362034,128,14449,94357373,CLX5
2025-09-24T19:40:47.408693925Z,2025-09-24T19:40:47.407472955Z,160,1,432669,A,B,64.810000000,2,26,8058566362037,128,18489,94357383,CLX5
2025-09-24T19:40:47.408768271Z,2025-09-24T19:40:47.407481057Z,160,1,432669,C,B,64.780000000,2,26,8058566361455,128,13633,94357385,CLX5
2025-09-24T19:40:47.409429169Z,2025-09-24T19:40:47.407751841Z,160,1,432669,A,B,64.830000000,1,26,8058566362048,128,20617,94357407,CLX5
2025-09-24T19:40:47.409684846Z,2025-09-24T19:40:47.407956733Z,160,1,432669,M,B,64.820000000,4,26,8058566346145,128,14653,94357419,CLX5
2025-09-24T19:40:47.409805685Z,2025-09-24T19:40:47.407993883Z,160,1,432669,M,A,65.990000000,4,26,8058566342145,128,15018,94357422,CLX5
2025-09-24T19:40:47.409937175Z,2025-09-24T19:40:47.408221529Z,160,1,432669,M,A,64.850000000,1,26,8058566173085,128,15033,94357428,CLX5
2025-09-24T19:40:47.410136276Z,2025-09-24T19:40:47.408522629Z,160,1,432669,A,A,64.840000000,1,26,8058566362053,128,14074,94357437,CLX5
2025-09-24T19:40:47.410330700Z,2025-09-24T19:40:47.409441251Z,160,1,432669,C,B,64.830000000,1,26,8058566362048,128,18786,94357445,CLX5
2025-09-24T19:40:47.410501541Z,2025-09-24T19:40:47.409841225Z,160,1,432669,M,B,64.820000000,1,26,8058566349770,128,14972,94357452,CLX5
2025-09-24T19:40:47.410821901Z,2025-09-24T19:40:47.410526695Z,160,1,432669,A,B,64.810000000,1,26,8058566362058,128,17362,94357468,CLX5
2025-09-24T19:40:47.412222646Z,2025-09-24T19:40:47.412086855Z,160,1,432669,C,B,64.790000000,2,26,8058566361454,128,18178,94357550,CLX5
2025-09-24T19:40:47.412750634Z,2025-09-24T19:40:47.412581541Z,160,1,432669,M,B,64.490000000,10,26,8058566151203,128,14734,94357582,CLX5
2025-09-24T19:40:47.425648640Z,2025-09-24T19:40:47.425221073Z,160,1,432669,T,A,64.830000000,1,26,8058566362121,0,14543,94357693,CLX5
2025-09-24T19:40:47.425648640Z,2025-09-24T19:40:47.425221073Z,160,1,432669,F,B,64.830000000,1,26,8058566362009,0,14543,94357693,CLX5
2025-09-24T19:40:47.425662176Z,2025-09-24T19:40:47.425221073Z,160,1,432669,M,B,64.830000000,1,26,8058566362009,128,18507,94357694,CLX5
2025-09-24T19:40:47.425828043Z,2025-09-24T19:40:47.425538685Z,160,1,432669,T,A,64.830000000,2,26,8058566362122,0,18030,94357699,CLX5
2025-09-24T19:40:47.425828043Z,2025-09-24T19:40:47.425538685Z,160,1,432669,F,B,64.830000000,1,26,8058566362034,0,18030,94357699,CLX5
2025-09-24T19:40:47.425828043Z,2025-09-24T19:40:47.425538685Z,160,1,432669,F,B,64.830000000,1,26,8058566362009,0,18030,94357699,CLX5
2025-09-24T19:40:47.425846143Z,2025-09-24T19:40:47.425538685Z,160,1,432669,C,B,64.830000000,1,26,8058566362034,0,16523,94357700,CLX5
2025-09-24T19:40:47.425846143Z,2025-09-24T19:40:47.425538685Z,160,1,432669,M,B,64.830000000,2,26,8058566362009,128,16523,94357700,CLX5
2025-09-24T19:40:47.425846143Z,2025-09-24T19:40:47.425603501Z,160,1,432669,C,A,64.840000000,1,26,8058566362053,128,16523,94357700,CLX5
2025-09-24T19:40:47.425917303Z,2025-09-24T19:40:47.425652151Z,160,1,432669,T,A,64.830000000,1,26,8058566362126,0,14610,94357704,CLX5
2025-09-24T19:40:47.425917303Z,2025-09-24T19:40:47.425652151Z,160,1,432669,F,B,64.830000000,1,26,8058566362009,0,14610,94357704,CLX5
2025-09-24T19:40:47.425972166Z,2025-09-24T19:40:47.425652151Z,160,1,432669,M,B,64.830000000,1,26,8058566362009,128,18022,94357705,CLX5
2025-09-24T19:40:47.425996227Z,2025-09-24T19:40:47.425652977Z,160,1,432669,T,A,64.830000000,2,26,8058566362127,0,14699,94357707,CLX5
2025-09-24T19:40:47.425996227Z,2025-09-24T19:40:47.425652977Z,160,1,432669,F,B,64.830000000,2,26,8058566362009,0,14699,94357707,CLX5
2025-09-24T19:40:47.426005450Z,2025-09-24T19:40:47.425652977Z,160,1,432669,M,B,64.830000000,1,26,8058566362009,128,16699,94357708,CLX5
2025-09-24T19:40:47.426208621Z,2025-09-24T19:40:47.425829649Z,160,1,432669,T,A,64.830000000,1,26,8058566362130,0,14839,94357718,CLX5
2025-09-24T19:40:47.426208621Z,2025-09-24T19:40:47.425829649Z,160,1,432669,F,B,64.830000000,1,26,8058566362009,0,14839,94357718,CLX5
2025-09-24T19:40:47.426252249Z,2025-09-24T19:40:47.425829649Z,160,1,432669,M,B,64.830000000,2,26,8058566362009,128,14582,94357719,CLX5
2025-09-24T19:40:47.426485962Z,2025-09-24T19:40:47.425860367Z,160,1,432669,A,B,64.830000000,2,26,8058566362134,128,14428,94357729,CLX5
2025-09-24T19:40:47.426663284Z,2025-09-24T19:40:47.426005377Z,160,1,432669,A,A,64.840000000,1,26,8058566362138,128,14991,94357737,CLX5
2025-09-24T19:40:47.426697865Z,2025-09-24T19:40:47.426030049Z,160,1,432669,C,B,64.820000000,4,26,8058566346145,128,14666,94357738,CLX5
2025-09-24T19:40:47.426962197Z,2025-09-24T19:40:47.426158585Z,160,1,432669,A,A,64.870000000,2,26,8058566362141,128,18268,94357749,CLX5
2025-09-24T19:40:47.427105782Z,2025-09-24T19:40:47.426254237Z,160,1,432669,A,A,64.880000000,2,26,8058566362143,128,14173,94357755,CLX5
2025-09-24T19:40:47.427150654Z,2025-09-24T19:40:47.426259825Z,160,1,432669,C,A,64.840000000,1,26,8058566362138,128,18410,94357757,CLX5
2025-09-24T19:40:47.427237549Z,2025-09-24T19:40:47.426304079Z,160,1,432669,C,B,64.810000000,2,26,8058566362037,128,14560,94357760,CLX5
2025-09-24T19:40:47.427308117Z,2025-09-24T19:40:47.426445653Z,160,1,432669,C,A,64.840000000,1,26,8058566359844,128,15197,94357763,CLX5
2025-09-24T19:40:47.427355192Z,2025-09-24T19:40:47.426486241Z,160,1,432669,A,B,64.830000000,1,26,8058566362146,128,16969,94357764,CLX5
2025-09-24T19:40:47.427534173Z,2025-09-24T19:40:47.427159593Z,160,1,432669,A,A,64.840000000,1,26,8058566362151,128,13627,94357775,CLX5
2025-09-24T19:40:47.427801446Z,2025-09-24T19:40:47.427265283Z,160,1,432669,C,B,64.810000000,1,26,8058566362058,128,14400,94357784,CLX5
2025-09-24T19:40:47.430301478Z,2025-09-24T19:40:47.430007133Z,160,1,432669,T,A,64.830000000,1,26,8058566362156,0,17064,94357791,CLX5
2025-09-24T19:40:47.430301478Z,2025-09-24T19:40:47.430007133Z,160,1,432669,F,B,64.830000000,1,26,8058566362009,0,17064,94357791,CLX5
2025-09-24T19:40:47.430301478Z,2025-09-24T19:40:47.430007133Z,160,1,432669,M,B,64.830000000,1,26,8058566362009,128,17064,94357791,CLX5
2025-09-24T19:40:47.430409560Z,2025-09-24T19:40:47.430265939Z,160,1,432669,C,B,64.830000000,1,26,8058566362146,128,21071,94357793,CLX5
2025-09-24T19:40:47.432889034Z,2025-09-24T19:40:47.432622039Z,160,1,432669,T,A,64.830000000,1,26,8058566362161,0,16215,94357801,CLX5
2025-09-24T19:40:47.432889034Z,2025-09-24T19:40:47.432622039Z,160,1,432669,F,B,64.830000000,1,26,8058566362009,0,16215,94357801,CLX5
2025-09-24T19:40:47.432889034Z,2025-09-24T19:40:47.432622039Z,160,1,432669,M,B,64.830000000,2,26,8058566362009,128,16215,94357801,CLX5
2025-09-24T19:40:47.433049891Z,2025-09-24T19:40:47.432909681Z,160,1,432669,C,B,64.830000000,2,26,8058566362134,128,18249,94357803,CLX5
2025-09-24T19:40:47.441638775Z,2025-09-24T19:40:47.441315897Z,160,1,432669,T,A,64.830000000,1,26,8058566362168,0,16565,94357821,CLX5
2025-09-24T19:40:47.441638775Z,2025-09-24T19:40:47.441315897Z,160,1,432669,F,B,64.830000000,1,26,8058566362009,0,16565,94357821,CLX5
2025-09-24T19:40:47.441638775Z,2025-09-24T19:40:47.441315897Z,160,1,432669,M,B,64.830000000,1,26,8058566362009,128,16565,94357821,CLX5
2025-09-24T19:40:47.441866598Z,2025-09-24T19:40:47.441638979Z,160,1,432669,T,A,64.830000000,1,26,8058566362169,0,17954,94357824,CLX5
2025-09-24T19:40:47.441866598Z,2025-09-24T19:40:47.441638979Z,160,1,432669,F,B,64.830000000,1,26,8058566362009,0,17954,94357824,CLX5
2025-09-24T19:40:47.441875315Z,2025-09-24T19:40:47.441638979Z,160,1,432669,M,B,64.830000000,2,26,8058566362009,128,14370,94357825,CLX5
2025-09-24T19:40:47.441910410Z,2025-09-24T19:40:47.441641667Z,160,1,432669,T,A,64.830000000,2,26,8058566362170,0,15145,94357827,CLX5
2025-09-24T19:40:47.441910410Z,2025-09-24T19:40:47.441641667Z,160,1,432669,F,B,64.830000000,2,26,8058566362009,0,15145,94357827,CLX5
2025-09-24T19:40:47.441910410Z,2025-09-24T19:40:47.441641667Z,160,1,432669,M,B,64.830000000,2,26,8058566362009,128,15145,94357827,CLX5
2025-09-24T19:40:47.441917675Z,2025-09-24T19:40:47.441656757Z,160,1,432669,A,B,64.820000000,1,26,8058566362171,128,15390,94357828,CLX5
2025-09-24T19:40:47.441992113Z,2025-09-24T19:40:47.441871557Z,160,1,432669,A,B,64.820000000,1,26,8058566362172,128,18117,94357829,CLX5
2025-09-24T19:40:47.442041263Z,2025-09-24T19:40:47.441919863Z,160,1,432669,C,A,64.840000000,1,26,8058566362151,128,15742,94357830,CLX5
2025-09-24T19:40:47.442172768Z,2025-09-24T19:40:47.442049113Z,160,1,432669,A,A,64.840000000,1,26,8058566362174,128,15231,94357832,CLX5
2025-09-24T19:40:47.442357163Z,2025-09-24T19:40:47.442218641Z,160,1,432669,A,B,64.830000000,1,26,8058566362176,128,17974,94357837,CLX5
2025-09-24T19:40:47.442830710Z,2025-09-24T19:40:47.442662005Z,160,1,432669,C,B,64.820000000,1,26,8058566362172,128,19065,94357848,CLX5
2025-09-24T19:40:47.445901896Z,2025-09-24T19:40:47.445616025Z,160,1,432669,T,A,64.830000000,1,26,8058566362185,0,16401,94357866,CLX5
2025-09-24T19:40:47.445901896Z,2025-09-24T19:40:47.445616025Z,160,1,432669,F,B,64.830000000,1,26,8058566362009,0,16401,94357866,CLX5
2025-09-24T19:40:47.445901896Z,2025-09-24T19:40:47.445616025Z,160,1,432669,M,B,64.830000000,1,26,8058566362009,128,16401,94357866,CLX5
2025-09-24T19:40:47.446011883Z,2025-09-24T19:40:47.445868131Z,160,1,432669,C,B,64.830000000,1,26,8058566362176,128,18218,94357869,CLX5
2025-09-24T19:40:47.446122354Z,2025-09-24T19:40:47.445902075Z,160,1,432669,T,A,64.830000000,1,26,8058566362186,0,17838,94357872,CLX5
2025-09-24T19:40:47.446122354Z,2025-09-24T19:40:47.445902075Z,160,1,432669,F,B,64.830000000,1,26,8058566362009,0,17838,94357872,CLX5
2025-09-24T19:40:47.446131362Z,2025-09-24T19:40:47.445902075Z,160,1,432669,C,B,64.830000000,1,26,8058566362009,128,14536,94357873,CLX5
2025-09-24T19:40:47.446257055Z,2025-09-24T19:40:47.446127013Z,160,1,432669,A,B,64.820000000,1,26,8058566362187,128,17836,94357879,CLX5
2025-09-24T19:40:47.446333044Z,2025-09-24T19:40:47.446134673Z,160,1,432669,C,B,64.820000000,1,26,8058566362171,128,14993,94357881,CLX5
2025-09-24T19:40:47.455852227Z,2025-09-24T19:40:47.455718179Z,160,1,432669,A,A,64.840000000,1,26,8058566362196,128,18755,94357907,CLX5
2025-09-24T19:40:47.455904702Z,2025-09-24T19:40:47.455719349Z,160,1,432669,A,A,64.830000000,2,26,8058566362197,128,14547,94357908,CLX5
2025-09-24T19:40:47.455998792Z,2025-09-24T19:40:47.455856951Z,160,1,432669,A,A,64.830000000,2,26,8058566362198,128,14534,94357912,CLX5
2025-09-24T19:40:47.456132863Z,2025-09-24T19:40:47.455913069Z,160,1,432669,A,A,64.830000000,1,26,8058566362203,128,15846,94357920,CLX5
2025-09-24T19:40:47.456296899Z,2025-09-24T19:40:47.456053261Z,160,1,432669,M,A,64.830000000,2,26,8058566362143,128,17797,94357924,CLX5
2025-09-24T19:40:47.456342638Z,2025-09-24T19:40:47.456145245Z,160,1,432669,A,B,64.800000000,1,26,8058566362206,128,14817,94357926,CLX5
2025-09-24T19:40:47.456707742Z,2025-09-24T19:40:47.456419735Z,160,1,432669,T,B,64.830000000,2,26,8058566362210,0,17923,94357930,CLX5
2025-09-24T19:40:47.456707742Z,2025-09-24T19:40:47.456419735Z,160,1,432669,F,A,64.830000000,2,26,8058566362197,0,17923,94357930,CLX5
2025-09-24T19:40:47.456724369Z,2025-09-24T19:40:47.456419735Z,160,1,432669,C,A,64.830000000,2,26,8058566362197,128,18779,94357931,CLX5
2025-09-24T19:40:47.456940426Z,2025-09-24T19:40:47.456697663Z,160,1,432669,C,A,64.840000000,1,26,8058566362174,128,17850,94357938,CLX5
2025-09-24T19:40:47.457014696Z,2025-09-24T19:40:47.456712733Z,160,1,432669,C,B,64.820000000,1,26,8058566362187,128,13708,94357940,CLX5
2025-09-24T19:40:47.457838862Z,2025-09-24T19:40:47.457567135Z,160,1,432669,T,B,64.830000000,2,26,8058566362214,0,17779,94357942,CLX5
2025-09-24T19:40:47.457838862Z,2025-09-24T19:40:47.457567135Z,160,1,432669,F,A,64.830000000,2,26,8058566362198,0,17779,94357942,CLX5
2025-09-24T19:40:47.457847625Z,2025-09-24T19:40:47.457567135Z,160,1,432669,C,A,64.830000000,2,26,8058566362198,128,15345,94357943,CLX5
2025-09-24T19:40:47.458132722Z,2025-09-24T19:40:47.457823941Z,160,1,432669,T,B,64.830000000,3,26,8058566362215,0,18416,94357949,CLX5
2025-09-24T19:40:47.458132722Z,2025-09-24T19:40:47.457823941Z,160,1,432669,F,A,64.830000000,1,26,8058566362203,0,18416,94357949,CLX5
2025-09-24T19:40:47.458132722Z,2025-09-24T19:40:47.457823941Z,160,1,432669,F,A,64.830000000,2,26,8058566362143,0,18416,94357949,CLX5
2025-09-24T19:40:47.458143558Z,2025-09-24T19:40:47.457823941Z,160,1,432669,C,A,64.830000000,1,26,8058566362203,0,14786,94357950,CLX5
2025-09-24T19:40:47.458143558Z,2025-09-24T19:40:47.457823941Z,160,1,432669,C,A,64.830000000,2,26,8058566362143,128,14786,94357950,CLX5
2025-09-24T19:40:47.458242517Z,2025-09-24T19:40:47.457974655Z,160,1,432669,A,B,64.820000000,1,26,8058566362220,128,18356,94357958,CLX5
2025-09-24T19:40:47.458270985Z,2025-09-24T19:40:47.458142667Z,160,1,432669,A,A,64.840000000,1,26,8058566362221,128,15198,94357959,CLX5
2025-09-24T19:40:47.464941921Z,2025-09-24T19:40:47.464799935Z,160,1,432669,A,B,64.820000000,1,26,8058566362234,128,18461,94357999,CLX5
2025-09-24T19:40:47.468581390Z,2025-09-24T19:40:47.468319215Z,160,1,432669,T,A,64.820000000,1,26,8058566362236,0,18050,94358002,CLX5
2025-09-24T19:40:47.468581390Z,2025-09-24T19:40:47.468319215Z,160,1,432669,F,B,64.820000000,1,26,8058566358204,0,18050,94358002,CLX5
2025-09-24T19:40:47.468591081Z,2025-09-24T19:40:47.468319215Z,160,1,432669,M,B,64.820000000,1,26,8058566358204,128,15132,94358003,CLX5
2025-09-24T19:40:47.470067546Z,2025-09-24T19:40:47.469850501Z,160,1,432669,A,A,64.830000000,1,26,8058566362240,128,18008,94358007,CLX5
2025-09-24T19:40:47.470352758Z,2025-09-24T19:40:47.470210833Z,160,1,432669,M,A,64.830000000,2,26,8058566362141,128,17489,94358012,CLX5
2025-09-24T19:40:47.512251811Z,2025-09-24T19:40:47.512109219Z,160,1,432669,A,B,64.810000000,2,26,8058566362253,128,19029,94358043,CLX5
2025-09-24T19:40:47.512385836Z,2025-09-24T19:40:47.512264619Z,160,1,432669,C,B,64.820000000,1,26,8058566362234,128,18017,94358044,CLX5
2025-09-24T19:40:47.515425021Z,2025-09-24T19:40:47.515280535Z,160,1,432669,C,B,64.820000000,1,26,8058566358471,128,18421,94358048,CLX5
2025-09-24T19:40:47.516105794Z,2025-09-24T19:40:47.515979117Z,160,1,432669,C,B,64.810000000,2,26,8058566362253,128,18342,94358049,CLX5
2025-09-24T19:40:47.584361339Z,2025-09-24T19:40:47.584224713Z,160,1,432669,C,B,64.800000000,1,26,8058566362033,128,22318,94358107,CLX5
2025-09-24T19:40:47.612210469Z,2025-09-24T19:40:47.612068555Z,160,1,432669,A,B,64.790000000,2,26,8058566362305,128,22453,94358120,CLX5
2025-09-24T19:40:47.633020288Z,2025-09-24T19:40:47.632881855Z,160,1,432669,A,B,64.820000000,4,26,8058566362312,128,20750,94358127,CLX5
2025-09-24T19:40:47.642953778Z,2025-09-24T19:40:47.642665457Z,160,1,432669,T,A,64.820000000,1,26,8058566362314,0,18375,94358130,CLX5
2025-09-24T19:40:47.642953778Z,2025-09-24T19:40:47.642665457Z,160,1,432669,F,B,64.820000000,1,26,8058566358204,0,18375,94358130,CLX5
2025-09-24T19:40:47.642963615Z,2025-09-24T19:40:47.642665457Z,160,1,432669,C,B,64.820000000,1,26,8058566358204,128,14900,94358131,CLX5
2025-09-24T19:40:47.712189708Z,2025-09-24T19:40:47.712054017Z,160,1,432669,A,B,64.780000000,2,26,8058566362327,128,18766,94358159,CLX5
2025-09-24T19:40:48.574455578Z,2025-09-24T19:40:48.574316193Z,160,1,432669,C,A,64.840000000,1,26,8058566362221,128,18289,94358216,CLX5
2025-09-24T19:40:48.868891012Z,2025-09-24T19:40:48.868565903Z,160,1,432669,T,B,64.830000000,2,26,8058566362395,0,17878,94358306,CLX5
2025-09-24T19:40:48.868891012Z,2025-09-24T19:40:48.868565903Z,160,1,432669,F,A,64.830000000,1,26,8058566362240,0,17878,94358306,CLX5
2025-09-24T19:40:48.868891012Z,2025-09-24T19:40:48.868565903Z,160,1,432669,F,A,64.830000000,1,26,8058566362141,0,17878,94358306,CLX5
2025-09-24T19:40:48.868901233Z,2025-09-24T19:40:48.868565903Z,160,1,432669,C,A,64.830000000,1,26,8058566362240,0,14704,94358307,CLX5
2025-09-24T19:40:48.868901233Z,2025-09-24T19:40:48.868565903Z,160,1,432669,M,A,64.830000000,1,26,8058566362141,128,14704,94358307,CLX5
2025-09-24T19:40:48.869316131Z,2025-09-24T19:40:48.868945777Z,160,1,432669,T,B,64.830000000,1,26,8058566362403,0,15109,94358331,CLX5
2025-09-24T19:40:48.869316131Z,2025-09-24T19:40:48.868945777Z,160,1,432669,F,A,64.830000000,1,26,8058566362141,0,15109,94358331,CLX5
2025-09-24T19:40:48.869337979Z,2025-09-24T19:40:48.868945777Z,160,1,432669,C,A,64.830000000,1,26,8058566362141,128,14999,94358332,CLX5
2025-09-24T19:40:48.869612088Z,2025-09-24T19:40:48.869316301Z,160,1,432669,C,A,64.840000000,1,26,8058566362196,128,17009,94358351,CLX5
2025-09-24T19:40:48.869776094Z,2025-09-24T19:40:48.869343795Z,160,1,432669,A,A,64.840000000,1,26,8058566362410,128,13953,94358359,CLX5
2025-09-24T19:40:48.869844634Z,2025-09-24T19:40:48.869442325Z,160,1,432669,A,B,64.800000000,1,26,8058566362411,128,14544,94358361,CLX5
2025-09-24T19:40:48.870377628Z,2025-09-24T19:40:48.870257407Z,160,1,432669,A,B,64.810000000,2,26,8058566362417,128,14641,94358382,CLX5
2025-09-24T19:40:48.870455883Z,2025-09-24T19:40:48.870263645Z,160,1,432669,C,B,64.780000000,2,26,8058566362327,128,14855,94358385,CLX5
2025-09-24T19:40:48.870663793Z,2025-09-24T19:40:48.870421597Z,160,1,432669,A,B,64.820000000,1,26,8058566362421,128,16076,94358389,CLX5
2025-09-24T19:40:48.879031951Z,2025-09-24T19:40:48.878491461Z,160,1,432669,A,B,64.830000000,2,26,8058566362429,128,14643,94358431,CLX5
2025-09-24T19:40:48.879291099Z,2025-09-24T19:40:48.878621727Z,160,1,432669,A,B,64.830000000,1,26,8058566362433,128,17370,94358443,CLX5
2025-09-24T19:40:48.879660948Z,2025-09-24T19:40:48.878669573Z,160,1,432669,A,B,64.830000000,1,26,8058566362439,128,20483,94358455,CLX5
2025-09-24T19:40:48.879789927Z,2025-09-24T19:40:48.878723407Z,160,1,432669,A,B,64.830000000,2,26,8058566362441,128,20342,94358459,CLX5
2025-09-24T19:40:48.880108669Z,2025-09-24T19:40:48.878758869Z,160,1,432669,A,B,64.830000000,2,26,8058566362445,128,16065,94358470,CLX5
2025-09-24T19:40:48.880190272Z,2025-09-24T19:40:48.878760871Z,160,1,432669,A,B,64.830000000,2,26,8058566362448,128,15357,94358473,CLX5
2025-09-24T19:40:48.880220507Z,2025-09-24T19:40:48.878761497Z,160,1,432669,A,B,64.820000000,2,26,8058566362449,128,14770,94358474,CLX5
2025-09-24T19:40:48.880310319Z,2025-09-24T19:40:48.878769447Z,160,1,432669,C,A,64.840000000,2,26,8058566329004,128,15034,94358478,CLX5
2025-09-24T19:40:48.880726192Z,2025-09-24T19:40:48.878878631Z,160,1,432669,A,B,64.820000000,2,26,8058566362456,128,14740,94358493,CLX5
2025-09-24T19:40:48.881455493Z,2025-09-24T19:40:48.879029901Z,160,1,432669,C,B,64.800000000,1,26,8058566362206,128,17191,94358533,CLX5
2025-09-24T19:40:48.881539978Z,2025-09-24T19:40:48.879058663Z,160,1,432669,A,B,64.830000000,1,26,8058566362474,128,15422,94358535,CLX5
2025-09-24T19:40:48.881607211Z,2025-09-24T19:40:48.879066535Z,160,1,432669,C,B,64.810000000,1,26,8058566358154,128,15747,94358538,CLX5
2025-09-24T19:40:48.881710494Z,2025-09-24T19:40:48.879071563Z,160,1,432669,A,B,64.830000000,1,26,8058566362476,128,15782,94358542,CLX5
2025-09-24T19:40:48.881920301Z,2025-09-24T19:40:48.879173493Z,160,1,432669,A,B,64.830000000,1,26,8058566362483,128,15291,94358552,CLX5
2025-09-24T19:40:48.882520868Z,2025-09-24T19:40:48.879755419Z,160,1,432669,A,B,64.830000000,2,26,8058566362492,128,18395,94358577,CLX5
2025-09-24T19:40:48.882645278Z,2025-09-24T19:40:48.879858747Z,160,1,432669,M,B,64.820000000,4,26,8058566345944,128,14738,94358583,CLX5
2025-09-24T19:40:48.883616417Z,2025-09-24T19:40:48.880625543Z,160,1,432669,C,B,64.830000000,2,26,8058566362492,128,18574,94358628,CLX5
2025-09-24T19:40:48.884870580Z,2025-09-24T19:40:48.881715499Z,160,1,432669,C,B,64.830000000,1,26,8058566362476,128,18805,94358703,CLX5
2025-09-24T19:40:48.887203065Z,2025-09-24T19:40:48.885048703Z,160,1,432669,C,B,64.830000000,2,26,8058566362441,128,18868,94358832,CLX5
2025-09-24T19:40:48.891664504Z,2025-09-24T19:40:48.891520775Z,160,1,432669,C,B,64.830000000,1,26,8058566362474,128,19368,94358949,CLX5
2025-09-24T19:40:48.891706350Z,2025-09-24T19:40:48.891529049Z,160,1,432669,A,B,64.810000000,1,26,8058566362586,128,14495,94358951,CLX5
2025-09-24T19:40:48.893068042Z,2025-09-24T19:40:48.892146571Z,160,1,432669,C,A,64.840000000,1,26,8058566362410,128,17265,94358971,CLX5
2025-09-24T19:40:48.893319074Z,2025-09-24T19:40:48.892373311Z,160,1,432669,A,B,64.830000000,1,26,8058566362608,128,15448,94358982,CLX5
2025-09-24T19:40:48.893511455Z,2025-09-24T19:40:48.892393991Z,160,1,432669,A,B,64.830000000,1,26,8058566362613,128,17332,94358990,CLX5
2025-09-24T19:40:48.893683732Z,2025-09-24T19:40:48.892407103Z,160,1,432669,A,B,64.830000000,1,26,8058566362615,128,15253,94358994,CLX5
2025-09-24T19:40:48.893764767Z,2025-09-24T19:40:48.892507881Z,160,1,432669,M,A,64.960000000,1,26,8058565075241,128,14692,94359000,CLX5
2025-09-24T19:40:48.894001544Z,2025-09-24T19:40:48.892681211Z,160,1,432669,C,A,64.840000000,2,26,8058566328837,128,14928,94359009,CLX5
2025-09-24T19:40:48.894522782Z,2025-09-24T19:40:48.893020535Z,160,1,432669,A,B,64.830000000,1,26,8058566362629,128,15004,94359041,CLX5
2025-09-24T19:40:48.894662804Z,2025-09-24T19:40:48.893119411Z,160,1,432669,C,B,64.830000000,1,26,8058566362615,128,15038,94359046,CLX5
2025-09-24T19:40:48.897086530Z,2025-09-24T19:40:48.894293363Z,160,1,432669,A,B,64.830000000,1,26,8058566362652,128,15319,94359182,CLX5
2025-09-24T19:40:48.897316196Z,2025-09-24T19:40:48.894488503Z,160,1,432669,C,B,64.830000000,1,26,8058566362652,128,15223,94359193,CLX5
2025-09-24T19:40:48.897766635Z,2025-09-24T19:40:48.895147957Z,160,1,432669,A,A,64.840000000,1,26,8058566362661,128,14891,94359217,CLX5
2025-09-24T19:40:48.897983208Z,2025-09-24T19:40:48.895501085Z,160,1,432669,A,B,64.830000000,1,26,8058566362663,128,15398,94359228,CLX5
2025-09-24T19:40:48.898230829Z,2025-09-24T19:40:48.895936023Z,160,1,432669,C,B,64.830000000,1,26,8058566362663,128,18800,94359242,CLX5
2025-09-24T19:40:48.899609147Z,2025-09-24T19:40:48.896386781Z,160,1,432669,A,B,64.830000000,2,26,8058566362687,128,14892,94359321,CLX5
2025-09-24T19:40:48.900601021Z,2025-09-24T19:40:48.897262129Z,160,1,432669,M,A,64.950000000,1,26,8058565075241,128,15128,94359384,CLX5
2025-09-24T19:40:48.901936273Z,2025-09-24T19:40:48.898217439Z,160,1,432669,M,A,64.860000000,1,26,8058566354507,128,14448,94359456,CLX5
2025-09-24T19:40:48.902622913Z,2025-09-24T19:40:48.899155241Z,160,1,432669,M,A,64.960000000,1,26,8058565075241,128,14743,94359495,CLX5
2025-09-24T19:40:48.902926756Z,2025-09-24T19:40:48.899336395Z,160,1,432669,C,B,64.830000000,1,26,8058566362613,128,15158,94359510,CLX5
2025-09-24T19:40:48.903007469Z,2025-09-24T19:40:48.899614081Z,160,1,432669,C,B,64.830000000,1,26,8058566362629,128,14554,94359517,CLX5
2025-09-24T19:40:48.903064643Z,2025-09-24T19:40:48.899702475Z,160,1,432669,C,B,64.830000000,2,26,8058566362687,128,14178,94359519,CLX5
2025-09-24T19:40:48.903178762Z,2025-09-24T19:40:48.899948913Z,160,1,432669,M,A,64.950000000,1,26,8058565075241,128,15125,94359524,CLX5
2025-09-24T19:40:48.903773924Z,2025-09-24T19:40:48.900636015Z,160,1,432669,M,A,64.960000000,1,26,8058565075241,128,14263,94359556,CLX5
2025-09-24T19:40:48.908876363Z,2025-09-24T19:40:48.907235685Z,160,1,432669,A,A,64.840000000,1,26,8058566362808,128,15531,94359870,CLX5
2025-09-24T19:40:48.908923731Z,2025-09-24T19:40:48.907526091Z,160,1,432669,C,B,64.830000000,1,26,8058566362608,128,15042,94359874,CLX5
2025-09-24T19:40:48.909711388Z,2025-09-24T19:40:48.908882165Z,160,1,432669,C,B,64.830000000,1,26,8058566362439,128,15791,94359924,CLX5
2025-09-24T19:40:48.909923606Z,2025-09-24T19:40:48.909084199Z,160,1,432669,A,A,64.840000000,1,26,8058566362827,128,16044,94359934,CLX5
2025-09-24T19:40:48.911666829Z,2025-09-24T19:40:48.910069327Z,160,1,432669,M,A,64.950000000,1,26,8058565075241,128,16019,94360047,CLX5
2025-09-24T19:40:48.911984903Z,2025-09-24T19:40:48.910743293Z,160,1,432669,A,A,64.840000000,1,26,8058566362865,128,15463,94360072,CLX5
2025-09-24T19:40:48.913089167Z,2025-09-24T19:40:48.912159441Z,160,1,432669,C,B,64.790000000,2,26,8058566362305,128,14895,94360137,CLX5
2025-09-24T19:40:48.913155888Z,2025-09-24T19:40:48.912185035Z,160,1,432669,M,A,64.960000000,1,26,8058565075241,128,14093,94360141,CLX5
2025-09-24T19:40:48.914028559Z,2025-09-24T19:40:48.913108053Z,160,1,432669,A,B,64.830000000,1,26,8058566362898,128,20105,94360185,CLX5
2025-09-24T19:40:48.921641052Z,2025-09-24T19:40:48.921071713Z,160,1,432669,M,A,64.950000000,1,26,8058565075241,128,14113,94360346,CLX5
2025-09-24T19:40:48.926778180Z,2025-09-24T19:40:48.926649293Z,160,1,432669,M,A,64.960000000,1,26,8058565075241,128,14147,94360386,CLX5
2025-09-24T19:40:48.930862021Z,2025-09-24T19:40:48.930723639Z,160,1,432669,A,B,64.830000000,1,26,8058566362944,128,19199,94360403,CLX5
2025-09-24T19:40:48.951263578Z,2025-09-24T19:40:48.951132685Z,160,1,432669,C,B,64.820000000,4,26,8058566362312,128,18159,94360484,CLX5
2025-09-24T19:40:49.007565792Z,2025-09-24T19:40:49.007379435Z,160,1,432669,C,B,64.830000000,2,26,8058566362445,128,17710,94360719,CLX5
2025-09-24T19:40:49.008519682Z,2025-09-24T19:40:49.008141843Z,160,1,432669,M,A,64.950000000,1,26,8058565075241,128,15266,94360761,CLX5
2025-09-24T19:40:49.008810032Z,2025-09-24T19:40:49.008478001Z,160,1,432669,C,B,64.830000000,1,26,8058566362944,128,15863,94360773,CLX5
2025-09-24T19:40:49.018755825Z,2025-09-24T19:40:49.018613811Z,160,1,432669,A,B,64.830000000,1,26,8058566363077,128,18410,94360844,CLX5
2025-09-24T19:40:49.019039532Z,2025-09-24T19:40:49.018780977Z,160,1,432669,M,A,64.960000000,1,26,8058565075241,128,16144,94360855,CLX5
2025-09-24T19:40:49.069039393Z,2025-09-24T19:40:49.068899675Z,160,1,432669,A,B,64.830000000,4,26,8058566363202,128,19349,94361071,CLX5
2025-09-24T19:40:49.069167066Z,2025-09-24T19:40:49.069039443Z,160,1,432669,A,B,64.830000000,2,26,8058566363203,128,19086,94361072,CLX5
2025-09-24T19:40:49.069196993Z,2025-09-24T19:40:49.069041305Z,160,1,432669,A,B,64.830000000,1,26,8058566363204,128,15026,94361073,CLX5
2025-09-24T19:40:49.069228871Z,2025-09-24T19:40:49.069045145Z,160,1,432669,A,B,64.830000000,1,26,8058566363205,128,15161,94361074,CLX5
2025-09-24T19:40:49.165778929Z,2025-09-24T19:40:49.165637101Z,160,1,432669,C,B,64.830000000,1,26,8058566363205,128,18297,94361254,CLX5
2025-09-24T19:40:49.165883648Z,2025-09-24T19:40:49.165761895Z,160,1,432669,C,B,64.830000000,2,26,8058566363203,128,18771,94361255,CLX5
2025-09-24T19:40:49.165914605Z,2025-09-24T19:40:49.165771743Z,160,1,432669,C,B,64.830000000,1,26,8058566363204,128,15075,94361256,CLX5
2025-09-24T19:40:49.191130208Z,2025-09-24T19:40:49.190999489Z,160,1,432669,M,A,64.950000000,1,26,8058565075241,128,17855,94361307,CLX5
2025-09-24T19:40:49.203648351Z,2025-09-24T19:40:49.203526513Z,160,1,432669,M,A,64.960000000,1,26,8058565075241,128,14054,94361333,CLX5
2025-09-24T19:40:49.530815190Z,2025-09-24T19:40:49.530673127Z,160,1,432669,C,B,64.820000000,1,26,8058566362002,128,19590,94361544,CLX5
2025-09-24T19:40:49.530843827Z,2025-09-24T19:40:49.530687699Z,160,1,432669,C,B,64.820000000,1,26,8058566362001,128,14883,94361545,CLX5
2025-09-24T19:40:49.530880174Z,2025-09-24T19:40:49.530707839Z,160,1,432669,A,A,64.860000000,1,26,8058566363455,128,14719,94361546,CLX5
2025-09-24T19:40:49.605905950Z,2025-09-24T19:40:49.605764795Z,160,1,432669,C,B,64.820000000,1,26,8058566362000,128,18643,94361556,CLX5
2025-09-24T19:40:49.900161204Z,2025-09-24T19:40:49.900008937Z,160,1,432669,C,B,64.830000000,1,26,8058566362483,128,19710,94361594,CLX5
2025-09-24T19:40:50.008740569Z,2025-09-24T19:40:50.008576593Z,160,1,432669,A,B,64.800000000,5,26,8058566363486,128,19192,94361614,CLX5
2025-09-24T19:40:50.008879163Z,2025-09-24T19:40:50.008756105Z,160,1,432669,C,B,64.810000000,1,26,8058566362586,128,17968,94361615,CLX5
2025-09-24T19:40:51.189675045Z,2025-09-24T19:40:51.189515679Z,160,1,432669,M,B,64.830000000,11,26,8058566360382,128,18348,94361864,CLX5
2025-09-24T19:40:51.401998761Z,2025-09-24T19:40:51.401848309Z,160,1,432669,M,B,64.810000000,1,26,8058566197138,128,18798,94361896,CLX5
2025-09-24T19:40:51.872885115Z,2025-09-24T19:40:51.872724449Z,160,1,432669,A,B,64.830000000,1,26,8058566363626,128,18176,94361917,CLX5
2025-09-24T19:40:51.875261435Z,2025-09-24T19:40:51.875136189Z,160,1,432669,A,B,64.830000000,1,26,8058566363628,128,18229,94361919,CLX5
2025-09-24T19:40:53.292268113Z,2025-09-24T19:40:53.292146815Z,160,1,432669,A,A,65.970000000,1,26,8058566363632,128,20420,94361954,CLX5
2025-09-24T19:40:53.797810191Z,2025-09-24T19:40:53.797648645Z,160,1,432669,A,A,64.840000000,1,26,8058566363633,128,22062,94361956,CLX5
2025-09-24T19:40:53.797990538Z,2025-09-24T19:40:53.797860239Z,160,1,432669,C,B,64.830000000,1,26,8058566363628,128,21880,94361957,CLX5
2025-09-24T19:40:54.372840993Z,2025-09-24T19:40:54.372713885Z,160,1,432669,A,B,64.830000000,1,26,8058566363638,128,17447,94361973,CLX5
2025-09-24T19:40:55.138780721Z,2025-09-24T19:40:55.138157267Z,160,1,432669,A,B,64.830000000,1,26,8058566363652,128,16202,94362037,CLX5
2025-09-24T19:40:55.139650489Z,2025-09-24T19:40:55.138786521Z,160,1,432669,C,B,64.830000000,1,26,8058566363652,128,14791,94362104,CLX5
2025-09-24T19:40:55.154910516Z,2025-09-24T19:40:55.154750539Z,160,1,432669,C,B,64.830000000,1,26,8058566363638,128,14712,94362566,CLX5
2025-09-24T19:40:55.738160065Z,2025-09-24T19:40:55.737948561Z,160,1,432669,A,B,64.830000000,1,26,8058566363934,128,13905,94362904,CLX5
2025-09-24T19:40:55.738252665Z,2025-09-24T19:40:55.738131949Z,160,1,432669,A,B,64.830000000,1,26,8058566363936,128,18286,94362906,CLX5
2025-09-24T19:40:58.888857931Z,2025-09-24T19:40:58.888710397Z,160,1,432669,C,B,64.760000000,2,26,8058564529110,128,18132,94363267,CLX5
2025-09-24T19:41:00.092790654Z,2025-09-24T19:41:00.092663039Z,160,1,432669,C,B,64.830000000,1,26,8058566363936,128,18943,94363465,CLX5
2025-09-24T19:41:00.092819091Z,2025-09-24T19:41:00.092684791Z,160,1,432669,C,B,64.830000000,1,26,8058566363934,128,14754,94363466,CLX5
2025-09-24T19:41:00.592453039Z,2025-09-24T19:41:00.592307173Z,160,1,432669,C,A,64.860000000,1,26,8058566363455,128,18222,94363538,CLX5
2025-09-24T19:41:00.838806616Z,2025-09-24T19:41:00.838673299Z,160,1,432669,A,B,64.830000000,1,26,8058566364185,128,17654,94363542,CLX5
2025-09-24T19:41:01.678212143Z,2025-09-24T19:41:01.678017091Z,160,1,432669,A,B,64.820000000,1,26,8058566364191,128,19332,94363565,CLX5
2025-09-24T19:41:02.267018403Z,2025-09-24T19:41:02.265494401Z,160,1,432669,C,B,64.830000000,1,26,8058566364185,128,15219,94363646,CLX5
2025-09-24T19:41:02.267927145Z,2025-09-24T19:41:02.265996555Z,160,1,432669,C,A,64.840000000,2,26,8058566324579,128,19478,94363698,CLX5
2025-09-24T19:41:02.268096994Z,2025-09-24T19:41:02.265998877Z,160,1,432669,C,A,64.870000000,2,26,8058566358030,128,13695,94363704,CLX5
2025-09-24T19:41:02.268124579Z,2025-09-24T19:41:02.266000067Z,160,1,432669,C,A,64.840000000,1,26,8058566319356,128,15119,94363705,CLX5
2025-09-24T19:41:02.268234290Z,2025-09-24T19:41:02.266012565Z,160,1,432669,C,A,64.840000000,2,26,8058566307859,128,14922,94363709,CLX5
2025-09-24T19:41:02.268333725Z,2025-09-24T19:41:02.266021263Z,160,1,432669,C,A,64.840000000,1,26,8058566307923,128,15191,94363713,CLX5
2025-09-24T19:41:02.268555274Z,2025-09-24T19:41:02.266022377Z,160,1,432669,A,B,64.830000000,1,26,8058566364234,128,22009,94363718,CLX5
2025-09-24T19:41:02.268608624Z,2025-09-24T19:41:02.266030883Z,160,1,432669,A,B,64.830000000,1,26,8058566364236,128,15131,94363720,CLX5
2025-09-24T19:41:02.268915271Z,2025-09-24T19:41:02.266061351Z,160,1,432669,A,B,64.830000000,1,26,8058566364240,128,15831,94363731,CLX5
2025-09-24T19:41:02.269196968Z,2025-09-24T19:41:02.266105549Z,160,1,432669,C,A,64.840000000,1,26,8058566362661,128,16240,94363740,CLX5
2025-09-24T19:41:02.269498298Z,2025-09-24T19:41:02.266198281Z,160,1,432669,C,A,64.840000000,1,26,8058566319355,128,14720,94363752,CLX5
2025-09-24T19:41:02.269527196Z,2025-09-24T19:41:02.266209875Z,160,1,432669,T,B,64.840000000,1,26,8058566364249,0,18362,94363754,CLX5
2025-09-24T19:41:02.269527196Z,2025-09-24T19:41:02.266209875Z,160,1,432669,F,A,64.840000000,1,26,8058566274106,0,18362,94363754,CLX5
2025-09-24T19:41:02.269547969Z,2025-09-24T19:41:02.266209875Z,160,1,432669,C,A,64.840000000,1,26,8058566274106,128,15346,94363755,CLX5
2025-09-24T19:41:02.269798900Z,2025-09-24T19:41:02.266383207Z,160,1,432669,C,B,64.830000000,1,26,8058566364240,128,14850,94363768,CLX5
2025-09-24T19:41:02.269886033Z,2025-09-24T19:41:02.266426903Z,160,1,432669,A,B,64.810000000,1,26,8058566364251,128,14884,94363772,CLX5
2025-09-24T19:41:02.270652034Z,2025-09-24T19:41:02.266632431Z,160,1,432669,A,B,64.830000000,1,26,8058566364265,128,14628,94363802,CLX5
2025-09-24T19:41:02.271343030Z,2025-09-24T19:41:02.267168317Z,160,1,432669,A,B,64.820000000,2,26,8058566364279,128,15187,94363834,CLX5
2025-09-24T19:41:02.271600926Z,2025-09-24T19:41:02.267497161Z,160,1,432669,A,B,64.830000000,2,26,8058566364287,128,14729,94363845,CLX5
2025-09-24T19:41:02.271636091Z,2025-09-24T19:41:02.267499675Z,160,1,432669,C,A,64.840000000,3,26,8058566307931,128,15320,94363846,CLX5
2025-09-24T19:41:02.272202745Z,2025-09-24T19:41:02.267958709Z,160,1,432669,C,A,64.840000000,1,26,8058566274281,128,14093,94363870,CLX5
2025-09-24T19:41:02.272362135Z,2025-09-24T19:41:02.268131079Z,160,1,432669,C,A,64.870000000,1,26,8058566329645,128,14368,94363876,CLX5
2025-09-24T19:41:02.272372318Z,2025-09-24T19:41:02.268146285Z,160,1,432669,T,N,64.840000000,1,26,0,0,14652,94363877,CLX5
2025-09-24T19:41:02.272372318Z,2025-09-24T19:41:02.268146285Z,160,1,432669,F,N,64.840000000,1,26,8058566307934,0,14652,94363877,CLX5
2025-09-24T19:41:02.272421606Z,2025-09-24T19:41:02.268146285Z,160,1,432669,C,A,64.840000000,1,26,8058566307934,128,20711,94363878,CLX5
2025-09-24T19:41:02.272563632Z,2025-09-24T19:41:02.268341405Z,160,1,432669,A,A,64.840000000,1,26,8058566364299,128,16133,94363882,CLX5
2025-09-24T19:41:02.272693056Z,2025-09-24T19:41:02.268476163Z,160,1,432669,A,B,64.830000000,1,26,8058566364302,128,15114,94363887,CLX5
2025-09-24T19:41:02.272885968Z,2025-09-24T19:41:02.268570815Z,160,1,432669,A,B,64.830000000,1,26,8058566364303,128,15152,94363892,CLX5
2025-09-24T19:41:02.273157734Z,2025-09-24T19:41:02.268922755Z,160,1,432669,A,A,64.840000000,2,26,8058566364306,128,14108,94363902,CLX5
2025-09-24T19:41:02.273219447Z,2025-09-24T19:41:02.268995347Z,160,1,432669,C,B,64.830000000,1,26,8058566364302,128,14947,94363904,CLX5
2025-09-24T19:41:02.273366273Z,2025-09-24T19:41:02.269541429Z,160,1,432669,T,N,64.840000000,1,26,0,0,13473,94363911,CLX5
2025-09-24T19:41:02.273366273Z,2025-09-24T19:41:02.269541429Z,160,1,432669,F,N,64.840000000,1,26,8058566329855,0,13473,94363911,CLX5
2025-09-24T19:41:02.273410377Z,2025-09-24T19:41:02.269541429Z,160,1,432669,C,A,64.840000000,1,26,8058566329855,128,16168,94363912,CLX5
2025-09-24T19:41:02.273444559Z,2025-09-24T19:41:02.269556211Z,160,1,432669,C,B,64.820000000,2,26,8058566364279,128,18668,94363913,CLX5
2025-09-24T19:41:02.275326905Z,2025-09-24T19:41:02.272213931Z,160,1,432669,M,A,64.850000000,1,26,8058566349378,128,16029,94363991,CLX5
2025-09-24T19:41:02.276047743Z,2025-09-24T19:41:02.273323239Z,160,1,432669,A,B,64.810000000,1,26,8058566364346,128,14788,94364038,CLX5
2025-09-24T19:41:02.276182489Z,2025-09-24T19:41:02.273898425Z,160,1,432669,C,B,64.830000000,1,26,8058566364234,128,14871,94364044,CLX5
2025-09-24T19:41:02.276770524Z,2025-09-24T19:41:02.274603093Z,160,1,432669,M,A,64.850000000,1,26,8058566361816,128,15536,94364076,CLX5
2025-09-24T19:41:02.277103627Z,2025-09-24T19:41:02.276026155Z,160,1,432669,A,A,64.840000000,1,26,8058566364362,128,15073,94364096,CLX5
2025-09-24T19:41:02.277505984Z,2025-09-24T19:41:02.277109177Z,160,1,432669,A,A,64.840000000,1,26,8058566364368,128,15153,94364118,CLX5
2025-09-24T19:41:02.277690517Z,2025-09-24T19:41:02.277292683Z,160,1,432669,A,A,64.840000000,3,26,8058566364370,128,18992,94364123,CLX5
2025-09-24T19:41:02.277746378Z,2025-09-24T19:41:02.277330831Z,160,1,432669,A,A,64.840000000,2,26,8058566364372,128,14919,94364126,CLX5
2025-09-24T19:41:02.278743927Z,2025-09-24T19:41:02.278375669Z,160,1,432669,C,B,64.830000000,1,26,8058566364303,128,14621,94364175,CLX5
2025-09-24T19:41:02.279085155Z,2025-09-24T19:41:02.278685947Z,160,1,432669,A,A,64.840000000,1,26,8058566364389,128,18290,94364193,CLX5
2025-09-24T19:41:02.279142767Z,2025-09-24T19:41:02.278694107Z,160,1,432669,C,B,64.830000000,2,26,8058566364287,128,14745,94364195,CLX5
2025-09-24T19:41:02.279293456Z,2025-09-24T19:41:02.278757465Z,160,1,432669,A,A,64.840000000,2,26,8058566364393,128,15030,94364199,CLX5
2025-09-24T19:41:02.279523475Z,2025-09-24T19:41:02.278958497Z,160,1,432669,A,A,64.870000000,1,26,8058566364396,128,14443,94364205,CLX5
2025-09-24T19:41:02.279698463Z,2025-09-24T19:41:02.279090147Z,160,1,432669,C,B,64.830000000,1,26,8058566364265,128,18410,94364212,CLX5
2025-09-24T19:41:02.279728413Z,2025-09-24T19:41:02.279096617Z,160,1,432669,C,A,64.840000000,2,26,8058566364393,128,15118,94364213,CLX5
2025-09-24T19:41:02.280206361Z,2025-09-24T19:41:02.279566669Z,160,1,432669,M,A,64.950000000,1,26,8058565075241,128,17115,94364234,CLX5
2025-09-24T19:41:02.280490905Z,2025-09-24T19:41:02.279765381Z,160,1,432669,A,A,64.840000000,1,26,8058566364411,128,15080,94364246,CLX5
2025-09-24T19:41:02.280794986Z,2025-09-24T19:41:02.279929705Z,160,1,432669,T,A,64.830000000,1,26,8058566364417,0,14875,94364263,CLX5
2025-09-24T19:41:02.280794986Z,2025-09-24T19:41:02.279929705Z,160,1,432669,F,B,64.830000000,1,26,8058566362429,0,14875,94364263,CLX5
2025-09-24T19:41:02.280832900Z,2025-09-24T19:41:02.279929705Z,160,1,432669,M,B,64.830000000,1,26,8058566362429,128,19022,94364264,CLX5
2025-09-24T19:41:02.280920670Z,2025-09-24T19:41:02.280019653Z,160,1,432669,A,A,64.840000000,2,26,8058566364420,128,15362,94364270,CLX5
2025-09-24T19:41:02.281038146Z,2025-09-24T19:41:02.280036897Z,160,1,432669,C,B,64.830000000,1,26,8058566362433,128,17568,94364275,CLX5
2025-09-24T19:41:02.281107815Z,2025-09-24T19:41:02.280046917Z,160,1,432669,C,B,64.830000000,2,26,8058566362448,128,14898,94364277,CLX5
2025-09-24T19:41:02.281669032Z,2025-09-24T19:41:02.280470853Z,160,1,432669,C,B,64.830000000,1,26,8058566362429,128,16810,94364308,CLX5
2025-09-24T19:41:02.281748124Z,2025-09-24T19:41:02.280505277Z,160,1,432669,C,B,64.830000000,1,26,8058566363077,128,18638,94364311,CLX5
2025-09-24T19:41:02.282084744Z,2025-09-24T19:41:02.281030951Z,160,1,432669,A,A,64.870000000,2,26,8058566364431,128,14723,94364329,CLX5
2025-09-24T19:41:02.283748828Z,2025-09-24T19:41:02.283612719Z,160,1,432669,M,A,64.840000000,1,26,8058566361816,128,16589,94364400,CLX5
2025-09-24T19:41:02.287839773Z,2025-09-24T19:41:02.287711679Z,160,1,432669,M,A,64.840000000,1,26,8058566349378,128,19092,94364420,CLX5
2025-09-24T19:41:02.292483027Z,2025-09-24T19:41:02.292361657Z,160,1,432669,A,A,64.870000000,2,26,8058566364454,128,17938,94364426,CLX5
2025-09-24T19:41:02.292870209Z,2025-09-24T19:41:02.292740763Z,160,1,432669,C,B,64.830000000,1,26,8058566364236,128,14747,94364438,CLX5
2025-09-24T19:41:02.295818054Z,2025-09-24T19:41:02.295497589Z,160,1,432669,T,B,64.840000000,2,26,8058566364467,0,17899,94364491,CLX5
2025-09-24T19:41:02.295818054Z,2025-09-24T19:41:02.295497589Z,160,1,432669,F,A,64.840000000,1,26,8058566357446,0,17899,94364491,CLX5
2025-09-24T19:41:02.295818054Z,2025-09-24T19:41:02.295497589Z,160,1,432669,F,A,64.840000000,1,26,8058566360573,0,17899,94364491,CLX5
2025-09-24T19:41:02.295829757Z,2025-09-24T19:41:02.295497589Z,160,1,432669,C,A,64.840000000,1,26,8058566357446,0,15430,94364492,CLX5
2025-09-24T19:41:02.295829757Z,2025-09-24T19:41:02.295497589Z,160,1,432669,C,A,64.840000000,1,26,8058566360573,128,15430,94364492,CLX5
2025-09-24T19:41:02.296185062Z,2025-09-24T19:41:02.295828159Z,160,1,432669,A,B,64.830000000,1,26,8058566364471,128,14683,94364501,CLX5
2025-09-24T19:41:02.296265344Z,2025-09-24T19:41:02.295835417Z,160,1,432669,C,A,64.840000000,2,26,8058566364420,128,19220,94364504,CLX5
2025-09-24T19:41:02.314554921Z,2025-09-24T19:41:02.314409215Z,160,1,432669,C,B,64.740000000,2,26,8058566262123,128,19526,94364595,CLX5
2025-09-24T19:41:02.337552091Z,2025-09-24T19:41:02.337440499Z,160,1,432669,M,A,64.960000000,1,26,8058565075241,128,14679,94364648,CLX5
2025-09-24T19:41:02.444424608Z,2025-09-24T19:41:02.444300179Z,160,1,432669,C,B,64.810000000,1,26,8058566364251,128,18729,94364820,CLX5
2025-09-24T19:41:02.577564224Z,2025-09-24T19:41:02.577417889Z,160,1,432669,A,A,64.840000000,1,26,8058566364660,128,19172,94364900,CLX5
2025-09-24T19:41:03.400043364Z,2025-09-24T19:41:03.399922837Z,160,1,432669,C,A,65.080000000,1,26,8058566358089,128,18271,94365019,CLX5
2025-09-24T19:41:03.415541174Z,2025-09-24T19:41:03.415431029Z,160,1,432669,A,A,65.070000000,1,26,8058566364716,128,18973,94365020,CLX5
2025-09-24T19:41:03.573195343Z,2025-09-24T19:41:03.572908315Z,160,1,432669,T,B,64.840000000,1,26,8058566364719,0,18221,94365026,CLX5
2025-09-24T19:41:03.573195343Z,2025-09-24T19:41:03.572908315Z,160,1,432669,F,A,64.840000000,1,26,8058566361263,0,18221,94365026,CLX5
2025-09-24T19:41:03.573206278Z,2025-09-24T19:41:03.572908315Z,160,1,432669,C,A,64.840000000,1,26,8058566361263,128,16444,94365027,CLX5
2025-09-24T19:41:03.588774756Z,2025-09-24T19:41:03.588663793Z,160,1,432669,C,A,65.080000000,1,26,8058566358088,128,18270,94365034,CLX5
2025-09-24T19:41:03.620159749Z,2025-09-24T19:41:03.620050279Z,160,1,432669,A,A,65.070000000,1,26,8058566364722,128,18224,94365035,CLX5
2025-09-24T19:41:03.806611442Z,2025-09-24T19:41:03.806496035Z,160,1,432669,C,B,64.600000000,2,26,8058564984683,128,18591,94365043,CLX5
2025-09-24T19:41:04.336961611Z,2025-09-24T19:41:04.336590919Z,160,1,432669,T,A,64.830000000,1,26,8058566364741,0,16893,94365083,CLX5
2025-09-24T19:41:04.336961611Z,2025-09-24T19:41:04.336590919Z,160,1,432669,F,B,64.830000000,1,26,8058566362898,0,16893,94365083,CLX5
2025-09-24T19:41:04.336961611Z,2025-09-24T19:41:04.336590919Z,160,1,432669,C,B,64.830000000,1,26,8058566362898,128,16893,94365083,CLX5
2025-09-24T19:41:04.337284508Z,2025-09-24T19:41:04.336968929Z,160,1,432669,A,A,64.840000000,2,26,8058566364745,128,14844,94365096,CLX5
2025-09-24T19:41:04.337314996Z,2025-09-24T19:41:04.336969109Z,160,1,432669,A,A,64.840000000,1,26,8058566364746,128,14129,94365097,CLX5
2025-09-24T19:41:04.337388773Z,2025-09-24T19:41:04.336984999Z,160,1,432669,C,B,64.810000000,1,26,8058566364346,128,14678,94365099,CLX5
2025-09-24T19:41:04.337420674Z,2025-09-24T19:41:04.336997901Z,160,1,432669,A,A,64.840000000,2,26,8058566364747,128,15491,94365100,CLX5
2025-09-24T19:41:04.337593412Z,2025-09-24T19:41:04.337314573Z,160,1,432669,C,A,64.840000000,2,26,8058566364747,128,19134,94365109,CLX5
2025-09-24T19:41:04.338152587Z,2025-09-24T19:41:04.337718675Z,160,1,432669,C,B,64.830000000,1,26,8058566364471,128,15198,94365136,CLX5
2025-09-24T19:41:04.338633667Z,2025-09-24T19:41:04.338063665Z,160,1,432669,M,A,64.950000000,1,26,8058565075241,128,14744,94365152,CLX5
2025-09-24T19:41:04.347931863Z,2025-09-24T19:41:04.347785693Z,160,1,432669,A,B,64.830000000,1,26,8058566364779,128,18835,94365228,CLX5
2025-09-24T19:41:04.349067829Z,2025-09-24T19:41:04.348932133Z,160,1,432669,A,B,64.830000000,1,26,8058566364784,128,18436,94365249,CLX5
2025-09-24T19:41:04.403842366Z,2025-09-24T19:41:04.403740953Z,160,1,432669,C,A,65.110000000,1,26,8058566359226,128,17759,94365281,CLX5
2025-09-24T19:41:04.408387650Z,2025-09-24T19:41:04.408162863Z,160,1,432669,M,A,64.960000000,1,26,8058565075241,128,15742,94365290,CLX5
2025-09-24T19:41:04.481930561Z,2025-09-24T19:41:04.481832181Z,160,1,432669,A,A,65.100000000,1,26,8058566364828,128,14338,94365348,CLX5
2025-09-24T19:41:04.529251412Z,2025-09-24T19:41:04.529146381Z,160,1,432669,C,A,65.240000000,1,26,8058566280143,128,18118,94365368,CLX5
2025-09-24T19:41:04.576579098Z,2025-09-24T19:41:04.576458699Z,160,1,432669,A,A,65.100000000,1,26,8058566364843,128,18370,94365378,CLX5
2025-09-24T19:41:07.020222744Z,2025-09-24T19:41:07.019861661Z,160,1,432669,T,B,64.840000000,1,26,8058566365217,0,17912,94366315,CLX5
2025-09-24T19:41:07.020222744Z,2025-09-24T19:41:07.019861661Z,160,1,432669,F,A,64.840000000,1,26,8058566362808,0,17912,94366315,CLX5
2025-09-24T19:41:07.020233350Z,2025-09-24T19:41:07.019861661Z,160,1,432669,C,A,64.840000000,1,26,8058566362808,128,15812,94366316,CLX5
2025-09-24T19:41:08.131540696Z,2025-09-24T19:41:08.131418059Z,160,1,432669,A,B,64.720000000,1,26,8058566365291,128,18967,94366495,CLX5
2025-09-24T19:41:09.170394136Z,2025-09-24T19:41:09.170234667Z,160,1,432669,A,B,64.750000000,1,26,8058566365346,128,18815,94366609,CLX5
2025-09-24T19:41:09.434728754Z,2025-09-24T19:41:09.434325869Z,160,1,432669,T,A,64.830000000,1,26,8058566365361,0,16249,94366640,CLX5
2025-09-24T19:41:09.434728754Z,2025-09-24T19:41:09.434325869Z,160,1,432669,F,B,64.830000000,1,26,8058566363202,0,16249,94366640,CLX5
2025-09-24T19:41:09.434728754Z,2025-09-24T19:41:09.434325869Z,160,1,432669,M,B,64.830000000,3,26,8058566363202,128,16249,94366640,CLX5
2025-09-24T19:41:09.441006495Z,2025-09-24T19:41:09.440640971Z,160,1,432669,T,A,64.830000000,1,26,8058566365380,0,16200,94366701,CLX5
2025-09-24T19:41:09.441006495Z,2025-09-24T19:41:09.440640971Z,160,1,432669,F,B,64.830000000,1,26,8058566363202,0,16200,94366701,CLX5
2025-09-24T19:41:09.441030601Z,2025-09-24T19:41:09.440640971Z,160,1,432669,M,B,64.830000000,2,26,8058566363202,128,18542,94366702,CLX5
2025-09-24T19:41:09.441104279Z,2025-09-24T19:41:09.440948197Z,160,1,432669,A,A,64.840000000,2,26,8058566365382,128,15147,94366704,CLX5
2025-09-24T19:41:09.441161031Z,2025-09-24T19:41:09.441018119Z,160,1,432669,C,B,64.830000000,1,26,8058566364784,128,14962,94366706,CLX5
2025-09-24T19:41:09.441309601Z,2025-09-24T19:41:09.441186035Z,160,1,432669,M,A,64.840000000,2,26,8058566364431,128,18170,94366707,CLX5
2025-09-24T19:41:09.441339674Z,2025-09-24T19:41:09.441186785Z,160,1,432669,A,B,64.830000000,1,26,8058566365384,128,14995,94366708,CLX5
2025-09-24T19:41:09.449148205Z,2025-09-24T19:41:09.449020039Z,160,1,432669,C,A,64.840000000,2,26,8058566365382,128,18694,94366722,CLX5
2025-09-24T19:41:09.454208591Z,2025-09-24T19:41:09.453902077Z,160,1,432669,T,A,64.830000000,1,26,8058566365390,0,15996,94366725,CLX5
2025-09-24T19:41:09.454208591Z,2025-09-24T19:41:09.453902077Z,160,1,432669,F,B,64.830000000,1,26,8058566363202,0,15996,94366725,CLX5
2025-09-24T19:41:09.454208591Z,2025-09-24T19:41:09.453902077Z,160,1,432669,M,B,64.830000000,1,26,8058566363202,128,15996,94366725,CLX5
2025-09-24T19:41:09.454457249Z,2025-09-24T19:41:09.454231821Z,160,1,432669,A,A,64.840000000,2,26,8058566365394,128,18351,94366732,CLX5
2025-09-24T19:41:09.461107542Z,2025-09-24T19:41:09.460770305Z,160,1,432669,T,A,64.830000000,1,26,8058566365398,0,16735,94366738,CLX5
2025-09-24T19:41:09.461107542Z,2025-09-24T19:41:09.460770305Z,160,1,432669,F,B,64.830000000,1,26,8058566363202,0,16735,94366738,CLX5
2025-09-24T19:41:09.461107542Z,2025-09-24T19:41:09.460770305Z,160,1,432669,C,B,64.830000000,1,26,8058566363202,128,16735,94366738,CLX5
2025-09-24T19:41:09.464706271Z,2025-09-24T19:41:09.464457291Z,160,1,432669,T,A,64.830000000,1,26,8058566365403,0,18279,94366752,CLX5
2025-09-24T19:41:09.464706271Z,2025-09-24T19:41:09.464457291Z,160,1,432669,F,B,64.830000000,1,26,8058566360382,0,18279,94366752,CLX5
2025-09-24T19:41:09.464716623Z,2025-09-24T19:41:09.464457291Z,160,1,432669,M,B,64.830000000,10,26,8058566360382,128,15620,94366753,CLX5
2025-09-24T19:41:09.464994040Z,2025-09-24T19:41:09.464712927Z,160,1,432669,T,A,64.830000000,13,26,8058566365404,0,18578,94366754,CLX5
2025-09-24T19:41:09.464994040Z,2025-09-24T19:41:09.464712927Z,160,1,432669,F,B,64.830000000,10,26,8058566360382,0,18578,94366754,CLX5
2025-09-24T19:41:09.464994040Z,2025-09-24T19:41:09.464712927Z,160,1,432669,F,B,64.830000000,1,26,8058566363626,0,18578,94366754,CLX5
2025-09-24T19:41:09.464994040Z,2025-09-24T19:41:09.464712927Z,160,1,432669,F,B,64.830000000,1,26,8058566364779,0,18578,94366754,CLX5
2025-09-24T19:41:09.464994040Z,2025-09-24T19:41:09.464712927Z,160,1,432669,F,B,64.830000000,1,26,8058566365384,0,18578,94366754,CLX5
2025-09-24T19:41:09.465003663Z,2025-09-24T19:41:09.464712927Z,160,1,432669,C,B,64.830000000,10,26,8058566360382,0,14868,94366755,CLX5
2025-09-24T19:41:09.465003663Z,2025-09-24T19:41:09.464712927Z,160,1,432669,C,B,64.830000000,1,26,8058566363626,0,14868,94366755,CLX5
2025-09-24T19:41:09.465003663Z,2025-09-24T19:41:09.464712927Z,160,1,432669,C,B,64.830000000,1,26,8058566364779,0,14868,94366755,CLX5
2025-09-24T19:41:09.465003663Z,2025-09-24T19:41:09.464712927Z,160,1,432669,C,B,64.830000000,1,26,8058566365384,128,14868,94366755,CLX5
2025-09-24T19:41:09.465306139Z,2025-09-24T19:41:09.464978375Z,160,1,432669,T,A,64.830000000,1,26,8058566365405,128,17870,94366759,CLX5
2025-09-24T19:41:09.465488967Z,2025-09-24T19:41:09.464995019Z,160,1,432669,C,B,64.820000000,1,26,8058566362421,128,14707,94366771,CLX5
2025-09-24T19:41:09.466144421Z,2025-09-24T19:41:09.465005971Z,160,1,432669,A,A,64.830000000,2,26,8058566365417,128,13990,94366799,CLX5
2025-09-24T19:41:09.466631983Z,2025-09-24T19:41:09.465029829Z,160,1,432669,A,B,64.820000000,1,26,8058566365422,128,18009,94366814,CLX5
2025-09-24T19:41:09.466663454Z,2025-09-24T19:41:09.465044533Z,160,1,432669,A,A,64.840000000,3,26,8058566365423,128,14777,94366815,CLX5
2025-09-24T19:41:09.466892376Z,2025-09-24T19:41:09.465256053Z,160,1,432669,C,A,64.840000000,1,26,8058566362827,128,14788,94366828,CLX5
2025-09-24T19:41:09.466919915Z,2025-09-24T19:41:09.465259911Z,160,1,432669,A,A,64.840000000,2,26,8058566365428,128,15202,94366829,CLX5
2025-09-24T19:41:09.467016939Z,2025-09-24T19:41:09.465313439Z,160,1,432669,M,A,64.830000000,2,26,8058566362865,128,14572,94366831,CLX5
2025-09-24T19:41:09.467188885Z,2025-09-24T19:41:09.465343139Z,160,1,432669,A,A,64.830000000,3,26,8058566365429,128,17459,94366841,CLX5
2025-09-24T19:41:09.467342838Z,2025-09-24T19:41:09.465402637Z,160,1,432669,A,A,64.830000000,2,26,8058566365432,128,15897,94366847,CLX5
2025-09-24T19:41:09.467433672Z,2025-09-24T19:41:09.465492029Z,160,1,432669,M,B,63.670000000,4,26,8058566345944,128,14598,94366854,CLX5
2025-09-24T19:41:09.467625286Z,2025-09-24T19:41:09.465650267Z,160,1,432669,A,A,64.830000000,1,26,8058566365436,128,15992,94366866,CLX5
2025-09-24T19:41:09.468356675Z,2025-09-24T19:41:09.465951943Z,160,1,432669,M,A,64.950000000,1,26,8058565075241,128,14432,94366896,CLX5
2025-09-24T19:41:09.468406700Z,2025-09-24T19:41:09.466002629Z,160,1,432669,A,A,64.840000000,1,26,8058566365445,128,14659,94366899,CLX5
2025-09-24T19:41:09.468697657Z,2025-09-24T19:41:09.466148275Z,160,1,432669,A,A,64.830000000,1,26,8058566365448,128,18949,94366909,CLX5
2025-09-24T19:41:09.468808995Z,2025-09-24T19:41:09.466158315Z,160,1,432669,A,A,64.830000000,1,26,8058566365450,128,15639,94366913,CLX5
2025-09-24T19:41:09.468896974Z,2025-09-24T19:41:09.466165823Z,160,1,432669,C,A,64.830000000,2,26,8058566365432,128,17828,94366916,CLX5
2025-09-24T19:41:09.469265233Z,2025-09-24T19:41:09.466286183Z,160,1,432669,M,A,64.830000000,1,26,8058566357626,128,16071,94366935,CLX5
2025-09-24T19:41:09.469337037Z,2025-09-24T19:41:09.466377205Z,160,1,432669,C,B,64.820000000,2,26,8058566362449,128,14535,94366937,CLX5
2025-09-24T19:41:09.469422910Z,2025-09-24T19:41:09.466401839Z,160,1,432669,C,A,64.840000000,1,26,8058566363633,128,15100,94366940,CLX5
2025-09-24T19:41:09.469956674Z,2025-09-24T19:41:09.466977467Z,160,1,432669,A,A,64.830000000,1,26,8058566365462,128,15694,94366962,CLX5
2025-09-24T19:41:09.470498968Z,2025-09-24T19:41:09.467628795Z,160,1,432669,C,A,64.830000000,1,26,8058566365448,128,15719,94366994,CLX5
2025-09-24T19:41:09.470618493Z,2025-09-24T19:41:09.467699431Z,160,1,432669,A,B,64.820000000,1,26,8058566365470,128,15198,94367000,CLX5
2025-09-24T19:41:09.471417363Z,2025-09-24T19:41:09.469302925Z,160,1,432669,A,B,64.820000000,1,26,8058566365480,128,14959,94367041,CLX5
2025-09-24T19:41:09.472167207Z,2025-09-24T19:41:09.470618797Z,160,1,432669,A,B,64.820000000,1,26,8058566365490,128,14672,94367080,CLX5
2025-09-24T19:41:09.473760593Z,2025-09-24T19:41:09.473363353Z,160,1,432669,T,A,64.820000000,1,26,8058566365517,0,16934,94367182,CLX5
2025-09-24T19:41:09.473760593Z,2025-09-24T19:41:09.473363353Z,160,1,432669,F,B,64.820000000,1,26,8058566358218,0,16934,94367182,CLX5
2025-09-24T19:41:09.473760593Z,2025-09-24T19:41:09.473363353Z,160,1,432669,M,B,64.820000000,1,26,8058566358218,128,16934,94367182,CLX5
2025-09-24T19:41:09.473905929Z,2025-09-24T19:41:09.473688395Z,160,1,432669,A,A,64.830000000,2,26,8058566365518,128,15605,94367192,CLX5
2025-09-24T19:41:09.474225823Z,2025-09-24T19:41:09.473793567Z,160,1,432669,C,B,64.820000000,1,26,8058566365490,128,14994,94367204,CLX5
2025-09-24T19:41:09.475487934Z,2025-09-24T19:41:09.474924361Z,160,1,432669,C,B,64.820000000,1,26,8058566365470,128,15451,94367266,CLX5
2025-09-24T19:41:09.475822288Z,2025-09-24T19:41:09.475222791Z,160,1,432669,C,A,64.830000000,2,26,8058566365518,128,14913,94367282,CLX5
2025-09-24T19:41:09.478635663Z,2025-09-24T19:41:09.478517695Z,160,1,432669,A,B,63.680000000,4,26,8058566365565,128,13959,94367361,CLX5
2025-09-24T19:41:09.483409424Z,2025-09-24T19:41:09.483275857Z,160,1,432669,C,B,64.810000000,2,26,8058566362417,128,13699,94367594,CLX5
2025-09-24T19:41:09.483530339Z,2025-09-24T19:41:09.483291773Z,160,1,432669,C,B,64.820000000,1,26,8058566365480,128,15080,94367598,CLX5
2025-09-24T19:41:09.486216055Z,2025-09-24T19:41:09.485944215Z,160,1,432669,T,A,64.820000000,1,26,8058566365636,0,18122,94367619,CLX5
2025-09-24T19:41:09.486216055Z,2025-09-24T19:41:09.485944215Z,160,1,432669,F,B,64.820000000,1,26,8058566358218,0,18122,94367619,CLX5
2025-09-24T19:41:09.486227321Z,2025-09-24T19:41:09.485944215Z,160,1,432669,C,B,64.820000000,1,26,8058566358218,128,15883,94367620,CLX5
2025-09-24T19:41:09.486437005Z,2025-09-24T19:41:09.486216381Z,160,1,432669,A,A,64.830000000,1,26,8058566365637,128,18808,94367626,CLX5
2025-09-24T19:41:09.486466502Z,2025-09-24T19:41:09.486216561Z,160,1,432669,A,A,64.830000000,2,26,8058566365638,128,15483,94367627,CLX5
2025-09-24T19:41:09.486496783Z,2025-09-24T19:41:09.486221277Z,160,1,432669,A,A,64.830000000,1,26,8058566365639,128,15894,94367628,CLX5
2025-09-24T19:41:09.498097184Z,2025-09-24T19:41:09.497839915Z,160,1,432669,T,A,64.820000000,1,26,8058566365669,0,18599,94367733,CLX5
2025-09-24T19:41:09.498097184Z,2025-09-24T19:41:09.497839915Z,160,1,432669,F,B,64.820000000,1,26,8058566359580,0,18599,94367733,CLX5
2025-09-24T19:41:09.498108058Z,2025-09-24T19:41:09.497839915Z,160,1,432669,M,B,64.820000000,1,26,8058566359580,128,16000,94367734,CLX5
2025-09-24T19:41:09.498860213Z,2025-09-24T19:41:09.498713187Z,160,1,432669,A,A,64.830000000,1,26,8058566365672,128,17878,94367738,CLX5
2025-09-24T19:41:09.501791900Z,2025-09-24T19:41:09.501637045Z,160,1,432669,A,B,64.820000000,1,26,8058566365673,128,18327,94367741,CLX5
2025-09-24T19:41:09.502111056Z,2025-09-24T19:41:09.501986643Z,160,1,432669,C,A,64.830000000,1,26,8058566365637,128,19258,94367744,CLX5
2025-09-24T19:41:09.502245411Z,2025-09-24T19:41:09.502120825Z,160,1,432669,C,A,64.830000000,2,26,8058566365638,128,19134,94367746,CLX5
2025-09-24T19:41:09.506416722Z,2025-09-24T19:41:09.506057457Z,160,1,432669,T,A,64.820000000,1,26,8058566365679,0,19346,94367758,CLX5
2025-09-24T19:41:09.506416722Z,2025-09-24T19:41:09.506057457Z,160,1,432669,F,B,64.820000000,1,26,8058566359580,0,19346,94367758,CLX5
2025-09-24T19:41:09.506427589Z,2025-09-24T19:41:09.506057457Z,160,1,432669,C,B,64.820000000,1,26,8058566359580,128,15368,94367759,CLX5
2025-09-24T19:41:09.506481139Z,2025-09-24T19:41:09.506350667Z,160,1,432669,A,A,64.830000000,1,26,8058566365680,128,19051,94367760,CLX5
2025-09-24T19:41:09.506611054Z,2025-09-24T19:41:09.506445531Z,160,1,432669,A,A,64.830000000,2,26,8058566365685,128,15510,94367765,CLX5
2025-09-24T19:41:09.506643500Z,2025-09-24T19:41:09.506521423Z,160,1,432669,M,A,64.840000000,4,26,8058566342145,128,14415,94367766,CLX5
2025-09-24T19:41:09.510660936Z,2025-09-24T19:41:09.510378169Z,160,1,432669,T,A,64.820000000,1,26,8058566365688,0,17928,94367773,CLX5
2025-09-24T19:41:09.510660936Z,2025-09-24T19:41:09.510378169Z,160,1,432669,F,B,64.820000000,1,26,8058566359581,0,17928,94367773,CLX5
2025-09-24T19:41:09.510671703Z,2025-09-24T19:41:09.510378169Z,160,1,432669,C,B,64.820000000,1,26,8058566359581,128,15745,94367774,CLX5
2025-09-24T19:41:09.510841023Z,2025-09-24T19:41:09.510661437Z,160,1,432669,C,B,64.820000000,2,26,8058566362456,128,15220,94367776,CLX5
2025-09-24T19:41:09.512110061Z,2025-09-24T19:41:09.511905327Z,160,1,432669,A,B,64.820000000,2,26,8058566365694,128,15231,94367787,CLX5
2025-09-24T19:41:09.512308832Z,2025-09-24T19:41:09.512118957Z,160,1,432669,C,A,64.830000000,2,26,8058566365685,128,15889,94367798,CLX5
2025-09-24T19:41:09.512393407Z,2025-09-24T19:41:09.512211151Z,160,1,432669,A,B,64.790000000,2,26,8058566365698,128,17890,94367800,CLX5
2025-09-24T19:41:09.512829831Z,2025-09-24T19:41:09.512700767Z,160,1,432669,C,A,64.830000000,1,26,8058566365680,128,19275,94367806,CLX5
2025-09-24T19:41:09.515105426Z,2025-09-24T19:41:09.514955649Z,160,1,432669,A,A,64.830000000,1,26,8058566365708,128,15426,94367817,CLX5
2025-09-24T19:41:09.515136398Z,2025-09-24T19:41:09.514956763Z,160,1,432669,A,A,64.830000000,1,26,8058566365709,128,15512,94367818,CLX5
2025-09-24T19:41:09.515359590Z,2025-09-24T19:41:09.515233673Z,160,1,432669,C,A,64.840000000,1,26,8058566365445,128,18416,94367820,CLX5
2025-09-24T19:41:09.516963513Z,2025-09-24T19:41:09.516836399Z,160,1,432669,A,A,64.830000000,1,26,8058566365712,128,18744,94367825,CLX5
2025-09-24T19:41:09.522441945Z,2025-09-24T19:41:09.522202429Z,160,1,432669,T,A,64.820000000,1,26,8058566365721,0,16811,94367854,CLX5
2025-09-24T19:41:09.522441945Z,2025-09-24T19:41:09.522202429Z,160,1,432669,F,B,64.820000000,1,26,8058566357569,0,16811,94367854,CLX5
2025-09-24T19:41:09.522453081Z,2025-09-24T19:41:09.522202429Z,160,1,432669,M,B,64.820000000,3,26,8058566357569,128,15990,94367855,CLX5
2025-09-24T19:41:09.522597319Z,2025-09-24T19:41:09.522395129Z,160,1,432669,A,B,64.810000000,1,26,8058566365723,128,14550,94367861,CLX5
2025-09-24T19:41:09.522682370Z,2025-09-24T19:41:09.522553849Z,160,1,432669,A,B,64.820000000,3,26,8058566365725,128,14619,94367865,CLX5
2025-09-24T19:41:09.527943002Z,2025-09-24T19:41:09.527622157Z,160,1,432669,T,A,64.820000000,1,26,8058566365728,0,17070,94367876,CLX5
2025-09-24T19:41:09.527943002Z,2025-09-24T19:41:09.527622157Z,160,1,432669,F,B,64.820000000,1,26,8058566357569,0,17070,94367876,CLX5
2025-09-24T19:41:09.527953262Z,2025-09-24T19:41:09.527622157Z,160,1,432669,M,B,64.820000000,2,26,8058566357569,128,15518,94367877,CLX5
2025-09-24T19:41:09.528069623Z,2025-09-24T19:41:09.527917883Z,160,1,432669,C,A,64.830000000,1,26,8058566365709,128,15470,94367879,CLX5
2025-09-24T19:41:09.528106301Z,2025-09-24T19:41:09.527966073Z,160,1,432669,A,B,64.820000000,1,26,8058566365730,128,14906,94367880,CLX5
2025-09-24T19:41:09.528278639Z,2025-09-24T19:41:09.528124329Z,160,1,432669,C,A,64.830000000,1,26,8058566365708,128,16443,94367884,CLX5
2025-09-24T19:41:09.536472985Z,2025-09-24T19:41:09.536249199Z,160,1,432669,T,A,64.820000000,1,26,8058566365735,0,17693,94367898,CLX5
2025-09-24T19:41:09.536472985Z,2025-09-24T19:41:09.536249199Z,160,1,432669,F,B,64.820000000,1,26,8058566357569,0,17693,94367898,CLX5
2025-09-24T19:41:09.536483007Z,2025-09-24T19:41:09.536249199Z,160,1,432669,M,B,64.820000000,1,26,8058566357569,128,15508,94367899,CLX5
2025-09-24T19:41:09.536609082Z,2025-09-24T19:41:09.536473331Z,160,1,432669,A,A,64.830000000,1,26,8058566365736,128,19123,94367901,CLX5
2025-09-24T19:41:09.537029049Z,2025-09-24T19:41:09.536646623Z,160,1,432669,T,A,64.820000000,1,26,8058566365741,0,13798,94367908,CLX5
2025-09-24T19:41:09.537029049Z,2025-09-24T19:41:09.536646623Z,160,1,432669,F,B,64.820000000,1,26,8058566357569,0,13798,94367908,CLX5
2025-09-24T19:41:09.537029049Z,2025-09-24T19:41:09.536646623Z,160,1,432669,C,B,64.820000000,1,26,8058566357569,128,13798,94367908,CLX5
2025-09-24T19:41:09.537125382Z,2025-09-24T19:41:09.536995663Z,160,1,432669,A,A,64.830000000,1,26,8058566365742,128,18954,94367910,CLX5
2025-09-24T19:41:09.537231053Z,2025-09-24T19:41:09.537044201Z,160,1,432669,A,A,64.830000000,2,26,8058566365745,128,19734,94367914,CLX5
2025-09-24T19:41:09.544691252Z,2025-09-24T19:41:09.544548303Z,160,1,432669,C,A,64.830000000,2,26,8058566365745,128,18879,94367942,CLX5
2025-09-24T19:41:09.547561686Z,2025-09-24T19:41:09.547441079Z,160,1,432669,C,A,64.830000000,1,26,8058566365742,128,18784,94367947,CLX5
2025-09-24T19:41:09.550285156Z,2025-09-24T19:41:09.550030123Z,160,1,432669,T,A,64.820000000,1,26,8058566365755,0,17851,94367949,CLX5
2025-09-24T19:41:09.550285156Z,2025-09-24T19:41:09.550030123Z,160,1,432669,F,B,64.820000000,1,26,8058566359682,0,17851,94367949,CLX5
2025-09-24T19:41:09.550295423Z,2025-09-24T19:41:09.550030123Z,160,1,432669,C,B,64.820000000,1,26,8058566359682,128,15657,94367950,CLX5
2025-09-24T19:41:09.550999750Z,2025-09-24T19:41:09.550872657Z,160,1,432669,A,A,64.860000000,2,26,8058566365758,128,18366,94367953,CLX5
2025-09-24T19:41:09.551154371Z,2025-09-24T19:41:09.550915299Z,160,1,432669,A,A,64.830000000,2,26,8058566365765,128,16540,94367960,CLX5
2025-09-24T19:41:09.553508674Z,2025-09-24T19:41:09.553191359Z,160,1,432669,T,A,64.820000000,1,26,8058566365771,0,15479,94367973,CLX5
2025-09-24T19:41:09.553508674Z,2025-09-24T19:41:09.553191359Z,160,1,432669,F,B,64.820000000,1,26,8058566361811,0,15479,94367973,CLX5
2025-09-24T19:41:09.553508674Z,2025-09-24T19:41:09.553191359Z,160,1,432669,C,B,64.820000000,1,26,8058566361811,128,15479,94367973,CLX5
2025-09-24T19:41:09.553765511Z,2025-09-24T19:41:09.553495531Z,160,1,432669,A,A,64.830000000,2,26,8058566365775,128,15507,94367979,CLX5
2025-09-24T19:41:09.553929094Z,2025-09-24T19:41:09.553497335Z,160,1,432669,A,A,64.830000000,1,26,8058566365778,128,19044,94367985,CLX5
2025-09-24T19:41:09.553964267Z,2025-09-24T19:41:09.553499199Z,160,1,432669,C,B,64.820000000,1,26,8058566365422,128,14917,94367986,CLX5
2025-09-24T19:41:09.554175716Z,2025-09-24T19:41:09.553524907Z,160,1,432669,C,B,64.820000000,3,26,8058566365725,128,14372,94367996,CLX5
2025-09-24T19:41:09.554374787Z,2025-09-24T19:41:09.554031493Z,160,1,432669,C,A,64.830000000,1,26,8058566365778,128,14887,94368005,CLX5
2025-09-24T19:41:09.554406957Z,2025-09-24T19:41:09.554046065Z,160,1,432669,M,A,64.830000000,1,26,8058566361816,128,16280,94368006,CLX5
2025-09-24T19:41:09.554437821Z,2025-09-24T19:41:09.554200929Z,160,1,432669,A,A,64.830000000,1,26,8058566365783,128,18097,94368007,CLX5
2025-09-24T19:41:09.555420449Z,2025-09-24T19:41:09.555288329Z,160,1,432669,A,B,64.820000000,3,26,8058566365788,128,14988,94368015,CLX5
2025-09-24T19:41:09.555556631Z,2025-09-24T19:41:09.555429231Z,160,1,432669,A,B,64.820000000,1,26,8058566365789,128,20318,94368016,CLX5
2025-09-24T19:41:09.555692414Z,2025-09-24T19:41:09.555565047Z,160,1,432669,A,B,64.820000000,1,26,8058566365790,128,17628,94368019,CLX5
2025-09-24T19:41:09.556099855Z,2025-09-24T19:41:09.555979459Z,160,1,432669,C,A,64.830000000,2,26,8058566365765,128,18622,94368020,CLX5
2025-09-24T19:41:09.561986766Z,2025-09-24T19:41:09.561748441Z,160,1,432669,T,A,64.820000000,1,26,8058566365795,0,17679,94368029,CLX5
2025-09-24T19:41:09.561986766Z,2025-09-24T19:41:09.561748441Z,160,1,432669,F,B,64.820000000,1,26,8058566130074,0,17679,94368029,CLX5
2025-09-24T19:41:09.561997187Z,2025-09-24T19:41:09.561748441Z,160,1,432669,C,B,64.820000000,1,26,8058566130074,128,15692,94368030,CLX5
2025-09-24T19:41:09.575447833Z,2025-09-24T19:41:09.575164271Z,160,1,432669,T,A,64.820000000,1,26,8058566365801,0,17700,94368041,CLX5
2025-09-24T19:41:09.575447833Z,2025-09-24T19:41:09.575164271Z,160,1,432669,F,B,64.820000000,1,26,8058566362025,0,17700,94368041,CLX5
2025-09-24T19:41:09.575457924Z,2025-09-24T19:41:09.575164271Z,160,1,432669,M,B,64.820000000,2,26,8058566362025,128,15336,94368042,CLX5
2025-09-24T19:41:09.575658400Z,2025-09-24T19:41:09.575481595Z,160,1,432669,A,A,64.830000000,3,26,8058566365804,128,14928,94368047,CLX5
2025-09-24T19:41:09.577612911Z,2025-09-24T19:41:09.577474659Z,160,1,432669,A,A,64.830000000,1,26,8058566365806,128,18395,94368054,CLX5
2025-09-24T19:41:09.586562676Z,2025-09-24T19:41:09.586315735Z,160,1,432669,T,A,64.820000000,1,26,8058566365819,0,17762,94368073,CLX5
2025-09-24T19:41:09.586562676Z,2025-09-24T19:41:09.586315735Z,160,1,432669,F,B,64.820000000,1,26,8058566362025,0,17762,94368073,CLX5
2025-09-24T19:41:09.586574656Z,2025-09-24T19:41:09.586315735Z,160,1,432669,M,B,64.820000000,1,26,8058566362025,128,15835,94368074,CLX5
2025-09-24T19:41:09.586809529Z,2025-09-24T19:41:09.586594507Z,160,1,432669,C,B,64.820000000,1,26,8058566362025,128,15089,94368080,CLX5
2025-09-24T19:41:09.612329569Z,2025-09-24T19:41:09.612208537Z,160,1,432669,C,A,64.880000000,2,26,8058566361892,128,17565,94368150,CLX5
2025-09-24T19:41:09.855010420Z,2025-09-24T19:41:09.854880109Z,160,1,432669,M,A,65.990000000,4,26,8058566342145,128,17090,94368398,CLX5
2025-09-24T19:41:09.861323287Z,2025-09-24T19:41:09.861133177Z,160,1,432669,A,B,64.820000000,1,26,8058566365967,128,15041,94368414,CLX5
2025-09-24T19:41:09.861468147Z,2025-09-24T19:41:09.861297329Z,160,1,432669,C,B,64.820000000,1,26,8058566365967,128,15262,94368422,CLX5
2025-09-24T19:41:09.861741894Z,2025-09-24T19:41:09.861526183Z,160,1,432669,A,B,64.820000000,2,26,8058566365972,128,15437,94368435,CLX5
2025-09-24T19:41:09.871273526Z,2025-09-24T19:41:09.870976677Z,160,1,432669,T,A,64.820000000,1,26,8058566365977,0,18229,94368461,CLX5
2025-09-24T19:41:09.871273526Z,2025-09-24T19:41:09.870976677Z,160,1,432669,F,B,64.820000000,1,26,8058566349770,0,18229,94368461,CLX5
2025-09-24T19:41:09.871284316Z,2025-09-24T19:41:09.870976677Z,160,1,432669,C,B,64.820000000,1,26,8058566349770,128,15797,94368462,CLX5
2025-09-24T19:41:09.871559852Z,2025-09-24T19:41:09.871290431Z,160,1,432669,C,B,64.820000000,2,26,8058566365972,128,14956,94368469,CLX5
2025-09-24T19:41:09.871590494Z,2025-09-24T19:41:09.871329499Z,160,1,432669,A,B,64.810000000,1,26,8058566365981,128,14504,94368470,CLX5
2025-09-24T19:41:09.907863344Z,2025-09-24T19:41:09.907395609Z,160,1,432669,A,B,64.820000000,1,26,8058566366017,128,15043,94368542,CLX5
2025-09-24T19:41:09.907904122Z,2025-09-24T19:41:09.907399833Z,160,1,432669,A,B,64.820000000,1,26,8058566366018,128,18156,94368543,CLX5
2025-09-24T19:41:09.908497571Z,2025-09-24T19:41:09.907886837Z,160,1,432669,C,B,64.820000000,1,26,8058566366018,128,18270,94368574,CLX5
2025-09-24T19:41:10.023954172Z,2025-09-24T19:41:10.023809537Z,160,1,432669,A,A,64.860000000,1,26,8058566366055,128,18212,94368652,CLX5
2025-09-24T19:41:10.493086254Z,2025-09-24T19:41:10.492937841Z,160,1,432669,C,A,64.830000000,1,26,8058566365672,128,18506,94368737,CLX5
2025-09-24T19:41:10.600545277Z,2025-09-24T19:41:10.600404831Z,160,1,432669,C,B,64.810000000,1,26,8058566365723,128,18752,94368777,CLX5
2025-09-24T19:41:10.600582638Z,2025-09-24T19:41:10.600411857Z,160,1,432669,A,B,64.820000000,1,26,8058566366123,128,15334,94368778,CLX5
2025-09-24T19:41:10.600709106Z,2025-09-24T19:41:10.600582843Z,160,1,432669,A,B,64.820000000,1,26,8058566366124,128,18374,94368779,CLX5
2025-09-24T19:41:10.600743664Z,2025-09-24T19:41:10.600587549Z,160,1,432669,C,A,64.830000000,2,26,8058566365775,128,14943,94368780,CLX5
2025-09-24T19:41:10.600774851Z,2025-09-24T19:41:10.600598567Z,160,1,432669,C,A,64.830000000,1,26,8058566365783,128,14761,94368781,CLX5
2025-09-24T19:41:10.600979082Z,2025-09-24T19:41:10.600853533Z,160,1,432669,A,B,64.820000000,1,26,8058566366126,128,18215,94368785,CLX5
2025-09-24T19:41:10.664827753Z,2025-09-24T19:41:10.664705749Z,160,1,432669,C,B,63.640000000,2,26,8058562072296,128,20245,94368795,CLX5
2025-09-24T19:41:10.665013269Z,2025-09-24T19:41:10.664916481Z,160,1,432669,C,B,64.100000000,2,26,8058561842297,128,17559,94368796,CLX5
2025-09-24T19:41:10.665260751Z,2025-09-24T19:41:10.665165319Z,160,1,432669,C,B,64.470000000,2,26,8058562455486,128,17487,94368797,CLX5
2025-09-24T19:41:10.665616041Z,2025-09-24T19:41:10.665510923Z,160,1,432669,C,B,64.310000000,2,26,8058563779693,128,17900,94368798,CLX5
2025-09-24T19:41:15.014533399Z,2025-09-24T19:41:15.014374399Z,160,1,432669,C,B,64.800000000,1,26,8058566362411,128,20264,94368920,CLX5
2025-09-24T19:41:15.016734702Z,2025-09-24T19:41:15.016480855Z,160,1,432669,C,B,64.820000000,1,26,8058566366123,128,18473,94368922,CLX5
2025-09-24T19:41:15.213690922Z,2025-09-24T19:41:15.213558699Z,160,1,432669,A,B,64.820000000,1,26,8058566366186,128,19042,94368928,CLX5
2025-09-24T19:41:15.213833478Z,2025-09-24T19:41:15.213703155Z,160,1,432669,C,A,64.830000000,1,26,8058566365736,128,18408,94368929,CLX5
2025-09-24T19:41:15.213968171Z,2025-09-24T19:41:15.213845017Z,160,1,432669,C,B,64.820000000,1,26,8058566366186,128,18579,94368931,CLX5
2025-09-24T19:41:15.724121050Z,2025-09-24T19:41:15.723966569Z,160,1,432669,C,B,64.810000000,1,26,8058566358085,128,20918,94368932,CLX5
2025-09-24T19:41:16.725916799Z,2025-09-24T19:41:16.725715969Z,160,1,432669,M,B,64.800000000,1,26,8058566365346,128,20034,94368979,CLX5
2025-09-24T19:41:18.826989234Z,2025-09-24T19:41:18.826828861Z,160,1,432669,A,B,64.760000000,1,26,8058566366211,128,19010,94368996,CLX5
2025-09-24T19:41:20.024540919Z,2025-09-24T19:41:20.024388381Z,160,1,432669,A,A,64.870000000,1,26,8058566366218,128,18321,94369012,CLX5
2025-09-24T19:41:20.156064418Z,2025-09-24T19:41:20.155903057Z,160,1,432669,C,B,64.820000000,1,26,8058566364191,128,18914,94369013,CLX5
2025-09-24T19:41:21.187998750Z,2025-09-24T19:41:21.187824781Z,160,1,432669,A,B,64.820000000,1,26,8058566366225,128,21792,94369057,CLX5
2025-09-24T19:41:21.976879712Z,2025-09-24T19:41:21.976732807Z,160,1,432669,M,B,64.810000000,1,26,8058566365346,128,23785,94369060,CLX5
2025-09-24T19:41:24.064626858Z,2025-09-24T19:41:24.064456857Z,160,1,432669,C,B,64.810000000,1,26,8058566365346,128,23467,94369065,CLX5
2025-09-24T19:41:26.563463540Z,2025-09-24T19:41:26.563296573Z,160,1,432669,A,A,64.830000000,1,26,8058566366236,128,20841,94369103,CLX5
2025-09-24T19:41:26.581171177Z,2025-09-24T19:41:26.581013513Z,160,1,432669,C,B,64.820000000,1,26,8058566366017,128,21196,94369105,CLX5
2025-09-24T19:41:26.676435356Z,2025-09-24T19:41:26.676281973Z,160,1,432669,A,B,64.820000000,1,26,8058566366238,128,20664,94369107,CLX5
2025-09-24T19:41:29.390093217Z,2025-09-24T19:41:29.389925337Z,160,1,432669,A,B,64.820000000,2,26,8058566366244,128,24989,94369132,CLX5
2025-09-24T19:41:30.124784694Z,2025-09-24T19:41:30.124425921Z,160,1,432669,A,A,64.830000000,2,26,8058566366280,128,17970,94369231,CLX5
2025-09-24T19:41:30.126659906Z,2025-09-24T19:41:30.125778673Z,160,1,432669,C,B,64.820000000,1,26,8058566366126,128,14796,94369335,CLX5
2025-09-24T19:41:31.156805745Z,2025-09-24T19:41:31.156660761Z,160,1,432669,C,A,64.830000000,2,26,8058566366280,128,18343,94369656,CLX5
2025-09-24T19:41:31.456305623Z,2025-09-24T19:41:31.456181289Z,160,1,432669,M,B,64.420000000,1,26,8058566360017,128,18323,94369667,CLX5
2025-09-24T19:41:38.633184209Z,2025-09-24T19:41:38.633050337Z,160,1,432669,A,B,64.510000000,1,26,8058566367011,128,22280,94371112,CLX5
2025-09-24T19:41:43.423485435Z,2025-09-24T19:41:43.423302243Z,160,1,432669,C,B,64.800000000,1,26,8058566357018,128,21286,94371164,CLX5
2025-09-24T19:41:43.569835294Z,2025-09-24T19:41:43.569684207Z,160,1,432669,A,B,64.810000000,1,26,8058566367028,128,23333,94371166,CLX5
2025-09-24T19:41:47.028806315Z,2025-09-24T19:41:47.027727885Z,160,1,432669,T,A,64.820000000,59,26,8058566367036,0,24045,94371200,CLX5
2025-09-24T19:41:47.028806315Z,2025-09-24T19:41:47.027727885Z,160,1,432669,F,B,64.820000000,1,26,8058566362220,0,24045,94371200,CLX5
2025-09-24T19:41:47.028806315Z,2025-09-24T19:41:47.027727885Z,160,1,432669,F,B,64.820000000,1,26,8058566365673,0,24045,94371200,CLX5
2025-09-24T19:41:47.028806315Z,2025-09-24T19:41:47.027727885Z,160,1,432669,F,B,64.820000000,2,26,8058566365694,0,24045,94371200,CLX5
2025-09-24T19:41:47.028806315Z,2025-09-24T19:41:47.027727885Z,160,1,432669,F,B,64.820000000,1,26,8058566365730,0,24045,94371200,CLX5
2025-09-24T19:41:47.028806315Z,2025-09-24T19:41:47.027727885Z,160,1,432669,F,B,64.820000000,3,26,8058566365788,0,24045,94371200,CLX5
2025-09-24T19:41:47.028806315Z,2025-09-24T19:41:47.027727885Z,160,1,432669,F,B,64.820000000,1,26,8058566365789,0,24045,94371200,CLX5
2025-09-24T19:41:47.028806315Z,2025-09-24T19:41:47.027727885Z,160,1,432669,F,B,64.820000000,1,26,8058566365790,0,24045,94371200,CLX5
2025-09-24T19:41:47.028806315Z,2025-09-24T19:41:47.027727885Z,160,1,432669,F,B,64.820000000,1,26,8058566366124,0,24045,94371200,CLX5
2025-09-24T19:41:47.028806315Z,2025-09-24T19:41:47.027727885Z,160,1,432669,F,B,64.820000000,1,26,8058566366225,0,24045,94371200,CLX5
2025-09-24T19:41:47.028806315Z,2025-09-24T19:41:47.027727885Z,160,1,432669,F,B,64.820000000,1,26,8058566366238,0,24045,94371200,CLX5
2025-09-24T19:41:47.028806315Z,2025-09-24T19:41:47.027727885Z,160,1,432669,F,B,64.820000000,2,26,8058566366244,0,24045,94371200,CLX5
2025-09-24T19:41:47.029078434Z,2025-09-24T19:41:47.027727885Z,160,1,432669,C,B,64.820000000,1,26,8058566362220,0,31109,94371201,CLX5
2025-09-24T19:41:47.029078434Z,2025-09-24T19:41:47.027727885Z,160,1,432669,C,B,64.820000000,1,26,8058566365673,0,31109,94371201,CLX5
2025-09-24T19:41:47.029078434Z,2025-09-24T19:41:47.027727885Z,160,1,432669,C,B,64.820000000,2,26,8058566365694,0,31109,94371201,CLX5
2025-09-24T19:41:47.029078434Z,2025-09-24T19:41:47.027727885Z,160,1,432669,C,B,64.820000000,1,26,8058566365730,0,31109,94371201,CLX5
2025-09-24T19:41:47.029078434Z,2025-09-24T19:41:47.027727885Z,160,1,432669,C,B,64.820000000,3,26,8058566365788,0,31109,94371201,CLX5
2025-09-24T19:41:47.029078434Z,2025-09-24T19:41:47.027727885Z,160,1,432669,C,B,64.820000000,1,26,8058566365789,0,31109,94371201,CLX5
2025-09-24T19:41:47.029078434Z,2025-09-24T19:41:47.027727885Z,160,1,432669,C,B,64.820000000,1,26,8058566365790,0,31109,94371201,CLX5
2025-09-24T19:41:47.029078434Z,2025-09-24T19:41:47.027727885Z,160,1,432669,C,B,64.820000000,1,26,8058566366124,0,31109,94371201,CLX5
2025-09-24T19:41:47.029078434Z,2025-09-24T19:41:47.027727885Z,160,1,432669,C,B,64.820000000,1,26,8058566366225,0,31109,94371201,CLX5
2025-09-24T19:41:47.029078434Z,2025-09-24T19:41:47.027727885Z,160,1,432669,C,B,64.820000000,1,26,8058566366238,0,31109,94371201,CLX5
2025-09-24T19:41:47.029078434Z,2025-09-24T19:41:47.027727885Z,160,1,432669,C,B,64.820000000,2,26,8058566366244,0,31109,94371201,CLX5
2025-09-24T19:41:47.029078434Z,2025-09-24T19:41:47.027727885Z,160,1,432669,A,A,64.820000000,1,26,8058566367036,128,31109,94371201,CLX5
2025-09-24T19:41:47.029556673Z,2025-09-24T19:41:47.028635505Z,160,1,432669,A,A,64.830000000,2,26,8058566367038,128,20939,94371211,CLX5
2025-09-24T19:41:47.029754800Z,2025-09-24T19:41:47.028673181Z,160,1,432669,A,A,64.820000000,2,26,8058566367045,128,17871,94371218,CLX5
2025-09-24T19:41:47.029788252Z,2025-09-24T19:41:47.028673509Z,160,1,432669,A,A,64.820000000,1,26,8058566367047,128,19474,94371220,CLX5
2025-09-24T19:41:47.030329832Z,2025-09-24T19:41:47.028699669Z,160,1,432669,A,A,64.820000000,1,26,8058566367054,128,21778,94371237,CLX5
2025-09-24T19:41:47.030419829Z,2025-09-24T19:41:47.028710863Z,160,1,432669,A,A,64.830000000,1,26,8058566367057,128,21977,94371240,CLX5
2025-09-24T19:41:47.030546366Z,2025-09-24T19:41:47.028727411Z,160,1,432669,A,A,64.830000000,2,26,8058566367062,128,15055,94371245,CLX5
2025-09-24T19:41:47.030631225Z,2025-09-24T19:41:47.028806413Z,160,1,432669,A,A,64.830000000,2,26,8058566367066,128,14297,94371249,CLX5
2025-09-24T19:41:47.031147164Z,2025-09-24T19:41:47.028814613Z,160,1,432669,A,B,64.810000000,1,26,8058566367076,128,14967,94371272,CLX5
2025-09-24T19:41:47.031346611Z,2025-09-24T19:41:47.028815805Z,160,1,432669,A,A,64.830000000,1,26,8058566367079,128,14715,94371278,CLX5
2025-09-24T19:41:47.031613277Z,2025-09-24T19:41:47.028825001Z,160,1,432669,A,A,64.860000000,1,26,8058566367087,128,14946,94371289,CLX5
2025-09-24T19:41:47.031657734Z,2025-09-24T19:41:47.028830051Z,160,1,432669,A,A,64.820000000,1,26,8058566367089,128,17806,94371290,CLX5
2025-09-24T19:41:47.031878984Z,2025-09-24T19:41:47.028835755Z,160,1,432669,A,B,64.810000000,1,26,8058566367096,128,15292,94371302,CLX5
2025-09-24T19:41:47.032222891Z,2025-09-24T19:41:47.028864571Z,160,1,432669,A,A,64.830000000,1,26,8058566367102,128,15358,94371322,CLX5
2025-09-24T19:41:47.032359127Z,2025-09-24T19:41:47.028898725Z,160,1,432669,A,A,64.820000000,2,26,8058566367111,128,14755,94371330,CLX5
2025-09-24T19:41:47.032422039Z,2025-09-24T19:41:47.028921305Z,160,1,432669,M,A,64.830000000,1,26,8058566173085,128,14867,94371333,CLX5
2025-09-24T19:41:47.032460314Z,2025-09-24T19:41:47.028978653Z,160,1,432669,A,A,64.820000000,1,26,8058566367116,128,16113,94371336,CLX5
2025-09-24T19:41:47.032655437Z,2025-09-24T19:41:47.029082309Z,160,1,432669,A,A,64.820000000,3,26,8058566367120,128,14689,94371344,CLX5
2025-09-24T19:41:47.032755464Z,2025-09-24T19:41:47.029088895Z,160,1,432669,A,A,64.820000000,1,26,8058566367121,128,19530,94371349,CLX5
2025-09-24T19:41:47.032766683Z,2025-09-24T19:41:47.029091063Z,160,1,432669,T,B,64.820000000,1,26,8058566367122,0,14633,94371350,CLX5
2025-09-24T19:41:47.032766683Z,2025-09-24T19:41:47.029091063Z,160,1,432669,F,A,64.820000000,1,26,8058566367036,0,14633,94371350,CLX5
2025-09-24T19:41:47.032766683Z,2025-09-24T19:41:47.029091063Z,160,1,432669,C,A,64.820000000,1,26,8058566367036,128,14633,94371350,CLX5
2025-09-24T19:41:47.032825126Z,2025-09-24T19:41:47.029117999Z,160,1,432669,A,A,64.820000000,1,26,8058566367123,128,16253,94371353,CLX5
2025-09-24T19:41:47.032850000Z,2025-09-24T19:41:47.029140059Z,160,1,432669,C,A,64.840000000,1,26,8058566364299,128,17939,94371354,CLX5
2025-09-24T19:41:47.033047857Z,2025-09-24T19:41:47.029149371Z,160,1,432669,A,A,64.820000000,2,26,8058566367127,128,16047,94371361,CLX5
2025-09-24T19:41:47.033268046Z,2025-09-24T19:41:47.029215243Z,160,1,432669,A,A,64.820000000,2,26,8058566367135,128,16139,94371370,CLX5
2025-09-24T19:41:47.033364671Z,2025-09-24T19:41:47.029235305Z,160,1,432669,M,A,64.820000000,1,26,8058566366218,128,15683,94371372,CLX5
2025-09-24T19:41:47.033679719Z,2025-09-24T19:41:47.029325311Z,160,1,432669,A,A,64.820000000,1,26,8058566367142,128,15713,94371390,CLX5
2025-09-24T19:41:47.033797854Z,2025-09-24T19:41:47.029405699Z,160,1,432669,C,B,64.810000000,2,26,8058566358051,128,14856,94371395,CLX5
2025-09-24T19:41:47.033920828Z,2025-09-24T19:41:47.029476177Z,160,1,432669,M,A,64.820000000,2,26,8058566362865,128,16158,94371401,CLX5
2025-09-24T19:41:47.033947775Z,2025-09-24T19:41:47.029482513Z,160,1,432669,A,A,64.820000000,2,26,8058566367146,128,15171,94371402,CLX5
2025-09-24T19:41:47.034028734Z,2025-09-24T19:41:47.029539079Z,160,1,432669,A,A,64.820000000,2,26,8058566367149,128,14287,94371406,CLX5
2025-09-24T19:41:47.034178194Z,2025-09-24T19:41:47.029560809Z,160,1,432669,C,A,64.860000000,1,26,8058566354507,128,13657,94371411,CLX5
2025-09-24T19:41:47.034228656Z,2025-09-24T19:41:47.029577089Z,160,1,432669,A,A,64.850000000,1,26,8058566367153,128,14673,94371413,CLX5
2025-09-24T19:41:47.034534811Z,2025-09-24T19:41:47.029605101Z,160,1,432669,A,B,64.810000000,1,26,8058566367158,128,15141,94371425,CLX5
2025-09-24T19:41:47.035929357Z,2025-09-24T19:41:47.029761861Z,160,1,432669,M,A,64.840000000,4,26,8058566342145,128,13499,94371483,CLX5
2025-09-24T19:41:47.036054473Z,2025-09-24T19:41:47.029795633Z,160,1,432669,C,A,64.830000000,1,26,8058566365712,128,15045,94371489,CLX5
2025-09-24T19:41:47.036064818Z,2025-09-24T19:41:47.029795965Z,160,1,432669,T,A,64.810000000,2,26,8058566367183,0,14629,94371490,CLX5
2025-09-24T19:41:47.036064818Z,2025-09-24T19:41:47.029795965Z,160,1,432669,F,B,64.810000000,1,26,8058566356317,0,14629,94371490,CLX5
2025-09-24T19:41:47.036064818Z,2025-09-24T19:41:47.029795965Z,160,1,432669,F,B,64.810000000,1,26,8058566356356,0,14629,94371490,CLX5
