ts_recv,ts_event,rtype,publisher_id,instrument_id,action,side,price,size,channel_id,order_id,flags,ts_in_delta,sequence,symbol
2025-09-24T19:30:00.001385399Z,2025-09-24T19:30:00.000860311Z,160,1,432669,A,A,64.830000000,1,26,8058566314544,128,17528,94225061,CLX5
2025-09-24T19:30:00.001551547Z,2025-09-24T19:30:00.001394777Z,160,1,432669,C,A,64.830000000,1,26,8058566314535,128,17697,94225065,CLX5
2025-09-24T19:30:00.061626992Z,2025-09-24T19:30:00.061472325Z,160,1,432669,C,B,64.790000000,1,26,8058566226379,128,21053,94225124,CLX5
2025-09-24T19:30:00.061653502Z,2025-09-24T19:30:00.061473053Z,160,1,432669,C,B,64.800000000,1,26,8058566253567,128,17668,94225125,CLX5
2025-09-24T19:30:00.093778945Z,2025-09-24T19:30:00.093437495Z,160,1,432669,C,A,64.830000000,1,26,8058566314534,128,18699,94225162,CLX5
2025-09-24T19:30:00.094056547Z,2025-09-24T19:30:00.093784155Z,160,1,432669,A,B,64.820000000,1,26,8058566314579,128,15148,94225181,CLX5
2025-09-24T19:30:00.126096118Z,2025-09-24T19:30:00.125953257Z,160,1,432669,C,A,64.860000000,1,26,8058566175788,128,18262,94225208,CLX5
2025-09-24T19:30:00.398856714Z,2025-09-24T19:30:00.398580505Z,160,1,432669,C,A,64.830000000,2,26,8058566314531,128,16291,94225265,CLX5
2025-09-24T19:30:00.398891680Z,2025-09-24T19:30:00.398599399Z,160,1,432669,C,A,64.830000000,2,26,8058566314530,128,14788,94225266,CLX5
2025-09-24T19:30:00.400126559Z,2025-09-24T19:30:00.399976013Z,160,1,432669,C,A,64.830000000,1,26,8058566314503,128,16415,94225293,CLX5
2025-09-24T19:30:00.400562968Z,2025-09-24T19:30:00.400141223Z,160,1,432669,T,B,64.830000000,6,26,8058566314620,0,18442,94225298,CLX5
2025-09-24T19:30:00.400562968Z,2025-09-24T19:30:00.400141223Z,160,1,432669,F,A,64.830000000,1,26,8058566308744,0,18442,94225298,CLX5
2025-09-24T19:30:00.400562968Z,2025-09-24T19:30:00.400141223Z,160,1,432669,F,A,64.830000000,2,26,8058566308768,0,18442,94225298,CLX5
2025-09-24T19:30:00.400562968Z,2025-09-24T19:30:00.400141223Z,160,1,432669,F,A,64.830000000,1,26,8058566311024,0,18442,94225298,CLX5
2025-09-24T19:30:00.400562968Z,2025-09-24T19:30:00.400141223Z,160,1,432669,F,A,64.830000000,1,26,8058566313468,0,18442,94225298,CLX5
2025-09-24T19:30:00.400562968Z,2025-09-24T19:30:00.400141223Z,160,1,432669,F,A,64.830000000,1,26,8058566314544,0,18442,94225298,CLX5
2025-09-24T19:30:00.400573005Z,2025-09-24T19:30:00.400141223Z,160,1,432669,C,A,64.830000000,1,26,8058566308744,0,15030,94225299,CLX5
2025-09-24T19:30:00.400573005Z,2025-09-24T19:30:00.400141223Z,160,1,432669,C,A,64.830000000,2,26,8058566308768,0,15030,94225299,CLX5
2025-09-24T19:30:00.400573005Z,2025-09-24T19:30:00.400141223Z,160,1,432669,C,A,64.830000000,1,26,8058566311024,0,15030,94225299,CLX5
2025-09-24T19:30:00.400573005Z,2025-09-24T19:30:00.400141223Z,160,1,432669,C,A,64.830000000,1,26,8058566313468,0,15030,94225299,CLX5
2025-09-24T19:30:00.400573005Z,2025-09-24T19:30:00.400141223Z,160,1,432669,C,A,64.830000000,1,26,8058566314544,128,15030,94225299,CLX5
2025-09-24T19:30:00.400605658Z,2025-09-24T19:30:00.400153319Z,160,1,432669,A,B,64.830000000,3,26,8058566314621,128,16510,94225302,CLX5
2025-09-24T19:30:00.400701546Z,2025-09-24T19:30:00.400477971Z,160,1,432669,A,B,64.820000000,2,26,8058566314622,128,15238,94225306,CLX5
2025-09-24T19:30:00.400808615Z,2025-09-24T19:30:00.400484563Z,160,1,432669,A,B,64.820000000,1,26,8058566314624,128,15142,94225309,CLX5
2025-09-24T19:30:00.400880043Z,2025-09-24T19:30:00.400522039Z,160,1,432669,C,A,65.050000000,1,26,8058565884948,128,17488,94225313,CLX5
2025-09-24T19:30:00.400880043Z,2025-09-24T19:30:00.400522481Z,160,1,432669,C,A,65.030000000,1,26,8058565958174,128,17488,94225313,CLX5
2025-09-24T19:30:00.400880043Z,2025-09-24T19:30:00.400522885Z,160,1,432669,C,A,65.020000000,1,26,8058565971028,128,17488,94225313,CLX5
2025-09-24T19:30:00.400893582Z,2025-09-24T19:30:00.400523209Z,160,1,432669,C,A,65.010000000,1,26,8058565978397,128,15461,94225314,CLX5
2025-09-24T19:30:00.400893582Z,2025-09-24T19:30:00.400523537Z,160,1,432669,C,A,65.000000000,1,26,8058565986118,128,15461,94225314,CLX5
2025-09-24T19:30:00.400893582Z,2025-09-24T19:30:00.400523863Z,160,1,432669,C,A,64.990000000,1,26,8058566056746,128,15461,94225314,CLX5
2025-09-24T19:30:00.400893582Z,2025-09-24T19:30:00.400524151Z,160,1,432669,C,A,64.980000000,1,26,8058566058624,128,15461,94225314,CLX5
2025-09-24T19:30:00.400893582Z,2025-09-24T19:30:00.400524479Z,160,1,432669,C,A,64.940000000,1,26,8058566099503,128,15461,94225314,CLX5
2025-09-24T19:30:00.400913756Z,2025-09-24T19:30:00.400524765Z,160,1,432669,C,A,64.930000000,1,26,8058566106311,128,14820,94225315,CLX5
2025-09-24T19:30:00.400937908Z,2025-09-24T19:30:00.400525111Z,160,1,432669,C,A,64.920000000,1,26,8058566107908,128,14663,94225316,CLX5
2025-09-24T19:30:00.400960778Z,2025-09-24T19:30:00.400525379Z,160,1,432669,C,A,64.910000000,1,26,8058566108705,128,15033,94225317,CLX5
2025-09-24T19:30:00.400984984Z,2025-09-24T19:30:00.400525649Z,160,1,432669,C,A,64.890000000,1,26,8058566173002,128,16997,94225318,CLX5
2025-09-24T19:30:00.401005781Z,2025-09-24T19:30:00.400525879Z,160,1,432669,C,A,64.880000000,1,26,8058566173150,128,15056,94225319,CLX5
2025-09-24T19:30:00.401027268Z,2025-09-24T19:30:00.400526025Z,160,1,432669,C,A,64.860000000,1,26,8058566175980,128,14702,94225320,CLX5
2025-09-24T19:30:00.401049677Z,2025-09-24T19:30:00.400526263Z,160,1,432669,C,A,64.850000000,1,26,8058566273445,128,14936,94225321,CLX5
2025-09-24T19:30:00.401075626Z,2025-09-24T19:30:00.400526493Z,160,1,432669,C,A,64.840000000,1,26,8058566274081,128,15684,94225322,CLX5
2025-09-24T19:30:00.401465052Z,2025-09-24T19:30:00.400569155Z,160,1,432669,A,A,64.840000000,1,26,8058566314633,128,18331,94225336,CLX5
2025-09-24T19:30:00.401922441Z,2025-09-24T19:30:00.400587451Z,160,1,432669,A,A,64.840000000,1,26,8058566314639,128,18642,94225356,CLX5
2025-09-24T19:30:00.402015256Z,2025-09-24T19:30:00.400611643Z,160,1,432669,A,A,64.840000000,1,26,8058566314641,128,17860,94225359,CLX5
2025-09-24T19:30:00.402127939Z,2025-09-24T19:30:00.400614887Z,160,1,432669,M,B,64.820000000,1,26,8058566311303,128,18451,94225364,CLX5
2025-09-24T19:30:00.402236259Z,2025-09-24T19:30:00.400626829Z,160,1,432669,C,A,64.850000000,1,26,8058566313455,128,18766,94225370,CLX5
2025-09-24T19:30:00.402268214Z,2025-09-24T19:30:00.400634277Z,160,1,432669,A,B,64.820000000,3,26,8058566314643,128,15218,94225371,CLX5
2025-09-24T19:30:00.402350839Z,2025-09-24T19:30:00.400640921Z,160,1,432669,C,A,64.850000000,1,26,8058566313240,128,18171,94225373,CLX5
2025-09-24T19:30:00.402372680Z,2025-09-24T19:30:00.400642399Z,160,1,432669,C,A,64.850000000,1,26,8058566311241,128,15215,94225374,CLX5
2025-09-24T19:30:00.402428119Z,2025-09-24T19:30:00.400680529Z,160,1,432669,A,B,64.830000000,1,26,8058566314644,128,18845,94225375,CLX5
2025-09-24T19:30:00.402471171Z,2025-09-24T19:30:00.400722919Z,160,1,432669,A,B,64.830000000,1,26,8058566314645,128,20600,94225376,CLX5
2025-09-24T19:30:00.402706535Z,2025-09-24T19:30:00.400985489Z,160,1,432669,M,B,64.820000000,3,26,8058566311409,128,14400,94225382,CLX5
2025-09-24T19:30:00.402850228Z,2025-09-24T19:30:00.401298643Z,160,1,432669,A,B,64.800000000,1,26,8058566314647,128,18131,94225389,CLX5
2025-09-24T19:30:00.403450603Z,2025-09-24T19:30:00.401678269Z,160,1,432669,C,B,64.780000000,1,26,8058566287073,128,14898,94225417,CLX5
2025-09-24T19:30:00.404761142Z,2025-09-24T19:30:00.403177857Z,160,1,432669,M,A,64.850000000,1,26,8058566173085,128,15075,94225489,CLX5
2025-09-24T19:30:00.405524317Z,2025-09-24T19:30:00.404368897Z,160,1,432669,C,A,64.840000000,1,26,8058566314641,128,15342,94225543,CLX5
2025-09-24T19:30:00.405680559Z,2025-09-24T19:30:00.404766703Z,160,1,432669,A,A,64.840000000,1,26,8058566314689,128,15317,94225555,CLX5
2025-09-24T19:30:00.405761671Z,2025-09-24T19:30:00.404808405Z,160,1,432669,A,B,64.830000000,1,26,8058566314690,128,20056,94225558,CLX5
2025-09-24T19:30:00.410572723Z,2025-09-24T19:30:00.410209565Z,160,1,432669,T,A,64.830000000,6,26,8058566314695,0,18162,94225587,CLX5
2025-09-24T19:30:00.410572723Z,2025-09-24T19:30:00.410209565Z,160,1,432669,F,B,64.830000000,3,26,8058566314621,0,18162,94225587,CLX5
2025-09-24T19:30:00.410572723Z,2025-09-24T19:30:00.410209565Z,160,1,432669,F,B,64.830000000,1,26,8058566314644,0,18162,94225587,CLX5
2025-09-24T19:30:00.410572723Z,2025-09-24T19:30:00.410209565Z,160,1,432669,F,B,64.830000000,1,26,8058566314645,0,18162,94225587,CLX5
2025-09-24T19:30:00.410572723Z,2025-09-24T19:30:00.410209565Z,160,1,432669,F,B,64.830000000,1,26,8058566314690,0,18162,94225587,CLX5
2025-09-24T19:30:00.410582130Z,2025-09-24T19:30:00.410209565Z,160,1,432669,C,B,64.830000000,3,26,8058566314621,0,14895,94225588,CLX5
2025-09-24T19:30:00.410582130Z,2025-09-24T19:30:00.410209565Z,160,1,432669,C,B,64.830000000,1,26,8058566314644,0,14895,94225588,CLX5
2025-09-24T19:30:00.410582130Z,2025-09-24T19:30:00.410209565Z,160,1,432669,C,B,64.830000000,1,26,8058566314645,0,14895,94225588,CLX5
2025-09-24T19:30:00.410582130Z,2025-09-24T19:30:00.410209565Z,160,1,432669,C,B,64.830000000,1,26,8058566314690,128,14895,94225588,CLX5
2025-09-24T19:30:00.410667059Z,2025-09-24T19:30:00.410521073Z,160,1,432669,C,A,64.840000000,1,26,8058566314689,128,18762,94225592,CLX5
2025-09-24T19:30:00.410775418Z,2025-09-24T19:30:00.410522069Z,160,1,432669,A,A,64.830000000,2,26,8058566314696,128,17093,94225594,CLX5
2025-09-24T19:30:00.411198418Z,2025-09-24T19:30:00.410581271Z,160,1,432669,C,B,64.810000000,1,26,8058566313373,128,14884,94225615,CLX5
2025-09-24T19:30:00.411555926Z,2025-09-24T19:30:00.410671921Z,160,1,432669,A,A,64.840000000,1,26,8058566314709,128,17862,94225627,CLX5
2025-09-24T19:30:00.411587535Z,2025-09-24T19:30:00.410701201Z,160,1,432669,A,A,64.840000000,1,26,8058566314710,128,18899,94225628,CLX5
2025-09-24T19:30:00.411611681Z,2025-09-24T19:30:00.410721571Z,160,1,432669,C,A,64.840000000,1,26,8058566314709,128,15330,94225629,CLX5
2025-09-24T19:30:00.411636877Z,2025-09-24T19:30:00.410740329Z,160,1,432669,A,A,64.840000000,1,26,8058566314711,128,14986,94225630,CLX5
2025-09-24T19:30:00.411712813Z,2025-09-24T19:30:00.410783373Z,160,1,432669,M,B,63.670000000,4,26,8058566311409,128,18470,94225633,CLX5
2025-09-24T19:30:00.412092400Z,2025-09-24T19:30:00.411223245Z,160,1,432669,C,B,64.810000000,1,26,8058566312861,128,14937,94225651,CLX5
2025-09-24T19:30:00.412209836Z,2025-09-24T19:30:00.411522059Z,160,1,432669,A,A,64.830000000,1,26,8058566314722,128,14588,94225654,CLX5
2025-09-24T19:30:00.412272471Z,2025-09-24T19:30:00.411639307Z,160,1,432669,A,A,64.840000000,1,26,8058566314723,128,15573,94225658,CLX5
2025-09-24T19:30:00.412621055Z,2025-09-24T19:30:00.412135413Z,160,1,432669,A,A,64.830000000,2,26,8058566314726,128,18069,94225670,CLX5
2025-09-24T19:30:00.412753452Z,2025-09-24T19:30:00.412171817Z,160,1,432669,A,A,64.830000000,1,26,8058566314728,128,16937,94225675,CLX5
2025-09-24T19:30:00.457821411Z,2025-09-24T19:30:00.457666111Z,160,1,432669,A,A,64.830000000,1,26,8058566314750,128,19714,94225710,CLX5
2025-09-24T19:30:00.457981884Z,2025-09-24T19:30:00.457862229Z,160,1,432669,C,A,64.840000000,1,26,8058566314723,128,18915,94225711,CLX5
2025-09-24T19:30:00.458005806Z,2025-09-24T19:30:00.457864841Z,160,1,432669,C,A,64.840000000,1,26,8058566314711,128,15373,94225712,CLX5
2025-09-24T19:30:00.458031080Z,2025-09-24T19:30:00.457870581Z,160,1,432669,C,A,64.840000000,1,26,8058566314710,128,15383,94225713,CLX5
2025-09-24T19:30:00.458424889Z,2025-09-24T19:30:00.458311799Z,160,1,432669,C,A,64.840000000,1,26,8058566314639,128,18354,94225718,CLX5
2025-09-24T19:30:00.545948940Z,2025-09-24T19:30:00.545829295Z,160,1,432669,M,B,64.370000000,4,26,8058559498241,128,18301,94225736,CLX5
2025-09-24T19:30:00.567997891Z,2025-09-24T19:30:00.567889583Z,160,1,432669,M,B,64.370000000,4,26,8058559498258,128,18395,94225744,CLX5
2025-09-24T19:30:00.580930439Z,2025-09-24T19:30:00.580800899Z,160,1,432669,C,B,64.800000000,1,26,8058566314647,128,18532,94225748,CLX5
2025-09-24T19:30:00.853371521Z,2025-09-24T19:30:00.853205783Z,160,1,432669,A,A,64.830000000,3,26,8058566314782,128,19780,94225781,CLX5
2025-09-24T19:30:00.855692188Z,2025-09-24T19:30:00.855478847Z,160,1,432669,C,B,64.820000000,1,26,8058566314624,128,18885,94225802,CLX5
2025-09-24T19:30:00.856264057Z,2025-09-24T19:30:00.855602719Z,160,1,432669,A,A,64.830000000,1,26,8058566314797,128,15440,94225826,CLX5
2025-09-24T19:30:00.856634022Z,2025-09-24T19:30:00.855990925Z,160,1,432669,C,A,64.830000000,1,26,8058566314797,128,18727,94225841,CLX5
2025-09-24T19:30:00.856717184Z,2025-09-24T19:30:00.856398255Z,160,1,432669,A,A,64.860000000,1,26,8058566314803,128,13814,94225845,CLX5
2025-09-24T19:30:00.926413892Z,2025-09-24T19:30:00.926263687Z,160,1,432669,A,A,64.830000000,2,26,8058566314816,128,18960,94225877,CLX5
2025-09-24T19:30:00.998211499Z,2025-09-24T19:30:00.998056981Z,160,1,432669,A,A,64.830000000,1,26,8058566314818,128,19138,94225912,CLX5
2025-09-24T19:30:00.998321616Z,2025-09-24T19:30:00.998062607Z,160,1,432669,C,B,64.810000000,2,26,8058566313321,128,19724,94225916,CLX5
2025-09-24T19:30:00.998473342Z,2025-09-24T19:30:00.998063471Z,160,1,432669,C,B,64.820000000,2,26,8058566314622,128,14862,94225922,CLX5
2025-09-24T19:30:00.998556850Z,2025-09-24T19:30:00.998066851Z,160,1,432669,C,B,64.820000000,1,26,8058566314579,128,19848,94225926,CLX5
2025-09-24T19:30:00.998612358Z,2025-09-24T19:30:00.998078869Z,160,1,432669,A,A,64.830000000,1,26,8058566314820,128,15355,94225929,CLX5
2025-09-24T19:30:00.998884200Z,2025-09-24T19:30:00.998224917Z,160,1,432669,C,A,64.830000000,1,26,8058566314820,128,17861,94225941,CLX5
2025-09-24T19:30:00.998916693Z,2025-09-24T19:30:00.998243405Z,160,1,432669,C,B,64.820000000,3,26,8058566314643,128,15839,94225942,CLX5
2025-09-24T19:30:00.999112223Z,2025-09-24T19:30:00.998401741Z,160,1,432669,A,A,64.830000000,1,26,8058566314826,128,15776,94225951,CLX5
2025-09-24T19:30:00.999260332Z,2025-09-24T19:30:00.998452197Z,160,1,432669,C,A,64.830000000,1,26,8058566314826,128,15555,94225957,CLX5
2025-09-24T19:30:00.999533703Z,2025-09-24T19:30:00.998584171Z,160,1,432669,C,B,64.820000000,1,26,8058566314389,128,15194,94225973,CLX5
2025-09-24T19:30:00.999698768Z,2025-09-24T19:30:00.998781769Z,160,1,432669,A,A,64.830000000,1,26,8058566314832,128,18784,94225980,CLX5
2025-09-24T19:30:00.999750175Z,2025-09-24T19:30:00.998789159Z,160,1,432669,A,A,64.830000000,1,26,8058566314833,128,15911,94225982,CLX5
2025-09-24T19:30:01.000038851Z,2025-09-24T19:30:00.998930139Z,160,1,432669,C,B,64.820000000,1,26,8058566313063,128,15482,94225993,CLX5
2025-09-24T19:30:01.000196122Z,2025-09-24T19:30:00.999264531Z,160,1,432669,C,A,64.830000000,1,26,8058566314833,128,15408,94226000,CLX5
2025-09-24T19:30:01.000255308Z,2025-09-24T19:30:00.999538157Z,160,1,432669,A,A,64.830000000,1,26,8058566314835,128,15178,94226003,CLX5
2025-09-24T19:30:01.000614813Z,2025-09-24T19:30:00.999757777Z,160,1,432669,C,B,64.820000000,1,26,8058566314167,128,15276,94226025,CLX5
2025-09-24T19:30:01.000820711Z,2025-09-24T19:30:01.000048607Z,160,1,432669,A,B,64.820000000,1,26,8058566314839,128,15288,94226036,CLX5
2025-09-24T19:30:01.000858149Z,2025-09-24T19:30:01.000204003Z,160,1,432669,A,A,64.830000000,1,26,8058566314841,128,14764,94226039,CLX5
2025-09-24T19:30:01.001023176Z,2025-09-24T19:30:01.000825213Z,160,1,432669,A,B,64.820000000,1,26,8058566314852,128,15160,94226052,CLX5
2025-09-24T19:30:01.004010217Z,2025-09-24T19:30:01.003866837Z,160,1,432669,A,B,64.820000000,1,26,8058566314853,128,19257,94226065,CLX5
2025-09-24T19:30:01.024232803Z,2025-09-24T19:30:01.024092071Z,160,1,432669,C,B,64.820000000,1,26,8058566314852,128,18842,94226082,CLX5
2025-09-24T19:30:01.024357120Z,2025-09-24T19:30:01.024221415Z,160,1,432669,M,A,64.940000000,1,26,8058565075241,128,14894,94226085,CLX5
2025-09-24T19:30:01.026282395Z,2025-09-24T19:30:01.026182495Z,160,1,432669,M,A,64.950000000,1,26,8058565075241,128,18598,94226131,CLX5
2025-09-24T19:30:01.109248303Z,2025-09-24T19:30:01.109114159Z,160,1,432669,A,B,64.790000000,2,26,8058566314879,128,18113,94226160,CLX5
2025-09-24T19:30:01.209269337Z,2025-09-24T19:30:01.209105749Z,160,1,432669,A,B,64.780000000,2,26,8058566314889,128,19915,94226178,CLX5
2025-09-24T19:30:01.428864794Z,2025-09-24T19:30:01.428712711Z,160,1,432669,C,A,64.830000000,1,26,8058566314750,128,19424,94226201,CLX5
2025-09-24T19:30:01.429009201Z,2025-09-24T19:30:01.428872449Z,160,1,432669,A,B,64.820000000,1,26,8058566314905,128,19012,94226202,CLX5
2025-09-24T19:30:01.429054449Z,2025-09-24T19:30:01.428896965Z,160,1,432669,C,B,64.810000000,1,26,8058566305478,128,15269,94226204,CLX5
2025-09-24T19:30:01.520715715Z,2025-09-24T19:30:01.520251767Z,160,1,432669,A,B,64.810000000,2,26,8058566314917,128,14201,94226237,CLX5
2025-09-24T19:30:01.520903297Z,2025-09-24T19:30:01.520252517Z,160,1,432669,A,B,64.820000000,2,26,8058566314921,128,15835,94226243,CLX5
2025-09-24T19:30:01.521293121Z,2025-09-24T19:30:01.520256521Z,160,1,432669,C,A,64.830000000,1,26,8058566314835,128,15656,94226258,CLX5
2025-09-24T19:30:01.521387688Z,2025-09-24T19:30:01.520257787Z,160,1,432669,A,B,64.820000000,1,26,8058566314930,128,15752,94226261,CLX5
2025-09-24T19:30:01.521499799Z,2025-09-24T19:30:01.520260877Z,160,1,432669,C,B,64.780000000,2,26,8058566314889,128,14398,94226265,CLX5
2025-09-24T19:30:01.521560117Z,2025-09-24T19:30:01.520262395Z,160,1,432669,C,A,64.830000000,1,26,8058566314818,128,21996,94226267,CLX5
2025-09-24T19:30:01.521778809Z,2025-09-24T19:30:01.520287201Z,160,1,432669,C,A,64.830000000,1,26,8058566314841,128,15919,94226272,CLX5
2025-09-24T19:30:01.521809067Z,2025-09-24T19:30:01.520306361Z,160,1,432669,C,A,64.830000000,2,26,8058566314816,128,15816,94226273,CLX5
2025-09-24T19:30:01.522596410Z,2025-09-24T19:30:01.520813257Z,160,1,432669,C,A,64.830000000,1,26,8058566314832,128,16313,94226305,CLX5
2025-09-24T19:30:01.522835215Z,2025-09-24T19:30:01.520910061Z,160,1,432669,C,A,64.860000000,1,26,8058566314803,128,14948,94226314,CLX5
2025-09-24T19:30:01.522907879Z,2025-09-24T19:30:01.521103337Z,160,1,432669,A,B,64.820000000,1,26,8058566314950,128,18808,94226317,CLX5
2025-09-24T19:30:01.570813263Z,2025-09-24T19:30:01.570616551Z,160,1,432669,A,B,64.820000000,5,26,8058566314979,128,16695,94226457,CLX5
2025-09-24T19:30:01.571066282Z,2025-09-24T19:30:01.570820793Z,160,1,432669,C,A,64.830000000,1,26,8058566314728,128,19086,94226464,CLX5
2025-09-24T19:30:01.595647910Z,2025-09-24T19:30:01.595505643Z,160,1,432669,C,A,64.830000000,2,26,8058566314726,128,20253,94226492,CLX5
2025-09-24T19:30:01.609258620Z,2025-09-24T19:30:01.609133719Z,160,1,432669,C,B,64.790000000,2,26,8058566314879,128,19097,94226499,CLX5
2025-09-24T19:30:01.709323530Z,2025-09-24T19:30:01.709117843Z,160,1,432669,A,B,64.800000000,2,26,8058566314994,128,18388,94226522,CLX5
2025-09-24T19:30:01.709347959Z,2025-09-24T19:30:01.709121643Z,160,1,432669,A,B,64.790000000,2,26,8058566314995,128,15047,94226523,CLX5
2025-09-24T19:30:01.989441255Z,2025-09-24T19:30:01.989038983Z,160,1,432669,T,B,64.830000000,6,26,8058566315004,0,18677,94226565,CLX5
2025-09-24T19:30:01.989441255Z,2025-09-24T19:30:01.989038983Z,160,1,432669,F,A,64.830000000,2,26,8058566314696,0,18677,94226565,CLX5
2025-09-24T19:30:01.989441255Z,2025-09-24T19:30:01.989038983Z,160,1,432669,F,A,64.830000000,1,26,8058566314722,0,18677,94226565,CLX5
2025-09-24T19:30:01.989441255Z,2025-09-24T19:30:01.989038983Z,160,1,432669,F,A,64.830000000,3,26,8058566314782,0,18677,94226565,CLX5
2025-09-24T19:30:01.989450386Z,2025-09-24T19:30:01.989038983Z,160,1,432669,C,A,64.830000000,2,26,8058566314696,0,14729,94226566,CLX5
2025-09-24T19:30:01.989450386Z,2025-09-24T19:30:01.989038983Z,160,1,432669,C,A,64.830000000,1,26,8058566314722,0,14729,94226566,CLX5
2025-09-24T19:30:01.989450386Z,2025-09-24T19:30:01.989038983Z,160,1,432669,C,A,64.830000000,3,26,8058566314782,128,14729,94226566,CLX5
2025-09-24T19:30:01.992362174Z,2025-09-24T19:30:01.989510781Z,160,1,432669,A,A,64.840000000,1,26,8058566315040,128,17112,94226680,CLX5
2025-09-24T19:30:01.992672755Z,2025-09-24T19:30:01.989676893Z,160,1,432669,A,A,64.840000000,1,26,8058566315047,128,16068,94226693,CLX5
2025-09-24T19:30:01.992723691Z,2025-09-24T19:30:01.989678831Z,160,1,432669,C,A,64.840000000,1,26,8058566314633,128,17600,94226694,CLX5
2025-09-24T19:30:01.992800295Z,2025-09-24T19:30:01.989680309Z,160,1,432669,A,B,64.830000000,1,26,8058566315049,128,15019,94226696,CLX5
2025-09-24T19:30:01.992826344Z,2025-09-24T19:30:01.989682979Z,160,1,432669,C,A,64.840000000,1,26,8058566315040,128,14906,94226699,CLX5
2025-09-24T19:30:01.993106189Z,2025-09-24T19:30:01.990074353Z,160,1,432669,A,B,64.830000000,1,26,8058566315054,128,14792,94226713,CLX5
2025-09-24T19:30:01.993177171Z,2025-09-24T19:30:01.990086833Z,160,1,432669,A,B,64.800000000,1,26,8058566315055,128,15597,94226718,CLX5
2025-09-24T19:30:01.994249919Z,2025-09-24T19:30:01.990581979Z,160,1,432669,A,B,64.830000000,2,26,8058566315063,128,14858,94226792,CLX5
2025-09-24T19:30:01.994657037Z,2025-09-24T19:30:01.990663443Z,160,1,432669,A,B,64.830000000,2,26,8058566315072,128,17830,94226809,CLX5
2025-09-24T19:30:01.996050177Z,2025-09-24T19:30:01.992375909Z,160,1,432669,A,A,64.840000000,1,26,8058566315091,128,15276,94226878,CLX5
2025-09-24T19:30:01.996121390Z,2025-09-24T19:30:01.992439325Z,160,1,432669,C,A,64.840000000,1,26,8058566315047,128,19253,94226880,CLX5
2025-09-24T19:30:01.996188994Z,2025-09-24T19:30:01.992828837Z,160,1,432669,A,A,64.840000000,1,26,8058566315093,128,15261,94226882,CLX5
2025-09-24T19:30:01.996227146Z,2025-09-24T19:30:01.993073167Z,160,1,432669,M,B,64.820000000,3,26,8058566311409,128,16564,94226883,CLX5
2025-09-24T19:30:01.996380270Z,2025-09-24T19:30:01.993193947Z,160,1,432669,A,B,64.830000000,1,26,8058566315094,128,17064,94226893,CLX5
2025-09-24T19:30:01.997163765Z,2025-09-24T19:30:01.993741199Z,160,1,432669,M,B,64.820000000,4,26,8058566314979,128,19057,94226951,CLX5
2025-09-24T19:30:01.997278943Z,2025-09-24T19:30:01.994019741Z,160,1,432669,C,B,64.830000000,2,26,8058566315072,128,20656,94226958,CLX5
2025-09-24T19:30:01.997515414Z,2025-09-24T19:30:01.994179823Z,160,1,432669,C,B,64.830000000,2,26,8058566315063,128,15272,94226971,CLX5
2025-09-24T19:30:01.997691108Z,2025-09-24T19:30:01.994252301Z,160,1,432669,C,B,64.830000000,1,26,8058566315054,128,17072,94226979,CLX5
2025-09-24T19:30:01.998241527Z,2025-09-24T19:30:01.994868461Z,160,1,432669,M,B,64.820000000,2,26,8058566314979,128,15543,94227013,CLX5
2025-09-24T19:30:01.998318338Z,2025-09-24T19:30:01.995116741Z,160,1,432669,A,A,64.840000000,1,26,8058566315118,128,19024,94227015,CLX5
2025-09-24T19:30:01.998390012Z,2025-09-24T19:30:01.995276709Z,160,1,432669,C,B,64.820000000,2,26,8058566314979,128,15628,94227017,CLX5
2025-09-24T19:30:01.998510689Z,2025-09-24T19:30:01.996057499Z,160,1,432669,T,A,64.830000000,2,26,8058566315122,0,14803,94227026,CLX5
2025-09-24T19:30:01.998510689Z,2025-09-24T19:30:01.996057499Z,160,1,432669,F,B,64.830000000,1,26,8058566315049,0,14803,94227026,CLX5
2025-09-24T19:30:01.998510689Z,2025-09-24T19:30:01.996057499Z,160,1,432669,F,B,64.830000000,1,26,8058566315094,0,14803,94227026,CLX5
2025-09-24T19:30:01.998562212Z,2025-09-24T19:30:01.996057499Z,160,1,432669,C,B,64.830000000,1,26,8058566315049,0,18792,94227027,CLX5
2025-09-24T19:30:01.998562212Z,2025-09-24T19:30:01.996057499Z,160,1,432669,C,B,64.830000000,1,26,8058566315094,128,18792,94227027,CLX5
2025-09-24T19:30:01.998583515Z,2025-09-24T19:30:01.996058557Z,160,1,432669,A,A,64.830000000,1,26,8058566315123,128,18920,94227029,CLX5
2025-09-24T19:30:01.999064158Z,2025-09-24T19:30:01.996884869Z,160,1,432669,M,A,64.850000000,1,26,8058566305433,128,15606,94227052,CLX5
2025-09-24T19:30:01.999496296Z,2025-09-24T19:30:01.998271511Z,160,1,432669,A,B,64.820000000,1,26,8058566315140,128,16846,94227072,CLX5
2025-09-24T19:30:01.999852921Z,2025-09-24T19:30:01.998525359Z,160,1,432669,C,B,64.820000000,1,26,8058566314853,128,15172,94227088,CLX5
2025-09-24T19:30:01.999903684Z,2025-09-24T19:30:01.998569921Z,160,1,432669,A,A,64.830000000,1,26,8058566315148,128,14810,94227089,CLX5
2025-09-24T19:30:01.999938480Z,2025-09-24T19:30:01.998586701Z,160,1,432669,C,B,64.820000000,1,26,8058566314930,128,15269,94227092,CLX5
2025-09-24T19:30:02.000081428Z,2025-09-24T19:30:01.998588265Z,160,1,432669,A,A,64.830000000,2,26,8058566315151,128,14056,94227097,CLX5
2025-09-24T19:30:02.000114228Z,2025-09-24T19:30:01.998588583Z,160,1,432669,C,B,64.820000000,1,26,8058566315140,128,15152,94227099,CLX5
2025-09-24T19:30:02.000186485Z,2025-09-24T19:30:01.998606747Z,160,1,432669,A,A,64.830000000,1,26,8058566315154,128,17019,94227102,CLX5
2025-09-24T19:30:02.000252384Z,2025-09-24T19:30:01.998641785Z,160,1,432669,A,A,64.830000000,2,26,8058566315156,128,20083,94227104,CLX5
2025-09-24T19:30:02.000280775Z,2025-09-24T19:30:01.998641959Z,160,1,432669,A,A,64.830000000,1,26,8058566315157,128,16745,94227105,CLX5
2025-09-24T19:30:02.000376179Z,2025-09-24T19:30:01.998716489Z,160,1,432669,M,B,63.670000000,4,26,8058566311409,128,15950,94227109,CLX5
2025-09-24T19:30:02.001171923Z,2025-09-24T19:30:02.000081375Z,160,1,432669,C,B,64.820000000,2,26,8058566314921,128,15624,94227145,CLX5
2025-09-24T19:30:02.007125607Z,2025-09-24T19:30:02.006982915Z,160,1,432669,M,A,64.840000000,1,26,8058566305433,128,18580,94227215,CLX5
2025-09-24T19:30:02.048525483Z,2025-09-24T19:30:02.048374791Z,160,1,432669,A,B,64.820000000,5,26,8058566315208,128,18773,94227254,CLX5
2025-09-24T19:30:02.048662303Z,2025-09-24T19:30:02.048525369Z,160,1,432669,C,A,64.830000000,2,26,8058566315156,128,19932,94227255,CLX5
2025-09-24T19:30:02.048748653Z,2025-09-24T19:30:02.048525667Z,160,1,432669,C,A,64.830000000,1,26,8058566315157,128,15444,94227258,CLX5
2025-09-24T19:30:02.048780830Z,2025-09-24T19:30:02.048530765Z,160,1,432669,C,A,64.840000000,1,26,8058566315118,128,18744,94227259,CLX5
2025-09-24T19:30:02.170939409Z,2025-09-24T19:30:02.170807581Z,160,1,432669,C,B,64.800000000,1,26,8058566315055,128,19416,94227364,CLX5
2025-09-24T19:30:04.438111442Z,2025-09-24T19:30:04.437985893Z,160,1,432669,C,A,65.060000000,1,26,8058566310050,128,23267,94227584,CLX5
2025-09-24T19:30:04.547708351Z,2025-09-24T19:30:04.547585373Z,160,1,432669,A,A,65.050000000,1,26,8058566315368,128,24132,94227586,CLX5
2025-09-24T19:30:05.511687003Z,2025-09-24T19:30:05.511573591Z,160,1,432669,C,A,64.970000000,1,26,8058566060211,128,20633,94227591,CLX5
2025-09-24T19:30:11.345277122Z,2025-09-24T19:30:11.344915535Z,160,1,432669,T,A,64.820000000,1,26,8058566315605,0,18462,94228164,CLX5
2025-09-24T19:30:11.345277122Z,2025-09-24T19:30:11.344915535Z,160,1,432669,F,B,64.820000000,1,26,8058566312886,0,18462,94228164,CLX5
2025-09-24T19:30:11.345287412Z,2025-09-24T19:30:11.344915535Z,160,1,432669,M,B,64.820000000,2,26,8058566312886,128,15642,94228165,CLX5
2025-09-24T19:30:11.345660272Z,2025-09-24T19:30:11.345289727Z,160,1,432669,T,B,64.830000000,5,26,8058566315609,0,17271,94228169,CLX5
2025-09-24T19:30:11.345660272Z,2025-09-24T19:30:11.345289727Z,160,1,432669,F,A,64.830000000,1,26,8058566315123,0,17271,94228169,CLX5
2025-09-24T19:30:11.345660272Z,2025-09-24T19:30:11.345289727Z,160,1,432669,F,A,64.830000000,1,26,8058566315148,0,17271,94228169,CLX5
2025-09-24T19:30:11.345660272Z,2025-09-24T19:30:11.345289727Z,160,1,432669,F,A,64.830000000,2,26,8058566315151,0,17271,94228169,CLX5
2025-09-24T19:30:11.345660272Z,2025-09-24T19:30:11.345289727Z,160,1,432669,F,A,64.830000000,1,26,8058566315154,0,17271,94228169,CLX5
2025-09-24T19:30:11.345684401Z,2025-09-24T19:30:11.345289727Z,160,1,432669,C,A,64.830000000,1,26,8058566315123,0,15268,94228170,CLX5
2025-09-24T19:30:11.345684401Z,2025-09-24T19:30:11.345289727Z,160,1,432669,C,A,64.830000000,1,26,8058566315148,0,15268,94228170,CLX5
2025-09-24T19:30:11.345684401Z,2025-09-24T19:30:11.345289727Z,160,1,432669,C,A,64.830000000,2,26,8058566315151,0,15268,94228170,CLX5
2025-09-24T19:30:11.345684401Z,2025-09-24T19:30:11.345289727Z,160,1,432669,C,A,64.830000000,1,26,8058566315154,128,15268,94228170,CLX5
2025-09-24T19:30:11.345716202Z,2025-09-24T19:30:11.345300899Z,160,1,432669,A,B,64.830000000,2,26,8058566315610,128,17521,94228173,CLX5
2025-09-24T19:30:11.346033623Z,2025-09-24T19:30:11.345639399Z,160,1,432669,A,B,64.820000000,2,26,8058566315615,128,15632,94228190,CLX5
2025-09-24T19:30:11.346396451Z,2025-09-24T19:30:11.345665491Z,160,1,432669,A,B,64.820000000,1,26,8058566315620,128,15812,94228202,CLX5
2025-09-24T19:30:11.346431050Z,2025-09-24T19:30:11.345669083Z,160,1,432669,A,A,64.840000000,1,26,8058566315621,128,15744,94228203,CLX5
2025-09-24T19:30:11.346694322Z,2025-09-24T19:30:11.345712415Z,160,1,432669,A,B,64.830000000,2,26,8058566315625,128,14878,94228214,CLX5
2025-09-24T19:30:11.346882648Z,2025-09-24T19:30:11.345726027Z,160,1,432669,A,B,64.830000000,1,26,8058566315626,128,17306,94228222,CLX5
2025-09-24T19:30:11.346985494Z,2025-09-24T19:30:11.345763599Z,160,1,432669,A,B,64.820000000,3,26,8058566315628,128,15081,94228230,CLX5
2025-09-24T19:30:11.347144285Z,2025-09-24T19:30:11.345784681Z,160,1,432669,A,B,64.830000000,2,26,8058566315630,128,17189,94228236,CLX5
2025-09-24T19:30:11.347180502Z,2025-09-24T19:30:11.345784857Z,160,1,432669,A,B,64.830000000,1,26,8058566315631,128,19409,94228237,CLX5
2025-09-24T19:30:11.347281520Z,2025-09-24T19:30:11.345818393Z,160,1,432669,A,B,64.830000000,1,26,8058566315632,128,19333,94228241,CLX5
2025-09-24T19:30:11.347350275Z,2025-09-24T19:30:11.345942247Z,160,1,432669,C,A,64.840000000,1,26,8058566308520,128,15090,94228246,CLX5
2025-09-24T19:30:11.348381768Z,2025-09-24T19:30:11.347058333Z,160,1,432669,M,B,64.820000000,3,26,8058566311409,128,15672,94228289,CLX5
2025-09-24T19:30:11.349133254Z,2025-09-24T19:30:11.347763287Z,160,1,432669,A,B,64.830000000,1,26,8058566315658,128,19582,94228324,CLX5
2025-09-24T19:30:11.349159573Z,2025-09-24T19:30:11.347779357Z,160,1,432669,M,B,64.820000000,4,26,8058566315208,128,15345,94228325,CLX5
2025-09-24T19:30:11.349186858Z,2025-09-24T19:30:11.347812149Z,160,1,432669,M,B,64.820000000,3,26,8058566315208,128,14285,94228326,CLX5
2025-09-24T19:30:11.349239886Z,2025-09-24T19:30:11.347900715Z,160,1,432669,M,B,64.820000000,2,26,8058566315208,128,18396,94228328,CLX5
2025-09-24T19:30:11.350002109Z,2025-09-24T19:30:11.349191685Z,160,1,432669,A,B,64.820000000,1,26,8058566315665,128,17625,94228369,CLX5
2025-09-24T19:30:11.350110207Z,2025-09-24T19:30:11.349237975Z,160,1,432669,A,B,64.820000000,1,26,8058566315666,128,19059,94228375,CLX5
2025-09-24T19:30:11.350135611Z,2025-09-24T19:30:11.349265735Z,160,1,432669,A,B,64.820000000,1,26,8058566315667,128,15187,94228376,CLX5
2025-09-24T19:30:11.350267231Z,2025-09-24T19:30:11.349752685Z,160,1,432669,M,B,64.820000000,1,26,8058566315208,128,15202,94228382,CLX5
2025-09-24T19:30:11.350795396Z,2025-09-24T19:30:11.350671805Z,160,1,432669,A,B,64.800000000,1,26,8058566315674,128,18315,94228400,CLX5
2025-09-24T19:30:11.352251540Z,2025-09-24T19:30:11.351820395Z,160,1,432669,A,B,64.830000000,1,26,8058566315677,128,15710,94228416,CLX5
2025-09-24T19:30:11.352994249Z,2025-09-24T19:30:11.352872567Z,160,1,432669,C,B,64.820000000,1,26,8058566315208,128,18406,94228440,CLX5
2025-09-24T19:30:11.358358241Z,2025-09-24T19:30:11.358220549Z,160,1,432669,M,A,64.850000000,1,26,8058566305433,128,18947,94228454,CLX5
2025-09-24T19:30:11.358495928Z,2025-09-24T19:30:11.358364387Z,160,1,432669,C,A,64.840000000,1,26,8058566315621,128,14463,94228458,CLX5
2025-09-24T19:30:11.358533366Z,2025-09-24T19:30:11.358370973Z,160,1,432669,C,B,64.830000000,1,26,8058566315658,128,14987,94228460,CLX5
2025-09-24T19:30:11.375559025Z,2025-09-24T19:30:11.375423527Z,160,1,432669,A,A,64.850000000,1,26,8058566315687,128,21093,94228485,CLX5
2025-09-24T19:30:11.375701812Z,2025-09-24T19:30:11.375575659Z,160,1,432669,C,B,64.830000000,1,26,8058566315677,128,19595,94228486,CLX5
2025-09-24T19:30:11.375893679Z,2025-09-24T19:30:11.375730733Z,160,1,432669,C,B,64.820000000,1,26,8058566315667,128,15286,94228488,CLX5
2025-09-24T19:30:11.375994550Z,2025-09-24T19:30:11.375743711Z,160,1,432669,C,B,64.820000000,1,26,8058566315666,128,15363,94228491,CLX5
2025-09-24T19:30:11.376022642Z,2025-09-24T19:30:11.375747841Z,160,1,432669,C,B,64.820000000,1,26,8058566315665,128,14511,94228492,CLX5
2025-09-24T19:30:11.378293745Z,2025-09-24T19:30:11.378000477Z,160,1,432669,T,A,64.830000000,1,26,8058566315688,0,18968,94228493,CLX5
2025-09-24T19:30:11.378293745Z,2025-09-24T19:30:11.378000477Z,160,1,432669,F,B,64.830000000,1,26,8058566315610,0,18968,94228493,CLX5
2025-09-24T19:30:11.378304273Z,2025-09-24T19:30:11.378000477Z,160,1,432669,M,B,64.830000000,1,26,8058566315610,128,16221,94228494,CLX5
2025-09-24T19:30:11.378446769Z,2025-09-24T19:30:11.378298849Z,160,1,432669,A,A,64.840000000,1,26,8058566315689,128,15411,94228496,CLX5
2025-09-24T19:30:11.441051037Z,2025-09-24T19:30:11.440910343Z,160,1,432669,M,A,64.840000000,1,26,8058566305433,128,19405,94228532,CLX5
2025-09-24T19:30:11.441240439Z,2025-09-24T19:30:11.441056851Z,160,1,432669,C,A,64.840000000,1,26,8058566315689,128,15136,94228536,CLX5
2025-09-24T19:30:12.379867692Z,2025-09-24T19:30:12.379732257Z,160,1,432669,A,A,64.840000000,1,26,8058566315833,128,18608,94228933,CLX5
2025-09-24T19:30:12.380047994Z,2025-09-24T19:30:12.379874253Z,160,1,432669,C,B,64.830000000,1,26,8058566315631,128,16187,94228936,CLX5
2025-09-24T19:30:12.380081715Z,2025-09-24T19:30:12.379906393Z,160,1,432669,A,A,64.840000000,1,26,8058566315834,128,18184,94228937,CLX5
2025-09-24T19:30:12.380188983Z,2025-09-24T19:30:12.380046181Z,160,1,432669,C,B,64.830000000,2,26,8058566315625,128,20467,94228938,CLX5
2025-09-24T19:30:12.380231191Z,2025-09-24T19:30:12.380046489Z,160,1,432669,C,B,64.830000000,2,26,8058566315630,128,13977,94228939,CLX5
2025-09-24T19:30:12.380262685Z,2025-09-24T19:30:12.380081259Z,160,1,432669,A,A,64.840000000,1,26,8058566315835,128,15752,94228941,CLX5
2025-09-24T19:30:12.400171074Z,2025-09-24T19:30:12.400009653Z,160,1,432669,C,B,64.830000000,1,26,8058566315632,128,19615,94228953,CLX5
2025-09-24T19:30:12.418079319Z,2025-09-24T19:30:12.417761345Z,160,1,432669,T,A,64.830000000,2,26,8058566315841,0,19067,94228966,CLX5
2025-09-24T19:30:12.418079319Z,2025-09-24T19:30:12.417761345Z,160,1,432669,F,B,64.830000000,1,26,8058566315610,0,19067,94228966,CLX5
2025-09-24T19:30:12.418079319Z,2025-09-24T19:30:12.417761345Z,160,1,432669,F,B,64.830000000,1,26,8058566315626,0,19067,94228966,CLX5
2025-09-24T19:30:12.418089518Z,2025-09-24T19:30:12.417761345Z,160,1,432669,C,B,64.830000000,1,26,8058566315610,0,15132,94228967,CLX5
2025-09-24T19:30:12.418089518Z,2025-09-24T19:30:12.417761345Z,160,1,432669,C,B,64.830000000,1,26,8058566315626,128,15132,94228967,CLX5
2025-09-24T19:30:12.418942921Z,2025-09-24T19:30:12.418339603Z,160,1,432669,M,B,63.670000000,4,26,8058566311409,128,15700,94228998,CLX5
2025-09-24T19:30:12.419105152Z,2025-09-24T19:30:12.418517177Z,160,1,432669,C,B,64.800000000,1,26,8058566315674,128,17349,94229007,CLX5
2025-09-24T19:30:12.426705611Z,2025-09-24T19:30:12.426480909Z,160,1,432669,A,A,64.830000000,3,26,8058566315883,128,18449,94229113,CLX5
2025-09-24T19:30:12.426835390Z,2025-09-24T19:30:12.426705675Z,160,1,432669,A,A,64.840000000,1,26,8058566315884,128,18319,94229117,CLX5
2025-09-24T19:30:12.427053743Z,2025-09-24T19:30:12.426715503Z,160,1,432669,A,A,64.830000000,1,26,8058566315889,128,22674,94229124,CLX5
2025-09-24T19:30:12.437677299Z,2025-09-24T19:30:12.437533037Z,160,1,432669,M,B,64.820000000,1,26,8058566314284,128,18058,94229185,CLX5
2025-09-24T19:30:12.437842695Z,2025-09-24T19:30:12.437720383Z,160,1,432669,C,A,64.840000000,1,26,8058566315835,128,15091,94229187,CLX5
2025-09-24T19:30:12.437872638Z,2025-09-24T19:30:12.437731729Z,160,1,432669,C,A,64.840000000,1,26,8058566315834,128,17250,94229188,CLX5
2025-09-24T19:30:12.437897051Z,2025-09-24T19:30:12.437735837Z,160,1,432669,C,A,64.840000000,1,26,8058566315833,128,15089,94229189,CLX5
2025-09-24T19:30:13.345265781Z,2025-09-24T19:30:13.344934115Z,160,1,432669,T,A,64.820000000,1,26,8058566316000,0,19190,94229380,CLX5
2025-09-24T19:30:13.345265781Z,2025-09-24T19:30:13.344934115Z,160,1,432669,F,B,64.820000000,1,26,8058566312886,0,19190,94229380,CLX5
2025-09-24T19:30:13.345276149Z,2025-09-24T19:30:13.344934115Z,160,1,432669,M,B,64.820000000,1,26,8058566312886,128,15553,94229381,CLX5
2025-09-24T19:30:16.286192487Z,2025-09-24T19:30:16.285865443Z,160,1,432669,T,B,64.830000000,2,26,8058566316025,0,30218,94229430,CLX5
2025-09-24T19:30:16.286192487Z,2025-09-24T19:30:16.285865443Z,160,1,432669,F,A,64.830000000,2,26,8058566315883,0,30218,94229430,CLX5
2025-09-24T19:30:16.286204130Z,2025-09-24T19:30:16.285865443Z,160,1,432669,M,A,64.830000000,1,26,8058566315883,128,17154,94229431,CLX5
2025-09-24T19:30:16.286619434Z,2025-09-24T19:30:16.286205099Z,160,1,432669,T,B,64.830000000,2,26,8058566316030,0,18009,94229442,CLX5
2025-09-24T19:30:16.286619434Z,2025-09-24T19:30:16.286205099Z,160,1,432669,F,A,64.830000000,1,26,8058566315883,0,18009,94229442,CLX5
2025-09-24T19:30:16.286619434Z,2025-09-24T19:30:16.286205099Z,160,1,432669,F,A,64.830000000,1,26,8058566315889,0,18009,94229442,CLX5
2025-09-24T19:30:16.286619434Z,2025-09-24T19:30:16.286205099Z,160,1,432669,C,A,64.830000000,1,26,8058566315883,0,18009,94229442,CLX5
2025-09-24T19:30:16.286619434Z,2025-09-24T19:30:16.286205099Z,160,1,432669,C,A,64.830000000,1,26,8058566315889,128,18009,94229442,CLX5
2025-09-24T19:30:16.286843394Z,2025-09-24T19:30:16.286627765Z,160,1,432669,A,A,64.840000000,1,26,8058566316031,128,17653,94229451,CLX5
2025-09-24T19:30:16.287127739Z,2025-09-24T19:30:16.286665111Z,160,1,432669,A,B,64.820000000,1,26,8058566316035,128,17971,94229464,CLX5
2025-09-24T19:30:16.741405877Z,2025-09-24T19:30:16.741276793Z,160,1,432669,M,A,64.980000000,1,26,8058566157942,128,18144,94229534,CLX5
2025-09-24T19:30:17.199222273Z,2025-09-24T19:30:17.199058545Z,160,1,432669,A,A,64.840000000,1,26,8058566316078,128,19354,94229566,CLX5
2025-09-24T19:30:18.148831343Z,2025-09-24T19:30:18.148699065Z,160,1,432669,C,A,64.850000000,1,26,8058566315687,128,17877,94229661,CLX5
2025-09-24T19:30:18.162159015Z,2025-09-24T19:30:18.162002195Z,160,1,432669,A,A,64.840000000,1,26,8058566316117,128,18580,94229678,CLX5
2025-09-24T19:30:18.162293031Z,2025-09-24T19:30:18.162164485Z,160,1,432669,C,A,64.840000000,1,26,8058566316031,128,18707,94229679,CLX5
2025-09-24T19:30:19.837705976Z,2025-09-24T19:30:19.837502365Z,160,1,432669,A,A,64.830000000,2,26,8058566316187,128,18053,94229828,CLX5
2025-09-24T19:30:19.838012030Z,2025-09-24T19:30:19.837721525Z,160,1,432669,A,A,64.830000000,1,26,8058566316189,128,14899,94229837,CLX5
2025-09-24T19:30:19.838162443Z,2025-09-24T19:30:19.837866499Z,160,1,432669,C,A,64.840000000,1,26,8058566316117,128,15724,94229847,CLX5
2025-09-24T19:30:19.838345947Z,2025-09-24T19:30:19.838199851Z,160,1,432669,A,A,64.840000000,1,26,8058566316194,128,15108,94229852,CLX5
2025-09-24T19:30:19.888499022Z,2025-09-24T19:30:19.888333355Z,160,1,432669,A,A,64.830000000,1,26,8058566316199,128,18299,94229864,CLX5
2025-09-24T19:30:19.888871390Z,2025-09-24T19:30:19.888509371Z,160,1,432669,T,B,64.830000000,4,26,8058566316200,0,17487,94229866,CLX5
2025-09-24T19:30:19.888871390Z,2025-09-24T19:30:19.888509371Z,160,1,432669,F,A,64.830000000,2,26,8058566316187,0,17487,94229866,CLX5
2025-09-24T19:30:19.888871390Z,2025-09-24T19:30:19.888509371Z,160,1,432669,F,A,64.830000000,1,26,8058566316189,0,17487,94229866,CLX5
2025-09-24T19:30:19.888871390Z,2025-09-24T19:30:19.888509371Z,160,1,432669,F,A,64.830000000,1,26,8058566316199,0,17487,94229866,CLX5
2025-09-24T19:30:19.888879914Z,2025-09-24T19:30:19.888509371Z,160,1,432669,C,A,64.830000000,2,26,8058566316187,0,14732,94229867,CLX5
2025-09-24T19:30:19.888879914Z,2025-09-24T19:30:19.888509371Z,160,1,432669,C,A,64.830000000,1,26,8058566316189,0,14732,94229867,CLX5
2025-09-24T19:30:19.888879914Z,2025-09-24T19:30:19.888509371Z,160,1,432669,C,A,64.830000000,1,26,8058566316199,128,14732,94229867,CLX5
2025-09-24T19:30:19.888914465Z,2025-09-24T19:30:19.888519355Z,160,1,432669,A,B,64.830000000,1,26,8058566316201,128,18306,94229870,CLX5
2025-09-24T19:30:19.888935653Z,2025-09-24T19:30:19.888537633Z,160,1,432669,C,A,64.840000000,1,26,8058566316194,128,19329,94229872,CLX5
2025-09-24T19:30:19.889228268Z,2025-09-24T19:30:19.888878841Z,160,1,432669,A,A,64.840000000,1,26,8058566316205,128,16034,94229884,CLX5
2025-09-24T19:30:19.889947294Z,2025-09-24T19:30:19.889468581Z,160,1,432669,A,B,64.800000000,1,26,8058566316211,128,15339,94229921,CLX5
2025-09-24T19:30:21.276130293Z,2025-09-24T19:30:21.275960883Z,160,1,432669,M,B,64.820000000,3,26,8058566311409,128,21306,94230276,CLX5
2025-09-24T19:30:21.332066218Z,2025-09-24T19:30:21.331750457Z,160,1,432669,T,A,64.830000000,1,26,8058566316343,0,19092,94230277,CLX5
2025-09-24T19:30:21.332066218Z,2025-09-24T19:30:21.331750457Z,160,1,432669,F,B,64.830000000,1,26,8058566316201,0,19092,94230277,CLX5
2025-09-24T19:30:21.332074243Z,2025-09-24T19:30:21.331750457Z,160,1,432669,C,B,64.830000000,1,26,8058566316201,128,14871,94230278,CLX5
2025-09-24T19:30:21.332352344Z,2025-09-24T19:30:21.332074441Z,160,1,432669,C,A,64.840000000,1,26,8058566316205,128,18575,94230287,CLX5
2025-09-24T19:30:21.332531540Z,2025-09-24T19:30:21.332281715Z,160,1,432669,M,B,63.670000000,4,26,8058566311409,128,14584,94230295,CLX5
2025-09-24T19:30:21.332569968Z,2025-09-24T19:30:21.332291967Z,160,1,432669,A,A,64.840000000,1,26,8058566316347,128,18603,94230296,CLX5
2025-09-24T19:30:21.332596325Z,2025-09-24T19:30:21.332320613Z,160,1,432669,A,A,64.840000000,1,26,8058566316348,128,15156,94230297,CLX5
2025-09-24T19:30:21.332680746Z,2025-09-24T19:30:21.332383911Z,160,1,432669,A,A,64.840000000,1,26,8058566316349,128,15364,94230301,CLX5
2025-09-24T19:30:21.332707932Z,2025-09-24T19:30:21.332504215Z,160,1,432669,A,A,64.840000000,1,26,8058566316350,128,14403,94230302,CLX5
2025-09-24T19:30:21.332736255Z,2025-09-24T19:30:21.332574715Z,160,1,432669,C,A,64.840000000,1,26,8058566316350,128,16048,94230303,CLX5
2025-09-24T19:30:21.332769699Z,2025-09-24T19:30:21.332585887Z,160,1,432669,C,B,64.800000000,1,26,8058566316211,128,18119,94230304,CLX5
2025-09-24T19:30:21.782315388Z,2025-09-24T19:30:21.782172409Z,160,1,432669,C,A,64.840000000,1,26,8058566316349,128,20495,94230334,CLX5
2025-09-24T19:30:21.782341391Z,2025-09-24T19:30:21.782185215Z,160,1,432669,C,A,64.840000000,1,26,8058566316348,128,15954,94230335,CLX5
2025-09-24T19:30:21.782368715Z,2025-09-24T19:30:21.782195715Z,160,1,432669,C,A,64.840000000,1,26,8058566316347,128,15415,94230336,CLX5
2025-09-24T19:30:22.403249993Z,2025-09-24T19:30:22.403122069Z,160,1,432669,A,A,64.840000000,1,26,8058566316388,128,17892,94230413,CLX5
2025-09-24T19:30:24.859277052Z,2025-09-24T19:30:24.859102505Z,160,1,432669,C,A,64.840000000,1,26,8058566316388,128,16265,94230694,CLX5
2025-09-24T19:30:24.859544470Z,2025-09-24T19:30:24.859417101Z,160,1,432669,A,A,64.840000000,1,26,8058566316473,128,15658,94230703,CLX5
2025-09-24T19:30:24.859731845Z,2025-09-24T19:30:24.859617117Z,160,1,432669,C,A,64.840000000,1,26,8058566316473,128,18734,94230708,CLX5
2025-09-24T19:30:26.085513892Z,2025-09-24T19:30:26.085376981Z,160,1,432669,A,A,64.840000000,1,26,8058566316525,128,19154,94230849,CLX5
2025-09-24T19:30:26.549745773Z,2025-09-24T19:30:26.548911745Z,160,1,432669,A,B,64.830000000,1,26,8058566316563,128,14288,94230963,CLX5
2025-09-24T19:30:26.551757105Z,2025-09-24T19:30:26.549751747Z,160,1,432669,C,A,64.840000000,1,26,8058566315093,128,18901,94231077,CLX5
2025-09-24T19:30:26.551898725Z,2025-09-24T19:30:26.549847723Z,160,1,432669,A,B,64.830000000,1,26,8058566316595,128,18424,94231083,CLX5
2025-09-24T19:30:26.552600432Z,2025-09-24T19:30:26.550275577Z,160,1,432669,A,B,64.800000000,1,26,8058566316599,128,15206,94231111,CLX5
2025-09-24T19:30:26.555317036Z,2025-09-24T19:30:26.554982479Z,160,1,432669,A,A,64.840000000,1,26,8058566316632,128,15525,94231274,CLX5
2025-09-24T19:30:26.555586406Z,2025-09-24T19:30:26.555320749Z,160,1,432669,C,A,64.840000000,1,26,8058566316525,128,15690,94231290,CLX5
2025-09-24T19:30:26.558641672Z,2025-09-24T19:30:26.558515853Z,160,1,432669,M,A,64.850000000,1,26,8058566305433,128,16903,94231310,CLX5
2025-09-24T19:30:26.558895705Z,2025-09-24T19:30:26.558648449Z,160,1,432669,A,A,64.840000000,1,26,8058566316638,128,15071,94231318,CLX5
2025-09-24T19:30:26.559016482Z,2025-09-24T19:30:26.558900393Z,160,1,432669,C,A,64.840000000,1,26,8058566316638,128,18674,94231319,CLX5
2025-09-24T19:30:26.605306603Z,2025-09-24T19:30:26.605007351Z,160,1,432669,T,A,64.830000000,2,26,8058566316656,0,17915,94231354,CLX5
2025-09-24T19:30:26.605306603Z,2025-09-24T19:30:26.605007351Z,160,1,432669,F,B,64.830000000,1,26,8058566316563,0,17915,94231354,CLX5
2025-09-24T19:30:26.605306603Z,2025-09-24T19:30:26.605007351Z,160,1,432669,F,B,64.830000000,1,26,8058566316595,0,17915,94231354,CLX5
2025-09-24T19:30:26.605315519Z,2025-09-24T19:30:26.605007351Z,160,1,432669,C,B,64.830000000,1,26,8058566316563,0,15160,94231355,CLX5
2025-09-24T19:30:26.605315519Z,2025-09-24T19:30:26.605007351Z,160,1,432669,C,B,64.830000000,1,26,8058566316595,128,15160,94231355,CLX5
2025-09-24T19:30:26.605482972Z,2025-09-24T19:30:26.605268729Z,160,1,432669,A,A,64.840000000,1,26,8058566316659,128,16068,94231360,CLX5
2025-09-24T19:30:26.605621520Z,2025-09-24T19:30:26.605402105Z,160,1,432669,A,A,64.840000000,1,26,8058566316661,128,18880,94231366,CLX5
2025-09-24T19:30:26.605647285Z,2025-09-24T19:30:26.605454809Z,160,1,432669,A,A,64.840000000,1,26,8058566316662,128,15304,94231367,CLX5
2025-09-24T19:30:26.605740162Z,2025-09-24T19:30:26.605625583Z,160,1,432669,C,A,64.840000000,1,26,8058566316659,128,19313,94231370,CLX5
2025-09-24T19:30:26.605776609Z,2025-09-24T19:30:26.605647971Z,160,1,432669,A,A,64.840000000,1,26,8058566316665,128,15381,94231372,CLX5
2025-09-24T19:30:26.611134180Z,2025-09-24T19:30:26.611007663Z,160,1,432669,C,A,64.840000000,1,26,8058566316665,128,18582,94231384,CLX5
2025-09-24T19:30:26.611159338Z,2025-09-24T19:30:26.611017819Z,160,1,432669,C,A,64.840000000,1,26,8058566316662,128,14568,94231385,CLX5
2025-09-24T19:30:26.611186600Z,2025-09-24T19:30:26.611022485Z,160,1,432669,C,A,64.840000000,1,26,8058566316661,128,15611,94231386,CLX5
2025-09-24T19:30:26.611306080Z,2025-09-24T19:30:26.611190555Z,160,1,432669,A,A,64.840000000,1,26,8058566316669,128,19006,94231387,CLX5
2025-09-24T19:30:26.731081383Z,2025-09-24T19:30:26.730941647Z,160,1,432669,C,B,64.800000000,1,26,8058566316599,128,19268,94231483,CLX5
2025-09-24T19:30:31.742893927Z,2025-09-24T19:30:31.742717865Z,160,1,432669,M,A,64.840000000,1,26,8058566305433,128,19346,94232040,CLX5
2025-09-24T19:30:32.243079788Z,2025-09-24T19:30:32.242934813Z,160,1,432669,M,A,64.850000000,1,26,8058566305433,128,18665,94232086,CLX5
2025-09-24T19:30:34.352911312Z,2025-09-24T19:30:34.352561815Z,160,1,432669,T,B,64.840000000,1,26,8058566317039,0,21344,94232193,CLX5
2025-09-24T19:30:34.352911312Z,2025-09-24T19:30:34.352561815Z,160,1,432669,F,A,64.840000000,1,26,8058566274047,0,21344,94232193,CLX5
2025-09-24T19:30:34.352923830Z,2025-09-24T19:30:34.352561815Z,160,1,432669,C,A,64.840000000,1,26,8058566274047,128,18157,94232194,CLX5
2025-09-24T19:30:34.353141139Z,2025-09-24T19:30:34.352881711Z,160,1,432669,A,B,64.830000000,2,26,8058566317040,128,24452,94232195,CLX5
2025-09-24T19:30:34.353403190Z,2025-09-24T19:30:34.352888449Z,160,1,432669,C,A,64.840000000,1,26,8058566316669,128,22207,94232206,CLX5
2025-09-24T19:30:34.353505920Z,2025-09-24T19:30:34.352911315Z,160,1,432669,C,B,64.830000000,2,26,8058566317040,128,19567,94232210,CLX5
2025-09-24T19:30:34.353832725Z,2025-09-24T19:30:34.353178837Z,160,1,432669,A,A,64.840000000,1,26,8058566317050,128,15363,94232229,CLX5
2025-09-24T19:30:34.353911994Z,2025-09-24T19:30:34.353194773Z,160,1,432669,A,A,64.840000000,1,26,8058566317051,128,17367,94232232,CLX5
2025-09-24T19:30:34.353980335Z,2025-09-24T19:30:34.353203431Z,160,1,432669,A,B,64.830000000,1,26,8058566317052,128,15216,94232234,CLX5
2025-09-24T19:30:34.354013234Z,2025-09-24T19:30:34.353257323Z,160,1,432669,T,A,64.830000000,1,26,8058566317053,0,18451,94232237,CLX5
2025-09-24T19:30:34.354013234Z,2025-09-24T19:30:34.353257323Z,160,1,432669,F,B,64.830000000,1,26,8058566317052,0,18451,94232237,CLX5
2025-09-24T19:30:34.354013234Z,2025-09-24T19:30:34.353257323Z,160,1,432669,C,B,64.830000000,1,26,8058566317052,128,18451,94232237,CLX5
2025-09-24T19:30:34.354109360Z,2025-09-24T19:30:34.353257515Z,160,1,432669,A,A,64.830000000,2,26,8058566317054,128,18697,94232240,CLX5
2025-09-24T19:30:34.354154500Z,2025-09-24T19:30:34.353257695Z,160,1,432669,A,A,64.830000000,1,26,8058566317055,128,15093,94232243,CLX5
2025-09-24T19:30:34.354543610Z,2025-09-24T19:30:34.353626773Z,160,1,432669,A,A,64.830000000,2,26,8058566317060,128,18376,94232264,CLX5
2025-09-24T19:30:34.354637309Z,2025-09-24T19:30:34.353693797Z,160,1,432669,A,B,64.800000000,1,26,8058566317062,128,17381,94232269,CLX5
2025-09-24T19:30:34.354778314Z,2025-09-24T19:30:34.353983435Z,160,1,432669,C,B,64.820000000,1,26,8058566315620,128,15864,94232277,CLX5
2025-09-24T19:30:34.354843821Z,2025-09-24T19:30:34.354009525Z,160,1,432669,A,A,64.830000000,1,26,8058566317067,128,19709,94232279,CLX5
2025-09-24T19:30:34.355476643Z,2025-09-24T19:30:34.354553247Z,160,1,432669,T,B,64.830000000,5,26,8058566317077,0,15212,94232300,CLX5
2025-09-24T19:30:34.355476643Z,2025-09-24T19:30:34.354553247Z,160,1,432669,F,A,64.830000000,2,26,8058566317054,0,15212,94232300,CLX5
2025-09-24T19:30:34.355476643Z,2025-09-24T19:30:34.354553247Z,160,1,432669,F,A,64.830000000,1,26,8058566317055,0,15212,94232300,CLX5
2025-09-24T19:30:34.355476643Z,2025-09-24T19:30:34.354553247Z,160,1,432669,F,A,64.830000000,2,26,8058566317060,0,15212,94232300,CLX5
2025-09-24T19:30:34.355524640Z,2025-09-24T19:30:34.354553247Z,160,1,432669,C,A,64.830000000,2,26,8058566317054,0,15263,94232301,CLX5
2025-09-24T19:30:34.355524640Z,2025-09-24T19:30:34.354553247Z,160,1,432669,C,A,64.830000000,1,26,8058566317055,0,15263,94232301,CLX5
2025-09-24T19:30:34.355524640Z,2025-09-24T19:30:34.354553247Z,160,1,432669,C,A,64.830000000,2,26,8058566317060,128,15263,94232301,CLX5
2025-09-24T19:30:34.355611351Z,2025-09-24T19:30:34.354565303Z,160,1,432669,T,B,64.830000000,1,26,8058566317078,0,15080,94232307,CLX5
2025-09-24T19:30:34.355611351Z,2025-09-24T19:30:34.354565303Z,160,1,432669,F,A,64.830000000,1,26,8058566317067,0,15080,94232307,CLX5
2025-09-24T19:30:34.355611351Z,2025-09-24T19:30:34.354565303Z,160,1,432669,A,B,64.830000000,1,26,8058566317078,0,15080,94232307,CLX5
2025-09-24T19:30:34.355611351Z,2025-09-24T19:30:34.354565303Z,160,1,432669,C,A,64.830000000,1,26,8058566317067,128,15080,94232307,CLX5
2025-09-24T19:30:34.355760442Z,2025-09-24T19:30:34.354577225Z,160,1,432669,T,A,64.830000000,1,26,8058566317079,0,15111,94232315,CLX5
2025-09-24T19:30:34.355760442Z,2025-09-24T19:30:34.354577225Z,160,1,432669,F,B,64.830000000,1,26,8058566317078,0,15111,94232315,CLX5
2025-09-24T19:30:34.355760442Z,2025-09-24T19:30:34.354577225Z,160,1,432669,C,B,64.830000000,1,26,8058566317078,0,15111,94232315,CLX5
2025-09-24T19:30:34.355760442Z,2025-09-24T19:30:34.354577225Z,160,1,432669,A,A,64.830000000,1,26,8058566317079,128,15111,94232315,CLX5
2025-09-24T19:30:34.357009613Z,2025-09-24T19:30:34.355479989Z,160,1,432669,A,B,64.820000000,1,26,8058566317092,128,15110,94232367,CLX5
2025-09-24T19:30:34.357058133Z,2025-09-24T19:30:34.355488515Z,160,1,432669,T,B,64.830000000,1,26,8058566317094,0,15295,94232370,CLX5
2025-09-24T19:30:34.357058133Z,2025-09-24T19:30:34.355488515Z,160,1,432669,F,A,64.830000000,1,26,8058566317079,0,15295,94232370,CLX5
2025-09-24T19:30:34.357115507Z,2025-09-24T19:30:34.355488515Z,160,1,432669,C,A,64.830000000,1,26,8058566317079,128,18636,94232371,CLX5
2025-09-24T19:30:34.357477055Z,2025-09-24T19:30:34.355612407Z,160,1,432669,A,B,64.830000000,1,26,8058566317099,128,16335,94232387,CLX5
2025-09-24T19:30:34.357588624Z,2025-09-24T19:30:34.355620259Z,160,1,432669,C,B,64.820000000,1,26,8058566317092,128,15743,94232392,CLX5
2025-09-24T19:30:34.357869359Z,2025-09-24T19:30:34.355768437Z,160,1,432669,T,A,64.830000000,1,26,8058566317105,0,14612,94232405,CLX5
2025-09-24T19:30:34.357869359Z,2025-09-24T19:30:34.355768437Z,160,1,432669,F,B,64.830000000,1,26,8058566317099,0,14612,94232405,CLX5
2025-09-24T19:30:34.357917610Z,2025-09-24T19:30:34.355768437Z,160,1,432669,C,B,64.830000000,1,26,8058566317099,128,18553,94232406,CLX5
2025-09-24T19:30:34.357984699Z,2025-09-24T19:30:34.356145569Z,160,1,432669,A,B,64.820000000,1,26,8058566317107,128,14873,94232411,CLX5
2025-09-24T19:30:34.358408098Z,2025-09-24T19:30:34.356268135Z,160,1,432669,A,A,64.830000000,1,26,8058566317112,128,14900,94232428,CLX5
2025-09-24T19:30:34.358480755Z,2025-09-24T19:30:34.356549441Z,160,1,432669,T,B,64.830000000,1,26,8058566317113,0,14843,94232434,CLX5
2025-09-24T19:30:34.358480755Z,2025-09-24T19:30:34.356549441Z,160,1,432669,F,A,64.830000000,1,26,8058566317112,0,14843,94232434,CLX5
2025-09-24T19:30:34.358531717Z,2025-09-24T19:30:34.356549441Z,160,1,432669,C,A,64.830000000,1,26,8058566317112,128,19733,94232435,CLX5
2025-09-24T19:30:34.359053844Z,2025-09-24T19:30:34.357618719Z,160,1,432669,A,B,64.820000000,1,26,8058566317120,128,14449,94232459,CLX5
2025-09-24T19:30:34.475097802Z,2025-09-24T19:30:34.474947355Z,160,1,432669,M,A,64.840000000,1,26,8058566305433,128,18784,94232537,CLX5
2025-09-24T19:30:34.475493194Z,2025-09-24T19:30:34.475133509Z,160,1,432669,C,B,64.820000000,1,26,8058566317120,128,14279,94232547,CLX5
2025-09-24T19:30:34.475612319Z,2025-09-24T19:30:34.475496181Z,160,1,432669,C,B,64.820000000,1,26,8058566317107,128,15152,94232549,CLX5
2025-09-24T19:30:34.531129667Z,2025-09-24T19:30:34.530989433Z,160,1,432669,C,B,64.800000000,1,26,8058566317062,128,20988,94232564,CLX5
2025-09-24T19:30:34.664201777Z,2025-09-24T19:30:34.664047861Z,160,1,432669,A,A,64.840000000,1,26,8058566317159,128,18363,94232595,CLX5
2025-09-24T19:30:34.668509586Z,2025-09-24T19:30:34.668204035Z,160,1,432669,T,A,64.820000000,1,26,8058566317160,0,18374,94232596,CLX5
2025-09-24T19:30:34.668509586Z,2025-09-24T19:30:34.668204035Z,160,1,432669,F,B,64.820000000,1,26,8058566312886,0,18374,94232596,CLX5
2025-09-24T19:30:34.668519485Z,2025-09-24T19:30:34.668204035Z,160,1,432669,C,B,64.820000000,1,26,8058566312886,128,15157,94232597,CLX5
2025-09-24T19:30:34.668765148Z,2025-09-24T19:30:34.668483209Z,160,1,432669,A,A,64.830000000,2,26,8058566317162,128,18082,94232602,CLX5
2025-09-24T19:30:34.668810542Z,2025-09-24T19:30:34.668486167Z,160,1,432669,A,A,64.830000000,2,26,8058566317163,128,15061,94232605,CLX5
2025-09-24T19:30:34.668973511Z,2025-09-24T19:30:34.668771869Z,160,1,432669,A,A,64.830000000,1,26,8058566317168,128,21374,94232613,CLX5
2025-09-24T19:30:34.669037052Z,2025-09-24T19:30:34.668810613Z,160,1,432669,C,A,64.830000000,2,26,8058566317162,128,18787,94232616,CLX5
2025-09-24T19:30:34.670622390Z,2025-09-24T19:30:34.670471551Z,160,1,432669,A,A,64.830000000,1,26,8058566317181,128,21681,94232650,CLX5
2025-09-24T19:30:35.012926919Z,2025-09-24T19:30:35.012777673Z,160,1,432669,C,A,64.830000000,1,26,8058566317181,128,20425,94232711,CLX5
2025-09-24T19:30:35.013908925Z,2025-09-24T19:30:35.013741873Z,160,1,432669,A,B,64.820000000,1,26,8058566317207,128,18271,94232723,CLX5
2025-09-24T19:30:35.014060428Z,2025-09-24T19:30:35.013916623Z,160,1,432669,C,A,64.830000000,1,26,8058566317168,128,21523,94232725,CLX5
2025-09-24T19:30:35.793135957Z,2025-09-24T19:30:35.792971665Z,160,1,432669,A,A,64.830000000,1,26,8058566317233,128,17935,94232801,CLX5
2025-09-24T19:30:35.793157222Z,2025-09-24T19:30:35.792978729Z,160,1,432669,C,B,64.800000000,2,26,8058566314994,128,14125,94232803,CLX5
2025-09-24T19:30:35.793449883Z,2025-09-24T19:30:35.793021813Z,160,1,432669,A,A,64.830000000,2,26,8058566317236,128,14833,94232816,CLX5
2025-09-24T19:30:35.793490616Z,2025-09-24T19:30:35.793096729Z,160,1,432669,A,A,64.830000000,1,26,8058566317237,128,15718,94232818,CLX5
2025-09-24T19:30:35.793551477Z,2025-09-24T19:30:35.793345549Z,160,1,432669,C,A,64.830000000,2,26,8058566317236,128,28341,94232820,CLX5
2025-09-24T19:30:35.909377370Z,2025-09-24T19:30:35.909236227Z,160,1,432669,A,B,64.800000000,2,26,8058566317244,128,19600,94232844,CLX5
2025-09-24T19:30:40.215420322Z,2025-09-24T19:30:40.215027601Z,160,1,432669,T,B,64.830000000,4,26,8058566317319,0,22552,94233005,CLX5
2025-09-24T19:30:40.215420322Z,2025-09-24T19:30:40.215027601Z,160,1,432669,F,A,64.830000000,2,26,8058566317163,0,22552,94233005,CLX5
2025-09-24T19:30:40.215420322Z,2025-09-24T19:30:40.215027601Z,160,1,432669,F,A,64.830000000,1,26,8058566317233,0,22552,94233005,CLX5
2025-09-24T19:30:40.215420322Z,2025-09-24T19:30:40.215027601Z,160,1,432669,F,A,64.830000000,1,26,8058566317237,0,22552,94233005,CLX5
2025-09-24T19:30:40.215434606Z,2025-09-24T19:30:40.215027601Z,160,1,432669,A,B,64.830000000,1,26,8058566317319,0,18558,94233006,CLX5
2025-09-24T19:30:40.215434606Z,2025-09-24T19:30:40.215027601Z,160,1,432669,C,A,64.830000000,2,26,8058566317163,0,18558,94233006,CLX5
2025-09-24T19:30:40.215434606Z,2025-09-24T19:30:40.215027601Z,160,1,432669,C,A,64.830000000,1,26,8058566317233,0,18558,94233006,CLX5
2025-09-24T19:30:40.215434606Z,2025-09-24T19:30:40.215027601Z,160,1,432669,C,A,64.830000000,1,26,8058566317237,128,18558,94233006,CLX5
2025-09-24T19:30:40.215524626Z,2025-09-24T19:30:40.215364969Z,160,1,432669,C,A,64.840000000,1,26,8058566317051,128,23066,94233011,CLX5
2025-09-24T19:30:40.215714151Z,2025-09-24T19:30:40.215431147Z,160,1,432669,A,B,64.820000000,1,26,8058566317325,128,18595,94233018,CLX5
2025-09-24T19:30:40.216134424Z,2025-09-24T19:30:40.215531809Z,160,1,432669,A,A,64.840000000,1,26,8058566317329,128,15334,94233038,CLX5
2025-09-24T19:30:40.216426295Z,2025-09-24T19:30:40.216071441Z,160,1,432669,A,B,64.800000000,1,26,8058566317334,128,14830,94233053,CLX5
2025-09-24T19:30:40.223832783Z,2025-09-24T19:30:40.223683751Z,160,1,432669,M,A,64.850000000,1,26,8058566305433,128,18750,94233140,CLX5
2025-09-24T19:30:40.224004207Z,2025-09-24T19:30:40.223877549Z,160,1,432669,A,A,64.840000000,1,26,8058566317358,128,15834,94233145,CLX5
2025-09-24T19:30:40.224157660Z,2025-09-24T19:30:40.224031063Z,160,1,432669,A,A,64.840000000,1,26,8058566317359,128,18728,94233148,CLX5
2025-09-24T19:30:40.224310930Z,2025-09-24T19:30:40.224187999Z,160,1,432669,A,A,64.840000000,1,26,8058566317360,128,19542,94233150,CLX5
2025-09-24T19:30:40.251005339Z,2025-09-24T19:30:40.250747799Z,160,1,432669,T,A,64.830000000,1,26,8058566317365,0,20121,94233160,CLX5
2025-09-24T19:30:40.251005339Z,2025-09-24T19:30:40.250747799Z,160,1,432669,F,B,64.830000000,1,26,8058566317319,0,20121,94233160,CLX5
2025-09-24T19:30:40.251027741Z,2025-09-24T19:30:40.250747799Z,160,1,432669,C,B,64.830000000,1,26,8058566317319,128,15268,94233161,CLX5
2025-09-24T19:30:40.251309651Z,2025-09-24T19:30:40.251011865Z,160,1,432669,C,A,64.840000000,1,26,8058566317329,128,18331,94233170,CLX5
2025-09-24T19:30:40.251393681Z,2025-09-24T19:30:40.251212171Z,160,1,432669,C,B,64.820000000,1,26,8058566317325,128,16226,94233174,CLX5
2025-09-24T19:30:40.258807587Z,2025-09-24T19:30:40.258672731Z,160,1,432669,M,A,64.840000000,1,26,8058566305433,128,19287,94233184,CLX5
2025-09-24T19:30:40.258967069Z,2025-09-24T19:30:40.258846963Z,160,1,432669,C,A,64.840000000,1,26,8058566317360,128,18355,94233185,CLX5
2025-09-24T19:30:40.258990845Z,2025-09-24T19:30:40.258853297Z,160,1,432669,C,A,64.840000000,1,26,8058566317359,128,14960,94233186,CLX5
2025-09-24T19:30:40.259018185Z,2025-09-24T19:30:40.258864069Z,160,1,432669,C,A,64.840000000,1,26,8058566317358,128,15396,94233187,CLX5
2025-09-24T19:30:40.259217470Z,2025-09-24T19:30:40.259073475Z,160,1,432669,A,A,64.840000000,1,26,8058566317370,128,14274,94233192,CLX5
2025-09-24T19:30:40.259332341Z,2025-09-24T19:30:40.259221845Z,160,1,432669,C,A,64.840000000,1,26,8058566317370,128,18422,94233193,CLX5
2025-09-24T19:30:40.316099246Z,2025-09-24T19:30:40.315972029Z,160,1,432669,A,A,64.840000000,1,26,8058566317376,128,18546,94233209,CLX5
2025-09-24T19:30:40.401167975Z,2025-09-24T19:30:40.401023607Z,160,1,432669,C,B,64.800000000,1,26,8058566317334,128,18227,94233228,CLX5
2025-09-24T19:30:44.709862687Z,2025-09-24T19:30:44.709674249Z,160,1,432669,A,A,64.890000000,2,26,8058566317481,128,26222,94233446,CLX5
2025-09-24T19:30:45.017034322Z,2025-09-24T19:30:45.016880903Z,160,1,432669,C,A,64.840000000,1,26,8058566317376,128,21578,94233463,CLX5
2025-09-24T19:30:45.752079574Z,2025-09-24T19:30:45.750889213Z,160,1,432669,A,A,64.830000000,2,26,8058566317514,128,13889,94233533,CLX5
2025-09-24T19:30:45.754751206Z,2025-09-24T19:30:45.751074985Z,160,1,432669,A,A,64.830000000,2,26,8058566317579,128,18500,94233672,CLX5
2025-09-24T19:30:45.755650933Z,2025-09-24T19:30:45.751276441Z,160,1,432669,A,A,64.830000000,2,26,8058566317601,128,16915,94233720,CLX5
2025-09-24T19:30:45.757241761Z,2025-09-24T19:30:45.751875933Z,160,1,432669,C,B,64.800000000,2,26,8058566317244,128,14801,94233809,CLX5
2025-09-24T19:30:45.757383611Z,2025-09-24T19:30:45.751893137Z,160,1,432669,A,A,64.830000000,1,26,8058566317631,128,16920,94233815,CLX5
2025-09-24T19:30:45.757908987Z,2025-09-24T19:30:45.752273873Z,160,1,432669,A,A,64.830000000,1,26,8058566317639,128,16998,94233842,CLX5
2025-09-24T19:30:45.758568681Z,2025-09-24T19:30:45.752431941Z,160,1,432669,A,A,64.830000000,1,26,8058566317644,128,20342,94233882,CLX5
2025-09-24T19:30:45.758835101Z,2025-09-24T19:30:45.752529241Z,160,1,432669,A,A,64.830000000,1,26,8058566317646,128,16014,94233902,CLX5
2025-09-24T19:30:45.758896200Z,2025-09-24T19:30:45.752534177Z,160,1,432669,C,B,64.790000000,2,26,8058566314995,128,15047,94233905,CLX5
2025-09-24T19:30:45.760236412Z,2025-09-24T19:30:45.753051767Z,160,1,432669,C,B,64.810000000,2,26,8058566314917,128,17581,94233958,CLX5
2025-09-24T19:30:45.760267837Z,2025-09-24T19:30:45.753052517Z,160,1,432669,C,B,64.820000000,1,26,8058566316035,128,15318,94233959,CLX5
2025-09-24T19:30:45.760352958Z,2025-09-24T19:30:45.753052813Z,160,1,432669,C,B,64.820000000,1,26,8058566317207,128,15445,94233962,CLX5
2025-09-24T19:30:45.760402345Z,2025-09-24T19:30:45.753052965Z,160,1,432669,A,A,64.830000000,2,26,8058566317660,128,16046,94233964,CLX5
2025-09-24T19:30:45.760440090Z,2025-09-24T19:30:45.753053291Z,160,1,432669,A,A,64.830000000,2,26,8058566317661,128,18730,94233966,CLX5
2025-09-24T19:30:45.760467514Z,2025-09-24T19:30:45.753053467Z,160,1,432669,A,A,64.830000000,1,26,8058566317662,128,15352,94233967,CLX5
2025-09-24T19:30:45.760786210Z,2025-09-24T19:30:45.753166923Z,160,1,432669,C,B,64.820000000,2,26,8058566315615,128,15424,94233991,CLX5
2025-09-24T19:30:45.761129864Z,2025-09-24T19:30:45.753277013Z,160,1,432669,A,A,64.830000000,1,26,8058566317666,128,14490,94234006,CLX5
2025-09-24T19:30:45.761160107Z,2025-09-24T19:30:45.753279603Z,160,1,432669,A,A,64.830000000,1,26,8058566317667,128,15791,94234007,CLX5
2025-09-24T19:30:45.763133571Z,2025-09-24T19:30:45.754296083Z,160,1,432669,A,A,64.830000000,1,26,8058566317696,128,16146,94234104,CLX5
2025-09-24T19:30:45.763423891Z,2025-09-24T19:30:45.754477305Z,160,1,432669,A,A,64.860000000,1,26,8058566317700,128,14108,94234120,CLX5
2025-09-24T19:30:45.763707322Z,2025-09-24T19:30:45.754761373Z,160,1,432669,T,B,64.830000000,4,26,8058566317705,0,18328,94234132,CLX5
2025-09-24T19:30:45.763707322Z,2025-09-24T19:30:45.754761373Z,160,1,432669,F,A,64.830000000,2,26,8058566317514,0,18328,94234132,CLX5
2025-09-24T19:30:45.763707322Z,2025-09-24T19:30:45.754761373Z,160,1,432669,F,A,64.830000000,2,26,8058566317579,0,18328,94234132,CLX5
2025-09-24T19:30:45.763733371Z,2025-09-24T19:30:45.754761373Z,160,1,432669,C,A,64.830000000,2,26,8058566317514,0,16877,94234133,CLX5
2025-09-24T19:30:45.763733371Z,2025-09-24T19:30:45.754761373Z,160,1,432669,C,A,64.830000000,2,26,8058566317579,128,16877,94234133,CLX5
2025-09-24T19:30:45.763747740Z,2025-09-24T19:30:45.754772663Z,160,1,432669,T,B,64.830000000,1,26,8058566317706,0,14279,94234134,CLX5
2025-09-24T19:30:45.763747740Z,2025-09-24T19:30:45.754772663Z,160,1,432669,F,A,64.830000000,1,26,8058566317601,0,14279,94234134,CLX5
2025-09-24T19:30:45.763747740Z,2025-09-24T19:30:45.754772663Z,160,1,432669,M,A,64.830000000,1,26,8058566317601,128,14279,94234134,CLX5
2025-09-24T19:30:45.763851099Z,2025-09-24T19:30:45.754824865Z,160,1,432669,C,A,64.830000000,2,26,8058566317660,128,15634,94234138,CLX5
2025-09-24T19:30:45.763879998Z,2025-09-24T19:30:45.754825019Z,160,1,432669,C,A,64.830000000,1,26,8058566317662,128,16012,94234139,CLX5
2025-09-24T19:30:45.764810566Z,2025-09-24T19:30:45.755656113Z,160,1,432669,M,A,64.940000000,1,26,8058565075241,128,14546,94234191,CLX5
2025-09-24T19:30:45.765143722Z,2025-09-24T19:30:45.756128623Z,160,1,432669,C,A,64.830000000,1,26,8058566317601,128,16321,94234213,CLX5
2025-09-24T19:30:45.765242765Z,2025-09-24T19:30:45.756190905Z,160,1,432669,C,A,64.830000000,1,26,8058566317639,128,16102,94234218,CLX5
2025-09-24T19:30:45.766318477Z,2025-09-24T19:30:45.757133873Z,160,1,432669,C,A,64.830000000,2,26,8058566317661,128,15396,94234275,CLX5
2025-09-24T19:30:45.767147659Z,2025-09-24T19:30:45.757785507Z,160,1,432669,A,B,64.820000000,2,26,8058566317765,128,15175,94234317,CLX5
2025-09-24T19:30:45.767465225Z,2025-09-24T19:30:45.757913817Z,160,1,432669,A,B,64.820000000,2,26,8058566317770,128,18419,94234334,CLX5
2025-09-24T19:30:45.768090675Z,2025-09-24T19:30:45.758296247Z,160,1,432669,C,A,64.830000000,1,26,8058566317666,128,16947,94234359,CLX5
2025-09-24T19:30:45.768469041Z,2025-09-24T19:30:45.758890365Z,160,1,432669,A,B,64.820000000,2,26,8058566317788,128,14995,94234378,CLX5
2025-09-24T19:30:45.768565504Z,2025-09-24T19:30:45.758937863Z,160,1,432669,C,A,64.830000000,1,26,8058566317667,128,17204,94234380,CLX5
2025-09-24T19:30:45.768596661Z,2025-09-24T19:30:45.758938687Z,160,1,432669,A,B,64.820000000,1,26,8058566317789,128,15104,94234381,CLX5
2025-09-24T19:30:45.768606161Z,2025-09-24T19:30:45.758941299Z,160,1,432669,T,B,64.830000000,2,26,8058566317790,0,15223,94234382,CLX5
2025-09-24T19:30:45.768606161Z,2025-09-24T19:30:45.758941299Z,160,1,432669,F,A,64.830000000,1,26,8058566317631,0,15223,94234382,CLX5
2025-09-24T19:30:45.768606161Z,2025-09-24T19:30:45.758941299Z,160,1,432669,F,A,64.830000000,1,26,8058566317644,0,15223,94234382,CLX5
2025-09-24T19:30:45.768649988Z,2025-09-24T19:30:45.758941299Z,160,1,432669,C,A,64.830000000,1,26,8058566317631,0,18250,94234383,CLX5
2025-09-24T19:30:45.768649988Z,2025-09-24T19:30:45.758941299Z,160,1,432669,C,A,64.830000000,1,26,8058566317644,128,18250,94234383,CLX5
2025-09-24T19:30:45.768744486Z,2025-09-24T19:30:45.758962573Z,160,1,432669,T,B,64.830000000,2,26,8058566317794,0,17000,94234387,CLX5
2025-09-24T19:30:45.768744486Z,2025-09-24T19:30:45.758962573Z,160,1,432669,F,A,64.830000000,1,26,8058566317646,0,17000,94234387,CLX5
2025-09-24T19:30:45.768744486Z,2025-09-24T19:30:45.758962573Z,160,1,432669,F,A,64.830000000,1,26,8058566317696,0,17000,94234387,CLX5
2025-09-24T19:30:45.768782046Z,2025-09-24T19:30:45.758962573Z,160,1,432669,C,A,64.830000000,1,26,8058566317646,0,15005,94234388,CLX5
2025-09-24T19:30:45.768782046Z,2025-09-24T19:30:45.758962573Z,160,1,432669,C,A,64.830000000,1,26,8058566317696,128,15005,94234388,CLX5
2025-09-24T19:30:45.768843460Z,2025-09-24T19:30:45.758962765Z,160,1,432669,A,B,64.830000000,2,26,8058566317795,128,17214,94234391,CLX5
2025-09-24T19:30:45.768866399Z,2025-09-24T19:30:45.758962939Z,160,1,432669,A,B,64.830000000,1,26,8058566317796,128,16076,94234393,CLX5
2025-09-24T19:30:45.769029399Z,2025-09-24T19:30:45.759126341Z,160,1,432669,M,A,64.840000000,3,26,8058566291196,128,15012,94234403,CLX5
2025-09-24T19:30:45.770594577Z,2025-09-24T19:30:45.760400243Z,160,1,432669,M,A,64.950000000,1,26,8058565075241,128,14467,94234477,CLX5
2025-09-24T19:30:45.770622530Z,2025-09-24T19:30:45.760426929Z,160,1,432669,M,B,63.660000000,4,26,8058566280404,128,15377,94234478,CLX5
2025-09-24T19:30:45.771516267Z,2025-09-24T19:30:45.761173699Z,160,1,432669,C,B,64.820000000,1,26,8058566314950,128,15186,94234529,CLX5
2025-09-24T19:30:45.772352683Z,2025-09-24T19:30:45.762101499Z,160,1,432669,A,B,64.820000000,2,26,8058566317866,128,14253,94234571,CLX5
2025-09-24T19:30:45.772519783Z,2025-09-24T19:30:45.762158557Z,160,1,432669,A,B,64.830000000,1,26,8058566317869,128,21537,94234576,CLX5
2025-09-24T19:30:45.772608083Z,2025-09-24T19:30:45.762237121Z,160,1,432669,A,B,64.830000000,1,26,8058566317871,128,17257,94234580,CLX5
2025-09-24T19:30:45.772859636Z,2025-09-24T19:30:45.762996565Z,160,1,432669,A,B,64.830000000,3,26,8058566317882,128,19138,94234592,CLX5
2025-09-24T19:30:45.774490491Z,2025-09-24T19:30:45.765297411Z,160,1,432669,C,A,64.840000000,3,26,8058566291196,128,15164,94234710,CLX5
2025-09-24T19:30:45.775624468Z,2025-09-24T19:30:45.766320013Z,160,1,432669,C,B,64.830000000,3,26,8058566317882,128,16945,94234765,CLX5
2025-09-24T19:30:45.775667742Z,2025-09-24T19:30:45.766350617Z,160,1,432669,T,A,64.830000000,1,26,8058566317951,0,14838,94234767,CLX5
2025-09-24T19:30:45.775667742Z,2025-09-24T19:30:45.766350617Z,160,1,432669,F,B,64.830000000,1,26,8058566317795,0,14838,94234767,CLX5
2025-09-24T19:30:45.775709366Z,2025-09-24T19:30:45.766350617Z,160,1,432669,M,B,64.830000000,1,26,8058566317795,128,20315,94234768,CLX5
2025-09-24T19:30:45.777000406Z,2025-09-24T19:30:45.768750321Z,160,1,432669,A,A,64.840000000,1,26,8058566317974,128,15307,94234843,CLX5
2025-09-24T19:30:45.777334691Z,2025-09-24T19:30:45.769217147Z,160,1,432669,M,B,64.820000000,3,26,8058566311409,128,15389,94234862,CLX5
2025-09-24T19:30:45.777756255Z,2025-09-24T19:30:45.770177795Z,160,1,432669,C,A,64.840000000,1,26,8058566317974,128,14865,94234881,CLX5
2025-09-24T19:30:45.778210549Z,2025-09-24T19:30:45.770904235Z,160,1,432669,M,B,64.810000000,3,26,8058566291224,128,14714,94234904,CLX5
2025-09-24T19:30:45.778683482Z,2025-09-24T19:30:45.772435557Z,160,1,432669,A,B,64.820000000,1,26,8058566317999,128,15140,94234934,CLX5
2025-09-24T19:30:45.783141358Z,2025-09-24T19:30:45.778876471Z,160,1,432669,A,A,64.840000000,1,26,8058566318116,128,18137,94235215,CLX5
2025-09-24T19:30:45.785746884Z,2025-09-24T19:30:45.783146555Z,160,1,432669,C,A,64.840000000,1,26,8058566318116,128,15403,94235388,CLX5
2025-09-24T19:30:45.787669356Z,2025-09-24T19:30:45.786195053Z,160,1,432669,A,B,64.830000000,1,26,8058566318242,128,20198,94235513,CLX5
2025-09-24T19:30:45.788440795Z,2025-09-24T19:30:45.787674463Z,160,1,432669,C,A,64.840000000,1,26,8058566317050,128,15131,94235571,CLX5
2025-09-24T19:30:45.789241132Z,2025-09-24T19:30:45.788485187Z,160,1,432669,C,A,64.840000000,2,26,8058566307924,128,15054,94235632,CLX5
2025-09-24T19:30:45.790260476Z,2025-09-24T19:30:45.789246145Z,160,1,432669,A,B,64.830000000,2,26,8058566318303,128,16847,94235697,CLX5
2025-09-24T19:30:45.790503719Z,2025-09-24T19:30:45.789578713Z,160,1,432669,C,A,64.840000000,1,26,8058566315884,128,19396,94235709,CLX5
2025-09-24T19:30:45.790693267Z,2025-09-24T19:30:45.789821045Z,160,1,432669,A,B,64.830000000,2,26,8058566318310,128,17279,94235719,CLX5
2025-09-24T19:30:45.790805159Z,2025-09-24T19:30:45.789822773Z,160,1,432669,C,A,64.840000000,1,26,8058566316632,128,15384,94235723,CLX5
2025-09-24T19:30:45.791129054Z,2025-09-24T19:30:45.790262127Z,160,1,432669,C,A,64.840000000,1,26,8058566307926,128,15137,94235743,CLX5
2025-09-24T19:30:45.791182588Z,2025-09-24T19:30:45.790401511Z,160,1,432669,A,B,64.830000000,1,26,8058566318320,128,15616,94235745,CLX5
2025-09-24T19:30:45.791244516Z,2025-09-24T19:30:45.790405295Z,160,1,432669,A,A,64.840000000,1,26,8058566318321,128,18505,94235748,CLX5
2025-09-24T19:30:45.791311329Z,2025-09-24T19:30:45.790414779Z,160,1,432669,A,B,64.830000000,1,26,8058566318322,128,14587,94235752,CLX5
2025-09-24T19:30:45.791608475Z,2025-09-24T19:30:45.790698197Z,160,1,432669,A,B,64.830000000,1,26,8058566318327,128,15452,94235762,CLX5
2025-09-24T19:30:45.791967958Z,2025-09-24T19:30:45.791252649Z,160,1,432669,C,B,64.830000000,1,26,8058566318322,128,15406,94235785,CLX5
2025-09-24T19:30:45.791998837Z,2025-09-24T19:30:45.791253243Z,160,1,432669,A,B,64.810000000,2,26,8058566318334,128,18109,94235786,CLX5
2025-09-24T19:30:45.795120087Z,2025-09-24T19:30:45.794987017Z,160,1,432669,M,A,64.850000000,1,26,8058566305433,128,19067,94235870,CLX5
2025-09-24T19:30:45.859734555Z,2025-09-24T19:30:45.859588177Z,160,1,432669,C,A,64.840000000,1,26,8058566318321,128,18922,94236116,CLX5
2025-09-24T19:30:45.860354207Z,2025-09-24T19:30:45.860225129Z,160,1,432669,C,A,64.840000000,1,26,8058566315091,128,18706,94236125,CLX5
2025-09-24T19:30:45.866323513Z,2025-09-24T19:30:45.866180993Z,160,1,432669,A,B,64.830000000,1,26,8058566318496,128,19240,94236180,CLX5
2025-09-24T19:30:45.866432939Z,2025-09-24T19:30:45.866301277Z,160,1,432669,C,B,64.830000000,1,26,8058566318496,128,18931,94236181,CLX5
2025-09-24T19:30:45.866466100Z,2025-09-24T19:30:45.866328269Z,160,1,432669,C,A,64.840000000,1,26,8058566307925,128,15475,94236182,CLX5
2025-09-24T19:30:45.866570519Z,2025-09-24T19:30:45.866437935Z,160,1,432669,A,A,64.840000000,1,26,8058566318497,128,18832,94236183,CLX5
2025-09-24T19:30:45.931186354Z,2025-09-24T19:30:45.931051975Z,160,1,432669,C,A,64.860000000,1,26,8058566317700,128,18347,94236387,CLX5
2025-09-24T19:30:48.050241860Z,2025-09-24T19:30:48.050076459Z,160,1,432669,C,B,64.830000000,1,26,8058566318320,128,19614,94237068,CLX5
2025-09-24T19:30:48.050414467Z,2025-09-24T19:30:48.050281755Z,160,1,432669,A,B,64.830000000,1,26,8058566318949,128,18882,94237069,CLX5
2025-09-24T19:30:48.050563934Z,2025-09-24T19:30:48.050420065Z,160,1,432669,C,A,64.840000000,1,26,8058566318497,128,19584,94237070,CLX5
2025-09-24T19:30:48.209447151Z,2025-09-24T19:30:48.209303005Z,160,1,432669,A,B,64.790000000,2,26,8058566318951,128,18954,94237073,CLX5
2025-09-24T19:30:48.389478610Z,2025-09-24T19:30:48.389115229Z,160,1,432669,T,A,64.830000000,1,26,8058566318952,0,20754,94237074,CLX5
2025-09-24T19:30:48.389478610Z,2025-09-24T19:30:48.389115229Z,160,1,432669,F,B,64.830000000,1,26,8058566317795,0,20754,94237074,CLX5
2025-09-24T19:30:48.389489761Z,2025-09-24T19:30:48.389115229Z,160,1,432669,C,B,64.830000000,1,26,8058566317795,128,15949,94237075,CLX5
2025-09-24T19:30:48.389584550Z,2025-09-24T19:30:48.389445745Z,160,1,432669,C,B,64.830000000,2,26,8058566318310,128,20417,94237076,CLX5
2025-09-24T19:30:48.389615653Z,2025-09-24T19:30:48.389452099Z,160,1,432669,A,A,64.840000000,1,26,8058566318953,128,15698,94237077,CLX5
2025-09-24T19:30:48.389652714Z,2025-09-24T19:30:48.389467495Z,160,1,432669,C,B,64.830000000,1,26,8058566318949,128,16904,94237078,CLX5
2025-09-24T19:30:48.389725348Z,2025-09-24T19:30:48.389586761Z,160,1,432669,A,B,64.830000000,1,26,8058566318954,128,16619,94237081,CLX5
2025-09-24T19:30:48.389769644Z,2025-09-24T19:30:48.389629653Z,160,1,432669,A,B,64.830000000,1,26,8058566318955,128,16136,94237083,CLX5
2025-09-24T19:30:48.390027279Z,2025-09-24T19:30:48.389714801Z,160,1,432669,T,A,64.830000000,3,26,8058566318956,0,17977,94237084,CLX5
2025-09-24T19:30:48.390027279Z,2025-09-24T19:30:48.389714801Z,160,1,432669,F,B,64.830000000,1,26,8058566317796,0,17977,94237084,CLX5
2025-09-24T19:30:48.390027279Z,2025-09-24T19:30:48.389714801Z,160,1,432669,F,B,64.830000000,1,26,8058566317869,0,17977,94237084,CLX5
2025-09-24T19:30:48.390027279Z,2025-09-24T19:30:48.389714801Z,160,1,432669,F,B,64.830000000,1,26,8058566317871,0,17977,94237084,CLX5
2025-09-24T19:30:48.390039858Z,2025-09-24T19:30:48.389714801Z,160,1,432669,C,B,64.830000000,1,26,8058566317796,0,17662,94237085,CLX5
2025-09-24T19:30:48.390039858Z,2025-09-24T19:30:48.389714801Z,160,1,432669,C,B,64.830000000,1,26,8058566317869,0,17662,94237085,CLX5
2025-09-24T19:30:48.390039858Z,2025-09-24T19:30:48.389714801Z,160,1,432669,C,B,64.830000000,1,26,8058566317871,128,17662,94237085,CLX5
2025-09-24T19:30:48.390127421Z,2025-09-24T19:30:48.389987237Z,160,1,432669,C,B,64.830000000,1,26,8058566318955,128,20821,94237086,CLX5
2025-09-24T19:30:48.390154775Z,2025-09-24T19:30:48.390004899Z,160,1,432669,A,A,64.840000000,1,26,8058566318957,128,14992,94237087,CLX5
2025-09-24T19:30:48.390197151Z,2025-09-24T19:30:48.390009797Z,160,1,432669,C,B,64.830000000,1,26,8058566318954,128,17254,94237088,CLX5
2025-09-24T19:30:48.390323573Z,2025-09-24T19:30:48.390206337Z,160,1,432669,C,A,64.840000000,1,26,8058566318957,128,18614,94237093,CLX5
2025-09-24T19:30:48.390468064Z,2025-09-24T19:30:48.390333953Z,160,1,432669,A,B,64.830000000,1,26,8058566318958,128,21491,94237094,CLX5
2025-09-24T19:30:48.390675275Z,2025-09-24T19:30:48.390561099Z,160,1,432669,C,B,64.790000000,2,26,8058566318951,128,18347,94237095,CLX5
2025-09-24T19:30:48.392043925Z,2025-09-24T19:30:48.391909553Z,160,1,432669,A,A,64.840000000,1,26,8058566318959,128,19620,94237096,CLX5
2025-09-24T19:30:48.392171008Z,2025-09-24T19:30:48.392053143Z,160,1,432669,C,A,64.840000000,1,26,8058566318959,128,18548,94237097,CLX5
2025-09-24T19:30:48.851824633Z,2025-09-24T19:30:48.850939383Z,160,1,432669,A,B,64.830000000,1,26,8058566319024,128,20783,94237260,CLX5
2025-09-24T19:30:48.851859122Z,2025-09-24T19:30:48.850939559Z,160,1,432669,A,B,64.830000000,1,26,8058566319025,128,15121,94237261,CLX5
2025-09-24T19:30:48.852069842Z,2025-09-24T19:30:48.851135101Z,160,1,432669,A,B,64.830000000,1,26,8058566319028,128,16153,94237272,CLX5
2025-09-24T19:30:48.852649237Z,2025-09-24T19:30:48.852078411Z,160,1,432669,A,B,64.830000000,1,26,8058566319037,128,14943,94237317,CLX5
2025-09-24T19:30:50.032223110Z,2025-09-24T19:30:50.032046661Z,160,1,432669,M,A,64.840000000,1,26,8058566305433,128,22104,94237514,CLX5
2025-09-24T19:30:50.032380373Z,2025-09-24T19:30:50.032235275Z,160,1,432669,C,B,64.830000000,1,26,8058566319037,128,19512,94237515,CLX5
2025-09-24T19:30:50.032522830Z,2025-09-24T19:30:50.032394205Z,160,1,432669,C,B,64.830000000,1,26,8058566319028,128,19415,94237517,CLX5
2025-09-24T19:30:53.953432521Z,2025-09-24T19:30:53.953166935Z,160,1,432669,A,A,64.840000000,1,26,8058566319282,128,22166,94237812,CLX5
2025-09-24T19:30:53.953533800Z,2025-09-24T19:30:53.953180221Z,160,1,432669,A,A,64.840000000,1,26,8058566319284,128,23496,94237816,CLX5
2025-09-24T19:30:53.953600819Z,2025-09-24T19:30:53.953191047Z,160,1,432669,C,B,64.830000000,1,26,8058566319024,128,20922,94237818,CLX5
2025-09-24T19:30:53.953646559Z,2025-09-24T19:30:53.953191203Z,160,1,432669,C,B,64.830000000,1,26,8058566319025,128,23451,94237819,CLX5
2025-09-24T19:30:53.953784523Z,2025-09-24T19:30:53.953192751Z,160,1,432669,C,B,64.810000000,2,26,8058566318334,128,14857,94237826,CLX5
2025-09-24T19:30:53.953844800Z,2025-09-24T19:30:53.953472353Z,160,1,432669,C,A,64.840000000,1,26,8058566319284,128,18374,94237830,CLX5
2025-09-24T19:30:53.990462057Z,2025-09-24T19:30:53.990313513Z,160,1,432669,A,B,64.810000000,2,26,8058566319302,128,15027,94237883,CLX5
2025-09-24T19:30:54.457715423Z,2025-09-24T19:30:54.457330113Z,160,1,432669,T,B,64.840000000,4,26,8058566319345,0,18467,94237980,CLX5
2025-09-24T19:30:54.457715423Z,2025-09-24T19:30:54.457330113Z,160,1,432669,F,A,64.840000000,1,26,8058566274057,0,18467,94237980,CLX5
2025-09-24T19:30:54.457715423Z,2025-09-24T19:30:54.457330113Z,160,1,432669,F,A,64.840000000,1,26,8058566274071,0,18467,94237980,CLX5
2025-09-24T19:30:54.457715423Z,2025-09-24T19:30:54.457330113Z,160,1,432669,F,A,64.840000000,2,26,8058566274087,0,18467,94237980,CLX5
2025-09-24T19:30:54.457727173Z,2025-09-24T19:30:54.457330113Z,160,1,432669,C,A,64.840000000,1,26,8058566274057,0,15967,94237981,CLX5
2025-09-24T19:30:54.457727173Z,2025-09-24T19:30:54.457330113Z,160,1,432669,C,A,64.840000000,1,26,8058566274071,0,15967,94237981,CLX5
2025-09-24T19:30:54.457727173Z,2025-09-24T19:30:54.457330113Z,160,1,432669,C,A,64.840000000,2,26,8058566274087,128,15967,94237981,CLX5
2025-09-24T19:30:54.457884927Z,2025-09-24T19:30:54.457662035Z,160,1,432669,A,B,64.830000000,1,26,8058566319347,128,16054,94237984,CLX5
2025-09-24T19:30:54.457949489Z,2025-09-24T19:30:54.457673375Z,160,1,432669,C,A,64.840000000,1,26,8058566318953,128,15840,94237986,CLX5
2025-09-24T19:30:54.457993992Z,2025-09-24T19:30:54.457673527Z,160,1,432669,A,B,64.830000000,1,26,8058566319348,128,20107,94237987,CLX5
2025-09-24T19:30:54.458025463Z,2025-09-24T19:30:54.457673703Z,160,1,432669,A,B,64.830000000,2,26,8058566319349,128,15144,94237988,CLX5
2025-09-24T19:30:54.458078806Z,2025-09-24T19:30:54.457677351Z,160,1,432669,A,B,64.830000000,1,26,8058566319351,128,15903,94237990,CLX5
2025-09-24T19:30:54.458114532Z,2025-09-24T19:30:54.457677887Z,160,1,432669,C,A,64.840000000,1,26,8058566319282,128,18310,94237991,CLX5
2025-09-24T19:30:54.458144175Z,2025-09-24T19:30:54.457679673Z,160,1,432669,A,B,64.830000000,1,26,8058566319352,128,15726,94237992,CLX5
2025-09-24T19:30:54.458174195Z,2025-09-24T19:30:54.457691289Z,160,1,432669,A,B,64.830000000,1,26,8058566319353,128,15728,94237993,CLX5
2025-09-24T19:30:54.458213837Z,2025-09-24T19:30:54.457761921Z,160,1,432669,A,B,64.830000000,2,26,8058566319354,128,18574,94237995,CLX5
2025-09-24T19:30:54.458270144Z,2025-09-24T19:30:54.457954297Z,160,1,432669,A,A,64.840000000,1,26,8058566319355,128,15477,94237998,CLX5
2025-09-24T19:30:54.458300532Z,2025-09-24T19:30:54.458028003Z,160,1,432669,C,B,64.830000000,1,26,8058566319352,128,15309,94237999,CLX5
2025-09-24T19:30:54.458333224Z,2025-09-24T19:30:54.458037469Z,160,1,432669,C,B,64.830000000,2,26,8058566319354,128,18543,94238000,CLX5
2025-09-24T19:30:54.458361093Z,2025-09-24T19:30:54.458153047Z,160,1,432669,C,B,64.830000000,1,26,8058566319353,128,15711,94238001,CLX5
2025-09-24T19:30:54.458460167Z,2025-09-24T19:30:54.458335709Z,160,1,432669,A,A,64.840000000,1,26,8058566319356,128,15514,94238005,CLX5
2025-09-24T19:30:54.458490402Z,2025-09-24T19:30:54.458343041Z,160,1,432669,A,A,64.840000000,2,26,8058566319357,128,15713,94238006,CLX5
2025-09-24T19:30:54.458520268Z,2025-09-24T19:30:54.458370111Z,160,1,432669,A,A,64.840000000,1,26,8058566319358,128,15936,94238007,CLX5
2025-09-24T19:30:54.458557038Z,2025-09-24T19:30:54.458370361Z,160,1,432669,A,B,64.830000000,1,26,8058566319359,128,20938,94238008,CLX5
2025-09-24T19:30:54.458584200Z,2025-09-24T19:30:54.458428881Z,160,1,432669,C,A,64.840000000,1,26,8058566319358,128,15640,94238009,CLX5
2025-09-24T19:30:54.458639417Z,2025-09-24T19:30:54.458459927Z,160,1,432669,A,A,64.840000000,1,26,8058566319360,128,15650,94238012,CLX5
2025-09-24T19:30:54.458690709Z,2025-09-24T19:30:54.458566771Z,160,1,432669,A,A,64.840000000,1,26,8058566319361,128,19120,94238013,CLX5
2025-09-24T19:30:55.167944976Z,2025-09-24T19:30:55.167788907Z,160,1,432669,C,B,64.830000000,1,26,8058566319359,128,15348,94238051,CLX5
2025-09-24T19:30:55.168075299Z,2025-09-24T19:30:55.167953729Z,160,1,432669,C,B,64.830000000,1,26,8058566319351,128,19485,94238053,CLX5
2025-09-24T19:30:55.168105265Z,2025-09-24T19:30:55.167984507Z,160,1,432669,C,A,64.840000000,1,26,8058566319361,128,15777,94238054,CLX5
2025-09-24T19:30:55.637869180Z,2025-09-24T19:30:55.637730687Z,160,1,432669,A,A,64.850000000,1,26,8058566319376,128,14886,94238095,CLX5
2025-09-24T19:30:55.638895204Z,2025-09-24T19:30:55.638719347Z,160,1,432669,C,B,64.830000000,1,26,8058566319347,128,16203,94238103,CLX5
2025-09-24T19:30:55.638934186Z,2025-09-24T19:30:55.638770841Z,160,1,432669,C,B,64.830000000,1,26,8058566319348,128,19266,94238104,CLX5
2025-09-24T19:30:55.639035672Z,2025-09-24T19:30:55.638908401Z,160,1,432669,A,A,64.840000000,1,26,8058566319377,128,18634,94238105,CLX5
2025-09-24T19:30:55.639299950Z,2025-09-24T19:30:55.639147987Z,160,1,432669,C,B,64.830000000,2,26,8058566319349,128,21265,94238109,CLX5
2025-09-24T19:30:55.639792404Z,2025-09-24T19:30:55.639415431Z,160,1,432669,A,A,64.840000000,1,26,8058566319383,128,15297,94238135,CLX5
2025-09-24T19:30:55.639914156Z,2025-09-24T19:30:55.639760517Z,160,1,432669,C,A,64.840000000,1,26,8058566319383,128,15743,94238141,CLX5
2025-09-24T19:30:55.640101623Z,2025-09-24T19:30:55.639922771Z,160,1,432669,A,A,64.840000000,1,26,8058566319390,128,15699,94238153,CLX5
2025-09-24T19:30:55.641473776Z,2025-09-24T19:30:55.641202855Z,160,1,432669,T,A,64.830000000,1,26,8058566305433,0,18453,94238217,CLX5
2025-09-24T19:30:55.641473776Z,2025-09-24T19:30:55.641202855Z,160,1,432669,F,A,64.830000000,1,26,8058566305433,0,18453,94238217,CLX5
2025-09-24T19:30:55.641473776Z,2025-09-24T19:30:55.641202855Z,160,1,432669,F,B,64.830000000,1,26,8058566318242,0,18453,94238217,CLX5
2025-09-24T19:30:55.641499372Z,2025-09-24T19:30:55.641202855Z,160,1,432669,C,B,64.830000000,1,26,8058566318242,0,15180,94238218,CLX5
2025-09-24T19:30:55.641499372Z,2025-09-24T19:30:55.641202855Z,160,1,432669,C,A,64.840000000,1,26,8058566305433,128,15180,94238218,CLX5
2025-09-24T19:30:55.641781643Z,2025-09-24T19:30:55.641454593Z,160,1,432669,C,B,64.830000000,2,26,8058566318303,128,18309,94238226,CLX5
2025-09-24T19:30:55.641917863Z,2025-09-24T19:30:55.641487519Z,160,1,432669,T,A,64.830000000,2,26,8058566319415,0,15227,94238234,CLX5
2025-09-24T19:30:55.641917863Z,2025-09-24T19:30:55.641487519Z,160,1,432669,F,B,64.830000000,1,26,8058566318327,0,15227,94238234,CLX5
2025-09-24T19:30:55.641917863Z,2025-09-24T19:30:55.641487519Z,160,1,432669,F,B,64.830000000,1,26,8058566318958,0,15227,94238234,CLX5
2025-09-24T19:30:55.641941670Z,2025-09-24T19:30:55.641487519Z,160,1,432669,C,B,64.830000000,1,26,8058566318327,0,15541,94238235,CLX5
2025-09-24T19:30:55.641941670Z,2025-09-24T19:30:55.641487519Z,160,1,432669,C,B,64.830000000,1,26,8058566318958,128,15541,94238235,CLX5
2025-09-24T19:30:55.642218366Z,2025-09-24T19:30:55.641909193Z,160,1,432669,A,A,64.840000000,2,26,8058566319423,128,15169,94238251,CLX5
2025-09-24T19:30:55.642715942Z,2025-09-24T19:30:55.641968075Z,160,1,432669,A,A,64.840000000,2,26,8058566319432,128,15847,94238276,CLX5
2025-09-24T19:30:55.643004785Z,2025-09-24T19:30:55.642113873Z,160,1,432669,C,B,64.820000000,3,26,8058566311409,128,19143,94238288,CLX5
2025-09-24T19:30:55.643922261Z,2025-09-24T19:30:55.643016501Z,160,1,432669,C,B,64.820000000,2,26,8058566317866,128,18150,94238325,CLX5
2025-09-24T19:30:55.647333285Z,2025-09-24T19:30:55.647121685Z,160,1,432669,A,A,64.830000000,1,26,8058566319448,128,18182,94238350,CLX5
2025-09-24T19:30:55.649741553Z,2025-09-24T19:30:55.649459259Z,160,1,432669,T,B,64.830000000,1,26,8058566319450,0,18214,94238355,CLX5
2025-09-24T19:30:55.649741553Z,2025-09-24T19:30:55.649459259Z,160,1,432669,F,A,64.830000000,1,26,8058566319448,0,18214,94238355,CLX5
2025-09-24T19:30:55.649750853Z,2025-09-24T19:30:55.649459259Z,160,1,432669,C,A,64.830000000,1,26,8058566319448,128,15237,94238356,CLX5
2025-09-24T19:30:55.649941882Z,2025-09-24T19:30:55.649742811Z,160,1,432669,A,B,64.830000000,1,26,8058566319451,128,15109,94238362,CLX5
2025-09-24T19:30:55.653645153Z,2025-09-24T19:30:55.653268235Z,160,1,432669,A,B,64.830000000,1,26,8058566319466,128,14117,94238418,CLX5
2025-09-24T19:30:55.654446834Z,2025-09-24T19:30:55.654141585Z,160,1,432669,T,A,64.830000000,1,26,8058566319475,0,18469,94238465,CLX5
2025-09-24T19:30:55.654446834Z,2025-09-24T19:30:55.654141585Z,160,1,432669,F,B,64.830000000,1,26,8058566319451,0,18469,94238465,CLX5
2025-09-24T19:30:55.654456080Z,2025-09-24T19:30:55.654141585Z,160,1,432669,C,B,64.830000000,1,26,8058566319451,128,14889,94238466,CLX5
2025-09-24T19:30:55.657642699Z,2025-09-24T19:30:55.657484485Z,160,1,432669,A,B,64.830000000,1,26,8058566319482,128,14808,94238515,CLX5
2025-09-24T19:30:55.659088874Z,2025-09-24T19:30:55.658954181Z,160,1,432669,A,A,64.840000000,1,26,8058566319483,128,19189,94238523,CLX5
2025-09-24T19:30:55.687279301Z,2025-09-24T19:30:55.686992835Z,160,1,432669,T,A,64.830000000,1,26,8058566319488,0,18641,94238531,CLX5
2025-09-24T19:30:55.687279301Z,2025-09-24T19:30:55.686992835Z,160,1,432669,F,B,64.830000000,1,26,8058566319466,0,18641,94238531,CLX5
2025-09-24T19:30:55.687287648Z,2025-09-24T19:30:55.686992835Z,160,1,432669,C,B,64.830000000,1,26,8058566319466,128,14998,94238532,CLX5
2025-09-24T19:30:55.687404286Z,2025-09-24T19:30:55.687251601Z,160,1,432669,C,B,64.830000000,1,26,8058566319482,128,17781,94238535,CLX5
2025-09-24T19:30:55.687577983Z,2025-09-24T19:30:55.687446069Z,160,1,432669,A,A,64.840000000,1,26,8058566319490,128,15417,94238539,CLX5
2025-09-24T19:30:55.687729571Z,2025-09-24T19:30:55.687606689Z,160,1,432669,A,A,64.840000000,1,26,8058566319491,128,18596,94238540,CLX5
2025-09-24T19:30:55.687877096Z,2025-09-24T19:30:55.687754619Z,160,1,432669,A,A,64.840000000,1,26,8058566319492,128,18239,94238541,CLX5
2025-09-24T19:30:55.691537000Z,2025-09-24T19:30:55.691332785Z,160,1,432669,M,A,64.830000000,1,26,8058566319483,128,18684,94238547,CLX5
2025-09-24T19:30:55.694743002Z,2025-09-24T19:30:55.694647595Z,160,1,432669,A,B,63.680000000,4,26,8058566319508,128,14944,94238594,CLX5
2025-09-24T19:30:55.709485147Z,2025-09-24T19:30:55.709349539Z,160,1,432669,C,A,64.840000000,1,26,8058566319492,128,18852,94238602,CLX5
2025-09-24T19:30:55.709510590Z,2025-09-24T19:30:55.709361787Z,160,1,432669,C,A,64.840000000,1,26,8058566319491,128,15188,94238603,CLX5
2025-09-24T19:30:55.709536908Z,2025-09-24T19:30:55.709366511Z,160,1,432669,C,A,64.840000000,1,26,8058566319490,128,15304,94238604,CLX5
2025-09-24T19:30:57.354956414Z,2025-09-24T19:30:57.354646367Z,160,1,432669,T,B,64.830000000,1,26,8058566319640,0,19954,94238893,CLX5
2025-09-24T19:30:57.354956414Z,2025-09-24T19:30:57.354646367Z,160,1,432669,F,A,64.830000000,1,26,8058566319483,0,19954,94238893,CLX5
2025-09-24T19:30:57.354964970Z,2025-09-24T19:30:57.354646367Z,160,1,432669,C,A,64.830000000,1,26,8058566319483,128,15251,94238894,CLX5
2025-09-24T19:30:57.356267038Z,2025-09-24T19:30:57.355927181Z,160,1,432669,A,B,64.820000000,1,26,8058566319652,128,15424,94238947,CLX5
2025-09-24T19:30:57.356446471Z,2025-09-24T19:30:57.356293559Z,160,1,432669,A,B,64.820000000,1,26,8058566319654,128,18543,94238956,CLX5
2025-09-24T19:30:57.356684876Z,2025-09-24T19:30:57.356469075Z,160,1,432669,A,B,64.820000000,1,26,8058566319657,128,14454,94238965,CLX5
2025-09-24T19:30:57.361914828Z,2025-09-24T19:30:57.361690805Z,160,1,432669,A,A,64.830000000,1,26,8058566319663,128,18901,94238983,CLX5
2025-09-24T19:30:57.364162792Z,2025-09-24T19:30:57.363882331Z,160,1,432669,T,B,64.830000000,1,26,8058566319667,0,18559,94238991,CLX5
2025-09-24T19:30:57.364162792Z,2025-09-24T19:30:57.363882331Z,160,1,432669,F,A,64.830000000,1,26,8058566319663,0,18559,94238991,CLX5
2025-09-24T19:30:57.364171454Z,2025-09-24T19:30:57.363882331Z,160,1,432669,C,A,64.830000000,1,26,8058566319663,128,14974,94238992,CLX5
2025-09-24T19:30:57.368637793Z,2025-09-24T19:30:57.368438653Z,160,1,432669,A,A,64.830000000,1,26,8058566319669,128,17309,94238998,CLX5
2025-09-24T19:30:57.370510425Z,2025-09-24T19:30:57.370259541Z,160,1,432669,T,B,64.830000000,1,26,8058566319671,0,18640,94239003,CLX5
2025-09-24T19:30:57.370510425Z,2025-09-24T19:30:57.370259541Z,160,1,432669,F,A,64.830000000,1,26,8058566319669,0,18640,94239003,CLX5
2025-09-24T19:30:57.370519149Z,2025-09-24T19:30:57.370259541Z,160,1,432669,C,A,64.830000000,1,26,8058566319669,128,14928,94239004,CLX5
2025-09-24T19:30:57.373865495Z,2025-09-24T19:30:57.373558991Z,160,1,432669,A,B,64.830000000,2,26,8058566319675,128,13988,94239021,CLX5
2025-09-24T19:30:57.373920212Z,2025-09-24T19:30:57.373575619Z,160,1,432669,A,B,64.830000000,2,26,8058566319676,128,17679,94239024,CLX5
2025-09-24T19:30:57.374324258Z,2025-09-24T19:30:57.373916269Z,160,1,432669,A,B,64.830000000,1,26,8058566319680,128,17735,94239043,CLX5
2025-09-24T19:30:57.375241440Z,2025-09-24T19:30:57.375002537Z,160,1,432669,T,A,64.830000000,1,26,8058566319682,0,18112,94239074,CLX5
2025-09-24T19:30:57.375241440Z,2025-09-24T19:30:57.375002537Z,160,1,432669,F,B,64.830000000,1,26,8058566319675,0,18112,94239074,CLX5
2025-09-24T19:30:57.375255916Z,2025-09-24T19:30:57.375002537Z,160,1,432669,M,B,64.830000000,1,26,8058566319675,128,18815,94239075,CLX5
2025-09-24T19:30:57.375404486Z,2025-09-24T19:30:57.375223961Z,160,1,432669,C,B,64.830000000,1,26,8058566319675,128,14993,94239079,CLX5
2025-09-24T19:30:57.375673441Z,2025-09-24T19:30:57.375425995Z,160,1,432669,T,A,64.830000000,1,26,8058566319685,0,18686,94239087,CLX5
2025-09-24T19:30:57.375673441Z,2025-09-24T19:30:57.375425995Z,160,1,432669,F,B,64.830000000,1,26,8058566319676,0,18686,94239087,CLX5
2025-09-24T19:30:57.375682326Z,2025-09-24T19:30:57.375425995Z,160,1,432669,M,B,64.830000000,1,26,8058566319676,128,15056,94239088,CLX5
2025-09-24T19:30:57.375913866Z,2025-09-24T19:30:57.375655271Z,160,1,432669,T,A,64.830000000,1,26,8058566319686,0,17912,94239091,CLX5
2025-09-24T19:30:57.375913866Z,2025-09-24T19:30:57.375655271Z,160,1,432669,F,B,64.830000000,1,26,8058566319680,0,17912,94239091,CLX5
2025-09-24T19:30:57.375924794Z,2025-09-24T19:30:57.375655271Z,160,1,432669,C,B,64.830000000,1,26,8058566319680,0,15110,94239092,CLX5
2025-09-24T19:30:57.375924794Z,2025-09-24T19:30:57.375655271Z,160,1,432669,C,B,64.830000000,1,26,8058566319676,128,15110,94239092,CLX5
2025-09-24T19:30:57.379913768Z,2025-09-24T19:30:57.379779211Z,160,1,432669,A,A,64.840000000,1,26,8058566319697,128,18287,94239121,CLX5
2025-09-24T19:30:57.380064957Z,2025-09-24T19:30:57.379937853Z,160,1,432669,C,B,64.820000000,1,26,8058566319657,128,18591,94239122,CLX5
2025-09-24T19:30:57.380095844Z,2025-09-24T19:30:57.379952079Z,160,1,432669,C,B,64.820000000,1,26,8058566319654,128,15319,94239123,CLX5
2025-09-24T19:30:57.380123721Z,2025-09-24T19:30:57.379959491Z,160,1,432669,A,A,64.840000000,1,26,8058566319698,128,14238,94239124,CLX5
2025-09-24T19:30:57.380212090Z,2025-09-24T19:30:57.380091119Z,160,1,432669,C,B,64.820000000,1,26,8058566319652,128,18502,94239125,CLX5
2025-09-24T19:30:57.382073087Z,2025-09-24T19:30:57.381902713Z,160,1,432669,M,A,64.830000000,1,26,8058566319697,128,17961,94239133,CLX5
2025-09-24T19:30:57.382236263Z,2025-09-24T19:30:57.382081803Z,160,1,432669,A,A,64.830000000,1,26,8058566319702,128,15035,94239137,CLX5
2025-09-24T19:30:57.382318105Z,2025-09-24T19:30:57.382105513Z,160,1,432669,A,A,64.840000000,1,26,8058566319703,128,17010,94239142,CLX5
2025-09-24T19:30:58.464677200Z,2025-09-24T19:30:58.464385695Z,160,1,432669,A,A,64.830000000,1,26,8058566319805,128,13852,94239371,CLX5
2025-09-24T19:30:58.464995965Z,2025-09-24T19:30:58.464686737Z,160,1,432669,T,B,64.830000000,3,26,8058566319809,0,17559,94239384,CLX5
2025-09-24T19:30:58.464995965Z,2025-09-24T19:30:58.464686737Z,160,1,432669,F,A,64.830000000,1,26,8058566319697,0,17559,94239384,CLX5
2025-09-24T19:30:58.464995965Z,2025-09-24T19:30:58.464686737Z,160,1,432669,F,A,64.830000000,1,26,8058566319702,0,17559,94239384,CLX5
2025-09-24T19:30:58.464995965Z,2025-09-24T19:30:58.464686737Z,160,1,432669,F,A,64.830000000,1,26,8058566319805,0,17559,94239384,CLX5
2025-09-24T19:30:58.464995965Z,2025-09-24T19:30:58.464686737Z,160,1,432669,C,A,64.830000000,1,26,8058566319697,0,17559,94239384,CLX5
2025-09-24T19:30:58.464995965Z,2025-09-24T19:30:58.464686737Z,160,1,432669,C,A,64.830000000,1,26,8058566319702,0,17559,94239384,CLX5
2025-09-24T19:30:58.464995965Z,2025-09-24T19:30:58.464686737Z,160,1,432669,C,A,64.830000000,1,26,8058566319805,128,17559,94239384,CLX5
2025-09-24T19:30:58.465032988Z,2025-09-24T19:30:58.464698217Z,160,1,432669,A,B,64.830000000,1,26,8058566319810,128,15329,94239388,CLX5
2025-09-24T19:30:58.465056188Z,2025-09-24T19:30:58.464726805Z,160,1,432669,C,A,64.840000000,1,26,8058566319703,128,17268,94239390,CLX5
2025-09-24T19:30:58.465063307Z,2025-09-24T19:30:58.464739343Z,160,1,432669,C,A,64.840000000,1,26,8058566319698,128,15281,94239391,CLX5
2025-09-24T19:30:58.465605771Z,2025-09-24T19:30:58.465037179Z,160,1,432669,C,B,64.820000000,1,26,8058566317789,128,14110,94239416,CLX5
2025-09-24T19:30:58.465637971Z,2025-09-24T19:30:58.465041365Z,160,1,432669,T,A,64.830000000,1,26,8058566319818,0,14969,94239418,CLX5
2025-09-24T19:30:58.465637971Z,2025-09-24T19:30:58.465041365Z,160,1,432669,F,B,64.830000000,1,26,8058566319810,0,14969,94239418,CLX5
2025-09-24T19:30:58.465686675Z,2025-09-24T19:30:58.465041365Z,160,1,432669,C,B,64.830000000,1,26,8058566319810,128,18155,94239419,CLX5
2025-09-24T19:30:58.465912954Z,2025-09-24T19:30:58.465425999Z,160,1,432669,M,B,64.820000000,3,26,8058566280404,128,15353,94239428,CLX5
2025-09-24T19:30:58.466088602Z,2025-09-24T19:30:58.465640993Z,160,1,432669,A,B,64.820000000,1,26,8058566319820,128,18964,94239437,CLX5
2025-09-24T19:30:58.466178776Z,2025-09-24T19:30:58.465792415Z,160,1,432669,A,B,64.820000000,1,26,8058566319823,128,15977,94239442,CLX5
2025-09-24T19:30:58.466211176Z,2025-09-24T19:30:58.465936101Z,160,1,432669,M,B,63.670000000,4,26,8058566280404,128,18584,94239443,CLX5
2025-09-24T19:30:58.466237149Z,2025-09-24T19:30:58.465937907Z,160,1,432669,A,B,64.820000000,1,26,8058566319824,128,15425,94239444,CLX5
2025-09-24T19:30:58.470835607Z,2025-09-24T19:30:58.470650127Z,160,1,432669,A,A,64.830000000,1,26,8058566319829,128,18258,94239463,CLX5
2025-09-24T19:30:58.473743186Z,2025-09-24T19:30:58.473420605Z,160,1,432669,T,B,64.830000000,1,26,8058566319831,0,18746,94239467,CLX5
2025-09-24T19:30:58.473743186Z,2025-09-24T19:30:58.473420605Z,160,1,432669,F,A,64.830000000,1,26,8058566319829,0,18746,94239467,CLX5
2025-09-24T19:30:58.473752010Z,2025-09-24T19:30:58.473420605Z,160,1,432669,C,A,64.830000000,1,26,8058566319829,128,15046,94239468,CLX5
2025-09-24T19:30:58.473793457Z,2025-09-24T19:30:58.473436251Z,160,1,432669,A,B,64.820000000,1,26,8058566319832,128,14899,94239472,CLX5
2025-09-24T19:30:58.474111016Z,2025-09-24T19:30:58.473806813Z,160,1,432669,A,B,64.830000000,1,26,8058566319837,128,15267,94239482,CLX5
2025-09-24T19:30:58.474289121Z,2025-09-24T19:30:58.474113367Z,160,1,432669,C,B,64.820000000,1,26,8058566319832,128,14548,94239490,CLX5
2025-09-24T19:30:58.474746886Z,2025-09-24T19:30:58.474588739Z,160,1,432669,M,B,64.820000000,3,26,8058566319508,128,15138,94239503,CLX5
2025-09-24T19:30:58.478381133Z,2025-09-24T19:30:58.478143231Z,160,1,432669,T,A,64.830000000,1,26,8058566319845,0,18551,94239517,CLX5
2025-09-24T19:30:58.478381133Z,2025-09-24T19:30:58.478143231Z,160,1,432669,F,B,64.830000000,1,26,8058566319837,0,18551,94239517,CLX5
2025-09-24T19:30:58.478389811Z,2025-09-24T19:30:58.478143231Z,160,1,432669,C,B,64.830000000,1,26,8058566319837,128,15106,94239518,CLX5
2025-09-24T19:30:58.478735392Z,2025-09-24T19:30:58.478574119Z,160,1,432669,M,B,63.660000000,4,26,8058566319508,128,14645,94239527,CLX5
2025-09-24T19:30:58.478904666Z,2025-09-24T19:30:58.478780817Z,160,1,432669,C,B,64.820000000,1,26,8058566319824,128,18976,94239529,CLX5
2025-09-24T19:30:58.478931845Z,2025-09-24T19:30:58.478792681Z,160,1,432669,C,B,64.820000000,1,26,8058566319823,128,15812,94239530,CLX5
2025-09-24T19:30:58.478962771Z,2025-09-24T19:30:58.478799381Z,160,1,432669,A,A,64.840000000,1,26,8058566319849,128,14949,94239531,CLX5
2025-09-24T19:30:58.479052783Z,2025-09-24T19:30:58.478936827Z,160,1,432669,A,A,64.840000000,1,26,8058566319850,128,18751,94239532,CLX5
2025-09-24T19:30:58.482028312Z,2025-09-24T19:30:58.481922067Z,160,1,432669,A,B,63.680000000,4,26,8058566319851,128,18938,94239539,CLX5
2025-09-24T19:30:58.486434357Z,2025-09-24T19:30:58.486295075Z,160,1,432669,A,A,64.840000000,1,26,8058566319856,128,18799,94239566,CLX5
2025-09-24T19:30:58.486597557Z,2025-09-24T19:30:58.486460957Z,160,1,432669,A,B,64.820000000,1,26,8058566319857,128,18990,94239567,CLX5
2025-09-24T19:30:58.486621356Z,2025-09-24T19:30:58.486469807Z,160,1,432669,C,A,64.840000000,1,26,8058566319850,128,15073,94239568,CLX5
2025-09-24T19:30:58.486648119Z,2025-09-24T19:30:58.486478677Z,160,1,432669,C,A,64.840000000,1,26,8058566319849,128,14957,94239569,CLX5
2025-09-24T19:30:58.486745036Z,2025-09-24T19:30:58.486621077Z,160,1,432669,A,B,64.820000000,1,26,8058566319858,128,19155,94239570,CLX5
2025-09-24T19:30:58.539916137Z,2025-09-24T19:30:58.539721347Z,160,1,432669,M,A,64.830000000,1,26,8058566319856,128,18752,94239593,CLX5
2025-09-24T19:30:58.838790284Z,2025-09-24T19:30:58.838643737Z,160,1,432669,C,B,64.820000000,1,26,8058566319858,128,18445,94239680,CLX5
2025-09-24T19:30:58.838820526Z,2025-09-24T19:30:58.838656005Z,160,1,432669,C,B,64.820000000,1,26,8058566319857,128,15425,94239681,CLX5
2025-09-24T19:30:58.838851014Z,2025-09-24T19:30:58.838658521Z,160,1,432669,C,B,64.820000000,1,26,8058566319820,128,15385,94239682,CLX5
2025-09-24T19:30:59.399072446Z,2025-09-24T19:30:59.398960427Z,160,1,432669,A,A,64.830000000,2,26,8058566319927,128,15108,94239742,CLX5
2025-09-24T19:30:59.399181773Z,2025-09-24T19:30:59.399015895Z,160,1,432669,A,A,64.830000000,2,26,8058566319928,128,14986,94239746,CLX5
2025-09-24T19:30:59.399228373Z,2025-09-24T19:30:59.399016075Z,160,1,432669,A,A,64.830000000,1,26,8058566319929,128,21273,94239748,CLX5
2025-09-24T19:30:59.399260496Z,2025-09-24T19:30:59.399020599Z,160,1,432669,A,A,64.830000000,2,26,8058566319930,128,17233,94239749,CLX5
2025-09-24T19:30:59.399393207Z,2025-09-24T19:30:59.399185249Z,160,1,432669,A,A,64.830000000,1,26,8058566319932,128,16413,94239753,CLX5
2025-09-24T19:30:59.399426645Z,2025-09-24T19:30:59.399191451Z,160,1,432669,C,B,64.820000000,2,26,8058566317788,128,15257,94239754,CLX5
2025-09-24T19:30:59.399560039Z,2025-09-24T19:30:59.399435071Z,160,1,432669,A,A,64.830000000,1,26,8058566319933,128,19433,94239759,CLX5
2025-09-24T19:30:59.399990419Z,2025-09-24T19:30:59.399755529Z,160,1,432669,C,B,64.820000000,2,26,8058566317770,128,16052,94239768,CLX5
2025-09-24T19:30:59.401107908Z,2025-09-24T19:30:59.400465449Z,160,1,432669,A,A,64.860000000,1,26,8058566319952,128,15216,94239813,CLX5
2025-09-24T19:30:59.469483583Z,2025-09-24T19:30:59.469152419Z,160,1,432669,A,A,64.830000000,1,26,8058566319972,128,16887,94239920,CLX5
2025-09-24T19:30:59.469578764Z,2025-09-24T19:30:59.469161843Z,160,1,432669,A,A,64.830000000,2,26,8058566319973,128,15201,94239924,CLX5
2025-09-24T19:30:59.469597364Z,2025-09-24T19:30:59.469164817Z,160,1,432669,C,B,64.810000000,2,26,8058566319302,128,14871,94239926,CLX5
2025-09-24T19:30:59.469657910Z,2025-09-24T19:30:59.469165687Z,160,1,432669,A,A,64.830000000,1,26,8058566319974,128,15064,94239930,CLX5
2025-09-24T19:30:59.469810765Z,2025-09-24T19:30:59.469169295Z,160,1,432669,A,A,64.830000000,2,26,8058566319976,128,15893,94239936,CLX5
2025-09-24T19:30:59.469848556Z,2025-09-24T19:30:59.469172291Z,160,1,432669,C,B,64.820000000,2,26,8058566317765,128,19003,94239937,CLX5
2025-09-24T19:30:59.470844577Z,2025-09-24T19:30:59.469517201Z,160,1,432669,C,B,64.820000000,3,26,8058566315628,128,15818,94239994,CLX5
2025-09-24T19:30:59.471684679Z,2025-09-24T19:30:59.470263607Z,160,1,432669,C,B,64.820000000,1,26,8058566317999,128,15499,94240029,CLX5
2025-09-24T19:30:59.471705475Z,2025-09-24T19:30:59.470294709Z,160,1,432669,M,A,64.940000000,1,26,8058565075241,128,15060,94240031,CLX5
2025-09-24T19:30:59.472062116Z,2025-09-24T19:30:59.470602645Z,160,1,432669,C,B,64.820000000,1,26,8058566313296,128,15520,94240047,CLX5
2025-09-24T19:30:59.472299054Z,2025-09-24T19:30:59.470847703Z,160,1,432669,A,A,64.830000000,1,26,8058566319992,128,18901,94240058,CLX5
2025-09-24T19:30:59.472332806Z,2025-09-24T19:30:59.470849489Z,160,1,432669,C,B,64.820000000,1,26,8058566314905,128,16504,94240059,CLX5
2025-09-24T19:30:59.472358970Z,2025-09-24T19:30:59.470850545Z,160,1,432669,C,B,64.790000000,1,26,8058566312959,128,14800,94240060,CLX5
2025-09-24T19:30:59.472989243Z,2025-09-24T19:30:59.471700107Z,160,1,432669,A,A,64.830000000,1,26,8058566319995,128,15700,94240104,CLX5
2025-09-24T19:30:59.474837944Z,2025-09-24T19:30:59.473859129Z,160,1,432669,C,B,64.820000000,2,26,8058566312953,128,16529,94240192,CLX5
2025-09-24T19:30:59.475028806Z,2025-09-24T19:30:59.473915305Z,160,1,432669,A,A,64.830000000,2,26,8058566320018,128,15101,94240201,CLX5
2025-09-24T19:30:59.475231846Z,2025-09-24T19:30:59.473938095Z,160,1,432669,M,B,64.800000000,1,26,8058566311303,128,16396,94240210,CLX5
2025-09-24T19:30:59.476461196Z,2025-09-24T19:30:59.475313677Z,160,1,432669,C,B,64.820000000,1,26,8058566312891,128,17094,94240267,CLX5
2025-09-24T19:30:59.476669574Z,2025-09-24T19:30:59.475522199Z,160,1,432669,A,A,64.860000000,2,26,8058566320040,128,15219,94240277,CLX5
2025-09-24T19:30:59.477322724Z,2025-09-24T19:30:59.475840999Z,160,1,432669,C,B,64.820000000,3,26,8058566313288,128,15726,94240304,CLX5
2025-09-24T19:30:59.477569823Z,2025-09-24T19:30:59.475851175Z,160,1,432669,A,B,64.790000000,1,26,8058566320052,128,15719,94240312,CLX5
2025-09-24T19:30:59.477962934Z,2025-09-24T19:30:59.476077303Z,160,1,432669,M,B,64.810000000,1,26,8058566311303,128,19503,94240334,CLX5
2025-09-24T19:30:59.478085255Z,2025-09-24T19:30:59.476237309Z,160,1,432669,C,B,64.820000000,1,26,8058566314163,128,18423,94240340,CLX5
2025-09-24T19:30:59.478266378Z,2025-09-24T19:30:59.476663511Z,160,1,432669,M,A,64.840000000,1,26,8058566173085,128,15306,94240351,CLX5
2025-09-24T19:30:59.479913644Z,2025-09-24T19:30:59.479177197Z,160,1,432669,C,A,64.840000000,1,26,8058566319390,128,14204,94240441,CLX5
2025-09-24T19:30:59.509529197Z,2025-09-24T19:30:59.509402925Z,160,1,432669,C,A,64.880000000,2,26,8058566313101,128,18234,94240559,CLX5
2025-09-24T19:30:59.509563817Z,2025-09-24T19:30:59.509403539Z,160,1,432669,A,B,64.790000000,2,26,8058566320130,128,14928,94240560,CLX5
2025-09-24T19:30:59.658942884Z,2025-09-24T19:30:59.658776677Z,160,1,432669,A,B,64.820000000,2,26,8058566320217,128,18861,94240733,CLX5
2025-09-24T19:31:00.240602524Z,2025-09-24T19:31:00.240421081Z,160,1,432669,A,B,64.820000000,1,26,8058566320267,128,18557,94240853,CLX5
2025-09-24T19:31:00.615022929Z,2025-09-24T19:31:00.614666819Z,160,1,432669,T,A,64.820000000,1,26,8058566320272,0,29808,94240863,CLX5
2025-09-24T19:31:00.615022929Z,2025-09-24T19:31:00.614666819Z,160,1,432669,F,B,64.820000000,1,26,8058566314839,0,29808,94240863,CLX5
2025-09-24T19:31:00.615045353Z,2025-09-24T19:31:00.614666819Z,160,1,432669,C,B,64.820000000,1,26,8058566314839,128,27240,94240864,CLX5
2025-09-24T19:31:04.110888513Z,2025-09-24T19:31:04.110602635Z,160,1,432669,T,A,64.820000000,1,26,8058566320426,0,21561,94241330,CLX5
2025-09-24T19:31:04.110888513Z,2025-09-24T19:31:04.110602635Z,160,1,432669,F,B,64.820000000,1,26,8058566314284,0,21561,94241330,CLX5
2025-09-24T19:31:04.110901906Z,2025-09-24T19:31:04.110602635Z,160,1,432669,C,B,64.820000000,1,26,8058566314284,128,15113,94241331,CLX5
2025-09-24T19:31:04.636208772Z,2025-09-24T19:31:04.636080813Z,160,1,432669,C,A,65.050000000,1,26,8058566315368,128,21575,94241335,CLX5
2025-09-24T19:31:04.730010769Z,2025-09-24T19:31:04.729895097Z,160,1,432669,A,A,65.040000000,1,26,8058566320427,128,18654,94241336,CLX5
2025-09-24T19:31:07.568194869Z,2025-09-24T19:31:07.568020899Z,160,1,432669,A,B,64.820000000,2,26,8058566320436,128,20779,94241362,CLX5
2025-09-24T19:31:07.568343055Z,2025-09-24T19:31:07.568196783Z,160,1,432669,A,B,64.820000000,2,26,8058566320438,128,24556,94241366,CLX5
2025-09-24T19:31:07.568481610Z,2025-09-24T19:31:07.568342371Z,160,1,432669,C,A,64.830000000,2,26,8058566320018,128,22697,94241369,CLX5
2025-09-24T19:31:07.570049389Z,2025-09-24T19:31:07.569165189Z,160,1,432669,C,A,64.830000000,1,26,8058566319992,128,18045,94241424,CLX5
2025-09-24T19:31:07.570457455Z,2025-09-24T19:31:07.569174769Z,160,1,432669,A,B,64.820000000,1,26,8058566320455,128,20008,94241442,CLX5
2025-09-24T19:31:07.570956452Z,2025-09-24T19:31:07.569950049Z,160,1,432669,C,B,64.820000000,1,26,8058566320455,128,15453,94241469,CLX5
2025-09-24T19:31:07.571485814Z,2025-09-24T19:31:07.571171405Z,160,1,432669,C,B,64.820000000,2,26,8058566320438,128,17016,94241497,CLX5
2025-09-24T19:31:07.578536444Z,2025-09-24T19:31:07.578347567Z,160,1,432669,A,B,64.820000000,1,26,8058566320468,128,16080,94241513,CLX5
2025-09-24T19:31:07.579896846Z,2025-09-24T19:31:07.579759473Z,160,1,432669,C,B,64.820000000,1,26,8058566320468,128,20209,94241543,CLX5
2025-09-24T19:31:07.587347345Z,2025-09-24T19:31:07.587196093Z,160,1,432669,A,A,64.830000000,1,26,8058566320480,128,19323,94241571,CLX5
2025-09-24T19:31:07.749029083Z,2025-09-24T19:31:07.748813051Z,160,1,432669,A,B,64.820000000,1,26,8058566320502,128,16828,94241620,CLX5
2025-09-24T19:31:10.507521475Z,2025-09-24T19:31:10.507189327Z,160,1,432669,T,A,64.820000000,1,26,8058566320525,0,19152,94241665,CLX5
2025-09-24T19:31:10.507521475Z,2025-09-24T19:31:10.507189327Z,160,1,432669,F,B,64.820000000,1,26,8058566320217,0,19152,94241665,CLX5
2025-09-24T19:31:10.507533694Z,2025-09-24T19:31:10.507189327Z,160,1,432669,M,B,64.820000000,1,26,8058566320217,128,17398,94241666,CLX5
2025-09-24T19:31:10.507925131Z,2025-09-24T19:31:10.507581411Z,160,1,432669,C,B,64.820000000,1,26,8058566320502,128,20976,94241673,CLX5
2025-09-24T19:31:10.508101492Z,2025-09-24T19:31:10.507935541Z,160,1,432669,C,B,64.820000000,1,26,8058566320217,128,14814,94241675,CLX5
2025-09-24T19:31:10.988454031Z,2025-09-24T19:31:10.988307401Z,160,1,432669,C,B,64.810000000,4,26,8058566306863,128,18934,94241765,CLX5
2025-09-24T19:31:11.322039550Z,2025-09-24T19:31:11.321858055Z,160,1,432669,A,B,64.820000000,2,26,8058566320558,128,21789,94241769,CLX5
2025-09-24T19:31:11.322059071Z,2025-09-24T19:31:11.321858235Z,160,1,432669,A,B,64.820000000,1,26,8058566320559,128,17645,94241771,CLX5
2025-09-24T19:31:11.322115463Z,2025-09-24T19:31:11.321894611Z,160,1,432669,A,B,64.820000000,2,26,8058566320560,128,16279,94241773,CLX5
2025-09-24T19:31:11.322277886Z,2025-09-24T19:31:11.322084201Z,160,1,432669,A,B,64.820000000,1,26,8058566320562,128,15470,94241781,CLX5
2025-09-24T19:31:11.325509069Z,2025-09-24T19:31:11.325366123Z,160,1,432669,C,A,64.830000000,1,26,8058566320480,128,19490,94241799,CLX5
2025-09-24T19:31:12.645393183Z,2025-09-24T19:31:12.645224575Z,160,1,432669,A,A,64.830000000,1,26,8058566320580,128,18427,94241829,CLX5
2025-09-24T19:31:12.645541522Z,2025-09-24T19:31:12.645400363Z,160,1,432669,C,B,64.820000000,2,26,8058566320560,128,19326,94241830,CLX5
2025-09-24T19:31:12.645584252Z,2025-09-24T19:31:12.645448515Z,160,1,432669,C,B,64.820000000,1,26,8058566320562,128,16937,94241831,CLX5
2025-09-24T19:31:12.645723483Z,2025-09-24T19:31:12.645583811Z,160,1,432669,C,B,64.820000000,2,26,8058566320436,128,21774,94241832,CLX5
2025-09-24T19:31:13.471197590Z,2025-09-24T19:31:13.471040395Z,160,1,432669,C,A,64.840000000,1,26,8058566317159,128,22021,94241843,CLX5
2025-09-24T19:31:16.377320767Z,2025-09-24T19:31:16.376961839Z,160,1,432669,T,A,64.820000000,1,26,8058566320602,0,18324,94241910,CLX5
2025-09-24T19:31:16.377320767Z,2025-09-24T19:31:16.376961839Z,160,1,432669,F,B,64.820000000,1,26,8058566320267,0,18324,94241910,CLX5
2025-09-24T19:31:16.377331341Z,2025-09-24T19:31:16.376961839Z,160,1,432669,C,B,64.820000000,1,26,8058566320267,128,16250,94241911,CLX5
2025-09-24T19:31:16.586318704Z,2025-09-24T19:31:16.586003471Z,160,1,432669,T,A,64.820000000,1,26,8058566320607,0,19107,94241926,CLX5
2025-09-24T19:31:16.586318704Z,2025-09-24T19:31:16.586003471Z,160,1,432669,F,B,64.820000000,1,26,8058566320558,0,19107,94241926,CLX5
2025-09-24T19:31:16.586328219Z,2025-09-24T19:31:16.586003471Z,160,1,432669,M,B,64.820000000,1,26,8058566320558,128,16197,94241927,CLX5
2025-09-24T19:31:16.586458311Z,2025-09-24T19:31:16.586298293Z,160,1,432669,A,A,64.830000000,2,26,8058566320608,128,20144,94241930,CLX5
2025-09-24T19:31:16.586484521Z,2025-09-24T19:31:16.586305973Z,160,1,432669,A,A,64.830000000,1,26,8058566320609,128,14735,94241931,CLX5
2025-09-24T19:31:16.586516054Z,2025-09-24T19:31:16.586318567Z,160,1,432669,A,A,64.830000000,1,26,8058566320610,128,15999,94241932,CLX5
2025-09-24T19:31:16.672918739Z,2025-09-24T19:31:16.672749125Z,160,1,432669,A,B,64.820000000,1,26,8058566320612,128,18312,94241940,CLX5
2025-09-24T19:31:16.673093434Z,2025-09-24T19:31:16.672935837Z,160,1,432669,C,A,64.830000000,1,26,8058566320610,128,15326,94241945,CLX5
2025-09-24T19:31:17.561091362Z,2025-09-24T19:31:17.560932723Z,160,1,432669,A,A,64.830000000,1,26,8058566320622,128,19106,94241978,CLX5
2025-09-24T19:31:21.500449893Z,2025-09-24T19:31:21.500102713Z,160,1,432669,T,A,64.820000000,1,26,8058566320634,0,24305,94242003,CLX5
2025-09-24T19:31:21.500449893Z,2025-09-24T19:31:21.500102713Z,160,1,432669,F,B,64.820000000,1,26,8058566320558,0,24305,94242003,CLX5
2025-09-24T19:31:21.500461843Z,2025-09-24T19:31:21.500102713Z,160,1,432669,C,B,64.820000000,1,26,8058566320558,128,18508,94242004,CLX5
2025-09-24T19:31:21.500569626Z,2025-09-24T19:31:21.500407365Z,160,1,432669,C,B,64.820000000,1,26,8058566320559,128,22722,94242007,CLX5
2025-09-24T19:31:21.500597756Z,2025-09-24T19:31:21.500407517Z,160,1,432669,C,B,64.820000000,1,26,8058566320612,128,18636,94242009,CLX5
2025-09-24T19:31:21.500836054Z,2025-09-24T19:31:21.500616943Z,160,1,432669,A,B,64.810000000,2,26,8058566320639,128,18054,94242019,CLX5
2025-09-24T19:31:21.500872555Z,2025-09-24T19:31:21.500628789Z,160,1,432669,A,A,64.830000000,3,26,8058566320640,128,18139,94242020,CLX5
2025-09-24T19:31:21.500907382Z,2025-09-24T19:31:21.500663999Z,160,1,432669,A,A,64.830000000,1,26,8058566320641,128,22711,94242021,CLX5
2025-09-24T19:31:21.500966576Z,2025-09-24T19:31:21.500840843Z,160,1,432669,C,A,64.830000000,1,26,8058566320609,128,18178,94242022,CLX5
2025-09-24T19:31:21.500993363Z,2025-09-24T19:31:21.500869393Z,160,1,432669,A,A,64.830000000,1,26,8058566320642,128,16749,94242023,CLX5
2025-09-24T19:31:21.501034871Z,2025-09-24T19:31:21.500905851Z,160,1,432669,A,A,64.830000000,1,26,8058566320643,128,21175,94242024,CLX5
2025-09-24T19:31:21.501064768Z,2025-09-24T19:31:21.500918215Z,160,1,432669,M,B,63.650000000,4,26,8058566291224,128,17382,94242025,CLX5
2025-09-24T19:31:21.501257449Z,2025-09-24T19:31:21.501076647Z,160,1,432669,A,B,64.810000000,1,26,8058566320645,128,19701,94242027,CLX5
2025-09-24T19:31:21.501283867Z,2025-09-24T19:31:21.501114699Z,160,1,432669,C,B,64.790000000,1,26,8058566320052,128,17452,94242028,CLX5
2025-09-24T19:31:21.501431638Z,2025-09-24T19:31:21.501259767Z,160,1,432669,A,A,64.830000000,1,26,8058566320647,128,17526,94242033,CLX5
2025-09-24T19:31:21.509575205Z,2025-09-24T19:31:21.509429277Z,160,1,432669,A,B,64.770000000,2,26,8058566320648,128,21652,94242040,CLX5
2025-09-24T19:31:21.515148611Z,2025-09-24T19:31:21.515009029Z,160,1,432669,C,A,64.830000000,1,26,8058566320643,128,21313,94242041,CLX5
2025-09-24T19:31:21.515174707Z,2025-09-24T19:31:21.515015807Z,160,1,432669,C,A,64.830000000,1,26,8058566320642,128,18497,94242042,CLX5
2025-09-24T19:31:21.515201140Z,2025-09-24T19:31:21.515026099Z,160,1,432669,C,A,64.830000000,1,26,8058566320641,128,17286,94242043,CLX5
2025-09-24T19:31:21.515329274Z,2025-09-24T19:31:21.515208665Z,160,1,432669,C,B,64.810000000,1,26,8058566320645,128,17772,94242046,CLX5
2025-09-24T19:31:21.515478220Z,2025-09-24T19:31:21.515347339Z,160,1,432669,A,B,64.810000000,1,26,8058566320650,128,21345,94242047,CLX5
2025-09-24T19:31:21.569609318Z,2025-09-24T19:31:21.569460001Z,160,1,432669,C,B,64.800000000,5,26,8058566286350,128,21489,94242050,CLX5
2025-09-24T19:31:21.773552204Z,2025-09-24T19:31:21.773408461Z,160,1,432669,C,B,64.810000000,1,26,8058566320650,128,20730,94242053,CLX5
2025-09-24T19:31:21.773715265Z,2025-09-24T19:31:21.773576607Z,160,1,432669,A,B,64.810000000,1,26,8058566320653,128,20952,94242054,CLX5
2025-09-24T19:31:23.142370719Z,2025-09-24T19:31:23.141978327Z,160,1,432669,T,A,64.810000000,5,26,8058566320655,0,23230,94242068,CLX5
2025-09-24T19:31:23.142370719Z,2025-09-24T19:31:23.141978327Z,160,1,432669,F,B,64.810000000,1,26,8058566288068,0,23230,94242068,CLX5
2025-09-24T19:31:23.142370719Z,2025-09-24T19:31:23.141978327Z,160,1,432669,F,B,64.810000000,2,26,8058566288099,0,23230,94242068,CLX5
2025-09-24T19:31:23.142370719Z,2025-09-24T19:31:23.141978327Z,160,1,432669,F,B,64.810000000,1,26,8058566288142,0,23230,94242068,CLX5
2025-09-24T19:31:23.142370719Z,2025-09-24T19:31:23.141978327Z,160,1,432669,F,B,64.810000000,1,26,8058566288513,0,23230,94242068,CLX5
2025-09-24T19:31:23.142385441Z,2025-09-24T19:31:23.141978327Z,160,1,432669,C,B,64.810000000,1,26,8058566288068,0,18609,94242069,CLX5
2025-09-24T19:31:23.142385441Z,2025-09-24T19:31:23.141978327Z,160,1,432669,C,B,64.810000000,2,26,8058566288099,0,18609,94242069,CLX5
2025-09-24T19:31:23.142385441Z,2025-09-24T19:31:23.141978327Z,160,1,432669,C,B,64.810000000,1,26,8058566288142,0,18609,94242069,CLX5
2025-09-24T19:31:23.142385441Z,2025-09-24T19:31:23.141978327Z,160,1,432669,C,B,64.810000000,1,26,8058566288513,128,18609,94242069,CLX5
2025-09-24T19:31:23.142516593Z,2025-09-24T19:31:23.142326273Z,160,1,432669,A,A,64.820000000,2,26,8058566320657,128,20660,94242072,CLX5
2025-09-24T19:31:23.143019638Z,2025-09-24T19:31:23.142346413Z,160,1,432669,C,B,64.810000000,1,26,8058566320653,128,17652,94242090,CLX5
2025-09-24T19:31:23.143077919Z,2025-09-24T19:31:23.142348065Z,160,1,432669,C,A,64.820000000,2,26,8058566320657,128,20804,94242091,CLX5
2025-09-24T19:31:23.143178291Z,2025-09-24T19:31:23.142431773Z,160,1,432669,A,B,64.810000000,1,26,8058566320663,128,21010,94242097,CLX5
2025-09-24T19:31:23.143307984Z,2025-09-24T19:31:23.142535179Z,160,1,432669,C,B,64.810000000,1,26,8058566320663,128,17478,94242105,CLX5
2025-09-24T19:31:23.143641893Z,2025-09-24T19:31:23.142871701Z,160,1,432669,A,B,64.810000000,1,26,8058566320665,128,17825,94242123,CLX5
2025-09-24T19:31:23.143674961Z,2025-09-24T19:31:23.142892205Z,160,1,432669,C,A,64.830000000,1,26,8058566320580,128,17316,94242124,CLX5
2025-09-24T19:31:23.143807219Z,2025-09-24T19:31:23.142954779Z,160,1,432669,M,A,64.840000000,4,26,8058566275421,128,17730,94242129,CLX5
2025-09-24T19:31:23.143994056Z,2025-09-24T19:31:23.143092071Z,160,1,432669,A,A,64.820000000,1,26,8058566320669,128,18700,94242137,CLX5
2025-09-24T19:31:23.144508888Z,2025-09-24T19:31:23.144217371Z,160,1,432669,M,B,64.810000000,2,26,8058566291224,128,17718,94242165,CLX5
2025-09-24T19:31:23.144540736Z,2025-09-24T19:31:23.144290635Z,160,1,432669,C,A,64.830000000,1,26,8058566320647,128,15100,94242166,CLX5
2025-09-24T19:31:23.144710524Z,2025-09-24T19:31:23.144577491Z,160,1,432669,A,A,64.830000000,1,26,8058566320675,128,15152,94242173,CLX5
2025-09-24T19:31:23.174464244Z,2025-09-24T19:31:23.174330765Z,160,1,432669,C,A,64.830000000,1,26,8058566320675,128,18554,94242186,CLX5
2025-09-24T19:31:23.193292534Z,2025-09-24T19:31:23.193126947Z,160,1,432669,A,A,64.820000000,1,26,8058566320677,128,18277,94242187,CLX5
2025-09-24T19:31:23.194669047Z,2025-09-24T19:31:23.194522111Z,160,1,432669,A,A,64.820000000,1,26,8058566320680,128,18350,94242196,CLX5
2025-09-24T19:31:23.194811896Z,2025-09-24T19:31:23.194677259Z,160,1,432669,A,A,64.820000000,1,26,8058566320681,128,18271,94242199,CLX5
2025-09-24T19:31:23.195168298Z,2025-09-24T19:31:23.194822999Z,160,1,432669,T,B,64.820000000,4,26,8058566320683,0,18546,94242204,CLX5
2025-09-24T19:31:23.195168298Z,2025-09-24T19:31:23.194822999Z,160,1,432669,F,A,64.820000000,1,26,8058566320669,0,18546,94242204,CLX5
2025-09-24T19:31:23.195168298Z,2025-09-24T19:31:23.194822999Z,160,1,432669,F,A,64.820000000,1,26,8058566320677,0,18546,94242204,CLX5
2025-09-24T19:31:23.195168298Z,2025-09-24T19:31:23.194822999Z,160,1,432669,F,A,64.820000000,1,26,8058566320680,0,18546,94242204,CLX5
2025-09-24T19:31:23.195168298Z,2025-09-24T19:31:23.194822999Z,160,1,432669,F,A,64.820000000,1,26,8058566320681,0,18546,94242204,CLX5
2025-09-24T19:31:23.195178773Z,2025-09-24T19:31:23.194822999Z,160,1,432669,C,A,64.820000000,1,26,8058566320669,0,15447,94242205,CLX5
2025-09-24T19:31:23.195178773Z,2025-09-24T19:31:23.194822999Z,160,1,432669,C,A,64.820000000,1,26,8058566320677,0,15447,94242205,CLX5
2025-09-24T19:31:23.195178773Z,2025-09-24T19:31:23.194822999Z,160,1,432669,C,A,64.820000000,1,26,8058566320680,0,15447,94242205,CLX5
2025-09-24T19:31:23.195178773Z,2025-09-24T19:31:23.194822999Z,160,1,432669,C,A,64.820000000,1,26,8058566320681,128,15447,94242205,CLX5
2025-09-24T19:31:23.195229827Z,2025-09-24T19:31:23.194833865Z,160,1,432669,A,B,64.820000000,1,26,8058566320684,128,14733,94242209,CLX5
2025-09-24T19:31:23.195339960Z,2025-09-24T19:31:23.195153321Z,160,1,432669,A,B,64.810000000,1,26,8058566320687,128,15537,94242215,CLX5
2025-09-24T19:31:23.195376761Z,2025-09-24T19:31:23.195168227Z,160,1,432669,A,B,64.810000000,1,26,8058566320689,128,15571,94242216,CLX5
2025-09-24T19:31:23.195429904Z,2025-09-24T19:31:23.195169757Z,160,1,432669,A,B,64.820000000,2,26,8058566320690,128,20018,94242217,CLX5
2025-09-24T19:31:23.195821655Z,2025-09-24T19:31:23.195238565Z,160,1,432669,A,B,64.810000000,2,26,8058566320694,128,19133,94242237,CLX5
2025-09-24T19:31:23.195892361Z,2025-09-24T19:31:23.195391813Z,160,1,432669,M,B,63.650000000,4,26,8058566291224,128,15717,94242240,CLX5
2025-09-24T19:31:23.195944844Z,2025-09-24T19:31:23.195598683Z,160,1,432669,M,A,65.980000000,4,26,8058566275421,128,19109,94242242,CLX5
2025-09-24T19:31:23.196130029Z,2025-09-24T19:31:23.195770997Z,160,1,432669,A,B,64.790000000,1,26,8058566320697,128,14958,94242252,CLX5
2025-09-24T19:31:23.196303450Z,2025-09-24T19:31:23.195924147Z,160,1,432669,A,B,64.810000000,1,26,8058566320698,128,15217,94242260,CLX5
2025-09-24T19:31:23.209952059Z,2025-09-24T19:31:23.209817807Z,160,1,432669,C,B,64.810000000,1,26,8058566320698,128,18183,94242272,CLX5
2025-09-24T19:31:23.209986594Z,2025-09-24T19:31:23.209831591Z,160,1,432669,A,A,64.830000000,1,26,8058566320699,128,15709,94242273,CLX5
2025-09-24T19:31:23.210105443Z,2025-09-24T19:31:23.209984303Z,160,1,432669,A,A,64.830000000,1,26,8058566320700,128,18698,94242274,CLX5
2025-09-24T19:31:23.210131247Z,2025-09-24T19:31:23.210011871Z,160,1,432669,A,A,64.830000000,1,26,8058566320701,128,15434,94242275,CLX5
2025-09-24T19:31:24.280589646Z,2025-09-24T19:31:24.280440171Z,160,1,432669,C,A,64.830000000,1,26,8058566320701,128,18495,94242306,CLX5
2025-09-24T19:31:24.280617008Z,2025-09-24T19:31:24.280446411Z,160,1,432669,C,A,64.830000000,1,26,8058566320700,128,15385,94242307,CLX5
2025-09-24T19:31:24.833711857Z,2025-09-24T19:31:24.833566971Z,160,1,432669,C,A,64.830000000,1,26,8058566320699,128,20112,94242319,CLX5
2025-09-24T19:31:24.920438599Z,2025-09-24T19:31:24.920274725Z,160,1,432669,A,A,64.830000000,1,26,8058566320718,128,15306,94242341,CLX5
2025-09-24T19:31:24.920597766Z,2025-09-24T19:31:24.920453661Z,160,1,432669,C,B,64.810000000,1,26,8058566320689,128,15712,94242348,CLX5
2025-09-24T19:31:24.921004140Z,2025-09-24T19:31:24.920857783Z,160,1,432669,C,B,64.820000000,2,26,8058566320690,128,18082,94242360,CLX5
2025-09-24T19:31:24.968596024Z,2025-09-24T19:31:24.968307953Z,160,1,432669,T,A,64.820000000,1,26,8058566320724,0,20941,94242370,CLX5
2025-09-24T19:31:24.968596024Z,2025-09-24T19:31:24.968307953Z,160,1,432669,F,B,64.820000000,1,26,8058566320684,0,20941,94242370,CLX5
2025-09-24T19:31:24.968604986Z,2025-09-24T19:31:24.968307953Z,160,1,432669,C,B,64.820000000,1,26,8058566320684,128,14898,94242371,CLX5
2025-09-24T19:31:24.968983582Z,2025-09-24T19:31:24.968629519Z,160,1,432669,C,B,64.810000000,1,26,8058566320687,128,15228,94242383,CLX5
2025-09-24T19:31:24.969425873Z,2025-09-24T19:31:24.968797321Z,160,1,432669,A,A,64.830000000,1,26,8058566320733,128,15428,94242406,CLX5
2025-09-24T19:31:24.969713781Z,2025-09-24T19:31:24.968993829Z,160,1,432669,A,B,64.810000000,1,26,8058566320736,128,15316,94242423,CLX5
2025-09-24T19:31:24.969764697Z,2025-09-24T19:31:24.969019839Z,160,1,432669,A,A,64.830000000,1,26,8058566320737,128,14249,94242425,CLX5
2025-09-24T19:31:24.969821158Z,2025-09-24T19:31:24.969085077Z,160,1,432669,A,A,64.830000000,1,26,8058566320738,128,15388,94242428,CLX5
2025-09-24T19:31:24.969934501Z,2025-09-24T19:31:24.969130387Z,160,1,432669,A,A,64.830000000,1,26,8058566320740,128,15127,94242433,CLX5
2025-09-24T19:31:24.969967408Z,2025-09-24T19:31:24.969132383Z,160,1,432669,C,B,64.790000000,1,26,8058566320697,128,15024,94242434,CLX5
2025-09-24T19:31:25.036480183Z,2025-09-24T19:31:25.036340785Z,160,1,432669,C,A,64.830000000,1,26,8058566320740,128,18277,94242450,CLX5
2025-09-24T19:31:25.036506478Z,2025-09-24T19:31:25.036348617Z,160,1,432669,C,A,64.830000000,1,26,8058566320737,128,15092,94242451,CLX5
2025-09-24T19:31:25.036534688Z,2025-09-24T19:31:25.036357219Z,160,1,432669,C,A,64.830000000,1,26,8058566320733,128,14995,94242452,CLX5
2025-09-24T19:31:26.602075562Z,2025-09-24T19:31:26.601811361Z,160,1,432669,A,A,64.820000000,3,26,8058566320762,128,18155,94242496,CLX5
2025-09-24T19:31:26.602756391Z,2025-09-24T19:31:26.601912023Z,160,1,432669,C,B,64.810000000,1,26,8058566320665,128,18660,94242550,CLX5
2025-09-24T19:31:26.602895300Z,2025-09-24T19:31:26.602047529Z,160,1,432669,A,A,64.820000000,2,26,8058566320770,128,22911,94242557,CLX5
2025-09-24T19:31:26.603011338Z,2025-09-24T19:31:26.602048681Z,160,1,432669,C,B,64.780000000,1,26,8058566302456,128,18354,94242560,CLX5
2025-09-24T19:31:26.603038923Z,2025-09-24T19:31:26.602048829Z,160,1,432669,C,B,64.800000000,2,26,8058566302528,128,15069,94242561,CLX5
2025-09-24T19:31:26.603067868Z,2025-09-24T19:31:26.602048979Z,160,1,432669,C,B,64.770000000,1,26,8058566302713,128,15228,94242562,CLX5
2025-09-24T19:31:26.603247939Z,2025-09-24T19:31:26.602049603Z,160,1,432669,C,B,64.790000000,2,26,8058566320130,128,15441,94242568,CLX5
2025-09-24T19:31:26.603576780Z,2025-09-24T19:31:26.602073735Z,160,1,432669,A,A,64.820000000,1,26,8058566320777,128,17041,94242580,CLX5
2025-09-24T19:31:26.603616314Z,2025-09-24T19:31:26.602075639Z,160,1,432669,A,A,64.820000000,2,26,8058566320778,128,19904,94242581,CLX5
2025-09-24T19:31:26.603739096Z,2025-09-24T19:31:26.602082915Z,160,1,432669,C,B,64.810000000,2,26,8058566320694,128,15378,94242586,CLX5
2025-09-24T19:31:26.603778200Z,2025-09-24T19:31:26.602086829Z,160,1,432669,A,A,64.820000000,2,26,8058566320780,128,16282,94242587,CLX5
2025-09-24T19:31:26.603812996Z,2025-09-24T19:31:26.602087011Z,160,1,432669,A,A,64.820000000,1,26,8058566320781,128,18520,94242588,CLX5
2025-09-24T19:31:26.603984474Z,2025-09-24T19:31:26.602108737Z,160,1,432669,A,A,64.820000000,1,26,8058566320783,128,15756,94242596,CLX5
2025-09-24T19:31:26.604077604Z,2025-09-24T19:31:26.602133925Z,160,1,432669,A,A,64.820000000,1,26,8058566320785,128,15371,94242602,CLX5
2025-09-24T19:31:26.604306871Z,2025-09-24T19:31:26.602355159Z,160,1,432669,M,A,64.840000000,4,26,8058566275421,128,15353,94242612,CLX5
2025-09-24T19:31:26.604400554Z,2025-09-24T19:31:26.602491547Z,160,1,432669,C,A,64.830000000,1,26,8058566320738,128,15059,94242617,CLX5
2025-09-24T19:31:26.604549485Z,2025-09-24T19:31:26.602700493Z,160,1,432669,A,A,64.820000000,2,26,8058566320792,128,18540,94242624,CLX5
2025-09-24T19:31:26.604580135Z,2025-09-24T19:31:26.602700877Z,160,1,432669,C,A,64.820000000,2,26,8058566320778,128,15723,94242625,CLX5
2025-09-24T19:31:26.605305457Z,2025-09-24T19:31:26.603482053Z,160,1,432669,C,B,64.770000000,2,26,8058566320648,128,14731,94242658,CLX5
2025-09-24T19:31:26.605338794Z,2025-09-24T19:31:26.603483089Z,160,1,432669,C,B,64.720000000,2,26,8058566302431,128,18141,94242659,CLX5
2025-09-24T19:31:26.605374097Z,2025-09-24T19:31:26.603507145Z,160,1,432669,C,A,64.820000000,1,26,8058566320781,128,15727,94242660,CLX5
2025-09-24T19:31:26.605409008Z,2025-09-24T19:31:26.603513655Z,160,1,432669,C,A,64.820000000,2,26,8058566320780,128,16098,94242661,CLX5
2025-09-24T19:31:26.605795561Z,2025-09-24T19:31:26.603850601Z,160,1,432669,C,A,64.820000000,2,26,8058566320792,128,16554,94242688,CLX5
2025-09-24T19:31:26.605843351Z,2025-09-24T19:31:26.603851699Z,160,1,432669,C,B,64.810000000,2,26,8058566320639,128,15977,94242690,CLX5
2025-09-24T19:31:26.606268040Z,2025-09-24T19:31:26.604286939Z,160,1,432669,C,B,64.760000000,1,26,8058566305832,128,18571,94242715,CLX5
2025-09-24T19:31:26.606684098Z,2025-09-24T19:31:26.604814647Z,160,1,432669,C,A,64.820000000,1,26,8058566320785,128,16642,94242734,CLX5
2025-09-24T19:31:26.606914186Z,2025-09-24T19:31:26.605081765Z,160,1,432669,A,B,64.810000000,2,26,8058566320831,128,16721,94242745,CLX5
2025-09-24T19:31:26.607041307Z,2025-09-24T19:31:26.605417711Z,160,1,432669,A,B,64.810000000,1,26,8058566320834,128,14396,94242751,CLX5
2025-09-24T19:31:26.607052688Z,2025-09-24T19:31:26.605423413Z,160,1,432669,T,B,64.820000000,7,26,8058566320835,0,14858,94242752,CLX5
2025-09-24T19:31:26.607052688Z,2025-09-24T19:31:26.605423413Z,160,1,432669,F,A,64.820000000,3,26,8058566320762,0,14858,94242752,CLX5
2025-09-24T19:31:26.607052688Z,2025-09-24T19:31:26.605423413Z,160,1,432669,F,A,64.820000000,2,26,8058566320770,0,14858,94242752,CLX5
2025-09-24T19:31:26.607052688Z,2025-09-24T19:31:26.605423413Z,160,1,432669,F,A,64.820000000,1,26,8058566320777,0,14858,94242752,CLX5
2025-09-24T19:31:26.607052688Z,2025-09-24T19:31:26.605423413Z,160,1,432669,F,A,64.820000000,1,26,8058566320783,0,14858,94242752,CLX5
2025-09-24T19:31:26.607109686Z,2025-09-24T19:31:26.605423413Z,160,1,432669,C,A,64.820000000,3,26,8058566320762,0,19121,94242753,CLX5
2025-09-24T19:31:26.607109686Z,2025-09-24T19:31:26.605423413Z,160,1,432669,C,A,64.820000000,2,26,8058566320770,0,19121,94242753,CLX5
2025-09-24T19:31:26.607109686Z,2025-09-24T19:31:26.605423413Z,160,1,432669,C,A,64.820000000,1,26,8058566320777,0,19121,94242753,CLX5
2025-09-24T19:31:26.607109686Z,2025-09-24T19:31:26.605423413Z,160,1,432669,C,A,64.820000000,1,26,8058566320783,128,19121,94242753,CLX5
2025-09-24T19:31:26.607178879Z,2025-09-24T19:31:26.605433743Z,160,1,432669,A,B,64.820000000,3,26,8058566320836,128,14900,94242757,CLX5
2025-09-24T19:31:26.607243718Z,2025-09-24T19:31:26.605599295Z,160,1,432669,C,B,64.810000000,1,26,8058566320834,128,14926,94242764,CLX5
2025-09-24T19:31:26.607306860Z,2025-09-24T19:31:26.605601849Z,160,1,432669,C,B,64.810000000,2,26,8058566320831,128,19511,94242766,CLX5
2025-09-24T19:31:26.607587334Z,2025-09-24T19:31:26.605804131Z,160,1,432669,A,B,64.810000000,2,26,8058566320840,128,16061,94242783,CLX5
2025-09-24T19:31:26.607683805Z,2025-09-24T19:31:26.605851497Z,160,1,432669,A,B,64.810000000,1,26,8058566320842,128,14949,94242786,CLX5
2025-09-24T19:31:26.608104270Z,2025-09-24T19:31:26.607052669Z,160,1,432669,A,B,64.810000000,1,26,8058566320845,128,15418,94242807,CLX5
2025-09-24T19:31:26.608153566Z,2025-09-24T19:31:26.607053901Z,160,1,432669,A,B,64.820000000,2,26,8058566320846,128,14854,94242808,CLX5
2025-09-24T19:31:26.608314753Z,2025-09-24T19:31:26.607077383Z,160,1,432669,A,B,64.820000000,1,26,8058566320850,128,17376,94242817,CLX5
2025-09-24T19:31:26.608458592Z,2025-09-24T19:31:26.607147747Z,160,1,432669,C,A,64.830000000,1,26,8058566320718,128,18654,94242824,CLX5
2025-09-24T19:31:26.608497873Z,2025-09-24T19:31:26.607178927Z,160,1,432669,A,B,64.820000000,3,26,8058566320851,128,16374,94242825,CLX5
2025-09-24T19:31:26.608532846Z,2025-09-24T19:31:26.607179105Z,160,1,432669,A,B,64.820000000,2,26,8058566320852,128,15196,94242826,CLX5
2025-09-24T19:31:26.608682798Z,2025-09-24T19:31:26.607205171Z,160,1,432669,A,B,64.810000000,2,26,8058566320855,128,17464,94242831,CLX5
2025-09-24T19:31:26.608712226Z,2025-09-24T19:31:26.607271505Z,160,1,432669,A,B,64.810000000,1,26,8058566320856,128,15351,94242832,CLX5
2025-09-24T19:31:26.608766966Z,2025-09-24T19:31:26.607332595Z,160,1,432669,A,B,64.810000000,1,26,8058566320857,128,14280,94242834,CLX5
2025-09-24T19:31:26.608953972Z,2025-09-24T19:31:26.607655661Z,160,1,432669,C,B,64.820000000,2,26,8058566320852,128,16473,94242841,CLX5
2025-09-24T19:31:26.609069972Z,2025-09-24T19:31:26.607693579Z,160,1,432669,C,B,64.820000000,3,26,8058566320851,128,16778,94242845,CLX5
2025-09-24T19:31:26.610476475Z,2025-09-24T19:31:26.609850161Z,160,1,432669,C,A,64.850000000,1,26,8058566319376,128,15203,94242919,CLX5
2025-09-24T19:31:26.617040879Z,2025-09-24T19:31:26.616904583Z,160,1,432669,A,A,64.830000000,1,26,8058566320899,128,18925,94242998,CLX5
2025-09-24T19:31:26.617200937Z,2025-09-24T19:31:26.617047731Z,160,1,432669,A,B,64.770000000,1,26,8058566320901,128,14801,94243003,CLX5
2025-09-24T19:31:26.617250993Z,2025-09-24T19:31:26.617068813Z,160,1,432669,A,A,64.830000000,1,26,8058566320902,128,18517,94243005,CLX5
2025-09-24T19:31:26.617396659Z,2025-09-24T19:31:26.617276241Z,160,1,432669,A,A,64.830000000,1,26,8058566320903,128,17447,94243008,CLX5
2025-09-24T19:31:26.617544323Z,2025-09-24T19:31:26.617420445Z,160,1,432669,C,B,64.810000000,1,26,8058566320857,128,19005,94243009,CLX5
2025-09-24T19:31:26.617579357Z,2025-09-24T19:31:26.617431313Z,160,1,432669,C,B,64.810000000,1,26,8058566320856,128,15595,94243010,CLX5
2025-09-24T19:31:26.646665929Z,2025-09-24T19:31:26.646568121Z,160,1,432669,A,B,64.720000000,2,26,8058566320913,128,18108,94243036,CLX5
2025-09-24T19:31:26.663635488Z,2025-09-24T19:31:26.663496955Z,160,1,432669,A,B,64.800000000,2,26,8058566320918,128,18738,94243043,CLX5
2025-09-24T19:31:26.663663043Z,2025-09-24T19:31:26.663501101Z,160,1,432669,A,B,64.790000000,2,26,8058566320919,128,14808,94243044,CLX5
2025-09-24T19:31:26.749874527Z,2025-09-24T19:31:26.749733215Z,160,1,432669,A,B,64.780000000,1,26,8058566320930,128,19077,94243065,CLX5
2025-09-24T19:31:27.046063149Z,2025-09-24T19:31:27.045917593Z,160,1,432669,C,A,64.830000000,1,26,8058566320903,128,19534,94243129,CLX5
2025-09-24T19:31:27.046090558Z,2025-09-24T19:31:27.045927731Z,160,1,432669,C,A,64.830000000,1,26,8058566320902,128,15291,94243130,CLX5
2025-09-24T19:31:27.046119210Z,2025-09-24T19:31:27.045934219Z,160,1,432669,C,A,64.830000000,1,26,8058566320899,128,15134,94243131,CLX5
2025-09-24T19:31:27.046233221Z,2025-09-24T19:31:27.046071801Z,160,1,432669,A,B,64.790000000,1,26,8058566320981,128,14781,94243134,CLX5
2025-09-24T19:31:27.631058392Z,2025-09-24T19:31:27.630814845Z,160,1,432669,C,B,64.820000000,2,26,8058566320846,128,19417,94243185,CLX5
2025-09-24T19:31:27.631893594Z,2025-09-24T19:31:27.630824959Z,160,1,432669,T,A,64.820000000,4,26,8058566321021,0,18420,94243245,CLX5
2025-09-24T19:31:27.631893594Z,2025-09-24T19:31:27.630824959Z,160,1,432669,F,B,64.820000000,3,26,8058566320836,0,18420,94243245,CLX5
2025-09-24T19:31:27.631893594Z,2025-09-24T19:31:27.630824959Z,160,1,432669,F,B,64.820000000,1,26,8058566320850,0,18420,94243245,CLX5
2025-09-24T19:31:27.631904507Z,2025-09-24T19:31:27.630824959Z,160,1,432669,C,B,64.820000000,3,26,8058566320836,0,15742,94243246,CLX5
2025-09-24T19:31:27.631904507Z,2025-09-24T19:31:27.630824959Z,160,1,432669,C,B,64.820000000,1,26,8058566320850,128,15742,94243246,CLX5
2025-09-24T19:31:27.632216490Z,2025-09-24T19:31:27.631878535Z,160,1,432669,A,A,64.830000000,1,26,8058566321026,128,18864,94243268,CLX5
2025-09-24T19:31:27.632860563Z,2025-09-24T19:31:27.632259447Z,160,1,432669,A,A,64.830000000,1,26,8058566321035,128,17789,94243298,CLX5
2025-09-24T19:31:27.632902491Z,2025-09-24T19:31:27.632352793Z,160,1,432669,A,A,64.830000000,1,26,8058566321036,128,16142,94243300,CLX5
2025-09-24T19:31:27.632985403Z,2025-09-24T19:31:27.632383627Z,160,1,432669,C,B,64.790000000,1,26,8058566320981,128,18756,94243303,CLX5
2025-09-24T19:31:27.633168315Z,2025-09-24T19:31:27.632545379Z,160,1,432669,A,A,64.830000000,1,26,8058566321040,128,14552,94243311,CLX5
2025-09-24T19:31:27.633277849Z,2025-09-24T19:31:27.632616569Z,160,1,432669,A,A,64.820000000,2,26,8058566321041,128,14884,94243314,CLX5
2025-09-24T19:31:27.633309727Z,2025-09-24T19:31:27.632652723Z,160,1,432669,A,A,64.830000000,1,26,8058566321042,128,15134,94243317,CLX5
2025-09-24T19:31:27.633374405Z,2025-09-24T19:31:27.632678277Z,160,1,432669,A,A,64.820000000,1,26,8058566321043,128,15107,94243319,CLX5
2025-09-24T19:31:27.633390332Z,2025-09-24T19:31:27.632766189Z,160,1,432669,C,B,64.810000000,1,26,8058566320845,128,14989,94243321,CLX5
2025-09-24T19:31:27.633705496Z,2025-09-24T19:31:27.633279383Z,160,1,432669,A,A,64.820000000,2,26,8058566321045,128,22686,94243333,CLX5
2025-09-24T19:31:27.682719472Z,2025-09-24T19:31:27.682572211Z,160,1,432669,C,A,64.830000000,1,26,8058566321036,128,18248,94243367,CLX5
2025-09-24T19:31:27.682858327Z,2025-09-24T19:31:27.682729279Z,160,1,432669,C,B,64.810000000,2,26,8058566320840,128,18491,94243368,CLX5
2025-09-24T19:31:27.682886380Z,2025-09-24T19:31:27.682763069Z,160,1,432669,C,A,64.830000000,1,26,8058566321042,128,15051,94243369,CLX5
2025-09-24T19:31:27.682916238Z,2025-09-24T19:31:27.682772379Z,160,1,432669,C,A,64.830000000,1,26,8058566321040,128,15172,94243370,CLX5
2025-09-24T19:31:27.682943317Z,2025-09-24T19:31:27.682776969Z,160,1,432669,C,A,64.830000000,1,26,8058566321035,128,14849,94243371,CLX5
2025-09-24T19:31:27.709601747Z,2025-09-24T19:31:27.709474313Z,160,1,432669,A,B,64.770000000,2,26,8058566321063,128,18604,94243375,CLX5
2025-09-24T19:31:27.720066811Z,2025-09-24T19:31:27.719952443Z,160,1,432669,M,B,64.540000000,1,26,8058566301815,128,18367,94243376,CLX5
2025-09-24T19:31:27.993944717Z,2025-09-24T19:31:27.993779177Z,160,1,432669,A,A,64.820000000,1,26,8058566321103,128,23141,94243428,CLX5
2025-09-24T19:31:30.002185014Z,2025-09-24T19:31:30.001285211Z,160,1,432669,A,B,64.760000000,1,26,8058566321133,128,21906,94243474,CLX5
2025-09-24T19:31:30.698429748Z,2025-09-24T19:31:30.697810361Z,160,1,432669,T,B,64.820000000,7,26,8058566321144,0,22425,94243497,CLX5
2025-09-24T19:31:30.698429748Z,2025-09-24T19:31:30.697810361Z,160,1,432669,F,A,64.820000000,2,26,8058566321041,0,22425,94243497,CLX5
2025-09-24T19:31:30.698429748Z,2025-09-24T19:31:30.697810361Z,160,1,432669,F,A,64.820000000,1,26,8058566321043,0,22425,94243497,CLX5
2025-09-24T19:31:30.698429748Z,2025-09-24T19:31:30.697810361Z,160,1,432669,F,A,64.820000000,2,26,8058566321045,0,22425,94243497,CLX5
2025-09-24T19:31:30.698429748Z,2025-09-24T19:31:30.697810361Z,160,1,432669,F,A,64.820000000,1,26,8058566321103,0,22425,94243497,CLX5
2025-09-24T19:31:30.698445130Z,2025-09-24T19:31:30.697810361Z,160,1,432669,C,A,64.820000000,2,26,8058566321041,0,20216,94243498,CLX5
2025-09-24T19:31:30.698445130Z,2025-09-24T19:31:30.697810361Z,160,1,432669,C,A,64.820000000,1,26,8058566321043,0,20216,94243498,CLX5
2025-09-24T19:31:30.698445130Z,2025-09-24T19:31:30.697810361Z,160,1,432669,C,A,64.820000000,2,26,8058566321045,0,20216,94243498,CLX5
2025-09-24T19:31:30.698445130Z,2025-09-24T19:31:30.697810361Z,160,1,432669,C,A,64.820000000,1,26,8058566321103,128,20216,94243498,CLX5
2025-09-24T19:31:30.698959125Z,2025-09-24T19:31:30.698132465Z,160,1,432669,A,B,64.810000000,1,26,8058566321155,128,18996,94243531,CLX5
2025-09-24T19:31:30.699321733Z,2025-09-24T19:31:30.698135985Z,160,1,432669,C,A,64.860000000,1,26,8058566319952,128,15214,94243548,CLX5
2025-09-24T19:31:30.699916871Z,2025-09-24T19:31:30.698142775Z,160,1,432669,C,A,64.830000000,1,26,8058566321026,128,14977,94243593,CLX5
2025-09-24T19:31:30.700037364Z,2025-09-24T19:31:30.698144331Z,160,1,432669,A,B,64.810000000,2,26,8058566321160,128,15508,94243598,CLX5
2025-09-24T19:31:30.700679639Z,2025-09-24T19:31:30.698431377Z,160,1,432669,A,B,64.820000000,1,26,8058566321171,128,15437,94243638,CLX5
2025-09-24T19:31:30.701006598Z,2025-09-24T19:31:30.698482409Z,160,1,432669,C,A,64.830000000,2,26,8058566319973,128,18859,94243658,CLX5
2025-09-24T19:31:30.701323482Z,2025-09-24T19:31:30.698997465Z,160,1,432669,A,B,64.810000000,1,26,8058566321180,128,18717,94243677,CLX5
2025-09-24T19:31:30.701491734Z,2025-09-24T19:31:30.699105881Z,160,1,432669,A,B,64.810000000,1,26,8058566321182,128,14931,94243686,CLX5
2025-09-24T19:31:30.701745667Z,2025-09-24T19:31:30.700290449Z,160,1,432669,A,B,64.540000000,8,26,8058566321185,128,14533,94243702,CLX5
2025-09-24T19:31:30.702331544Z,2025-09-24T19:31:30.700706093Z,160,1,432669,A,A,64.830000000,1,26,8058566321192,128,15355,94243739,CLX5
2025-09-24T19:31:30.702394478Z,2025-09-24T19:31:30.700742495Z,160,1,432669,A,B,64.820000000,1,26,8058566321193,128,18517,94243740,CLX5
2025-09-24T19:31:30.702426210Z,2025-09-24T19:31:30.700819503Z,160,1,432669,C,B,64.800000000,2,26,8058566320918,128,14429,94243743,CLX5
2025-09-24T19:31:30.702604646Z,2025-09-24T19:31:30.700820415Z,160,1,432669,C,B,64.790000000,2,26,8058566320919,128,18690,94243748,CLX5
2025-09-24T19:31:30.702659048Z,2025-09-24T19:31:30.700820809Z,160,1,432669,C,B,64.770000000,2,26,8058566321063,128,15104,94243750,CLX5
2025-09-24T19:31:30.702668977Z,2025-09-24T19:31:30.700822019Z,160,1,432669,C,B,64.720000000,2,26,8058566320913,128,14531,94243751,CLX5
2025-09-24T19:31:30.702679821Z,2025-09-24T19:31:30.700833479Z,160,1,432669,T,A,64.820000000,2,26,8058566321194,0,15229,94243752,CLX5
2025-09-24T19:31:30.702679821Z,2025-09-24T19:31:30.700833479Z,160,1,432669,F,B,64.820000000,1,26,8058566321171,0,15229,94243752,CLX5
2025-09-24T19:31:30.702679821Z,2025-09-24T19:31:30.700833479Z,160,1,432669,F,B,64.820000000,1,26,8058566321193,0,15229,94243752,CLX5
2025-09-24T19:31:30.702679821Z,2025-09-24T19:31:30.700833479Z,160,1,432669,C,B,64.820000000,1,26,8058566321171,0,15229,94243752,CLX5
2025-09-24T19:31:30.702679821Z,2025-09-24T19:31:30.700833479Z,160,1,432669,C,B,64.820000000,1,26,8058566321193,128,15229,94243752,CLX5
2025-09-24T19:31:30.702781361Z,2025-09-24T19:31:30.700833659Z,160,1,432669,A,A,64.820000000,2,26,8058566321195,128,14946,94243755,CLX5
2025-09-24T19:31:30.702836377Z,2025-09-24T19:31:30.700833835Z,160,1,432669,A,A,64.820000000,1,26,8058566321196,128,18337,94243759,CLX5
2025-09-24T19:31:30.702947601Z,2025-09-24T19:31:30.701000417Z,160,1,432669,M,A,65.980000000,4,26,8058566275421,128,18657,94243767,CLX5
2025-09-24T19:31:30.703154120Z,2025-09-24T19:31:30.701251579Z,160,1,432669,A,B,64.790000000,1,26,8058566321200,128,18180,94243778,CLX5
2025-09-24T19:31:30.704266157Z,2025-09-24T19:31:30.701843519Z,160,1,432669,A,A,64.820000000,1,26,8058566321216,128,18211,94243861,CLX5
2025-09-24T19:31:30.704814097Z,2025-09-24T19:31:30.702340689Z,160,1,432669,A,A,64.820000000,1,26,8058566321224,128,18635,94243893,CLX5
2025-09-24T19:31:30.704883958Z,2025-09-24T19:31:30.702432845Z,160,1,432669,M,B,64.810000000,3,26,8058566291224,128,16734,94243896,CLX5
2025-09-24T19:31:30.704914661Z,2025-09-24T19:31:30.702452967Z,160,1,432669,A,B,64.800000000,1,26,8058566321226,128,15118,94243897,CLX5
2025-09-24T19:31:30.705196740Z,2025-09-24T19:31:30.702686389Z,160,1,432669,A,A,64.860000000,1,26,8058566321231,128,16954,94243909,CLX5
2025-09-24T19:31:30.705229371Z,2025-09-24T19:31:30.702699367Z,160,1,432669,C,B,64.810000000,2,26,8058566321160,128,15262,94243910,CLX5
2025-09-24T19:31:30.705269696Z,2025-09-24T19:31:30.702781445Z,160,1,432669,A,A,64.820000000,2,26,8058566321232,128,17132,94243911,CLX5
2025-09-24T19:31:30.705306144Z,2025-09-24T19:31:30.702782789Z,160,1,432669,A,A,64.820000000,2,26,8058566321233,128,19608,94243912,CLX5
2025-09-24T19:31:30.705336240Z,2025-09-24T19:31:30.702798627Z,160,1,432669,A,A,64.820000000,2,26,8058566321234,128,16472,94243913,CLX5
2025-09-24T19:31:30.705382087Z,2025-09-24T19:31:30.702803927Z,160,1,432669,C,B,64.810000000,1,26,8058566321182,128,14296,94243915,CLX5
2025-09-24T19:31:30.705475364Z,2025-09-24T19:31:30.702814025Z,160,1,432669,C,B,64.810000000,1,26,8058566321180,128,15542,94243918,CLX5
2025-09-24T19:31:30.705530135Z,2025-09-24T19:31:30.702825873Z,160,1,432669,C,B,64.810000000,1,26,8058566321155,128,15429,94243921,CLX5
2025-09-24T19:31:30.705604573Z,2025-09-24T19:31:30.702901229Z,160,1,432669,C,B,64.810000000,3,26,8058566291224,128,19505,94243924,CLX5
2025-09-24T19:31:30.705831881Z,2025-09-24T19:31:30.703232971Z,160,1,432669,M,A,64.840000000,4,26,8058566288785,128,18490,94243933,CLX5
2025-09-24T19:31:30.706348196Z,2025-09-24T19:31:30.704893831Z,160,1,432669,C,A,64.820000000,2,26,8058566321234,128,16630,94243959,CLX5
2025-09-24T19:31:30.706470831Z,2025-09-24T19:31:30.705080967Z,160,1,432669,C,A,64.820000000,2,26,8058566321232,128,17076,94243963,CLX5
2025-09-24T19:31:30.706510750Z,2025-09-24T19:31:30.705114833Z,160,1,432669,C,A,64.820000000,2,26,8058566321233,128,18777,94243964,CLX5
2025-09-24T19:31:30.706622581Z,2025-09-24T19:31:30.705278737Z,160,1,432669,C,A,64.820000000,1,26,8058566321224,128,25076,94243968,CLX5
2025-09-24T19:31:30.706889301Z,2025-09-24T19:31:30.705798055Z,160,1,432669,A,A,64.820000000,1,26,8058566321253,128,18158,94243981,CLX5
2025-09-24T19:31:30.707449166Z,2025-09-24T19:31:30.706670023Z,160,1,432669,A,A,64.820000000,2,26,8058566321260,128,16847,94244010,CLX5
2025-09-24T19:31:30.707597030Z,2025-09-24T19:31:30.707178589Z,160,1,432669,C,A,64.820000000,2,26,8058566321260,128,20176,94244017,CLX5
2025-09-24T19:31:30.720098838Z,2025-09-24T19:31:30.719995463Z,160,1,432669,C,B,64.540000000,8,26,8058566321185,128,18990,94244047,CLX5
2025-09-24T19:31:30.720252023Z,2025-09-24T19:31:30.720124807Z,160,1,432669,C,B,64.800000000,1,26,8058566321226,128,18315,94244048,CLX5
2025-09-24T19:31:30.752196937Z,2025-09-24T19:31:30.752053577Z,160,1,432669,A,B,64.720000000,2,26,8058566321275,128,17952,94244068,CLX5
2025-09-24T19:31:30.762194459Z,2025-09-24T19:31:30.762030319Z,160,1,432669,A,B,64.800000000,2,26,8058566321278,128,14950,94244071,CLX5
2025-09-24T19:31:30.762223158Z,2025-09-24T19:31:30.762034563Z,160,1,432669,A,B,64.790000000,2,26,8058566321279,128,14677,94244072,CLX5
2025-09-24T19:31:30.809958337Z,2025-09-24T19:31:30.809826133Z,160,1,432669,A,B,64.770000000,2,26,8058566321294,128,18932,94244102,CLX5
2025-09-24T19:31:30.881429201Z,2025-09-24T19:31:30.881288587Z,160,1,432669,C,B,64.790000000,1,26,8058566321200,128,19724,94244122,CLX5
2025-09-24T19:31:35.419287772Z,2025-09-24T19:31:35.419135989Z,160,1,432669,A,B,64.810000000,2,26,8058566321424,128,21618,94244319,CLX5
2025-09-24T19:31:35.419401468Z,2025-09-24T19:31:35.419164807Z,160,1,432669,C,A,64.820000000,1,26,8058566321253,128,18999,94244323,CLX5
2025-09-24T19:31:35.419749669Z,2025-09-24T19:31:35.419411247Z,160,1,432669,T,B,64.820000000,4,26,8058566321427,0,22785,94244332,CLX5
2025-09-24T19:31:35.419749669Z,2025-09-24T19:31:35.419411247Z,160,1,432669,F,A,64.820000000,2,26,8058566321195,0,22785,94244332,CLX5
2025-09-24T19:31:35.419749669Z,2025-09-24T19:31:35.419411247Z,160,1,432669,F,A,64.820000000,1,26,8058566321196,0,22785,94244332,CLX5
2025-09-24T19:31:35.419749669Z,2025-09-24T19:31:35.419411247Z,160,1,432669,F,A,64.820000000,1,26,8058566321216,0,22785,94244332,CLX5
2025-09-24T19:31:35.419763923Z,2025-09-24T19:31:35.419411247Z,160,1,432669,C,A,64.820000000,2,26,8058566321195,0,19248,94244333,CLX5
2025-09-24T19:31:35.419763923Z,2025-09-24T19:31:35.419411247Z,160,1,432669,C,A,64.820000000,1,26,8058566321196,0,19248,94244333,CLX5
2025-09-24T19:31:35.419763923Z,2025-09-24T19:31:35.419411247Z,160,1,432669,C,A,64.820000000,1,26,8058566321216,128,19248,94244333,CLX5
2025-09-24T19:31:35.419815591Z,2025-09-24T19:31:35.419421961Z,160,1,432669,A,B,64.820000000,1,26,8058566321428,128,20070,94244336,CLX5
2025-09-24T19:31:35.420003318Z,2025-09-24T19:31:35.419749593Z,160,1,432669,A,B,64.810000000,1,26,8058566321434,128,15115,94244347,CLX5
2025-09-24T19:31:35.420588119Z,2025-09-24T19:31:35.419807343Z,160,1,432669,A,B,64.820000000,2,26,8058566321442,128,14036,94244377,CLX5
2025-09-24T19:31:35.420633636Z,2025-09-24T19:31:35.419820093Z,160,1,432669,C,A,64.830000000,1,26,8058566321192,128,19183,94244380,CLX5
2025-09-24T19:31:35.420786968Z,2025-09-24T19:31:35.419917817Z,160,1,432669,A,B,64.820000000,1,26,8058566321444,128,14569,94244389,CLX5
2025-09-24T19:31:35.421116469Z,2025-09-24T19:31:35.420140585Z,160,1,432669,M,A,65.990000000,4,26,8058566288785,128,15111,94244407,CLX5
2025-09-24T19:31:35.421195829Z,2025-09-24T19:31:35.420169537Z,160,1,432669,A,B,64.820000000,2,26,8058566321446,128,15543,94244410,CLX5
2025-09-24T19:31:35.421630210Z,2025-09-24T19:31:35.420399099Z,160,1,432669,C,B,64.820000000,2,26,8058566321446,128,18827,94244429,CLX5
2025-09-24T19:31:35.421660461Z,2025-09-24T19:31:35.420425327Z,160,1,432669,A,B,64.790000000,1,26,8058566321452,128,18001,94244430,CLX5
2025-09-24T19:31:35.421909295Z,2025-09-24T19:31:35.420605799Z,160,1,432669,M,B,64.810000000,3,26,8058566319508,128,15070,94244442,CLX5
2025-09-24T19:31:35.424675417Z,2025-09-24T19:31:35.424563665Z,160,1,432669,A,A,65.970000000,4,26,8058566321460,128,18024,94244480,CLX5
2025-09-24T19:31:35.592277481Z,2025-09-24T19:31:35.592112641Z,160,1,432669,A,B,64.810000000,2,26,8058566321508,128,19077,94244577,CLX5
2025-09-24T19:31:36.500182233Z,2025-09-24T19:31:36.500008981Z,160,1,432669,C,B,64.820000000,1,26,8058566321444,128,20785,94244618,CLX5
2025-09-24T19:31:36.626689899Z,2025-09-24T19:31:36.626384355Z,160,1,432669,T,A,64.820000000,1,26,8058566321532,0,18340,94244627,CLX5
2025-09-24T19:31:36.626689899Z,2025-09-24T19:31:36.626384355Z,160,1,432669,F,B,64.820000000,1,26,8058566321428,0,18340,94244627,CLX5
2025-09-24T19:31:36.626700343Z,2025-09-24T19:31:36.626384355Z,160,1,432669,C,B,64.820000000,1,26,8058566321428,128,16679,94244628,CLX5
2025-09-24T19:31:36.626857668Z,2025-09-24T19:31:36.626691715Z,160,1,432669,C,B,64.820000000,2,26,8058566321442,128,14925,94244632,CLX5
2025-09-24T19:31:36.627204018Z,2025-09-24T19:31:36.627073201Z,160,1,432669,M,B,63.660000000,4,26,8058566319508,128,18940,94244636,CLX5
2025-09-24T19:31:36.627465347Z,2025-09-24T19:31:36.627349227Z,160,1,432669,C,B,64.790000000,1,26,8058566321452,128,18528,94244637,CLX5
2025-09-24T19:31:36.627500250Z,2025-09-24T19:31:36.627351897Z,160,1,432669,A,A,64.830000000,1,26,8058566321534,128,15042,94244638,CLX5
2025-09-24T19:31:36.627630320Z,2025-09-24T19:31:36.627503395Z,160,1,432669,A,A,64.830000000,1,26,8058566321535,128,19463,94244639,CLX5
2025-09-24T19:31:36.627783911Z,2025-09-24T19:31:36.627664573Z,160,1,432669,A,A,64.830000000,1,26,8058566321537,128,17637,94244641,CLX5
2025-09-24T19:31:37.001516480Z,2025-09-24T19:31:37.001372289Z,160,1,432669,C,A,64.830000000,1,26,8058566321537,128,19449,94244643,CLX5
2025-09-24T19:31:37.001541446Z,2025-09-24T19:31:37.001383923Z,160,1,432669,C,A,64.830000000,1,26,8058566321535,128,15373,94244644,CLX5
2025-09-24T19:31:37.001573916Z,2025-09-24T19:31:37.001389511Z,160,1,432669,C,A,64.830000000,1,26,8058566321534,128,15177,94244645,CLX5
2025-09-24T19:31:37.201335770Z,2025-09-24T19:31:37.201187533Z,160,1,432669,A,A,64.830000000,1,26,8058566321539,128,19413,94244646,CLX5
2025-09-24T19:31:42.815672372Z,2025-09-24T19:31:42.815459287Z,160,1,432669,A,B,64.820000000,2,26,8058566321575,128,18181,94244761,CLX5
2025-09-24T19:31:42.815817909Z,2025-09-24T19:31:42.815551213Z,160,1,432669,A,B,64.820000000,2,26,8058566321577,128,17590,94244766,CLX5
2025-09-24T19:31:42.815945566Z,2025-09-24T19:31:42.815672379Z,160,1,432669,A,B,64.820000000,1,26,8058566321578,128,15058,94244771,CLX5
2025-09-24T19:31:42.816006873Z,2025-09-24T19:31:42.815734641Z,160,1,432669,A,B,64.820000000,1,26,8058566321579,128,17020,94244776,CLX5
2025-09-24T19:31:42.816347263Z,2025-09-24T19:31:42.816203697Z,160,1,432669,A,B,64.790000000,1,26,8058566321584,128,16193,94244798,CLX5
2025-09-24T19:31:42.898175006Z,2025-09-24T19:31:42.898025343Z,160,1,432669,M,B,64.810000000,3,26,8058566319508,128,18787,94244898,CLX5
2025-09-24T19:31:43.900203255Z,2025-09-24T19:31:43.900008501Z,160,1,432669,C,B,64.820000000,1,26,8058566321579,128,17366,94244953,CLX5
2025-09-24T19:31:45.017778610Z,2025-09-24T19:31:45.017632845Z,160,1,432669,A,B,64.820000000,2,26,8058566321643,128,19829,94244989,CLX5
2025-09-24T19:31:45.017960110Z,2025-09-24T19:31:45.017774571Z,160,1,432669,A,B,64.820000000,1,26,8058566321644,128,16206,94244992,CLX5
2025-09-24T19:31:45.018220763Z,2025-09-24T19:31:45.017819959Z,160,1,432669,A,B,64.820000000,1,26,8058566321647,128,16158,94245002,CLX5
2025-09-24T19:31:45.019008321Z,2025-09-24T19:31:45.018784657Z,160,1,432669,C,B,64.820000000,2,26,8058566321643,128,14160,94245034,CLX5
2025-09-24T19:31:45.019108909Z,2025-09-24T19:31:45.018955299Z,160,1,432669,C,B,64.820000000,1,26,8058566321647,128,16608,94245039,CLX5
2025-09-24T19:31:45.021129549Z,2025-09-24T19:31:45.020831633Z,160,1,432669,A,B,64.820000000,1,26,8058566321662,128,16294,94245063,CLX5
2025-09-24T19:31:45.021164099Z,2025-09-24T19:31:45.020832171Z,160,1,432669,A,B,64.820000000,1,26,8058566321663,128,16250,94245064,CLX5
2025-09-24T19:31:45.021200501Z,2025-09-24T19:31:45.020833919Z,160,1,432669,A,B,64.820000000,1,26,8058566321664,128,19791,94245065,CLX5
2025-09-24T19:31:45.021249850Z,2025-09-24T19:31:45.020840733Z,160,1,432669,A,B,64.820000000,1,26,8058566321666,128,16055,94245067,CLX5
2025-09-24T19:31:45.021323735Z,2025-09-24T19:31:45.020848413Z,160,1,432669,A,B,64.820000000,3,26,8058566321668,128,15388,94245070,CLX5
2025-09-24T19:31:45.021388996Z,2025-09-24T19:31:45.020851485Z,160,1,432669,C,A,64.860000000,2,26,8058566320040,128,14695,94245073,CLX5
2025-09-24T19:31:45.021422533Z,2025-09-24T19:31:45.020852925Z,160,1,432669,C,A,64.830000000,2,26,8058566320608,128,18284,94245074,CLX5
2025-09-24T19:31:45.021604854Z,2025-09-24T19:31:45.020898695Z,160,1,432669,A,B,64.820000000,2,26,8058566321672,128,14458,94245080,CLX5
2025-09-24T19:31:45.021818201Z,2025-09-24T19:31:45.021214445Z,160,1,432669,C,B,64.820000000,2,26,8058566321672,128,15925,94245090,CLX5
2025-09-24T19:31:45.022115164Z,2025-09-24T19:31:45.021370919Z,160,1,432669,C,B,64.820000000,3,26,8058566321668,128,15298,94245107,CLX5
2025-09-24T19:31:45.022124533Z,2025-09-24T19:31:45.021406227Z,160,1,432669,M,A,64.950000000,1,26,8058565075241,128,15008,94245108,CLX5
2025-09-24T19:31:45.022436778Z,2025-09-24T19:31:45.021825151Z,160,1,432669,C,B,64.820000000,1,26,8058566321664,128,16136,94245122,CLX5
2025-09-24T19:31:45.022510709Z,2025-09-24T19:31:45.021970893Z,160,1,432669,C,B,64.820000000,1,26,8058566321662,128,19712,94245125,CLX5
2025-09-24T19:31:45.022570863Z,2025-09-24T19:31:45.022190549Z,160,1,432669,M,A,64.940000000,1,26,8058565075241,128,14882,94245129,CLX5
2025-09-24T19:31:45.022962860Z,2025-09-24T19:31:45.022409957Z,160,1,432669,M,B,64.810000000,1,26,8058566321508,128,15093,94245150,CLX5
2025-09-24T19:31:45.031000434Z,2025-09-24T19:31:45.030870083Z,160,1,432669,C,B,64.820000000,1,26,8058566321666,128,19440,94245187,CLX5
2025-09-24T19:31:45.031749425Z,2025-09-24T19:31:45.031617469Z,160,1,432669,C,B,64.820000000,1,26,8058566321644,128,19679,94245194,CLX5
2025-09-24T19:31:45.031789544Z,2025-09-24T19:31:45.031625763Z,160,1,432669,C,B,64.820000000,1,26,8058566321663,128,17076,94245195,CLX5
2025-09-24T19:31:45.093864841Z,2025-09-24T19:31:45.093732219Z,160,1,432669,A,B,64.820000000,1,26,8058566321696,128,16913,94245216,CLX5
2025-09-24T19:31:45.093905013Z,2025-09-24T19:31:45.093736271Z,160,1,432669,A,B,64.820000000,3,26,8058566321697,128,19569,94245217,CLX5
2025-09-24T19:31:45.094056416Z,2025-09-24T19:31:45.093933293Z,160,1,432669,A,B,64.820000000,1,26,8058566321698,128,19290,94245218,CLX5
2025-09-24T19:31:45.094332482Z,2025-09-24T19:31:45.094210489Z,160,1,432669,A,B,64.820000000,1,26,8058566321699,128,19349,94245219,CLX5
2025-09-24T19:31:45.094368515Z,2025-09-24T19:31:45.094220395Z,160,1,432669,A,B,64.820000000,1,26,8058566321701,128,14194,94245221,CLX5
2025-09-24T19:31:45.094477135Z,2025-09-24T19:31:45.094221817Z,160,1,432669,A,B,64.820000000,1,26,8058566321704,128,16689,94245226,CLX5
2025-09-24T19:31:45.094533496Z,2025-09-24T19:31:45.094226809Z,160,1,432669,A,B,64.820000000,1,26,8058566321705,128,15452,94245228,CLX5
2025-09-24T19:31:45.094683301Z,2025-09-24T19:31:45.094341369Z,160,1,432669,M,A,64.950000000,1,26,8058565075241,128,15052,94245234,CLX5
2025-09-24T19:31:45.098733214Z,2025-09-24T19:31:45.098593311Z,160,1,432669,A,B,64.810000000,1,26,8058566321713,128,18461,94245257,CLX5
2025-09-24T19:31:45.125745089Z,2025-09-24T19:31:45.125616253Z,160,1,432669,C,A,64.830000000,1,26,8058566319974,128,18449,94245265,CLX5
2025-09-24T19:31:45.182253289Z,2025-09-24T19:31:45.182127061Z,160,1,432669,C,B,64.820000000,1,26,8058566321701,128,18822,94245285,CLX5
2025-09-24T19:31:45.182282210Z,2025-09-24T19:31:45.182150215Z,160,1,432669,C,B,64.820000000,1,26,8058566321705,128,15482,94245286,CLX5
2025-09-24T19:31:45.209699568Z,2025-09-24T19:31:45.209567411Z,160,1,432669,A,A,64.880000000,2,26,8058566321732,128,19097,94245302,CLX5
2025-09-24T19:31:45.310023257Z,2025-09-24T19:31:45.309883007Z,160,1,432669,A,B,64.780000000,2,26,8058566321739,128,17938,94245314,CLX5
2025-09-24T19:31:45.890778998Z,2025-09-24T19:31:45.890491993Z,160,1,432669,A,B,64.820000000,1,26,8058566321757,128,15407,94245368,CLX5
2025-09-24T19:31:46.468843562Z,2025-09-24T19:31:46.468557783Z,160,1,432669,C,B,64.820000000,1,26,8058566321757,128,18723,94245457,CLX5
2025-09-24T19:31:47.071617669Z,2025-09-24T19:31:47.071351759Z,160,1,432669,A,B,64.820000000,1,26,8058566321794,128,14679,94245497,CLX5
2025-09-24T19:31:47.071707121Z,2025-09-24T19:31:47.071472579Z,160,1,432669,C,B,64.820000000,1,26,8058566321794,128,15780,94245501,CLX5
2025-09-24T19:31:47.071916367Z,2025-09-24T19:31:47.071757437Z,160,1,432669,A,B,64.820000000,1,26,8058566321798,128,15349,94245512,CLX5
2025-09-24T19:31:47.072010664Z,2025-09-24T19:31:47.071775637Z,160,1,432669,C,B,64.820000000,1,26,8058566321798,128,15560,94245515,CLX5
2025-09-24T19:31:47.129012131Z,2025-09-24T19:31:47.128874265Z,160,1,432669,A,B,64.820000000,1,26,8058566321802,128,18842,94245533,CLX5
2025-09-24T19:31:47.129924889Z,2025-09-24T19:31:47.129023461Z,160,1,432669,A,B,64.820000000,1,26,8058566321823,128,15638,94245582,CLX5
2025-09-24T19:31:47.130411338Z,2025-09-24T19:31:47.129455865Z,160,1,432669,C,A,64.830000000,2,26,8058566319976,128,14835,94245620,CLX5
2025-09-24T19:31:47.132100304Z,2025-09-24T19:31:47.130019399Z,160,1,432669,C,A,64.830000000,2,26,8058566319930,128,18488,94245696,CLX5
2025-09-24T19:31:47.132202689Z,2025-09-24T19:31:47.130026387Z,160,1,432669,A,B,64.820000000,2,26,8058566321854,128,19535,94245700,CLX5
2025-09-24T19:31:47.132420221Z,2025-09-24T19:31:47.130113033Z,160,1,432669,C,A,64.830000000,1,26,8058566319995,128,14583,94245709,CLX5
2025-09-24T19:31:47.132997550Z,2025-09-24T19:31:47.130409819Z,160,1,432669,A,B,64.810000000,2,26,8058566321863,128,18532,94245737,CLX5
2025-09-24T19:31:47.133155773Z,2025-09-24T19:31:47.130415207Z,160,1,432669,A,B,64.540000000,8,26,8058566321866,128,15247,94245744,CLX5
2025-09-24T19:31:47.133155773Z,2025-09-24T19:31:47.130417703Z,160,1,432669,C,B,64.780000000,2,26,8058566321739,128,15247,94245744,CLX5
2025-09-24T19:31:47.133312183Z,2025-09-24T19:31:47.130432699Z,160,1,432669,A,B,64.820000000,1,26,8058566321868,128,15162,94245749,CLX5
2025-09-24T19:31:47.133570908Z,2025-09-24T19:31:47.130545397Z,160,1,432669,A,B,64.820000000,1,26,8058566321871,128,18948,94245761,CLX5
2025-09-24T19:31:47.134188725Z,2025-09-24T19:31:47.130820983Z,160,1,432669,C,A,64.830000000,1,26,8058566319932,128,19324,94245797,CLX5
2025-09-24T19:31:47.134284420Z,2025-09-24T19:31:47.130823439Z,160,1,432669,C,A,64.830000000,1,26,8058566319933,128,19160,94245800,CLX5
2025-09-24T19:31:47.134312689Z,2025-09-24T19:31:47.130827643Z,160,1,432669,C,A,64.830000000,1,26,8058566319972,128,16209,94245801,CLX5
2025-09-24T19:31:47.134561193Z,2025-09-24T19:31:47.130937741Z,160,1,432669,A,B,64.820000000,1,26,8058566321888,128,15293,94245816,CLX5
2025-09-24T19:31:47.134991995Z,2025-09-24T19:31:47.131102615Z,160,1,432669,C,B,64.820000000,2,26,8058566321854,128,18734,94245839,CLX5
2025-09-24T19:31:47.135910928Z,2025-09-24T19:31:47.132208717Z,160,1,432669,C,A,64.860000000,1,26,8058566321231,128,18869,94245900,CLX5
2025-09-24T19:31:47.135928876Z,2025-09-24T19:31:47.132213881Z,160,1,432669,T,B,64.830000000,11,26,8058566321904,0,14112,94245901,CLX5
2025-09-24T19:31:47.135928876Z,2025-09-24T19:31:47.132213881Z,160,1,432669,F,A,64.830000000,1,26,8058566319856,0,14112,94245901,CLX5
2025-09-24T19:31:47.135928876Z,2025-09-24T19:31:47.132213881Z,160,1,432669,F,A,64.830000000,2,26,8058566319927,0,14112,94245901,CLX5
2025-09-24T19:31:47.135928876Z,2025-09-24T19:31:47.132213881Z,160,1,432669,F,A,64.830000000,2,26,8058566319928,0,14112,94245901,CLX5
2025-09-24T19:31:47.135928876Z,2025-09-24T19:31:47.132213881Z,160,1,432669,F,A,64.830000000,1,26,8058566319929,0,14112,94245901,CLX5
2025-09-24T19:31:47.135928876Z,2025-09-24T19:31:47.132213881Z,160,1,432669,F,A,64.830000000,1,26,8058566320622,0,14112,94245901,CLX5
2025-09-24T19:31:47.135928876Z,2025-09-24T19:31:47.132213881Z,160,1,432669,F,A,64.830000000,3,26,8058566320640,0,14112,94245901,CLX5
2025-09-24T19:31:47.135928876Z,2025-09-24T19:31:47.132213881Z,160,1,432669,F,A,64.830000000,1,26,8058566321539,0,14112,94245901,CLX5
2025-09-24T19:31:47.135975951Z,2025-09-24T19:31:47.132213881Z,160,1,432669,C,A,64.830000000,1,26,8058566319856,0,15277,94245902,CLX5
2025-09-24T19:31:47.135975951Z,2025-09-24T19:31:47.132213881Z,160,1,432669,C,A,64.830000000,2,26,8058566319927,0,15277,94245902,CLX5
2025-09-24T19:31:47.135975951Z,2025-09-24T19:31:47.132213881Z,160,1,432669,C,A,64.830000000,2,26,8058566319928,0,15277,94245902,CLX5
2025-09-24T19:31:47.135975951Z,2025-09-24T19:31:47.132213881Z,160,1,432669,C,A,64.830000000,1,26,8058566319929,0,15277,94245902,CLX5
2025-09-24T19:31:47.135975951Z,2025-09-24T19:31:47.132213881Z,160,1,432669,C,A,64.830000000,1,26,8058566320622,0,15277,94245902,CLX5
2025-09-24T19:31:47.135975951Z,2025-09-24T19:31:47.132213881Z,160,1,432669,C,A,64.830000000,3,26,8058566320640,0,15277,94245902,CLX5
2025-09-24T19:31:47.135975951Z,2025-09-24T19:31:47.132213881Z,160,1,432669,C,A,64.830000000,1,26,8058566321539,128,15277,94245902,CLX5
2025-09-24T19:31:47.136046312Z,2025-09-24T19:31:47.132224785Z,160,1,432669,A,B,64.830000000,3,26,8058566321905,128,14863,94245906,CLX5
2025-09-24T19:31:47.136092136Z,2025-09-24T19:31:47.132270789Z,160,1,432669,T,A,64.830000000,1,26,8058566321906,0,15705,94245911,CLX5
2025-09-24T19:31:47.136092136Z,2025-09-24T19:31:47.132270789Z,160,1,432669,F,B,64.830000000,1,26,8058566321905,0,15705,94245911,CLX5
2025-09-24T19:31:47.136136432Z,2025-09-24T19:31:47.132270789Z,160,1,432669,M,B,64.830000000,2,26,8058566321905,128,19008,94245912,CLX5
2025-09-24T19:31:47.136370191Z,2025-09-24T19:31:47.132682243Z,160,1,432669,T,A,64.830000000,1,26,8058566321909,0,14911,94245927,CLX5
2025-09-24T19:31:47.136370191Z,2025-09-24T19:31:47.132682243Z,160,1,432669,F,B,64.830000000,1,26,8058566321905,0,14911,94245927,CLX5
2025-09-24T19:31:47.136421629Z,2025-09-24T19:31:47.132682243Z,160,1,432669,M,B,64.830000000,1,26,8058566321905,128,18561,94245928,CLX5
2025-09-24T19:31:47.136640037Z,2025-09-24T19:31:47.133461749Z,160,1,432669,A,B,64.820000000,2,26,8058566321912,128,18992,94245942,CLX5
2025-09-24T19:31:47.137071208Z,2025-09-24T19:31:47.133590233Z,160,1,432669,T,A,64.830000000,1,26,8058566321922,0,15121,94245964,CLX5
2025-09-24T19:31:47.137071208Z,2025-09-24T19:31:47.133590233Z,160,1,432669,F,B,64.830000000,1,26,8058566321905,0,15121,94245964,CLX5
2025-09-24T19:31:47.137071208Z,2025-09-24T19:31:47.133590233Z,160,1,432669,C,B,64.830000000,1,26,8058566321905,128,15121,94245964,CLX5
2025-09-24T19:31:47.137682657Z,2025-09-24T19:31:47.134432201Z,160,1,432669,M,B,64.820000000,3,26,8058566280404,128,15847,94245991,CLX5
2025-09-24T19:31:47.139442207Z,2025-09-24T19:31:47.135930339Z,160,1,432669,A,B,64.830000000,1,26,8058566321965,128,18713,94246104,CLX5
2025-09-24T19:31:47.139497338Z,2025-09-24T19:31:47.135930933Z,160,1,432669,A,B,64.830000000,3,26,8058566321967,128,15441,94246108,CLX5
2025-09-24T19:31:47.139900441Z,2025-09-24T19:31:47.135944739Z,160,1,432669,A,B,64.830000000,1,26,8058566321971,128,21947,94246125,CLX5
2025-09-24T19:31:47.140131174Z,2025-09-24T19:31:47.135949939Z,160,1,432669,A,B,64.820000000,2,26,8058566321973,128,14328,94246132,CLX5
2025-09-24T19:31:47.140380684Z,2025-09-24T19:31:47.135957947Z,160,1,432669,A,A,64.840000000,1,26,8058566321976,128,15283,94246141,CLX5
2025-09-24T19:31:47.140589147Z,2025-09-24T19:31:47.136046519Z,160,1,432669,A,B,64.830000000,3,26,8058566321978,128,15314,94246150,CLX5
2025-09-24T19:31:47.140661343Z,2025-09-24T19:31:47.136046695Z,160,1,432669,A,B,64.830000000,2,26,8058566321979,128,16541,94246152,CLX5
2025-09-24T19:31:47.140690779Z,2025-09-24T19:31:47.136046875Z,160,1,432669,C,A,64.840000000,2,26,8058566319423,128,14302,94246153,CLX5
2025-09-24T19:31:47.140789139Z,2025-09-24T19:31:47.136047991Z,160,1,432669,C,A,64.840000000,2,26,8058566319432,128,15339,94246157,CLX5
2025-09-24T19:31:47.141043150Z,2025-09-24T19:31:47.136062121Z,160,1,432669,A,B,64.830000000,1,26,8058566321983,128,14629,94246167,CLX5
2025-09-24T19:31:47.141145880Z,2025-09-24T19:31:47.136073717Z,160,1,432669,C,B,64.810000000,1,26,8058566321713,128,14711,94246172,CLX5
2025-09-24T19:31:47.141531242Z,2025-09-24T19:31:47.136375987Z,160,1,432669,T,A,64.830000000,1,26,8058566321992,0,15055,94246195,CLX5
2025-09-24T19:31:47.141531242Z,2025-09-24T19:31:47.136375987Z,160,1,432669,F,B,64.830000000,1,26,8058566321965,0,15055,94246195,CLX5
2025-09-24T19:31:47.141568158Z,2025-09-24T19:31:47.136375987Z,160,1,432669,C,B,64.830000000,1,26,8058566321965,128,18260,94246196,CLX5
2025-09-24T19:31:47.141578225Z,2025-09-24T19:31:47.136378831Z,160,1,432669,T,A,64.830000000,1,26,8058566321993,0,15426,94246197,CLX5
2025-09-24T19:31:47.141578225Z,2025-09-24T19:31:47.136378831Z,160,1,432669,F,B,64.830000000,1,26,8058566321967,0,15426,94246197,CLX5
2025-09-24T19:31:47.141607055Z,2025-09-24T19:31:47.136378831Z,160,1,432669,M,B,64.830000000,2,26,8058566321967,128,16195,94246198,CLX5
2025-09-24T19:31:47.141949872Z,2025-09-24T19:31:47.136574161Z,160,1,432669,T,A,64.830000000,1,26,8058566321994,0,14973,94246222,CLX5
2025-09-24T19:31:47.141949872Z,2025-09-24T19:31:47.136574161Z,160,1,432669,F,B,64.830000000,1,26,8058566321967,0,14973,94246222,CLX5
2025-09-24T19:31:47.141987671Z,2025-09-24T19:31:47.136574161Z,160,1,432669,M,B,64.830000000,1,26,8058566321967,128,19631,94246223,CLX5
2025-09-24T19:31:47.142040852Z,2025-09-24T19:31:47.136605629Z,160,1,432669,A,B,64.800000000,1,26,8058566321995,128,14680,94246227,CLX5
2025-09-24T19:31:47.142372303Z,2025-09-24T19:31:47.137051435Z,160,1,432669,C,B,64.830000000,2,26,8058566321979,128,17338,94246241,CLX5
2025-09-24T19:31:47.142614541Z,2025-09-24T19:31:47.137084305Z,160,1,432669,C,B,64.820000000,1,26,8058566321868,128,16797,94246255,CLX5
2025-09-24T19:31:47.142699078Z,2025-09-24T19:31:47.137173657Z,160,1,432669,C,B,64.830000000,1,26,8058566321967,128,20742,94246260,CLX5
2025-09-24T19:31:47.142756606Z,2025-09-24T19:31:47.137332049Z,160,1,432669,C,B,64.820000000,3,26,8058566280404,128,15298,94246263,CLX5
2025-09-24T19:31:47.142887067Z,2025-09-24T19:31:47.137574781Z,160,1,432669,C,B,64.830000000,3,26,8058566321978,128,15978,94246268,CLX5
2025-09-24T19:31:47.143098033Z,2025-09-24T19:31:47.137668091Z,160,1,432669,T,A,64.830000000,2,26,8058566322018,0,15852,94246278,CLX5
2025-09-24T19:31:47.143098033Z,2025-09-24T19:31:47.137668091Z,160,1,432669,F,B,64.830000000,1,26,8058566321971,0,15852,94246278,CLX5
2025-09-24T19:31:47.143098033Z,2025-09-24T19:31:47.137668091Z,160,1,432669,F,B,64.830000000,1,26,8058566321983,0,15852,94246278,CLX5
2025-09-24T19:31:47.143098033Z,2025-09-24T19:31:47.137668091Z,160,1,432669,C,B,64.830000000,1,26,8058566321971,0,15852,94246278,CLX5
2025-09-24T19:31:47.143098033Z,2025-09-24T19:31:47.137668091Z,160,1,432669,C,B,64.830000000,1,26,8058566321983,128,15852,94246278,CLX5
2025-09-24T19:31:47.143207974Z,2025-09-24T19:31:47.137694855Z,160,1,432669,C,B,64.820000000,2,26,8058566321973,128,19122,94246284,CLX5
2025-09-24T19:31:47.143845365Z,2025-09-24T19:31:47.138083255Z,160,1,432669,M,A,64.850000000,1,26,8058566173085,128,15915,94246321,CLX5
2025-09-24T19:31:47.145104981Z,2025-09-24T19:31:47.139443801Z,160,1,432669,A,A,64.840000000,2,26,8058566322040,128,17859,94246404,CLX5
2025-09-24T19:31:47.145591030Z,2025-09-24T19:31:47.139931615Z,160,1,432669,M,B,64.820000000,1,26,8058566311303,128,15367,94246434,CLX5
2025-09-24T19:31:47.146125316Z,2025-09-24T19:31:47.140181261Z,160,1,432669,A,A,64.840000000,1,26,8058566322055,128,15281,94246457,CLX5
2025-09-24T19:31:47.146154559Z,2025-09-24T19:31:47.140181437Z,160,1,432669,A,A,64.840000000,1,26,8058566322056,128,16257,94246458,CLX5
2025-09-24T19:31:47.146470068Z,2025-09-24T19:31:47.140418217Z,160,1,432669,A,A,64.830000000,1,26,8058566322062,128,18517,94246472,CLX5
2025-09-24T19:31:47.147118280Z,2025-09-24T19:31:47.140792619Z,160,1,432669,C,B,64.810000000,1,26,8058566320842,128,15189,94246502,CLX5
2025-09-24T19:31:47.148261372Z,2025-09-24T19:31:47.141822309Z,160,1,432669,A,A,64.830000000,3,26,8058566322092,128,14925,94246570,CLX5
2025-09-24T19:31:47.149802721Z,2025-09-24T19:31:47.142894583Z,160,1,432669,A,A,64.830000000,1,26,8058566322115,128,17156,94246663,CLX5
2025-09-24T19:31:47.149846633Z,2025-09-24T19:31:47.142897807Z,160,1,432669,A,A,64.830000000,1,26,8058566322118,128,18956,94246664,CLX5
2025-09-24T19:31:47.150214893Z,2025-09-24T19:31:47.143179765Z,160,1,432669,A,A,64.830000000,2,26,8058566322124,128,16426,94246681,CLX5
2025-09-24T19:31:47.150460072Z,2025-09-24T19:31:47.143441777Z,160,1,432669,A,B,64.820000000,2,26,8058566322126,128,19246,94246691,CLX5
2025-09-24T19:31:47.150587108Z,2025-09-24T19:31:47.143541811Z,160,1,432669,A,B,64.820000000,1,26,8058566322127,128,15292,94246696,CLX5
2025-09-24T19:31:47.150627349Z,2025-09-24T19:31:47.143638377Z,160,1,432669,M,A,64.840000000,1,26,8058566322062,128,16922,94246697,CLX5
2025-09-24T19:31:47.151012895Z,2025-09-24T19:31:47.143871473Z,160,1,432669,A,B,64.820000000,1,26,8058566322132,128,15250,94246713,CLX5
2025-09-24T19:31:47.151611282Z,2025-09-24T19:31:47.144261253Z,160,1,432669,C,B,64.820000000,1,26,8058566321888,128,15188,94246757,CLX5
2025-09-24T19:31:47.151796675Z,2025-09-24T19:31:47.144449559Z,160,1,432669,A,A,64.830000000,1,26,8058566322139,128,19933,94246762,CLX5
2025-09-24T19:31:47.152299082Z,2025-09-24T19:31:47.145129651Z,160,1,432669,A,B,64.820000000,1,26,8058566322143,128,18551,94246795,CLX5
2025-09-24T19:31:47.153196896Z,2025-09-24T19:31:47.146470115Z,160,1,432669,C,B,64.820000000,2,26,8058566321912,128,18191,94246856,CLX5
2025-09-24T19:31:47.153263056Z,2025-09-24T19:31:47.146472343Z,160,1,432669,A,A,64.830000000,3,26,8058566322156,128,16266,94246858,CLX5
2025-09-24T19:31:47.153318426Z,2025-09-24T19:31:47.146487241Z,160,1,432669,C,B,64.820000000,2,26,8058566322126,128,18663,94246860,CLX5
2025-09-24T19:31:47.153347424Z,2025-09-24T19:31:47.146495421Z,160,1,432669,A,A,64.830000000,1,26,8058566322158,128,15263,94246861,CLX5
2025-09-24T19:31:47.153424750Z,2025-09-24T19:31:47.146633961Z,160,1,432669,M,A,64.830000000,1,26,8058566322062,128,19075,94246865,CLX5
2025-09-24T19:31:47.154205089Z,2025-09-24T19:31:47.147337133Z,160,1,432669,A,B,64.820000000,2,26,8058566322165,128,16246,94246919,CLX5
2025-09-24T19:31:47.154794206Z,2025-09-24T19:31:47.148270019Z,160,1,432669,C,B,64.820000000,2,26,8058566322165,128,14265,94246961,CLX5
2025-09-24T19:31:47.154845030Z,2025-09-24T19:31:47.148285415Z,160,1,432669,C,B,64.820000000,1,26,8058566322143,128,19418,94246963,CLX5
2025-09-24T19:31:47.154871424Z,2025-09-24T19:31:47.148298989Z,160,1,432669,C,B,64.820000000,1,26,8058566322132,128,15162,94246964,CLX5
2025-09-24T19:31:47.154901436Z,2025-09-24T19:31:47.148301619Z,160,1,432669,C,B,64.820000000,1,26,8058566322127,128,15269,94246965,CLX5
2025-09-24T19:31:47.158288307Z,2025-09-24T19:31:47.154627491Z,160,1,432669,C,A,64.830000000,1,26,8058566322158,128,19300,94247156,CLX5
2025-09-24T19:31:47.164117299Z,2025-09-24T19:31:47.163982893Z,160,1,432669,A,A,64.830000000,1,26,8058566322274,128,18880,94247315,CLX5
2025-09-24T19:31:47.164146382Z,2025-09-24T19:31:47.164026263Z,160,1,432669,A,A,64.830000000,1,26,8058566322275,128,15502,94247316,CLX5
2025-09-24T19:31:47.164381085Z,2025-09-24T19:31:47.164153957Z,160,1,432669,C,A,64.840000000,1,26,8058566321976,128,15392,94247324,CLX5
2025-09-24T19:31:47.164434059Z,2025-09-24T19:31:47.164173463Z,160,1,432669,C,B,64.820000000,1,26,8058566321802,128,15403,94247326,CLX5
2025-09-24T19:31:47.164467489Z,2025-09-24T19:31:47.164301063Z,160,1,432669,C,A,64.830000000,1,26,8058566322275,128,18650,94247327,CLX5
2025-09-24T19:31:47.164492886Z,2025-09-24T19:31:47.164372119Z,160,1,432669,C,A,64.830000000,1,26,8058566322274,128,15765,94247328,CLX5
2025-09-24T19:31:47.164992436Z,2025-09-24T19:31:47.164851193Z,160,1,432669,C,B,64.810000000,2,26,8058566321863,128,18397,94247335,CLX5
2025-09-24T19:31:47.165056153Z,2025-09-24T19:31:47.164852077Z,160,1,432669,C,B,64.770000000,2,26,8058566321294,128,15410,94247337,CLX5
2025-09-24T19:31:47.165192927Z,2025-09-24T19:31:47.164862291Z,160,1,432669,A,A,64.830000000,1,26,8058566322282,128,15503,94247342,CLX5
2025-09-24T19:31:47.165260476Z,2025-09-24T19:31:47.164902419Z,160,1,432669,A,A,64.830000000,2,26,8058566322283,128,16029,94247346,CLX5
2025-09-24T19:31:47.165481011Z,2025-09-24T19:31:47.165063151Z,160,1,432669,A,A,64.860000000,1,26,8058566322286,128,14906,94247358,CLX5
2025-09-24T19:31:47.165537257Z,2025-09-24T19:31:47.165128161Z,160,1,432669,A,A,64.830000000,1,26,8058566322287,128,18883,94247361,CLX5
2025-09-24T19:31:47.165674691Z,2025-09-24T19:31:47.165337875Z,160,1,432669,C,A,64.830000000,1,26,8058566322282,128,14007,94247369,CLX5
2025-09-24T19:31:47.165843542Z,2025-09-24T19:31:47.165494767Z,160,1,432669,C,A,64.830000000,2,26,8058566322283,128,14344,94247375,CLX5
2025-09-24T19:31:47.165907437Z,2025-09-24T19:31:47.165545069Z,160,1,432669,A,A,64.830000000,1,26,8058566322289,128,15407,94247377,CLX5
2025-09-24T19:31:47.166062203Z,2025-09-24T19:31:47.165680963Z,160,1,432669,C,A,64.830000000,1,26,8058566322289,128,15400,94247383,CLX5
2025-09-24T19:31:47.223484221Z,2025-09-24T19:31:47.223269667Z,160,1,432669,M,A,64.940000000,1,26,8058565075241,128,15345,94247567,CLX5
2025-09-24T19:31:47.223989953Z,2025-09-24T19:31:47.223856009Z,160,1,432669,A,A,64.830000000,2,26,8058566322384,128,18747,94247579,CLX5
2025-09-24T19:31:47.224122342Z,2025-09-24T19:31:47.223999407Z,160,1,432669,A,A,64.830000000,1,26,8058566322385,128,15370,94247585,CLX5
2025-09-24T19:31:47.224152454Z,2025-09-24T19:31:47.224046005Z,160,1,432669,M,A,64.950000000,1,26,8058565075241,128,14677,94247587,CLX5
2025-09-24T19:31:47.224246153Z,2025-09-24T19:31:47.224130039Z,160,1,432669,C,A,64.830000000,1,26,8058566322385,128,18366,94247588,CLX5
2025-09-24T19:31:47.224921911Z,2025-09-24T19:31:47.224785671Z,160,1,432669,A,B,64.810000000,2,26,8058566322388,128,18525,94247595,CLX5
2025-09-24T19:31:47.226119107Z,2025-09-24T19:31:47.225998385Z,160,1,432669,C,A,64.830000000,2,26,8058566322384,128,18452,94247613,CLX5
2025-09-24T19:31:47.227565843Z,2025-09-24T19:31:47.227428185Z,160,1,432669,C,B,64.810000000,2,26,8058566322388,128,18342,94247618,CLX5
2025-09-24T19:31:47.227613249Z,2025-09-24T19:31:47.227435577Z,160,1,432669,A,A,64.830000000,1,26,8058566322394,128,15301,94247620,CLX5
2025-09-24T19:31:47.227668558Z,2025-09-24T19:31:47.227484113Z,160,1,432669,A,A,64.830000000,2,26,8058566322395,128,17283,94247622,CLX5
2025-09-24T19:31:47.227788797Z,2025-09-24T19:31:47.227675853Z,160,1,432669,C,A,64.830000000,1,26,8058566322394,128,18571,94247623,CLX5
2025-09-24T19:31:47.231002010Z,2025-09-24T19:31:47.230883401Z,160,1,432669,A,A,64.830000000,1,26,8058566322403,128,19227,94247638,CLX5
2025-09-24T19:31:47.321502066Z,2025-09-24T19:31:47.321369643Z,160,1,432669,C,B,64.800000000,1,26,8058566321995,128,19005,94247788,CLX5
2025-09-24T19:31:47.509754114Z,2025-09-24T19:31:47.509613311Z,160,1,432669,A,B,64.780000000,2,26,8058566322627,128,18463,94247974,CLX5
2025-09-24T19:31:48.088671552Z,2025-09-24T19:31:48.088532141Z,160,1,432669,A,B,64.810000000,2,26,8058566322745,128,19423,94248172,CLX5
2025-09-24T19:31:48.088749776Z,2025-09-24T19:31:48.088536883Z,160,1,432669,C,A,64.830000000,1,26,8058566322287,128,15252,94248174,CLX5
2025-09-24T19:31:48.088786715Z,2025-09-24T19:31:48.088538881Z,160,1,432669,C,B,64.780000000,2,26,8058566322627,128,17257,94248176,CLX5
2025-09-24T19:31:48.088816251Z,2025-09-24T19:31:48.088548155Z,160,1,432669,C,A,64.830000000,1,26,8058566322403,128,15786,94248177,CLX5
2025-09-24T19:31:48.088845011Z,2025-09-24T19:31:48.088565435Z,160,1,432669,C,A,64.830000000,2,26,8058566322395,128,15328,94248178,CLX5
2025-09-24T19:31:48.089177799Z,2025-09-24T19:31:48.088773319Z,160,1,432669,C,B,64.810000000,2,26,8058566322745,128,15189,94248191,CLX5
2025-09-24T19:31:48.089254165Z,2025-09-24T19:31:48.088783419Z,160,1,432669,A,A,64.830000000,1,26,8058566322751,128,15710,94248194,CLX5
2025-09-24T19:31:48.089282640Z,2025-09-24T19:31:48.088823949Z,160,1,432669,C,A,64.830000000,1,26,8058566322139,128,15584,94248195,CLX5
2025-09-24T19:31:48.089312606Z,2025-09-24T19:31:48.088825199Z,160,1,432669,C,A,64.830000000,1,26,8058566322751,128,16049,94248196,CLX5
2025-09-24T19:31:48.089580624Z,2025-09-24T19:31:48.088949089Z,160,1,432669,A,A,64.830000000,2,26,8058566322755,128,15493,94248207,CLX5
2025-09-24T19:31:48.089726890Z,2025-09-24T19:31:48.089122265Z,160,1,432669,A,A,64.830000000,1,26,8058566322756,128,16984,94248214,CLX5
2025-09-24T19:31:48.089774281Z,2025-09-24T19:31:48.089122977Z,160,1,432669,A,A,64.830000000,1,26,8058566322757,128,15506,94248216,CLX5
2025-09-24T19:31:48.089807457Z,2025-09-24T19:31:48.089287303Z,160,1,432669,A,A,64.830000000,1,26,8058566322758,128,19931,94248217,CLX5
2025-09-24T19:31:48.209725825Z,2025-09-24T19:31:48.209591789Z,160,1,432669,A,B,64.780000000,2,26,8058566322764,128,18263,94248250,CLX5
2025-09-24T19:31:50.549261345Z,2025-09-24T19:31:50.549106865Z,160,1,432669,A,B,64.810000000,2,26,8058566322824,128,20182,94248368,CLX5
2025-09-24T19:31:50.549347856Z,2025-09-24T19:31:50.549113297Z,160,1,432669,C,A,64.830000000,1,26,8058566322757,128,15198,94248371,CLX5
2025-09-24T19:31:50.549451953Z,2025-09-24T19:31:50.549116773Z,160,1,432669,C,B,64.780000000,2,26,8058566322764,128,14930,94248375,CLX5
2025-09-24T19:31:50.549522858Z,2025-09-24T19:31:50.549152349Z,160,1,432669,C,A,64.830000000,2,26,8058566322755,128,15637,94248378,CLX5
2025-09-24T19:31:50.549551795Z,2025-09-24T19:31:50.549155899Z,160,1,432669,C,A,64.830000000,1,26,8058566322756,128,15681,94248379,CLX5
2025-09-24T19:31:50.601389059Z,2025-09-24T19:31:50.601248617Z,160,1,432669,C,A,64.860000000,1,26,8058566322286,128,14956,94248433,CLX5
2025-09-24T19:31:50.602428292Z,2025-09-24T19:31:50.602287847Z,160,1,432669,C,A,64.830000000,1,26,8058566322758,128,16837,94248458,CLX5
2025-09-24T19:31:50.609742586Z,2025-09-24T19:31:50.609607909Z,160,1,432669,C,B,64.790000000,2,26,8058566321279,128,18107,94248484,CLX5
2025-09-24T19:31:52.031830085Z,2025-09-24T19:31:52.031546779Z,160,1,432669,A,A,64.830000000,2,26,8058566322947,128,18734,94248675,CLX5
2025-09-24T19:31:52.032053975Z,2025-09-24T19:31:52.031611711Z,160,1,432669,C,B,64.790000000,1,26,8058566321584,128,16024,94248685,CLX5
2025-09-24T19:31:52.032120289Z,2025-09-24T19:31:52.031612009Z,160,1,432669,C,B,64.780000000,1,26,8058566320930,128,14965,94248687,CLX5
2025-09-24T19:31:52.032275701Z,2025-09-24T19:31:52.031640683Z,160,1,432669,A,A,64.830000000,1,26,8058566322958,128,15355,94248694,CLX5
2025-09-24T19:31:52.032392730Z,2025-09-24T19:31:52.031710049Z,160,1,432669,A,A,64.830000000,1,26,8058566322962,128,15316,94248701,CLX5
2025-09-24T19:31:52.032521533Z,2025-09-24T19:31:52.031789373Z,160,1,432669,A,A,64.830000000,1,26,8058566322966,128,16132,94248707,CLX5
2025-09-24T19:31:52.032655242Z,2025-09-24T19:31:52.031790667Z,160,1,432669,A,A,64.830000000,2,26,8058566322971,128,18844,94248713,CLX5
2025-09-24T19:31:52.032703201Z,2025-09-24T19:31:52.031791741Z,160,1,432669,C,B,64.810000000,2,26,8058566322824,128,15262,94248715,CLX5
2025-09-24T19:31:52.032920395Z,2025-09-24T19:31:52.031793941Z,160,1,432669,C,B,64.800000000,2,26,8058566321278,128,14787,94248729,CLX5
2025-09-24T19:31:52.033093347Z,2025-09-24T19:31:52.031795431Z,160,1,432669,C,B,64.820000000,3,26,8058566321697,128,16325,94248739,CLX5
2025-09-24T19:31:52.033977354Z,2025-09-24T19:31:52.031802483Z,160,1,432669,A,A,64.830000000,2,26,8058566322975,128,15744,94248787,CLX5
2025-09-24T19:31:52.034120279Z,2025-09-24T19:31:52.031808367Z,160,1,432669,C,B,64.820000000,1,26,8058566321698,128,14637,94248795,CLX5
2025-09-24T19:31:52.034210990Z,2025-09-24T19:31:52.031837263Z,160,1,432669,C,B,64.820000000,2,26,8058566321577,128,16337,94248799,CLX5
2025-09-24T19:31:52.034244458Z,2025-09-24T19:31:52.031837415Z,160,1,432669,C,B,64.820000000,1,26,8058566321578,128,16227,94248800,CLX5
2025-09-24T19:31:52.034278501Z,2025-09-24T19:31:52.031837587Z,160,1,432669,A,A,64.830000000,2,26,8058566322979,128,19221,94248801,CLX5
2025-09-24T19:31:52.034303214Z,2025-09-24T19:31:52.031837779Z,160,1,432669,A,A,64.830000000,1,26,8058566322980,128,15529,94248802,CLX5
2025-09-24T19:31:52.034342396Z,2025-09-24T19:31:52.031839585Z,160,1,432669,A,A,64.830000000,1,26,8058566322981,128,15525,94248804,CLX5
2025-09-24T19:31:52.034384917Z,2025-09-24T19:31:52.031842331Z,160,1,432669,A,A,64.830000000,1,26,8058566322982,128,18291,94248806,CLX5
2025-09-24T19:31:52.034642322Z,2025-09-24T19:31:52.031896529Z,160,1,432669,A,A,64.830000000,1,26,8058566322983,128,15678,94248817,CLX5
2025-09-24T19:31:52.034734562Z,2025-09-24T19:31:52.032056325Z,160,1,432669,C,A,64.830000000,1,26,8058566322958,128,15410,94248823,CLX5
2025-09-24T19:31:52.035008762Z,2025-09-24T19:31:52.032229923Z,160,1,432669,C,B,64.820000000,1,26,8058566321704,128,16587,94248838,CLX5
2025-09-24T19:31:52.035147970Z,2025-09-24T19:31:52.032280571Z,160,1,432669,C,B,64.820000000,2,26,8058566321575,128,17468,94248845,CLX5
2025-09-24T19:31:52.035349037Z,2025-09-24T19:31:52.032309407Z,160,1,432669,C,B,64.820000000,1,26,8058566321699,128,17049,94248857,CLX5
2025-09-24T19:31:52.036412032Z,2025-09-24T19:31:52.033069119Z,160,1,432669,C,A,64.830000000,2,26,8058566322975,128,16089,94248914,CLX5
2025-09-24T19:31:52.036449447Z,2025-09-24T19:31:52.033106057Z,160,1,432669,A,A,64.860000000,1,26,8058566322999,128,14798,94248916,CLX5
2025-09-24T19:31:52.036657994Z,2025-09-24T19:31:52.033225015Z,160,1,432669,A,B,64.820000000,1,26,8058566323002,128,17853,94248925,CLX5
2025-09-24T19:31:52.036944934Z,2025-09-24T19:31:52.033543511Z,160,1,432669,C,A,64.830000000,1,26,8058566322962,128,15096,94248941,CLX5
2025-09-24T19:31:52.037028189Z,2025-09-24T19:31:52.033572769Z,160,1,432669,C,A,64.830000000,2,26,8058566322979,128,15169,94248945,CLX5
2025-09-24T19:31:52.037395388Z,2025-09-24T19:31:52.033999413Z,160,1,432669,A,A,64.860000000,2,26,8058566323015,128,15725,94248965,CLX5
2025-09-24T19:31:52.037715282Z,2025-09-24T19:31:52.034117487Z,160,1,432669,C,B,64.820000000,1,26,8058566321871,128,15780,94248974,CLX5
2025-09-24T19:31:52.037722278Z,2025-09-24T19:31:52.034134171Z,160,1,432669,M,A,64.940000000,1,26,8058565075241,128,16239,94248975,CLX5
2025-09-24T19:31:52.037972510Z,2025-09-24T19:31:52.034301127Z,160,1,432669,A,B,64.820000000,1,26,8058566323022,128,16092,94248983,CLX5
2025-09-24T19:31:52.038038539Z,2025-09-24T19:31:52.034303315Z,160,1,432669,A,B,64.820000000,2,26,8058566323023,128,15791,94248985,CLX5
2025-09-24T19:31:52.038076338Z,2025-09-24T19:31:52.034305811Z,160,1,432669,C,A,64.830000000,1,26,8058566322981,128,18941,94248986,CLX5
2025-09-24T19:31:52.038109921Z,2025-09-24T19:31:52.034305967Z,160,1,432669,A,B,64.820000000,2,26,8058566323024,128,16905,94248987,CLX5
2025-09-24T19:31:52.038137775Z,2025-09-24T19:31:52.034307175Z,160,1,432669,C,A,64.830000000,1,26,8058566322983,128,14585,94248988,CLX5
2025-09-24T19:31:52.038170429Z,2025-09-24T19:31:52.034309095Z,160,1,432669,C,A,64.830000000,1,26,8058566322982,128,18737,94248989,CLX5
2025-09-24T19:31:52.038195426Z,2025-09-24T19:31:52.034310419Z,160,1,432669,C,A,64.830000000,1,26,8058566322980,128,15865,94248990,CLX5
2025-09-24T19:31:52.038229316Z,2025-09-24T19:31:52.034316409Z,160,1,432669,A,B,64.820000000,1,26,8058566323025,128,14772,94248991,CLX5
2025-09-24T19:31:52.038258444Z,2025-09-24T19:31:52.034318771Z,160,1,432669,A,A,64.830000000,1,26,8058566323026,128,15406,94248992,CLX5
2025-09-24T19:31:52.038780457Z,2025-09-24T19:31:52.035010997Z,160,1,432669,A,B,64.820000000,2,26,8058566323034,128,14578,94249013,CLX5
2025-09-24T19:31:52.038815192Z,2025-09-24T19:31:52.035011189Z,160,1,432669,A,B,64.820000000,1,26,8058566323035,128,15205,94249014,CLX5
2025-09-24T19:31:52.038824085Z,2025-09-24T19:31:52.035056307Z,160,1,432669,C,A,64.860000000,2,26,8058566323015,128,15036,94249015,CLX5
2025-09-24T19:31:52.038994411Z,2025-09-24T19:31:52.035202989Z,160,1,432669,T,A,64.820000000,1,26,8058566323036,0,14702,94249027,CLX5
2025-09-24T19:31:52.038994411Z,2025-09-24T19:31:52.035202989Z,160,1,432669,F,B,64.820000000,1,26,8058566321696,0,14702,94249027,CLX5
2025-09-24T19:31:52.039023970Z,2025-09-24T19:31:52.035202989Z,160,1,432669,C,B,64.820000000,1,26,8058566321696,128,15789,94249028,CLX5
2025-09-24T19:31:52.039126495Z,2025-09-24T19:31:52.035353683Z,160,1,432669,A,A,64.830000000,1,26,8058566323037,128,15495,94249034,CLX5
2025-09-24T19:31:52.039184397Z,2025-09-24T19:31:52.035380023Z,160,1,432669,M,B,64.800000000,1,26,8058566311303,128,18439,94249036,CLX5
2025-09-24T19:31:52.039211889Z,2025-09-24T19:31:52.035435183Z,160,1,432669,C,A,64.830000000,1,26,8058566323037,128,16103,94249037,CLX5
2025-09-24T19:31:52.039363945Z,2025-09-24T19:31:52.035701053Z,160,1,432669,A,A,64.830000000,1,26,8058566323040,128,15486,94249046,CLX5
2025-09-24T19:31:52.039371326Z,2025-09-24T19:31:52.035702705Z,160,1,432669,M,A,64.950000000,1,26,8058565075241,128,14557,94249047,CLX5
2025-09-24T19:31:52.039397183Z,2025-09-24T19:31:52.035704433Z,160,1,432669,A,A,64.830000000,1,26,8058566323041,128,18329,94249048,CLX5
2025-09-24T19:31:52.039493623Z,2025-09-24T19:31:52.035776371Z,160,1,432669,A,A,64.830000000,1,26,8058566323044,128,18014,94249053,CLX5
2025-09-24T19:31:52.039954560Z,2025-09-24T19:31:52.036440431Z,160,1,432669,M,B,64.810000000,1,26,8058566311303,128,14875,94249087,CLX5
2025-09-24T19:31:52.040028276Z,2025-09-24T19:31:52.036592337Z,160,1,432669,C,A,64.830000000,1,26,8058566323044,128,18474,94249092,CLX5
2025-09-24T19:31:52.040076581Z,2025-09-24T19:31:52.036666195Z,160,1,432669,C,A,64.830000000,1,26,8058566323041,128,15125,94249095,CLX5
2025-09-24T19:31:52.040104581Z,2025-09-24T19:31:52.036793869Z,160,1,432669,M,A,64.840000000,1,26,8058566173085,128,15730,94249096,CLX5
2025-09-24T19:31:52.040133602Z,2025-09-24T19:31:52.036953241Z,160,1,432669,A,A,64.830000000,1,26,8058566323054,128,18361,94249097,CLX5
2025-09-24T19:31:52.040454379Z,2025-09-24T19:31:52.037723417Z,160,1,432669,C,A,64.830000000,1,26,8058566323040,128,14733,94249115,CLX5
2025-09-24T19:31:52.040483370Z,2025-09-24T19:31:52.037724145Z,160,1,432669,C,A,64.830000000,1,26,8058566323054,128,15495,94249116,CLX5
2025-09-24T19:31:52.040650501Z,2025-09-24T19:31:52.037976133Z,160,1,432669,A,B,64.820000000,1,26,8058566323061,128,15335,94249121,CLX5
2025-09-24T19:31:52.040800675Z,2025-09-24T19:31:52.038030775Z,160,1,432669,A,A,64.830000000,1,26,8058566323063,128,17490,94249127,CLX5
2025-09-24T19:31:52.040877371Z,2025-09-24T19:31:52.038080673Z,160,1,432669,A,A,64.830000000,1,26,8058566323065,128,15486,94249130,CLX5
2025-09-24T19:31:52.040916691Z,2025-09-24T19:31:52.038083821Z,160,1,432669,A,A,64.830000000,1,26,8058566323066,128,18769,94249132,CLX5
2025-09-24T19:31:52.040963383Z,2025-09-24T19:31:52.038112677Z,160,1,432669,C,B,64.820000000,1,26,8058566323025,128,15571,94249134,CLX5
2025-09-24T19:31:52.040971085Z,2025-09-24T19:31:52.038151287Z,160,1,432669,M,A,64.940000000,1,26,8058565075241,128,14546,94249135,CLX5
2025-09-24T19:31:52.041030725Z,2025-09-24T19:31:52.038184251Z,160,1,432669,C,A,64.830000000,1,26,8058566323026,128,18626,94249137,CLX5
2025-09-24T19:31:52.041490226Z,2025-09-24T19:31:52.039401363Z,160,1,432669,C,A,64.830000000,1,26,8058566323065,128,15037,94249161,CLX5
2025-09-24T19:31:52.041804944Z,2025-09-24T19:31:52.040080803Z,160,1,432669,A,A,64.830000000,1,26,8058566323079,128,17654,94249176,CLX5
2025-09-24T19:31:52.042024519Z,2025-09-24T19:31:52.040740043Z,160,1,432669,C,A,64.830000000,1,26,8058566323066,128,19087,94249186,CLX5
2025-09-24T19:31:52.042048686Z,2025-09-24T19:31:52.040740217Z,160,1,432669,C,A,64.830000000,1,26,8058566323063,128,15412,94249187,CLX5
2025-09-24T19:31:52.042130221Z,2025-09-24T19:31:52.040804957Z,160,1,432669,C,A,64.830000000,1,26,8058566323079,128,18721,94249189,CLX5
2025-09-24T19:31:52.042239586Z,2025-09-24T19:31:52.040923741Z,160,1,432669,A,A,64.830000000,1,26,8058566323088,128,17136,94249193,CLX5
2025-09-24T19:31:52.042298104Z,2025-09-24T19:31:52.041038265Z,160,1,432669,C,A,64.830000000,1,26,8058566323088,128,15322,94249195,CLX5
2025-09-24T19:31:52.042325083Z,2025-09-24T19:31:52.041038411Z,160,1,432669,A,A,64.830000000,1,26,8058566323089,128,15387,94249196,CLX5
2025-09-24T19:31:52.042466065Z,2025-09-24T19:31:52.041168971Z,160,1,432669,A,A,64.830000000,1,26,8058566323091,128,15708,94249202,CLX5
2025-09-24T19:31:52.042544942Z,2025-09-24T19:31:52.041272129Z,160,1,432669,C,A,64.830000000,1,26,8058566323091,128,15257,94249205,CLX5
2025-09-24T19:31:52.042579584Z,2025-09-24T19:31:52.041272859Z,160,1,432669,C,A,64.830000000,1,26,8058566323089,128,18584,94249206,CLX5
2025-09-24T19:31:52.042603621Z,2025-09-24T19:31:52.041494513Z,160,1,432669,A,A,64.830000000,1,26,8058566323092,128,15633,94249207,CLX5
2025-09-24T19:31:52.042629939Z,2025-09-24T19:31:52.041497833Z,160,1,432669,A,A,64.830000000,1,26,8058566323093,128,15380,94249208,CLX5
2025-09-24T19:31:52.042721058Z,2025-09-24T19:31:52.041512617Z,160,1,432669,C,A,64.830000000,1,26,8058566323093,128,15838,94249214,CLX5
2025-09-24T19:31:52.043447909Z,2025-09-24T19:31:52.041809187Z,160,1,432669,C,A,64.830000000,1,26,8058566323092,128,14801,94249252,CLX5
2025-09-24T19:31:52.043477483Z,2025-09-24T19:31:52.041812123Z,160,1,432669,A,A,64.830000000,1,26,8058566323104,128,15381,94249253,CLX5
2025-09-24T19:31:52.043599919Z,2025-09-24T19:31:52.042028941Z,160,1,432669,A,A,64.830000000,1,26,8058566323108,128,15371,94249262,CLX5
2025-09-24T19:31:52.043640206Z,2025-09-24T19:31:52.042032511Z,160,1,432669,C,A,64.830000000,1,26,8058566323104,128,15413,94249264,CLX5
2025-09-24T19:31:52.043701143Z,2025-09-24T19:31:52.042066301Z,160,1,432669,C,A,64.830000000,2,26,8058566322971,128,14284,94249267,CLX5
2025-09-24T19:31:52.043746883Z,2025-09-24T19:31:52.042108311Z,160,1,432669,A,A,64.830000000,1,26,8058566323112,128,15559,94249270,CLX5
2025-09-24T19:31:52.043774284Z,2025-09-24T19:31:52.042115529Z,160,1,432669,C,A,64.830000000,1,26,8058566322966,128,15345,94249271,CLX5
2025-09-24T19:31:52.043800471Z,2025-09-24T19:31:52.042247063Z,160,1,432669,A,A,64.830000000,1,26,8058566323113,128,15430,94249272,CLX5
2025-09-24T19:31:52.043879962Z,2025-09-24T19:31:52.042726811Z,160,1,432669,A,B,64.780000000,1,26,8058566323114,128,14957,94249277,CLX5
2025-09-24T19:31:52.044025352Z,2025-09-24T19:31:52.043185747Z,160,1,432669,A,B,64.820000000,1,26,8058566323117,128,18584,94249283,CLX5
2025-09-24T19:31:52.044366381Z,2025-09-24T19:31:52.043316761Z,160,1,432669,M,A,64.950000000,1,26,8058565075241,128,15089,94249299,CLX5
2025-09-24T19:31:52.044475884Z,2025-09-24T19:31:52.043432285Z,160,1,432669,A,B,64.790000000,1,26,8058566323125,128,15263,94249305,CLX5
2025-09-24T19:31:52.045253359Z,2025-09-24T19:31:52.044153385Z,160,1,432669,A,B,64.820000000,1,26,8058566323139,128,15337,94249339,CLX5
2025-09-24T19:31:52.045388797Z,2025-09-24T19:31:52.044306939Z,160,1,432669,C,A,64.830000000,1,26,8058566323112,128,18974,94249345,CLX5
2025-09-24T19:31:52.045831011Z,2025-09-24T19:31:52.044746561Z,160,1,432669,A,A,64.830000000,1,26,8058566323149,128,15184,94249367,CLX5
2025-09-24T19:31:52.046023200Z,2025-09-24T19:31:52.045421815Z,160,1,432669,A,A,64.830000000,1,26,8058566323152,128,15471,94249378,CLX5
2025-09-24T19:31:52.046276151Z,2025-09-24T19:31:52.045971621Z,160,1,432669,A,B,64.820000000,1,26,8058566323157,128,15286,94249391,CLX5
2025-09-24T19:31:52.048606916Z,2025-09-24T19:31:52.047638569Z,160,1,432669,C,A,64.830000000,1,26,8058566323113,128,18675,94249515,CLX5
2025-09-24T19:31:52.048633956Z,2025-09-24T19:31:52.047639509Z,160,1,432669,C,A,64.830000000,1,26,8058566323149,128,14639,94249516,CLX5
2025-09-24T19:31:52.049429501Z,2025-09-24T19:31:52.048614827Z,160,1,432669,A,A,64.830000000,1,26,8058566323192,128,15158,94249588,CLX5
2025-09-24T19:31:52.049490753Z,2025-09-24T19:31:52.048615001Z,160,1,432669,A,A,64.830000000,1,26,8058566323193,128,18497,94249590,CLX5
2025-09-24T19:31:52.050330878Z,2025-09-24T19:31:52.050153255Z,160,1,432669,C,A,64.830000000,1,26,8058566323192,128,17596,94249655,CLX5
2025-09-24T19:31:52.050359484Z,2025-09-24T19:31:52.050153829Z,160,1,432669,C,A,64.830000000,1,26,8058566323193,128,15722,94249656,CLX5
2025-09-24T19:31:52.050455372Z,2025-09-24T19:31:52.050338775Z,160,1,432669,A,A,64.830000000,1,26,8058566323213,128,18166,94249660,CLX5
2025-09-24T19:31:52.066005818Z,2025-09-24T19:31:52.065884925Z,160,1,432669,C,A,64.830000000,1,26,8058566323152,128,20457,94249685,CLX5
2025-09-24T19:31:52.066126449Z,2025-09-24T19:31:52.066014001Z,160,1,432669,C,A,64.830000000,1,26,8058566323213,128,18370,94249686,CLX5
2025-09-24T19:31:52.088861718Z,2025-09-24T19:31:52.088726331Z,160,1,432669,A,B,64.800000000,2,26,8058566323254,128,18285,94249763,CLX5
2025-09-24T19:31:52.088915667Z,2025-09-24T19:31:52.088729075Z,160,1,432669,A,B,64.790000000,2,26,8058566323256,128,15077,94249765,CLX5
2025-09-24T19:31:52.101856363Z,2025-09-24T19:31:52.101703709Z,160,1,432669,C,A,64.830000000,2,26,8058566322947,128,15451,94249798,CLX5
2025-09-24T19:31:52.209798919Z,2025-09-24T19:31:52.209665849Z,160,1,432669,A,B,64.780000000,2,26,8058566323353,128,18698,94249954,CLX5
2025-09-24T19:31:52.341534572Z,2025-09-24T19:31:52.341396885Z,160,1,432669,C,A,64.860000000,1,26,8058566322999,128,18512,94250105,CLX5
2025-09-24T19:31:54.162354570Z,2025-09-24T19:31:54.162219287Z,160,1,432669,M,A,64.970000000,1,26,8058566157942,128,20035,94250305,CLX5
2025-09-24T19:31:54.464925295Z,2025-09-24T19:31:54.464671017Z,160,1,432669,A,A,64.830000000,2,26,8058566323542,128,16152,94250318,CLX5
2025-09-24T19:31:54.465059242Z,2025-09-24T19:31:54.464934009Z,160,1,432669,C,B,64.820000000,2,26,8058566323024,128,15788,94250321,CLX5
2025-09-24T19:31:55.016812366Z,2025-09-24T19:31:55.016603251Z,160,1,432669,C,B,64.820000000,2,26,8058566323023,128,15751,94250339,CLX5
2025-09-24T19:31:55.017078249Z,2025-09-24T19:31:55.016733153Z,160,1,432669,A,A,64.830000000,1,26,8058566323554,128,15256,94250349,CLX5
2025-09-24T19:31:55.017198689Z,2025-09-24T19:31:55.016830011Z,160,1,432669,A,A,64.830000000,1,26,8058566323555,128,15238,94250354,CLX5
2025-09-24T19:31:55.017355114Z,2025-09-24T19:31:55.017181453Z,160,1,432669,C,B,64.820000000,1,26,8058566323139,128,15774,94250361,CLX5
2025-09-24T19:31:55.017484308Z,2025-09-24T19:31:55.017250973Z,160,1,432669,C,B,64.820000000,1,26,8058566323157,128,19880,94250366,CLX5
2025-09-24T19:31:55.017585909Z,2025-09-24T19:31:55.017267943Z,160,1,432669,A,A,64.860000000,1,26,8058566323560,128,19132,94250369,CLX5
2025-09-24T19:31:55.017747833Z,2025-09-24T19:31:55.017280463Z,160,1,432669,C,B,64.820000000,1,26,8058566323117,128,16229,94250376,CLX5
2025-09-24T19:31:55.018053573Z,2025-09-24T19:31:55.017492249Z,160,1,432669,C,A,64.830000000,1,26,8058566323554,128,14921,94250391,CLX5
2025-09-24T19:31:55.018394616Z,2025-09-24T19:31:55.017755737Z,160,1,432669,A,A,64.830000000,1,26,8058566323573,128,15056,94250412,CLX5
2025-09-24T19:31:55.018471260Z,2025-09-24T19:31:55.017776165Z,160,1,432669,C,B,64.820000000,1,26,8058566323022,128,16209,94250415,CLX5
2025-09-24T19:31:55.019036094Z,2025-09-24T19:31:55.017912017Z,160,1,432669,A,A,64.830000000,1,26,8058566323583,128,15699,94250443,CLX5
2025-09-24T19:31:55.019201266Z,2025-09-24T19:31:55.018020783Z,160,1,432669,A,A,64.860000000,2,26,8058566323588,128,14822,94250453,CLX5
2025-09-24T19:31:55.019440716Z,2025-09-24T19:31:55.018164525Z,160,1,432669,M,A,64.940000000,1,26,8058565075241,128,14920,94250465,CLX5
2025-09-24T19:31:55.020065398Z,2025-09-24T19:31:55.018916807Z,160,1,432669,C,A,64.830000000,1,26,8058566323573,128,15333,94250493,CLX5
2025-09-24T19:31:55.020095210Z,2025-09-24T19:31:55.018919303Z,160,1,432669,C,A,64.830000000,1,26,8058566323555,128,15346,94250494,CLX5
2025-09-24T19:31:55.020516136Z,2025-09-24T19:31:55.019774875Z,160,1,432669,A,B,64.820000000,1,26,8058566323603,128,17077,94250517,CLX5
2025-09-24T19:31:55.020581896Z,2025-09-24T19:31:55.019780615Z,160,1,432669,A,A,64.830000000,1,26,8058566323604,128,19256,94250519,CLX5
2025-09-24T19:31:55.020686999Z,2025-09-24T19:31:55.019851115Z,160,1,432669,C,A,64.830000000,1,26,8058566323604,128,18916,94250523,CLX5
2025-09-24T19:31:55.021030800Z,2025-09-24T19:31:55.020448841Z,160,1,432669,A,B,64.820000000,2,26,8058566323611,128,16593,94250541,CLX5
2025-09-24T19:31:55.021172473Z,2025-09-24T19:31:55.020546141Z,160,1,432669,A,B,64.820000000,1,26,8058566323615,128,19032,94250548,CLX5
2025-09-24T19:31:55.021203614Z,2025-09-24T19:31:55.020589571Z,160,1,432669,A,A,64.830000000,1,26,8058566323616,128,15718,94250549,CLX5
2025-09-24T19:31:55.021620738Z,2025-09-24T19:31:55.020994041Z,160,1,432669,C,A,64.830000000,1,26,8058566323616,128,18995,94250576,CLX5
2025-09-24T19:31:55.029288516Z,2025-09-24T19:31:55.029162185Z,160,1,432669,A,A,64.830000000,1,26,8058566323638,128,18705,94250643,CLX5
2025-09-24T19:31:55.092217153Z,2025-09-24T19:31:55.092085835Z,160,1,432669,C,B,64.820000000,2,26,8058566323611,128,19419,94250681,CLX5
2025-09-24T19:31:55.092248808Z,2025-09-24T19:31:55.092086163Z,160,1,432669,C,B,64.820000000,1,26,8058566323615,128,16399,94250682,CLX5
2025-09-24T19:31:55.092282030Z,2025-09-24T19:31:55.092087295Z,160,1,432669,A,A,64.830000000,1,26,8058566323651,128,15209,94250683,CLX5
2025-09-24T19:31:55.092482744Z,2025-09-24T19:31:55.092227025Z,160,1,432669,C,A,64.830000000,1,26,8058566323651,128,15586,94250688,CLX5
2025-09-24T19:31:55.092511988Z,2025-09-24T19:31:55.092289711Z,160,1,432669,C,A,64.830000000,1,26,8058566323638,128,15463,94250689,CLX5
2025-09-24T19:31:55.092616184Z,2025-09-24T19:31:55.092490343Z,160,1,432669,A,A,64.830000000,1,26,8058566323653,128,15876,94250692,CLX5
2025-09-24T19:31:55.092643700Z,2025-09-24T19:31:55.092519581Z,160,1,432669,C,A,64.830000000,1,26,8058566323653,128,15413,94250693,CLX5
2025-09-24T19:31:55.092766213Z,2025-09-24T19:31:55.092651135Z,160,1,432669,A,A,64.830000000,1,26,8058566323654,128,18782,94250694,CLX5
2025-09-24T19:31:55.109796395Z,2025-09-24T19:31:55.109668325Z,160,1,432669,C,A,64.880000000,2,26,8058566321732,128,19166,94250705,CLX5
2025-09-24T19:31:55.242754350Z,2025-09-24T19:31:55.242628451Z,160,1,432669,C,A,64.830000000,1,26,8058566323654,128,18023,94250788,CLX5
2025-09-24T19:31:55.242887744Z,2025-09-24T19:31:55.242762749Z,160,1,432669,A,A,64.830000000,1,26,8058566323698,128,18783,94250790,CLX5
2025-09-24T19:31:55.243020341Z,2025-09-24T19:31:55.242898141Z,160,1,432669,A,A,64.830000000,1,26,8058566323701,128,13922,94250796,CLX5
2025-09-24T19:31:55.300121190Z,2025-09-24T19:31:55.299996001Z,160,1,432669,C,A,64.830000000,1,26,8058566323698,128,18854,94250828,CLX5
2025-09-24T19:31:55.300147354Z,2025-09-24T19:31:55.299996405Z,160,1,432669,C,A,64.830000000,1,26,8058566323701,128,15264,94250829,CLX5
2025-09-24T19:31:55.300293981Z,2025-09-24T19:31:55.300162131Z,160,1,432669,A,B,64.820000000,2,26,8058566323716,128,19980,94250831,CLX5
2025-09-24T19:31:55.300379056Z,2025-09-24T19:31:55.300258953Z,160,1,432669,A,B,64.820000000,1,26,8058566323717,128,15159,94250832,CLX5
2025-09-24T19:31:55.305003117Z,2025-09-24T19:31:55.304858763Z,160,1,432669,M,B,64.820000000,1,26,8058566321508,128,20089,94250836,CLX5
2025-09-24T19:31:55.305133747Z,2025-09-24T19:31:55.305012453Z,160,1,432669,A,A,64.830000000,1,26,8058566323720,128,18827,94250837,CLX5
2025-09-24T19:31:55.305255077Z,2025-09-24T19:31:55.305141107Z,160,1,432669,C,A,64.830000000,1,26,8058566323720,128,18973,94250838,CLX5
2025-09-24T19:31:55.367695681Z,2025-09-24T19:31:55.367580997Z,160,1,432669,C,A,64.830000000,1,26,8058566323583,128,15288,94250851,CLX5
2025-09-24T19:31:55.371347129Z,2025-09-24T19:31:55.371205719Z,160,1,432669,A,B,64.820000000,1,26,8058566323724,128,19033,94250852,CLX5
2025-09-24T19:31:55.457116698Z,2025-09-24T19:31:55.456963057Z,160,1,432669,A,B,64.820000000,1,26,8058566323755,128,19641,94250928,CLX5
2025-09-24T19:31:55.457299780Z,2025-09-24T19:31:55.456964689Z,160,1,432669,C,A,64.860000000,2,26,8058566323588,128,15044,94250935,CLX5
2025-09-24T19:31:55.457449725Z,2025-09-24T19:31:55.457090347Z,160,1,432669,M,A,64.950000000,1,26,8058565075241,128,14845,94250942,CLX5
2025-09-24T19:31:55.457449725Z,2025-09-24T19:31:55.457116515Z,160,1,432669,A,B,64.820000000,1,26,8058566323760,128,14845,94250942,CLX5
2025-09-24T19:31:55.457613868Z,2025-09-24T19:31:55.457386475Z,160,1,432669,A,A,64.830000000,1,26,8058566323762,128,15428,94250951,CLX5
2025-09-24T19:31:55.457647082Z,2025-09-24T19:31:55.457405693Z,160,1,432669,A,B,64.820000000,1,26,8058566323763,128,15152,94250952,CLX5
2025-09-24T19:31:55.460174453Z,2025-09-24T19:31:55.460033635Z,160,1,432669,A,B,64.810000000,1,26,8058566323766,128,18242,94250973,CLX5
2025-09-24T19:31:55.509772784Z,2025-09-24T19:31:55.509641791Z,160,1,432669,A,A,64.880000000,2,26,8058566323777,128,18476,94250989,CLX5
2025-09-24T19:31:55.563818145Z,2025-09-24T19:31:55.563684337Z,160,1,432669,C,B,64.820000000,1,26,8058566323755,128,19175,94250998,CLX5
2025-09-24T19:31:59.447080277Z,2025-09-24T19:31:59.446964141Z,160,1,432669,C,B,64.290000000,1,26,8058566137346,128,18340,94251791,CLX5
2025-09-24T19:32:00.408265272Z,2025-09-24T19:32:00.408110559Z,160,1,432669,A,B,64.810000000,2,26,8058566324253,128,18679,94252132,CLX5
2025-09-24T19:32:00.408449229Z,2025-09-24T19:32:00.408123153Z,160,1,432669,C,B,64.780000000,2,26,8058566323353,128,14849,94252136,CLX5
2025-09-24T19:32:00.408677996Z,2025-09-24T19:32:00.408157981Z,160,1,432669,C,A,64.830000000,1,26,8058566323762,128,14796,94252142,CLX5
2025-09-24T19:32:00.408707532Z,2025-09-24T19:32:00.408176717Z,160,1,432669,C,A,64.830000000,2,26,8058566323542,128,15433,94252143,CLX5
2025-09-24T19:32:00.408917423Z,2025-09-24T19:32:00.408332845Z,160,1,432669,A,A,64.830000000,2,26,8058566324260,128,16238,94252148,CLX5
2025-09-24T19:32:00.408970803Z,2025-09-24T19:32:00.408446811Z,160,1,432669,C,A,64.830000000,1,26,8058566323108,128,15449,94252151,CLX5
2025-09-24T19:32:00.409128550Z,2025-09-24T19:32:00.408494233Z,160,1,432669,C,B,64.810000000,2,26,8058566324253,128,18554,94252157,CLX5
